Workbook

Sheet 期望
B1: 最小攻击 | C1: 最大攻击 | D1: 穿透 | E1: 伤害加成 | F1: 武学属性 | G1: 牵丝 | H1: 怪物属性 | K1: 期望 | L1: 会心期望 | M1: 会意期望 | N1: 普通期望 | O1: 擦伤期望 | P1: 次数 | Q1: 技能 | R1: 增益1 | S1: 增益2 | T1: 增益3 | U1: 增益4 | V1: 增益5 | W1: 增益6 | X1: 增益7 | Y1: 增益8 | Z1: 增益9 | AA1: 增益10 | AB1: 增益11 | AC1: 增益12 | AD1: 增益13 | AE1: 增益14 | AF1: 增益15 | AG1: 类型 | AH1: 外功倍率 | AI1: 外攻固伤 | AJ1: 属性倍率 | AK1: 属性固伤 | AL1: 通用增伤 | AM1: 外攻加成 | AN1: 即时小外 | AO1: 即时大外 | AP1: 外穿加成 | AQ1: 外伤加成 | AR1: 属攻加成 | AS1: 即时小鸣 | AT1: 即时大鸣 | AU1: 鸣金穿透 | AV1: 鸣金加成 | AW1: 即时小裂 | AX1: 即时大裂 | AY1: 裂石穿透 | AZ1: 裂石加成 | BA1: 即时小牵 | BB1: 即时大牵 | BC1: 牵丝穿透 | BD1: 牵丝加成 | BE1: 即时小破 | BF1: 即时大破 | BG1: 破竹穿透 | BH1: 破竹加成 | BI1: 生效精准 | BJ1: 生效会心 | BK1: 生效会心伤害 | BL1: 生效会意 | BM1: 生效会意伤害 | BN1: 会心占比 | BO1: 普攻占比 | BP1: 擦伤占比 | BQ1: 特殊增伤
A2: 外功 | B2: 4320 | C2: 3339.6 | D2: =58.7+IF(OR($E$20="征人归",$E$22="征人归"),5.1,0) -> 63.8 | E2: =IF($E$22="四时无常",2.8%,0) -> 0 | F2: 套装 | G2: 浣花 | H2: 防御 | I2: =620*(1-IF(F17="√",0.06,0)-IF(F19="√",0.04,0)) -> 582.8 | K2: =($L2*$BN2+$M2*$BL2+$N2*$BO2+$O2*$BP2) -> 116312.79 | L2: =((($AN2+$AO2)/2*$AH2+$AI2)*(1+$AP2)*(1+$AQ2)+(($AS2+$AT2)/2*IF($G$1="鸣金",$AJ2,$AH2)+IF($G$1="鸣金",$AK2*1.5,0))*(1+$AU2)*(1+$AV2)+(($AW2+$AX2)/2*IF($G$1="裂石",$AJ2,$AH2)+IF($G$1="裂石",$AK2*1.5,0))*(1+$AY2)*(1+$AZ2)+(($BA2+$BB2)/2*IF($G$1="牵丝",$AJ2,$AH2)+IF($G$1="牵丝",$AK2*1.5,0))*(1+$BC2)*(1+$BD2)+(($BE2+$BF2)/2*IF($G$1="破竹",$AJ2,$AH2)+IF($G$1="破竹",$AK2*1.5,0))*(1+$BG2)*(1+$BH2))*(1+$AL2)*$BK2*$P2*(1+IF(VLOOKUP($Q2,武学奇术!$A:$ZZ,30,FALSE)="蓄力技",#REF!,0))*(1+$BQ2) -> 118509.44 | M2: =(($AO2*$AH2+$AI2)*(1+$AP2)*(1+$AQ2)+($AT2*IF($G$1="鸣金",$AJ2,$AH2)+IF($G$1="鸣金",$AK2*1.5,0))*(1+$AU2)*(1+$AV2)+($AX2*IF($G$1="裂石",$AJ2,$AH2)+IF($G$1="裂石",$AK2*1.5,0))*(1+$AY2)*(1+$AZ2)+($BB2*IF($G$1="牵丝",$AJ2,$AH2)+IF($G$1="牵丝",$AK2*1.5,0))*(1+$BC2)*(1+$BD2)+($BF2*IF($G$1="破竹",$AJ2,$AH2)+IF($G$1="破竹",$AK2*1.5,0))*(1+$BG2)*(1+$BH2))*(1+$AL2)*$BM2*$P2*(1+IF(VLOOKUP($Q2,武学奇术!$A:$ZZ,30,FALSE)="蓄力技",#REF!,0))*(1+$BQ2) -> 103739.8 | N2: =((($AN2+$AO2)/2*$AH2+$AI2)*(1+$AP2)*(1+$AQ2)+(($AS2+$AT2)/2*IF($G$1="鸣金",$AJ2,$AH2)+IF($G$1="鸣金",$AK2*1.5,0))*(1+$AU2)*(1+$AV2)+(($AW2+$AX2)/2*IF($G$1="裂石",$AJ2,$AH2)+IF($G$1="裂石",$AK2*1.5,0))*(1+$AY2)*(1+$AZ2)+(($BA2+$BB2)/2*IF($G$1="牵丝",$AJ2,$AH2)+IF($G$1="牵丝",$AK2*1.5,0))*(1+$BC2)*(1+$BD2)+(($BE2+$BF2)/2*IF($G$1="破竹",$AJ2,$AH2)+IF($G$1="破竹",$AK2*1.5,0))*(1+$BG2)*(1+$BH2))*(1+$AL2)*$P2*(1+IF(VLOOKUP($Q2,武学奇术!$A:$ZZ,30,FALSE)="蓄力技",#REF!,0))*(1+$BQ2) -> 67719.682 | O2: =((($AN2*$AH2+$AI2)*(1+$AP2)*(1+$AQ2)+($AS2*IF($G$1="鸣金",$AJ2,$AH2)+IF($G$1="鸣金",$AK2*1.5,0))*(1+$AU2)*(1+$AV2)+($AW2*IF($G$1="裂石",$AJ2,$AH2)+IF($G$1="裂石",$AK2*1.5,0))*(1+$AY2)*(1+$AZ2)+($BA2*IF($G$1="牵丝",$AJ2,$AH2)+IF($G$1="牵丝",$AK2*1.5,0))*(1+$BC2)*(1+$BD2)+($BE2*IF($G$1="破竹",$AJ2,$AH2)+IF($G$1="破竹",$AK2*1.5,0))*(1+$BG2)*(1+$BH2))*(1+$AL2))*$P2*(1+IF(VLOOKUP($Q2,武学奇术!$A:$ZZ,30,FALSE)="蓄力技",#REF!,0))*(1+$BQ2) -> 58595.067 | P2: 1 | Q2: 神龙吐火暗灼2hit | R2: 惧刃(拐) | S2: 伞增 | T2: 沧海帖10层 | U2: 易水歌5层 | V2: 四时之秋 | W2: N/a | X2: 裁云(拐) | Y2: 离猎(拐) | Z2: 扶风(拐) | AA2: 浣花 | AB2: N/a | AC2: N/a | AD2: N/a | AE2: 大卷(30%+) | AF2: 无惧 | AG2: =VLOOKUP($Q2,武学奇术!$A:$ZZ,25,FALSE) -> 单体奇术 | AH2: =VLOOKUP($Q2,武学奇术!$A:$ZZ,26,FALSE) -> 3.987 | AI2: =VLOOKUP($Q2,武学奇术!$A:$ZZ,27,FALSE)*(1+IF(OR($AG2=$F$4,$AG2=$F$5),$B$21,0)) -> 807 | AJ2: =VLOOKUP($Q2,武学奇术!$A:$ZZ,28,FALSE) -> 5.9805 | AK2: =VLOOKUP($Q2,武学奇术!$A:$ZZ,29,FALSE)*(1+IF(OR($AG2=$F$4,$AG2=$F$5),$B$21,0)) -> 0 | AL2: {=$G$3+IFERROR(VLOOKUP($AG2,$F$4:$G$7,2,FALSE),0)+VLOOKUP($Q2,武学奇术!$A:$ZZ,2,FALSE)+SUM(_xlfn.XLOOKUP($R2:$AF2,增益!$A:$A,增益!$B:$B,0))} -> 0.8219 | AM2: {=VLOOKUP($Q2,武学奇术!$A:$ZZ,5,FALSE)+SUM(_xlfn.XLOOKUP($R2:$AF2,增益!$A:$A,增益!$E:$E,0))} -> 0 | AN2: {=$D$10*(1+$AM2)+VLOOKUP($Q2,武学奇术!$A:$ZZ,3,FALSE)+SUM(_xlfn.XLOOKUP($R2:$AF2,增益!$A:$A,增益!$C:$C,0))-$I$2} -> 3977.2 | AO2: {=$E$10*(1+$AM2)+VLOOKUP($Q2,武学奇术!$A:$ZZ,4,FALSE)+SUM(_xlfn.XLOOKUP($R2:$AF2,增益!$A:$A,增益!$D:$D,0))-$I$2} -> 3977.2 | AP2: {=IF($F$10-$I$3+VLOOKUP($Q2,武学奇术!$A:$ZZ,6,FALSE)+SUM(_xlfn.XLOOKUP(R2:AF2,增益!$A:$A,增益!$F:$F,0))>0,($F$10-$I$3+VLOOKUP($Q2,武学奇术!$A:$ZZ,6,FALSE)+SUM(_xlfn.XLOOKUP(R2:AF2,增益!$A:$A,增益!$F:$F,0)))/200,($F$10-$I$3+VLOOKUP($Q2,武学奇术!$A:$ZZ,6,FALSE)+SUM(_xlfn.XLOOKUP(R2:AF2,增益!$A:$A,增益!$F:$F,0)))/100)} -> 0.344 | AQ2: {=$G$10+VLOOKUP($Q2,武学奇术!$A:$ZZ,7,FALSE)+SUM(_xlfn.XLOOKUP(R2:AF2,增益!$A:$A,增益!$G:$G,0))} -> 0.04 | AR2: {=VLOOKUP($Q2,武学奇术!$A:$ZZ,8,FALSE)+SUM(_xlfn.XLOOKUP(R2:AF2,增益!$A:$A,增益!$H:$H,0))} -> 0.06 | AS2: =$D$11*(1+$AR2) -> 0 | AT2: =$E$11*(1+$AR2) -> 0 | AU2: {=IF($F$11-$I$4+VLOOKUP($Q2,武学奇术!$A:$ZZ,9,FALSE)+SUM(_xlfn.XLOOKUP(R2:AF2,增益!$A:$A,增益!$I:$I,0))>0,($F$11-$I$4+VLOOKUP($Q2,武学奇术!$A:$ZZ,9,FALSE)+SUM(_xlfn.XLOOKUP(R2:AF2,增益!$A:$A,增益!$I:$I,0)))/200,($F$11-$I$4+VLOOKUP($Q2,武学奇术!$A:$ZZ,9,FALSE)+SUM(_xlfn.XLOOKUP(R2:AF2,增益!$A:$A,增益!$I:$I,0)))/100)} -> -0.14 | AV2: {=$G$11+VLOOKUP($Q2,武学奇术!$A:$ZZ,10,FALSE)+SUM(_xlfn.XLOOKUP(R2:AF2,增益!$A:$A,增益!$J:$J,0))} -> 0.04 | AW2: =$D$12*(1+$AR2) -> 0 | AX2: =$E$12*(1+$AR2) -> 0 | AY2: {=IF($F$12-$I$4+VLOOKUP($Q2,武学奇术!$A:$ZZ,11,FALSE)+SUM(_xlfn.XLOOKUP(R2:AF2,增益!$A:$A,增益!$K:$K,0))>0,($F$12-$I$4+VLOOKUP($Q2,武学奇术!$A:$ZZ,11,FALSE)+SUM(_xlfn.XLOOKUP(R2:AF2,增益!$A:$A,增益!$K:$K,0)))/200,($F$12-$I$4+VLOOKUP($Q2,武学奇术!$A:$ZZ,11,FALSE)+SUM(_xlfn.XLOOKUP(R2:AF2,增益!$A:$A,增益!$K:$K,0)))/100)} -> -0.14 | AZ2: {=$G$12+VLOOKUP($Q2,武学奇术!$A:$ZZ,12,FALSE)+SUM(_xlfn.XLOOKUP(R2:AF2,增益!$A:$A,增益!$L:$L,0))} -> 0.04 | BA2: =$D$13*(1+$AR2) -> 739.244 | BB2: =$E$13*(1+$AR2) -> 1913.3 | BC2: {=IF($F$13-$I$4+VLOOKUP($Q2,武学奇术!$A:$ZZ,13,FALSE)+SUM(_xlfn.XLOOKUP(R2:AF2,增益!$A:$A,增益!$M:$M,0))>0,($F$13-$I$4+VLOOKUP($Q2,武学奇术!$A:$ZZ,13,FALSE)+SUM(_xlfn.XLOOKUP(R2:AF2,增益!$A:$A,增益!$K:$K,0)))/200,($F$13-$I$4+VLOOKUP($Q2,武学奇术!$A:$ZZ,13,FALSE)+SUM(_xlfn.XLOOKUP(R2:AF2,增益!$A:$A,增益!$M:$M,0)))/100)} -> 0.08 | BD2: {=$G$13+VLOOKUP($Q2,武学奇术!$A:$ZZ,14,FALSE)+SUM(_xlfn.XLOOKUP(R2:AF2,增益!$A:$A,增益!$N:$N,0))} -> 0.19 | BE2: =$D$14*(1+$AR2) -> 0 | BF2: =$E$14*(1+$AR2) -> 0 | BG2: {=IF($F$14-$I$4+VLOOKUP($Q2,武学奇术!$A:$ZZ,15,FALSE)+SUM(_xlfn.XLOOKUP(R2:AF2,增益!$A:$A,增益!$O:$O,0))>0,($F$14-$I$4+VLOOKUP($Q2,武学奇术!$A:$ZZ,15,FALSE)+SUM(_xlfn.XLOOKUP(R2:AF2,增益!$A:$A,增益!$O:$O,0)))/200,($F$14-$I$4+VLOOKUP($Q2,武学奇术!$A:$ZZ,15,FALSE)+SUM(_xlfn.XLOOKUP(R2:AF2,增益!$A:$A,增益!$O:$O,0)))/100)} -> -0.14 | BH2: {=$G$14+VLOOKUP($Q2,武学奇术!$A:$ZZ,16,FALSE)+SUM(_xlfn.XLOOKUP(R2:AF2,增益!$A:$A,增益!$P:$P,0))} -> 0.04 | BI2: =MIN(IF(VLOOKUP($Q2,武学奇术!$A:$ZZ,23,FALSE)=1,100%,$B$8),100%) -> 1 | BJ2: {=IF(VLOOKUP($Q2,武学奇术!$A:$ZZ,23,FALSE)=1,100%,MIN(80%,$B$9+VLOOKUP($Q2,武学奇术!$A:$ZZ,17,FALSE)+SUM(_xlfn.XLOOKUP(R2:AF2,增益!$A:$A,增益!$Q:$Q,0)))+$B$11+SUM(_xlfn.XLOOKUP(R2:AF2,增益!$A:$A,增益!$U:$U,0)))*IF(VLOOKUP($Q2,武学奇术!$A:$ZZ,24,FALSE)=1,0,1)} -> 0.892 | BK2: {=1+$B$13+VLOOKUP($Q2,武学奇术!$A:$ZZ,18,FALSE)+SUM(_xlfn.XLOOKUP(R2:AF2,增益!$A:$A,增益!$R:$R,0))} -> 1.75 | BL2: {=IF(VLOOKUP($Q2,武学奇术!$A:$ZZ,24,FALSE)=1,100%,MIN(40%,$B$10+VLOOKUP($Q2,武学奇术!$A:$ZZ,19,FALSE)+SUM(_xlfn.XLOOKUP(R2:AF2,增益!$A:$A,增益!$S:$S,0)))+$B$12+SUM(_xlfn.XLOOKUP(R2:AF2,增益!$A:$A,增益!$V:$V,0)))*IF(VLOOKUP($Q2,武学奇术!$A:$ZZ,23,FALSE)=1,0,1)} -> 0.0913 | BM2: {=1+$B$14+VLOOKUP($Q2,武学奇术!$A:$ZZ,20,FALSE)+SUM(_xlfn.XLOOKUP(R2:AF2,增益!$A:$A,增益!$T:$T,0))} -> 1.35 | BN2: =MIN((1-BL2)*BI2,BI2*BJ2) -> 0.892 | BO2: =1-BL2-BN2-BP2 -> 0.0167 | BP2: =IF(VLOOKUP($Q2,武学奇术!$A:$ZZ,22,FALSE)=1,0,(1-$BI2))*(1-$BL2) -> 0 | BQ2: {=SUM(_xlfn.XLOOKUP(R2:AF2,增益!$A:$A,增益!$W:$W,0))+$I$5} -> 0.11
A3: 鸣金 | F3: 通用增伤 | G3: =B16+1.5%+IF($D$16="√",8%,0)+IF(OR($E$20="征人归",$E$22="征人归"),8%,0) -> 0.2642 | H3: 外抗 | I3: =25-IF(D17="√",10,0)-IF(F17="√",10,0) -> 5 | K3: =($L3*$BN3+$M3*$BL3+$N3*$BO3+$O3*$BP3) -> 78285.685 | L3: =((($AN3+$AO3)/2*$AH3+$AI3)*(1+$AP3)*(1+$AQ3)+(($AS3+$AT3)/2*IF($G$1="鸣金",$AJ3,$AH3)+IF($G$1="鸣金",$AK3*1.5,0))*(1+$AU3)*(1+$AV3)+(($AW3+$AX3)/2*IF($G$1="裂石",$AJ3,$AH3)+IF($G$1="裂石",$AK3*1.5,0))*(1+$AY3)*(1+$AZ3)+(($BA3+$BB3)/2*IF($G$1="牵丝",$AJ3,$AH3)+IF($G$1="牵丝",$AK3*1.5,0))*(1+$BC3)*(1+$BD3)+(($BE3+$BF3)/2*IF($G$1="破竹",$AJ3,$AH3)+IF($G$1="破竹",$AK3*1.5,0))*(1+$BG3)*(1+$BH3))*(1+$AL3)*$BK3*$P3*(1+IF(VLOOKUP($Q3,武学奇术!$A:$ZZ,30,FALSE)="蓄力技",#REF!,0))*(1+$BQ3) -> 79763.742 | M3: =(($AO3*$AH3+$AI3)*(1+$AP3)*(1+$AQ3)+($AT3*IF($G$1="鸣金",$AJ3,$AH3)+IF($G$1="鸣金",$AK3*1.5,0))*(1+$AU3)*(1+$AV3)+($AX3*IF($G$1="裂石",$AJ3,$AH3)+IF($G$1="裂石",$AK3*1.5,0))*(1+$AY3)*(1+$AZ3)+($BB3*IF($G$1="牵丝",$AJ3,$AH3)+IF($G$1="牵丝",$AK3*1.5,0))*(1+$BC3)*(1+$BD3)+($BF3*IF($G$1="破竹",$AJ3,$AH3)+IF($G$1="破竹",$AK3*1.5,0))*(1+$BG3)*(1+$BH3))*(1+$AL3)*$BM3*$P3*(1+IF(VLOOKUP($Q3,武学奇术!$A:$ZZ,30,FALSE)="蓄力技",#REF!,0))*(1+$BQ3) -> 69827.525 | N3: =((($AN3+$AO3)/2*$AH3+$AI3)*(1+$AP3)*(1+$AQ3)+(($AS3+$AT3)/2*IF($G$1="鸣金",$AJ3,$AH3)+IF($G$1="鸣金",$AK3*1.5,0))*(1+$AU3)*(1+$AV3)+(($AW3+$AX3)/2*IF($G$1="裂石",$AJ3,$AH3)+IF($G$1="裂石",$AK3*1.5,0))*(1+$AY3)*(1+$AZ3)+(($BA3+$BB3)/2*IF($G$1="牵丝",$AJ3,$AH3)+IF($G$1="牵丝",$AK3*1.5,0))*(1+$BC3)*(1+$BD3)+(($BE3+$BF3)/2*IF($G$1="破竹",$AJ3,$AH3)+IF($G$1="破竹",$AK3*1.5,0))*(1+$BG3)*(1+$BH3))*(1+$AL3)*$P3*(1+IF(VLOOKUP($Q3,武学奇术!$A:$ZZ,30,FALSE)="蓄力技",#REF!,0))*(1+$BQ3) -> 45579.281 | O3: =((($AN3*$AH3+$AI3)*(1+$AP3)*(1+$AQ3)+($AS3*IF($G$1="鸣金",$AJ3,$AH3)+IF($G$1="鸣金",$AK3*1.5,0))*(1+$AU3)*(1+$AV3)+($AW3*IF($G$1="裂石",$AJ3,$AH3)+IF($G$1="裂石",$AK3*1.5,0))*(1+$AY3)*(1+$AZ3)+($BA3*IF($G$1="牵丝",$AJ3,$AH3)+IF($G$1="牵丝",$AK3*1.5,0))*(1+$BC3)*(1+$BD3)+($BE3*IF($G$1="破竹",$AJ3,$AH3)+IF($G$1="破竹",$AK3*1.5,0))*(1+$BG3)*(1+$BH3))*(1+$AL3))*$P3*(1+IF(VLOOKUP($Q3,武学奇术!$A:$ZZ,30,FALSE)="蓄力技",#REF!,0))*(1+$BQ3) -> 39434.47 | P3: 10 | Q3: 神龙吐火暗灼dot | R3: 惧刃(拐) | S3: 伞增 | T3: 沧海帖10层 | U3: 易水歌5层 | V3: 四时之秋 | W3: 惊神5(拐) | X3: 裁云(拐) | Y3: 离猎(拐) | Z3: 扶风(拐) | AA3: 浣花 | AB3: N/a | AC3: N/a | AD3: N/a | AE3: 大卷(30%+) | AF3: 无惧 | AG3: =VLOOKUP($Q3,武学奇术!$A:$ZZ,25,FALSE) -> 单体奇术 | AH3: =VLOOKUP($Q3,武学奇术!$A:$ZZ,26,FALSE) -> 0.2361 | AI3: =VLOOKUP($Q3,武学奇术!$A:$ZZ,27,FALSE)*(1+IF(OR($AG3=$F$4,$AG3=$F$5),$B$21,0)) -> 47 | AJ3: =VLOOKUP($Q3,武学奇术!$A:$ZZ,28,FALSE) -> 0.35415 | AK3: =VLOOKUP($Q3,武学奇术!$A:$ZZ,29,FALSE)*(1+IF(OR($AG3=$F$4,$AG3=$F$5),$B$21,0)) -> 0 | AL3: {=$G$3+IFERROR(VLOOKUP($AG3,$F$4:$G$7,2,FALSE),0)+VLOOKUP($Q3,武学奇术!$A:$ZZ,2,FALSE)+SUM(_xlfn.XLOOKUP($R3:$AF3,增益!$A:$A,增益!$B:$B,0))} -> 1.0719 | AM3: {=VLOOKUP($Q3,武学奇术!$A:$ZZ,5,FALSE)+SUM(_xlfn.XLOOKUP($R3:$AF3,增益!$A:$A,增益!$E:$E,0))} -> 0 | AN3: {=$D$10*(1+$AM3)+VLOOKUP($Q3,武学奇术!$A:$ZZ,3,FALSE)+SUM(_xlfn.XLOOKUP($R3:$AF3,增益!$A:$A,增益!$C:$C,0))-$I$2} -> 3977.2 | AO3: {=$E$10*(1+$AM3)+VLOOKUP($Q3,武学奇术!$A:$ZZ,4,FALSE)+SUM(_xlfn.XLOOKUP($R3:$AF3,增益!$A:$A,增益!$D:$D,0))-$I$2} -> 3977.2 | AP3: {=IF($F$10-$I$3+VLOOKUP($Q3,武学奇术!$A:$ZZ,6,FALSE)+SUM(_xlfn.XLOOKUP(R3:AF3,增益!$A:$A,增益!$F:$F,0))>0,($F$10-$I$3+VLOOKUP($Q3,武学奇术!$A:$ZZ,6,FALSE)+SUM(_xlfn.XLOOKUP(R3:AF3,增益!$A:$A,增益!$F:$F,0)))/200,($F$10-$I$3+VLOOKUP($Q3,武学奇术!$A:$ZZ,6,FALSE)+SUM(_xlfn.XLOOKUP(R3:AF3,增益!$A:$A,增益!$F:$F,0)))/100)} -> 0.344 | AQ3: {=$G$10+VLOOKUP($Q3,武学奇术!$A:$ZZ,7,FALSE)+SUM(_xlfn.XLOOKUP(R3:AF3,增益!$A:$A,增益!$G:$G,0))} -> 0.04 | AR3: {=VLOOKUP($Q3,武学奇术!$A:$ZZ,8,FALSE)+SUM(_xlfn.XLOOKUP(R3:AF3,增益!$A:$A,增益!$H:$H,0))} -> 0.06 | AS3: =$D$11*(1+$AR3) -> 0 | AT3: =$E$11*(1+$AR3) -> 0 | AU3: {=IF($F$11-$I$4+VLOOKUP($Q3,武学奇术!$A:$ZZ,9,FALSE)+SUM(_xlfn.XLOOKUP(R3:AF3,增益!$A:$A,增益!$I:$I,0))>0,($F$11-$I$4+VLOOKUP($Q3,武学奇术!$A:$ZZ,9,FALSE)+SUM(_xlfn.XLOOKUP(R3:AF3,增益!$A:$A,增益!$I:$I,0)))/200,($F$11-$I$4+VLOOKUP($Q3,武学奇术!$A:$ZZ,9,FALSE)+SUM(_xlfn.XLOOKUP(R3:AF3,增益!$A:$A,增益!$I:$I,0)))/100)} -> -0.14 | AV3: {=$G$11+VLOOKUP($Q3,武学奇术!$A:$ZZ,10,FALSE)+SUM(_xlfn.XLOOKUP(R3:AF3,增益!$A:$A,增益!$J:$J,0))} -> 0.04 | AW3: =$D$12*(1+$AR3) -> 0 | AX3: =$E$12*(1+$AR3) -> 0 | AY3: {=IF($F$12-$I$4+VLOOKUP($Q3,武学奇术!$A:$ZZ,11,FALSE)+SUM(_xlfn.XLOOKUP(R3:AF3,增益!$A:$A,增益!$K:$K,0))>0,($F$12-$I$4+VLOOKUP($Q3,武学奇术!$A:$ZZ,11,FALSE)+SUM(_xlfn.XLOOKUP(R3:AF3,增益!$A:$A,增益!$K:$K,0)))/200,($F$12-$I$4+VLOOKUP($Q3,武学奇术!$A:$ZZ,11,FALSE)+SUM(_xlfn.XLOOKUP(R3:AF3,增益!$A:$A,增益!$K:$K,0)))/100)} -> -0.14 | AZ3: {=$G$12+VLOOKUP($Q3,武学奇术!$A:$ZZ,12,FALSE)+SUM(_xlfn.XLOOKUP(R3:AF3,增益!$A:$A,增益!$L:$L,0))} -> 0.04 | BA3: =$D$13*(1+$AR3) -> 739.244 | BB3: =$E$13*(1+$AR3) -> 1913.3 | BC3: {=IF($F$13-$I$4+VLOOKUP($Q3,武学奇术!$A:$ZZ,13,FALSE)+SUM(_xlfn.XLOOKUP(R3:AF3,增益!$A:$A,增益!$M:$M,0))>0,($F$13-$I$4+VLOOKUP($Q3,武学奇术!$A:$ZZ,13,FALSE)+SUM(_xlfn.XLOOKUP(R3:AF3,增益!$A:$A,增益!$K:$K,0)))/200,($F$13-$I$4+VLOOKUP($Q3,武学奇术!$A:$ZZ,13,FALSE)+SUM(_xlfn.XLOOKUP(R3:AF3,增益!$A:$A,增益!$M:$M,0)))/100)} -> 0.08 | BD3: {=$G$13+VLOOKUP($Q3,武学奇术!$A:$ZZ,14,FALSE)+SUM(_xlfn.XLOOKUP(R3:AF3,增益!$A:$A,增益!$N:$N,0))} -> 0.19 | BE3: =$D$14*(1+$AR3) -> 0 | BF3: =$E$14*(1+$AR3) -> 0 | BG3: {=IF($F$14-$I$4+VLOOKUP($Q3,武学奇术!$A:$ZZ,15,FALSE)+SUM(_xlfn.XLOOKUP(R3:AF3,增益!$A:$A,增益!$O:$O,0))>0,($F$14-$I$4+VLOOKUP($Q3,武学奇术!$A:$ZZ,15,FALSE)+SUM(_xlfn.XLOOKUP(R3:AF3,增益!$A:$A,增益!$O:$O,0)))/200,($F$14-$I$4+VLOOKUP($Q3,武学奇术!$A:$ZZ,15,FALSE)+SUM(_xlfn.XLOOKUP(R3:AF3,增益!$A:$A,增益!$O:$O,0)))/100)} -> -0.14 | BH3: {=$G$14+VLOOKUP($Q3,武学奇术!$A:$ZZ,16,FALSE)+SUM(_xlfn.XLOOKUP(R3:AF3,增益!$A:$A,增益!$P:$P,0))} -> 0.04 | BI3: =MIN(IF(VLOOKUP($Q3,武学奇术!$A:$ZZ,23,FALSE)=1,100%,$B$8),100%) -> 1 | BJ3: {=IF(VLOOKUP($Q3,武学奇术!$A:$ZZ,23,FALSE)=1,100%,MIN(80%,$B$9+VLOOKUP($Q3,武学奇术!$A:$ZZ,17,FALSE)+SUM(_xlfn.XLOOKUP(R3:AF3,增益!$A:$A,增益!$Q:$Q,0)))+$B$11+SUM(_xlfn.XLOOKUP(R3:AF3,增益!$A:$A,增益!$U:$U,0)))*IF(VLOOKUP($Q3,武学奇术!$A:$ZZ,24,FALSE)=1,0,1)} -> 0.892 | BK3: {=1+$B$13+VLOOKUP($Q3,武学奇术!$A:$ZZ,18,FALSE)+SUM(_xlfn.XLOOKUP(R3:AF3,增益!$A:$A,增益!$R:$R,0))} -> 1.75 | BL3: {=IF(VLOOKUP($Q3,武学奇术!$A:$ZZ,24,FALSE)=1,100%,MIN(40%,$B$10+VLOOKUP($Q3,武学奇术!$A:$ZZ,19,FALSE)+SUM(_xlfn.XLOOKUP(R3:AF3,增益!$A:$A,增益!$S:$S,0)))+$B$12+SUM(_xlfn.XLOOKUP(R3:AF3,增益!$A:$A,增益!$V:$V,0)))*IF(VLOOKUP($Q3,武学奇术!$A:$ZZ,23,FALSE)=1,0,1)} -> 0.0913 | BM3: {=1+$B$14+VLOOKUP($Q3,武学奇术!$A:$ZZ,20,FALSE)+SUM(_xlfn.XLOOKUP(R3:AF3,增益!$A:$A,增益!$T:$T,0))} -> 1.35 | BN3: =MIN((1-BL3)*BI3,BI3*BJ3) -> 0.892 | BO3: =1-BL3-BN3-BP3 -> 0.0167 | BP3: =IF(VLOOKUP($Q3,武学奇术!$A:$ZZ,22,FALSE)=1,0,(1-$BI3))*(1-$BL3) -> 0 | BQ3: {=SUM(_xlfn.XLOOKUP(R3:AF3,增益!$A:$A,增益!$W:$W,0))+$I$5} -> 0.11
A4: 裂石 | F4: 伞 | G4: =B15+B17 -> 0 | H4: 属抗 | I4: =30 -> 30 | K4: =($L4*$BN4+$M4*$BL4+$N4*$BO4+$O4*$BP4) -> 119410.61 | L4: =((($AN4+$AO4)/2*$AH4+$AI4)*(1+$AP4)*(1+$AQ4)+(($AS4+$AT4)/2*IF($G$1="鸣金",$AJ4,$AH4)+IF($G$1="鸣金",$AK4*1.5,0))*(1+$AU4)*(1+$AV4)+(($AW4+$AX4)/2*IF($G$1="裂石",$AJ4,$AH4)+IF($G$1="裂石",$AK4*1.5,0))*(1+$AY4)*(1+$AZ4)+(($BA4+$BB4)/2*IF($G$1="牵丝",$AJ4,$AH4)+IF($G$1="牵丝",$AK4*1.5,0))*(1+$BC4)*(1+$BD4)+(($BE4+$BF4)/2*IF($G$1="破竹",$AJ4,$AH4)+IF($G$1="破竹",$AK4*1.5,0))*(1+$BG4)*(1+$BH4))*(1+$AL4)*$BK4*$P4*(1+IF(VLOOKUP($Q4,武学奇术!$A:$ZZ,30,FALSE)="蓄力技",#REF!,0))*(1+$BQ4) -> 121664.95 | M4: =(($AO4*$AH4+$AI4)*(1+$AP4)*(1+$AQ4)+($AT4*IF($G$1="鸣金",$AJ4,$AH4)+IF($G$1="鸣金",$AK4*1.5,0))*(1+$AU4)*(1+$AV4)+($AX4*IF($G$1="裂石",$AJ4,$AH4)+IF($G$1="裂石",$AK4*1.5,0))*(1+$AY4)*(1+$AZ4)+($BB4*IF($G$1="牵丝",$AJ4,$AH4)+IF($G$1="牵丝",$AK4*1.5,0))*(1+$BC4)*(1+$BD4)+($BF4*IF($G$1="破竹",$AJ4,$AH4)+IF($G$1="破竹",$AK4*1.5,0))*(1+$BG4)*(1+$BH4))*(1+$AL4)*$BM4*$P4*(1+IF(VLOOKUP($Q4,武学奇术!$A:$ZZ,30,FALSE)="蓄力技",#REF!,0))*(1+$BQ4) -> 106510.82 | N4: =((($AN4+$AO4)/2*$AH4+$AI4)*(1+$AP4)*(1+$AQ4)+(($AS4+$AT4)/2*IF($G$1="鸣金",$AJ4,$AH4)+IF($G$1="鸣金",$AK4*1.5,0))*(1+$AU4)*(1+$AV4)+(($AW4+$AX4)/2*IF($G$1="裂石",$AJ4,$AH4)+IF($G$1="裂石",$AK4*1.5,0))*(1+$AY4)*(1+$AZ4)+(($BA4+$BB4)/2*IF($G$1="牵丝",$AJ4,$AH4)+IF($G$1="牵丝",$AK4*1.5,0))*(1+$BC4)*(1+$BD4)+(($BE4+$BF4)/2*IF($G$1="破竹",$AJ4,$AH4)+IF($G$1="破竹",$AK4*1.5,0))*(1+$BG4)*(1+$BH4))*(1+$AL4)*$P4*(1+IF(VLOOKUP($Q4,武学奇术!$A:$ZZ,30,FALSE)="蓄力技",#REF!,0))*(1+$BQ4) -> 69522.83 | O4: =((($AN4*$AH4+$AI4)*(1+$AP4)*(1+$AQ4)+($AS4*IF($G$1="鸣金",$AJ4,$AH4)+IF($G$1="鸣金",$AK4*1.5,0))*(1+$AU4)*(1+$AV4)+($AW4*IF($G$1="裂石",$AJ4,$AH4)+IF($G$1="裂石",$AK4*1.5,0))*(1+$AY4)*(1+$AZ4)+($BA4*IF($G$1="牵丝",$AJ4,$AH4)+IF($G$1="牵丝",$AK4*1.5,0))*(1+$BC4)*(1+$BD4)+($BE4*IF($G$1="破竹",$AJ4,$AH4)+IF($G$1="破竹",$AK4*1.5,0))*(1+$BG4)*(1+$BH4))*(1+$AL4))*$P4*(1+IF(VLOOKUP($Q4,武学奇术!$A:$ZZ,30,FALSE)="蓄力技",#REF!,0))*(1+$BQ4) -> 60148.758 | P4: 4 | Q4: 太白醉月1-4 | R4: 惧刃(拐) | S4: 伞增 | T4: 沧海帖10层 | U4: 易水歌5层 | V4: 四时之秋 | W4: N/a | X4: 裁云(拐) | Y4: 离猎(拐) | Z4: 扶风(拐) | AA4: 浣花 | AB4: N/a | AC4: N/a | AD4: N/a | AE4: 大卷(30%+) | AF4: 无惧 | AG4: =VLOOKUP($Q4,武学奇术!$A:$ZZ,25,FALSE) -> 单体奇术 | AH4: =VLOOKUP($Q4,武学奇术!$A:$ZZ,26,FALSE) -> 1.024 | AI4: =VLOOKUP($Q4,武学奇术!$A:$ZZ,27,FALSE)*(1+IF(OR($AG4=$F$4,$AG4=$F$5),$B$21,0)) -> 203 | AJ4: =VLOOKUP($Q4,武学奇术!$A:$ZZ,28,FALSE) -> 1.536 | AK4: =VLOOKUP($Q4,武学奇术!$A:$ZZ,29,FALSE)*(1+IF(OR($AG4=$F$4,$AG4=$F$5),$B$21,0)) -> 0 | AL4: {=$G$3+IFERROR(VLOOKUP($AG4,$F$4:$G$7,2,FALSE),0)+VLOOKUP($Q4,武学奇术!$A:$ZZ,2,FALSE)+SUM(_xlfn.XLOOKUP($R4:$AF4,增益!$A:$A,增益!$B:$B,0))} -> 0.8219 | AM4: {=VLOOKUP($Q4,武学奇术!$A:$ZZ,5,FALSE)+SUM(_xlfn.XLOOKUP($R4:$AF4,增益!$A:$A,增益!$E:$E,0))} -> 0 | AN4: {=$D$10*(1+$AM4)+VLOOKUP($Q4,武学奇术!$A:$ZZ,3,FALSE)+SUM(_xlfn.XLOOKUP($R4:$AF4,增益!$A:$A,增益!$C:$C,0))-$I$2} -> 3977.2 | AO4: {=$E$10*(1+$AM4)+VLOOKUP($Q4,武学奇术!$A:$ZZ,4,FALSE)+SUM(_xlfn.XLOOKUP($R4:$AF4,增益!$A:$A,增益!$D:$D,0))-$I$2} -> 3977.2 | AP4: {=IF($F$10-$I$3+VLOOKUP($Q4,武学奇术!$A:$ZZ,6,FALSE)+SUM(_xlfn.XLOOKUP(R4:AF4,增益!$A:$A,增益!$F:$F,0))>0,($F$10-$I$3+VLOOKUP($Q4,武学奇术!$A:$ZZ,6,FALSE)+SUM(_xlfn.XLOOKUP(R4:AF4,增益!$A:$A,增益!$F:$F,0)))/200,($F$10-$I$3+VLOOKUP($Q4,武学奇术!$A:$ZZ,6,FALSE)+SUM(_xlfn.XLOOKUP(R4:AF4,增益!$A:$A,增益!$F:$F,0)))/100)} -> 0.344 | AQ4: {=$G$10+VLOOKUP($Q4,武学奇术!$A:$ZZ,7,FALSE)+SUM(_xlfn.XLOOKUP(R4:AF4,增益!$A:$A,增益!$G:$G,0))} -> 0.04 | AR4: {=VLOOKUP($Q4,武学奇术!$A:$ZZ,8,FALSE)+SUM(_xlfn.XLOOKUP(R4:AF4,增益!$A:$A,增益!$H:$H,0))} -> 0.06 | AS4: =$D$11*(1+$AR4) -> 0 | AT4: =$E$11*(1+$AR4) -> 0 | AU4: {=IF($F$11-$I$4+VLOOKUP($Q4,武学奇术!$A:$ZZ,9,FALSE)+SUM(_xlfn.XLOOKUP(R4:AF4,增益!$A:$A,增益!$I:$I,0))>0,($F$11-$I$4+VLOOKUP($Q4,武学奇术!$A:$ZZ,9,FALSE)+SUM(_xlfn.XLOOKUP(R4:AF4,增益!$A:$A,增益!$I:$I,0)))/200,($F$11-$I$4+VLOOKUP($Q4,武学奇术!$A:$ZZ,9,FALSE)+SUM(_xlfn.XLOOKUP(R4:AF4,增益!$A:$A,增益!$I:$I,0)))/100)} -> -0.14 | AV4: {=$G$11+VLOOKUP($Q4,武学奇术!$A:$ZZ,10,FALSE)+SUM(_xlfn.XLOOKUP(R4:AF4,增益!$A:$A,增益!$J:$J,0))} -> 0.04 | AW4: =$D$12*(1+$AR4) -> 0 | AX4: =$E$12*(1+$AR4) -> 0 | AY4: {=IF($F$12-$I$4+VLOOKUP($Q4,武学奇术!$A:$ZZ,11,FALSE)+SUM(_xlfn.XLOOKUP(R4:AF4,增益!$A:$A,增益!$K:$K,0))>0,($F$12-$I$4+VLOOKUP($Q4,武学奇术!$A:$ZZ,11,FALSE)+SUM(_xlfn.XLOOKUP(R4:AF4,增益!$A:$A,增益!$K:$K,0)))/200,($F$12-$I$4+VLOOKUP($Q4,武学奇术!$A:$ZZ,11,FALSE)+SUM(_xlfn.XLOOKUP(R4:AF4,增益!$A:$A,增益!$K:$K,0)))/100)} -> -0.14 | AZ4: {=$G$12+VLOOKUP($Q4,武学奇术!$A:$ZZ,12,FALSE)+SUM(_xlfn.XLOOKUP(R4:AF4,增益!$A:$A,增益!$L:$L,0))} -> 0.04 | BA4: =$D$13*(1+$AR4) -> 739.244 | BB4: =$E$13*(1+$AR4) -> 1913.3 | BC4: {=IF($F$13-$I$4+VLOOKUP($Q4,武学奇术!$A:$ZZ,13,FALSE)+SUM(_xlfn.XLOOKUP(R4:AF4,增益!$A:$A,增益!$M:$M,0))>0,($F$13-$I$4+VLOOKUP($Q4,武学奇术!$A:$ZZ,13,FALSE)+SUM(_xlfn.XLOOKUP(R4:AF4,增益!$A:$A,增益!$K:$K,0)))/200,($F$13-$I$4+VLOOKUP($Q4,武学奇术!$A:$ZZ,13,FALSE)+SUM(_xlfn.XLOOKUP(R4:AF4,增益!$A:$A,增益!$M:$M,0)))/100)} -> 0.08 | BD4: {=$G$13+VLOOKUP($Q4,武学奇术!$A:$ZZ,14,FALSE)+SUM(_xlfn.XLOOKUP(R4:AF4,增益!$A:$A,增益!$N:$N,0))} -> 0.19 | BE4: =$D$14*(1+$AR4) -> 0 | BF4: =$E$14*(1+$AR4) -> 0 | BG4: {=IF($F$14-$I$4+VLOOKUP($Q4,武学奇术!$A:$ZZ,15,FALSE)+SUM(_xlfn.XLOOKUP(R4:AF4,增益!$A:$A,增益!$O:$O,0))>0,($F$14-$I$4+VLOOKUP($Q4,武学奇术!$A:$ZZ,15,FALSE)+SUM(_xlfn.XLOOKUP(R4:AF4,增益!$A:$A,增益!$O:$O,0)))/200,($F$14-$I$4+VLOOKUP($Q4,武学奇术!$A:$ZZ,15,FALSE)+SUM(_xlfn.XLOOKUP(R4:AF4,增益!$A:$A,增益!$O:$O,0)))/100)} -> -0.14 | BH4: {=$G$14+VLOOKUP($Q4,武学奇术!$A:$ZZ,16,FALSE)+SUM(_xlfn.XLOOKUP(R4:AF4,增益!$A:$A,增益!$P:$P,0))} -> 0.04 | BI4: =MIN(IF(VLOOKUP($Q4,武学奇术!$A:$ZZ,23,FALSE)=1,100%,$B$8),100%) -> 1 | BJ4: {=IF(VLOOKUP($Q4,武学奇术!$A:$ZZ,23,FALSE)=1,100%,MIN(80%,$B$9+VLOOKUP($Q4,武学奇术!$A:$ZZ,17,FALSE)+SUM(_xlfn.XLOOKUP(R4:AF4,增益!$A:$A,增益!$Q:$Q,0)))+$B$11+SUM(_xlfn.XLOOKUP(R4:AF4,增益!$A:$A,增益!$U:$U,0)))*IF(VLOOKUP($Q4,武学奇术!$A:$ZZ,24,FALSE)=1,0,1)} -> 0.892 | BK4: {=1+$B$13+VLOOKUP($Q4,武学奇术!$A:$ZZ,18,FALSE)+SUM(_xlfn.XLOOKUP(R4:AF4,增益!$A:$A,增益!$R:$R,0))} -> 1.75 | BL4: {=IF(VLOOKUP($Q4,武学奇术!$A:$ZZ,24,FALSE)=1,100%,MIN(40%,$B$10+VLOOKUP($Q4,武学奇术!$A:$ZZ,19,FALSE)+SUM(_xlfn.XLOOKUP(R4:AF4,增益!$A:$A,增益!$S:$S,0)))+$B$12+SUM(_xlfn.XLOOKUP(R4:AF4,增益!$A:$A,增益!$V:$V,0)))*IF(VLOOKUP($Q4,武学奇术!$A:$ZZ,23,FALSE)=1,0,1)} -> 0.0913 | BM4: {=1+$B$14+VLOOKUP($Q4,武学奇术!$A:$ZZ,20,FALSE)+SUM(_xlfn.XLOOKUP(R4:AF4,增益!$A:$A,增益!$T:$T,0))} -> 1.35 | BN4: =MIN((1-BL4)*BI4,BI4*BJ4) -> 0.892 | BO4: =1-BL4-BN4-BP4 -> 0.0167 | BP4: =IF(VLOOKUP($Q4,武学奇术!$A:$ZZ,22,FALSE)=1,0,(1-$BI4))*(1-$BL4) -> 0 | BQ4: {=SUM(_xlfn.XLOOKUP(R4:AF4,增益!$A:$A,增益!$W:$W,0))+$I$5} -> 0.11
A5: 牵丝 | B5: 539 | C5: 1554.2 | D5: 30 | E5: 0.15 | F5: 扇 | G5: =B15+B18 -> 0 | H5: 副本天赋 | I5: 0.06 | K5: =($L5*$BN5+$M5*$BL5+$N5*$BO5+$O5*$BP5) -> 71603.593 | L5: =((($AN5+$AO5)/2*$AH5+$AI5)*(1+$AP5)*(1+$AQ5)+(($AS5+$AT5)/2*IF($G$1="鸣金",$AJ5,$AH5)+IF($G$1="鸣金",$AK5*1.5,0))*(1+$AU5)*(1+$AV5)+(($AW5+$AX5)/2*IF($G$1="裂石",$AJ5,$AH5)+IF($G$1="裂石",$AK5*1.5,0))*(1+$AY5)*(1+$AZ5)+(($BA5+$BB5)/2*IF($G$1="牵丝",$AJ5,$AH5)+IF($G$1="牵丝",$AK5*1.5,0))*(1+$BC5)*(1+$BD5)+(($BE5+$BF5)/2*IF($G$1="破竹",$AJ5,$AH5)+IF($G$1="破竹",$AK5*1.5,0))*(1+$BG5)*(1+$BH5))*(1+$AL5)*$BK5*$P5*(1+IF(VLOOKUP($Q5,武学奇术!$A:$ZZ,30,FALSE)="蓄力技",#REF!,0))*(1+$BQ5) -> 72955.44 | M5: =(($AO5*$AH5+$AI5)*(1+$AP5)*(1+$AQ5)+($AT5*IF($G$1="鸣金",$AJ5,$AH5)+IF($G$1="鸣金",$AK5*1.5,0))*(1+$AU5)*(1+$AV5)+($AX5*IF($G$1="裂石",$AJ5,$AH5)+IF($G$1="裂石",$AK5*1.5,0))*(1+$AY5)*(1+$AZ5)+($BB5*IF($G$1="牵丝",$AJ5,$AH5)+IF($G$1="牵丝",$AK5*1.5,0))*(1+$BC5)*(1+$BD5)+($BF5*IF($G$1="破竹",$AJ5,$AH5)+IF($G$1="破竹",$AK5*1.5,0))*(1+$BG5)*(1+$BH5))*(1+$AL5)*$BM5*$P5*(1+IF(VLOOKUP($Q5,武学奇术!$A:$ZZ,30,FALSE)="蓄力技",#REF!,0))*(1+$BQ5) -> 63867.878 | N5: =((($AN5+$AO5)/2*$AH5+$AI5)*(1+$AP5)*(1+$AQ5)+(($AS5+$AT5)/2*IF($G$1="鸣金",$AJ5,$AH5)+IF($G$1="鸣金",$AK5*1.5,0))*(1+$AU5)*(1+$AV5)+(($AW5+$AX5)/2*IF($G$1="裂石",$AJ5,$AH5)+IF($G$1="裂石",$AK5*1.5,0))*(1+$AY5)*(1+$AZ5)+(($BA5+$BB5)/2*IF($G$1="牵丝",$AJ5,$AH5)+IF($G$1="牵丝",$AK5*1.5,0))*(1+$BC5)*(1+$BD5)+(($BE5+$BF5)/2*IF($G$1="破竹",$AJ5,$AH5)+IF($G$1="破竹",$AK5*1.5,0))*(1+$BG5)*(1+$BH5))*(1+$AL5)*$P5*(1+IF(VLOOKUP($Q5,武学奇术!$A:$ZZ,30,FALSE)="蓄力技",#REF!,0))*(1+$BQ5) -> 41688.823 | O5: =((($AN5*$AH5+$AI5)*(1+$AP5)*(1+$AQ5)+($AS5*IF($G$1="鸣金",$AJ5,$AH5)+IF($G$1="鸣金",$AK5*1.5,0))*(1+$AU5)*(1+$AV5)+($AW5*IF($G$1="裂石",$AJ5,$AH5)+IF($G$1="裂石",$AK5*1.5,0))*(1+$AY5)*(1+$AZ5)+($BA5*IF($G$1="牵丝",$AJ5,$AH5)+IF($G$1="牵丝",$AK5*1.5,0))*(1+$BC5)*(1+$BD5)+($BE5*IF($G$1="破竹",$AJ5,$AH5)+IF($G$1="破竹",$AK5*1.5,0))*(1+$BG5)*(1+$BH5))*(1+$AL5))*$P5*(1+IF(VLOOKUP($Q5,武学奇术!$A:$ZZ,30,FALSE)="蓄力技",#REF!,0))*(1+$BQ5) -> 36068.107 | P5: 1 | Q5: 太白醉月5 | R5: 惧刃(拐) | S5: 伞增 | T5: 沧海帖10层 | U5: 易水歌5层 | V5: 四时之秋 | W5: N/a | X5: 裁云(拐) | Y5: 离猎(拐) | Z5: 扶风(拐) | AA5: 浣花 | AB5: N/a | AC5: N/a | AD5: N/a | AE5: 大卷(30%+) | AF5: 无惧 | AG5: =VLOOKUP($Q5,武学奇术!$A:$ZZ,25,FALSE) -> 单体奇术 | AH5: =VLOOKUP($Q5,武学奇术!$A:$ZZ,26,FALSE) -> 1.7066 | AI5: =VLOOKUP($Q5,武学奇术!$A:$ZZ,27,FALSE)*(1+IF(OR($AG5=$F$4,$AG5=$F$5),$B$21,0)) -> 339 | AJ5: =VLOOKUP($Q5,武学奇术!$A:$ZZ,28,FALSE) -> 2.5599 | AK5: =VLOOKUP($Q5,武学奇术!$A:$ZZ,29,FALSE)*(1+IF(OR($AG5=$F$4,$AG5=$F$5),$B$21,0)) -> 0 | AL5: {=$G$3+IFERROR(VLOOKUP($AG5,$F$4:$G$7,2,FALSE),0)+VLOOKUP($Q5,武学奇术!$A:$ZZ,2,FALSE)+SUM(_xlfn.XLOOKUP($R5:$AF5,增益!$A:$A,增益!$B:$B,0))} -> 1.6219 | AM5: {=VLOOKUP($Q5,武学奇术!$A:$ZZ,5,FALSE)+SUM(_xlfn.XLOOKUP($R5:$AF5,增益!$A:$A,增益!$E:$E,0))} -> 0 | AN5: {=$D$10*(1+$AM5)+VLOOKUP($Q5,武学奇术!$A:$ZZ,3,FALSE)+SUM(_xlfn.XLOOKUP($R5:$AF5,增益!$A:$A,增益!$C:$C,0))-$I$2} -> 3977.2 | AO5: {=$E$10*(1+$AM5)+VLOOKUP($Q5,武学奇术!$A:$ZZ,4,FALSE)+SUM(_xlfn.XLOOKUP($R5:$AF5,增益!$A:$A,增益!$D:$D,0))-$I$2} -> 3977.2 | AP5: {=IF($F$10-$I$3+VLOOKUP($Q5,武学奇术!$A:$ZZ,6,FALSE)+SUM(_xlfn.XLOOKUP(R5:AF5,增益!$A:$A,增益!$F:$F,0))>0,($F$10-$I$3+VLOOKUP($Q5,武学奇术!$A:$ZZ,6,FALSE)+SUM(_xlfn.XLOOKUP(R5:AF5,增益!$A:$A,增益!$F:$F,0)))/200,($F$10-$I$3+VLOOKUP($Q5,武学奇术!$A:$ZZ,6,FALSE)+SUM(_xlfn.XLOOKUP(R5:AF5,增益!$A:$A,增益!$F:$F,0)))/100)} -> 0.344 | AQ5: {=$G$10+VLOOKUP($Q5,武学奇术!$A:$ZZ,7,FALSE)+SUM(_xlfn.XLOOKUP(R5:AF5,增益!$A:$A,增益!$G:$G,0))} -> 0.04 | AR5: {=VLOOKUP($Q5,武学奇术!$A:$ZZ,8,FALSE)+SUM(_xlfn.XLOOKUP(R5:AF5,增益!$A:$A,增益!$H:$H,0))} -> 0.06 | AS5: =$D$11*(1+$AR5) -> 0 | AT5: =$E$11*(1+$AR5) -> 0 | AU5: {=IF($F$11-$I$4+VLOOKUP($Q5,武学奇术!$A:$ZZ,9,FALSE)+SUM(_xlfn.XLOOKUP(R5:AF5,增益!$A:$A,增益!$I:$I,0))>0,($F$11-$I$4+VLOOKUP($Q5,武学奇术!$A:$ZZ,9,FALSE)+SUM(_xlfn.XLOOKUP(R5:AF5,增益!$A:$A,增益!$I:$I,0)))/200,($F$11-$I$4+VLOOKUP($Q5,武学奇术!$A:$ZZ,9,FALSE)+SUM(_xlfn.XLOOKUP(R5:AF5,增益!$A:$A,增益!$I:$I,0)))/100)} -> -0.14 | AV5: {=$G$11+VLOOKUP($Q5,武学奇术!$A:$ZZ,10,FALSE)+SUM(_xlfn.XLOOKUP(R5:AF5,增益!$A:$A,增益!$J:$J,0))} -> 0.04 | AW5: =$D$12*(1+$AR5) -> 0 | AX5: =$E$12*(1+$AR5) -> 0 | AY5: {=IF($F$12-$I$4+VLOOKUP($Q5,武学奇术!$A:$ZZ,11,FALSE)+SUM(_xlfn.XLOOKUP(R5:AF5,增益!$A:$A,增益!$K:$K,0))>0,($F$12-$I$4+VLOOKUP($Q5,武学奇术!$A:$ZZ,11,FALSE)+SUM(_xlfn.XLOOKUP(R5:AF5,增益!$A:$A,增益!$K:$K,0)))/200,($F$12-$I$4+VLOOKUP($Q5,武学奇术!$A:$ZZ,11,FALSE)+SUM(_xlfn.XLOOKUP(R5:AF5,增益!$A:$A,增益!$K:$K,0)))/100)} -> -0.14 | AZ5: {=$G$12+VLOOKUP($Q5,武学奇术!$A:$ZZ,12,FALSE)+SUM(_xlfn.XLOOKUP(R5:AF5,增益!$A:$A,增益!$L:$L,0))} -> 0.04 | BA5: =$D$13*(1+$AR5) -> 739.244 | BB5: =$E$13*(1+$AR5) -> 1913.3 | BC5: {=IF($F$13-$I$4+VLOOKUP($Q5,武学奇术!$A:$ZZ,13,FALSE)+SUM(_xlfn.XLOOKUP(R5:AF5,增益!$A:$A,增益!$M:$M,0))>0,($F$13-$I$4+VLOOKUP($Q5,武学奇术!$A:$ZZ,13,FALSE)+SUM(_xlfn.XLOOKUP(R5:AF5,增益!$A:$A,增益!$K:$K,0)))/200,($F$13-$I$4+VLOOKUP($Q5,武学奇术!$A:$ZZ,13,FALSE)+SUM(_xlfn.XLOOKUP(R5:AF5,增益!$A:$A,增益!$M:$M,0)))/100)} -> 0.08 | BD5: {=$G$13+VLOOKUP($Q5,武学奇术!$A:$ZZ,14,FALSE)+SUM(_xlfn.XLOOKUP(R5:AF5,增益!$A:$A,增益!$N:$N,0))} -> 0.19 | BE5: =$D$14*(1+$AR5) -> 0 | BF5: =$E$14*(1+$AR5) -> 0 | BG5: {=IF($F$14-$I$4+VLOOKUP($Q5,武学奇术!$A:$ZZ,15,FALSE)+SUM(_xlfn.XLOOKUP(R5:AF5,增益!$A:$A,增益!$O:$O,0))>0,($F$14-$I$4+VLOOKUP($Q5,武学奇术!$A:$ZZ,15,FALSE)+SUM(_xlfn.XLOOKUP(R5:AF5,增益!$A:$A,增益!$O:$O,0)))/200,($F$14-$I$4+VLOOKUP($Q5,武学奇术!$A:$ZZ,15,FALSE)+SUM(_xlfn.XLOOKUP(R5:AF5,增益!$A:$A,增益!$O:$O,0)))/100)} -> -0.14 | BH5: {=$G$14+VLOOKUP($Q5,武学奇术!$A:$ZZ,16,FALSE)+SUM(_xlfn.XLOOKUP(R5:AF5,增益!$A:$A,增益!$P:$P,0))} -> 0.04 | BI5: =MIN(IF(VLOOKUP($Q5,武学奇术!$A:$ZZ,23,FALSE)=1,100%,$B$8),100%) -> 1 | BJ5: {=IF(VLOOKUP($Q5,武学奇术!$A:$ZZ,23,FALSE)=1,100%,MIN(80%,$B$9+VLOOKUP($Q5,武学奇术!$A:$ZZ,17,FALSE)+SUM(_xlfn.XLOOKUP(R5:AF5,增益!$A:$A,增益!$Q:$Q,0)))+$B$11+SUM(_xlfn.XLOOKUP(R5:AF5,增益!$A:$A,增益!$U:$U,0)))*IF(VLOOKUP($Q5,武学奇术!$A:$ZZ,24,FALSE)=1,0,1)} -> 0.892 | BK5: {=1+$B$13+VLOOKUP($Q5,武学奇术!$A:$ZZ,18,FALSE)+SUM(_xlfn.XLOOKUP(R5:AF5,增益!$A:$A,增益!$R:$R,0))} -> 1.75 | BL5: {=IF(VLOOKUP($Q5,武学奇术!$A:$ZZ,24,FALSE)=1,100%,MIN(40%,$B$10+VLOOKUP($Q5,武学奇术!$A:$ZZ,19,FALSE)+SUM(_xlfn.XLOOKUP(R5:AF5,增益!$A:$A,增益!$S:$S,0)))+$B$12+SUM(_xlfn.XLOOKUP(R5:AF5,增益!$A:$A,增益!$V:$V,0)))*IF(VLOOKUP($Q5,武学奇术!$A:$ZZ,23,FALSE)=1,0,1)} -> 0.0913 | BM5: {=1+$B$14+VLOOKUP($Q5,武学奇术!$A:$ZZ,20,FALSE)+SUM(_xlfn.XLOOKUP(R5:AF5,增益!$A:$A,增益!$T:$T,0))} -> 1.35 | BN5: =MIN((1-BL5)*BI5,BI5*BJ5) -> 0.892 | BO5: =1-BL5-BN5-BP5 -> 0.0167 | BP5: =IF(VLOOKUP($Q5,武学奇术!$A:$ZZ,22,FALSE)=1,0,(1-$BI5))*(1-$BL5) -> 0 | BQ5: {=SUM(_xlfn.XLOOKUP(R5:AF5,增益!$A:$A,增益!$W:$W,0))+$I$5} -> 0.11
A6: 破竹 | F6: 单体奇术 | G6: =B19 -> 0.2677 | K6: =($L6*$BN6+$M6*$BL6+$N6*$BO6+$O6*$BP6) -> 234550.5 | L6: =((($AN6+$AO6)/2*$AH6+$AI6)*(1+$AP6)*(1+$AQ6)+(($AS6+$AT6)/2*IF($G$1="鸣金",$AJ6,$AH6)+IF($G$1="鸣金",$AK6*1.5,0))*(1+$AU6)*(1+$AV6)+(($AW6+$AX6)/2*IF($G$1="裂石",$AJ6,$AH6)+IF($G$1="裂石",$AK6*1.5,0))*(1+$AY6)*(1+$AZ6)+(($BA6+$BB6)/2*IF($G$1="牵丝",$AJ6,$AH6)+IF($G$1="牵丝",$AK6*1.5,0))*(1+$BC6)*(1+$BD6)+(($BE6+$BF6)/2*IF($G$1="破竹",$AJ6,$AH6)+IF($G$1="破竹",$AK6*1.5,0))*(1+$BG6)*(1+$BH6))*(1+$AL6)*$BK6*$P6*(1+IF(VLOOKUP($Q6,武学奇术!$A:$ZZ,30,FALSE)="蓄力技",#REF!,0))*(1+$BQ6) -> 238978.57 | M6: =(($AO6*$AH6+$AI6)*(1+$AP6)*(1+$AQ6)+($AT6*IF($G$1="鸣金",$AJ6,$AH6)+IF($G$1="鸣金",$AK6*1.5,0))*(1+$AU6)*(1+$AV6)+($AX6*IF($G$1="裂石",$AJ6,$AH6)+IF($G$1="裂石",$AK6*1.5,0))*(1+$AY6)*(1+$AZ6)+($BB6*IF($G$1="牵丝",$AJ6,$AH6)+IF($G$1="牵丝",$AK6*1.5,0))*(1+$BC6)*(1+$BD6)+($BF6*IF($G$1="破竹",$AJ6,$AH6)+IF($G$1="破竹",$AK6*1.5,0))*(1+$BG6)*(1+$BH6))*(1+$AL6)*$BM6*$P6*(1+IF(VLOOKUP($Q6,武学奇术!$A:$ZZ,30,FALSE)="蓄力技",#REF!,0))*(1+$BQ6) -> 209212.27 | N6: =((($AN6+$AO6)/2*$AH6+$AI6)*(1+$AP6)*(1+$AQ6)+(($AS6+$AT6)/2*IF($G$1="鸣金",$AJ6,$AH6)+IF($G$1="鸣金",$AK6*1.5,0))*(1+$AU6)*(1+$AV6)+(($AW6+$AX6)/2*IF($G$1="裂石",$AJ6,$AH6)+IF($G$1="裂石",$AK6*1.5,0))*(1+$AY6)*(1+$AZ6)+(($BA6+$BB6)/2*IF($G$1="牵丝",$AJ6,$AH6)+IF($G$1="牵丝",$AK6*1.5,0))*(1+$BC6)*(1+$BD6)+(($BE6+$BF6)/2*IF($G$1="破竹",$AJ6,$AH6)+IF($G$1="破竹",$AK6*1.5,0))*(1+$BG6)*(1+$BH6))*(1+$AL6)*$P6*(1+IF(VLOOKUP($Q6,武学奇术!$A:$ZZ,30,FALSE)="蓄力技",#REF!,0))*(1+$BQ6) -> 136559.18 | O6: =((($AN6*$AH6+$AI6)*(1+$AP6)*(1+$AQ6)+($AS6*IF($G$1="鸣金",$AJ6,$AH6)+IF($G$1="鸣金",$AK6*1.5,0))*(1+$AU6)*(1+$AV6)+($AW6*IF($G$1="裂石",$AJ6,$AH6)+IF($G$1="裂石",$AK6*1.5,0))*(1+$AY6)*(1+$AZ6)+($BA6*IF($G$1="牵丝",$AJ6,$AH6)+IF($G$1="牵丝",$AK6*1.5,0))*(1+$BC6)*(1+$BD6)+($BE6*IF($G$1="破竹",$AJ6,$AH6)+IF($G$1="破竹",$AK6*1.5,0))*(1+$BG6)*(1+$BH6))*(1+$AL6))*$P6*(1+IF(VLOOKUP($Q6,武学奇术!$A:$ZZ,30,FALSE)="蓄力技",#REF!,0))*(1+$BQ6) -> 118146.32 | P6: 5 | Q6: 太白醉月暗灼 | R6: 惧刃(拐) | S6: 伞增 | T6: 沧海帖10层 | U6: 易水歌5层 | V6: 四时之秋 | W6: N/a | X6: 裁云(拐) | Y6: 离猎(拐) | Z6: 扶风(拐) | AA6: 浣花 | AB6: N/a | AC6: N/a | AD6: N/a | AE6: 大卷(30%+) | AF6: 无惧 | AG6: =VLOOKUP($Q6,武学奇术!$A:$ZZ,25,FALSE) -> 单体奇术 | AH6: =VLOOKUP($Q6,武学奇术!$A:$ZZ,26,FALSE) -> 1.6091 | AI6: =VLOOKUP($Q6,武学奇术!$A:$ZZ,27,FALSE)*(1+IF(OR($AG6=$F$4,$AG6=$F$5),$B$21,0)) -> 319 | AJ6: =VLOOKUP($Q6,武学奇术!$A:$ZZ,28,FALSE) -> 2.41365 | AK6: =VLOOKUP($Q6,武学奇术!$A:$ZZ,29,FALSE)*(1+IF(OR($AG6=$F$4,$AG6=$F$5),$B$21,0)) -> 0 | AL6: {=$G$3+IFERROR(VLOOKUP($AG6,$F$4:$G$7,2,FALSE),0)+VLOOKUP($Q6,武学奇术!$A:$ZZ,2,FALSE)+SUM(_xlfn.XLOOKUP($R6:$AF6,增益!$A:$A,增益!$B:$B,0))} -> 0.8219 | AM6: {=VLOOKUP($Q6,武学奇术!$A:$ZZ,5,FALSE)+SUM(_xlfn.XLOOKUP($R6:$AF6,增益!$A:$A,增益!$E:$E,0))} -> 0 | AN6: {=$D$10*(1+$AM6)+VLOOKUP($Q6,武学奇术!$A:$ZZ,3,FALSE)+SUM(_xlfn.XLOOKUP($R6:$AF6,增益!$A:$A,增益!$C:$C,0))-$I$2} -> 3977.2 | AO6: {=$E$10*(1+$AM6)+VLOOKUP($Q6,武学奇术!$A:$ZZ,4,FALSE)+SUM(_xlfn.XLOOKUP($R6:$AF6,增益!$A:$A,增益!$D:$D,0))-$I$2} -> 3977.2 | AP6: {=IF($F$10-$I$3+VLOOKUP($Q6,武学奇术!$A:$ZZ,6,FALSE)+SUM(_xlfn.XLOOKUP(R6:AF6,增益!$A:$A,增益!$F:$F,0))>0,($F$10-$I$3+VLOOKUP($Q6,武学奇术!$A:$ZZ,6,FALSE)+SUM(_xlfn.XLOOKUP(R6:AF6,增益!$A:$A,增益!$F:$F,0)))/200,($F$10-$I$3+VLOOKUP($Q6,武学奇术!$A:$ZZ,6,FALSE)+SUM(_xlfn.XLOOKUP(R6:AF6,增益!$A:$A,增益!$F:$F,0)))/100)} -> 0.344 | AQ6: {=$G$10+VLOOKUP($Q6,武学奇术!$A:$ZZ,7,FALSE)+SUM(_xlfn.XLOOKUP(R6:AF6,增益!$A:$A,增益!$G:$G,0))} -> 0.04 | AR6: {=VLOOKUP($Q6,武学奇术!$A:$ZZ,8,FALSE)+SUM(_xlfn.XLOOKUP(R6:AF6,增益!$A:$A,增益!$H:$H,0))} -> 0.06 | AS6: =$D$11*(1+$AR6) -> 0 | AT6: =$E$11*(1+$AR6) -> 0 | AU6: {=IF($F$11-$I$4+VLOOKUP($Q6,武学奇术!$A:$ZZ,9,FALSE)+SUM(_xlfn.XLOOKUP(R6:AF6,增益!$A:$A,增益!$I:$I,0))>0,($F$11-$I$4+VLOOKUP($Q6,武学奇术!$A:$ZZ,9,FALSE)+SUM(_xlfn.XLOOKUP(R6:AF6,增益!$A:$A,增益!$I:$I,0)))/200,($F$11-$I$4+VLOOKUP($Q6,武学奇术!$A:$ZZ,9,FALSE)+SUM(_xlfn.XLOOKUP(R6:AF6,增益!$A:$A,增益!$I:$I,0)))/100)} -> -0.14 | AV6: {=$G$11+VLOOKUP($Q6,武学奇术!$A:$ZZ,10,FALSE)+SUM(_xlfn.XLOOKUP(R6:AF6,增益!$A:$A,增益!$J:$J,0))} -> 0.04 | AW6: =$D$12*(1+$AR6) -> 0 | AX6: =$E$12*(1+$AR6) -> 0 | AY6: {=IF($F$12-$I$4+VLOOKUP($Q6,武学奇术!$A:$ZZ,11,FALSE)+SUM(_xlfn.XLOOKUP(R6:AF6,增益!$A:$A,增益!$K:$K,0))>0,($F$12-$I$4+VLOOKUP($Q6,武学奇术!$A:$ZZ,11,FALSE)+SUM(_xlfn.XLOOKUP(R6:AF6,增益!$A:$A,增益!$K:$K,0)))/200,($F$12-$I$4+VLOOKUP($Q6,武学奇术!$A:$ZZ,11,FALSE)+SUM(_xlfn.XLOOKUP(R6:AF6,增益!$A:$A,增益!$K:$K,0)))/100)} -> -0.14 | AZ6: {=$G$12+VLOOKUP($Q6,武学奇术!$A:$ZZ,12,FALSE)+SUM(_xlfn.XLOOKUP(R6:AF6,增益!$A:$A,增益!$L:$L,0))} -> 0.04 | BA6: =$D$13*(1+$AR6) -> 739.244 | BB6: =$E$13*(1+$AR6) -> 1913.3 | BC6: {=IF($F$13-$I$4+VLOOKUP($Q6,武学奇术!$A:$ZZ,13,FALSE)+SUM(_xlfn.XLOOKUP(R6:AF6,增益!$A:$A,增益!$M:$M,0))>0,($F$13-$I$4+VLOOKUP($Q6,武学奇术!$A:$ZZ,13,FALSE)+SUM(_xlfn.XLOOKUP(R6:AF6,增益!$A:$A,增益!$K:$K,0)))/200,($F$13-$I$4+VLOOKUP($Q6,武学奇术!$A:$ZZ,13,FALSE)+SUM(_xlfn.XLOOKUP(R6:AF6,增益!$A:$A,增益!$M:$M,0)))/100)} -> 0.08 | BD6: {=$G$13+VLOOKUP($Q6,武学奇术!$A:$ZZ,14,FALSE)+SUM(_xlfn.XLOOKUP(R6:AF6,增益!$A:$A,增益!$N:$N,0))} -> 0.19 | BE6: =$D$14*(1+$AR6) -> 0 | BF6: =$E$14*(1+$AR6) -> 0 | BG6: {=IF($F$14-$I$4+VLOOKUP($Q6,武学奇术!$A:$ZZ,15,FALSE)+SUM(_xlfn.XLOOKUP(R6:AF6,增益!$A:$A,增益!$O:$O,0))>0,($F$14-$I$4+VLOOKUP($Q6,武学奇术!$A:$ZZ,15,FALSE)+SUM(_xlfn.XLOOKUP(R6:AF6,增益!$A:$A,增益!$O:$O,0)))/200,($F$14-$I$4+VLOOKUP($Q6,武学奇术!$A:$ZZ,15,FALSE)+SUM(_xlfn.XLOOKUP(R6:AF6,增益!$A:$A,增益!$O:$O,0)))/100)} -> -0.14 | BH6: {=$G$14+VLOOKUP($Q6,武学奇术!$A:$ZZ,16,FALSE)+SUM(_xlfn.XLOOKUP(R6:AF6,增益!$A:$A,增益!$P:$P,0))} -> 0.04 | BI6: =MIN(IF(VLOOKUP($Q6,武学奇术!$A:$ZZ,23,FALSE)=1,100%,$B$8),100%) -> 1 | BJ6: {=IF(VLOOKUP($Q6,武学奇术!$A:$ZZ,23,FALSE)=1,100%,MIN(80%,$B$9+VLOOKUP($Q6,武学奇术!$A:$ZZ,17,FALSE)+SUM(_xlfn.XLOOKUP(R6:AF6,增益!$A:$A,增益!$Q:$Q,0)))+$B$11+SUM(_xlfn.XLOOKUP(R6:AF6,增益!$A:$A,增益!$U:$U,0)))*IF(VLOOKUP($Q6,武学奇术!$A:$ZZ,24,FALSE)=1,0,1)} -> 0.892 | BK6: {=1+$B$13+VLOOKUP($Q6,武学奇术!$A:$ZZ,18,FALSE)+SUM(_xlfn.XLOOKUP(R6:AF6,增益!$A:$A,增益!$R:$R,0))} -> 1.75 | BL6: {=IF(VLOOKUP($Q6,武学奇术!$A:$ZZ,24,FALSE)=1,100%,MIN(40%,$B$10+VLOOKUP($Q6,武学奇术!$A:$ZZ,19,FALSE)+SUM(_xlfn.XLOOKUP(R6:AF6,增益!$A:$A,增益!$S:$S,0)))+$B$12+SUM(_xlfn.XLOOKUP(R6:AF6,增益!$A:$A,增益!$V:$V,0)))*IF(VLOOKUP($Q6,武学奇术!$A:$ZZ,23,FALSE)=1,0,1)} -> 0.0913 | BM6: {=1+$B$14+VLOOKUP($Q6,武学奇术!$A:$ZZ,20,FALSE)+SUM(_xlfn.XLOOKUP(R6:AF6,增益!$A:$A,增益!$T:$T,0))} -> 1.35 | BN6: =MIN((1-BL6)*BI6,BI6*BJ6) -> 0.892 | BO6: =1-BL6-BN6-BP6 -> 0.0167 | BP6: =IF(VLOOKUP($Q6,武学奇术!$A:$ZZ,22,FALSE)=1,0,(1-$BI6))*(1-$BL6) -> 0 | BQ6: {=SUM(_xlfn.XLOOKUP(R6:AF6,增益!$A:$A,增益!$W:$W,0))+$I$5} -> 0.11
A7: 无相 | B7: =79.2+IF($E$22="大卷微身",22.1,0)+79.2 -> 158.4 | C7: =92.4+79.2*2+IF($E$22="大卷微身",44.3,0) -> 250.8 | D7: =IF($E$22="大卷微身",6,0) -> 0 | F7: 群体奇术 | G7: =B19 -> 0.2677 | K7: =($L7*$BN7+$M7*$BL7+$N7*$BO7+$O7*$BP7) -> 264583.29 | L7: =((($AN7+$AO7)/2*$AH7+$AI7)*(1+$AP7)*(1+$AQ7)+(($AS7+$AT7)/2*IF($G$1="鸣金",$AJ7,$AH7)+IF($G$1="鸣金",$AK7*1.5,0))*(1+$AU7)*(1+$AV7)+(($AW7+$AX7)/2*IF($G$1="裂石",$AJ7,$AH7)+IF($G$1="裂石",$AK7*1.5,0))*(1+$AY7)*(1+$AZ7)+(($BA7+$BB7)/2*IF($G$1="牵丝",$AJ7,$AH7)+IF($G$1="牵丝",$AK7*1.5,0))*(1+$BC7)*(1+$BD7)+(($BE7+$BF7)/2*IF($G$1="破竹",$AJ7,$AH7)+IF($G$1="破竹",$AK7*1.5,0))*(1+$BG7)*(1+$BH7))*(1+$AL7)*$BK7*$P7*(1+IF(VLOOKUP($Q7,武学奇术!$A:$ZZ,30,FALSE)="蓄力技",#REF!,0))*(1+$BQ7) -> 269700.23 | M7: =(($AO7*$AH7+$AI7)*(1+$AP7)*(1+$AQ7)+($AT7*IF($G$1="鸣金",$AJ7,$AH7)+IF($G$1="鸣金",$AK7*1.5,0))*(1+$AU7)*(1+$AV7)+($AX7*IF($G$1="裂石",$AJ7,$AH7)+IF($G$1="裂石",$AK7*1.5,0))*(1+$AY7)*(1+$AZ7)+($BB7*IF($G$1="牵丝",$AJ7,$AH7)+IF($G$1="牵丝",$AK7*1.5,0))*(1+$BC7)*(1+$BD7)+($BF7*IF($G$1="破竹",$AJ7,$AH7)+IF($G$1="破竹",$AK7*1.5,0))*(1+$BG7)*(1+$BH7))*(1+$AL7)*$BM7*$P7*(1+IF(VLOOKUP($Q7,武学奇术!$A:$ZZ,30,FALSE)="蓄力技",#REF!,0))*(1+$BQ7) -> 234797.1 | N7: =((($AN7+$AO7)/2*$AH7+$AI7)*(1+$AP7)*(1+$AQ7)+(($AS7+$AT7)/2*IF($G$1="鸣金",$AJ7,$AH7)+IF($G$1="鸣金",$AK7*1.5,0))*(1+$AU7)*(1+$AV7)+(($AW7+$AX7)/2*IF($G$1="裂石",$AJ7,$AH7)+IF($G$1="裂石",$AK7*1.5,0))*(1+$AY7)*(1+$AZ7)+(($BA7+$BB7)/2*IF($G$1="牵丝",$AJ7,$AH7)+IF($G$1="牵丝",$AK7*1.5,0))*(1+$BC7)*(1+$BD7)+(($BE7+$BF7)/2*IF($G$1="破竹",$AJ7,$AH7)+IF($G$1="破竹",$AK7*1.5,0))*(1+$BG7)*(1+$BH7))*(1+$AL7)*$P7*(1+IF(VLOOKUP($Q7,武学奇术!$A:$ZZ,30,FALSE)="蓄力技",#REF!,0))*(1+$BQ7) -> 154114.42 | O7: =((($AN7*$AH7+$AI7)*(1+$AP7)*(1+$AQ7)+($AS7*IF($G$1="鸣金",$AJ7,$AH7)+IF($G$1="鸣金",$AK7*1.5,0))*(1+$AU7)*(1+$AV7)+($AW7*IF($G$1="裂石",$AJ7,$AH7)+IF($G$1="裂石",$AK7*1.5,0))*(1+$AY7)*(1+$AZ7)+($BA7*IF($G$1="牵丝",$AJ7,$AH7)+IF($G$1="牵丝",$AK7*1.5,0))*(1+$BC7)*(1+$BD7)+($BE7*IF($G$1="破竹",$AJ7,$AH7)+IF($G$1="破竹",$AK7*1.5,0))*(1+$BG7)*(1+$BH7))*(1+$AL7))*$P7*(1+IF(VLOOKUP($Q7,武学奇术!$A:$ZZ,30,FALSE)="蓄力技",#REF!,0))*(1+$BQ7) -> 134305.06 | P7: 8 | Q7: 太白醉月1-4 | R7: 惧刃(拐) | S7: 伞增 | T7: 沧海帖10层 | U7: 易水歌5层 | V7: 四时之秋 | W7: N/a | X7: 裁云(拐) | Y7: 离猎(拐) | Z7: 烁鼓(拐) | AA7: 浣花 | AB7: N/a | AC7: N/a | AD7: N/a | AE7: 大卷(30%+) | AF7: 无惧 | AG7: =VLOOKUP($Q7,武学奇术!$A:$ZZ,25,FALSE) -> 单体奇术 | AH7: =VLOOKUP($Q7,武学奇术!$A:$ZZ,26,FALSE) -> 1.024 | AI7: =VLOOKUP($Q7,武学奇术!$A:$ZZ,27,FALSE)*(1+IF(OR($AG7=$F$4,$AG7=$F$5),$B$21,0)) -> 203 | AJ7: =VLOOKUP($Q7,武学奇术!$A:$ZZ,28,FALSE) -> 1.536 | AK7: =VLOOKUP($Q7,武学奇术!$A:$ZZ,29,FALSE)*(1+IF(OR($AG7=$F$4,$AG7=$F$5),$B$21,0)) -> 0 | AL7: {=$G$3+IFERROR(VLOOKUP($AG7,$F$4:$G$7,2,FALSE),0)+VLOOKUP($Q7,武学奇术!$A:$ZZ,2,FALSE)+SUM(_xlfn.XLOOKUP($R7:$AF7,增益!$A:$A,增益!$B:$B,0))} -> 0.8219 | AM7: {=VLOOKUP($Q7,武学奇术!$A:$ZZ,5,FALSE)+SUM(_xlfn.XLOOKUP($R7:$AF7,增益!$A:$A,增益!$E:$E,0))} -> 0.12 | AN7: {=$D$10*(1+$AM7)+VLOOKUP($Q7,武学奇术!$A:$ZZ,3,FALSE)+SUM(_xlfn.XLOOKUP($R7:$AF7,增益!$A:$A,增益!$C:$C,0))-$I$2} -> 4524.4 | AO7: {=$E$10*(1+$AM7)+VLOOKUP($Q7,武学奇术!$A:$ZZ,4,FALSE)+SUM(_xlfn.XLOOKUP($R7:$AF7,增益!$A:$A,增益!$D:$D,0))-$I$2} -> 4524.4 | AP7: {=IF($F$10-$I$3+VLOOKUP($Q7,武学奇术!$A:$ZZ,6,FALSE)+SUM(_xlfn.XLOOKUP(R7:AF7,增益!$A:$A,增益!$F:$F,0))>0,($F$10-$I$3+VLOOKUP($Q7,武学奇术!$A:$ZZ,6,FALSE)+SUM(_xlfn.XLOOKUP(R7:AF7,增益!$A:$A,增益!$F:$F,0)))/200,($F$10-$I$3+VLOOKUP($Q7,武学奇术!$A:$ZZ,6,FALSE)+SUM(_xlfn.XLOOKUP(R7:AF7,增益!$A:$A,增益!$F:$F,0)))/100)} -> 0.344 | AQ7: {=$G$10+VLOOKUP($Q7,武学奇术!$A:$ZZ,7,FALSE)+SUM(_xlfn.XLOOKUP(R7:AF7,增益!$A:$A,增益!$G:$G,0))} -> 0.04 | AR7: {=VLOOKUP($Q7,武学奇术!$A:$ZZ,8,FALSE)+SUM(_xlfn.XLOOKUP(R7:AF7,增益!$A:$A,增益!$H:$H,0))} -> 0.12 | AS7: =$D$11*(1+$AR7) -> 0 | AT7: =$E$11*(1+$AR7) -> 0 | AU7: {=IF($F$11-$I$4+VLOOKUP($Q7,武学奇术!$A:$ZZ,9,FALSE)+SUM(_xlfn.XLOOKUP(R7:AF7,增益!$A:$A,增益!$I:$I,0))>0,($F$11-$I$4+VLOOKUP($Q7,武学奇术!$A:$ZZ,9,FALSE)+SUM(_xlfn.XLOOKUP(R7:AF7,增益!$A:$A,增益!$I:$I,0)))/200,($F$11-$I$4+VLOOKUP($Q7,武学奇术!$A:$ZZ,9,FALSE)+SUM(_xlfn.XLOOKUP(R7:AF7,增益!$A:$A,增益!$I:$I,0)))/100)} -> -0.14 | AV7: {=$G$11+VLOOKUP($Q7,武学奇术!$A:$ZZ,10,FALSE)+SUM(_xlfn.XLOOKUP(R7:AF7,增益!$A:$A,增益!$J:$J,0))} -> 0.04 | AW7: =$D$12*(1+$AR7) -> 0 | AX7: =$E$12*(1+$AR7) -> 0 | AY7: {=IF($F$12-$I$4+VLOOKUP($Q7,武学奇术!$A:$ZZ,11,FALSE)+SUM(_xlfn.XLOOKUP(R7:AF7,增益!$A:$A,增益!$K:$K,0))>0,($F$12-$I$4+VLOOKUP($Q7,武学奇术!$A:$ZZ,11,FALSE)+SUM(_xlfn.XLOOKUP(R7:AF7,增益!$A:$A,增益!$K:$K,0)))/200,($F$12-$I$4+VLOOKUP($Q7,武学奇术!$A:$ZZ,11,FALSE)+SUM(_xlfn.XLOOKUP(R7:AF7,增益!$A:$A,增益!$K:$K,0)))/100)} -> -0.14 | AZ7: {=$G$12+VLOOKUP($Q7,武学奇术!$A:$ZZ,12,FALSE)+SUM(_xlfn.XLOOKUP(R7:AF7,增益!$A:$A,增益!$L:$L,0))} -> 0.04 | BA7: =$D$13*(1+$AR7) -> 781.088 | BB7: =$E$13*(1+$AR7) -> 2021.6 | BC7: {=IF($F$13-$I$4+VLOOKUP($Q7,武学奇术!$A:$ZZ,13,FALSE)+SUM(_xlfn.XLOOKUP(R7:AF7,增益!$A:$A,增益!$M:$M,0))>0,($F$13-$I$4+VLOOKUP($Q7,武学奇术!$A:$ZZ,13,FALSE)+SUM(_xlfn.XLOOKUP(R7:AF7,增益!$A:$A,增益!$K:$K,0)))/200,($F$13-$I$4+VLOOKUP($Q7,武学奇术!$A:$ZZ,13,FALSE)+SUM(_xlfn.XLOOKUP(R7:AF7,增益!$A:$A,增益!$M:$M,0)))/100)} -> 0.08 | BD7: {=$G$13+VLOOKUP($Q7,武学奇术!$A:$ZZ,14,FALSE)+SUM(_xlfn.XLOOKUP(R7:AF7,增益!$A:$A,增益!$N:$N,0))} -> 0.19 | BE7: =$D$14*(1+$AR7) -> 0 | BF7: =$E$14*(1+$AR7) -> 0 | BG7: {=IF($F$14-$I$4+VLOOKUP($Q7,武学奇术!$A:$ZZ,15,FALSE)+SUM(_xlfn.XLOOKUP(R7:AF7,增益!$A:$A,增益!$O:$O,0))>0,($F$14-$I$4+VLOOKUP($Q7,武学奇术!$A:$ZZ,15,FALSE)+SUM(_xlfn.XLOOKUP(R7:AF7,增益!$A:$A,增益!$O:$O,0)))/200,($F$14-$I$4+VLOOKUP($Q7,武学奇术!$A:$ZZ,15,FALSE)+SUM(_xlfn.XLOOKUP(R7:AF7,增益!$A:$A,增益!$O:$O,0)))/100)} -> -0.14 | BH7: {=$G$14+VLOOKUP($Q7,武学奇术!$A:$ZZ,16,FALSE)+SUM(_xlfn.XLOOKUP(R7:AF7,增益!$A:$A,增益!$P:$P,0))} -> 0.04 | BI7: =MIN(IF(VLOOKUP($Q7,武学奇术!$A:$ZZ,23,FALSE)=1,100%,$B$8),100%) -> 1 | BJ7: {=IF(VLOOKUP($Q7,武学奇术!$A:$ZZ,23,FALSE)=1,100%,MIN(80%,$B$9+VLOOKUP($Q7,武学奇术!$A:$ZZ,17,FALSE)+SUM(_xlfn.XLOOKUP(R7:AF7,增益!$A:$A,增益!$Q:$Q,0)))+$B$11+SUM(_xlfn.XLOOKUP(R7:AF7,增益!$A:$A,增益!$U:$U,0)))*IF(VLOOKUP($Q7,武学奇术!$A:$ZZ,24,FALSE)=1,0,1)} -> 0.892 | BK7: {=1+$B$13+VLOOKUP($Q7,武学奇术!$A:$ZZ,18,FALSE)+SUM(_xlfn.XLOOKUP(R7:AF7,增益!$A:$A,增益!$R:$R,0))} -> 1.75 | BL7: {=IF(VLOOKUP($Q7,武学奇术!$A:$ZZ,24,FALSE)=1,100%,MIN(40%,$B$10+VLOOKUP($Q7,武学奇术!$A:$ZZ,19,FALSE)+SUM(_xlfn.XLOOKUP(R7:AF7,增益!$A:$A,增益!$S:$S,0)))+$B$12+SUM(_xlfn.XLOOKUP(R7:AF7,增益!$A:$A,增益!$V:$V,0)))*IF(VLOOKUP($Q7,武学奇术!$A:$ZZ,23,FALSE)=1,0,1)} -> 0.0913 | BM7: {=1+$B$14+VLOOKUP($Q7,武学奇术!$A:$ZZ,20,FALSE)+SUM(_xlfn.XLOOKUP(R7:AF7,增益!$A:$A,增益!$T:$T,0))} -> 1.35 | BN7: =MIN((1-BL7)*BI7,BI7*BJ7) -> 0.892 | BO7: =1-BL7-BN7-BP7 -> 0.0167 | BP7: =IF(VLOOKUP($Q7,武学奇术!$A:$ZZ,22,FALSE)=1,0,(1-$BI7))*(1-$BL7) -> 0 | BQ7: {=SUM(_xlfn.XLOOKUP(R7:AF7,增益!$A:$A,增益!$W:$W,0))+$I$5} -> 0.11
A8: 精准率 | B8: 1.0029 | C8: 实际属性 | H8: 战斗时间 | I8: 15 | K8: =($L8*$BN8+$M8*$BL8+$N8*$BO8+$O8*$BP8) -> 158654.19 | L8: =((($AN8+$AO8)/2*$AH8+$AI8)*(1+$AP8)*(1+$AQ8)+(($AS8+$AT8)/2*IF($G$1="鸣金",$AJ8,$AH8)+IF($G$1="鸣金",$AK8*1.5,0))*(1+$AU8)*(1+$AV8)+(($AW8+$AX8)/2*IF($G$1="裂石",$AJ8,$AH8)+IF($G$1="裂石",$AK8*1.5,0))*(1+$AY8)*(1+$AZ8)+(($BA8+$BB8)/2*IF($G$1="牵丝",$AJ8,$AH8)+IF($G$1="牵丝",$AK8*1.5,0))*(1+$BC8)*(1+$BD8)+(($BE8+$BF8)/2*IF($G$1="破竹",$AJ8,$AH8)+IF($G$1="破竹",$AK8*1.5,0))*(1+$BG8)*(1+$BH8))*(1+$AL8)*$BK8*$P8*(1+IF(VLOOKUP($Q8,武学奇术!$A:$ZZ,30,FALSE)="蓄力技",#REF!,0))*(1+$BQ8) -> 161722.59 | M8: =(($AO8*$AH8+$AI8)*(1+$AP8)*(1+$AQ8)+($AT8*IF($G$1="鸣金",$AJ8,$AH8)+IF($G$1="鸣金",$AK8*1.5,0))*(1+$AU8)*(1+$AV8)+($AX8*IF($G$1="裂石",$AJ8,$AH8)+IF($G$1="裂石",$AK8*1.5,0))*(1+$AY8)*(1+$AZ8)+($BB8*IF($G$1="牵丝",$AJ8,$AH8)+IF($G$1="牵丝",$AK8*1.5,0))*(1+$BC8)*(1+$BD8)+($BF8*IF($G$1="破竹",$AJ8,$AH8)+IF($G$1="破竹",$AK8*1.5,0))*(1+$BG8)*(1+$BH8))*(1+$AL8)*$BM8*$P8*(1+IF(VLOOKUP($Q8,武学奇术!$A:$ZZ,30,FALSE)="蓄力技",#REF!,0))*(1+$BQ8) -> 140792.38 | N8: =((($AN8+$AO8)/2*$AH8+$AI8)*(1+$AP8)*(1+$AQ8)+(($AS8+$AT8)/2*IF($G$1="鸣金",$AJ8,$AH8)+IF($G$1="鸣金",$AK8*1.5,0))*(1+$AU8)*(1+$AV8)+(($AW8+$AX8)/2*IF($G$1="裂石",$AJ8,$AH8)+IF($G$1="裂石",$AK8*1.5,0))*(1+$AY8)*(1+$AZ8)+(($BA8+$BB8)/2*IF($G$1="牵丝",$AJ8,$AH8)+IF($G$1="牵丝",$AK8*1.5,0))*(1+$BC8)*(1+$BD8)+(($BE8+$BF8)/2*IF($G$1="破竹",$AJ8,$AH8)+IF($G$1="破竹",$AK8*1.5,0))*(1+$BG8)*(1+$BH8))*(1+$AL8)*$P8*(1+IF(VLOOKUP($Q8,武学奇术!$A:$ZZ,30,FALSE)="蓄力技",#REF!,0))*(1+$BQ8) -> 92412.91 | O8: =((($AN8*$AH8+$AI8)*(1+$AP8)*(1+$AQ8)+($AS8*IF($G$1="鸣金",$AJ8,$AH8)+IF($G$1="鸣金",$AK8*1.5,0))*(1+$AU8)*(1+$AV8)+($AW8*IF($G$1="裂石",$AJ8,$AH8)+IF($G$1="裂石",$AK8*1.5,0))*(1+$AY8)*(1+$AZ8)+($BA8*IF($G$1="牵丝",$AJ8,$AH8)+IF($G$1="牵丝",$AK8*1.5,0))*(1+$BC8)*(1+$BD8)+($BE8*IF($G$1="破竹",$AJ8,$AH8)+IF($G$1="破竹",$AK8*1.5,0))*(1+$BG8)*(1+$BH8))*(1+$AL8))*$P8*(1+IF(VLOOKUP($Q8,武学奇术!$A:$ZZ,30,FALSE)="蓄力技",#REF!,0))*(1+$BQ8) -> 80535.17 | P8: 2 | Q8: 太白醉月5 | R8: 惧刃(拐) | S8: 伞增 | T8: 沧海帖10层 | U8: 易水歌5层 | V8: 四时之秋 | W8: N/a | X8: 裁云(拐) | Y8: 离猎(拐) | Z8: 烁鼓(拐) | AA8: 浣花 | AB8: N/a | AC8: N/a | AD8: N/a | AE8: 大卷(30%+) | AF8: 无惧 | AG8: =VLOOKUP($Q8,武学奇术!$A:$ZZ,25,FALSE) -> 单体奇术 | AH8: =VLOOKUP($Q8,武学奇术!$A:$ZZ,26,FALSE) -> 1.7066 | AI8: =VLOOKUP($Q8,武学奇术!$A:$ZZ,27,FALSE)*(1+IF(OR($AG8=$F$4,$AG8=$F$5),$B$21,0)) -> 339 | AJ8: =VLOOKUP($Q8,武学奇术!$A:$ZZ,28,FALSE) -> 2.5599 | AK8: =VLOOKUP($Q8,武学奇术!$A:$ZZ,29,FALSE)*(1+IF(OR($AG8=$F$4,$AG8=$F$5),$B$21,0)) -> 0 | AL8: {=$G$3+IFERROR(VLOOKUP($AG8,$F$4:$G$7,2,FALSE),0)+VLOOKUP($Q8,武学奇术!$A:$ZZ,2,FALSE)+SUM(_xlfn.XLOOKUP($R8:$AF8,增益!$A:$A,增益!$B:$B,0))} -> 1.6219 | AM8: {=VLOOKUP($Q8,武学奇术!$A:$ZZ,5,FALSE)+SUM(_xlfn.XLOOKUP($R8:$AF8,增益!$A:$A,增益!$E:$E,0))} -> 0.12 | AN8: {=$D$10*(1+$AM8)+VLOOKUP($Q8,武学奇术!$A:$ZZ,3,FALSE)+SUM(_xlfn.XLOOKUP($R8:$AF8,增益!$A:$A,增益!$C:$C,0))-$I$2} -> 4524.4 | AO8: {=$E$10*(1+$AM8)+VLOOKUP($Q8,武学奇术!$A:$ZZ,4,FALSE)+SUM(_xlfn.XLOOKUP($R8:$AF8,增益!$A:$A,增益!$D:$D,0))-$I$2} -> 4524.4 | AP8: {=IF($F$10-$I$3+VLOOKUP($Q8,武学奇术!$A:$ZZ,6,FALSE)+SUM(_xlfn.XLOOKUP(R8:AF8,增益!$A:$A,增益!$F:$F,0))>0,($F$10-$I$3+VLOOKUP($Q8,武学奇术!$A:$ZZ,6,FALSE)+SUM(_xlfn.XLOOKUP(R8:AF8,增益!$A:$A,增益!$F:$F,0)))/200,($F$10-$I$3+VLOOKUP($Q8,武学奇术!$A:$ZZ,6,FALSE)+SUM(_xlfn.XLOOKUP(R8:AF8,增益!$A:$A,增益!$F:$F,0)))/100)} -> 0.344 | AQ8: {=$G$10+VLOOKUP($Q8,武学奇术!$A:$ZZ,7,FALSE)+SUM(_xlfn.XLOOKUP(R8:AF8,增益!$A:$A,增益!$G:$G,0))} -> 0.04 | AR8: {=VLOOKUP($Q8,武学奇术!$A:$ZZ,8,FALSE)+SUM(_xlfn.XLOOKUP(R8:AF8,增益!$A:$A,增益!$H:$H,0))} -> 0.12 | AS8: =$D$11*(1+$AR8) -> 0 | AT8: =$E$11*(1+$AR8) -> 0 | AU8: {=IF($F$11-$I$4+VLOOKUP($Q8,武学奇术!$A:$ZZ,9,FALSE)+SUM(_xlfn.XLOOKUP(R8:AF8,增益!$A:$A,增益!$I:$I,0))>0,($F$11-$I$4+VLOOKUP($Q8,武学奇术!$A:$ZZ,9,FALSE)+SUM(_xlfn.XLOOKUP(R8:AF8,增益!$A:$A,增益!$I:$I,0)))/200,($F$11-$I$4+VLOOKUP($Q8,武学奇术!$A:$ZZ,9,FALSE)+SUM(_xlfn.XLOOKUP(R8:AF8,增益!$A:$A,增益!$I:$I,0)))/100)} -> -0.14 | AV8: {=$G$11+VLOOKUP($Q8,武学奇术!$A:$ZZ,10,FALSE)+SUM(_xlfn.XLOOKUP(R8:AF8,增益!$A:$A,增益!$J:$J,0))} -> 0.04 | AW8: =$D$12*(1+$AR8) -> 0 | AX8: =$E$12*(1+$AR8) -> 0 | AY8: {=IF($F$12-$I$4+VLOOKUP($Q8,武学奇术!$A:$ZZ,11,FALSE)+SUM(_xlfn.XLOOKUP(R8:AF8,增益!$A:$A,增益!$K:$K,0))>0,($F$12-$I$4+VLOOKUP($Q8,武学奇术!$A:$ZZ,11,FALSE)+SUM(_xlfn.XLOOKUP(R8:AF8,增益!$A:$A,增益!$K:$K,0)))/200,($F$12-$I$4+VLOOKUP($Q8,武学奇术!$A:$ZZ,11,FALSE)+SUM(_xlfn.XLOOKUP(R8:AF8,增益!$A:$A,增益!$K:$K,0)))/100)} -> -0.14 | AZ8: {=$G$12+VLOOKUP($Q8,武学奇术!$A:$ZZ,12,FALSE)+SUM(_xlfn.XLOOKUP(R8:AF8,增益!$A:$A,增益!$L:$L,0))} -> 0.04 | BA8: =$D$13*(1+$AR8) -> 781.088 | BB8: =$E$13*(1+$AR8) -> 2021.6 | BC8: {=IF($F$13-$I$4+VLOOKUP($Q8,武学奇术!$A:$ZZ,13,FALSE)+SUM(_xlfn.XLOOKUP(R8:AF8,增益!$A:$A,增益!$M:$M,0))>0,($F$13-$I$4+VLOOKUP($Q8,武学奇术!$A:$ZZ,13,FALSE)+SUM(_xlfn.XLOOKUP(R8:AF8,增益!$A:$A,增益!$K:$K,0)))/200,($F$13-$I$4+VLOOKUP($Q8,武学奇术!$A:$ZZ,13,FALSE)+SUM(_xlfn.XLOOKUP(R8:AF8,增益!$A:$A,增益!$M:$M,0)))/100)} -> 0.08 | BD8: {=$G$13+VLOOKUP($Q8,武学奇术!$A:$ZZ,14,FALSE)+SUM(_xlfn.XLOOKUP(R8:AF8,增益!$A:$A,增益!$N:$N,0))} -> 0.19 | BE8: =$D$14*(1+$AR8) -> 0 | BF8: =$E$14*(1+$AR8) -> 0 | BG8: {=IF($F$14-$I$4+VLOOKUP($Q8,武学奇术!$A:$ZZ,15,FALSE)+SUM(_xlfn.XLOOKUP(R8:AF8,增益!$A:$A,增益!$O:$O,0))>0,($F$14-$I$4+VLOOKUP($Q8,武学奇术!$A:$ZZ,15,FALSE)+SUM(_xlfn.XLOOKUP(R8:AF8,增益!$A:$A,增益!$O:$O,0)))/200,($F$14-$I$4+VLOOKUP($Q8,武学奇术!$A:$ZZ,15,FALSE)+SUM(_xlfn.XLOOKUP(R8:AF8,增益!$A:$A,增益!$O:$O,0)))/100)} -> -0.14 | BH8: {=$G$14+VLOOKUP($Q8,武学奇术!$A:$ZZ,16,FALSE)+SUM(_xlfn.XLOOKUP(R8:AF8,增益!$A:$A,增益!$P:$P,0))} -> 0.04 | BI8: =MIN(IF(VLOOKUP($Q8,武学奇术!$A:$ZZ,23,FALSE)=1,100%,$B$8),100%) -> 1 | BJ8: {=IF(VLOOKUP($Q8,武学奇术!$A:$ZZ,23,FALSE)=1,100%,MIN(80%,$B$9+VLOOKUP($Q8,武学奇术!$A:$ZZ,17,FALSE)+SUM(_xlfn.XLOOKUP(R8:AF8,增益!$A:$A,增益!$Q:$Q,0)))+$B$11+SUM(_xlfn.XLOOKUP(R8:AF8,增益!$A:$A,增益!$U:$U,0)))*IF(VLOOKUP($Q8,武学奇术!$A:$ZZ,24,FALSE)=1,0,1)} -> 0.892 | BK8: {=1+$B$13+VLOOKUP($Q8,武学奇术!$A:$ZZ,18,FALSE)+SUM(_xlfn.XLOOKUP(R8:AF8,增益!$A:$A,增益!$R:$R,0))} -> 1.75 | BL8: {=IF(VLOOKUP($Q8,武学奇术!$A:$ZZ,24,FALSE)=1,100%,MIN(40%,$B$10+VLOOKUP($Q8,武学奇术!$A:$ZZ,19,FALSE)+SUM(_xlfn.XLOOKUP(R8:AF8,增益!$A:$A,增益!$S:$S,0)))+$B$12+SUM(_xlfn.XLOOKUP(R8:AF8,增益!$A:$A,增益!$V:$V,0)))*IF(VLOOKUP($Q8,武学奇术!$A:$ZZ,23,FALSE)=1,0,1)} -> 0.0913 | BM8: {=1+$B$14+VLOOKUP($Q8,武学奇术!$A:$ZZ,20,FALSE)+SUM(_xlfn.XLOOKUP(R8:AF8,增益!$A:$A,增益!$T:$T,0))} -> 1.35 | BN8: =MIN((1-BL8)*BI8,BI8*BJ8) -> 0.892 | BO8: =1-BL8-BN8-BP8 -> 0.0167 | BP8: =IF(VLOOKUP($Q8,武学奇术!$A:$ZZ,22,FALSE)=1,0,(1-$BI8))*(1-$BL8) -> 0 | BQ8: {=SUM(_xlfn.XLOOKUP(R8:AF8,增益!$A:$A,增益!$W:$W,0))+$I$5} -> 0.11
A9: 会心率 | B9: 0.7705 | D9: 最小攻击 | E9: 最大攻击 | F9: 穿透 | G9: 伤害加成 | K9: =($L9*$BN9+$M9*$BL9+$N9*$BO9+$O9*$BP9) -> 519703.74 | L9: =((($AN9+$AO9)/2*$AH9+$AI9)*(1+$AP9)*(1+$AQ9)+(($AS9+$AT9)/2*IF($G$1="鸣金",$AJ9,$AH9)+IF($G$1="鸣金",$AK9*1.5,0))*(1+$AU9)*(1+$AV9)+(($AW9+$AX9)/2*IF($G$1="裂石",$AJ9,$AH9)+IF($G$1="裂石",$AK9*1.5,0))*(1+$AY9)*(1+$AZ9)+(($BA9+$BB9)/2*IF($G$1="牵丝",$AJ9,$AH9)+IF($G$1="牵丝",$AK9*1.5,0))*(1+$BC9)*(1+$BD9)+(($BE9+$BF9)/2*IF($G$1="破竹",$AJ9,$AH9)+IF($G$1="破竹",$AK9*1.5,0))*(1+$BG9)*(1+$BH9))*(1+$AL9)*$BK9*$P9*(1+IF(VLOOKUP($Q9,武学奇术!$A:$ZZ,30,FALSE)="蓄力技",#REF!,0))*(1+$BQ9) -> 529754.62 | M9: =(($AO9*$AH9+$AI9)*(1+$AP9)*(1+$AQ9)+($AT9*IF($G$1="鸣金",$AJ9,$AH9)+IF($G$1="鸣金",$AK9*1.5,0))*(1+$AU9)*(1+$AV9)+($AX9*IF($G$1="裂石",$AJ9,$AH9)+IF($G$1="裂石",$AK9*1.5,0))*(1+$AY9)*(1+$AZ9)+($BB9*IF($G$1="牵丝",$AJ9,$AH9)+IF($G$1="牵丝",$AK9*1.5,0))*(1+$BC9)*(1+$BD9)+($BF9*IF($G$1="破竹",$AJ9,$AH9)+IF($G$1="破竹",$AK9*1.5,0))*(1+$BG9)*(1+$BH9))*(1+$AL9)*$BM9*$P9*(1+IF(VLOOKUP($Q9,武学奇术!$A:$ZZ,30,FALSE)="蓄力技",#REF!,0))*(1+$BQ9) -> 461196.62 | N9: =((($AN9+$AO9)/2*$AH9+$AI9)*(1+$AP9)*(1+$AQ9)+(($AS9+$AT9)/2*IF($G$1="鸣金",$AJ9,$AH9)+IF($G$1="鸣金",$AK9*1.5,0))*(1+$AU9)*(1+$AV9)+(($AW9+$AX9)/2*IF($G$1="裂石",$AJ9,$AH9)+IF($G$1="裂石",$AK9*1.5,0))*(1+$AY9)*(1+$AZ9)+(($BA9+$BB9)/2*IF($G$1="牵丝",$AJ9,$AH9)+IF($G$1="牵丝",$AK9*1.5,0))*(1+$BC9)*(1+$BD9)+(($BE9+$BF9)/2*IF($G$1="破竹",$AJ9,$AH9)+IF($G$1="破竹",$AK9*1.5,0))*(1+$BG9)*(1+$BH9))*(1+$AL9)*$P9*(1+IF(VLOOKUP($Q9,武学奇术!$A:$ZZ,30,FALSE)="蓄力技",#REF!,0))*(1+$BQ9) -> 302716.92 | O9: =((($AN9*$AH9+$AI9)*(1+$AP9)*(1+$AQ9)+($AS9*IF($G$1="鸣金",$AJ9,$AH9)+IF($G$1="鸣金",$AK9*1.5,0))*(1+$AU9)*(1+$AV9)+($AW9*IF($G$1="裂石",$AJ9,$AH9)+IF($G$1="裂石",$AK9*1.5,0))*(1+$AY9)*(1+$AZ9)+($BA9*IF($G$1="牵丝",$AJ9,$AH9)+IF($G$1="牵丝",$AK9*1.5,0))*(1+$BC9)*(1+$BD9)+($BE9*IF($G$1="破竹",$AJ9,$AH9)+IF($G$1="破竹",$AK9*1.5,0))*(1+$BG9)*(1+$BH9))*(1+$AL9))*$P9*(1+IF(VLOOKUP($Q9,武学奇术!$A:$ZZ,30,FALSE)="蓄力技",#REF!,0))*(1+$BQ9) -> 263806.72 | P9: 10 | Q9: 太白醉月暗灼 | R9: 惧刃(拐) | S9: 伞增 | T9: 沧海帖10层 | U9: 易水歌5层 | V9: 四时之秋 | W9: N/a | X9: 裁云(拐) | Y9: 离猎(拐) | Z9: 烁鼓(拐) | AA9: 浣花 | AB9: N/a | AC9: N/a | AD9: N/a | AE9: 大卷(30%+) | AF9: 无惧 | AG9: =VLOOKUP($Q9,武学奇术!$A:$ZZ,25,FALSE) -> 单体奇术 | AH9: =VLOOKUP($Q9,武学奇术!$A:$ZZ,26,FALSE) -> 1.6091 | AI9: =VLOOKUP($Q9,武学奇术!$A:$ZZ,27,FALSE)*(1+IF(OR($AG9=$F$4,$AG9=$F$5),$B$21,0)) -> 319 | AJ9: =VLOOKUP($Q9,武学奇术!$A:$ZZ,28,FALSE) -> 2.41365 | AK9: =VLOOKUP($Q9,武学奇术!$A:$ZZ,29,FALSE)*(1+IF(OR($AG9=$F$4,$AG9=$F$5),$B$21,0)) -> 0 | AL9: {=$G$3+IFERROR(VLOOKUP($AG9,$F$4:$G$7,2,FALSE),0)+VLOOKUP($Q9,武学奇术!$A:$ZZ,2,FALSE)+SUM(_xlfn.XLOOKUP($R9:$AF9,增益!$A:$A,增益!$B:$B,0))} -> 0.8219 | AM9: {=VLOOKUP($Q9,武学奇术!$A:$ZZ,5,FALSE)+SUM(_xlfn.XLOOKUP($R9:$AF9,增益!$A:$A,增益!$E:$E,0))} -> 0.12 | AN9: {=$D$10*(1+$AM9)+VLOOKUP($Q9,武学奇术!$A:$ZZ,3,FALSE)+SUM(_xlfn.XLOOKUP($R9:$AF9,增益!$A:$A,增益!$C:$C,0))-$I$2} -> 4524.4 | AO9: {=$E$10*(1+$AM9)+VLOOKUP($Q9,武学奇术!$A:$ZZ,4,FALSE)+SUM(_xlfn.XLOOKUP($R9:$AF9,增益!$A:$A,增益!$D:$D,0))-$I$2} -> 4524.4 | AP9: {=IF($F$10-$I$3+VLOOKUP($Q9,武学奇术!$A:$ZZ,6,FALSE)+SUM(_xlfn.XLOOKUP(R9:AF9,增益!$A:$A,增益!$F:$F,0))>0,($F$10-$I$3+VLOOKUP($Q9,武学奇术!$A:$ZZ,6,FALSE)+SUM(_xlfn.XLOOKUP(R9:AF9,增益!$A:$A,增益!$F:$F,0)))/200,($F$10-$I$3+VLOOKUP($Q9,武学奇术!$A:$ZZ,6,FALSE)+SUM(_xlfn.XLOOKUP(R9:AF9,增益!$A:$A,增益!$F:$F,0)))/100)} -> 0.344 | AQ9: {=$G$10+VLOOKUP($Q9,武学奇术!$A:$ZZ,7,FALSE)+SUM(_xlfn.XLOOKUP(R9:AF9,增益!$A:$A,增益!$G:$G,0))} -> 0.04 | AR9: {=VLOOKUP($Q9,武学奇术!$A:$ZZ,8,FALSE)+SUM(_xlfn.XLOOKUP(R9:AF9,增益!$A:$A,增益!$H:$H,0))} -> 0.12 | AS9: =$D$11*(1+$AR9) -> 0 | AT9: =$E$11*(1+$AR9) -> 0 | AU9: {=IF($F$11-$I$4+VLOOKUP($Q9,武学奇术!$A:$ZZ,9,FALSE)+SUM(_xlfn.XLOOKUP(R9:AF9,增益!$A:$A,增益!$I:$I,0))>0,($F$11-$I$4+VLOOKUP($Q9,武学奇术!$A:$ZZ,9,FALSE)+SUM(_xlfn.XLOOKUP(R9:AF9,增益!$A:$A,增益!$I:$I,0)))/200,($F$11-$I$4+VLOOKUP($Q9,武学奇术!$A:$ZZ,9,FALSE)+SUM(_xlfn.XLOOKUP(R9:AF9,增益!$A:$A,增益!$I:$I,0)))/100)} -> -0.14 | AV9: {=$G$11+VLOOKUP($Q9,武学奇术!$A:$ZZ,10,FALSE)+SUM(_xlfn.XLOOKUP(R9:AF9,增益!$A:$A,增益!$J:$J,0))} -> 0.04 | AW9: =$D$12*(1+$AR9) -> 0 | AX9: =$E$12*(1+$AR9) -> 0 | AY9: {=IF($F$12-$I$4+VLOOKUP($Q9,武学奇术!$A:$ZZ,11,FALSE)+SUM(_xlfn.XLOOKUP(R9:AF9,增益!$A:$A,增益!$K:$K,0))>0,($F$12-$I$4+VLOOKUP($Q9,武学奇术!$A:$ZZ,11,FALSE)+SUM(_xlfn.XLOOKUP(R9:AF9,增益!$A:$A,增益!$K:$K,0)))/200,($F$12-$I$4+VLOOKUP($Q9,武学奇术!$A:$ZZ,11,FALSE)+SUM(_xlfn.XLOOKUP(R9:AF9,增益!$A:$A,增益!$K:$K,0)))/100)} -> -0.14 | AZ9: {=$G$12+VLOOKUP($Q9,武学奇术!$A:$ZZ,12,FALSE)+SUM(_xlfn.XLOOKUP(R9:AF9,增益!$A:$A,增益!$L:$L,0))} -> 0.04 | BA9: =$D$13*(1+$AR9) -> 781.088 | BB9: =$E$13*(1+$AR9) -> 2021.6 | BC9: {=IF($F$13-$I$4+VLOOKUP($Q9,武学奇术!$A:$ZZ,13,FALSE)+SUM(_xlfn.XLOOKUP(R9:AF9,增益!$A:$A,增益!$M:$M,0))>0,($F$13-$I$4+VLOOKUP($Q9,武学奇术!$A:$ZZ,13,FALSE)+SUM(_xlfn.XLOOKUP(R9:AF9,增益!$A:$A,增益!$K:$K,0)))/200,($F$13-$I$4+VLOOKUP($Q9,武学奇术!$A:$ZZ,13,FALSE)+SUM(_xlfn.XLOOKUP(R9:AF9,增益!$A:$A,增益!$M:$M,0)))/100)} -> 0.08 | BD9: {=$G$13+VLOOKUP($Q9,武学奇术!$A:$ZZ,14,FALSE)+SUM(_xlfn.XLOOKUP(R9:AF9,增益!$A:$A,增益!$N:$N,0))} -> 0.19 | BE9: =$D$14*(1+$AR9) -> 0 | BF9: =$E$14*(1+$AR9) -> 0 | BG9: {=IF($F$14-$I$4+VLOOKUP($Q9,武学奇术!$A:$ZZ,15,FALSE)+SUM(_xlfn.XLOOKUP(R9:AF9,增益!$A:$A,增益!$O:$O,0))>0,($F$14-$I$4+VLOOKUP($Q9,武学奇术!$A:$ZZ,15,FALSE)+SUM(_xlfn.XLOOKUP(R9:AF9,增益!$A:$A,增益!$O:$O,0)))/200,($F$14-$I$4+VLOOKUP($Q9,武学奇术!$A:$ZZ,15,FALSE)+SUM(_xlfn.XLOOKUP(R9:AF9,增益!$A:$A,增益!$O:$O,0)))/100)} -> -0.14 | BH9: {=$G$14+VLOOKUP($Q9,武学奇术!$A:$ZZ,16,FALSE)+SUM(_xlfn.XLOOKUP(R9:AF9,增益!$A:$A,增益!$P:$P,0))} -> 0.04 | BI9: =MIN(IF(VLOOKUP($Q9,武学奇术!$A:$ZZ,23,FALSE)=1,100%,$B$8),100%) -> 1 | BJ9: {=IF(VLOOKUP($Q9,武学奇术!$A:$ZZ,23,FALSE)=1,100%,MIN(80%,$B$9+VLOOKUP($Q9,武学奇术!$A:$ZZ,17,FALSE)+SUM(_xlfn.XLOOKUP(R9:AF9,增益!$A:$A,增益!$Q:$Q,0)))+$B$11+SUM(_xlfn.XLOOKUP(R9:AF9,增益!$A:$A,增益!$U:$U,0)))*IF(VLOOKUP($Q9,武学奇术!$A:$ZZ,24,FALSE)=1,0,1)} -> 0.892 | BK9: {=1+$B$13+VLOOKUP($Q9,武学奇术!$A:$ZZ,18,FALSE)+SUM(_xlfn.XLOOKUP(R9:AF9,增益!$A:$A,增益!$R:$R,0))} -> 1.75 | BL9: {=IF(VLOOKUP($Q9,武学奇术!$A:$ZZ,24,FALSE)=1,100%,MIN(40%,$B$10+VLOOKUP($Q9,武学奇术!$A:$ZZ,19,FALSE)+SUM(_xlfn.XLOOKUP(R9:AF9,增益!$A:$A,增益!$S:$S,0)))+$B$12+SUM(_xlfn.XLOOKUP(R9:AF9,增益!$A:$A,增益!$V:$V,0)))*IF(VLOOKUP($Q9,武学奇术!$A:$ZZ,23,FALSE)=1,0,1)} -> 0.0913 | BM9: {=1+$B$14+VLOOKUP($Q9,武学奇术!$A:$ZZ,20,FALSE)+SUM(_xlfn.XLOOKUP(R9:AF9,增益!$A:$A,增益!$T:$T,0))} -> 1.35 | BN9: =MIN((1-BL9)*BI9,BI9*BJ9) -> 0.892 | BO9: =1-BL9-BN9-BP9 -> 0.0167 | BP9: =IF(VLOOKUP($Q9,武学奇术!$A:$ZZ,22,FALSE)=1,0,(1-$BI9))*(1-$BL9) -> 0 | BQ9: {=SUM(_xlfn.XLOOKUP(R9:AF9,增益!$A:$A,增益!$W:$W,0))+$I$5} -> 0.11
A10: 会意率 | B10: 0.0913 | C10: 外功 | D10: =(B2+B22)*IF($G$2="撼天",1.06,1) -> 4560 | E10: =MAX(B2+B22,C2+B23)*IF($G$2="撼天",1.06,1) -> 4560 | F10: =D2 -> 63.8 | G10: =E2 -> 0 | H10: 总伤 | I10: =SUM(K:K) -> 1706440.3 | K10: =($L10*$BN10+$M10*$BL10+$N10*$BO10+$O10*$BP10) -> 112748.16 | L10: =((($AN10+$AO10)/2*$AH10+$AI10)*(1+$AP10)*(1+$AQ10)+(($AS10+$AT10)/2*IF($G$1="鸣金",$AJ10,$AH10)+IF($G$1="鸣金",$AK10*1.5,0))*(1+$AU10)*(1+$AV10)+(($AW10+$AX10)/2*IF($G$1="裂石",$AJ10,$AH10)+IF($G$1="裂石",$AK10*1.5,0))*(1+$AY10)*(1+$AZ10)+(($BA10+$BB10)/2*IF($G$1="牵丝",$AJ10,$AH10)+IF($G$1="牵丝",$AK10*1.5,0))*(1+$BC10)*(1+$BD10)+(($BE10+$BF10)/2*IF($G$1="破竹",$AJ10,$AH10)+IF($G$1="破竹",$AK10*1.5,0))*(1+$BG10)*(1+$BH10))*(1+$AL10)*$BK10*$P10*(1+IF(VLOOKUP($Q10,武学奇术!$A:$ZZ,30,FALSE)="蓄力技",#REF!,0))*(1+$BQ10) -> 114928.8 | M10: =(($AO10*$AH10+$AI10)*(1+$AP10)*(1+$AQ10)+($AT10*IF($G$1="鸣金",$AJ10,$AH10)+IF($G$1="鸣金",$AK10*1.5,0))*(1+$AU10)*(1+$AV10)+($AX10*IF($G$1="裂石",$AJ10,$AH10)+IF($G$1="裂石",$AK10*1.5,0))*(1+$AY10)*(1+$AZ10)+($BB10*IF($G$1="牵丝",$AJ10,$AH10)+IF($G$1="牵丝",$AK10*1.5,0))*(1+$BC10)*(1+$BD10)+($BF10*IF($G$1="破竹",$AJ10,$AH10)+IF($G$1="破竹",$AK10*1.5,0))*(1+$BG10)*(1+$BH10))*(1+$AL10)*$BM10*$P10*(1+IF(VLOOKUP($Q10,武学奇术!$A:$ZZ,30,FALSE)="蓄力技",#REF!,0))*(1+$BQ10) -> 100053.93 | N10: =((($AN10+$AO10)/2*$AH10+$AI10)*(1+$AP10)*(1+$AQ10)+(($AS10+$AT10)/2*IF($G$1="鸣金",$AJ10,$AH10)+IF($G$1="鸣金",$AK10*1.5,0))*(1+$AU10)*(1+$AV10)+(($AW10+$AX10)/2*IF($G$1="裂石",$AJ10,$AH10)+IF($G$1="裂石",$AK10*1.5,0))*(1+$AY10)*(1+$AZ10)+(($BA10+$BB10)/2*IF($G$1="牵丝",$AJ10,$AH10)+IF($G$1="牵丝",$AK10*1.5,0))*(1+$BC10)*(1+$BD10)+(($BE10+$BF10)/2*IF($G$1="破竹",$AJ10,$AH10)+IF($G$1="破竹",$AK10*1.5,0))*(1+$BG10)*(1+$BH10))*(1+$AL10)*$P10*(1+IF(VLOOKUP($Q10,武学奇术!$A:$ZZ,30,FALSE)="蓄力技",#REF!,0))*(1+$BQ10) -> 65673.599 | O10: =((($AN10*$AH10+$AI10)*(1+$AP10)*(1+$AQ10)+($AS10*IF($G$1="鸣金",$AJ10,$AH10)+IF($G$1="鸣金",$AK10*1.5,0))*(1+$AU10)*(1+$AV10)+($AW10*IF($G$1="裂石",$AJ10,$AH10)+IF($G$1="裂石",$AK10*1.5,0))*(1+$AY10)*(1+$AZ10)+($BA10*IF($G$1="牵丝",$AJ10,$AH10)+IF($G$1="牵丝",$AK10*1.5,0))*(1+$BC10)*(1+$BD10)+($BE10*IF($G$1="破竹",$AJ10,$AH10)+IF($G$1="破竹",$AK10*1.5,0))*(1+$BG10)*(1+$BH10))*(1+$AL10))*$P10*(1+IF(VLOOKUP($Q10,武学奇术!$A:$ZZ,30,FALSE)="蓄力技",#REF!,0))*(1+$BQ10) -> 57233.179 | P10: 13 | Q10: 神龙吐火暗灼dot | R10: 惧刃(拐) | S10: 伞增 | T10: 沧海帖10层 | U10: 易水歌5层 | V10: 四时之秋 | W10: 惊神5(拐) | X10: 裁云(拐) | Y10: 离猎(拐) | Z10: 烁鼓(拐) | AA10: 浣花 | AB10: N/a | AC10: N/a | AD10: N/a | AE10: 大卷(30%+) | AF10: 无惧 | AG10: =VLOOKUP($Q10,武学奇术!$A:$ZZ,25,FALSE) -> 单体奇术 | AH10: =VLOOKUP($Q10,武学奇术!$A:$ZZ,26,FALSE) -> 0.2361 | AI10: =VLOOKUP($Q10,武学奇术!$A:$ZZ,27,FALSE)*(1+IF(OR($AG10=$F$4,$AG10=$F$5),$B$21,0)) -> 47 | AJ10: =VLOOKUP($Q10,武学奇术!$A:$ZZ,28,FALSE) -> 0.35415 | AK10: =VLOOKUP($Q10,武学奇术!$A:$ZZ,29,FALSE)*(1+IF(OR($AG10=$F$4,$AG10=$F$5),$B$21,0)) -> 0 | AL10: {=$G$3+IFERROR(VLOOKUP($AG10,$F$4:$G$7,2,FALSE),0)+VLOOKUP($Q10,武学奇术!$A:$ZZ,2,FALSE)+SUM(_xlfn.XLOOKUP($R10:$AF10,增益!$A:$A,增益!$B:$B,0))} -> 1.0719 | AM10: {=VLOOKUP($Q10,武学奇术!$A:$ZZ,5,FALSE)+SUM(_xlfn.XLOOKUP($R10:$AF10,增益!$A:$A,增益!$E:$E,0))} -> 0.12 | AN10: {=$D$10*(1+$AM10)+VLOOKUP($Q10,武学奇术!$A:$ZZ,3,FALSE)+SUM(_xlfn.XLOOKUP($R10:$AF10,增益!$A:$A,增益!$C:$C,0))-$I$2} -> 4524.4 | AO10: {=$E$10*(1+$AM10)+VLOOKUP($Q10,武学奇术!$A:$ZZ,4,FALSE)+SUM(_xlfn.XLOOKUP($R10:$AF10,增益!$A:$A,增益!$D:$D,0))-$I$2} -> 4524.4 | AP10: {=IF($F$10-$I$3+VLOOKUP($Q10,武学奇术!$A:$ZZ,6,FALSE)+SUM(_xlfn.XLOOKUP(R10:AF10,增益!$A:$A,增益!$F:$F,0))>0,($F$10-$I$3+VLOOKUP($Q10,武学奇术!$A:$ZZ,6,FALSE)+SUM(_xlfn.XLOOKUP(R10:AF10,增益!$A:$A,增益!$F:$F,0)))/200,($F$10-$I$3+VLOOKUP($Q10,武学奇术!$A:$ZZ,6,FALSE)+SUM(_xlfn.XLOOKUP(R10:AF10,增益!$A:$A,增益!$F:$F,0)))/100)} -> 0.344 | AQ10: {=$G$10+VLOOKUP($Q10,武学奇术!$A:$ZZ,7,FALSE)+SUM(_xlfn.XLOOKUP(R10:AF10,增益!$A:$A,增益!$G:$G,0))} -> 0.04 | AR10: {=VLOOKUP($Q10,武学奇术!$A:$ZZ,8,FALSE)+SUM(_xlfn.XLOOKUP(R10:AF10,增益!$A:$A,增益!$H:$H,0))} -> 0.12 | AS10: =$D$11*(1+$AR10) -> 0 | AT10: =$E$11*(1+$AR10) -> 0 | AU10: {=IF($F$11-$I$4+VLOOKUP($Q10,武学奇术!$A:$ZZ,9,FALSE)+SUM(_xlfn.XLOOKUP(R10:AF10,增益!$A:$A,增益!$I:$I,0))>0,($F$11-$I$4+VLOOKUP($Q10,武学奇术!$A:$ZZ,9,FALSE)+SUM(_xlfn.XLOOKUP(R10:AF10,增益!$A:$A,增益!$I:$I,0)))/200,($F$11-$I$4+VLOOKUP($Q10,武学奇术!$A:$ZZ,9,FALSE)+SUM(_xlfn.XLOOKUP(R10:AF10,增益!$A:$A,增益!$I:$I,0)))/100)} -> -0.14 | AV10: {=$G$11+VLOOKUP($Q10,武学奇术!$A:$ZZ,10,FALSE)+SUM(_xlfn.XLOOKUP(R10:AF10,增益!$A:$A,增益!$J:$J,0))} -> 0.04 | AW10: =$D$12*(1+$AR10) -> 0 | AX10: =$E$12*(1+$AR10) -> 0 | AY10: {=IF($F$12-$I$4+VLOOKUP($Q10,武学奇术!$A:$ZZ,11,FALSE)+SUM(_xlfn.XLOOKUP(R10:AF10,增益!$A:$A,增益!$K:$K,0))>0,($F$12-$I$4+VLOOKUP($Q10,武学奇术!$A:$ZZ,11,FALSE)+SUM(_xlfn.XLOOKUP(R10:AF10,增益!$A:$A,增益!$K:$K,0)))/200,($F$12-$I$4+VLOOKUP($Q10,武学奇术!$A:$ZZ,11,FALSE)+SUM(_xlfn.XLOOKUP(R10:AF10,增益!$A:$A,增益!$K:$K,0)))/100)} -> -0.14 | AZ10: {=$G$12+VLOOKUP($Q10,武学奇术!$A:$ZZ,12,FALSE)+SUM(_xlfn.XLOOKUP(R10:AF10,增益!$A:$A,增益!$L:$L,0))} -> 0.04 | BA10: =$D$13*(1+$AR10) -> 781.088 | BB10: =$E$13*(1+$AR10) -> 2021.6 | BC10: {=IF($F$13-$I$4+VLOOKUP($Q10,武学奇术!$A:$ZZ,13,FALSE)+SUM(_xlfn.XLOOKUP(R10:AF10,增益!$A:$A,增益!$M:$M,0))>0,($F$13-$I$4+VLOOKUP($Q10,武学奇术!$A:$ZZ,13,FALSE)+SUM(_xlfn.XLOOKUP(R10:AF10,增益!$A:$A,增益!$K:$K,0)))/200,($F$13-$I$4+VLOOKUP($Q10,武学奇术!$A:$ZZ,13,FALSE)+SUM(_xlfn.XLOOKUP(R10:AF10,增益!$A:$A,增益!$M:$M,0)))/100)} -> 0.08 | BD10: {=$G$13+VLOOKUP($Q10,武学奇术!$A:$ZZ,14,FALSE)+SUM(_xlfn.XLOOKUP(R10:AF10,增益!$A:$A,增益!$N:$N,0))} -> 0.19 | BE10: =$D$14*(1+$AR10) -> 0 | BF10: =$E$14*(1+$AR10) -> 0 | BG10: {=IF($F$14-$I$4+VLOOKUP($Q10,武学奇术!$A:$ZZ,15,FALSE)+SUM(_xlfn.XLOOKUP(R10:AF10,增益!$A:$A,增益!$O:$O,0))>0,($F$14-$I$4+VLOOKUP($Q10,武学奇术!$A:$ZZ,15,FALSE)+SUM(_xlfn.XLOOKUP(R10:AF10,增益!$A:$A,增益!$O:$O,0)))/200,($F$14-$I$4+VLOOKUP($Q10,武学奇术!$A:$ZZ,15,FALSE)+SUM(_xlfn.XLOOKUP(R10:AF10,增益!$A:$A,增益!$O:$O,0)))/100)} -> -0.14 | BH10: {=$G$14+VLOOKUP($Q10,武学奇术!$A:$ZZ,16,FALSE)+SUM(_xlfn.XLOOKUP(R10:AF10,增益!$A:$A,增益!$P:$P,0))} -> 0.04 | BI10: =MIN(IF(VLOOKUP($Q10,武学奇术!$A:$ZZ,23,FALSE)=1,100%,$B$8),100%) -> 1 | BJ10: {=IF(VLOOKUP($Q10,武学奇术!$A:$ZZ,23,FALSE)=1,100%,MIN(80%,$B$9+VLOOKUP($Q10,武学奇术!$A:$ZZ,17,FALSE)+SUM(_xlfn.XLOOKUP(R10:AF10,增益!$A:$A,增益!$Q:$Q,0)))+$B$11+SUM(_xlfn.XLOOKUP(R10:AF10,增益!$A:$A,增益!$U:$U,0)))*IF(VLOOKUP($Q10,武学奇术!$A:$ZZ,24,FALSE)=1,0,1)} -> 0.892 | BK10: {=1+$B$13+VLOOKUP($Q10,武学奇术!$A:$ZZ,18,FALSE)+SUM(_xlfn.XLOOKUP(R10:AF10,增益!$A:$A,增益!$R:$R,0))} -> 1.75 | BL10: {=IF(VLOOKUP($Q10,武学奇术!$A:$ZZ,24,FALSE)=1,100%,MIN(40%,$B$10+VLOOKUP($Q10,武学奇术!$A:$ZZ,19,FALSE)+SUM(_xlfn.XLOOKUP(R10:AF10,增益!$A:$A,增益!$S:$S,0)))+$B$12+SUM(_xlfn.XLOOKUP(R10:AF10,增益!$A:$A,增益!$V:$V,0)))*IF(VLOOKUP($Q10,武学奇术!$A:$ZZ,23,FALSE)=1,0,1)} -> 0.0913 | BM10: {=1+$B$14+VLOOKUP($Q10,武学奇术!$A:$ZZ,20,FALSE)+SUM(_xlfn.XLOOKUP(R10:AF10,增益!$A:$A,增益!$T:$T,0))} -> 1.35 | BN10: =MIN((1-BL10)*BI10,BI10*BJ10) -> 0.892 | BO10: =1-BL10-BN10-BP10 -> 0.0167 | BP10: =IF(VLOOKUP($Q10,武学奇术!$A:$ZZ,22,FALSE)=1,0,(1-$BI10))*(1-$BL10) -> 0 | BQ10: {=SUM(_xlfn.XLOOKUP(R10:AF10,增益!$A:$A,增益!$W:$W,0))+$I$5} -> 0.11
