Workbook

Sheet 期望
B1: 最小攻击 | C1: 最大攻击 | D1: 穿透 | E1: 伤害加成 | F1: 武学属性 | G1: 牵丝 | H1: 怪物属性 | K1: 期望 | L1: 会心期望 | M1: 会意期望 | N1: 普通期望 | O1: 擦伤期望 | P1: 次数 | Q1: 技能 | R1: 增益1 | S1: 增益2 | T1: 增益3 | U1: 增益4 | V1: 增益5 | W1: 增益6 | X1: 增益7 | Y1: 增益8 | Z1: 增益9 | AA1: 增益10 | AB1: 增益11 | AC1: 增益12 | AD1: 增益13 | AE1: 增益14 | AF1: 增益15 | AG1: 增益16 | AH1: 增益17 | AI1: 增益18 | AJ1: 增益19 | AK1: 增益20 | AL1: 类型 | AM1: 外功倍率 | AN1: 外攻固伤 | AO1: 属性倍率 | AP1: 属性固伤 | AQ1: 通用增伤 | AR1: 外攻加成 | AS1: 即时小外 | AT1: 即时大外 | AU1: 外穿加成 | AV1: 外伤加成 | AW1: 属攻加成 | AX1: 即时小鸣 | AY1: 即时大鸣 | AZ1: 鸣金穿透 | BA1: 鸣金加成 | BB1: 即时小裂 | BC1: 即时大裂 | BD1: 裂石穿透 | BE1: 裂石加成 | BF1: 即时小牵 | BG1: 即时大牵 | BH1: 牵丝穿透 | BI1: 牵丝加成 | BJ1: 即时小破 | BK1: 即时大破 | BL1: 破竹穿透 | BM1: 破竹加成 | BN1: 生效精准 | BO1: 生效会心 | BP1: 生效会心伤害 | BQ1: 生效会意 | BR1: 生效会意伤害 | BS1: 会心占比 | BT1: 普攻占比 | BU1: 擦伤占比 | BV1: 特殊增伤
A2: 外功 | B2: 3909.8 | C2: 3144.7 | D2: 63.5 | F2: 套装 | G2: 撼天 | H2: 防御 | I2: =620*(1-IF(F17="√",0.06,0)-IF(D20="√",0.04,0)) -> 582.8 | K2: =($L2*$BS2+$M2*$BQ2+$N2*$BT2+$O2*$BU2) -> 20065.445 | L2: =((($AS2+$AT2)/2*$AM2+$AN2)*(1+$AU2)*(1+$AV2)+(($AX2+$AY2)/2*IF($G$1="鸣金",$AO2,$AM2)+IF($G$1="鸣金",$AP2*1.5,0))*(1+$AZ2)*(1+$BA2)+(($BB2+$BC2)/2*IF($G$1="裂石",$AO2,$AM2)+IF($G$1="裂石",$AP2*1.5,0))*(1+$BD2)*(1+$BE2)+(($BF2+$BG2)/2*IF($G$1="牵丝",$AO2,$AM2)+IF($G$1="牵丝",$AP2*1.5,0))*(1+$BH2)*(1+$BI2)+(($BJ2+$BK2)/2*IF($G$1="破竹",$AO2,$AM2)+IF($G$1="破竹",$AP2*1.5,0))*(1+$BL2)*(1+$BM2))*(1+$AQ2)*$BP2*$P2*(1+IF(VLOOKUP($Q2,武学奇术!$A:$ZZ,30,FALSE)="弹道",$B$21,0))*(1+$BV2) -> 20060.873 | M2: =(($AT2*$AM2+$AN2)*(1+$AU2)*(1+$AV2)+($AY2*IF($G$1="鸣金",$AO2,$AM2)+IF($G$1="鸣金",$AP2*1.5,0))*(1+$AZ2)*(1+$BA2)+($BC2*IF($G$1="裂石",$AO2,$AM2)+IF($G$1="裂石",$AP2*1.5,0))*(1+$BD2)*(1+$BE2)+($BG2*IF($G$1="牵丝",$AO2,$AM2)+IF($G$1="牵丝",$AP2*1.5,0))*(1+$BH2)*(1+$BI2)+($BK2*IF($G$1="破竹",$AO2,$AM2)+IF($G$1="破竹",$AP2*1.5,0))*(1+$BL2)*(1+$BM2))*(1+$AQ2)*$BR2*$P2*(1+IF(VLOOKUP($Q2,武学奇术!$A:$ZZ,30,FALSE)="弹道",$B$21,0))*(1+$BV2) -> 20110.093 | N2: =((($AS2+$AT2)/2*$AM2+$AN2)*(1+$AU2)*(1+$AV2)+(($AX2+$AY2)/2*IF($G$1="鸣金",$AO2,$AM2)+IF($G$1="鸣金",$AP2*1.5,0))*(1+$AZ2)*(1+$BA2)+(($BB2+$BC2)/2*IF($G$1="裂石",$AO2,$AM2)+IF($G$1="裂石",$AP2*1.5,0))*(1+$BD2)*(1+$BE2)+(($BF2+$BG2)/2*IF($G$1="牵丝",$AO2,$AM2)+IF($G$1="牵丝",$AP2*1.5,0))*(1+$BH2)*(1+$BI2)+(($BJ2+$BK2)/2*IF($G$1="破竹",$AO2,$AM2)+IF($G$1="破竹",$AP2*1.5,0))*(1+$BL2)*(1+$BM2))*(1+$AQ2)*$P2*(1+IF(VLOOKUP($Q2,武学奇术!$A:$ZZ,30,FALSE)="弹道",$B$21,0))*(1+$BV2) -> 13285.346 | O2: =((($AS2*$AM2+$AN2)*(1+$AU2)*(1+$AV2)+($AX2*IF($G$1="鸣金",$AO2,$AM2)+IF($G$1="鸣金",$AP2*1.5,0))*(1+$AZ2)*(1+$BA2)+($BB2*IF($G$1="裂石",$AO2,$AM2)+IF($G$1="裂石",$AP2*1.5,0))*(1+$BD2)*(1+$BE2)+($BF2*IF($G$1="牵丝",$AO2,$AM2)+IF($G$1="牵丝",$AP2*1.5,0))*(1+$BH2)*(1+$BI2)+($BJ2*IF($G$1="破竹",$AO2,$AM2)+IF($G$1="破竹",$AP2*1.5,0))*(1+$BL2)*(1+$BM2))*(1+$AQ2))*$P2*(1+IF(VLOOKUP($Q2,武学奇术!$A:$ZZ,30,FALSE)="弹道",$B$21,0))*(1+$BV2) -> 11674.328 | P2: 1 | Q2: 萧呤千浪流星 | R2: 易水歌1层 | S2: 沧海帖1层 | T2: N/a | U2: N/a | V2: N/a | W2: N/a | X2: N/a | Y2: N/a | Z2: N/a | AA2: 近战笛 | AB2: N/a | AC2: N/a | AD2: N/a | AE2: N/a | AF2: N/a | AG2: N/a | AH2: N/a | AI2: N/a | AJ2: N/a | AK2: N/a | AL2: =VLOOKUP($Q2,武学奇术!$A:$ZZ,25,FALSE) -> 群体奇术 | AM2: =VLOOKUP($Q2,武学奇术!$A:$ZZ,26,FALSE) -> 1.4904 | AN2: =VLOOKUP($Q2,武学奇术!$A:$ZZ,27,FALSE)*(1+IF(OR($AL2=$F$4,$AL2=$F$5),$B$22,0)) -> 378 | AO2: =VLOOKUP($Q2,武学奇术!$A:$ZZ,28,FALSE) -> 2.2356 | AP2: =VLOOKUP($Q2,武学奇术!$A:$ZZ,29,FALSE)*(1+IF(OR($AL2=$F$4,$AL2=$F$5),$B$22,0)) -> 0 | AQ2: {=$G$3+IFERROR(VLOOKUP($AL2,$F$4:$G$7,2,FALSE),0)+VLOOKUP($Q2,武学奇术!$A:$ZZ,2,FALSE)+SUM(_xlfn.XLOOKUP($R2:$AK2,增益!$A:$A,增益!$B:$B,0))} -> 0.2137 | AR2: {=VLOOKUP($Q2,武学奇术!$A:$ZZ,5,FALSE)+SUM(_xlfn.XLOOKUP($R2:$AK2,增益!$A:$A,增益!$E:$E,0))} -> 0 | AS2: {=$D$10*(1+$AR2)+VLOOKUP($Q2,武学奇术!$A:$ZZ,3,FALSE)+SUM(_xlfn.XLOOKUP($R2:$AK2,增益!$A:$A,增益!$C:$C,0))-$I$2} -> 3773.588 | AT2: {=$E$10*(1+$AR2)+VLOOKUP($Q2,武学奇术!$A:$ZZ,4,FALSE)+SUM(_xlfn.XLOOKUP($R2:$AK2,增益!$A:$A,增益!$D:$D,0))-$I$2} -> 3773.588 | AU2: {=IF($F$10-$I$3+VLOOKUP($Q2,武学奇术!$A:$ZZ,6,FALSE)+SUM(_xlfn.XLOOKUP($R2:$AK2,增益!$A:$A,增益!$F:$F,0))>0,($F$10-$I$3+VLOOKUP($Q2,武学奇术!$A:$ZZ,6,FALSE)+SUM(_xlfn.XLOOKUP($R2:$AK2,增益!$A:$A,增益!$F:$F,0)))/200,($F$10-$I$3+VLOOKUP($Q2,武学奇术!$A:$ZZ,6,FALSE)+SUM(_xlfn.XLOOKUP($R2:$AK2,增益!$A:$A,增益!$F:$F,0)))/100)} -> 0.2525 | AV2: {=$G$10+VLOOKUP($Q2,武学奇术!$A:$ZZ,7,FALSE)+SUM(_xlfn.XLOOKUP($R2:$AK2,增益!$A:$A,增益!$G:$G,0))} -> 0 | AW2: {=VLOOKUP($Q2,武学奇术!$A:$ZZ,8,FALSE)+SUM(_xlfn.XLOOKUP($R2:$AK2,增益!$A:$A,增益!$H:$H,0))} -> 0 | AX2: =$D$11*(1+$AW2) -> 0 | AY2: =$E$11*(1+$AW2) -> 0 | AZ2: {=IF($F$11-$I$4+VLOOKUP($Q2,武学奇术!$A:$ZZ,9,FALSE)+SUM(_xlfn.XLOOKUP($R2:$AK2,增益!$A:$A,增益!$I:$I,0))>0,($F$11-$I$4+VLOOKUP($Q2,武学奇术!$A:$ZZ,9,FALSE)+SUM(_xlfn.XLOOKUP($R2:$AK2,增益!$A:$A,增益!$I:$I,0)))/200,($F$11-$I$4+VLOOKUP($Q2,武学奇术!$A:$ZZ,9,FALSE)+SUM(_xlfn.XLOOKUP($R2:$AK2,增益!$A:$A,增益!$I:$I,0)))/100)} -> -0.3 | BA2: {=$G$11+VLOOKUP($Q2,武学奇术!$A:$ZZ,10,FALSE)+SUM(_xlfn.XLOOKUP($R2:$AK2,增益!$A:$A,增益!$J:$J,0))} -> 0 | BB2: =$D$12*(1+$AW2) -> 0 | BC2: =$E$12*(1+$AW2) -> 0 | BD2: {=IF($F$12-$I$4+VLOOKUP($Q2,武学奇术!$A:$ZZ,11,FALSE)+SUM(_xlfn.XLOOKUP($R2:$AK2,增益!$A:$A,增益!$K:$K,0))>0,($F$12-$I$4+VLOOKUP($Q2,武学奇术!$A:$ZZ,11,FALSE)+SUM(_xlfn.XLOOKUP($R2:$AK2,增益!$A:$A,增益!$K:$K,0)))/200,($F$12-$I$4+VLOOKUP($Q2,武学奇术!$A:$ZZ,11,FALSE)+SUM(_xlfn.XLOOKUP($R2:$AK2,增益!$A:$A,增益!$K:$K,0)))/100)} -> -0.3 | BE2: {=$G$12+VLOOKUP($Q2,武学奇术!$A:$ZZ,12,FALSE)+SUM(_xlfn.XLOOKUP($R2:$AK2,增益!$A:$A,增益!$L:$L,0))} -> 0 | BF2: =$D$13*(1+$AW2) -> 605.472 | BG2: =$E$13*(1+$AW2) -> 1579.612 | BH2: {=IF($F$13-$I$4+VLOOKUP($Q2,武学奇术!$A:$ZZ,13,FALSE)+SUM(_xlfn.XLOOKUP($R2:$AK2,增益!$A:$A,增益!$M:$M,0))>0,($F$13-$I$4+VLOOKUP($Q2,武学奇术!$A:$ZZ,13,FALSE)+SUM(_xlfn.XLOOKUP($R2:$AK2,增益!$A:$A,增益!$K:$K,0)))/200,($F$13-$I$4+VLOOKUP($Q2,武学奇术!$A:$ZZ,13,FALSE)+SUM(_xlfn.XLOOKUP($R2:$AK2,增益!$A:$A,增益!$M:$M,0)))/100)} -> 0 | BI2: {=$G$13+VLOOKUP($Q2,武学奇术!$A:$ZZ,14,FALSE)+SUM(_xlfn.XLOOKUP($R2:$AK2,增益!$A:$A,增益!$N:$N,0))} -> 0.15 | BJ2: =$D$14*(1+$AW2) -> 0 | BK2: =$E$14*(1+$AW2) -> 0 | BL2: {=IF($F$14-$I$4+VLOOKUP($Q2,武学奇术!$A:$ZZ,15,FALSE)+SUM(_xlfn.XLOOKUP($R2:$AK2,增益!$A:$A,增益!$O:$O,0))>0,($F$14-$I$4+VLOOKUP($Q2,武学奇术!$A:$ZZ,15,FALSE)+SUM(_xlfn.XLOOKUP($R2:$AK2,增益!$A:$A,增益!$O:$O,0)))/200,($F$14-$I$4+VLOOKUP($Q2,武学奇术!$A:$ZZ,15,FALSE)+SUM(_xlfn.XLOOKUP($R2:$AK2,增益!$A:$A,增益!$O:$O,0)))/100)} -> -0.3 | BM2: {=$G$14+VLOOKUP($Q2,武学奇术!$A:$ZZ,16,FALSE)+SUM(_xlfn.XLOOKUP($R2:$AK2,增益!$A:$A,增益!$P:$P,0))} -> 0 | BN2: =MIN(IF(VLOOKUP($Q2,武学奇术!$A:$ZZ,23,FALSE)=1,100%,$B$8),100%) -> 1 | BO2: {=IF(VLOOKUP($Q2,武学奇术!$A:$ZZ,23,FALSE)=1,100%,MIN(80%,$B$9+VLOOKUP($Q2,武学奇术!$A:$ZZ,17,FALSE)+SUM(_xlfn.XLOOKUP($R2:$AK2,增益!$A:$A,增益!$Q:$Q,0)))+$B$11+SUM(_xlfn.XLOOKUP($R2:$AK2,增益!$A:$A,增益!$U:$U,0)))*IF(VLOOKUP($Q2,武学奇术!$A:$ZZ,24,FALSE)=1,0,1)} -> 0.9093 | BP2: {=1+$B$13+VLOOKUP($Q2,武学奇术!$A:$ZZ,18,FALSE)+SUM(_xlfn.XLOOKUP($R2:$AK2,增益!$A:$A,增益!$R:$R,0))} -> 1.51 | BQ2: {=IF(VLOOKUP($Q2,武学奇术!$A:$ZZ,24,FALSE)=1,100%,MIN(40%,$B$10+VLOOKUP($Q2,武学奇术!$A:$ZZ,19,FALSE)+SUM(_xlfn.XLOOKUP($R2:$AK2,增益!$A:$A,增益!$S:$S,0)))+$B$12+SUM(_xlfn.XLOOKUP($R2:$AK2,增益!$A:$A,增益!$V:$V,0)))*IF(VLOOKUP($Q2,武学奇术!$A:$ZZ,23,FALSE)=1,0,1)} -> 0.0929 | BR2: {=1+$B$14+VLOOKUP($Q2,武学奇术!$A:$ZZ,20,FALSE)+SUM(_xlfn.XLOOKUP($R2:$AK2,增益!$A:$A,增益!$T:$T,0))} -> 1.35 | BS2: =MIN((1-BQ2)*BN2,BN2*BO2) -> 0.9071 | BT2: =1-BQ2-BS2-BU2 -> 0 | BU2: =IF(VLOOKUP($Q2,武学奇术!$A:$ZZ,22,FALSE)=1,0,(1-$BN2))*(1-$BQ2) -> 0 | BV2: {=SUM(_xlfn.XLOOKUP($R2:$AK2,增益!$A:$A,增益!$W:$W,0))+$I$5} -> 0.06
A3: 鸣金 | F3: 通用增伤 | G3: =B16+1.5%+IF($D$16="√",8%,0)+IF($E$22="征人归",8%,0) -> 0.1837 | H3: 外抗 | I3: =25-IF(D17="√",10,0)-IF(F17="√",10,0) -> 15 | K3: =($L3*$BS3+$M3*$BQ3+$N3*$BT3+$O3*$BU3) -> 20469.385 | L3: =((($AS3+$AT3)/2*$AM3+$AN3)*(1+$AU3)*(1+$AV3)+(($AX3+$AY3)/2*IF($G$1="鸣金",$AO3,$AM3)+IF($G$1="鸣金",$AP3*1.5,0))*(1+$AZ3)*(1+$BA3)+(($BB3+$BC3)/2*IF($G$1="裂石",$AO3,$AM3)+IF($G$1="裂石",$AP3*1.5,0))*(1+$BD3)*(1+$BE3)+(($BF3+$BG3)/2*IF($G$1="牵丝",$AO3,$AM3)+IF($G$1="牵丝",$AP3*1.5,0))*(1+$BH3)*(1+$BI3)+(($BJ3+$BK3)/2*IF($G$1="破竹",$AO3,$AM3)+IF($G$1="破竹",$AP3*1.5,0))*(1+$BL3)*(1+$BM3))*(1+$AQ3)*$BP3*$P3*(1+IF(VLOOKUP($Q3,武学奇术!$A:$ZZ,30,FALSE)="弹道",$B$21,0))*(1+$BV3) -> 20478.448 | M3: =(($AT3*$AM3+$AN3)*(1+$AU3)*(1+$AV3)+($AY3*IF($G$1="鸣金",$AO3,$AM3)+IF($G$1="鸣金",$AP3*1.5,0))*(1+$AZ3)*(1+$BA3)+($BC3*IF($G$1="裂石",$AO3,$AM3)+IF($G$1="裂石",$AP3*1.5,0))*(1+$BD3)*(1+$BE3)+($BG3*IF($G$1="牵丝",$AO3,$AM3)+IF($G$1="牵丝",$AP3*1.5,0))*(1+$BH3)*(1+$BI3)+($BK3*IF($G$1="破竹",$AO3,$AM3)+IF($G$1="破竹",$AP3*1.5,0))*(1+$BL3)*(1+$BM3))*(1+$AQ3)*$BR3*$P3*(1+IF(VLOOKUP($Q3,武学奇术!$A:$ZZ,30,FALSE)="弹道",$B$21,0))*(1+$BV3) -> 20380.89 | N3: =((($AS3+$AT3)/2*$AM3+$AN3)*(1+$AU3)*(1+$AV3)+(($AX3+$AY3)/2*IF($G$1="鸣金",$AO3,$AM3)+IF($G$1="鸣金",$AP3*1.5,0))*(1+$AZ3)*(1+$BA3)+(($BB3+$BC3)/2*IF($G$1="裂石",$AO3,$AM3)+IF($G$1="裂石",$AP3*1.5,0))*(1+$BD3)*(1+$BE3)+(($BF3+$BG3)/2*IF($G$1="牵丝",$AO3,$AM3)+IF($G$1="牵丝",$AP3*1.5,0))*(1+$BH3)*(1+$BI3)+(($BJ3+$BK3)/2*IF($G$1="破竹",$AO3,$AM3)+IF($G$1="破竹",$AP3*1.5,0))*(1+$BL3)*(1+$BM3))*(1+$AQ3)*$P3*(1+IF(VLOOKUP($Q3,武学奇术!$A:$ZZ,30,FALSE)="弹道",$B$21,0))*(1+$BV3) -> 13472.663 | O3: =((($AS3*$AM3+$AN3)*(1+$AU3)*(1+$AV3)+($AX3*IF($G$1="鸣金",$AO3,$AM3)+IF($G$1="鸣金",$AP3*1.5,0))*(1+$AZ3)*(1+$BA3)+($BB3*IF($G$1="裂石",$AO3,$AM3)+IF($G$1="裂石",$AP3*1.5,0))*(1+$BD3)*(1+$BE3)+($BF3*IF($G$1="牵丝",$AO3,$AM3)+IF($G$1="牵丝",$AP3*1.5,0))*(1+$BH3)*(1+$BI3)+($BJ3*IF($G$1="破竹",$AO3,$AM3)+IF($G$1="破竹",$AP3*1.5,0))*(1+$BL3)*(1+$BM3))*(1+$AQ3))*$P3*(1+IF(VLOOKUP($Q3,武学奇术!$A:$ZZ,30,FALSE)="弹道",$B$21,0))*(1+$BV3) -> 11848.371 | P3: 1 | Q3: 萧呤千浪流星 | R3: 易水歌2层 | S3: 沧海帖2层 | T3: N/a | U3: N/a | V3: N/a | W3: N/a | X3: N/a | Y3: N/a | Z3: N/a | AA3: 近战笛 | AB3: 惧刃(拐) | AC3: N/a | AD3: N/a | AE3: N/a | AF3: N/a | AG3: N/a | AH3: N/a | AI3: N/a | AJ3: N/a | AK3: N/a | AL3: =VLOOKUP($Q3,武学奇术!$A:$ZZ,25,FALSE) -> 群体奇术 | AM3: =VLOOKUP($Q3,武学奇术!$A:$ZZ,26,FALSE) -> 1.4904 | AN3: =VLOOKUP($Q3,武学奇术!$A:$ZZ,27,FALSE)*(1+IF(OR($AL3=$F$4,$AL3=$F$5),$B$22,0)) -> 378 | AO3: =VLOOKUP($Q3,武学奇术!$A:$ZZ,28,FALSE) -> 2.2356 | AP3: =VLOOKUP($Q3,武学奇术!$A:$ZZ,29,FALSE)*(1+IF(OR($AL3=$F$4,$AL3=$F$5),$B$22,0)) -> 0 | AQ3: {=$G$3+IFERROR(VLOOKUP($AL3,$F$4:$G$7,2,FALSE),0)+VLOOKUP($Q3,武学奇术!$A:$ZZ,2,FALSE)+SUM(_xlfn.XLOOKUP($R3:$AK3,增益!$A:$A,增益!$B:$B,0))} -> 0.2237 | AR3: {=VLOOKUP($Q3,武学奇术!$A:$ZZ,5,FALSE)+SUM(_xlfn.XLOOKUP($R3:$AK3,增益!$A:$A,增益!$E:$E,0))} -> 0 | AS3: {=$D$10*(1+$AR3)+VLOOKUP($Q3,武学奇术!$A:$ZZ,3,FALSE)+SUM(_xlfn.XLOOKUP($R3:$AK3,增益!$A:$A,增益!$C:$C,0))-$I$2} -> 3773.588 | AT3: {=$E$10*(1+$AR3)+VLOOKUP($Q3,武学奇术!$A:$ZZ,4,FALSE)+SUM(_xlfn.XLOOKUP($R3:$AK3,增益!$A:$A,增益!$D:$D,0))-$I$2} -> 3773.588 | AU3: {=IF($F$10-$I$3+VLOOKUP($Q3,武学奇术!$A:$ZZ,6,FALSE)+SUM(_xlfn.XLOOKUP($R3:$AK3,增益!$A:$A,增益!$F:$F,0))>0,($F$10-$I$3+VLOOKUP($Q3,武学奇术!$A:$ZZ,6,FALSE)+SUM(_xlfn.XLOOKUP($R3:$AK3,增益!$A:$A,增益!$F:$F,0)))/200,($F$10-$I$3+VLOOKUP($Q3,武学奇术!$A:$ZZ,6,FALSE)+SUM(_xlfn.XLOOKUP($R3:$AK3,增益!$A:$A,增益!$F:$F,0)))/100)} -> 0.2625 | AV3: {=$G$10+VLOOKUP($Q3,武学奇术!$A:$ZZ,7,FALSE)+SUM(_xlfn.XLOOKUP($R3:$AK3,增益!$A:$A,增益!$G:$G,0))} -> 0 | AW3: {=VLOOKUP($Q3,武学奇术!$A:$ZZ,8,FALSE)+SUM(_xlfn.XLOOKUP($R3:$AK3,增益!$A:$A,增益!$H:$H,0))} -> 0 | AX3: =$D$11*(1+$AW3) -> 0 | AY3: =$E$11*(1+$AW3) -> 0 | AZ3: {=IF($F$11-$I$4+VLOOKUP($Q3,武学奇术!$A:$ZZ,9,FALSE)+SUM(_xlfn.XLOOKUP($R3:$AK3,增益!$A:$A,增益!$I:$I,0))>0,($F$11-$I$4+VLOOKUP($Q3,武学奇术!$A:$ZZ,9,FALSE)+SUM(_xlfn.XLOOKUP($R3:$AK3,增益!$A:$A,增益!$I:$I,0)))/200,($F$11-$I$4+VLOOKUP($Q3,武学奇术!$A:$ZZ,9,FALSE)+SUM(_xlfn.XLOOKUP($R3:$AK3,增益!$A:$A,增益!$I:$I,0)))/100)} -> -0.3 | BA3: {=$G$11+VLOOKUP($Q3,武学奇术!$A:$ZZ,10,FALSE)+SUM(_xlfn.XLOOKUP($R3:$AK3,增益!$A:$A,增益!$J:$J,0))} -> 0 | BB3: =$D$12*(1+$AW3) -> 0 | BC3: =$E$12*(1+$AW3) -> 0 | BD3: {=IF($F$12-$I$4+VLOOKUP($Q3,武学奇术!$A:$ZZ,11,FALSE)+SUM(_xlfn.XLOOKUP($R3:$AK3,增益!$A:$A,增益!$K:$K,0))>0,($F$12-$I$4+VLOOKUP($Q3,武学奇术!$A:$ZZ,11,FALSE)+SUM(_xlfn.XLOOKUP($R3:$AK3,增益!$A:$A,增益!$K:$K,0)))/200,($F$12-$I$4+VLOOKUP($Q3,武学奇术!$A:$ZZ,11,FALSE)+SUM(_xlfn.XLOOKUP($R3:$AK3,增益!$A:$A,增益!$K:$K,0)))/100)} -> -0.3 | BE3: {=$G$12+VLOOKUP($Q3,武学奇术!$A:$ZZ,12,FALSE)+SUM(_xlfn.XLOOKUP($R3:$AK3,增益!$A:$A,增益!$L:$L,0))} -> 0 | BF3: =$D$13*(1+$AW3) -> 605.472 | BG3: =$E$13*(1+$AW3) -> 1579.612 | BH3: {=IF($F$13-$I$4+VLOOKUP($Q3,武学奇术!$A:$ZZ,13,FALSE)+SUM(_xlfn.XLOOKUP($R3:$AK3,增益!$A:$A,增益!$M:$M,0))>0,($F$13-$I$4+VLOOKUP($Q3,武学奇术!$A:$ZZ,13,FALSE)+SUM(_xlfn.XLOOKUP($R3:$AK3,增益!$A:$A,增益!$K:$K,0)))/200,($F$13-$I$4+VLOOKUP($Q3,武学奇术!$A:$ZZ,13,FALSE)+SUM(_xlfn.XLOOKUP($R3:$AK3,增益!$A:$A,增益!$M:$M,0)))/100)} -> 0 | BI3: {=$G$13+VLOOKUP($Q3,武学奇术!$A:$ZZ,14,FALSE)+SUM(_xlfn.XLOOKUP($R3:$AK3,增益!$A:$A,增益!$N:$N,0))} -> 0.15 | BJ3: =$D$14*(1+$AW3) -> 0 | BK3: =$E$14*(1+$AW3) -> 0 | BL3: {=IF($F$14-$I$4+VLOOKUP($Q3,武学奇术!$A:$ZZ,15,FALSE)+SUM(_xlfn.XLOOKUP($R3:$AK3,增益!$A:$A,增益!$O:$O,0))>0,($F$14-$I$4+VLOOKUP($Q3,武学奇术!$A:$ZZ,15,FALSE)+SUM(_xlfn.XLOOKUP($R3:$AK3,增益!$A:$A,增益!$O:$O,0)))/200,($F$14-$I$4+VLOOKUP($Q3,武学奇术!$A:$ZZ,15,FALSE)+SUM(_xlfn.XLOOKUP($R3:$AK3,增益!$A:$A,增益!$O:$O,0)))/100)} -> -0.3 | BM3: {=$G$14+VLOOKUP($Q3,武学奇术!$A:$ZZ,16,FALSE)+SUM(_xlfn.XLOOKUP($R3:$AK3,增益!$A:$A,增益!$P:$P,0))} -> 0 | BN3: =MIN(IF(VLOOKUP($Q3,武学奇术!$A:$ZZ,23,FALSE)=1,100%,$B$8),100%) -> 1 | BO3: {=IF(VLOOKUP($Q3,武学奇术!$A:$ZZ,23,FALSE)=1,100%,MIN(80%,$B$9+VLOOKUP($Q3,武学奇术!$A:$ZZ,17,FALSE)+SUM(_xlfn.XLOOKUP($R3:$AK3,增益!$A:$A,增益!$Q:$Q,0)))+$B$11+SUM(_xlfn.XLOOKUP($R3:$AK3,增益!$A:$A,增益!$U:$U,0)))*IF(VLOOKUP($Q3,武学奇术!$A:$ZZ,24,FALSE)=1,0,1)} -> 0.9093 | BP3: {=1+$B$13+VLOOKUP($Q3,武学奇术!$A:$ZZ,18,FALSE)+SUM(_xlfn.XLOOKUP($R3:$AK3,增益!$A:$A,增益!$R:$R,0))} -> 1.52 | BQ3: {=IF(VLOOKUP($Q3,武学奇术!$A:$ZZ,24,FALSE)=1,100%,MIN(40%,$B$10+VLOOKUP($Q3,武学奇术!$A:$ZZ,19,FALSE)+SUM(_xlfn.XLOOKUP($R3:$AK3,增益!$A:$A,增益!$S:$S,0)))+$B$12+SUM(_xlfn.XLOOKUP($R3:$AK3,增益!$A:$A,增益!$V:$V,0)))*IF(VLOOKUP($Q3,武学奇术!$A:$ZZ,23,FALSE)=1,0,1)} -> 0.0929 | BR3: {=1+$B$14+VLOOKUP($Q3,武学奇术!$A:$ZZ,20,FALSE)+SUM(_xlfn.XLOOKUP($R3:$AK3,增益!$A:$A,增益!$T:$T,0))} -> 1.35 | BS3: =MIN((1-BQ3)*BN3,BN3*BO3) -> 0.9071 | BT3: =1-BQ3-BS3-BU3 -> 0 | BU3: =IF(VLOOKUP($Q3,武学奇术!$A:$ZZ,22,FALSE)=1,0,(1-$BN3))*(1-$BQ3) -> 0 | BV3: {=SUM(_xlfn.XLOOKUP($R3:$AK3,增益!$A:$A,增益!$W:$W,0))+$I$5} -> 0.06
A4: 裂石 | F4: 伞 | G4: =B15+B17 -> 0.1704 | H4: 属抗 | I4: =30 -> 30 | K4: =($L4*$BS4+$M4*$BQ4+$N4*$BT4+$O4*$BU4) -> 22104.908 | L4: =((($AS4+$AT4)/2*$AM4+$AN4)*(1+$AU4)*(1+$AV4)+(($AX4+$AY4)/2*IF($G$1="鸣金",$AO4,$AM4)+IF($G$1="鸣金",$AP4*1.5,0))*(1+$AZ4)*(1+$BA4)+(($BB4+$BC4)/2*IF($G$1="裂石",$AO4,$AM4)+IF($G$1="裂石",$AP4*1.5,0))*(1+$BD4)*(1+$BE4)+(($BF4+$BG4)/2*IF($G$1="牵丝",$AO4,$AM4)+IF($G$1="牵丝",$AP4*1.5,0))*(1+$BH4)*(1+$BI4)+(($BJ4+$BK4)/2*IF($G$1="破竹",$AO4,$AM4)+IF($G$1="破竹",$AP4*1.5,0))*(1+$BL4)*(1+$BM4))*(1+$AQ4)*$BP4*$P4*(1+IF(VLOOKUP($Q4,武学奇术!$A:$ZZ,30,FALSE)="弹道",$B$21,0))*(1+$BV4) -> 22141.527 | M4: =(($AT4*$AM4+$AN4)*(1+$AU4)*(1+$AV4)+($AY4*IF($G$1="鸣金",$AO4,$AM4)+IF($G$1="鸣金",$AP4*1.5,0))*(1+$AZ4)*(1+$BA4)+($BC4*IF($G$1="裂石",$AO4,$AM4)+IF($G$1="裂石",$AP4*1.5,0))*(1+$BD4)*(1+$BE4)+($BG4*IF($G$1="牵丝",$AO4,$AM4)+IF($G$1="牵丝",$AP4*1.5,0))*(1+$BH4)*(1+$BI4)+($BK4*IF($G$1="破竹",$AO4,$AM4)+IF($G$1="破竹",$AP4*1.5,0))*(1+$BL4)*(1+$BM4))*(1+$AQ4)*$BR4*$P4*(1+IF(VLOOKUP($Q4,武学奇术!$A:$ZZ,30,FALSE)="弹道",$B$21,0))*(1+$BV4) -> 21747.355 | N4: =((($AS4+$AT4)/2*$AM4+$AN4)*(1+$AU4)*(1+$AV4)+(($AX4+$AY4)/2*IF($G$1="鸣金",$AO4,$AM4)+IF($G$1="鸣金",$AP4*1.5,0))*(1+$AZ4)*(1+$BA4)+(($BB4+$BC4)/2*IF($G$1="裂石",$AO4,$AM4)+IF($G$1="裂石",$AP4*1.5,0))*(1+$BD4)*(1+$BE4)+(($BF4+$BG4)/2*IF($G$1="牵丝",$AO4,$AM4)+IF($G$1="牵丝",$AP4*1.5,0))*(1+$BH4)*(1+$BI4)+(($BJ4+$BK4)/2*IF($G$1="破竹",$AO4,$AM4)+IF($G$1="破竹",$AP4*1.5,0))*(1+$BL4)*(1+$BM4))*(1+$AQ4)*$P4*(1+IF(VLOOKUP($Q4,武学奇术!$A:$ZZ,30,FALSE)="弹道",$B$21,0))*(1+$BV4) -> 14471.586 | O4: =((($AS4*$AM4+$AN4)*(1+$AU4)*(1+$AV4)+($AX4*IF($G$1="鸣金",$AO4,$AM4)+IF($G$1="鸣金",$AP4*1.5,0))*(1+$AZ4)*(1+$BA4)+($BB4*IF($G$1="裂石",$AO4,$AM4)+IF($G$1="裂石",$AP4*1.5,0))*(1+$BD4)*(1+$BE4)+($BF4*IF($G$1="牵丝",$AO4,$AM4)+IF($G$1="牵丝",$AP4*1.5,0))*(1+$BH4)*(1+$BI4)+($BJ4*IF($G$1="破竹",$AO4,$AM4)+IF($G$1="破竹",$AP4*1.5,0))*(1+$BL4)*(1+$BM4))*(1+$AQ4))*$P4*(1+IF(VLOOKUP($Q4,武学奇术!$A:$ZZ,30,FALSE)="弹道",$B$21,0))*(1+$BV4) -> 12834.02 | P4: 1 | Q4: 萧呤千浪流星 | R4: 易水歌3层 | S4: 沧海帖3层 | T4: N/a | U4: 小纵地 | V4: N/a | W4: N/a | X4: N/a | Y4: N/a | Z4: N/a | AA4: 近战笛 | AB4: 惧刃(拐) | AC4: N/a | AD4: N/a | AE4: N/a | AF4: N/a | AG4: N/a | AH4: N/a | AI4: N/a | AJ4: N/a | AK4: N/a | AL4: =VLOOKUP($Q4,武学奇术!$A:$ZZ,25,FALSE) -> 群体奇术 | AM4: =VLOOKUP($Q4,武学奇术!$A:$ZZ,26,FALSE) -> 1.4904 | AN4: =VLOOKUP($Q4,武学奇术!$A:$ZZ,27,FALSE)*(1+IF(OR($AL4=$F$4,$AL4=$F$5),$B$22,0)) -> 378 | AO4: =VLOOKUP($Q4,武学奇术!$A:$ZZ,28,FALSE) -> 2.2356 | AP4: =VLOOKUP($Q4,武学奇术!$A:$ZZ,29,FALSE)*(1+IF(OR($AL4=$F$4,$AL4=$F$5),$B$22,0)) -> 0 | AQ4: {=$G$3+IFERROR(VLOOKUP($AL4,$F$4:$G$7,2,FALSE),0)+VLOOKUP($Q4,武学奇术!$A:$ZZ,2,FALSE)+SUM(_xlfn.XLOOKUP($R4:$AK4,增益!$A:$A,增益!$B:$B,0))} -> 0.2337 | AR4: {=VLOOKUP($Q4,武学奇术!$A:$ZZ,5,FALSE)+SUM(_xlfn.XLOOKUP($R4:$AK4,增益!$A:$A,增益!$E:$E,0))} -> 0.075 | AS4: {=$D$10*(1+$AR4)+VLOOKUP($Q4,武学奇术!$A:$ZZ,3,FALSE)+SUM(_xlfn.XLOOKUP($R4:$AK4,增益!$A:$A,增益!$C:$C,0))-$I$2} -> 4100.3171 | AT4: {=$E$10*(1+$AR4)+VLOOKUP($Q4,武学奇术!$A:$ZZ,4,FALSE)+SUM(_xlfn.XLOOKUP($R4:$AK4,增益!$A:$A,增益!$D:$D,0))-$I$2} -> 4100.3171 | AU4: {=IF($F$10-$I$3+VLOOKUP($Q4,武学奇术!$A:$ZZ,6,FALSE)+SUM(_xlfn.XLOOKUP($R4:$AK4,增益!$A:$A,增益!$F:$F,0))>0,($F$10-$I$3+VLOOKUP($Q4,武学奇术!$A:$ZZ,6,FALSE)+SUM(_xlfn.XLOOKUP($R4:$AK4,增益!$A:$A,增益!$F:$F,0)))/200,($F$10-$I$3+VLOOKUP($Q4,武学奇术!$A:$ZZ,6,FALSE)+SUM(_xlfn.XLOOKUP($R4:$AK4,增益!$A:$A,增益!$F:$F,0)))/100)} -> 0.2725 | AV4: {=$G$10+VLOOKUP($Q4,武学奇术!$A:$ZZ,7,FALSE)+SUM(_xlfn.XLOOKUP($R4:$AK4,增益!$A:$A,增益!$G:$G,0))} -> 0 | AW4: {=VLOOKUP($Q4,武学奇术!$A:$ZZ,8,FALSE)+SUM(_xlfn.XLOOKUP($R4:$AK4,增益!$A:$A,增益!$H:$H,0))} -> 0 | AX4: =$D$11*(1+$AW4) -> 0 | AY4: =$E$11*(1+$AW4) -> 0 | AZ4: {=IF($F$11-$I$4+VLOOKUP($Q4,武学奇术!$A:$ZZ,9,FALSE)+SUM(_xlfn.XLOOKUP($R4:$AK4,增益!$A:$A,增益!$I:$I,0))>0,($F$11-$I$4+VLOOKUP($Q4,武学奇术!$A:$ZZ,9,FALSE)+SUM(_xlfn.XLOOKUP($R4:$AK4,增益!$A:$A,增益!$I:$I,0)))/200,($F$11-$I$4+VLOOKUP($Q4,武学奇术!$A:$ZZ,9,FALSE)+SUM(_xlfn.XLOOKUP($R4:$AK4,增益!$A:$A,增益!$I:$I,0)))/100)} -> -0.3 | BA4: {=$G$11+VLOOKUP($Q4,武学奇术!$A:$ZZ,10,FALSE)+SUM(_xlfn.XLOOKUP($R4:$AK4,增益!$A:$A,增益!$J:$J,0))} -> 0 | BB4: =$D$12*(1+$AW4) -> 0 | BC4: =$E$12*(1+$AW4) -> 0 | BD4: {=IF($F$12-$I$4+VLOOKUP($Q4,武学奇术!$A:$ZZ,11,FALSE)+SUM(_xlfn.XLOOKUP($R4:$AK4,增益!$A:$A,增益!$K:$K,0))>0,($F$12-$I$4+VLOOKUP($Q4,武学奇术!$A:$ZZ,11,FALSE)+SUM(_xlfn.XLOOKUP($R4:$AK4,增益!$A:$A,增益!$K:$K,0)))/200,($F$12-$I$4+VLOOKUP($Q4,武学奇术!$A:$ZZ,11,FALSE)+SUM(_xlfn.XLOOKUP($R4:$AK4,增益!$A:$A,增益!$K:$K,0)))/100)} -> -0.3 | BE4: {=$G$12+VLOOKUP($Q4,武学奇术!$A:$ZZ,12,FALSE)+SUM(_xlfn.XLOOKUP($R4:$AK4,增益!$A:$A,增益!$L:$L,0))} -> 0 | BF4: =$D$13*(1+$AW4) -> 605.472 | BG4: =$E$13*(1+$AW4) -> 1579.612 | BH4: {=IF($F$13-$I$4+VLOOKUP($Q4,武学奇术!$A:$ZZ,13,FALSE)+SUM(_xlfn.XLOOKUP($R4:$AK4,增益!$A:$A,增益!$M:$M,0))>0,($F$13-$I$4+VLOOKUP($Q4,武学奇术!$A:$ZZ,13,FALSE)+SUM(_xlfn.XLOOKUP($R4:$AK4,增益!$A:$A,增益!$K:$K,0)))/200,($F$13-$I$4+VLOOKUP($Q4,武学奇术!$A:$ZZ,13,FALSE)+SUM(_xlfn.XLOOKUP($R4:$AK4,增益!$A:$A,增益!$M:$M,0)))/100)} -> 0 | BI4: {=$G$13+VLOOKUP($Q4,武学奇术!$A:$ZZ,14,FALSE)+SUM(_xlfn.XLOOKUP($R4:$AK4,增益!$A:$A,增益!$N:$N,0))} -> 0.15 | BJ4: =$D$14*(1+$AW4) -> 0 | BK4: =$E$14*(1+$AW4) -> 0 | BL4: {=IF($F$14-$I$4+VLOOKUP($Q4,武学奇术!$A:$ZZ,15,FALSE)+SUM(_xlfn.XLOOKUP($R4:$AK4,增益!$A:$A,增益!$O:$O,0))>0,($F$14-$I$4+VLOOKUP($Q4,武学奇术!$A:$ZZ,15,FALSE)+SUM(_xlfn.XLOOKUP($R4:$AK4,增益!$A:$A,增益!$O:$O,0)))/200,($F$14-$I$4+VLOOKUP($Q4,武学奇术!$A:$ZZ,15,FALSE)+SUM(_xlfn.XLOOKUP($R4:$AK4,增益!$A:$A,增益!$O:$O,0)))/100)} -> -0.3 | BM4: {=$G$14+VLOOKUP($Q4,武学奇术!$A:$ZZ,16,FALSE)+SUM(_xlfn.XLOOKUP($R4:$AK4,增益!$A:$A,增益!$P:$P,0))} -> 0 | BN4: =MIN(IF(VLOOKUP($Q4,武学奇术!$A:$ZZ,23,FALSE)=1,100%,$B$8),100%) -> 1 | BO4: {=IF(VLOOKUP($Q4,武学奇术!$A:$ZZ,23,FALSE)=1,100%,MIN(80%,$B$9+VLOOKUP($Q4,武学奇术!$A:$ZZ,17,FALSE)+SUM(_xlfn.XLOOKUP($R4:$AK4,增益!$A:$A,增益!$Q:$Q,0)))+$B$11+SUM(_xlfn.XLOOKUP($R4:$AK4,增益!$A:$A,增益!$U:$U,0)))*IF(VLOOKUP($Q4,武学奇术!$A:$ZZ,24,FALSE)=1,0,1)} -> 0.9093 | BP4: {=1+$B$13+VLOOKUP($Q4,武学奇术!$A:$ZZ,18,FALSE)+SUM(_xlfn.XLOOKUP($R4:$AK4,增益!$A:$A,增益!$R:$R,0))} -> 1.53 | BQ4: {=IF(VLOOKUP($Q4,武学奇术!$A:$ZZ,24,FALSE)=1,100%,MIN(40%,$B$10+VLOOKUP($Q4,武学奇术!$A:$ZZ,19,FALSE)+SUM(_xlfn.XLOOKUP($R4:$AK4,增益!$A:$A,增益!$S:$S,0)))+$B$12+SUM(_xlfn.XLOOKUP($R4:$AK4,增益!$A:$A,增益!$V:$V,0)))*IF(VLOOKUP($Q4,武学奇术!$A:$ZZ,23,FALSE)=1,0,1)} -> 0.0929 | BR4: {=1+$B$14+VLOOKUP($Q4,武学奇术!$A:$ZZ,20,FALSE)+SUM(_xlfn.XLOOKUP($R4:$AK4,增益!$A:$A,增益!$T:$T,0))} -> 1.35 | BS4: =MIN((1-BQ4)*BN4,BN4*BO4) -> 0.9071 | BT4: =1-BQ4-BS4-BU4 -> 0 | BU4: =IF(VLOOKUP($Q4,武学奇术!$A:$ZZ,22,FALSE)=1,0,(1-$BN4))*(1-$BQ4) -> 0 | BV4: {=SUM(_xlfn.XLOOKUP($R4:$AK4,增益!$A:$A,增益!$W:$W,0))+$I$5} -> 0.06
A5: 牵丝 | B5: 492 | C5: 1260.2 | D5: 30 | E5: 0.15 | F5: 扇 | G5: =B15+B18 -> 0.0852 | H5: 副本天赋 | I5: 0.06 | K5: =($L5*$BS5+$M5*$BQ5+$N5*$BT5+$O5*$BU5) -> 22546.653 | L5: =((($AS5+$AT5)/2*$AM5+$AN5)*(1+$AU5)*(1+$AV5)+(($AX5+$AY5)/2*IF($G$1="鸣金",$AO5,$AM5)+IF($G$1="鸣金",$AP5*1.5,0))*(1+$AZ5)*(1+$BA5)+(($BB5+$BC5)/2*IF($G$1="裂石",$AO5,$AM5)+IF($G$1="裂石",$AP5*1.5,0))*(1+$BD5)*(1+$BE5)+(($BF5+$BG5)/2*IF($G$1="牵丝",$AO5,$AM5)+IF($G$1="牵丝",$AP5*1.5,0))*(1+$BH5)*(1+$BI5)+(($BJ5+$BK5)/2*IF($G$1="破竹",$AO5,$AM5)+IF($G$1="破竹",$AP5*1.5,0))*(1+$BL5)*(1+$BM5))*(1+$AQ5)*$BP5*$P5*(1+IF(VLOOKUP($Q5,武学奇术!$A:$ZZ,30,FALSE)="弹道",$B$21,0))*(1+$BV5) -> 22598.631 | M5: =(($AT5*$AM5+$AN5)*(1+$AU5)*(1+$AV5)+($AY5*IF($G$1="鸣金",$AO5,$AM5)+IF($G$1="鸣金",$AP5*1.5,0))*(1+$AZ5)*(1+$BA5)+($BC5*IF($G$1="裂石",$AO5,$AM5)+IF($G$1="裂石",$AP5*1.5,0))*(1+$BD5)*(1+$BE5)+($BG5*IF($G$1="牵丝",$AO5,$AM5)+IF($G$1="牵丝",$AP5*1.5,0))*(1+$BH5)*(1+$BI5)+($BK5*IF($G$1="破竹",$AO5,$AM5)+IF($G$1="破竹",$AP5*1.5,0))*(1+$BL5)*(1+$BM5))*(1+$AQ5)*$BR5*$P5*(1+IF(VLOOKUP($Q5,武学奇术!$A:$ZZ,30,FALSE)="弹道",$B$21,0))*(1+$BV5) -> 22039.121 | N5: =((($AS5+$AT5)/2*$AM5+$AN5)*(1+$AU5)*(1+$AV5)+(($AX5+$AY5)/2*IF($G$1="鸣金",$AO5,$AM5)+IF($G$1="鸣金",$AP5*1.5,0))*(1+$AZ5)*(1+$BA5)+(($BB5+$BC5)/2*IF($G$1="裂石",$AO5,$AM5)+IF($G$1="裂石",$AP5*1.5,0))*(1+$BD5)*(1+$BE5)+(($BF5+$BG5)/2*IF($G$1="牵丝",$AO5,$AM5)+IF($G$1="牵丝",$AP5*1.5,0))*(1+$BH5)*(1+$BI5)+(($BJ5+$BK5)/2*IF($G$1="破竹",$AO5,$AM5)+IF($G$1="破竹",$AP5*1.5,0))*(1+$BL5)*(1+$BM5))*(1+$AQ5)*$P5*(1+IF(VLOOKUP($Q5,武学奇术!$A:$ZZ,30,FALSE)="弹道",$B$21,0))*(1+$BV5) -> 14674.436 | O5: =((($AS5*$AM5+$AN5)*(1+$AU5)*(1+$AV5)+($AX5*IF($G$1="鸣金",$AO5,$AM5)+IF($G$1="鸣金",$AP5*1.5,0))*(1+$AZ5)*(1+$BA5)+($BB5*IF($G$1="裂石",$AO5,$AM5)+IF($G$1="裂石",$AP5*1.5,0))*(1+$BD5)*(1+$BE5)+($BF5*IF($G$1="牵丝",$AO5,$AM5)+IF($G$1="牵丝",$AP5*1.5,0))*(1+$BH5)*(1+$BI5)+($BJ5*IF($G$1="破竹",$AO5,$AM5)+IF($G$1="破竹",$AP5*1.5,0))*(1+$BL5)*(1+$BM5))*(1+$AQ5))*$P5*(1+IF(VLOOKUP($Q5,武学奇术!$A:$ZZ,30,FALSE)="弹道",$B$21,0))*(1+$BV5) -> 13023.596 | P5: 1 | Q5: 萧呤千浪流星 | R5: 易水歌4层 | S5: 沧海帖4层 | T5: N/a | U5: 小纵地 | V5: N/a | W5: N/a | X5: N/a | Y5: N/a | Z5: N/a | AA5: 近战笛 | AB5: 惧刃(拐) | AC5: N/a | AD5: N/a | AE5: N/a | AF5: N/a | AG5: N/a | AH5: N/a | AI5: N/a | AJ5: N/a | AK5: N/a | AL5: =VLOOKUP($Q5,武学奇术!$A:$ZZ,25,FALSE) -> 群体奇术 | AM5: =VLOOKUP($Q5,武学奇术!$A:$ZZ,26,FALSE) -> 1.4904 | AN5: =VLOOKUP($Q5,武学奇术!$A:$ZZ,27,FALSE)*(1+IF(OR($AL5=$F$4,$AL5=$F$5),$B$22,0)) -> 378 | AO5: =VLOOKUP($Q5,武学奇术!$A:$ZZ,28,FALSE) -> 2.2356 | AP5: =VLOOKUP($Q5,武学奇术!$A:$ZZ,29,FALSE)*(1+IF(OR($AL5=$F$4,$AL5=$F$5),$B$22,0)) -> 0 | AQ5: {=$G$3+IFERROR(VLOOKUP($AL5,$F$4:$G$7,2,FALSE),0)+VLOOKUP($Q5,武学奇术!$A:$ZZ,2,FALSE)+SUM(_xlfn.XLOOKUP($R5:$AK5,增益!$A:$A,增益!$B:$B,0))} -> 0.2437 | AR5: {=VLOOKUP($Q5,武学奇术!$A:$ZZ,5,FALSE)+SUM(_xlfn.XLOOKUP($R5:$AK5,增益!$A:$A,增益!$E:$E,0))} -> 0.075 | AS5: {=$D$10*(1+$AR5)+VLOOKUP($Q5,武学奇术!$A:$ZZ,3,FALSE)+SUM(_xlfn.XLOOKUP($R5:$AK5,增益!$A:$A,增益!$C:$C,0))-$I$2} -> 4100.3171 | AT5: {=$E$10*(1+$AR5)+VLOOKUP($Q5,武学奇术!$A:$ZZ,4,FALSE)+SUM(_xlfn.XLOOKUP($R5:$AK5,增益!$A:$A,增益!$D:$D,0))-$I$2} -> 4100.3171 | AU5: {=IF($F$10-$I$3+VLOOKUP($Q5,武学奇术!$A:$ZZ,6,FALSE)+SUM(_xlfn.XLOOKUP($R5:$AK5,增益!$A:$A,增益!$F:$F,0))>0,($F$10-$I$3+VLOOKUP($Q5,武学奇术!$A:$ZZ,6,FALSE)+SUM(_xlfn.XLOOKUP($R5:$AK5,增益!$A:$A,增益!$F:$F,0)))/200,($F$10-$I$3+VLOOKUP($Q5,武学奇术!$A:$ZZ,6,FALSE)+SUM(_xlfn.XLOOKUP($R5:$AK5,增益!$A:$A,增益!$F:$F,0)))/100)} -> 0.2825 | AV5: {=$G$10+VLOOKUP($Q5,武学奇术!$A:$ZZ,7,FALSE)+SUM(_xlfn.XLOOKUP($R5:$AK5,增益!$A:$A,增益!$G:$G,0))} -> 0 | AW5: {=VLOOKUP($Q5,武学奇术!$A:$ZZ,8,FALSE)+SUM(_xlfn.XLOOKUP($R5:$AK5,增益!$A:$A,增益!$H:$H,0))} -> 0 | AX5: =$D$11*(1+$AW5) -> 0 | AY5: =$E$11*(1+$AW5) -> 0 | AZ5: {=IF($F$11-$I$4+VLOOKUP($Q5,武学奇术!$A:$ZZ,9,FALSE)+SUM(_xlfn.XLOOKUP($R5:$AK5,增益!$A:$A,增益!$I:$I,0))>0,($F$11-$I$4+VLOOKUP($Q5,武学奇术!$A:$ZZ,9,FALSE)+SUM(_xlfn.XLOOKUP($R5:$AK5,增益!$A:$A,增益!$I:$I,0)))/200,($F$11-$I$4+VLOOKUP($Q5,武学奇术!$A:$ZZ,9,FALSE)+SUM(_xlfn.XLOOKUP($R5:$AK5,增益!$A:$A,增益!$I:$I,0)))/100)} -> -0.3 | BA5: {=$G$11+VLOOKUP($Q5,武学奇术!$A:$ZZ,10,FALSE)+SUM(_xlfn.XLOOKUP($R5:$AK5,增益!$A:$A,增益!$J:$J,0))} -> 0 | BB5: =$D$12*(1+$AW5) -> 0 | BC5: =$E$12*(1+$AW5) -> 0 | BD5: {=IF($F$12-$I$4+VLOOKUP($Q5,武学奇术!$A:$ZZ,11,FALSE)+SUM(_xlfn.XLOOKUP($R5:$AK5,增益!$A:$A,增益!$K:$K,0))>0,($F$12-$I$4+VLOOKUP($Q5,武学奇术!$A:$ZZ,11,FALSE)+SUM(_xlfn.XLOOKUP($R5:$AK5,增益!$A:$A,增益!$K:$K,0)))/200,($F$12-$I$4+VLOOKUP($Q5,武学奇术!$A:$ZZ,11,FALSE)+SUM(_xlfn.XLOOKUP($R5:$AK5,增益!$A:$A,增益!$K:$K,0)))/100)} -> -0.3 | BE5: {=$G$12+VLOOKUP($Q5,武学奇术!$A:$ZZ,12,FALSE)+SUM(_xlfn.XLOOKUP($R5:$AK5,增益!$A:$A,增益!$L:$L,0))} -> 0 | BF5: =$D$13*(1+$AW5) -> 605.472 | BG5: =$E$13*(1+$AW5) -> 1579.612 | BH5: {=IF($F$13-$I$4+VLOOKUP($Q5,武学奇术!$A:$ZZ,13,FALSE)+SUM(_xlfn.XLOOKUP($R5:$AK5,增益!$A:$A,增益!$M:$M,0))>0,($F$13-$I$4+VLOOKUP($Q5,武学奇术!$A:$ZZ,13,FALSE)+SUM(_xlfn.XLOOKUP($R5:$AK5,增益!$A:$A,增益!$K:$K,0)))/200,($F$13-$I$4+VLOOKUP($Q5,武学奇术!$A:$ZZ,13,FALSE)+SUM(_xlfn.XLOOKUP($R5:$AK5,增益!$A:$A,增益!$M:$M,0)))/100)} -> 0 | BI5: {=$G$13+VLOOKUP($Q5,武学奇术!$A:$ZZ,14,FALSE)+SUM(_xlfn.XLOOKUP($R5:$AK5,增益!$A:$A,增益!$N:$N,0))} -> 0.15 | BJ5: =$D$14*(1+$AW5) -> 0 | BK5: =$E$14*(1+$AW5) -> 0 | BL5: {=IF($F$14-$I$4+VLOOKUP($Q5,武学奇术!$A:$ZZ,15,FALSE)+SUM(_xlfn.XLOOKUP($R5:$AK5,增益!$A:$A,增益!$O:$O,0))>0,($F$14-$I$4+VLOOKUP($Q5,武学奇术!$A:$ZZ,15,FALSE)+SUM(_xlfn.XLOOKUP($R5:$AK5,增益!$A:$A,增益!$O:$O,0)))/200,($F$14-$I$4+VLOOKUP($Q5,武学奇术!$A:$ZZ,15,FALSE)+SUM(_xlfn.XLOOKUP($R5:$AK5,增益!$A:$A,增益!$O:$O,0)))/100)} -> -0.3 | BM5: {=$G$14+VLOOKUP($Q5,武学奇术!$A:$ZZ,16,FALSE)+SUM(_xlfn.XLOOKUP($R5:$AK5,增益!$A:$A,增益!$P:$P,0))} -> 0 | BN5: =MIN(IF(VLOOKUP($Q5,武学奇术!$A:$ZZ,23,FALSE)=1,100%,$B$8),100%) -> 1 | BO5: {=IF(VLOOKUP($Q5,武学奇术!$A:$ZZ,23,FALSE)=1,100%,MIN(80%,$B$9+VLOOKUP($Q5,武学奇术!$A:$ZZ,17,FALSE)+SUM(_xlfn.XLOOKUP($R5:$AK5,增益!$A:$A,增益!$Q:$Q,0)))+$B$11+SUM(_xlfn.XLOOKUP($R5:$AK5,增益!$A:$A,增益!$U:$U,0)))*IF(VLOOKUP($Q5,武学奇术!$A:$ZZ,24,FALSE)=1,0,1)} -> 0.9093 | BP5: {=1+$B$13+VLOOKUP($Q5,武学奇术!$A:$ZZ,18,FALSE)+SUM(_xlfn.XLOOKUP($R5:$AK5,增益!$A:$A,增益!$R:$R,0))} -> 1.54 | BQ5: {=IF(VLOOKUP($Q5,武学奇术!$A:$ZZ,24,FALSE)=1,100%,MIN(40%,$B$10+VLOOKUP($Q5,武学奇术!$A:$ZZ,19,FALSE)+SUM(_xlfn.XLOOKUP($R5:$AK5,增益!$A:$A,增益!$S:$S,0)))+$B$12+SUM(_xlfn.XLOOKUP($R5:$AK5,增益!$A:$A,增益!$V:$V,0)))*IF(VLOOKUP($Q5,武学奇术!$A:$ZZ,23,FALSE)=1,0,1)} -> 0.0929 | BR5: {=1+$B$14+VLOOKUP($Q5,武学奇术!$A:$ZZ,20,FALSE)+SUM(_xlfn.XLOOKUP($R5:$AK5,增益!$A:$A,增益!$T:$T,0))} -> 1.35 | BS5: =MIN((1-BQ5)*BN5,BN5*BO5) -> 0.9071 | BT5: =1-BQ5-BS5-BU5 -> 0 | BU5: =IF(VLOOKUP($Q5,武学奇术!$A:$ZZ,22,FALSE)=1,0,(1-$BN5))*(1-$BQ5) -> 0 | BV5: {=SUM(_xlfn.XLOOKUP($R5:$AK5,增益!$A:$A,增益!$W:$W,0))+$I$5} -> 0.06
A6: 破竹 | F6: 单体奇术 | G6: =B19 -> 0.2678 | K6: =($L6*$BS6+$M6*$BQ6+$N6*$BT6+$O6*$BU6) -> 22994.184 | L6: =((($AS6+$AT6)/2*$AM6+$AN6)*(1+$AU6)*(1+$AV6)+(($AX6+$AY6)/2*IF($G$1="鸣金",$AO6,$AM6)+IF($G$1="鸣金",$AP6*1.5,0))*(1+$AZ6)*(1+$BA6)+(($BB6+$BC6)/2*IF($G$1="裂石",$AO6,$AM6)+IF($G$1="裂石",$AP6*1.5,0))*(1+$BD6)*(1+$BE6)+(($BF6+$BG6)/2*IF($G$1="牵丝",$AO6,$AM6)+IF($G$1="牵丝",$AP6*1.5,0))*(1+$BH6)*(1+$BI6)+(($BJ6+$BK6)/2*IF($G$1="破竹",$AO6,$AM6)+IF($G$1="破竹",$AP6*1.5,0))*(1+$BL6)*(1+$BM6))*(1+$AQ6)*$BP6*$P6*(1+IF(VLOOKUP($Q6,武学奇术!$A:$ZZ,30,FALSE)="弹道",$B$21,0))*(1+$BV6) -> 23061.925 | M6: =(($AT6*$AM6+$AN6)*(1+$AU6)*(1+$AV6)+($AY6*IF($G$1="鸣金",$AO6,$AM6)+IF($G$1="鸣金",$AP6*1.5,0))*(1+$AZ6)*(1+$BA6)+($BC6*IF($G$1="裂石",$AO6,$AM6)+IF($G$1="裂石",$AP6*1.5,0))*(1+$BD6)*(1+$BE6)+($BG6*IF($G$1="牵丝",$AO6,$AM6)+IF($G$1="牵丝",$AP6*1.5,0))*(1+$BH6)*(1+$BI6)+($BK6*IF($G$1="破竹",$AO6,$AM6)+IF($G$1="破竹",$AP6*1.5,0))*(1+$BL6)*(1+$BM6))*(1+$AQ6)*$BR6*$P6*(1+IF(VLOOKUP($Q6,武学奇术!$A:$ZZ,30,FALSE)="弹道",$B$21,0))*(1+$BV6) -> 22332.745 | N6: =((($AS6+$AT6)/2*$AM6+$AN6)*(1+$AU6)*(1+$AV6)+(($AX6+$AY6)/2*IF($G$1="鸣金",$AO6,$AM6)+IF($G$1="鸣金",$AP6*1.5,0))*(1+$AZ6)*(1+$BA6)+(($BB6+$BC6)/2*IF($G$1="裂石",$AO6,$AM6)+IF($G$1="裂石",$AP6*1.5,0))*(1+$BD6)*(1+$BE6)+(($BF6+$BG6)/2*IF($G$1="牵丝",$AO6,$AM6)+IF($G$1="牵丝",$AP6*1.5,0))*(1+$BH6)*(1+$BI6)+(($BJ6+$BK6)/2*IF($G$1="破竹",$AO6,$AM6)+IF($G$1="破竹",$AP6*1.5,0))*(1+$BL6)*(1+$BM6))*(1+$AQ6)*$P6*(1+IF(VLOOKUP($Q6,武学奇术!$A:$ZZ,30,FALSE)="弹道",$B$21,0))*(1+$BV6) -> 14878.661 | O6: =((($AS6*$AM6+$AN6)*(1+$AU6)*(1+$AV6)+($AX6*IF($G$1="鸣金",$AO6,$AM6)+IF($G$1="鸣金",$AP6*1.5,0))*(1+$AZ6)*(1+$BA6)+($BB6*IF($G$1="裂石",$AO6,$AM6)+IF($G$1="裂石",$AP6*1.5,0))*(1+$BD6)*(1+$BE6)+($BF6*IF($G$1="牵丝",$AO6,$AM6)+IF($G$1="牵丝",$AP6*1.5,0))*(1+$BH6)*(1+$BI6)+($BJ6*IF($G$1="破竹",$AO6,$AM6)+IF($G$1="破竹",$AP6*1.5,0))*(1+$BL6)*(1+$BM6))*(1+$AQ6))*$P6*(1+IF(VLOOKUP($Q6,武学奇术!$A:$ZZ,30,FALSE)="弹道",$B$21,0))*(1+$BV6) -> 13214.548 | P6: 1 | Q6: 萧呤千浪流星 | R6: 易水歌5层 | S6: 沧海帖5层 | T6: N/a | U6: 小纵地 | V6: N/a | W6: N/a | X6: N/a | Y6: N/a | Z6: N/a | AA6: 近战笛 | AB6: 惧刃(拐) | AC6: N/a | AD6: N/a | AE6: N/a | AF6: N/a | AG6: N/a | AH6: N/a | AI6: N/a | AJ6: N/a | AK6: N/a | AL6: =VLOOKUP($Q6,武学奇术!$A:$ZZ,25,FALSE) -> 群体奇术 | AM6: =VLOOKUP($Q6,武学奇术!$A:$ZZ,26,FALSE) -> 1.4904 | AN6: =VLOOKUP($Q6,武学奇术!$A:$ZZ,27,FALSE)*(1+IF(OR($AL6=$F$4,$AL6=$F$5),$B$22,0)) -> 378 | AO6: =VLOOKUP($Q6,武学奇术!$A:$ZZ,28,FALSE) -> 2.2356 | AP6: =VLOOKUP($Q6,武学奇术!$A:$ZZ,29,FALSE)*(1+IF(OR($AL6=$F$4,$AL6=$F$5),$B$22,0)) -> 0 | AQ6: {=$G$3+IFERROR(VLOOKUP($AL6,$F$4:$G$7,2,FALSE),0)+VLOOKUP($Q6,武学奇术!$A:$ZZ,2,FALSE)+SUM(_xlfn.XLOOKUP($R6:$AK6,增益!$A:$A,增益!$B:$B,0))} -> 0.2537 | AR6: {=VLOOKUP($Q6,武学奇术!$A:$ZZ,5,FALSE)+SUM(_xlfn.XLOOKUP($R6:$AK6,增益!$A:$A,增益!$E:$E,0))} -> 0.075 | AS6: {=$D$10*(1+$AR6)+VLOOKUP($Q6,武学奇术!$A:$ZZ,3,FALSE)+SUM(_xlfn.XLOOKUP($R6:$AK6,增益!$A:$A,增益!$C:$C,0))-$I$2} -> 4100.3171 | AT6: {=$E$10*(1+$AR6)+VLOOKUP($Q6,武学奇术!$A:$ZZ,4,FALSE)+SUM(_xlfn.XLOOKUP($R6:$AK6,增益!$A:$A,增益!$D:$D,0))-$I$2} -> 4100.3171 | AU6: {=IF($F$10-$I$3+VLOOKUP($Q6,武学奇术!$A:$ZZ,6,FALSE)+SUM(_xlfn.XLOOKUP($R6:$AK6,增益!$A:$A,增益!$F:$F,0))>0,($F$10-$I$3+VLOOKUP($Q6,武学奇术!$A:$ZZ,6,FALSE)+SUM(_xlfn.XLOOKUP($R6:$AK6,增益!$A:$A,增益!$F:$F,0)))/200,($F$10-$I$3+VLOOKUP($Q6,武学奇术!$A:$ZZ,6,FALSE)+SUM(_xlfn.XLOOKUP($R6:$AK6,增益!$A:$A,增益!$F:$F,0)))/100)} -> 0.2925 | AV6: {=$G$10+VLOOKUP($Q6,武学奇术!$A:$ZZ,7,FALSE)+SUM(_xlfn.XLOOKUP($R6:$AK6,增益!$A:$A,增益!$G:$G,0))} -> 0 | AW6: {=VLOOKUP($Q6,武学奇术!$A:$ZZ,8,FALSE)+SUM(_xlfn.XLOOKUP($R6:$AK6,增益!$A:$A,增益!$H:$H,0))} -> 0 | AX6: =$D$11*(1+$AW6) -> 0 | AY6: =$E$11*(1+$AW6) -> 0 | AZ6: {=IF($F$11-$I$4+VLOOKUP($Q6,武学奇术!$A:$ZZ,9,FALSE)+SUM(_xlfn.XLOOKUP($R6:$AK6,增益!$A:$A,增益!$I:$I,0))>0,($F$11-$I$4+VLOOKUP($Q6,武学奇术!$A:$ZZ,9,FALSE)+SUM(_xlfn.XLOOKUP($R6:$AK6,增益!$A:$A,增益!$I:$I,0)))/200,($F$11-$I$4+VLOOKUP($Q6,武学奇术!$A:$ZZ,9,FALSE)+SUM(_xlfn.XLOOKUP($R6:$AK6,增益!$A:$A,增益!$I:$I,0)))/100)} -> -0.3 | BA6: {=$G$11+VLOOKUP($Q6,武学奇术!$A:$ZZ,10,FALSE)+SUM(_xlfn.XLOOKUP($R6:$AK6,增益!$A:$A,增益!$J:$J,0))} -> 0 | BB6: =$D$12*(1+$AW6) -> 0 | BC6: =$E$12*(1+$AW6) -> 0 | BD6: {=IF($F$12-$I$4+VLOOKUP($Q6,武学奇术!$A:$ZZ,11,FALSE)+SUM(_xlfn.XLOOKUP($R6:$AK6,增益!$A:$A,增益!$K:$K,0))>0,($F$12-$I$4+VLOOKUP($Q6,武学奇术!$A:$ZZ,11,FALSE)+SUM(_xlfn.XLOOKUP($R6:$AK6,增益!$A:$A,增益!$K:$K,0)))/200,($F$12-$I$4+VLOOKUP($Q6,武学奇术!$A:$ZZ,11,FALSE)+SUM(_xlfn.XLOOKUP($R6:$AK6,增益!$A:$A,增益!$K:$K,0)))/100)} -> -0.3 | BE6: {=$G$12+VLOOKUP($Q6,武学奇术!$A:$ZZ,12,FALSE)+SUM(_xlfn.XLOOKUP($R6:$AK6,增益!$A:$A,增益!$L:$L,0))} -> 0 | BF6: =$D$13*(1+$AW6) -> 605.472 | BG6: =$E$13*(1+$AW6) -> 1579.612 | BH6: {=IF($F$13-$I$4+VLOOKUP($Q6,武学奇术!$A:$ZZ,13,FALSE)+SUM(_xlfn.XLOOKUP($R6:$AK6,增益!$A:$A,增益!$M:$M,0))>0,($F$13-$I$4+VLOOKUP($Q6,武学奇术!$A:$ZZ,13,FALSE)+SUM(_xlfn.XLOOKUP($R6:$AK6,增益!$A:$A,增益!$K:$K,0)))/200,($F$13-$I$4+VLOOKUP($Q6,武学奇术!$A:$ZZ,13,FALSE)+SUM(_xlfn.XLOOKUP($R6:$AK6,增益!$A:$A,增益!$M:$M,0)))/100)} -> 0 | BI6: {=$G$13+VLOOKUP($Q6,武学奇术!$A:$ZZ,14,FALSE)+SUM(_xlfn.XLOOKUP($R6:$AK6,增益!$A:$A,增益!$N:$N,0))} -> 0.15 | BJ6: =$D$14*(1+$AW6) -> 0 | BK6: =$E$14*(1+$AW6) -> 0 | BL6: {=IF($F$14-$I$4+VLOOKUP($Q6,武学奇术!$A:$ZZ,15,FALSE)+SUM(_xlfn.XLOOKUP($R6:$AK6,增益!$A:$A,增益!$O:$O,0))>0,($F$14-$I$4+VLOOKUP($Q6,武学奇术!$A:$ZZ,15,FALSE)+SUM(_xlfn.XLOOKUP($R6:$AK6,增益!$A:$A,增益!$O:$O,0)))/200,($F$14-$I$4+VLOOKUP($Q6,武学奇术!$A:$ZZ,15,FALSE)+SUM(_xlfn.XLOOKUP($R6:$AK6,增益!$A:$A,增益!$O:$O,0)))/100)} -> -0.3 | BM6: {=$G$14+VLOOKUP($Q6,武学奇术!$A:$ZZ,16,FALSE)+SUM(_xlfn.XLOOKUP($R6:$AK6,增益!$A:$A,增益!$P:$P,0))} -> 0 | BN6: =MIN(IF(VLOOKUP($Q6,武学奇术!$A:$ZZ,23,FALSE)=1,100%,$B$8),100%) -> 1 | BO6: {=IF(VLOOKUP($Q6,武学奇术!$A:$ZZ,23,FALSE)=1,100%,MIN(80%,$B$9+VLOOKUP($Q6,武学奇术!$A:$ZZ,17,FALSE)+SUM(_xlfn.XLOOKUP($R6:$AK6,增益!$A:$A,增益!$Q:$Q,0)))+$B$11+SUM(_xlfn.XLOOKUP($R6:$AK6,增益!$A:$A,增益!$U:$U,0)))*IF(VLOOKUP($Q6,武学奇术!$A:$ZZ,24,FALSE)=1,0,1)} -> 0.9093 | BP6: {=1+$B$13+VLOOKUP($Q6,武学奇术!$A:$ZZ,18,FALSE)+SUM(_xlfn.XLOOKUP($R6:$AK6,增益!$A:$A,增益!$R:$R,0))} -> 1.55 | BQ6: {=IF(VLOOKUP($Q6,武学奇术!$A:$ZZ,24,FALSE)=1,100%,MIN(40%,$B$10+VLOOKUP($Q6,武学奇术!$A:$ZZ,19,FALSE)+SUM(_xlfn.XLOOKUP($R6:$AK6,增益!$A:$A,增益!$S:$S,0)))+$B$12+SUM(_xlfn.XLOOKUP($R6:$AK6,增益!$A:$A,增益!$V:$V,0)))*IF(VLOOKUP($Q6,武学奇术!$A:$ZZ,23,FALSE)=1,0,1)} -> 0.0929 | BR6: {=1+$B$14+VLOOKUP($Q6,武学奇术!$A:$ZZ,20,FALSE)+SUM(_xlfn.XLOOKUP($R6:$AK6,增益!$A:$A,增益!$T:$T,0))} -> 1.35 | BS6: =MIN((1-BQ6)*BN6,BN6*BO6) -> 0.9071 | BT6: =1-BQ6-BS6-BU6 -> 0 | BU6: =IF(VLOOKUP($Q6,武学奇术!$A:$ZZ,22,FALSE)=1,0,(1-$BN6))*(1-$BQ6) -> 0 | BV6: {=SUM(_xlfn.XLOOKUP($R6:$AK6,增益!$A:$A,增益!$W:$W,0))+$I$5} -> 0.06
A7: 无相 | B7: 79.2 | C7: =92.4+68.8*2 -> 230 | F7: 群体奇术 | G7: =B20 -> 0 | K7: =($L7*$BS7+$M7*$BQ7+$N7*$BT7+$O7*$BU7) -> 60565.692 | L7: =((($AS7+$AT7)/2*$AM7+$AN7)*(1+$AU7)*(1+$AV7)+(($AX7+$AY7)/2*IF($G$1="鸣金",$AO7,$AM7)+IF($G$1="鸣金",$AP7*1.5,0))*(1+$AZ7)*(1+$BA7)+(($BB7+$BC7)/2*IF($G$1="裂石",$AO7,$AM7)+IF($G$1="裂石",$AP7*1.5,0))*(1+$BD7)*(1+$BE7)+(($BF7+$BG7)/2*IF($G$1="牵丝",$AO7,$AM7)+IF($G$1="牵丝",$AP7*1.5,0))*(1+$BH7)*(1+$BI7)+(($BJ7+$BK7)/2*IF($G$1="破竹",$AO7,$AM7)+IF($G$1="破竹",$AP7*1.5,0))*(1+$BL7)*(1+$BM7))*(1+$AQ7)*$BP7*$P7*(1+IF(VLOOKUP($Q7,武学奇术!$A:$ZZ,30,FALSE)="弹道",$B$21,0))*(1+$BV7) -> 61701.229 | M7: =(($AT7*$AM7+$AN7)*(1+$AU7)*(1+$AV7)+($AY7*IF($G$1="鸣金",$AO7,$AM7)+IF($G$1="鸣金",$AP7*1.5,0))*(1+$AZ7)*(1+$BA7)+($BC7*IF($G$1="裂石",$AO7,$AM7)+IF($G$1="裂石",$AP7*1.5,0))*(1+$BD7)*(1+$BE7)+($BG7*IF($G$1="牵丝",$AO7,$AM7)+IF($G$1="牵丝",$AP7*1.5,0))*(1+$BH7)*(1+$BI7)+($BK7*IF($G$1="破竹",$AO7,$AM7)+IF($G$1="破竹",$AP7*1.5,0))*(1+$BL7)*(1+$BM7))*(1+$AQ7)*$BR7*$P7*(1+IF(VLOOKUP($Q7,武学奇术!$A:$ZZ,30,FALSE)="弹道",$B$21,0))*(1+$BV7) -> 49478.001 | N7: =((($AS7+$AT7)/2*$AM7+$AN7)*(1+$AU7)*(1+$AV7)+(($AX7+$AY7)/2*IF($G$1="鸣金",$AO7,$AM7)+IF($G$1="鸣金",$AP7*1.5,0))*(1+$AZ7)*(1+$BA7)+(($BB7+$BC7)/2*IF($G$1="裂石",$AO7,$AM7)+IF($G$1="裂石",$AP7*1.5,0))*(1+$BD7)*(1+$BE7)+(($BF7+$BG7)/2*IF($G$1="牵丝",$AO7,$AM7)+IF($G$1="牵丝",$AP7*1.5,0))*(1+$BH7)*(1+$BI7)+(($BJ7+$BK7)/2*IF($G$1="破竹",$AO7,$AM7)+IF($G$1="破竹",$AP7*1.5,0))*(1+$BL7)*(1+$BM7))*(1+$AQ7)*$P7*(1+IF(VLOOKUP($Q7,武学奇术!$A:$ZZ,30,FALSE)="弹道",$B$21,0))*(1+$BV7) -> 32995.31 | O7: =((($AS7*$AM7+$AN7)*(1+$AU7)*(1+$AV7)+($AX7*IF($G$1="鸣金",$AO7,$AM7)+IF($G$1="鸣金",$AP7*1.5,0))*(1+$AZ7)*(1+$BA7)+($BB7*IF($G$1="裂石",$AO7,$AM7)+IF($G$1="裂石",$AP7*1.5,0))*(1+$BD7)*(1+$BE7)+($BF7*IF($G$1="牵丝",$AO7,$AM7)+IF($G$1="牵丝",$AP7*1.5,0))*(1+$BH7)*(1+$BI7)+($BJ7*IF($G$1="破竹",$AO7,$AM7)+IF($G$1="破竹",$AP7*1.5,0))*(1+$BL7)*(1+$BM7))*(1+$AQ7))*$P7*(1+IF(VLOOKUP($Q7,武学奇术!$A:$ZZ,30,FALSE)="弹道",$B$21,0))*(1+$BV7) -> 29340.248 | P7: 1 | Q7: 伞Q | R7: N/a | S7: 沧海帖1层 | T7: N/a | U7: N/a | V7: 风墙(弹道) | W7: N/a | X7: N/a | Y7: N/a | Z7: N/a | AA7: N/a | AB7: N/a | AC7: N/a | AD7: N/a | AE7: N/a | AF7: N/a | AG7: N/a | AH7: N/a | AI7: N/a | AJ7: N/a | AK7: N/a | AL7: =VLOOKUP($Q7,武学奇术!$A:$ZZ,25,FALSE) -> 伞 | AM7: =VLOOKUP($Q7,武学奇术!$A:$ZZ,26,FALSE) -> 2.3397 | AN7: =VLOOKUP($Q7,武学奇术!$A:$ZZ,27,FALSE)*(1+IF(OR($AL7=$F$4,$AL7=$F$5),$B$22,0)) -> 972 | AO7: =VLOOKUP($Q7,武学奇术!$A:$ZZ,28,FALSE) -> 3.5095 | AP7: =VLOOKUP($Q7,武学奇术!$A:$ZZ,29,FALSE)*(1+IF(OR($AL7=$F$4,$AL7=$F$5),$B$22,0)) -> 529.5 | AQ7: {=$G$3+IFERROR(VLOOKUP($AL7,$F$4:$G$7,2,FALSE),0)+VLOOKUP($Q7,武学奇术!$A:$ZZ,2,FALSE)+SUM(_xlfn.XLOOKUP($R7:$AK7,增益!$A:$A,增益!$B:$B,0))} -> 0.7541 | AR7: {=VLOOKUP($Q7,武学奇术!$A:$ZZ,5,FALSE)+SUM(_xlfn.XLOOKUP($R7:$AK7,增益!$A:$A,增益!$E:$E,0))} -> 0 | AS7: {=$D$10*(1+$AR7)+VLOOKUP($Q7,武学奇术!$A:$ZZ,3,FALSE)+SUM(_xlfn.XLOOKUP($R7:$AK7,增益!$A:$A,增益!$C:$C,0))-$I$2} -> 3773.588 | AT7: {=$E$10*(1+$AR7)+VLOOKUP($Q7,武学奇术!$A:$ZZ,4,FALSE)+SUM(_xlfn.XLOOKUP($R7:$AK7,增益!$A:$A,增益!$D:$D,0))-$I$2} -> 3773.588 | AU7: {=IF($F$10-$I$3+VLOOKUP($Q7,武学奇术!$A:$ZZ,6,FALSE)+SUM(_xlfn.XLOOKUP($R7:$AK7,增益!$A:$A,增益!$F:$F,0))>0,($F$10-$I$3+VLOOKUP($Q7,武学奇术!$A:$ZZ,6,FALSE)+SUM(_xlfn.XLOOKUP($R7:$AK7,增益!$A:$A,增益!$F:$F,0)))/200,($F$10-$I$3+VLOOKUP($Q7,武学奇术!$A:$ZZ,6,FALSE)+SUM(_xlfn.XLOOKUP($R7:$AK7,增益!$A:$A,增益!$F:$F,0)))/100)} -> 0.2675 | AV7: {=$G$10+VLOOKUP($Q7,武学奇术!$A:$ZZ,7,FALSE)+SUM(_xlfn.XLOOKUP($R7:$AK7,增益!$A:$A,增益!$G:$G,0))} -> 0 | AW7: {=VLOOKUP($Q7,武学奇术!$A:$ZZ,8,FALSE)+SUM(_xlfn.XLOOKUP($R7:$AK7,增益!$A:$A,增益!$H:$H,0))} -> 0 | AX7: =$D$11*(1+$AW7) -> 0 | AY7: =$E$11*(1+$AW7) -> 0 | AZ7: {=IF($F$11-$I$4+VLOOKUP($Q7,武学奇术!$A:$ZZ,9,FALSE)+SUM(_xlfn.XLOOKUP($R7:$AK7,增益!$A:$A,增益!$I:$I,0))>0,($F$11-$I$4+VLOOKUP($Q7,武学奇术!$A:$ZZ,9,FALSE)+SUM(_xlfn.XLOOKUP($R7:$AK7,增益!$A:$A,增益!$I:$I,0)))/200,($F$11-$I$4+VLOOKUP($Q7,武学奇术!$A:$ZZ,9,FALSE)+SUM(_xlfn.XLOOKUP($R7:$AK7,增益!$A:$A,增益!$I:$I,0)))/100)} -> -0.3 | BA7: {=$G$11+VLOOKUP($Q7,武学奇术!$A:$ZZ,10,FALSE)+SUM(_xlfn.XLOOKUP($R7:$AK7,增益!$A:$A,增益!$J:$J,0))} -> 0 | BB7: =$D$12*(1+$AW7) -> 0 | BC7: =$E$12*(1+$AW7) -> 0 | BD7: {=IF($F$12-$I$4+VLOOKUP($Q7,武学奇术!$A:$ZZ,11,FALSE)+SUM(_xlfn.XLOOKUP($R7:$AK7,增益!$A:$A,增益!$K:$K,0))>0,($F$12-$I$4+VLOOKUP($Q7,武学奇术!$A:$ZZ,11,FALSE)+SUM(_xlfn.XLOOKUP($R7:$AK7,增益!$A:$A,增益!$K:$K,0)))/200,($F$12-$I$4+VLOOKUP($Q7,武学奇术!$A:$ZZ,11,FALSE)+SUM(_xlfn.XLOOKUP($R7:$AK7,增益!$A:$A,增益!$K:$K,0)))/100)} -> -0.3 | BE7: {=$G$12+VLOOKUP($Q7,武学奇术!$A:$ZZ,12,FALSE)+SUM(_xlfn.XLOOKUP($R7:$AK7,增益!$A:$A,增益!$L:$L,0))} -> 0 | BF7: =$D$13*(1+$AW7) -> 605.472 | BG7: =$E$13*(1+$AW7) -> 1579.612 | BH7: {=IF($F$13-$I$4+VLOOKUP($Q7,武学奇术!$A:$ZZ,13,FALSE)+SUM(_xlfn.XLOOKUP($R7:$AK7,增益!$A:$A,增益!$M:$M,0))>0,($F$13-$I$4+VLOOKUP($Q7,武学奇术!$A:$ZZ,13,FALSE)+SUM(_xlfn.XLOOKUP($R7:$AK7,增益!$A:$A,增益!$K:$K,0)))/200,($F$13-$I$4+VLOOKUP($Q7,武学奇术!$A:$ZZ,13,FALSE)+SUM(_xlfn.XLOOKUP($R7:$AK7,增益!$A:$A,增益!$M:$M,0)))/100)} -> 0 | BI7: {=$G$13+VLOOKUP($Q7,武学奇术!$A:$ZZ,14,FALSE)+SUM(_xlfn.XLOOKUP($R7:$AK7,增益!$A:$A,增益!$N:$N,0))} -> 0.15 | BJ7: =$D$14*(1+$AW7) -> 0 | BK7: =$E$14*(1+$AW7) -> 0 | BL7: {=IF($F$14-$I$4+VLOOKUP($Q7,武学奇术!$A:$ZZ,15,FALSE)+SUM(_xlfn.XLOOKUP($R7:$AK7,增益!$A:$A,增益!$O:$O,0))>0,($F$14-$I$4+VLOOKUP($Q7,武学奇术!$A:$ZZ,15,FALSE)+SUM(_xlfn.XLOOKUP($R7:$AK7,增益!$A:$A,增益!$O:$O,0)))/200,($F$14-$I$4+VLOOKUP($Q7,武学奇术!$A:$ZZ,15,FALSE)+SUM(_xlfn.XLOOKUP($R7:$AK7,增益!$A:$A,增益!$O:$O,0)))/100)} -> -0.3 | BM7: {=$G$14+VLOOKUP($Q7,武学奇术!$A:$ZZ,16,FALSE)+SUM(_xlfn.XLOOKUP($R7:$AK7,增益!$A:$A,增益!$P:$P,0))} -> 0 | BN7: =MIN(IF(VLOOKUP($Q7,武学奇术!$A:$ZZ,23,FALSE)=1,100%,$B$8),100%) -> 1 | BO7: {=IF(VLOOKUP($Q7,武学奇术!$A:$ZZ,23,FALSE)=1,100%,MIN(80%,$B$9+VLOOKUP($Q7,武学奇术!$A:$ZZ,17,FALSE)+SUM(_xlfn.XLOOKUP($R7:$AK7,增益!$A:$A,增益!$Q:$Q,0)))+$B$11+SUM(_xlfn.XLOOKUP($R7:$AK7,增益!$A:$A,增益!$U:$U,0)))*IF(VLOOKUP($Q7,武学奇术!$A:$ZZ,24,FALSE)=1,0,1)} -> 0.9093 | BP7: {=1+$B$13+VLOOKUP($Q7,武学奇术!$A:$ZZ,18,FALSE)+SUM(_xlfn.XLOOKUP($R7:$AK7,增益!$A:$A,增益!$R:$R,0))} -> 1.87 | BQ7: {=IF(VLOOKUP($Q7,武学奇术!$A:$ZZ,24,FALSE)=1,100%,MIN(40%,$B$10+VLOOKUP($Q7,武学奇术!$A:$ZZ,19,FALSE)+SUM(_xlfn.XLOOKUP($R7:$AK7,增益!$A:$A,增益!$S:$S,0)))+$B$12+SUM(_xlfn.XLOOKUP($R7:$AK7,增益!$A:$A,增益!$V:$V,0)))*IF(VLOOKUP($Q7,武学奇术!$A:$ZZ,23,FALSE)=1,0,1)} -> 0.0929 | BR7: {=1+$B$14+VLOOKUP($Q7,武学奇术!$A:$ZZ,20,FALSE)+SUM(_xlfn.XLOOKUP($R7:$AK7,增益!$A:$A,增益!$T:$T,0))} -> 1.35 | BS7: =MIN((1-BQ7)*BN7,BN7*BO7) -> 0.9071 | BT7: =1-BQ7-BS7-BU7 -> 0 | BU7: =IF(VLOOKUP($Q7,武学奇术!$A:$ZZ,22,FALSE)=1,0,(1-$BN7))*(1-$BQ7) -> 0 | BV7: {=SUM(_xlfn.XLOOKUP($R7:$AK7,增益!$A:$A,增益!$W:$W,0))+$I$5} -> 0.06
A8: 精准率 | B8: 1.0067 | C8: 实际属性 | H8: 战斗时间 | I8: 91.6 | K8: =($L8*$BS8+$M8*$BQ8+$N8*$BT8+$O8*$BU8) -> 70618.521 | L8: =((($AS8+$AT8)/2*$AM8+$AN8)*(1+$AU8)*(1+$AV8)+(($AX8+$AY8)/2*IF($G$1="鸣金",$AO8,$AM8)+IF($G$1="鸣金",$AP8*1.5,0))*(1+$AZ8)*(1+$BA8)+(($BB8+$BC8)/2*IF($G$1="裂石",$AO8,$AM8)+IF($G$1="裂石",$AP8*1.5,0))*(1+$BD8)*(1+$BE8)+(($BF8+$BG8)/2*IF($G$1="牵丝",$AO8,$AM8)+IF($G$1="牵丝",$AP8*1.5,0))*(1+$BH8)*(1+$BI8)+(($BJ8+$BK8)/2*IF($G$1="破竹",$AO8,$AM8)+IF($G$1="破竹",$AP8*1.5,0))*(1+$BL8)*(1+$BM8))*(1+$AQ8)*$BP8*$P8*(1+IF(VLOOKUP($Q8,武学奇术!$A:$ZZ,30,FALSE)="弹道",$B$21,0))*(1+$BV8) -> 71945.529 | M8: =(($AT8*$AM8+$AN8)*(1+$AU8)*(1+$AV8)+($AY8*IF($G$1="鸣金",$AO8,$AM8)+IF($G$1="鸣金",$AP8*1.5,0))*(1+$AZ8)*(1+$BA8)+($BC8*IF($G$1="裂石",$AO8,$AM8)+IF($G$1="裂石",$AP8*1.5,0))*(1+$BD8)*(1+$BE8)+($BG8*IF($G$1="牵丝",$AO8,$AM8)+IF($G$1="牵丝",$AP8*1.5,0))*(1+$BH8)*(1+$BI8)+($BK8*IF($G$1="破竹",$AO8,$AM8)+IF($G$1="破竹",$AP8*1.5,0))*(1+$BL8)*(1+$BM8))*(1+$AQ8)*$BR8*$P8*(1+IF(VLOOKUP($Q8,武学奇术!$A:$ZZ,30,FALSE)="弹道",$B$21,0))*(1+$BV8) -> 57661.267 | N8: =((($AS8+$AT8)/2*$AM8+$AN8)*(1+$AU8)*(1+$AV8)+(($AX8+$AY8)/2*IF($G$1="鸣金",$AO8,$AM8)+IF($G$1="鸣金",$AP8*1.5,0))*(1+$AZ8)*(1+$BA8)+(($BB8+$BC8)/2*IF($G$1="裂石",$AO8,$AM8)+IF($G$1="裂石",$AP8*1.5,0))*(1+$BD8)*(1+$BE8)+(($BF8+$BG8)/2*IF($G$1="牵丝",$AO8,$AM8)+IF($G$1="牵丝",$AP8*1.5,0))*(1+$BH8)*(1+$BI8)+(($BJ8+$BK8)/2*IF($G$1="破竹",$AO8,$AM8)+IF($G$1="破竹",$AP8*1.5,0))*(1+$BL8)*(1+$BM8))*(1+$AQ8)*$P8*(1+IF(VLOOKUP($Q8,武学奇术!$A:$ZZ,30,FALSE)="弹道",$B$21,0))*(1+$BV8) -> 38473.545 | O8: =((($AS8*$AM8+$AN8)*(1+$AU8)*(1+$AV8)+($AX8*IF($G$1="鸣金",$AO8,$AM8)+IF($G$1="鸣金",$AP8*1.5,0))*(1+$AZ8)*(1+$BA8)+($BB8*IF($G$1="裂石",$AO8,$AM8)+IF($G$1="裂石",$AP8*1.5,0))*(1+$BD8)*(1+$BE8)+($BF8*IF($G$1="牵丝",$AO8,$AM8)+IF($G$1="牵丝",$AP8*1.5,0))*(1+$BH8)*(1+$BI8)+($BJ8*IF($G$1="破竹",$AO8,$AM8)+IF($G$1="破竹",$AP8*1.5,0))*(1+$BL8)*(1+$BM8))*(1+$AQ8))*$P8*(1+IF(VLOOKUP($Q8,武学奇术!$A:$ZZ,30,FALSE)="弹道",$B$21,0))*(1+$BV8) -> 34235.041 | P8: 1 | Q8: 伞Q | R8: 易水歌1层 | S8: 沧海帖1层 | T8: 连中 | U8: N/a | V8: 风墙(弹道) | W8: N/a | X8: N/a | Y8: N/a | Z8: N/a | AA8: 近战笛 | AB8: N/a | AC8: N/a | AD8: N/a | AE8: N/a | AF8: N/a | AG8: N/a | AH8: N/a | AI8: N/a | AJ8: N/a | AK8: N/a | AL8: =VLOOKUP($Q8,武学奇术!$A:$ZZ,25,FALSE) -> 伞 | AM8: =VLOOKUP($Q8,武学奇术!$A:$ZZ,26,FALSE) -> 2.3397 | AN8: =VLOOKUP($Q8,武学奇术!$A:$ZZ,27,FALSE)*(1+IF(OR($AL8=$F$4,$AL8=$F$5),$B$22,0)) -> 972 | AO8: =VLOOKUP($Q8,武学奇术!$A:$ZZ,28,FALSE) -> 3.5095 | AP8: =VLOOKUP($Q8,武学奇术!$A:$ZZ,29,FALSE)*(1+IF(OR($AL8=$F$4,$AL8=$F$5),$B$22,0)) -> 529.5 | AQ8: {=$G$3+IFERROR(VLOOKUP($AL8,$F$4:$G$7,2,FALSE),0)+VLOOKUP($Q8,武学奇术!$A:$ZZ,2,FALSE)+SUM(_xlfn.XLOOKUP($R8:$AK8,增益!$A:$A,增益!$B:$B,0))} -> 1.0341 | AR8: {=VLOOKUP($Q8,武学奇术!$A:$ZZ,5,FALSE)+SUM(_xlfn.XLOOKUP($R8:$AK8,增益!$A:$A,增益!$E:$E,0))} -> 0 | AS8: {=$D$10*(1+$AR8)+VLOOKUP($Q8,武学奇术!$A:$ZZ,3,FALSE)+SUM(_xlfn.XLOOKUP($R8:$AK8,增益!$A:$A,增益!$C:$C,0))-$I$2} -> 3773.588 | AT8: {=$E$10*(1+$AR8)+VLOOKUP($Q8,武学奇术!$A:$ZZ,4,FALSE)+SUM(_xlfn.XLOOKUP($R8:$AK8,增益!$A:$A,增益!$D:$D,0))-$I$2} -> 3773.588 | AU8: {=IF($F$10-$I$3+VLOOKUP($Q8,武学奇术!$A:$ZZ,6,FALSE)+SUM(_xlfn.XLOOKUP($R8:$AK8,增益!$A:$A,增益!$F:$F,0))>0,($F$10-$I$3+VLOOKUP($Q8,武学奇术!$A:$ZZ,6,FALSE)+SUM(_xlfn.XLOOKUP($R8:$AK8,增益!$A:$A,增益!$F:$F,0)))/200,($F$10-$I$3+VLOOKUP($Q8,武学奇术!$A:$ZZ,6,FALSE)+SUM(_xlfn.XLOOKUP($R8:$AK8,增益!$A:$A,增益!$F:$F,0)))/100)} -> 0.2775 | AV8: {=$G$10+VLOOKUP($Q8,武学奇术!$A:$ZZ,7,FALSE)+SUM(_xlfn.XLOOKUP($R8:$AK8,增益!$A:$A,增益!$G:$G,0))} -> 0 | AW8: {=VLOOKUP($Q8,武学奇术!$A:$ZZ,8,FALSE)+SUM(_xlfn.XLOOKUP($R8:$AK8,增益!$A:$A,增益!$H:$H,0))} -> 0 | AX8: =$D$11*(1+$AW8) -> 0 | AY8: =$E$11*(1+$AW8) -> 0 | AZ8: {=IF($F$11-$I$4+VLOOKUP($Q8,武学奇术!$A:$ZZ,9,FALSE)+SUM(_xlfn.XLOOKUP($R8:$AK8,增益!$A:$A,增益!$I:$I,0))>0,($F$11-$I$4+VLOOKUP($Q8,武学奇术!$A:$ZZ,9,FALSE)+SUM(_xlfn.XLOOKUP($R8:$AK8,增益!$A:$A,增益!$I:$I,0)))/200,($F$11-$I$4+VLOOKUP($Q8,武学奇术!$A:$ZZ,9,FALSE)+SUM(_xlfn.XLOOKUP($R8:$AK8,增益!$A:$A,增益!$I:$I,0)))/100)} -> -0.3 | BA8: {=$G$11+VLOOKUP($Q8,武学奇术!$A:$ZZ,10,FALSE)+SUM(_xlfn.XLOOKUP($R8:$AK8,增益!$A:$A,增益!$J:$J,0))} -> 0 | BB8: =$D$12*(1+$AW8) -> 0 | BC8: =$E$12*(1+$AW8) -> 0 | BD8: {=IF($F$12-$I$4+VLOOKUP($Q8,武学奇术!$A:$ZZ,11,FALSE)+SUM(_xlfn.XLOOKUP($R8:$AK8,增益!$A:$A,增益!$K:$K,0))>0,($F$12-$I$4+VLOOKUP($Q8,武学奇术!$A:$ZZ,11,FALSE)+SUM(_xlfn.XLOOKUP($R8:$AK8,增益!$A:$A,增益!$K:$K,0)))/200,($F$12-$I$4+VLOOKUP($Q8,武学奇术!$A:$ZZ,11,FALSE)+SUM(_xlfn.XLOOKUP($R8:$AK8,增益!$A:$A,增益!$K:$K,0)))/100)} -> -0.3 | BE8: {=$G$12+VLOOKUP($Q8,武学奇术!$A:$ZZ,12,FALSE)+SUM(_xlfn.XLOOKUP($R8:$AK8,增益!$A:$A,增益!$L:$L,0))} -> 0 | BF8: =$D$13*(1+$AW8) -> 605.472 | BG8: =$E$13*(1+$AW8) -> 1579.612 | BH8: {=IF($F$13-$I$4+VLOOKUP($Q8,武学奇术!$A:$ZZ,13,FALSE)+SUM(_xlfn.XLOOKUP($R8:$AK8,增益!$A:$A,增益!$M:$M,0))>0,($F$13-$I$4+VLOOKUP($Q8,武学奇术!$A:$ZZ,13,FALSE)+SUM(_xlfn.XLOOKUP($R8:$AK8,增益!$A:$A,增益!$K:$K,0)))/200,($F$13-$I$4+VLOOKUP($Q8,武学奇术!$A:$ZZ,13,FALSE)+SUM(_xlfn.XLOOKUP($R8:$AK8,增益!$A:$A,增益!$M:$M,0)))/100)} -> 0 | BI8: {=$G$13+VLOOKUP($Q8,武学奇术!$A:$ZZ,14,FALSE)+SUM(_xlfn.XLOOKUP($R8:$AK8,增益!$A:$A,增益!$N:$N,0))} -> 0.15 | BJ8: =$D$14*(1+$AW8) -> 0 | BK8: =$E$14*(1+$AW8) -> 0 | BL8: {=IF($F$14-$I$4+VLOOKUP($Q8,武学奇术!$A:$ZZ,15,FALSE)+SUM(_xlfn.XLOOKUP($R8:$AK8,增益!$A:$A,增益!$O:$O,0))>0,($F$14-$I$4+VLOOKUP($Q8,武学奇术!$A:$ZZ,15,FALSE)+SUM(_xlfn.XLOOKUP($R8:$AK8,增益!$A:$A,增益!$O:$O,0)))/200,($F$14-$I$4+VLOOKUP($Q8,武学奇术!$A:$ZZ,15,FALSE)+SUM(_xlfn.XLOOKUP($R8:$AK8,增益!$A:$A,增益!$O:$O,0)))/100)} -> -0.3 | BM8: {=$G$14+VLOOKUP($Q8,武学奇术!$A:$ZZ,16,FALSE)+SUM(_xlfn.XLOOKUP($R8:$AK8,增益!$A:$A,增益!$P:$P,0))} -> 0 | BN8: =MIN(IF(VLOOKUP($Q8,武学奇术!$A:$ZZ,23,FALSE)=1,100%,$B$8),100%) -> 1 | BO8: {=IF(VLOOKUP($Q8,武学奇术!$A:$ZZ,23,FALSE)=1,100%,MIN(80%,$B$9+VLOOKUP($Q8,武学奇术!$A:$ZZ,17,FALSE)+SUM(_xlfn.XLOOKUP($R8:$AK8,增益!$A:$A,增益!$Q:$Q,0)))+$B$11+SUM(_xlfn.XLOOKUP($R8:$AK8,增益!$A:$A,增益!$U:$U,0)))*IF(VLOOKUP($Q8,武学奇术!$A:$ZZ,24,FALSE)=1,0,1)} -> 0.9093 | BP8: {=1+$B$13+VLOOKUP($Q8,武学奇术!$A:$ZZ,18,FALSE)+SUM(_xlfn.XLOOKUP($R8:$AK8,增益!$A:$A,增益!$R:$R,0))} -> 1.87 | BQ8: {=IF(VLOOKUP($Q8,武学奇术!$A:$ZZ,24,FALSE)=1,100%,MIN(40%,$B$10+VLOOKUP($Q8,武学奇术!$A:$ZZ,19,FALSE)+SUM(_xlfn.XLOOKUP($R8:$AK8,增益!$A:$A,增益!$S:$S,0)))+$B$12+SUM(_xlfn.XLOOKUP($R8:$AK8,增益!$A:$A,增益!$V:$V,0)))*IF(VLOOKUP($Q8,武学奇术!$A:$ZZ,23,FALSE)=1,0,1)} -> 0.0929 | BR8: {=1+$B$14+VLOOKUP($Q8,武学奇术!$A:$ZZ,20,FALSE)+SUM(_xlfn.XLOOKUP($R8:$AK8,增益!$A:$A,增益!$T:$T,0))} -> 1.35 | BS8: =MIN((1-BQ8)*BN8,BN8*BO8) -> 0.9071 | BT8: =1-BQ8-BS8-BU8 -> 0 | BU8: =IF(VLOOKUP($Q8,武学奇术!$A:$ZZ,22,FALSE)=1,0,(1-$BN8))*(1-$BQ8) -> 0 | BV8: {=SUM(_xlfn.XLOOKUP($R8:$AK8,增益!$A:$A,增益!$W:$W,0))+$I$5} -> 0.06
A9: 会心率 | B9: 0.7763 | D9: 最小攻击 | E9: 最大攻击 | F9: 穿透 | G9: 伤害加成 | K9: =($L9*$BS9+$M9*$BQ9+$N9*$BT9+$O9*$BU9) -> 28673.662 | L9: =((($AS9+$AT9)/2*$AM9+$AN9)*(1+$AU9)*(1+$AV9)+(($AX9+$AY9)/2*IF($G$1="鸣金",$AO9,$AM9)+IF($G$1="鸣金",$AP9*1.5,0))*(1+$AZ9)*(1+$BA9)+(($BB9+$BC9)/2*IF($G$1="裂石",$AO9,$AM9)+IF($G$1="裂石",$AP9*1.5,0))*(1+$BD9)*(1+$BE9)+(($BF9+$BG9)/2*IF($G$1="牵丝",$AO9,$AM9)+IF($G$1="牵丝",$AP9*1.5,0))*(1+$BH9)*(1+$BI9)+(($BJ9+$BK9)/2*IF($G$1="破竹",$AO9,$AM9)+IF($G$1="破竹",$AP9*1.5,0))*(1+$BL9)*(1+$BM9))*(1+$AQ9)*$BP9*$P9*(1+IF(VLOOKUP($Q9,武学奇术!$A:$ZZ,30,FALSE)="弹道",$B$21,0))*(1+$BV9) -> 28691.355 | M9: =(($AT9*$AM9+$AN9)*(1+$AU9)*(1+$AV9)+($AY9*IF($G$1="鸣金",$AO9,$AM9)+IF($G$1="鸣金",$AP9*1.5,0))*(1+$AZ9)*(1+$BA9)+($BC9*IF($G$1="裂石",$AO9,$AM9)+IF($G$1="裂石",$AP9*1.5,0))*(1+$BD9)*(1+$BE9)+($BG9*IF($G$1="牵丝",$AO9,$AM9)+IF($G$1="牵丝",$AP9*1.5,0))*(1+$BH9)*(1+$BI9)+($BK9*IF($G$1="破竹",$AO9,$AM9)+IF($G$1="破竹",$AP9*1.5,0))*(1+$BL9)*(1+$BM9))*(1+$AQ9)*$BR9*$P9*(1+IF(VLOOKUP($Q9,武学奇术!$A:$ZZ,30,FALSE)="弹道",$B$21,0))*(1+$BV9) -> 28500.898 | N9: =((($AS9+$AT9)/2*$AM9+$AN9)*(1+$AU9)*(1+$AV9)+(($AX9+$AY9)/2*IF($G$1="鸣金",$AO9,$AM9)+IF($G$1="鸣金",$AP9*1.5,0))*(1+$AZ9)*(1+$BA9)+(($BB9+$BC9)/2*IF($G$1="裂石",$AO9,$AM9)+IF($G$1="裂石",$AP9*1.5,0))*(1+$BD9)*(1+$BE9)+(($BF9+$BG9)/2*IF($G$1="牵丝",$AO9,$AM9)+IF($G$1="牵丝",$AP9*1.5,0))*(1+$BH9)*(1+$BI9)+(($BJ9+$BK9)/2*IF($G$1="破竹",$AO9,$AM9)+IF($G$1="破竹",$AP9*1.5,0))*(1+$BL9)*(1+$BM9))*(1+$AQ9)*$P9*(1+IF(VLOOKUP($Q9,武学奇术!$A:$ZZ,30,FALSE)="弹道",$B$21,0))*(1+$BV9) -> 19000.897 | O9: =((($AS9*$AM9+$AN9)*(1+$AU9)*(1+$AV9)+($AX9*IF($G$1="鸣金",$AO9,$AM9)+IF($G$1="鸣金",$AP9*1.5,0))*(1+$AZ9)*(1+$BA9)+($BB9*IF($G$1="裂石",$AO9,$AM9)+IF($G$1="裂石",$AP9*1.5,0))*(1+$BD9)*(1+$BE9)+($BF9*IF($G$1="牵丝",$AO9,$AM9)+IF($G$1="牵丝",$AP9*1.5,0))*(1+$BH9)*(1+$BI9)+($BJ9*IF($G$1="破竹",$AO9,$AM9)+IF($G$1="破竹",$AP9*1.5,0))*(1+$BL9)*(1+$BM9))*(1+$AQ9))*$P9*(1+IF(VLOOKUP($Q9,武学奇术!$A:$ZZ,30,FALSE)="弹道",$B$21,0))*(1+$BV9) -> 16890.019 | P9: 1 | Q9: 伞重击派生 | R9: 易水歌2层 | S9: 沧海帖1层 | T9: N/a | U9: N/a | V9: N/a | W9: N/a | X9: N/a | Y9: N/a | Z9: N/a | AA9: 近战笛 | AB9: 惧刃(拐) | AC9: N/a | AD9: N/a | AE9: N/a | AF9: N/a | AG9: N/a | AH9: N/a | AI9: N/a | AJ9: N/a | AK9: N/a | AL9: =VLOOKUP($Q9,武学奇术!$A:$ZZ,25,FALSE) -> 伞 | AM9: =VLOOKUP($Q9,武学奇术!$A:$ZZ,26,FALSE) -> 1.7001 | AN9: =VLOOKUP($Q9,武学奇术!$A:$ZZ,27,FALSE)*(1+IF(OR($AL9=$F$4,$AL9=$F$5),$B$22,0)) -> 706.5 | AO9: =VLOOKUP($Q9,武学奇术!$A:$ZZ,28,FALSE) -> 2.5502 | AP9: =VLOOKUP($Q9,武学奇术!$A:$ZZ,29,FALSE)*(1+IF(OR($AL9=$F$4,$AL9=$F$5),$B$22,0)) -> 384 | AQ9: {=$G$3+IFERROR(VLOOKUP($AL9,$F$4:$G$7,2,FALSE),0)+VLOOKUP($Q9,武学奇术!$A:$ZZ,2,FALSE)+SUM(_xlfn.XLOOKUP($R9:$AK9,增益!$A:$A,增益!$B:$B,0))} -> 0.3941 | AR9: {=VLOOKUP($Q9,武学奇术!$A:$ZZ,5,FALSE)+SUM(_xlfn.XLOOKUP($R9:$AK9,增益!$A:$A,增益!$E:$E,0))} -> 0 | AS9: {=$D$10*(1+$AR9)+VLOOKUP($Q9,武学奇术!$A:$ZZ,3,FALSE)+SUM(_xlfn.XLOOKUP($R9:$AK9,增益!$A:$A,增益!$C:$C,0))-$I$2} -> 3773.588 | AT9: {=$E$10*(1+$AR9)+VLOOKUP($Q9,武学奇术!$A:$ZZ,4,FALSE)+SUM(_xlfn.XLOOKUP($R9:$AK9,增益!$A:$A,增益!$D:$D,0))-$I$2} -> 3773.588 | AU9: {=IF($F$10-$I$3+VLOOKUP($Q9,武学奇术!$A:$ZZ,6,FALSE)+SUM(_xlfn.XLOOKUP($R9:$AK9,增益!$A:$A,增益!$F:$F,0))>0,($F$10-$I$3+VLOOKUP($Q9,武学奇术!$A:$ZZ,6,FALSE)+SUM(_xlfn.XLOOKUP($R9:$AK9,增益!$A:$A,增益!$F:$F,0)))/200,($F$10-$I$3+VLOOKUP($Q9,武学奇术!$A:$ZZ,6,FALSE)+SUM(_xlfn.XLOOKUP($R9:$AK9,增益!$A:$A,增益!$F:$F,0)))/100)} -> 0.2625 | AV9: {=$G$10+VLOOKUP($Q9,武学奇术!$A:$ZZ,7,FALSE)+SUM(_xlfn.XLOOKUP($R9:$AK9,增益!$A:$A,增益!$G:$G,0))} -> 0 | AW9: {=VLOOKUP($Q9,武学奇术!$A:$ZZ,8,FALSE)+SUM(_xlfn.XLOOKUP($R9:$AK9,增益!$A:$A,增益!$H:$H,0))} -> 0 | AX9: =$D$11*(1+$AW9) -> 0 | AY9: =$E$11*(1+$AW9) -> 0 | AZ9: {=IF($F$11-$I$4+VLOOKUP($Q9,武学奇术!$A:$ZZ,9,FALSE)+SUM(_xlfn.XLOOKUP($R9:$AK9,增益!$A:$A,增益!$I:$I,0))>0,($F$11-$I$4+VLOOKUP($Q9,武学奇术!$A:$ZZ,9,FALSE)+SUM(_xlfn.XLOOKUP($R9:$AK9,增益!$A:$A,增益!$I:$I,0)))/200,($F$11-$I$4+VLOOKUP($Q9,武学奇术!$A:$ZZ,9,FALSE)+SUM(_xlfn.XLOOKUP($R9:$AK9,增益!$A:$A,增益!$I:$I,0)))/100)} -> -0.3 | BA9: {=$G$11+VLOOKUP($Q9,武学奇术!$A:$ZZ,10,FALSE)+SUM(_xlfn.XLOOKUP($R9:$AK9,增益!$A:$A,增益!$J:$J,0))} -> 0 | BB9: =$D$12*(1+$AW9) -> 0 | BC9: =$E$12*(1+$AW9) -> 0 | BD9: {=IF($F$12-$I$4+VLOOKUP($Q9,武学奇术!$A:$ZZ,11,FALSE)+SUM(_xlfn.XLOOKUP($R9:$AK9,增益!$A:$A,增益!$K:$K,0))>0,($F$12-$I$4+VLOOKUP($Q9,武学奇术!$A:$ZZ,11,FALSE)+SUM(_xlfn.XLOOKUP($R9:$AK9,增益!$A:$A,增益!$K:$K,0)))/200,($F$12-$I$4+VLOOKUP($Q9,武学奇术!$A:$ZZ,11,FALSE)+SUM(_xlfn.XLOOKUP($R9:$AK9,增益!$A:$A,增益!$K:$K,0)))/100)} -> -0.3 | BE9: {=$G$12+VLOOKUP($Q9,武学奇术!$A:$ZZ,12,FALSE)+SUM(_xlfn.XLOOKUP($R9:$AK9,增益!$A:$A,增益!$L:$L,0))} -> 0 | BF9: =$D$13*(1+$AW9) -> 605.472 | BG9: =$E$13*(1+$AW9) -> 1579.612 | BH9: {=IF($F$13-$I$4+VLOOKUP($Q9,武学奇术!$A:$ZZ,13,FALSE)+SUM(_xlfn.XLOOKUP($R9:$AK9,增益!$A:$A,增益!$M:$M,0))>0,($F$13-$I$4+VLOOKUP($Q9,武学奇术!$A:$ZZ,13,FALSE)+SUM(_xlfn.XLOOKUP($R9:$AK9,增益!$A:$A,增益!$K:$K,0)))/200,($F$13-$I$4+VLOOKUP($Q9,武学奇术!$A:$ZZ,13,FALSE)+SUM(_xlfn.XLOOKUP($R9:$AK9,增益!$A:$A,增益!$M:$M,0)))/100)} -> 0 | BI9: {=$G$13+VLOOKUP($Q9,武学奇术!$A:$ZZ,14,FALSE)+SUM(_xlfn.XLOOKUP($R9:$AK9,增益!$A:$A,增益!$N:$N,0))} -> 0.15 | BJ9: =$D$14*(1+$AW9) -> 0 | BK9: =$E$14*(1+$AW9) -> 0 | BL9: {=IF($F$14-$I$4+VLOOKUP($Q9,武学奇术!$A:$ZZ,15,FALSE)+SUM(_xlfn.XLOOKUP($R9:$AK9,增益!$A:$A,增益!$O:$O,0))>0,($F$14-$I$4+VLOOKUP($Q9,武学奇术!$A:$ZZ,15,FALSE)+SUM(_xlfn.XLOOKUP($R9:$AK9,增益!$A:$A,增益!$O:$O,0)))/200,($F$14-$I$4+VLOOKUP($Q9,武学奇术!$A:$ZZ,15,FALSE)+SUM(_xlfn.XLOOKUP($R9:$AK9,增益!$A:$A,增益!$O:$O,0)))/100)} -> -0.3 | BM9: {=$G$14+VLOOKUP($Q9,武学奇术!$A:$ZZ,16,FALSE)+SUM(_xlfn.XLOOKUP($R9:$AK9,增益!$A:$A,增益!$P:$P,0))} -> 0 | BN9: =MIN(IF(VLOOKUP($Q9,武学奇术!$A:$ZZ,23,FALSE)=1,100%,$B$8),100%) -> 1 | BO9: {=IF(VLOOKUP($Q9,武学奇术!$A:$ZZ,23,FALSE)=1,100%,MIN(80%,$B$9+VLOOKUP($Q9,武学奇术!$A:$ZZ,17,FALSE)+SUM(_xlfn.XLOOKUP($R9:$AK9,增益!$A:$A,增益!$Q:$Q,0)))+$B$11+SUM(_xlfn.XLOOKUP($R9:$AK9,增益!$A:$A,增益!$U:$U,0)))*IF(VLOOKUP($Q9,武学奇术!$A:$ZZ,24,FALSE)=1,0,1)} -> 0.9093 | BP9: {=1+$B$13+VLOOKUP($Q9,武学奇术!$A:$ZZ,18,FALSE)+SUM(_xlfn.XLOOKUP($R9:$AK9,增益!$A:$A,增益!$R:$R,0))} -> 1.51 | BQ9: {=IF(VLOOKUP($Q9,武学奇术!$A:$ZZ,24,FALSE)=1,100%,MIN(40%,$B$10+VLOOKUP($Q9,武学奇术!$A:$ZZ,19,FALSE)+SUM(_xlfn.XLOOKUP($R9:$AK9,增益!$A:$A,增益!$S:$S,0)))+$B$12+SUM(_xlfn.XLOOKUP($R9:$AK9,增益!$A:$A,增益!$V:$V,0)))*IF(VLOOKUP($Q9,武学奇术!$A:$ZZ,23,FALSE)=1,0,1)} -> 0.0929 | BR9: {=1+$B$14+VLOOKUP($Q9,武学奇术!$A:$ZZ,20,FALSE)+SUM(_xlfn.XLOOKUP($R9:$AK9,增益!$A:$A,增益!$T:$T,0))} -> 1.35 | BS9: =MIN((1-BQ9)*BN9,BN9*BO9) -> 0.9071 | BT9: =1-BQ9-BS9-BU9 -> 0 | BU9: =IF(VLOOKUP($Q9,武学奇术!$A:$ZZ,22,FALSE)=1,0,(1-$BN9))*(1-$BQ9) -> 0 | BV9: {=SUM(_xlfn.XLOOKUP($R9:$AK9,增益!$A:$A,增益!$W:$W,0))+$I$5} -> 0.06
A10: 会意率 | B10: 0.0929 | C10: 外功 | D10: =(B2+B23)*IF($G$2="撼天",1.06,1) -> 4356.388 | E10: =MAX(B2+B23,C2+B24)*IF($G$2="撼天",1.06,1) -> 4356.388 | F10: =D2 -> 63.5 | G10: =E2 -> 0 | H10: 总伤 | I10: =SUM(K:K) -> 15323521 | K10: =($L10*$BS10+$M10*$BQ10+$N10*$BT10+$O10*$BU10) -> 12086.708 | L10: =((($AS10+$AT10)/2*$AM10+$AN10)*(1+$AU10)*(1+$AV10)+(($AX10+$AY10)/2*IF($G$1="鸣金",$AO10,$AM10)+IF($G$1="鸣金",$AP10*1.5,0))*(1+$AZ10)*(1+$BA10)+(($BB10+$BC10)/2*IF($G$1="裂石",$AO10,$AM10)+IF($G$1="裂石",$AP10*1.5,0))*(1+$BD10)*(1+$BE10)+(($BF10+$BG10)/2*IF($G$1="牵丝",$AO10,$AM10)+IF($G$1="牵丝",$AP10*1.5,0))*(1+$BH10)*(1+$BI10)+(($BJ10+$BK10)/2*IF($G$1="破竹",$AO10,$AM10)+IF($G$1="破竹",$AP10*1.5,0))*(1+$BL10)*(1+$BM10))*(1+$AQ10)*$BP10*$P10*(1+IF(VLOOKUP($Q10,武学奇术!$A:$ZZ,30,FALSE)="弹道",$B$21,0))*(1+$BV10) -> 12101.45 | M10: =(($AT10*$AM10+$AN10)*(1+$AU10)*(1+$AV10)+($AY10*IF($G$1="鸣金",$AO10,$AM10)+IF($G$1="鸣金",$AP10*1.5,0))*(1+$AZ10)*(1+$BA10)+($BC10*IF($G$1="裂石",$AO10,$AM10)+IF($G$1="裂石",$AP10*1.5,0))*(1+$BD10)*(1+$BE10)+($BG10*IF($G$1="牵丝",$AO10,$AM10)+IF($G$1="牵丝",$AP10*1.5,0))*(1+$BH10)*(1+$BI10)+($BK10*IF($G$1="破竹",$AO10,$AM10)+IF($G$1="破竹",$AP10*1.5,0))*(1+$BL10)*(1+$BM10))*(1+$AQ10)*$BR10*$P10*(1+IF(VLOOKUP($Q10,武学奇术!$A:$ZZ,30,FALSE)="弹道",$B$21,0))*(1+$BV10) -> 11942.761 | N10: =((($AS10+$AT10)/2*$AM10+$AN10)*(1+$AU10)*(1+$AV10)+(($AX10+$AY10)/2*IF($G$1="鸣金",$AO10,$AM10)+IF($G$1="鸣金",$AP10*1.5,0))*(1+$AZ10)*(1+$BA10)+(($BB10+$BC10)/2*IF($G$1="裂石",$AO10,$AM10)+IF($G$1="裂石",$AP10*1.5,0))*(1+$BD10)*(1+$BE10)+(($BF10+$BG10)/2*IF($G$1="牵丝",$AO10,$AM10)+IF($G$1="牵丝",$AP10*1.5,0))*(1+$BH10)*(1+$BI10)+(($BJ10+$BK10)/2*IF($G$1="破竹",$AO10,$AM10)+IF($G$1="破竹",$AP10*1.5,0))*(1+$BL10)*(1+$BM10))*(1+$AQ10)*$P10*(1+IF(VLOOKUP($Q10,武学奇术!$A:$ZZ,30,FALSE)="弹道",$B$21,0))*(1+$BV10) -> 7961.4801 | O10: =((($AS10*$AM10+$AN10)*(1+$AU10)*(1+$AV10)+($AX10*IF($G$1="鸣金",$AO10,$AM10)+IF($G$1="鸣金",$AP10*1.5,0))*(1+$AZ10)*(1+$BA10)+($BB10*IF($G$1="裂石",$AO10,$AM10)+IF($G$1="裂石",$AP10*1.5,0))*(1+$BD10)*(1+$BE10)+($BF10*IF($G$1="牵丝",$AO10,$AM10)+IF($G$1="牵丝",$AP10*1.5,0))*(1+$BH10)*(1+$BI10)+($BJ10*IF($G$1="破竹",$AO10,$AM10)+IF($G$1="破竹",$AP10*1.5,0))*(1+$BL10)*(1+$BM10))*(1+$AQ10))*$P10*(1+IF(VLOOKUP($Q10,武学奇术!$A:$ZZ,30,FALSE)="弹道",$B$21,0))*(1+$BV10) -> 7076.4706 | P10: 1 | Q10: 丢伞 | R10: 易水歌2层 | S10: 沧海帖2层 | T10: N/a | U10: N/a | V10: N/a | W10: N/a | X10: N/a | Y10: N/a | Z10: N/a | AA10: 近战笛 | AB10: 惧刃(拐) | AC10: N/a | AD10: N/a | AE10: N/a | AF10: N/a | AG10: N/a | AH10: N/a | AI10: N/a | AJ10: N/a | AK10: N/a | AL10: =VLOOKUP($Q10,武学奇术!$A:$ZZ,25,FALSE) -> 伞 | AM10: =VLOOKUP($Q10,武学奇术!$A:$ZZ,26,FALSE) -> 0.54 | AN10: =VLOOKUP($Q10,武学奇术!$A:$ZZ,27,FALSE)*(1+IF(OR($AL10=$F$4,$AL10=$F$5),$B$22,0)) -> 222 | AO10: =VLOOKUP($Q10,武学奇术!$A:$ZZ,28,FALSE) -> 0.81 | AP10: =VLOOKUP($Q10,武学奇术!$A:$ZZ,29,FALSE)*(1+IF(OR($AL10=$F$4,$AL10=$F$5),$B$22,0)) -> 122.25 | AQ10: {=$G$3+IFERROR(VLOOKUP($AL10,$F$4:$G$7,2,FALSE),0)+VLOOKUP($Q10,武学奇术!$A:$ZZ,2,FALSE)+SUM(_xlfn.XLOOKUP($R10:$AK10,增益!$A:$A,增益!$B:$B,0))} -> 0.3941 | AR10: {=VLOOKUP($Q10,武学奇术!$A:$ZZ,5,FALSE)+SUM(_xlfn.XLOOKUP($R10:$AK10,增益!$A:$A,增益!$E:$E,0))} -> 0 | AS10: {=$D$10*(1+$AR10)+VLOOKUP($Q10,武学奇术!$A:$ZZ,3,FALSE)+SUM(_xlfn.XLOOKUP($R10:$AK10,增益!$A:$A,增益!$C:$C,0))-$I$2} -> 3773.588 | AT10: {=$E$10*(1+$AR10)+VLOOKUP($Q10,武学奇术!$A:$ZZ,4,FALSE)+SUM(_xlfn.XLOOKUP($R10:$AK10,增益!$A:$A,增益!$D:$D,0))-$I$2} -> 3773.588 | AU10: {=IF($F$10-$I$3+VLOOKUP($Q10,武学奇术!$A:$ZZ,6,FALSE)+SUM(_xlfn.XLOOKUP($R10:$AK10,增益!$A:$A,增益!$F:$F,0))>0,($F$10-$I$3+VLOOKUP($Q10,武学奇术!$A:$ZZ,6,FALSE)+SUM(_xlfn.XLOOKUP($R10:$AK10,增益!$A:$A,增益!$F:$F,0)))/200,($F$10-$I$3+VLOOKUP($Q10,武学奇术!$A:$ZZ,6,FALSE)+SUM(_xlfn.XLOOKUP($R10:$AK10,增益!$A:$A,增益!$F:$F,0)))/100)} -> 0.2625 | AV10: {=$G$10+VLOOKUP($Q10,武学奇术!$A:$ZZ,7,FALSE)+SUM(_xlfn.XLOOKUP($R10:$AK10,增益!$A:$A,增益!$G:$G,0))} -> 0 | AW10: {=VLOOKUP($Q10,武学奇术!$A:$ZZ,8,FALSE)+SUM(_xlfn.XLOOKUP($R10:$AK10,增益!$A:$A,增益!$H:$H,0))} -> 0 | AX10: =$D$11*(1+$AW10) -> 0 | AY10: =$E$11*(1+$AW10) -> 0 | AZ10: {=IF($F$11-$I$4+VLOOKUP($Q10,武学奇术!$A:$ZZ,9,FALSE)+SUM(_xlfn.XLOOKUP($R10:$AK10,增益!$A:$A,增益!$I:$I,0))>0,($F$11-$I$4+VLOOKUP($Q10,武学奇术!$A:$ZZ,9,FALSE)+SUM(_xlfn.XLOOKUP($R10:$AK10,增益!$A:$A,增益!$I:$I,0)))/200,($F$11-$I$4+VLOOKUP($Q10,武学奇术!$A:$ZZ,9,FALSE)+SUM(_xlfn.XLOOKUP($R10:$AK10,增益!$A:$A,增益!$I:$I,0)))/100)} -> -0.3 | BA10: {=$G$11+VLOOKUP($Q10,武学奇术!$A:$ZZ,10,FALSE)+SUM(_xlfn.XLOOKUP($R10:$AK10,增益!$A:$A,增益!$J:$J,0))} -> 0 | BB10: =$D$12*(1+$AW10) -> 0 | BC10: =$E$12*(1+$AW10) -> 0 | BD10: {=IF($F$12-$I$4+VLOOKUP($Q10,武学奇术!$A:$ZZ,11,FALSE)+SUM(_xlfn.XLOOKUP($R10:$AK10,增益!$A:$A,增益!$K:$K,0))>0,($F$12-$I$4+VLOOKUP($Q10,武学奇术!$A:$ZZ,11,FALSE)+SUM(_xlfn.XLOOKUP($R10:$AK10,增益!$A:$A,增益!$K:$K,0)))/200,($F$12-$I$4+VLOOKUP($Q10,武学奇术!$A:$ZZ,11,FALSE)+SUM(_xlfn.XLOOKUP($R10:$AK10,增益!$A:$A,增益!$K:$K,0)))/100)} -> -0.3 | BE10: {=$G$12+VLOOKUP($Q10,武学奇术!$A:$ZZ,12,FALSE)+SUM(_xlfn.XLOOKUP($R10:$AK10,增益!$A:$A,增益!$L:$L,0))} -> 0 | BF10: =$D$13*(1+$AW10) -> 605.472 | BG10: =$E$13*(1+$AW10) -> 1579.612 | BH10: {=IF($F$13-$I$4+VLOOKUP($Q10,武学奇术!$A:$ZZ,13,FALSE)+SUM(_xlfn.XLOOKUP($R10:$AK10,增益!$A:$A,增益!$M:$M,0))>0,($F$13-$I$4+VLOOKUP($Q10,武学奇术!$A:$ZZ,13,FALSE)+SUM(_xlfn.XLOOKUP($R10:$AK10,增益!$A:$A,增益!$K:$K,0)))/200,($F$13-$I$4+VLOOKUP($Q10,武学奇术!$A:$ZZ,13,FALSE)+SUM(_xlfn.XLOOKUP($R10:$AK10,增益!$A:$A,增益!$M:$M,0)))/100)} -> 0 | BI10: {=$G$13+VLOOKUP($Q10,武学奇术!$A:$ZZ,14,FALSE)+SUM(_xlfn.XLOOKUP($R10:$AK10,增益!$A:$A,增益!$N:$N,0))} -> 0.15 | BJ10: =$D$14*(1+$AW10) -> 0 | BK10: =$E$14*(1+$AW10) -> 0 | BL10: {=IF($F$14-$I$4+VLOOKUP($Q10,武学奇术!$A:$ZZ,15,FALSE)+SUM(_xlfn.XLOOKUP($R10:$AK10,增益!$A:$A,增益!$O:$O,0))>0,($F$14-$I$4+VLOOKUP($Q10,武学奇术!$A:$ZZ,15,FALSE)+SUM(_xlfn.XLOOKUP($R10:$AK10,增益!$A:$A,增益!$O:$O,0)))/200,($F$14-$I$4+VLOOKUP($Q10,武学奇术!$A:$ZZ,15,FALSE)+SUM(_xlfn.XLOOKUP($R10:$AK10,增益!$A:$A,增益!$O:$O,0)))/100)} -> -0.3 | BM10: {=$G$14+VLOOKUP($Q10,武学奇术!$A:$ZZ,16,FALSE)+SUM(_xlfn.XLOOKUP($R10:$AK10,增益!$A:$A,增益!$P:$P,0))} -> 0 | BN10: =MIN(IF(VLOOKUP($Q10,武学奇术!$A:$ZZ,23,FALSE)=1,100%,$B$8),100%) -> 1 | BO10: {=IF(VLOOKUP($Q10,武学奇术!$A:$ZZ,23,FALSE)=1,100%,MIN(80%,$B$9+VLOOKUP($Q10,武学奇术!$A:$ZZ,17,FALSE)+SUM(_xlfn.XLOOKUP($R10:$AK10,增益!$A:$A,增益!$Q:$Q,0)))+$B$11+SUM(_xlfn.XLOOKUP($R10:$AK10,增益!$A:$A,增益!$U:$U,0)))*IF(VLOOKUP($Q10,武学奇术!$A:$ZZ,24,FALSE)=1,0,1)} -> 0.9093 | BP10: {=1+$B$13+VLOOKUP($Q10,武学奇术!$A:$ZZ,18,FALSE)+SUM(_xlfn.XLOOKUP($R10:$AK10,增益!$A:$A,增益!$R:$R,0))} -> 1.52 | BQ10: {=IF(VLOOKUP($Q10,武学奇术!$A:$ZZ,24,FALSE)=1,100%,MIN(40%,$B$10+VLOOKUP($Q10,武学奇术!$A:$ZZ,19,FALSE)+SUM(_xlfn.XLOOKUP($R10:$AK10,增益!$A:$A,增益!$S:$S,0)))+$B$12+SUM(_xlfn.XLOOKUP($R10:$AK10,增益!$A:$A,增益!$V:$V,0)))*IF(VLOOKUP($Q10,武学奇术!$A:$ZZ,23,FALSE)=1,0,1)} -> 0.0929 | BR10: {=1+$B$14+VLOOKUP($Q10,武学奇术!$A:$ZZ,20,FALSE)+SUM(_xlfn.XLOOKUP($R10:$AK10,增益!$A:$A,增益!$T:$T,0))} -> 1.35 | BS10: =MIN((1-BQ10)*BN10,BN10*BO10) -> 0.9071 | BT10: =1-BQ10-BS10-BU10 -> 0 | BU10: =IF(VLOOKUP($Q10,武学奇术!$A:$ZZ,22,FALSE)=1,0,(1-$BN10))*(1-$BQ10) -> 0 | BV10: {=SUM(_xlfn.XLOOKUP($R10:$AK10,增益!$A:$A,增益!$W:$W,0))+$I$5} -> 0.06
