Workbook

Sheet 期望
B1: 最小攻击 | C1: 最大攻击 | D1: 穿透 | E1: 伤害加成 | F1: 武学属性 | G1: 破竹 | H1: 怪物属性 | K1: 真气比列 | L1: 期望 | M1: 会心期望 | N1: 会意期望 | O1: 普通期望 | P1: 擦伤期望 | Q1: 次数 | R1: 技能 | S1: 增益1 | T1: 增益2 | U1: 增益3 | V1: 增益4 | W1: 增益5 | X1: 增益6 | Y1: 增益7 | Z1: 增益8 | AA1: 增益9 | AB1: 增益10 | AC1: 增益11 | AD1: 增益12 | AE1: 增益13 | AF1: 增益14 | AG1: 增益15 | AH1: 增益16 | AI1: 增益17 | AJ1: 增益18 | AK1: 增益19 | AL1: 增益20 | AM1: 类型 | AN1: 外功倍率 | AO1: 外攻固伤 | AP1: 属性倍率 | AQ1: 属性固伤 | AR1: 通用增伤 | AS1: 外攻加成 | AT1: 即时小外 | AU1: 即时大外 | AV1: 外穿加成 | AW1: 外伤加成 | AX1: 属攻加成 | AY1: 即时小鸣 | AZ1: 即时大鸣 | BA1: 鸣金穿透 | BB1: 鸣金加成 | BC1: 即时小裂 | BD1: 即时大裂 | BE1: 裂石穿透 | BF1: 裂石加成 | BG1: 即时小牵 | BH1: 即时大牵 | BI1: 牵丝穿透 | BJ1: 牵丝加成 | BK1: 即时小破 | BL1: 即时大破 | BM1: 破竹穿透 | BN1: 破竹加成 | BO1: 生效精准 | BP1: 生效会心 | BQ1: 生效会心伤害 | BR1: 生效会意 | BS1: 生效会意伤害 | BT1: 会心占比 | BU1: 普攻占比 | BV1: 擦伤占比 | BW1: 特殊增伤 | BX1: 结算增伤
A2: 外功 | B2: 3994.6 | C2: 3083.9 | D2: 63.5 | E2: =2.8%+IF(E24="所恨年年",2.5%,0) -> 0.028 | F2: 套装 | G2: 连星 | H2: 防御 | I2: =620*(1-IF(F17="√",0.06,0)-IF(D20="√",0.04,0)) -> 558 | K2: =$L2*VLOOKUP($R2,武学奇术!$A:$ZZ,31,FALSE) -> 26183.896 | L2: =($M2*$BT2+$N2*$BR2+$O2*$BU2+$P2*$BV2) -> 24937.043 | M2: =((($AT2+$AU2)/2*$AN2+$AO2)*(1+$AV2)*(1+$AW2)+(($AY2+$AZ2)/2*IF($G$1="鸣金",$AP2,$AN2)+IF($G$1="鸣金",$AQ2*1.5,0))*(1+$BA2)*(1+$BB2)+(($BC2+$BD2)/2*IF($G$1="裂石",$AP2,$AN2)+IF($G$1="裂石",$AQ2*1.5,0))*(1+$BE2)*(1+$BF2)+(($BG2+$BH2)/2*IF($G$1="牵丝",$AP2,$AN2)+IF($G$1="牵丝",$AQ2*1.5,0))*(1+$BI2)*(1+$BJ2)+(($BK2+$BL2)/2*IF($G$1="破竹",$AP2,$AN2)+IF($G$1="破竹",$AQ2*1.5,0))*(1+$BM2)*(1+$BN2))*(1+$AR2)*$BQ2*$Q2*(1+IF(VLOOKUP($R2,武学奇术!$A:$ZZ,30,FALSE)="回旋伞",$B$21,0))*(1+$BW2) -> 26274.887 | N2: =(($AU2*$AN2+$AO2)*(1+$AV2)*(1+$AW2)+($AZ2*IF($G$1="鸣金",$AP2,$AN2)+IF($G$1="鸣金",$AQ2*1.5,0))*(1+$BA2)*(1+$BB2)+($BD2*IF($G$1="裂石",$AP2,$AN2)+IF($G$1="裂石",$AQ2*1.5,0))*(1+$BE2)*(1+$BF2)+($BH2*IF($G$1="牵丝",$AP2,$AN2)+IF($G$1="牵丝",$AQ2*1.5,0))*(1+$BI2)*(1+$BJ2)+($BL2*IF($G$1="破竹",$AP2,$AN2)+IF($G$1="破竹",$AQ2*1.5,0))*(1+$BM2)*(1+$BN2))*(1+$AR2)*$BS2*$Q2*(1+IF(VLOOKUP($R2,武学奇术!$A:$ZZ,30,FALSE)="回旋伞",$B$21,0))*(1+$BW2) -> 22061.628 | O2: =((($AT2+$AU2)/2*$AN2+$AO2)*(1+$AV2)*(1+$AW2)+(($AY2+$AZ2)/2*IF($G$1="鸣金",$AP2,$AN2)+IF($G$1="鸣金",$AQ2*1.5,0))*(1+$BA2)*(1+$BB2)+(($BC2+$BD2)/2*IF($G$1="裂石",$AP2,$AN2)+IF($G$1="裂石",$AQ2*1.5,0))*(1+$BE2)*(1+$BF2)+(($BG2+$BH2)/2*IF($G$1="牵丝",$AP2,$AN2)+IF($G$1="牵丝",$AQ2*1.5,0))*(1+$BI2)*(1+$BJ2)+(($BK2+$BL2)/2*IF($G$1="破竹",$AP2,$AN2)+IF($G$1="破竹",$AQ2*1.5,0))*(1+$BM2)*(1+$BN2))*(1+$AR2)*$Q2*(1+IF(VLOOKUP($R2,武学奇术!$A:$ZZ,30,FALSE)="回旋伞",$B$21,0))*(1+$BW2) -> 14436.751 | P2: =((($AT2*$AN2+$AO2)*(1+$AV2)*(1+$AW2)+($AY2*IF($G$1="鸣金",$AP2,$AN2)+IF($G$1="鸣金",$AQ2*1.5,0))*(1+$BA2)*(1+$BB2)+($BC2*IF($G$1="裂石",$AP2,$AN2)+IF($G$1="裂石",$AQ2*1.5,0))*(1+$BE2)*(1+$BF2)+($BG2*IF($G$1="牵丝",$AP2,$AN2)+IF($G$1="牵丝",$AQ2*1.5,0))*(1+$BI2)*(1+$BJ2)+($BK2*IF($G$1="破竹",$AP2,$AN2)+IF($G$1="破竹",$AQ2*1.5,0))*(1+$BM2)*(1+$BN2))*(1+$AR2))*$Q2*(1+IF(VLOOKUP($R2,武学奇术!$A:$ZZ,30,FALSE)="回旋伞",$B$21,0))*(1+$BW2) -> 12531.556 | Q2: 1 | R2: 萧呤千浪流星 | S2: N/a | T2: N/a | U2: 失魂落魄 | V2: 近战笛 | W2: 沧海帖1层 | X2: 易水歌1层 | Y2: N/a | Z2: N/a | AA2: N/a | AB2: N/a | AC2: N/a | AD2: N/a | AE2: 离猎(拐) | AF2: 裁云(拐) | AG2: 无惧 | AH2: N/a | AI2: N/a | AJ2: N/a | AK2: N/a | AL2: N/a | AM2: =VLOOKUP($R2,武学奇术!$A:$ZZ,25,FALSE) -> 群体奇术 | AN2: =VLOOKUP($R2,武学奇术!$A:$ZZ,26,FALSE) -> 1.4904 | AO2: =VLOOKUP($R2,武学奇术!$A:$ZZ,27,FALSE)*(1+IF(OR($AM2=$F$4,$AM2=$F$5),$B$22,0)) -> 378 | AP2: =VLOOKUP($R2,武学奇术!$A:$ZZ,28,FALSE) -> 2.2356 | AQ2: =VLOOKUP($R2,武学奇术!$A:$ZZ,29,FALSE)*(1+IF(OR($AM2=$F$4,$AM2=$F$5),$B$22,0)) -> 0 | AR2: {=$G$3+IFERROR(VLOOKUP($AM2,$F$4:$G$7,2,FALSE),0)+VLOOKUP($R2,武学奇术!$A:$ZZ,2,FALSE)+SUM(_xlfn.XLOOKUP($S2:$AL2,增益!$A:$A,增益!$B:$B,0))} -> 0.2637 | AS2: {=VLOOKUP($R2,武学奇术!$A:$ZZ,5,FALSE)+SUM(_xlfn.XLOOKUP($S2:$AL2,增益!$A:$A,增益!$E:$E,0))} -> 0 | AT2: {=$D$10*(1+$AS2)+VLOOKUP($R2,武学奇术!$A:$ZZ,3,FALSE)+SUM(_xlfn.XLOOKUP($S2:$AL2,增益!$A:$A,增益!$C:$C,0))-$I$2} -> 3636.6 | AU2: {=$E$10*(1+$AS2)+VLOOKUP($R2,武学奇术!$A:$ZZ,4,FALSE)+SUM(_xlfn.XLOOKUP($S2:$AL2,增益!$A:$A,增益!$D:$D,0))-$I$2} -> 3636.6 | AV2: {=IF($F$10-$I$3+VLOOKUP($R2,武学奇术!$A:$ZZ,6,FALSE)+SUM(_xlfn.XLOOKUP($S2:$AL2,增益!$A:$A,增益!$F:$F,0))>0,($F$10-$I$3+VLOOKUP($R2,武学奇术!$A:$ZZ,6,FALSE)+SUM(_xlfn.XLOOKUP($S2:$AL2,增益!$A:$A,增益!$F:$F,0)))/200,($F$10-$I$3+VLOOKUP($R2,武学奇术!$A:$ZZ,6,FALSE)+SUM(_xlfn.XLOOKUP($S2:$AL2,增益!$A:$A,增益!$F:$F,0)))/100)} -> 0.2525 | AW2: {=$G$10+VLOOKUP($R2,武学奇术!$A:$ZZ,7,FALSE)+SUM(_xlfn.XLOOKUP($S2:$AL2,增益!$A:$A,增益!$G:$G,0))} -> 0.028 | AX2: {=VLOOKUP($R2,武学奇术!$A:$ZZ,8,FALSE)+SUM(_xlfn.XLOOKUP($S2:$AL2,增益!$A:$A,增益!$H:$H,0))} -> 0 | AY2: =$D$11*(1+$AX2) -> 0 | AZ2: =$E$11*(1+$AX2) -> 0 | BA2: {=IF($F$11-$I$4+VLOOKUP($R2,武学奇术!$A:$ZZ,9,FALSE)+SUM(_xlfn.XLOOKUP($S2:$AL2,增益!$A:$A,增益!$I:$I,0))>0,($F$11-$I$4+VLOOKUP($R2,武学奇术!$A:$ZZ,9,FALSE)+SUM(_xlfn.XLOOKUP($S2:$AL2,增益!$A:$A,增益!$I:$I,0)))/200,($F$11-$I$4+VLOOKUP($R2,武学奇术!$A:$ZZ,9,FALSE)+SUM(_xlfn.XLOOKUP($S2:$AL2,增益!$A:$A,增益!$I:$I,0)))/100)} -> -0.3 | BB2: {=$G$11+VLOOKUP($R2,武学奇术!$A:$ZZ,10,FALSE)+SUM(_xlfn.XLOOKUP($S2:$AL2,增益!$A:$A,增益!$J:$J,0))} -> 0 | BC2: =$D$12*(1+$AX2) -> 0 | BD2: =$E$12*(1+$AX2) -> 0 | BE2: {=IF($F$12-$I$4+VLOOKUP($R2,武学奇术!$A:$ZZ,11,FALSE)+SUM(_xlfn.XLOOKUP($S2:$AL2,增益!$A:$A,增益!$K:$K,0))>0,($F$12-$I$4+VLOOKUP($R2,武学奇术!$A:$ZZ,11,FALSE)+SUM(_xlfn.XLOOKUP($S2:$AL2,增益!$A:$A,增益!$K:$K,0)))/200,($F$12-$I$4+VLOOKUP($R2,武学奇术!$A:$ZZ,11,FALSE)+SUM(_xlfn.XLOOKUP($S2:$AL2,增益!$A:$A,增益!$K:$K,0)))/100)} -> -0.3 | BF2: {=$G$12+VLOOKUP($R2,武学奇术!$A:$ZZ,12,FALSE)+SUM(_xlfn.XLOOKUP($S2:$AL2,增益!$A:$A,增益!$L:$L,0))} -> 0 | BG2: =$D$13*(1+$AX2) -> 0 | BH2: =$E$13*(1+$AX2) -> 0 | BI2: {=IF($F$13-$I$4+VLOOKUP($R2,武学奇术!$A:$ZZ,13,FALSE)+SUM(_xlfn.XLOOKUP($S2:$AL2,增益!$A:$A,增益!$M:$M,0))>0,($F$13-$I$4+VLOOKUP($R2,武学奇术!$A:$ZZ,13,FALSE)+SUM(_xlfn.XLOOKUP($S2:$AL2,增益!$A:$A,增益!$K:$K,0)))/200,($F$13-$I$4+VLOOKUP($R2,武学奇术!$A:$ZZ,13,FALSE)+SUM(_xlfn.XLOOKUP($S2:$AL2,增益!$A:$A,增益!$M:$M,0)))/100)} -> -0.3 | BJ2: {=$G$13+VLOOKUP($R2,武学奇术!$A:$ZZ,14,FALSE)+SUM(_xlfn.XLOOKUP($S2:$AL2,增益!$A:$A,增益!$N:$N,0))} -> 0 | BK2: =$D$14*(1+$AX2) -> 571.2 | BL2: =$E$14*(1+$AX2) -> 1627.8 | BM2: {=IF($F$14-$I$4+VLOOKUP($R2,武学奇术!$A:$ZZ,15,FALSE)+SUM(_xlfn.XLOOKUP($S2:$AL2,增益!$A:$A,增益!$O:$O,0))>0,($F$14-$I$4+VLOOKUP($R2,武学奇术!$A:$ZZ,15,FALSE)+SUM(_xlfn.XLOOKUP($S2:$AL2,增益!$A:$A,增益!$O:$O,0)))/200,($F$14-$I$4+VLOOKUP($R2,武学奇术!$A:$ZZ,15,FALSE)+SUM(_xlfn.XLOOKUP($S2:$AL2,增益!$A:$A,增益!$O:$O,0)))/100)} -> 0 | BN2: {=$G$14+VLOOKUP($R2,武学奇术!$A:$ZZ,16,FALSE)+SUM(_xlfn.XLOOKUP($S2:$AL2,增益!$A:$A,增益!$P:$P,0))} -> 0.15 | BO2: =MIN(IF(VLOOKUP($R2,武学奇术!$A:$ZZ,23,FALSE)=1,100%,$B$8),100%) -> 0.981 | BP2: {=IF(VLOOKUP($R2,武学奇术!$A:$ZZ,23,FALSE)=1,100%,MIN(80%,$B$9+VLOOKUP($R2,武学奇术!$A:$ZZ,17,FALSE)+SUM(_xlfn.XLOOKUP($S2:$AL2,增益!$A:$A,增益!$Q:$Q,0)))+$B$11+SUM(_xlfn.XLOOKUP($S2:$AL2,增益!$A:$A,增益!$U:$U,0)))*IF(VLOOKUP($R2,武学奇术!$A:$ZZ,24,FALSE)=1,0,1)} -> 0.846 | BQ2: {=1+$B$13+VLOOKUP($R2,武学奇术!$A:$ZZ,18,FALSE)+SUM(_xlfn.XLOOKUP($S2:$AL2,增益!$A:$A,增益!$R:$R,0))} -> 1.82 | BR2: {=IF(VLOOKUP($R2,武学奇术!$A:$ZZ,24,FALSE)=1,100%,MIN(40%,$B$10+VLOOKUP($R2,武学奇术!$A:$ZZ,19,FALSE)+SUM(_xlfn.XLOOKUP($S2:$AL2,增益!$A:$A,增益!$S:$S,0)))+$B$12+SUM(_xlfn.XLOOKUP($S2:$AL2,增益!$A:$A,增益!$V:$V,0)))*IF(VLOOKUP($R2,武学奇术!$A:$ZZ,23,FALSE)=1,0,1)} -> 0.0929 | BS2: {=1+$B$14+VLOOKUP($R2,武学奇术!$A:$ZZ,20,FALSE)+SUM(_xlfn.XLOOKUP($S2:$AL2,增益!$A:$A,增益!$T:$T,0))} -> 1.35 | BT2: =MIN((1-BR2)*BO2,BO2*BP2) -> 0.829926 | BU2: =1-BR2-BT2-BV2 -> 0.0599391 | BV2: =IF(VLOOKUP($R2,武学奇术!$A:$ZZ,22,FALSE)=1,0,(1-$BO2))*(1-$BR2) -> 0.0172349 | BW2: {=SUM(_xlfn.XLOOKUP($S2:$AL2,增益!$A:$A,增益!$W:$W,0))+$I$5} -> 0.11 | BX2: {=SUM(_xlfn.XLOOKUP($S2:$AL2,增益!$A:$A,增益!$X:$X,0))} -> 0
A3: 鸣金 | F3: 通用增伤 | G3: =B16+1.5%+IF($D$16="√",8%,0)+IF($E$24="征人归",8%,0) -> 0.1837 | H3: 外抗 | I3: =25-IF(F17="√",10,0) -> 15 | K3: =$L3*VLOOKUP($R3,武学奇术!$A:$ZZ,31,FALSE) -> 31118.697 | L3: =($M3*$BT3+$N3*$BR3+$O3*$BU3+$P3*$BV3) -> 29636.854 | M3: =((($AT3+$AU3)/2*$AN3+$AO3)*(1+$AV3)*(1+$AW3)+(($AY3+$AZ3)/2*IF($G$1="鸣金",$AP3,$AN3)+IF($G$1="鸣金",$AQ3*1.5,0))*(1+$BA3)*(1+$BB3)+(($BC3+$BD3)/2*IF($G$1="裂石",$AP3,$AN3)+IF($G$1="裂石",$AQ3*1.5,0))*(1+$BE3)*(1+$BF3)+(($BG3+$BH3)/2*IF($G$1="牵丝",$AP3,$AN3)+IF($G$1="牵丝",$AQ3*1.5,0))*(1+$BI3)*(1+$BJ3)+(($BK3+$BL3)/2*IF($G$1="破竹",$AP3,$AN3)+IF($G$1="破竹",$AQ3*1.5,0))*(1+$BM3)*(1+$BN3))*(1+$AR3)*$BQ3*$Q3*(1+IF(VLOOKUP($R3,武学奇术!$A:$ZZ,30,FALSE)="回旋伞",$B$21,0))*(1+$BW3) -> 31235.218 | N3: =(($AU3*$AN3+$AO3)*(1+$AV3)*(1+$AW3)+($AZ3*IF($G$1="鸣金",$AP3,$AN3)+IF($G$1="鸣金",$AQ3*1.5,0))*(1+$BA3)*(1+$BB3)+($BD3*IF($G$1="裂石",$AP3,$AN3)+IF($G$1="裂石",$AQ3*1.5,0))*(1+$BE3)*(1+$BF3)+($BH3*IF($G$1="牵丝",$AP3,$AN3)+IF($G$1="牵丝",$AQ3*1.5,0))*(1+$BI3)*(1+$BJ3)+($BL3*IF($G$1="破竹",$AP3,$AN3)+IF($G$1="破竹",$AQ3*1.5,0))*(1+$BM3)*(1+$BN3))*(1+$AR3)*$BS3*$Q3*(1+IF(VLOOKUP($R3,武学奇术!$A:$ZZ,30,FALSE)="回旋伞",$B$21,0))*(1+$BW3) -> 26237.793 | O3: =((($AT3+$AU3)/2*$AN3+$AO3)*(1+$AV3)*(1+$AW3)+(($AY3+$AZ3)/2*IF($G$1="鸣金",$AP3,$AN3)+IF($G$1="鸣金",$AQ3*1.5,0))*(1+$BA3)*(1+$BB3)+(($BC3+$BD3)/2*IF($G$1="裂石",$AP3,$AN3)+IF($G$1="裂石",$AQ3*1.5,0))*(1+$BE3)*(1+$BF3)+(($BG3+$BH3)/2*IF($G$1="牵丝",$AP3,$AN3)+IF($G$1="牵丝",$AQ3*1.5,0))*(1+$BI3)*(1+$BJ3)+(($BK3+$BL3)/2*IF($G$1="破竹",$AP3,$AN3)+IF($G$1="破竹",$AQ3*1.5,0))*(1+$BM3)*(1+$BN3))*(1+$AR3)*$Q3*(1+IF(VLOOKUP($R3,武学奇术!$A:$ZZ,30,FALSE)="回旋伞",$B$21,0))*(1+$BW3) -> 17068.425 | P3: =((($AT3*$AN3+$AO3)*(1+$AV3)*(1+$AW3)+($AY3*IF($G$1="鸣金",$AP3,$AN3)+IF($G$1="鸣金",$AQ3*1.5,0))*(1+$BA3)*(1+$BB3)+($BC3*IF($G$1="裂石",$AP3,$AN3)+IF($G$1="裂石",$AQ3*1.5,0))*(1+$BE3)*(1+$BF3)+($BG3*IF($G$1="牵丝",$AP3,$AN3)+IF($G$1="牵丝",$AQ3*1.5,0))*(1+$BI3)*(1+$BJ3)+($BK3*IF($G$1="破竹",$AP3,$AN3)+IF($G$1="破竹",$AQ3*1.5,0))*(1+$BM3)*(1+$BN3))*(1+$AR3))*$Q3*(1+IF(VLOOKUP($R3,武学奇术!$A:$ZZ,30,FALSE)="回旋伞",$B$21,0))*(1+$BW3) -> 14701.448 | Q3: 1 | R3: 萧呤千浪流星 | S3: N/a | T3: N/a | U3: 失魂落魄 | V3: 远程笛 | W3: 沧海帖2层 | X3: 易水歌2层 | Y3: 惧刃(拐) | Z3: N/a | AA3: N/a | AB3: N/a | AC3: 扶风(拐) | AD3: N/a | AE3: 离猎(拐) | AF3: 裁云(拐) | AG3: 无惧 | AH3: N/a | AI3: N/a | AJ3: N/a | AK3: N/a | AL3: N/a | AM3: =VLOOKUP($R3,武学奇术!$A:$ZZ,25,FALSE) -> 群体奇术 | AN3: =VLOOKUP($R3,武学奇术!$A:$ZZ,26,FALSE) -> 1.4904 | AO3: =VLOOKUP($R3,武学奇术!$A:$ZZ,27,FALSE)*(1+IF(OR($AM3=$F$4,$AM3=$F$5),$B$22,0)) -> 378 | AP3: =VLOOKUP($R3,武学奇术!$A:$ZZ,28,FALSE) -> 2.2356 | AQ3: =VLOOKUP($R3,武学奇术!$A:$ZZ,29,FALSE)*(1+IF(OR($AM3=$F$4,$AM3=$F$5),$B$22,0)) -> 0 | AR3: {=$G$3+IFERROR(VLOOKUP($AM3,$F$4:$G$7,2,FALSE),0)+VLOOKUP($R3,武学奇术!$A:$ZZ,2,FALSE)+SUM(_xlfn.XLOOKUP($S3:$AL3,增益!$A:$A,增益!$B:$B,0))} -> 0.4537 | AS3: {=VLOOKUP($R3,武学奇术!$A:$ZZ,5,FALSE)+SUM(_xlfn.XLOOKUP($S3:$AL3,增益!$A:$A,增益!$E:$E,0))} -> 0 | AT3: {=$D$10*(1+$AS3)+VLOOKUP($R3,武学奇术!$A:$ZZ,3,FALSE)+SUM(_xlfn.XLOOKUP($S3:$AL3,增益!$A:$A,增益!$C:$C,0))-$I$2} -> 3636.6 | AU3: {=$E$10*(1+$AS3)+VLOOKUP($R3,武学奇术!$A:$ZZ,4,FALSE)+SUM(_xlfn.XLOOKUP($S3:$AL3,增益!$A:$A,增益!$D:$D,0))-$I$2} -> 3636.6 | AV3: {=IF($F$10-$I$3+VLOOKUP($R3,武学奇术!$A:$ZZ,6,FALSE)+SUM(_xlfn.XLOOKUP($S3:$AL3,增益!$A:$A,增益!$F:$F,0))>0,($F$10-$I$3+VLOOKUP($R3,武学奇术!$A:$ZZ,6,FALSE)+SUM(_xlfn.XLOOKUP($S3:$AL3,增益!$A:$A,增益!$F:$F,0)))/200,($F$10-$I$3+VLOOKUP($R3,武学奇术!$A:$ZZ,6,FALSE)+SUM(_xlfn.XLOOKUP($S3:$AL3,增益!$A:$A,增益!$F:$F,0)))/100)} -> 0.2625 | AW3: {=$G$10+VLOOKUP($R3,武学奇术!$A:$ZZ,7,FALSE)+SUM(_xlfn.XLOOKUP($S3:$AL3,增益!$A:$A,增益!$G:$G,0))} -> 0.028 | AX3: {=VLOOKUP($R3,武学奇术!$A:$ZZ,8,FALSE)+SUM(_xlfn.XLOOKUP($S3:$AL3,增益!$A:$A,增益!$H:$H,0))} -> 0 | AY3: =$D$11*(1+$AX3) -> 0 | AZ3: =$E$11*(1+$AX3) -> 0 | BA3: {=IF($F$11-$I$4+VLOOKUP($R3,武学奇术!$A:$ZZ,9,FALSE)+SUM(_xlfn.XLOOKUP($S3:$AL3,增益!$A:$A,增益!$I:$I,0))>0,($F$11-$I$4+VLOOKUP($R3,武学奇术!$A:$ZZ,9,FALSE)+SUM(_xlfn.XLOOKUP($S3:$AL3,增益!$A:$A,增益!$I:$I,0)))/200,($F$11-$I$4+VLOOKUP($R3,武学奇术!$A:$ZZ,9,FALSE)+SUM(_xlfn.XLOOKUP($S3:$AL3,增益!$A:$A,增益!$I:$I,0)))/100)} -> -0.14 | BB3: {=$G$11+VLOOKUP($R3,武学奇术!$A:$ZZ,10,FALSE)+SUM(_xlfn.XLOOKUP($S3:$AL3,增益!$A:$A,增益!$J:$J,0))} -> 0 | BC3: =$D$12*(1+$AX3) -> 0 | BD3: =$E$12*(1+$AX3) -> 0 | BE3: {=IF($F$12-$I$4+VLOOKUP($R3,武学奇术!$A:$ZZ,11,FALSE)+SUM(_xlfn.XLOOKUP($S3:$AL3,增益!$A:$A,增益!$K:$K,0))>0,($F$12-$I$4+VLOOKUP($R3,武学奇术!$A:$ZZ,11,FALSE)+SUM(_xlfn.XLOOKUP($S3:$AL3,增益!$A:$A,增益!$K:$K,0)))/200,($F$12-$I$4+VLOOKUP($R3,武学奇术!$A:$ZZ,11,FALSE)+SUM(_xlfn.XLOOKUP($S3:$AL3,增益!$A:$A,增益!$K:$K,0)))/100)} -> -0.14 | BF3: {=$G$12+VLOOKUP($R3,武学奇术!$A:$ZZ,12,FALSE)+SUM(_xlfn.XLOOKUP($S3:$AL3,增益!$A:$A,增益!$L:$L,0))} -> 0 | BG3: =$D$13*(1+$AX3) -> 0 | BH3: =$E$13*(1+$AX3) -> 0 | BI3: {=IF($F$13-$I$4+VLOOKUP($R3,武学奇术!$A:$ZZ,13,FALSE)+SUM(_xlfn.XLOOKUP($S3:$AL3,增益!$A:$A,增益!$M:$M,0))>0,($F$13-$I$4+VLOOKUP($R3,武学奇术!$A:$ZZ,13,FALSE)+SUM(_xlfn.XLOOKUP($S3:$AL3,增益!$A:$A,增益!$K:$K,0)))/200,($F$13-$I$4+VLOOKUP($R3,武学奇术!$A:$ZZ,13,FALSE)+SUM(_xlfn.XLOOKUP($S3:$AL3,增益!$A:$A,增益!$M:$M,0)))/100)} -> -0.14 | BJ3: {=$G$13+VLOOKUP($R3,武学奇术!$A:$ZZ,14,FALSE)+SUM(_xlfn.XLOOKUP($S3:$AL3,增益!$A:$A,增益!$N:$N,0))} -> 0 | BK3: =$D$14*(1+$AX3) -> 571.2 | BL3: =$E$14*(1+$AX3) -> 1627.8 | BM3: {=IF($F$14-$I$4+VLOOKUP($R3,武学奇术!$A:$ZZ,15,FALSE)+SUM(_xlfn.XLOOKUP($S3:$AL3,增益!$A:$A,增益!$O:$O,0))>0,($F$14-$I$4+VLOOKUP($R3,武学奇术!$A:$ZZ,15,FALSE)+SUM(_xlfn.XLOOKUP($S3:$AL3,增益!$A:$A,增益!$O:$O,0)))/200,($F$14-$I$4+VLOOKUP($R3,武学奇术!$A:$ZZ,15,FALSE)+SUM(_xlfn.XLOOKUP($S3:$AL3,增益!$A:$A,增益!$O:$O,0)))/100)} -> 0.08 | BN3: {=$G$14+VLOOKUP($R3,武学奇术!$A:$ZZ,16,FALSE)+SUM(_xlfn.XLOOKUP($S3:$AL3,增益!$A:$A,增益!$P:$P,0))} -> 0.15 | BO3: =MIN(IF(VLOOKUP($R3,武学奇术!$A:$ZZ,23,FALSE)=1,100%,$B$8),100%) -> 0.981 | BP3: {=IF(VLOOKUP($R3,武学奇术!$A:$ZZ,23,FALSE)=1,100%,MIN(80%,$B$9+VLOOKUP($R3,武学奇术!$A:$ZZ,17,FALSE)+SUM(_xlfn.XLOOKUP($S3:$AL3,增益!$A:$A,增益!$Q:$Q,0)))+$B$11+SUM(_xlfn.XLOOKUP($S3:$AL3,增益!$A:$A,增益!$U:$U,0)))*IF(VLOOKUP($R3,武学奇术!$A:$ZZ,24,FALSE)=1,0,1)} -> 0.846 | BQ3: {=1+$B$13+VLOOKUP($R3,武学奇术!$A:$ZZ,18,FALSE)+SUM(_xlfn.XLOOKUP($S3:$AL3,增益!$A:$A,增益!$R:$R,0))} -> 1.83 | BR3: {=IF(VLOOKUP($R3,武学奇术!$A:$ZZ,24,FALSE)=1,100%,MIN(40%,$B$10+VLOOKUP($R3,武学奇术!$A:$ZZ,19,FALSE)+SUM(_xlfn.XLOOKUP($S3:$AL3,增益!$A:$A,增益!$S:$S,0)))+$B$12+SUM(_xlfn.XLOOKUP($S3:$AL3,增益!$A:$A,增益!$V:$V,0)))*IF(VLOOKUP($R3,武学奇术!$A:$ZZ,23,FALSE)=1,0,1)} -> 0.0929 | BS3: {=1+$B$14+VLOOKUP($R3,武学奇术!$A:$ZZ,20,FALSE)+SUM(_xlfn.XLOOKUP($S3:$AL3,增益!$A:$A,增益!$T:$T,0))} -> 1.35 | BT3: =MIN((1-BR3)*BO3,BO3*BP3) -> 0.829926 | BU3: =1-BR3-BT3-BV3 -> 0.0599391 | BV3: =IF(VLOOKUP($R3,武学奇术!$A:$ZZ,22,FALSE)=1,0,(1-$BO3))*(1-$BR3) -> 0.0172349 | BW3: {=SUM(_xlfn.XLOOKUP($S3:$AL3,增益!$A:$A,增益!$W:$W,0))+$I$5} -> 0.11 | BX3: {=SUM(_xlfn.XLOOKUP($S3:$AL3,增益!$A:$A,增益!$X:$X,0))} -> 0
A4: 裂石 | F4: 伞 | G4: =B15+B17 -> 0.1704 | H4: 属抗 | I4: =30 -> 30 | K4: =$L4*VLOOKUP($R4,武学奇术!$A:$ZZ,31,FALSE) -> 31658.395 | L4: =($M4*$BT4+$N4*$BR4+$O4*$BU4+$P4*$BV4) -> 30150.852 | M4: =((($AT4+$AU4)/2*$AN4+$AO4)*(1+$AV4)*(1+$AW4)+(($AY4+$AZ4)/2*IF($G$1="鸣金",$AP4,$AN4)+IF($G$1="鸣金",$AQ4*1.5,0))*(1+$BA4)*(1+$BB4)+(($BC4+$BD4)/2*IF($G$1="裂石",$AP4,$AN4)+IF($G$1="裂石",$AQ4*1.5,0))*(1+$BE4)*(1+$BF4)+(($BG4+$BH4)/2*IF($G$1="牵丝",$AP4,$AN4)+IF($G$1="牵丝",$AQ4*1.5,0))*(1+$BI4)*(1+$BJ4)+(($BK4+$BL4)/2*IF($G$1="破竹",$AP4,$AN4)+IF($G$1="破竹",$AQ4*1.5,0))*(1+$BM4)*(1+$BN4))*(1+$AR4)*$BQ4*$Q4*(1+IF(VLOOKUP($R4,武学奇术!$A:$ZZ,30,FALSE)="回旋伞",$B$21,0))*(1+$BW4) -> 31800.125 | N4: =(($AU4*$AN4+$AO4)*(1+$AV4)*(1+$AW4)+($AZ4*IF($G$1="鸣金",$AP4,$AN4)+IF($G$1="鸣金",$AQ4*1.5,0))*(1+$BA4)*(1+$BB4)+($BD4*IF($G$1="裂石",$AP4,$AN4)+IF($G$1="裂石",$AQ4*1.5,0))*(1+$BE4)*(1+$BF4)+($BH4*IF($G$1="牵丝",$AP4,$AN4)+IF($G$1="牵丝",$AQ4*1.5,0))*(1+$BI4)*(1+$BJ4)+($BL4*IF($G$1="破竹",$AP4,$AN4)+IF($G$1="破竹",$AQ4*1.5,0))*(1+$BM4)*(1+$BN4))*(1+$AR4)*$BS4*$Q4*(1+IF(VLOOKUP($R4,武学奇术!$A:$ZZ,30,FALSE)="回旋伞",$B$21,0))*(1+$BW4) -> 26549.014 | O4: =((($AT4+$AU4)/2*$AN4+$AO4)*(1+$AV4)*(1+$AW4)+(($AY4+$AZ4)/2*IF($G$1="鸣金",$AP4,$AN4)+IF($G$1="鸣金",$AQ4*1.5,0))*(1+$BA4)*(1+$BB4)+(($BC4+$BD4)/2*IF($G$1="裂石",$AP4,$AN4)+IF($G$1="裂石",$AQ4*1.5,0))*(1+$BE4)*(1+$BF4)+(($BG4+$BH4)/2*IF($G$1="牵丝",$AP4,$AN4)+IF($G$1="牵丝",$AQ4*1.5,0))*(1+$BI4)*(1+$BJ4)+(($BK4+$BL4)/2*IF($G$1="破竹",$AP4,$AN4)+IF($G$1="破竹",$AQ4*1.5,0))*(1+$BM4)*(1+$BN4))*(1+$AR4)*$Q4*(1+IF(VLOOKUP($R4,武学奇术!$A:$ZZ,30,FALSE)="回旋伞",$B$21,0))*(1+$BW4) -> 17282.677 | P4: =((($AT4*$AN4+$AO4)*(1+$AV4)*(1+$AW4)+($AY4*IF($G$1="鸣金",$AP4,$AN4)+IF($G$1="鸣金",$AQ4*1.5,0))*(1+$BA4)*(1+$BB4)+($BC4*IF($G$1="裂石",$AP4,$AN4)+IF($G$1="裂石",$AQ4*1.5,0))*(1+$BE4)*(1+$BF4)+($BG4*IF($G$1="牵丝",$AP4,$AN4)+IF($G$1="牵丝",$AQ4*1.5,0))*(1+$BI4)*(1+$BJ4)+($BK4*IF($G$1="破竹",$AP4,$AN4)+IF($G$1="破竹",$AQ4*1.5,0))*(1+$BM4)*(1+$BN4))*(1+$AR4))*$Q4*(1+IF(VLOOKUP($R4,武学奇术!$A:$ZZ,30,FALSE)="回旋伞",$B$21,0))*(1+$BW4) -> 14899.417 | Q4: 1 | R4: 萧呤千浪流星 | S4: N/a | T4: N/a | U4: 失魂落魄 | V4: 远程笛 | W4: 沧海帖3层 | X4: 易水歌3层 | Y4: 惧刃(拐) | Z4: N/a | AA4: N/a | AB4: N/a | AC4: 烁鼓(拐) | AD4: N/a | AE4: 离猎(拐) | AF4: 裁云(拐) | AG4: 无惧 | AH4: N/a | AI4: N/a | AJ4: N/a | AK4: N/a | AL4: N/a | AM4: =VLOOKUP($R4,武学奇术!$A:$ZZ,25,FALSE) -> 群体奇术 | AN4: =VLOOKUP($R4,武学奇术!$A:$ZZ,26,FALSE) -> 1.4904 | AO4: =VLOOKUP($R4,武学奇术!$A:$ZZ,27,FALSE)*(1+IF(OR($AM4=$F$4,$AM4=$F$5),$B$22,0)) -> 378 | AP4: =VLOOKUP($R4,武学奇术!$A:$ZZ,28,FALSE) -> 2.2356 | AQ4: =VLOOKUP($R4,武学奇术!$A:$ZZ,29,FALSE)*(1+IF(OR($AM4=$F$4,$AM4=$F$5),$B$22,0)) -> 0 | AR4: {=$G$3+IFERROR(VLOOKUP($AM4,$F$4:$G$7,2,FALSE),0)+VLOOKUP($R4,武学奇术!$A:$ZZ,2,FALSE)+SUM(_xlfn.XLOOKUP($S4:$AL4,增益!$A:$A,增益!$B:$B,0))} -> 0.4637 | AS4: {=VLOOKUP($R4,武学奇术!$A:$ZZ,5,FALSE)+SUM(_xlfn.XLOOKUP($S4:$AL4,增益!$A:$A,增益!$E:$E,0))} -> 0 | AT4: {=$D$10*(1+$AS4)+VLOOKUP($R4,武学奇术!$A:$ZZ,3,FALSE)+SUM(_xlfn.XLOOKUP($S4:$AL4,增益!$A:$A,增益!$C:$C,0))-$I$2} -> 3636.6 | AU4: {=$E$10*(1+$AS4)+VLOOKUP($R4,武学奇术!$A:$ZZ,4,FALSE)+SUM(_xlfn.XLOOKUP($S4:$AL4,增益!$A:$A,增益!$D:$D,0))-$I$2} -> 3636.6 | AV4: {=IF($F$10-$I$3+VLOOKUP($R4,武学奇术!$A:$ZZ,6,FALSE)+SUM(_xlfn.XLOOKUP($S4:$AL4,增益!$A:$A,增益!$F:$F,0))>0,($F$10-$I$3+VLOOKUP($R4,武学奇术!$A:$ZZ,6,FALSE)+SUM(_xlfn.XLOOKUP($S4:$AL4,增益!$A:$A,增益!$F:$F,0)))/200,($F$10-$I$3+VLOOKUP($R4,武学奇术!$A:$ZZ,6,FALSE)+SUM(_xlfn.XLOOKUP($S4:$AL4,增益!$A:$A,增益!$F:$F,0)))/100)} -> 0.2725 | AW4: {=$G$10+VLOOKUP($R4,武学奇术!$A:$ZZ,7,FALSE)+SUM(_xlfn.XLOOKUP($S4:$AL4,增益!$A:$A,增益!$G:$G,0))} -> 0.028 | AX4: {=VLOOKUP($R4,武学奇术!$A:$ZZ,8,FALSE)+SUM(_xlfn.XLOOKUP($S4:$AL4,增益!$A:$A,增益!$H:$H,0))} -> 0 | AY4: =$D$11*(1+$AX4) -> 0 | AZ4: =$E$11*(1+$AX4) -> 0 | BA4: {=IF($F$11-$I$4+VLOOKUP($R4,武学奇术!$A:$ZZ,9,FALSE)+SUM(_xlfn.XLOOKUP($S4:$AL4,增益!$A:$A,增益!$I:$I,0))>0,($F$11-$I$4+VLOOKUP($R4,武学奇术!$A:$ZZ,9,FALSE)+SUM(_xlfn.XLOOKUP($S4:$AL4,增益!$A:$A,增益!$I:$I,0)))/200,($F$11-$I$4+VLOOKUP($R4,武学奇术!$A:$ZZ,9,FALSE)+SUM(_xlfn.XLOOKUP($S4:$AL4,增益!$A:$A,增益!$I:$I,0)))/100)} -> -0.14 | BB4: {=$G$11+VLOOKUP($R4,武学奇术!$A:$ZZ,10,FALSE)+SUM(_xlfn.XLOOKUP($S4:$AL4,增益!$A:$A,增益!$J:$J,0))} -> 0 | BC4: =$D$12*(1+$AX4) -> 0 | BD4: =$E$12*(1+$AX4) -> 0 | BE4: {=IF($F$12-$I$4+VLOOKUP($R4,武学奇术!$A:$ZZ,11,FALSE)+SUM(_xlfn.XLOOKUP($S4:$AL4,增益!$A:$A,增益!$K:$K,0))>0,($F$12-$I$4+VLOOKUP($R4,武学奇术!$A:$ZZ,11,FALSE)+SUM(_xlfn.XLOOKUP($S4:$AL4,增益!$A:$A,增益!$K:$K,0)))/200,($F$12-$I$4+VLOOKUP($R4,武学奇术!$A:$ZZ,11,FALSE)+SUM(_xlfn.XLOOKUP($S4:$AL4,增益!$A:$A,增益!$K:$K,0)))/100)} -> -0.14 | BF4: {=$G$12+VLOOKUP($R4,武学奇术!$A:$ZZ,12,FALSE)+SUM(_xlfn.XLOOKUP($S4:$AL4,增益!$A:$A,增益!$L:$L,0))} -> 0 | BG4: =$D$13*(1+$AX4) -> 0 | BH4: =$E$13*(1+$AX4) -> 0 | BI4: {=IF($F$13-$I$4+VLOOKUP($R4,武学奇术!$A:$ZZ,13,FALSE)+SUM(_xlfn.XLOOKUP($S4:$AL4,增益!$A:$A,增益!$M:$M,0))>0,($F$13-$I$4+VLOOKUP($R4,武学奇术!$A:$ZZ,13,FALSE)+SUM(_xlfn.XLOOKUP($S4:$AL4,增益!$A:$A,增益!$K:$K,0)))/200,($F$13-$I$4+VLOOKUP($R4,武学奇术!$A:$ZZ,13,FALSE)+SUM(_xlfn.XLOOKUP($S4:$AL4,增益!$A:$A,增益!$M:$M,0)))/100)} -> -0.14 | BJ4: {=$G$13+VLOOKUP($R4,武学奇术!$A:$ZZ,14,FALSE)+SUM(_xlfn.XLOOKUP($S4:$AL4,增益!$A:$A,增益!$N:$N,0))} -> 0 | BK4: =$D$14*(1+$AX4) -> 571.2 | BL4: =$E$14*(1+$AX4) -> 1627.8 | BM4: {=IF($F$14-$I$4+VLOOKUP($R4,武学奇术!$A:$ZZ,15,FALSE)+SUM(_xlfn.XLOOKUP($S4:$AL4,增益!$A:$A,增益!$O:$O,0))>0,($F$14-$I$4+VLOOKUP($R4,武学奇术!$A:$ZZ,15,FALSE)+SUM(_xlfn.XLOOKUP($S4:$AL4,增益!$A:$A,增益!$O:$O,0)))/200,($F$14-$I$4+VLOOKUP($R4,武学奇术!$A:$ZZ,15,FALSE)+SUM(_xlfn.XLOOKUP($S4:$AL4,增益!$A:$A,增益!$O:$O,0)))/100)} -> 0.08 | BN4: {=$G$14+VLOOKUP($R4,武学奇术!$A:$ZZ,16,FALSE)+SUM(_xlfn.XLOOKUP($S4:$AL4,增益!$A:$A,增益!$P:$P,0))} -> 0.15 | BO4: =MIN(IF(VLOOKUP($R4,武学奇术!$A:$ZZ,23,FALSE)=1,100%,$B$8),100%) -> 0.981 | BP4: {=IF(VLOOKUP($R4,武学奇术!$A:$ZZ,23,FALSE)=1,100%,MIN(80%,$B$9+VLOOKUP($R4,武学奇术!$A:$ZZ,17,FALSE)+SUM(_xlfn.XLOOKUP($S4:$AL4,增益!$A:$A,增益!$Q:$Q,0)))+$B$11+SUM(_xlfn.XLOOKUP($S4:$AL4,增益!$A:$A,增益!$U:$U,0)))*IF(VLOOKUP($R4,武学奇术!$A:$ZZ,24,FALSE)=1,0,1)} -> 0.846 | BQ4: {=1+$B$13+VLOOKUP($R4,武学奇术!$A:$ZZ,18,FALSE)+SUM(_xlfn.XLOOKUP($S4:$AL4,增益!$A:$A,增益!$R:$R,0))} -> 1.84 | BR4: {=IF(VLOOKUP($R4,武学奇术!$A:$ZZ,24,FALSE)=1,100%,MIN(40%,$B$10+VLOOKUP($R4,武学奇术!$A:$ZZ,19,FALSE)+SUM(_xlfn.XLOOKUP($S4:$AL4,增益!$A:$A,增益!$S:$S,0)))+$B$12+SUM(_xlfn.XLOOKUP($S4:$AL4,增益!$A:$A,增益!$V:$V,0)))*IF(VLOOKUP($R4,武学奇术!$A:$ZZ,23,FALSE)=1,0,1)} -> 0.0929 | BS4: {=1+$B$14+VLOOKUP($R4,武学奇术!$A:$ZZ,20,FALSE)+SUM(_xlfn.XLOOKUP($S4:$AL4,增益!$A:$A,增益!$T:$T,0))} -> 1.35 | BT4: =MIN((1-BR4)*BO4,BO4*BP4) -> 0.829926 | BU4: =1-BR4-BT4-BV4 -> 0.0599391 | BV4: =IF(VLOOKUP($R4,武学奇术!$A:$ZZ,22,FALSE)=1,0,(1-$BO4))*(1-$BR4) -> 0.0172349 | BW4: {=SUM(_xlfn.XLOOKUP($S4:$AL4,增益!$A:$A,增益!$W:$W,0))+$I$5} -> 0.11 | BX4: {=SUM(_xlfn.XLOOKUP($S4:$AL4,增益!$A:$A,增益!$X:$X,0))} -> 0
A5: 牵丝 | F5: 绳镖 | G5: =B15+B18 -> 0.0852 | H5: 副本天赋 | I5: 0.06 | K5: =$L5*VLOOKUP($R5,武学奇术!$A:$ZZ,31,FALSE) -> 33093.851 | L5: =($M5*$BT5+$N5*$BR5+$O5*$BU5+$P5*$BV5) -> 31517.953 | M5: =((($AT5+$AU5)/2*$AN5+$AO5)*(1+$AV5)*(1+$AW5)+(($AY5+$AZ5)/2*IF($G$1="鸣金",$AP5,$AN5)+IF($G$1="鸣金",$AQ5*1.5,0))*(1+$BA5)*(1+$BB5)+(($BC5+$BD5)/2*IF($G$1="裂石",$AP5,$AN5)+IF($G$1="裂石",$AQ5*1.5,0))*(1+$BE5)*(1+$BF5)+(($BG5+$BH5)/2*IF($G$1="牵丝",$AP5,$AN5)+IF($G$1="牵丝",$AQ5*1.5,0))*(1+$BI5)*(1+$BJ5)+(($BK5+$BL5)/2*IF($G$1="破竹",$AP5,$AN5)+IF($G$1="破竹",$AQ5*1.5,0))*(1+$BM5)*(1+$BN5))*(1+$AR5)*$BQ5*$Q5*(1+IF(VLOOKUP($R5,武学奇术!$A:$ZZ,30,FALSE)="回旋伞",$B$21,0))*(1+$BW5) -> 33273.636 | N5: =(($AU5*$AN5+$AO5)*(1+$AV5)*(1+$AW5)+($AZ5*IF($G$1="鸣金",$AP5,$AN5)+IF($G$1="鸣金",$AQ5*1.5,0))*(1+$BA5)*(1+$BB5)+($BD5*IF($G$1="裂石",$AP5,$AN5)+IF($G$1="裂石",$AQ5*1.5,0))*(1+$BE5)*(1+$BF5)+($BH5*IF($G$1="牵丝",$AP5,$AN5)+IF($G$1="牵丝",$AQ5*1.5,0))*(1+$BI5)*(1+$BJ5)+($BL5*IF($G$1="破竹",$AP5,$AN5)+IF($G$1="破竹",$AQ5*1.5,0))*(1+$BM5)*(1+$BN5))*(1+$AR5)*$BS5*$Q5*(1+IF(VLOOKUP($R5,武学奇术!$A:$ZZ,30,FALSE)="回旋伞",$B$21,0))*(1+$BW5) -> 27520.143 | O5: =((($AT5+$AU5)/2*$AN5+$AO5)*(1+$AV5)*(1+$AW5)+(($AY5+$AZ5)/2*IF($G$1="鸣金",$AP5,$AN5)+IF($G$1="鸣金",$AQ5*1.5,0))*(1+$BA5)*(1+$BB5)+(($BC5+$BD5)/2*IF($G$1="裂石",$AP5,$AN5)+IF($G$1="裂石",$AQ5*1.5,0))*(1+$BE5)*(1+$BF5)+(($BG5+$BH5)/2*IF($G$1="牵丝",$AP5,$AN5)+IF($G$1="牵丝",$AQ5*1.5,0))*(1+$BI5)*(1+$BJ5)+(($BK5+$BL5)/2*IF($G$1="破竹",$AP5,$AN5)+IF($G$1="破竹",$AQ5*1.5,0))*(1+$BM5)*(1+$BN5))*(1+$AR5)*$Q5*(1+IF(VLOOKUP($R5,武学奇术!$A:$ZZ,30,FALSE)="回旋伞",$B$21,0))*(1+$BW5) -> 17985.749 | P5: =((($AT5*$AN5+$AO5)*(1+$AV5)*(1+$AW5)+($AY5*IF($G$1="鸣金",$AP5,$AN5)+IF($G$1="鸣金",$AQ5*1.5,0))*(1+$BA5)*(1+$BB5)+($BC5*IF($G$1="裂石",$AP5,$AN5)+IF($G$1="裂石",$AQ5*1.5,0))*(1+$BE5)*(1+$BF5)+($BG5*IF($G$1="牵丝",$AP5,$AN5)+IF($G$1="牵丝",$AQ5*1.5,0))*(1+$BI5)*(1+$BJ5)+($BK5*IF($G$1="破竹",$AP5,$AN5)+IF($G$1="破竹",$AQ5*1.5,0))*(1+$BM5)*(1+$BN5))*(1+$AR5))*$Q5*(1+IF(VLOOKUP($R5,武学奇术!$A:$ZZ,30,FALSE)="回旋伞",$B$21,0))*(1+$BW5) -> 15586.207 | Q5: 1 | R5: 萧呤千浪流星 | S5: N/a | T5: 幻鸣5层 | U5: 失魂落魄 | V5: 远程笛 | W5: 沧海帖4层 | X5: 易水歌4层 | Y5: 惧刃(拐) | Z5: N/a | AA5: N/a | AB5: N/a | AC5: 烁鼓(拐) | AD5: N/a | AE5: 离猎(拐) | AF5: 裁云(拐) | AG5: 无惧 | AH5: N/a | AI5: N/a | AJ5: N/a | AK5: N/a | AL5: N/a | AM5: =VLOOKUP($R5,武学奇术!$A:$ZZ,25,FALSE) -> 群体奇术 | AN5: =VLOOKUP($R5,武学奇术!$A:$ZZ,26,FALSE) -> 1.4904 | AO5: =VLOOKUP($R5,武学奇术!$A:$ZZ,27,FALSE)*(1+IF(OR($AM5=$F$4,$AM5=$F$5),$B$22,0)) -> 378 | AP5: =VLOOKUP($R5,武学奇术!$A:$ZZ,28,FALSE) -> 2.2356 | AQ5: =VLOOKUP($R5,武学奇术!$A:$ZZ,29,FALSE)*(1+IF(OR($AM5=$F$4,$AM5=$F$5),$B$22,0)) -> 0 | AR5: {=$G$3+IFERROR(VLOOKUP($AM5,$F$4:$G$7,2,FALSE),0)+VLOOKUP($R5,武学奇术!$A:$ZZ,2,FALSE)+SUM(_xlfn.XLOOKUP($S5:$AL5,增益!$A:$A,增益!$B:$B,0))} -> 0.4737 | AS5: {=VLOOKUP($R5,武学奇术!$A:$ZZ,5,FALSE)+SUM(_xlfn.XLOOKUP($S5:$AL5,增益!$A:$A,增益!$E:$E,0))} -> 0 | AT5: {=$D$10*(1+$AS5)+VLOOKUP($R5,武学奇术!$A:$ZZ,3,FALSE)+SUM(_xlfn.XLOOKUP($S5:$AL5,增益!$A:$A,增益!$C:$C,0))-$I$2} -> 3636.6 | AU5: {=$E$10*(1+$AS5)+VLOOKUP($R5,武学奇术!$A:$ZZ,4,FALSE)+SUM(_xlfn.XLOOKUP($S5:$AL5,增益!$A:$A,增益!$D:$D,0))-$I$2} -> 3636.6 | AV5: {=IF($F$10-$I$3+VLOOKUP($R5,武学奇术!$A:$ZZ,6,FALSE)+SUM(_xlfn.XLOOKUP($S5:$AL5,增益!$A:$A,增益!$F:$F,0))>0,($F$10-$I$3+VLOOKUP($R5,武学奇术!$A:$ZZ,6,FALSE)+SUM(_xlfn.XLOOKUP($S5:$AL5,增益!$A:$A,增益!$F:$F,0)))/200,($F$10-$I$3+VLOOKUP($R5,武学奇术!$A:$ZZ,6,FALSE)+SUM(_xlfn.XLOOKUP($S5:$AL5,增益!$A:$A,增益!$F:$F,0)))/100)} -> 0.3325 | AW5: {=$G$10+VLOOKUP($R5,武学奇术!$A:$ZZ,7,FALSE)+SUM(_xlfn.XLOOKUP($S5:$AL5,增益!$A:$A,增益!$G:$G,0))} -> 0.028 | AX5: {=VLOOKUP($R5,武学奇术!$A:$ZZ,8,FALSE)+SUM(_xlfn.XLOOKUP($S5:$AL5,增益!$A:$A,增益!$H:$H,0))} -> 0 | AY5: =$D$11*(1+$AX5) -> 0 | AZ5: =$E$11*(1+$AX5) -> 0 | BA5: {=IF($F$11-$I$4+VLOOKUP($R5,武学奇术!$A:$ZZ,9,FALSE)+SUM(_xlfn.XLOOKUP($S5:$AL5,增益!$A:$A,增益!$I:$I,0))>0,($F$11-$I$4+VLOOKUP($R5,武学奇术!$A:$ZZ,9,FALSE)+SUM(_xlfn.XLOOKUP($S5:$AL5,增益!$A:$A,增益!$I:$I,0)))/200,($F$11-$I$4+VLOOKUP($R5,武学奇术!$A:$ZZ,9,FALSE)+SUM(_xlfn.XLOOKUP($S5:$AL5,增益!$A:$A,增益!$I:$I,0)))/100)} -> -0.14 | BB5: {=$G$11+VLOOKUP($R5,武学奇术!$A:$ZZ,10,FALSE)+SUM(_xlfn.XLOOKUP($S5:$AL5,增益!$A:$A,增益!$J:$J,0))} -> 0 | BC5: =$D$12*(1+$AX5) -> 0 | BD5: =$E$12*(1+$AX5) -> 0 | BE5: {=IF($F$12-$I$4+VLOOKUP($R5,武学奇术!$A:$ZZ,11,FALSE)+SUM(_xlfn.XLOOKUP($S5:$AL5,增益!$A:$A,增益!$K:$K,0))>0,($F$12-$I$4+VLOOKUP($R5,武学奇术!$A:$ZZ,11,FALSE)+SUM(_xlfn.XLOOKUP($S5:$AL5,增益!$A:$A,增益!$K:$K,0)))/200,($F$12-$I$4+VLOOKUP($R5,武学奇术!$A:$ZZ,11,FALSE)+SUM(_xlfn.XLOOKUP($S5:$AL5,增益!$A:$A,增益!$K:$K,0)))/100)} -> -0.14 | BF5: {=$G$12+VLOOKUP($R5,武学奇术!$A:$ZZ,12,FALSE)+SUM(_xlfn.XLOOKUP($S5:$AL5,增益!$A:$A,增益!$L:$L,0))} -> 0 | BG5: =$D$13*(1+$AX5) -> 0 | BH5: =$E$13*(1+$AX5) -> 0 | BI5: {=IF($F$13-$I$4+VLOOKUP($R5,武学奇术!$A:$ZZ,13,FALSE)+SUM(_xlfn.XLOOKUP($S5:$AL5,增益!$A:$A,增益!$M:$M,0))>0,($F$13-$I$4+VLOOKUP($R5,武学奇术!$A:$ZZ,13,FALSE)+SUM(_xlfn.XLOOKUP($S5:$AL5,增益!$A:$A,增益!$K:$K,0)))/200,($F$13-$I$4+VLOOKUP($R5,武学奇术!$A:$ZZ,13,FALSE)+SUM(_xlfn.XLOOKUP($S5:$AL5,增益!$A:$A,增益!$M:$M,0)))/100)} -> -0.14 | BJ5: {=$G$13+VLOOKUP($R5,武学奇术!$A:$ZZ,14,FALSE)+SUM(_xlfn.XLOOKUP($S5:$AL5,增益!$A:$A,增益!$N:$N,0))} -> 0 | BK5: =$D$14*(1+$AX5) -> 571.2 | BL5: =$E$14*(1+$AX5) -> 1627.8 | BM5: {=IF($F$14-$I$4+VLOOKUP($R5,武学奇术!$A:$ZZ,15,FALSE)+SUM(_xlfn.XLOOKUP($S5:$AL5,增益!$A:$A,增益!$O:$O,0))>0,($F$14-$I$4+VLOOKUP($R5,武学奇术!$A:$ZZ,15,FALSE)+SUM(_xlfn.XLOOKUP($S5:$AL5,增益!$A:$A,增益!$O:$O,0)))/200,($F$14-$I$4+VLOOKUP($R5,武学奇术!$A:$ZZ,15,FALSE)+SUM(_xlfn.XLOOKUP($S5:$AL5,增益!$A:$A,增益!$O:$O,0)))/100)} -> 0.08 | BN5: {=$G$14+VLOOKUP($R5,武学奇术!$A:$ZZ,16,FALSE)+SUM(_xlfn.XLOOKUP($S5:$AL5,增益!$A:$A,增益!$P:$P,0))} -> 0.15 | BO5: =MIN(IF(VLOOKUP($R5,武学奇术!$A:$ZZ,23,FALSE)=1,100%,$B$8),100%) -> 0.981 | BP5: {=IF(VLOOKUP($R5,武学奇术!$A:$ZZ,23,FALSE)=1,100%,MIN(80%,$B$9+VLOOKUP($R5,武学奇术!$A:$ZZ,17,FALSE)+SUM(_xlfn.XLOOKUP($S5:$AL5,增益!$A:$A,增益!$Q:$Q,0)))+$B$11+SUM(_xlfn.XLOOKUP($S5:$AL5,增益!$A:$A,增益!$U:$U,0)))*IF(VLOOKUP($R5,武学奇术!$A:$ZZ,24,FALSE)=1,0,1)} -> 0.846 | BQ5: {=1+$B$13+VLOOKUP($R5,武学奇术!$A:$ZZ,18,FALSE)+SUM(_xlfn.XLOOKUP($S5:$AL5,增益!$A:$A,增益!$R:$R,0))} -> 1.85 | BR5: {=IF(VLOOKUP($R5,武学奇术!$A:$ZZ,24,FALSE)=1,100%,MIN(40%,$B$10+VLOOKUP($R5,武学奇术!$A:$ZZ,19,FALSE)+SUM(_xlfn.XLOOKUP($S5:$AL5,增益!$A:$A,增益!$S:$S,0)))+$B$12+SUM(_xlfn.XLOOKUP($S5:$AL5,增益!$A:$A,增益!$V:$V,0)))*IF(VLOOKUP($R5,武学奇术!$A:$ZZ,23,FALSE)=1,0,1)} -> 0.0929 | BS5: {=1+$B$14+VLOOKUP($R5,武学奇术!$A:$ZZ,20,FALSE)+SUM(_xlfn.XLOOKUP($S5:$AL5,增益!$A:$A,增益!$T:$T,0))} -> 1.35 | BT5: =MIN((1-BR5)*BO5,BO5*BP5) -> 0.829926 | BU5: =1-BR5-BT5-BV5 -> 0.0599391 | BV5: =IF(VLOOKUP($R5,武学奇术!$A:$ZZ,22,FALSE)=1,0,(1-$BO5))*(1-$BR5) -> 0.0172349 | BW5: {=SUM(_xlfn.XLOOKUP($S5:$AL5,增益!$A:$A,增益!$W:$W,0))+$I$5} -> 0.11 | BX5: {=SUM(_xlfn.XLOOKUP($S5:$AL5,增益!$A:$A,增益!$X:$X,0))} -> 0
A6: 破竹 | B6: 492 | C6: 1397.8 | D6: 30 | E6: 0.15 | F6: 单体奇术 | G6: =B19 -> 0 | K6: =$L6*VLOOKUP($R6,武学奇术!$A:$ZZ,31,FALSE) -> 33497.543 | L6: =($M6*$BT6+$N6*$BR6+$O6*$BU6+$P6*$BV6) -> 31902.422 | M6: =((($AT6+$AU6)/2*$AN6+$AO6)*(1+$AV6)*(1+$AW6)+(($AY6+$AZ6)/2*IF($G$1="鸣金",$AP6,$AN6)+IF($G$1="鸣金",$AQ6*1.5,0))*(1+$BA6)*(1+$BB6)+(($BC6+$BD6)/2*IF($G$1="裂石",$AP6,$AN6)+IF($G$1="裂石",$AQ6*1.5,0))*(1+$BE6)*(1+$BF6)+(($BG6+$BH6)/2*IF($G$1="牵丝",$AP6,$AN6)+IF($G$1="牵丝",$AQ6*1.5,0))*(1+$BI6)*(1+$BJ6)+(($BK6+$BL6)/2*IF($G$1="破竹",$AP6,$AN6)+IF($G$1="破竹",$AQ6*1.5,0))*(1+$BM6)*(1+$BN6))*(1+$AR6)*$BQ6*$Q6*(1+IF(VLOOKUP($R6,武学奇术!$A:$ZZ,30,FALSE)="回旋伞",$B$21,0))*(1+$BW6) -> 33681.017 | N6: =(($AU6*$AN6+$AO6)*(1+$AV6)*(1+$AW6)+($AZ6*IF($G$1="鸣金",$AP6,$AN6)+IF($G$1="鸣金",$AQ6*1.5,0))*(1+$BA6)*(1+$BB6)+($BD6*IF($G$1="裂石",$AP6,$AN6)+IF($G$1="裂石",$AQ6*1.5,0))*(1+$BE6)*(1+$BF6)+($BH6*IF($G$1="牵丝",$AP6,$AN6)+IF($G$1="牵丝",$AQ6*1.5,0))*(1+$BI6)*(1+$BJ6)+($BL6*IF($G$1="破竹",$AP6,$AN6)+IF($G$1="破竹",$AQ6*1.5,0))*(1+$BM6)*(1+$BN6))*(1+$AR6)*$BS6*$Q6*(1+IF(VLOOKUP($R6,武学奇术!$A:$ZZ,30,FALSE)="回旋伞",$B$21,0))*(1+$BW6) -> 27839.402 | O6: =((($AT6+$AU6)/2*$AN6+$AO6)*(1+$AV6)*(1+$AW6)+(($AY6+$AZ6)/2*IF($G$1="鸣金",$AP6,$AN6)+IF($G$1="鸣金",$AQ6*1.5,0))*(1+$BA6)*(1+$BB6)+(($BC6+$BD6)/2*IF($G$1="裂石",$AP6,$AN6)+IF($G$1="裂石",$AQ6*1.5,0))*(1+$BE6)*(1+$BF6)+(($BG6+$BH6)/2*IF($G$1="牵丝",$AP6,$AN6)+IF($G$1="牵丝",$AQ6*1.5,0))*(1+$BI6)*(1+$BJ6)+(($BK6+$BL6)/2*IF($G$1="破竹",$AP6,$AN6)+IF($G$1="破竹",$AQ6*1.5,0))*(1+$BM6)*(1+$BN6))*(1+$AR6)*$Q6*(1+IF(VLOOKUP($R6,武学奇术!$A:$ZZ,30,FALSE)="回旋伞",$B$21,0))*(1+$BW6) -> 18205.955 | P6: =((($AT6*$AN6+$AO6)*(1+$AV6)*(1+$AW6)+($AY6*IF($G$1="鸣金",$AP6,$AN6)+IF($G$1="鸣金",$AQ6*1.5,0))*(1+$BA6)*(1+$BB6)+($BC6*IF($G$1="裂石",$AP6,$AN6)+IF($G$1="裂石",$AQ6*1.5,0))*(1+$BE6)*(1+$BF6)+($BG6*IF($G$1="牵丝",$AP6,$AN6)+IF($G$1="牵丝",$AQ6*1.5,0))*(1+$BI6)*(1+$BJ6)+($BK6*IF($G$1="破竹",$AP6,$AN6)+IF($G$1="破竹",$AQ6*1.5,0))*(1+$BM6)*(1+$BN6))*(1+$AR6))*$Q6*(1+IF(VLOOKUP($R6,武学奇术!$A:$ZZ,30,FALSE)="回旋伞",$B$21,0))*(1+$BW6) -> 15790.131 | Q6: 1 | R6: 萧呤千浪流星 | S6: N/a | T6: 幻鸣5层 | U6: 失魂落魄 | V6: 远程笛 | W6: 沧海帖4层 | X6: 易水歌5层 | Y6: 惧刃(拐) | Z6: N/a | AA6: N/a | AB6: N/a | AC6: 扶风(拐) | AD6: N/a | AE6: 离猎(拐) | AF6: 裁云(拐) | AG6: 无惧 | AH6: N/a | AI6: N/a | AJ6: N/a | AK6: N/a | AL6: N/a | AM6: =VLOOKUP($R6,武学奇术!$A:$ZZ,25,FALSE) -> 群体奇术 | AN6: =VLOOKUP($R6,武学奇术!$A:$ZZ,26,FALSE) -> 1.4904 | AO6: =VLOOKUP($R6,武学奇术!$A:$ZZ,27,FALSE)*(1+IF(OR($AM6=$F$4,$AM6=$F$5),$B$22,0)) -> 378 | AP6: =VLOOKUP($R6,武学奇术!$A:$ZZ,28,FALSE) -> 2.2356 | AQ6: =VLOOKUP($R6,武学奇术!$A:$ZZ,29,FALSE)*(1+IF(OR($AM6=$F$4,$AM6=$F$5),$B$22,0)) -> 0 | AR6: {=$G$3+IFERROR(VLOOKUP($AM6,$F$4:$G$7,2,FALSE),0)+VLOOKUP($R6,武学奇术!$A:$ZZ,2,FALSE)+SUM(_xlfn.XLOOKUP($S6:$AL6,增益!$A:$A,增益!$B:$B,0))} -> 0.4837 | AS6: {=VLOOKUP($R6,武学奇术!$A:$ZZ,5,FALSE)+SUM(_xlfn.XLOOKUP($S6:$AL6,增益!$A:$A,增益!$E:$E,0))} -> 0 | AT6: {=$D$10*(1+$AS6)+VLOOKUP($R6,武学奇术!$A:$ZZ,3,FALSE)+SUM(_xlfn.XLOOKUP($S6:$AL6,增益!$A:$A,增益!$C:$C,0))-$I$2} -> 3636.6 | AU6: {=$E$10*(1+$AS6)+VLOOKUP($R6,武学奇术!$A:$ZZ,4,FALSE)+SUM(_xlfn.XLOOKUP($S6:$AL6,增益!$A:$A,增益!$D:$D,0))-$I$2} -> 3636.6 | AV6: {=IF($F$10-$I$3+VLOOKUP($R6,武学奇术!$A:$ZZ,6,FALSE)+SUM(_xlfn.XLOOKUP($S6:$AL6,增益!$A:$A,增益!$F:$F,0))>0,($F$10-$I$3+VLOOKUP($R6,武学奇术!$A:$ZZ,6,FALSE)+SUM(_xlfn.XLOOKUP($S6:$AL6,增益!$A:$A,增益!$F:$F,0)))/200,($F$10-$I$3+VLOOKUP($R6,武学奇术!$A:$ZZ,6,FALSE)+SUM(_xlfn.XLOOKUP($S6:$AL6,增益!$A:$A,增益!$F:$F,0)))/100)} -> 0.3425 | AW6: {=$G$10+VLOOKUP($R6,武学奇术!$A:$ZZ,7,FALSE)+SUM(_xlfn.XLOOKUP($S6:$AL6,增益!$A:$A,增益!$G:$G,0))} -> 0.028 | AX6: {=VLOOKUP($R6,武学奇术!$A:$ZZ,8,FALSE)+SUM(_xlfn.XLOOKUP($S6:$AL6,增益!$A:$A,增益!$H:$H,0))} -> 0 | AY6: =$D$11*(1+$AX6) -> 0 | AZ6: =$E$11*(1+$AX6) -> 0 | BA6: {=IF($F$11-$I$4+VLOOKUP($R6,武学奇术!$A:$ZZ,9,FALSE)+SUM(_xlfn.XLOOKUP($S6:$AL6,增益!$A:$A,增益!$I:$I,0))>0,($F$11-$I$4+VLOOKUP($R6,武学奇术!$A:$ZZ,9,FALSE)+SUM(_xlfn.XLOOKUP($S6:$AL6,增益!$A:$A,增益!$I:$I,0)))/200,($F$11-$I$4+VLOOKUP($R6,武学奇术!$A:$ZZ,9,FALSE)+SUM(_xlfn.XLOOKUP($S6:$AL6,增益!$A:$A,增益!$I:$I,0)))/100)} -> -0.14 | BB6: {=$G$11+VLOOKUP($R6,武学奇术!$A:$ZZ,10,FALSE)+SUM(_xlfn.XLOOKUP($S6:$AL6,增益!$A:$A,增益!$J:$J,0))} -> 0 | BC6: =$D$12*(1+$AX6) -> 0 | BD6: =$E$12*(1+$AX6) -> 0 | BE6: {=IF($F$12-$I$4+VLOOKUP($R6,武学奇术!$A:$ZZ,11,FALSE)+SUM(_xlfn.XLOOKUP($S6:$AL6,增益!$A:$A,增益!$K:$K,0))>0,($F$12-$I$4+VLOOKUP($R6,武学奇术!$A:$ZZ,11,FALSE)+SUM(_xlfn.XLOOKUP($S6:$AL6,增益!$A:$A,增益!$K:$K,0)))/200,($F$12-$I$4+VLOOKUP($R6,武学奇术!$A:$ZZ,11,FALSE)+SUM(_xlfn.XLOOKUP($S6:$AL6,增益!$A:$A,增益!$K:$K,0)))/100)} -> -0.14 | BF6: {=$G$12+VLOOKUP($R6,武学奇术!$A:$ZZ,12,FALSE)+SUM(_xlfn.XLOOKUP($S6:$AL6,增益!$A:$A,增益!$L:$L,0))} -> 0 | BG6: =$D$13*(1+$AX6) -> 0 | BH6: =$E$13*(1+$AX6) -> 0 | BI6: {=IF($F$13-$I$4+VLOOKUP($R6,武学奇术!$A:$ZZ,13,FALSE)+SUM(_xlfn.XLOOKUP($S6:$AL6,增益!$A:$A,增益!$M:$M,0))>0,($F$13-$I$4+VLOOKUP($R6,武学奇术!$A:$ZZ,13,FALSE)+SUM(_xlfn.XLOOKUP($S6:$AL6,增益!$A:$A,增益!$K:$K,0)))/200,($F$13-$I$4+VLOOKUP($R6,武学奇术!$A:$ZZ,13,FALSE)+SUM(_xlfn.XLOOKUP($S6:$AL6,增益!$A:$A,增益!$M:$M,0)))/100)} -> -0.14 | BJ6: {=$G$13+VLOOKUP($R6,武学奇术!$A:$ZZ,14,FALSE)+SUM(_xlfn.XLOOKUP($S6:$AL6,增益!$A:$A,增益!$N:$N,0))} -> 0 | BK6: =$D$14*(1+$AX6) -> 571.2 | BL6: =$E$14*(1+$AX6) -> 1627.8 | BM6: {=IF($F$14-$I$4+VLOOKUP($R6,武学奇术!$A:$ZZ,15,FALSE)+SUM(_xlfn.XLOOKUP($S6:$AL6,增益!$A:$A,增益!$O:$O,0))>0,($F$14-$I$4+VLOOKUP($R6,武学奇术!$A:$ZZ,15,FALSE)+SUM(_xlfn.XLOOKUP($S6:$AL6,增益!$A:$A,增益!$O:$O,0)))/200,($F$14-$I$4+VLOOKUP($R6,武学奇术!$A:$ZZ,15,FALSE)+SUM(_xlfn.XLOOKUP($S6:$AL6,增益!$A:$A,增益!$O:$O,0)))/100)} -> 0.08 | BN6: {=$G$14+VLOOKUP($R6,武学奇术!$A:$ZZ,16,FALSE)+SUM(_xlfn.XLOOKUP($S6:$AL6,增益!$A:$A,增益!$P:$P,0))} -> 0.15 | BO6: =MIN(IF(VLOOKUP($R6,武学奇术!$A:$ZZ,23,FALSE)=1,100%,$B$8),100%) -> 0.981 | BP6: {=IF(VLOOKUP($R6,武学奇术!$A:$ZZ,23,FALSE)=1,100%,MIN(80%,$B$9+VLOOKUP($R6,武学奇术!$A:$ZZ,17,FALSE)+SUM(_xlfn.XLOOKUP($S6:$AL6,增益!$A:$A,增益!$Q:$Q,0)))+$B$11+SUM(_xlfn.XLOOKUP($S6:$AL6,增益!$A:$A,增益!$U:$U,0)))*IF(VLOOKUP($R6,武学奇术!$A:$ZZ,24,FALSE)=1,0,1)} -> 0.846 | BQ6: {=1+$B$13+VLOOKUP($R6,武学奇术!$A:$ZZ,18,FALSE)+SUM(_xlfn.XLOOKUP($S6:$AL6,增益!$A:$A,增益!$R:$R,0))} -> 1.85 | BR6: {=IF(VLOOKUP($R6,武学奇术!$A:$ZZ,24,FALSE)=1,100%,MIN(40%,$B$10+VLOOKUP($R6,武学奇术!$A:$ZZ,19,FALSE)+SUM(_xlfn.XLOOKUP($S6:$AL6,增益!$A:$A,增益!$S:$S,0)))+$B$12+SUM(_xlfn.XLOOKUP($S6:$AL6,增益!$A:$A,增益!$V:$V,0)))*IF(VLOOKUP($R6,武学奇术!$A:$ZZ,23,FALSE)=1,0,1)} -> 0.0929 | BS6: {=1+$B$14+VLOOKUP($R6,武学奇术!$A:$ZZ,20,FALSE)+SUM(_xlfn.XLOOKUP($S6:$AL6,增益!$A:$A,增益!$T:$T,0))} -> 1.35 | BT6: =MIN((1-BR6)*BO6,BO6*BP6) -> 0.829926 | BU6: =1-BR6-BT6-BV6 -> 0.0599391 | BV6: =IF(VLOOKUP($R6,武学奇术!$A:$ZZ,22,FALSE)=1,0,(1-$BO6))*(1-$BR6) -> 0.0172349 | BW6: {=SUM(_xlfn.XLOOKUP($S6:$AL6,增益!$A:$A,增益!$W:$W,0))+$I$5} -> 0.11 | BX6: {=SUM(_xlfn.XLOOKUP($S6:$AL6,增益!$A:$A,增益!$X:$X,0))} -> 0
A7: 无相 | B7: 79.2 | C7: =92.4+68.8*2 -> 230 | F7: 群体奇术 | G7: =B20 -> 0 | K7: =$L7*VLOOKUP($R7,武学奇术!$A:$ZZ,31,FALSE) -> 19446.434 | L7: =($M7*$BT7+$N7*$BR7+$O7*$BU7+$P7*$BV7) -> 18520.414 | M7: =((($AT7+$AU7)/2*$AN7+$AO7)*(1+$AV7)*(1+$AW7)+(($AY7+$AZ7)/2*IF($G$1="鸣金",$AP7,$AN7)+IF($G$1="鸣金",$AQ7*1.5,0))*(1+$BA7)*(1+$BB7)+(($BC7+$BD7)/2*IF($G$1="裂石",$AP7,$AN7)+IF($G$1="裂石",$AQ7*1.5,0))*(1+$BE7)*(1+$BF7)+(($BG7+$BH7)/2*IF($G$1="牵丝",$AP7,$AN7)+IF($G$1="牵丝",$AQ7*1.5,0))*(1+$BI7)*(1+$BJ7)+(($BK7+$BL7)/2*IF($G$1="破竹",$AP7,$AN7)+IF($G$1="破竹",$AQ7*1.5,0))*(1+$BM7)*(1+$BN7))*(1+$AR7)*$BQ7*$Q7*(1+IF(VLOOKUP($R7,武学奇术!$A:$ZZ,30,FALSE)="回旋伞",$B$21,0))*(1+$BW7) -> 19110.874 | N7: =(($AU7*$AN7+$AO7)*(1+$AV7)*(1+$AW7)+($AZ7*IF($G$1="鸣金",$AP7,$AN7)+IF($G$1="鸣金",$AQ7*1.5,0))*(1+$BA7)*(1+$BB7)+($BD7*IF($G$1="裂石",$AP7,$AN7)+IF($G$1="裂石",$AQ7*1.5,0))*(1+$BE7)*(1+$BF7)+($BH7*IF($G$1="牵丝",$AP7,$AN7)+IF($G$1="牵丝",$AQ7*1.5,0))*(1+$BI7)*(1+$BJ7)+($BL7*IF($G$1="破竹",$AP7,$AN7)+IF($G$1="破竹",$AQ7*1.5,0))*(1+$BM7)*(1+$BN7))*(1+$AR7)*$BS7*$Q7*(1+IF(VLOOKUP($R7,武学奇术!$A:$ZZ,30,FALSE)="回旋伞",$B$21,0))*(1+$BW7) -> 18666.111 | O7: =((($AT7+$AU7)/2*$AN7+$AO7)*(1+$AV7)*(1+$AW7)+(($AY7+$AZ7)/2*IF($G$1="鸣金",$AP7,$AN7)+IF($G$1="鸣金",$AQ7*1.5,0))*(1+$BA7)*(1+$BB7)+(($BC7+$BD7)/2*IF($G$1="裂石",$AP7,$AN7)+IF($G$1="裂石",$AQ7*1.5,0))*(1+$BE7)*(1+$BF7)+(($BG7+$BH7)/2*IF($G$1="牵丝",$AP7,$AN7)+IF($G$1="牵丝",$AQ7*1.5,0))*(1+$BI7)*(1+$BJ7)+(($BK7+$BL7)/2*IF($G$1="破竹",$AP7,$AN7)+IF($G$1="破竹",$AQ7*1.5,0))*(1+$BM7)*(1+$BN7))*(1+$AR7)*$Q7*(1+IF(VLOOKUP($R7,武学奇术!$A:$ZZ,30,FALSE)="回旋伞",$B$21,0))*(1+$BW7) -> 12329.596 | P7: =((($AT7*$AN7+$AO7)*(1+$AV7)*(1+$AW7)+($AY7*IF($G$1="鸣金",$AP7,$AN7)+IF($G$1="鸣金",$AQ7*1.5,0))*(1+$BA7)*(1+$BB7)+($BC7*IF($G$1="裂石",$AP7,$AN7)+IF($G$1="裂石",$AQ7*1.5,0))*(1+$BE7)*(1+$BF7)+($BG7*IF($G$1="牵丝",$AP7,$AN7)+IF($G$1="牵丝",$AQ7*1.5,0))*(1+$BI7)*(1+$BJ7)+($BK7*IF($G$1="破竹",$AP7,$AN7)+IF($G$1="破竹",$AQ7*1.5,0))*(1+$BM7)*(1+$BN7))*(1+$AR7))*$Q7*(1+IF(VLOOKUP($R7,武学奇术!$A:$ZZ,30,FALSE)="回旋伞",$B$21,0))*(1+$BW7) -> 10832.443 | Q7: 1 | R7: R蓄123 | S7: N/a | T7: N/a | U7: N/a | V7: N/a | W7: 沧海帖1层 | X7: 易水歌1层 | Y7: N/a | Z7: N/a | AA7: N/a | AB7: N/a | AC7: N/a | AD7: N/a | AE7: 离猎(拐) | AF7: 裁云(拐) | AG7: 无惧 | AH7: N/a | AI7: N/a | AJ7: N/a | AK7: N/a | AL7: N/a | AM7: =VLOOKUP($R7,武学奇术!$A:$ZZ,25,FALSE) -> 绳镖 | AN7: =VLOOKUP($R7,武学奇术!$A:$ZZ,26,FALSE) -> 1.1137 | AO7: =VLOOKUP($R7,武学奇术!$A:$ZZ,27,FALSE)*(1+IF(OR($AM7=$F$4,$AM7=$F$5),$B$22,0)) -> 463.5 | AP7: =VLOOKUP($R7,武学奇术!$A:$ZZ,28,FALSE) -> 1.6706 | AQ7: =VLOOKUP($R7,武学奇术!$A:$ZZ,29,FALSE)*(1+IF(OR($AM7=$F$4,$AM7=$F$5),$B$22,0)) -> 252 | AR7: {=$G$3+IFERROR(VLOOKUP($AM7,$F$4:$G$7,2,FALSE),0)+VLOOKUP($R7,武学奇术!$A:$ZZ,2,FALSE)+SUM(_xlfn.XLOOKUP($S7:$AL7,增益!$A:$A,增益!$B:$B,0))} -> 0.3289 | AS7: {=VLOOKUP($R7,武学奇术!$A:$ZZ,5,FALSE)+SUM(_xlfn.XLOOKUP($S7:$AL7,增益!$A:$A,增益!$E:$E,0))} -> 0 | AT7: {=$D$10*(1+$AS7)+VLOOKUP($R7,武学奇术!$A:$ZZ,3,FALSE)+SUM(_xlfn.XLOOKUP($S7:$AL7,增益!$A:$A,增益!$C:$C,0))-$I$2} -> 3636.6 | AU7: {=$E$10*(1+$AS7)+VLOOKUP($R7,武学奇术!$A:$ZZ,4,FALSE)+SUM(_xlfn.XLOOKUP($S7:$AL7,增益!$A:$A,增益!$D:$D,0))-$I$2} -> 3636.6 | AV7: {=IF($F$10-$I$3+VLOOKUP($R7,武学奇术!$A:$ZZ,6,FALSE)+SUM(_xlfn.XLOOKUP($S7:$AL7,增益!$A:$A,增益!$F:$F,0))>0,($F$10-$I$3+VLOOKUP($R7,武学奇术!$A:$ZZ,6,FALSE)+SUM(_xlfn.XLOOKUP($S7:$AL7,增益!$A:$A,增益!$F:$F,0)))/200,($F$10-$I$3+VLOOKUP($R7,武学奇术!$A:$ZZ,6,FALSE)+SUM(_xlfn.XLOOKUP($S7:$AL7,增益!$A:$A,增益!$F:$F,0)))/100)} -> 0.2525 | AW7: {=$G$10+VLOOKUP($R7,武学奇术!$A:$ZZ,7,FALSE)+SUM(_xlfn.XLOOKUP($S7:$AL7,增益!$A:$A,增益!$G:$G,0))} -> 0.028 | AX7: {=VLOOKUP($R7,武学奇术!$A:$ZZ,8,FALSE)+SUM(_xlfn.XLOOKUP($S7:$AL7,增益!$A:$A,增益!$H:$H,0))} -> 0 | AY7: =$D$11*(1+$AX7) -> 0 | AZ7: =$E$11*(1+$AX7) -> 0 | BA7: {=IF($F$11-$I$4+VLOOKUP($R7,武学奇术!$A:$ZZ,9,FALSE)+SUM(_xlfn.XLOOKUP($S7:$AL7,增益!$A:$A,增益!$I:$I,0))>0,($F$11-$I$4+VLOOKUP($R7,武学奇术!$A:$ZZ,9,FALSE)+SUM(_xlfn.XLOOKUP($S7:$AL7,增益!$A:$A,增益!$I:$I,0)))/200,($F$11-$I$4+VLOOKUP($R7,武学奇术!$A:$ZZ,9,FALSE)+SUM(_xlfn.XLOOKUP($S7:$AL7,增益!$A:$A,增益!$I:$I,0)))/100)} -> -0.3 | BB7: {=$G$11+VLOOKUP($R7,武学奇术!$A:$ZZ,10,FALSE)+SUM(_xlfn.XLOOKUP($S7:$AL7,增益!$A:$A,增益!$J:$J,0))} -> 0 | BC7: =$D$12*(1+$AX7) -> 0 | BD7: =$E$12*(1+$AX7) -> 0 | BE7: {=IF($F$12-$I$4+VLOOKUP($R7,武学奇术!$A:$ZZ,11,FALSE)+SUM(_xlfn.XLOOKUP($S7:$AL7,增益!$A:$A,增益!$K:$K,0))>0,($F$12-$I$4+VLOOKUP($R7,武学奇术!$A:$ZZ,11,FALSE)+SUM(_xlfn.XLOOKUP($S7:$AL7,增益!$A:$A,增益!$K:$K,0)))/200,($F$12-$I$4+VLOOKUP($R7,武学奇术!$A:$ZZ,11,FALSE)+SUM(_xlfn.XLOOKUP($S7:$AL7,增益!$A:$A,增益!$K:$K,0)))/100)} -> -0.3 | BF7: {=$G$12+VLOOKUP($R7,武学奇术!$A:$ZZ,12,FALSE)+SUM(_xlfn.XLOOKUP($S7:$AL7,增益!$A:$A,增益!$L:$L,0))} -> 0 | BG7: =$D$13*(1+$AX7) -> 0 | BH7: =$E$13*(1+$AX7) -> 0 | BI7: {=IF($F$13-$I$4+VLOOKUP($R7,武学奇术!$A:$ZZ,13,FALSE)+SUM(_xlfn.XLOOKUP($S7:$AL7,增益!$A:$A,增益!$M:$M,0))>0,($F$13-$I$4+VLOOKUP($R7,武学奇术!$A:$ZZ,13,FALSE)+SUM(_xlfn.XLOOKUP($S7:$AL7,增益!$A:$A,增益!$K:$K,0)))/200,($F$13-$I$4+VLOOKUP($R7,武学奇术!$A:$ZZ,13,FALSE)+SUM(_xlfn.XLOOKUP($S7:$AL7,增益!$A:$A,增益!$M:$M,0)))/100)} -> -0.3 | BJ7: {=$G$13+VLOOKUP($R7,武学奇术!$A:$ZZ,14,FALSE)+SUM(_xlfn.XLOOKUP($S7:$AL7,增益!$A:$A,增益!$N:$N,0))} -> 0 | BK7: =$D$14*(1+$AX7) -> 571.2 | BL7: =$E$14*(1+$AX7) -> 1627.8 | BM7: {=IF($F$14-$I$4+VLOOKUP($R7,武学奇术!$A:$ZZ,15,FALSE)+SUM(_xlfn.XLOOKUP($S7:$AL7,增益!$A:$A,增益!$O:$O,0))>0,($F$14-$I$4+VLOOKUP($R7,武学奇术!$A:$ZZ,15,FALSE)+SUM(_xlfn.XLOOKUP($S7:$AL7,增益!$A:$A,增益!$O:$O,0)))/200,($F$14-$I$4+VLOOKUP($R7,武学奇术!$A:$ZZ,15,FALSE)+SUM(_xlfn.XLOOKUP($S7:$AL7,增益!$A:$A,增益!$O:$O,0)))/100)} -> 0 | BN7: {=$G$14+VLOOKUP($R7,武学奇术!$A:$ZZ,16,FALSE)+SUM(_xlfn.XLOOKUP($S7:$AL7,增益!$A:$A,增益!$P:$P,0))} -> 0.15 | BO7: =MIN(IF(VLOOKUP($R7,武学奇术!$A:$ZZ,23,FALSE)=1,100%,$B$8),100%) -> 0.981 | BP7: {=IF(VLOOKUP($R7,武学奇术!$A:$ZZ,23,FALSE)=1,100%,MIN(80%,$B$9+VLOOKUP($R7,武学奇术!$A:$ZZ,17,FALSE)+SUM(_xlfn.XLOOKUP($S7:$AL7,增益!$A:$A,增益!$Q:$Q,0)))+$B$11+SUM(_xlfn.XLOOKUP($S7:$AL7,增益!$A:$A,增益!$U:$U,0)))*IF(VLOOKUP($R7,武学奇术!$A:$ZZ,24,FALSE)=1,0,1)} -> 0.846 | BQ7: {=1+$B$13+VLOOKUP($R7,武学奇术!$A:$ZZ,18,FALSE)+SUM(_xlfn.XLOOKUP($S7:$AL7,增益!$A:$A,增益!$R:$R,0))} -> 1.55 | BR7: {=IF(VLOOKUP($R7,武学奇术!$A:$ZZ,24,FALSE)=1,100%,MIN(40%,$B$10+VLOOKUP($R7,武学奇术!$A:$ZZ,19,FALSE)+SUM(_xlfn.XLOOKUP($S7:$AL7,增益!$A:$A,增益!$S:$S,0)))+$B$12+SUM(_xlfn.XLOOKUP($S7:$AL7,增益!$A:$A,增益!$V:$V,0)))*IF(VLOOKUP($R7,武学奇术!$A:$ZZ,23,FALSE)=1,0,1)} -> 0.0929 | BS7: {=1+$B$14+VLOOKUP($R7,武学奇术!$A:$ZZ,20,FALSE)+SUM(_xlfn.XLOOKUP($S7:$AL7,增益!$A:$A,增益!$T:$T,0))} -> 1.35 | BT7: =MIN((1-BR7)*BO7,BO7*BP7) -> 0.829926 | BU7: =1-BR7-BT7-BV7 -> 0.0599391 | BV7: =IF(VLOOKUP($R7,武学奇术!$A:$ZZ,22,FALSE)=1,0,(1-$BO7))*(1-$BR7) -> 0.0172349 | BW7: {=SUM(_xlfn.XLOOKUP($S7:$AL7,增益!$A:$A,增益!$W:$W,0))+$I$5} -> 0.11 | BX7: {=SUM(_xlfn.XLOOKUP($S7:$AL7,增益!$A:$A,增益!$X:$X,0))} -> 0
A8: 精准率 | B8: 0.981 | C8: 实际属性 | H8: 战斗时间 | I8: 101 | K8: =$L8*VLOOKUP($R8,武学奇术!$A:$ZZ,31,FALSE) -> 14563.299 | L8: =($M8*$BT8+$N8*$BR8+$O8*$BU8+$P8*$BV8) -> 13869.809 | M8: =((($AT8+$AU8)/2*$AN8+$AO8)*(1+$AV8)*(1+$AW8)+(($AY8+$AZ8)/2*IF($G$1="鸣金",$AP8,$AN8)+IF($G$1="鸣金",$AQ8*1.5,0))*(1+$BA8)*(1+$BB8)+(($BC8+$BD8)/2*IF($G$1="裂石",$AP8,$AN8)+IF($G$1="裂石",$AQ8*1.5,0))*(1+$BE8)*(1+$BF8)+(($BG8+$BH8)/2*IF($G$1="牵丝",$AP8,$AN8)+IF($G$1="牵丝",$AQ8*1.5,0))*(1+$BI8)*(1+$BJ8)+(($BK8+$BL8)/2*IF($G$1="破竹",$AP8,$AN8)+IF($G$1="破竹",$AQ8*1.5,0))*(1+$BM8)*(1+$BN8))*(1+$AR8)*$BQ8*$Q8*(1+IF(VLOOKUP($R8,武学奇术!$A:$ZZ,30,FALSE)="回旋伞",$B$21,0))*(1+$BW8) -> 14305.273 | N8: =(($AU8*$AN8+$AO8)*(1+$AV8)*(1+$AW8)+($AZ8*IF($G$1="鸣金",$AP8,$AN8)+IF($G$1="鸣金",$AQ8*1.5,0))*(1+$BA8)*(1+$BB8)+($BD8*IF($G$1="裂石",$AP8,$AN8)+IF($G$1="裂石",$AQ8*1.5,0))*(1+$BE8)*(1+$BF8)+($BH8*IF($G$1="牵丝",$AP8,$AN8)+IF($G$1="牵丝",$AQ8*1.5,0))*(1+$BI8)*(1+$BJ8)+($BL8*IF($G$1="破竹",$AP8,$AN8)+IF($G$1="破竹",$AQ8*1.5,0))*(1+$BM8)*(1+$BN8))*(1+$AR8)*$BS8*$Q8*(1+IF(VLOOKUP($R8,武学奇术!$A:$ZZ,30,FALSE)="回旋伞",$B$21,0))*(1+$BW8) -> 14053.703 | O8: =((($AT8+$AU8)/2*$AN8+$AO8)*(1+$AV8)*(1+$AW8)+(($AY8+$AZ8)/2*IF($G$1="鸣金",$AP8,$AN8)+IF($G$1="鸣金",$AQ8*1.5,0))*(1+$BA8)*(1+$BB8)+(($BC8+$BD8)/2*IF($G$1="裂石",$AP8,$AN8)+IF($G$1="裂石",$AQ8*1.5,0))*(1+$BE8)*(1+$BF8)+(($BG8+$BH8)/2*IF($G$1="牵丝",$AP8,$AN8)+IF($G$1="牵丝",$AQ8*1.5,0))*(1+$BI8)*(1+$BJ8)+(($BK8+$BL8)/2*IF($G$1="破竹",$AP8,$AN8)+IF($G$1="破竹",$AQ8*1.5,0))*(1+$BM8)*(1+$BN8))*(1+$AR8)*$Q8*(1+IF(VLOOKUP($R8,武学奇术!$A:$ZZ,30,FALSE)="回旋伞",$B$21,0))*(1+$BW8) -> 9229.2086 | P8: =((($AT8*$AN8+$AO8)*(1+$AV8)*(1+$AW8)+($AY8*IF($G$1="鸣金",$AP8,$AN8)+IF($G$1="鸣金",$AQ8*1.5,0))*(1+$BA8)*(1+$BB8)+($BC8*IF($G$1="裂石",$AP8,$AN8)+IF($G$1="裂石",$AQ8*1.5,0))*(1+$BE8)*(1+$BF8)+($BG8*IF($G$1="牵丝",$AP8,$AN8)+IF($G$1="牵丝",$AQ8*1.5,0))*(1+$BI8)*(1+$BJ8)+($BK8*IF($G$1="破竹",$AP8,$AN8)+IF($G$1="破竹",$AQ8*1.5,0))*(1+$BM8)*(1+$BN8))*(1+$AR8))*$Q8*(1+IF(VLOOKUP($R8,武学奇术!$A:$ZZ,30,FALSE)="回旋伞",$B$21,0))*(1+$BW8) -> 8048.2672 | Q8: 1 | R8: R蓄45 | S8: N/a | T8: N/a | U8: N/a | V8: N/a | W8: 沧海帖1层 | X8: 易水歌1层 | Y8: 惧刃(拐) | Z8: N/a | AA8: N/a | AB8: N/a | AC8: 扶风(拐) | AD8: N/a | AE8: 离猎(拐) | AF8: 裁云(拐) | AG8: 无惧 | AH8: N/a | AI8: N/a | AJ8: N/a | AK8: N/a | AL8: N/a | AM8: =VLOOKUP($R8,武学奇术!$A:$ZZ,25,FALSE) -> 绳镖 | AN8: =VLOOKUP($R8,武学奇术!$A:$ZZ,26,FALSE) -> 0.7839 | AO8: =VLOOKUP($R8,武学奇术!$A:$ZZ,27,FALSE)*(1+IF(OR($AM8=$F$4,$AM8=$F$5),$B$22,0)) -> 327 | AP8: =VLOOKUP($R8,武学奇术!$A:$ZZ,28,FALSE) -> 1.1759 | AQ8: =VLOOKUP($R8,武学奇术!$A:$ZZ,29,FALSE)*(1+IF(OR($AM8=$F$4,$AM8=$F$5),$B$22,0)) -> 178.5 | AR8: {=$G$3+IFERROR(VLOOKUP($AM8,$F$4:$G$7,2,FALSE),0)+VLOOKUP($R8,武学奇术!$A:$ZZ,2,FALSE)+SUM(_xlfn.XLOOKUP($S8:$AL8,增益!$A:$A,增益!$B:$B,0))} -> 0.3789 | AS8: {=VLOOKUP($R8,武学奇术!$A:$ZZ,5,FALSE)+SUM(_xlfn.XLOOKUP($S8:$AL8,增益!$A:$A,增益!$E:$E,0))} -> 0 | AT8: {=$D$10*(1+$AS8)+VLOOKUP($R8,武学奇术!$A:$ZZ,3,FALSE)+SUM(_xlfn.XLOOKUP($S8:$AL8,增益!$A:$A,增益!$C:$C,0))-$I$2} -> 3636.6 | AU8: {=$E$10*(1+$AS8)+VLOOKUP($R8,武学奇术!$A:$ZZ,4,FALSE)+SUM(_xlfn.XLOOKUP($S8:$AL8,增益!$A:$A,增益!$D:$D,0))-$I$2} -> 3636.6 | AV8: {=IF($F$10-$I$3+VLOOKUP($R8,武学奇术!$A:$ZZ,6,FALSE)+SUM(_xlfn.XLOOKUP($S8:$AL8,增益!$A:$A,增益!$F:$F,0))>0,($F$10-$I$3+VLOOKUP($R8,武学奇术!$A:$ZZ,6,FALSE)+SUM(_xlfn.XLOOKUP($S8:$AL8,增益!$A:$A,增益!$F:$F,0)))/200,($F$10-$I$3+VLOOKUP($R8,武学奇术!$A:$ZZ,6,FALSE)+SUM(_xlfn.XLOOKUP($S8:$AL8,增益!$A:$A,增益!$F:$F,0)))/100)} -> 0.2525 | AW8: {=$G$10+VLOOKUP($R8,武学奇术!$A:$ZZ,7,FALSE)+SUM(_xlfn.XLOOKUP($S8:$AL8,增益!$A:$A,增益!$G:$G,0))} -> 0.028 | AX8: {=VLOOKUP($R8,武学奇术!$A:$ZZ,8,FALSE)+SUM(_xlfn.XLOOKUP($S8:$AL8,增益!$A:$A,增益!$H:$H,0))} -> 0 | AY8: =$D$11*(1+$AX8) -> 0 | AZ8: =$E$11*(1+$AX8) -> 0 | BA8: {=IF($F$11-$I$4+VLOOKUP($R8,武学奇术!$A:$ZZ,9,FALSE)+SUM(_xlfn.XLOOKUP($S8:$AL8,增益!$A:$A,增益!$I:$I,0))>0,($F$11-$I$4+VLOOKUP($R8,武学奇术!$A:$ZZ,9,FALSE)+SUM(_xlfn.XLOOKUP($S8:$AL8,增益!$A:$A,增益!$I:$I,0)))/200,($F$11-$I$4+VLOOKUP($R8,武学奇术!$A:$ZZ,9,FALSE)+SUM(_xlfn.XLOOKUP($S8:$AL8,增益!$A:$A,增益!$I:$I,0)))/100)} -> -0.14 | BB8: {=$G$11+VLOOKUP($R8,武学奇术!$A:$ZZ,10,FALSE)+SUM(_xlfn.XLOOKUP($S8:$AL8,增益!$A:$A,增益!$J:$J,0))} -> 0 | BC8: =$D$12*(1+$AX8) -> 0 | BD8: =$E$12*(1+$AX8) -> 0 | BE8: {=IF($F$12-$I$4+VLOOKUP($R8,武学奇术!$A:$ZZ,11,FALSE)+SUM(_xlfn.XLOOKUP($S8:$AL8,增益!$A:$A,增益!$K:$K,0))>0,($F$12-$I$4+VLOOKUP($R8,武学奇术!$A:$ZZ,11,FALSE)+SUM(_xlfn.XLOOKUP($S8:$AL8,增益!$A:$A,增益!$K:$K,0)))/200,($F$12-$I$4+VLOOKUP($R8,武学奇术!$A:$ZZ,11,FALSE)+SUM(_xlfn.XLOOKUP($S8:$AL8,增益!$A:$A,增益!$K:$K,0)))/100)} -> -0.14 | BF8: {=$G$12+VLOOKUP($R8,武学奇术!$A:$ZZ,12,FALSE)+SUM(_xlfn.XLOOKUP($S8:$AL8,增益!$A:$A,增益!$L:$L,0))} -> 0 | BG8: =$D$13*(1+$AX8) -> 0 | BH8: =$E$13*(1+$AX8) -> 0 | BI8: {=IF($F$13-$I$4+VLOOKUP($R8,武学奇术!$A:$ZZ,13,FALSE)+SUM(_xlfn.XLOOKUP($S8:$AL8,增益!$A:$A,增益!$M:$M,0))>0,($F$13-$I$4+VLOOKUP($R8,武学奇术!$A:$ZZ,13,FALSE)+SUM(_xlfn.XLOOKUP($S8:$AL8,增益!$A:$A,增益!$K:$K,0)))/200,($F$13-$I$4+VLOOKUP($R8,武学奇术!$A:$ZZ,13,FALSE)+SUM(_xlfn.XLOOKUP($S8:$AL8,增益!$A:$A,增益!$M:$M,0)))/100)} -> -0.14 | BJ8: {=$G$13+VLOOKUP($R8,武学奇术!$A:$ZZ,14,FALSE)+SUM(_xlfn.XLOOKUP($S8:$AL8,增益!$A:$A,增益!$N:$N,0))} -> 0 | BK8: =$D$14*(1+$AX8) -> 571.2 | BL8: =$E$14*(1+$AX8) -> 1627.8 | BM8: {=IF($F$14-$I$4+VLOOKUP($R8,武学奇术!$A:$ZZ,15,FALSE)+SUM(_xlfn.XLOOKUP($S8:$AL8,增益!$A:$A,增益!$O:$O,0))>0,($F$14-$I$4+VLOOKUP($R8,武学奇术!$A:$ZZ,15,FALSE)+SUM(_xlfn.XLOOKUP($S8:$AL8,增益!$A:$A,增益!$O:$O,0)))/200,($F$14-$I$4+VLOOKUP($R8,武学奇术!$A:$ZZ,15,FALSE)+SUM(_xlfn.XLOOKUP($S8:$AL8,增益!$A:$A,增益!$O:$O,0)))/100)} -> 0.08 | BN8: {=$G$14+VLOOKUP($R8,武学奇术!$A:$ZZ,16,FALSE)+SUM(_xlfn.XLOOKUP($S8:$AL8,增益!$A:$A,增益!$P:$P,0))} -> 0.15 | BO8: =MIN(IF(VLOOKUP($R8,武学奇术!$A:$ZZ,23,FALSE)=1,100%,$B$8),100%) -> 0.981 | BP8: {=IF(VLOOKUP($R8,武学奇术!$A:$ZZ,23,FALSE)=1,100%,MIN(80%,$B$9+VLOOKUP($R8,武学奇术!$A:$ZZ,17,FALSE)+SUM(_xlfn.XLOOKUP($S8:$AL8,增益!$A:$A,增益!$Q:$Q,0)))+$B$11+SUM(_xlfn.XLOOKUP($S8:$AL8,增益!$A:$A,增益!$U:$U,0)))*IF(VLOOKUP($R8,武学奇术!$A:$ZZ,24,FALSE)=1,0,1)} -> 0.846 | BQ8: {=1+$B$13+VLOOKUP($R8,武学奇术!$A:$ZZ,18,FALSE)+SUM(_xlfn.XLOOKUP($S8:$AL8,增益!$A:$A,增益!$R:$R,0))} -> 1.55 | BR8: {=IF(VLOOKUP($R8,武学奇术!$A:$ZZ,24,FALSE)=1,100%,MIN(40%,$B$10+VLOOKUP($R8,武学奇术!$A:$ZZ,19,FALSE)+SUM(_xlfn.XLOOKUP($S8:$AL8,增益!$A:$A,增益!$S:$S,0)))+$B$12+SUM(_xlfn.XLOOKUP($S8:$AL8,增益!$A:$A,增益!$V:$V,0)))*IF(VLOOKUP($R8,武学奇术!$A:$ZZ,23,FALSE)=1,0,1)} -> 0.0929 | BS8: {=1+$B$14+VLOOKUP($R8,武学奇术!$A:$ZZ,20,FALSE)+SUM(_xlfn.XLOOKUP($S8:$AL8,增益!$A:$A,增益!$T:$T,0))} -> 1.35 | BT8: =MIN((1-BR8)*BO8,BO8*BP8) -> 0.829926 | BU8: =1-BR8-BT8-BV8 -> 0.0599391 | BV8: =IF(VLOOKUP($R8,武学奇术!$A:$ZZ,22,FALSE)=1,0,(1-$BO8))*(1-$BR8) -> 0.0172349 | BW8: {=SUM(_xlfn.XLOOKUP($S8:$AL8,增益!$A:$A,增益!$W:$W,0))+$I$5} -> 0.11 | BX8: {=SUM(_xlfn.XLOOKUP($S8:$AL8,增益!$A:$A,增益!$X:$X,0))} -> 0
A9: 会心率 | B9: 0.8049 | D9: 最小攻击 | E9: 最大攻击 | F9: 穿透 | G9: 伤害加成 | K9: =$L9*VLOOKUP($R9,武学奇术!$A:$ZZ,31,FALSE) -> 75345.192 | L9: =($M9*$BT9+$N9*$BR9+$O9*$BU9+$P9*$BV9) -> 71757.326 | M9: =((($AT9+$AU9)/2*$AN9+$AO9)*(1+$AV9)*(1+$AW9)+(($AY9+$AZ9)/2*IF($G$1="鸣金",$AP9,$AN9)+IF($G$1="鸣金",$AQ9*1.5,0))*(1+$BA9)*(1+$BB9)+(($BC9+$BD9)/2*IF($G$1="裂石",$AP9,$AN9)+IF($G$1="裂石",$AQ9*1.5,0))*(1+$BE9)*(1+$BF9)+(($BG9+$BH9)/2*IF($G$1="牵丝",$AP9,$AN9)+IF($G$1="牵丝",$AQ9*1.5,0))*(1+$BI9)*(1+$BJ9)+(($BK9+$BL9)/2*IF($G$1="破竹",$AP9,$AN9)+IF($G$1="破竹",$AQ9*1.5,0))*(1+$BM9)*(1+$BN9))*(1+$AR9)*$BQ9*$Q9*(1+IF(VLOOKUP($R9,武学奇术!$A:$ZZ,30,FALSE)="回旋伞",$B$21,0))*(1+$BW9) -> 75633.331 | N9: =(($AU9*$AN9+$AO9)*(1+$AV9)*(1+$AW9)+($AZ9*IF($G$1="鸣金",$AP9,$AN9)+IF($G$1="鸣金",$AQ9*1.5,0))*(1+$BA9)*(1+$BB9)+($BD9*IF($G$1="裂石",$AP9,$AN9)+IF($G$1="裂石",$AQ9*1.5,0))*(1+$BE9)*(1+$BF9)+($BH9*IF($G$1="牵丝",$AP9,$AN9)+IF($G$1="牵丝",$AQ9*1.5,0))*(1+$BI9)*(1+$BJ9)+($BL9*IF($G$1="破竹",$AP9,$AN9)+IF($G$1="破竹",$AQ9*1.5,0))*(1+$BM9)*(1+$BN9))*(1+$AR9)*$BS9*$Q9*(1+IF(VLOOKUP($R9,武学奇术!$A:$ZZ,30,FALSE)="回旋伞",$B$21,0))*(1+$BW9) -> 63193.719 | O9: =((($AT9+$AU9)/2*$AN9+$AO9)*(1+$AV9)*(1+$AW9)+(($AY9+$AZ9)/2*IF($G$1="鸣金",$AP9,$AN9)+IF($G$1="鸣金",$AQ9*1.5,0))*(1+$BA9)*(1+$BB9)+(($BC9+$BD9)/2*IF($G$1="裂石",$AP9,$AN9)+IF($G$1="裂石",$AQ9*1.5,0))*(1+$BE9)*(1+$BF9)+(($BG9+$BH9)/2*IF($G$1="牵丝",$AP9,$AN9)+IF($G$1="牵丝",$AQ9*1.5,0))*(1+$BI9)*(1+$BJ9)+(($BK9+$BL9)/2*IF($G$1="破竹",$AP9,$AN9)+IF($G$1="破竹",$AQ9*1.5,0))*(1+$BM9)*(1+$BN9))*(1+$AR9)*$Q9*(1+IF(VLOOKUP($R9,武学奇术!$A:$ZZ,30,FALSE)="回旋伞",$B$21,0))*(1+$BW9) -> 41556.775 | P9: =((($AT9*$AN9+$AO9)*(1+$AV9)*(1+$AW9)+($AY9*IF($G$1="鸣金",$AP9,$AN9)+IF($G$1="鸣金",$AQ9*1.5,0))*(1+$BA9)*(1+$BB9)+($BC9*IF($G$1="裂石",$AP9,$AN9)+IF($G$1="裂石",$AQ9*1.5,0))*(1+$BE9)*(1+$BF9)+($BG9*IF($G$1="牵丝",$AP9,$AN9)+IF($G$1="牵丝",$AQ9*1.5,0))*(1+$BI9)*(1+$BJ9)+($BK9*IF($G$1="破竹",$AP9,$AN9)+IF($G$1="破竹",$AQ9*1.5,0))*(1+$BM9)*(1+$BN9))*(1+$AR9))*$Q9*(1+IF(VLOOKUP($R9,武学奇术!$A:$ZZ,30,FALSE)="回旋伞",$B$21,0))*(1+$BW9) -> 36303.388 | Q9: 1 | R9: 完美伞 | S9: 连星(8+) | T9: N/a | U9: 失魂落魄 | V9: 远程笛 | W9: 沧海帖1层 | X9: 易水歌2层 | Y9: 惧刃(拐) | Z9: N/a | AA9: N/a | AB9: N/a | AC9: 扶风(拐) | AD9: N/a | AE9: 离猎(拐) | AF9: 裁云(拐) | AG9: 无惧 | AH9: N/a | AI9: N/a | AJ9: N/a | AK9: N/a | AL9: N/a | AM9: =VLOOKUP($R9,武学奇术!$A:$ZZ,25,FALSE) -> 伞 | AN9: =VLOOKUP($R9,武学奇术!$A:$ZZ,26,FALSE) -> 1.8084 | AO9: =VLOOKUP($R9,武学奇术!$A:$ZZ,27,FALSE)*(1+IF(OR($AM9=$F$4,$AM9=$F$5),$B$22,0)) -> 750 | AP9: =VLOOKUP($R9,武学奇术!$A:$ZZ,28,FALSE) -> 2.7126 | AQ9: =VLOOKUP($R9,武学奇术!$A:$ZZ,29,FALSE)*(1+IF(OR($AM9=$F$4,$AM9=$F$5),$B$22,0)) -> 408 | AR9: {=$G$3+IFERROR(VLOOKUP($AM9,$F$4:$G$7,2,FALSE),0)+VLOOKUP($R9,武学奇术!$A:$ZZ,2,FALSE)+SUM(_xlfn.XLOOKUP($S9:$AL9,增益!$A:$A,增益!$B:$B,0))} -> 0.8241 | AS9: {=VLOOKUP($R9,武学奇术!$A:$ZZ,5,FALSE)+SUM(_xlfn.XLOOKUP($S9:$AL9,增益!$A:$A,增益!$E:$E,0))} -> 0 | AT9: {=$D$10*(1+$AS9)+VLOOKUP($R9,武学奇术!$A:$ZZ,3,FALSE)+SUM(_xlfn.XLOOKUP($S9:$AL9,增益!$A:$A,增益!$C:$C,0))-$I$2} -> 3636.6 | AU9: {=$E$10*(1+$AS9)+VLOOKUP($R9,武学奇术!$A:$ZZ,4,FALSE)+SUM(_xlfn.XLOOKUP($S9:$AL9,增益!$A:$A,增益!$D:$D,0))-$I$2} -> 3636.6 | AV9: {=IF($F$10-$I$3+VLOOKUP($R9,武学奇术!$A:$ZZ,6,FALSE)+SUM(_xlfn.XLOOKUP($S9:$AL9,增益!$A:$A,增益!$F:$F,0))>0,($F$10-$I$3+VLOOKUP($R9,武学奇术!$A:$ZZ,6,FALSE)+SUM(_xlfn.XLOOKUP($S9:$AL9,增益!$A:$A,增益!$F:$F,0)))/200,($F$10-$I$3+VLOOKUP($R9,武学奇术!$A:$ZZ,6,FALSE)+SUM(_xlfn.XLOOKUP($S9:$AL9,增益!$A:$A,增益!$F:$F,0)))/100)} -> 0.2625 | AW9: {=$G$10+VLOOKUP($R9,武学奇术!$A:$ZZ,7,FALSE)+SUM(_xlfn.XLOOKUP($S9:$AL9,增益!$A:$A,增益!$G:$G,0))} -> 0.148 | AX9: {=VLOOKUP($R9,武学奇术!$A:$ZZ,8,FALSE)+SUM(_xlfn.XLOOKUP($S9:$AL9,增益!$A:$A,增益!$H:$H,0))} -> 0 | AY9: =$D$11*(1+$AX9) -> 0 | AZ9: =$E$11*(1+$AX9) -> 0 | BA9: {=IF($F$11-$I$4+VLOOKUP($R9,武学奇术!$A:$ZZ,9,FALSE)+SUM(_xlfn.XLOOKUP($S9:$AL9,增益!$A:$A,增益!$I:$I,0))>0,($F$11-$I$4+VLOOKUP($R9,武学奇术!$A:$ZZ,9,FALSE)+SUM(_xlfn.XLOOKUP($S9:$AL9,增益!$A:$A,增益!$I:$I,0)))/200,($F$11-$I$4+VLOOKUP($R9,武学奇术!$A:$ZZ,9,FALSE)+SUM(_xlfn.XLOOKUP($S9:$AL9,增益!$A:$A,增益!$I:$I,0)))/100)} -> -0.14 | BB9: {=$G$11+VLOOKUP($R9,武学奇术!$A:$ZZ,10,FALSE)+SUM(_xlfn.XLOOKUP($S9:$AL9,增益!$A:$A,增益!$J:$J,0))} -> 0 | BC9: =$D$12*(1+$AX9) -> 0 | BD9: =$E$12*(1+$AX9) -> 0 | BE9: {=IF($F$12-$I$4+VLOOKUP($R9,武学奇术!$A:$ZZ,11,FALSE)+SUM(_xlfn.XLOOKUP($S9:$AL9,增益!$A:$A,增益!$K:$K,0))>0,($F$12-$I$4+VLOOKUP($R9,武学奇术!$A:$ZZ,11,FALSE)+SUM(_xlfn.XLOOKUP($S9:$AL9,增益!$A:$A,增益!$K:$K,0)))/200,($F$12-$I$4+VLOOKUP($R9,武学奇术!$A:$ZZ,11,FALSE)+SUM(_xlfn.XLOOKUP($S9:$AL9,增益!$A:$A,增益!$K:$K,0)))/100)} -> -0.14 | BF9: {=$G$12+VLOOKUP($R9,武学奇术!$A:$ZZ,12,FALSE)+SUM(_xlfn.XLOOKUP($S9:$AL9,增益!$A:$A,增益!$L:$L,0))} -> 0 | BG9: =$D$13*(1+$AX9) -> 0 | BH9: =$E$13*(1+$AX9) -> 0 | BI9: {=IF($F$13-$I$4+VLOOKUP($R9,武学奇术!$A:$ZZ,13,FALSE)+SUM(_xlfn.XLOOKUP($S9:$AL9,增益!$A:$A,增益!$M:$M,0))>0,($F$13-$I$4+VLOOKUP($R9,武学奇术!$A:$ZZ,13,FALSE)+SUM(_xlfn.XLOOKUP($S9:$AL9,增益!$A:$A,增益!$K:$K,0)))/200,($F$13-$I$4+VLOOKUP($R9,武学奇术!$A:$ZZ,13,FALSE)+SUM(_xlfn.XLOOKUP($S9:$AL9,增益!$A:$A,增益!$M:$M,0)))/100)} -> -0.14 | BJ9: {=$G$13+VLOOKUP($R9,武学奇术!$A:$ZZ,14,FALSE)+SUM(_xlfn.XLOOKUP($S9:$AL9,增益!$A:$A,增益!$N:$N,0))} -> 0 | BK9: =$D$14*(1+$AX9) -> 571.2 | BL9: =$E$14*(1+$AX9) -> 1627.8 | BM9: {=IF($F$14-$I$4+VLOOKUP($R9,武学奇术!$A:$ZZ,15,FALSE)+SUM(_xlfn.XLOOKUP($S9:$AL9,增益!$A:$A,增益!$O:$O,0))>0,($F$14-$I$4+VLOOKUP($R9,武学奇术!$A:$ZZ,15,FALSE)+SUM(_xlfn.XLOOKUP($S9:$AL9,增益!$A:$A,增益!$O:$O,0)))/200,($F$14-$I$4+VLOOKUP($R9,武学奇术!$A:$ZZ,15,FALSE)+SUM(_xlfn.XLOOKUP($S9:$AL9,增益!$A:$A,增益!$O:$O,0)))/100)} -> 0.08 | BN9: {=$G$14+VLOOKUP($R9,武学奇术!$A:$ZZ,16,FALSE)+SUM(_xlfn.XLOOKUP($S9:$AL9,增益!$A:$A,增益!$P:$P,0))} -> 0.27 | BO9: =MIN(IF(VLOOKUP($R9,武学奇术!$A:$ZZ,23,FALSE)=1,100%,$B$8),100%) -> 0.981 | BP9: {=IF(VLOOKUP($R9,武学奇术!$A:$ZZ,23,FALSE)=1,100%,MIN(80%,$B$9+VLOOKUP($R9,武学奇术!$A:$ZZ,17,FALSE)+SUM(_xlfn.XLOOKUP($S9:$AL9,增益!$A:$A,增益!$Q:$Q,0)))+$B$11+SUM(_xlfn.XLOOKUP($S9:$AL9,增益!$A:$A,增益!$U:$U,0)))*IF(VLOOKUP($R9,武学奇术!$A:$ZZ,24,FALSE)=1,0,1)} -> 0.846 | BQ9: {=1+$B$13+VLOOKUP($R9,武学奇术!$A:$ZZ,18,FALSE)+SUM(_xlfn.XLOOKUP($S9:$AL9,增益!$A:$A,增益!$R:$R,0))} -> 1.82 | BR9: {=IF(VLOOKUP($R9,武学奇术!$A:$ZZ,24,FALSE)=1,100%,MIN(40%,$B$10+VLOOKUP($R9,武学奇术!$A:$ZZ,19,FALSE)+SUM(_xlfn.XLOOKUP($S9:$AL9,增益!$A:$A,增益!$S:$S,0)))+$B$12+SUM(_xlfn.XLOOKUP($S9:$AL9,增益!$A:$A,增益!$V:$V,0)))*IF(VLOOKUP($R9,武学奇术!$A:$ZZ,23,FALSE)=1,0,1)} -> 0.0929 | BS9: {=1+$B$14+VLOOKUP($R9,武学奇术!$A:$ZZ,20,FALSE)+SUM(_xlfn.XLOOKUP($S9:$AL9,增益!$A:$A,增益!$T:$T,0))} -> 1.35 | BT9: =MIN((1-BR9)*BO9,BO9*BP9) -> 0.829926 | BU9: =1-BR9-BT9-BV9 -> 0.0599391 | BV9: =IF(VLOOKUP($R9,武学奇术!$A:$ZZ,22,FALSE)=1,0,(1-$BO9))*(1-$BR9) -> 0.0172349 | BW9: {=SUM(_xlfn.XLOOKUP($S9:$AL9,增益!$A:$A,增益!$W:$W,0))+$I$5} -> 0.11 | BX9: {=SUM(_xlfn.XLOOKUP($S9:$AL9,增益!$A:$A,增益!$X:$X,0))} -> 0
