Workbook

Sheet 期望
B1: 最小攻击 | C1: 最大攻击 | D1: 穿透 | E1: 伤害加成 | F1: 武学属性 | G1: 破竹 | H1: 怪物属性 | K1: 真气比列 | L1: 期望 | M1: 会心期望 | N1: 会意期望 | O1: 普通期望 | P1: 擦伤期望 | Q1: 次数 | R1: 技能 | S1: 增益1 | T1: 增益2 | U1: 增益3 | V1: 增益4 | W1: 增益5 | X1: 增益6 | Y1: 增益7 | Z1: 增益8 | AA1: 增益9 | AB1: 增益10 | AC1: 增益11 | AD1: 增益12 | AE1: 增益13 | AF1: 增益14 | AG1: 增益15 | AH1: 增益16 | AI1: 增益17 | AJ1: 增益18 | AK1: 增益19 | AL1: 增益20 | AM1: 类型 | AN1: 外功倍率 | AO1: 外攻固伤 | AP1: 属性倍率 | AQ1: 属性固伤 | AR1: 通用增伤 | AS1: 外攻加成 | AT1: 即时小外 | AU1: 即时大外 | AV1: 外穿加成 | AW1: 外伤加成 | AX1: 属攻加成 | AY1: 即时小鸣 | AZ1: 即时大鸣 | BA1: 鸣金穿透 | BB1: 鸣金加成 | BC1: 即时小裂 | BD1: 即时大裂 | BE1: 裂石穿透 | BF1: 裂石加成 | BG1: 即时小牵 | BH1: 即时大牵 | BI1: 牵丝穿透 | BJ1: 牵丝加成 | BK1: 即时小破 | BL1: 即时大破 | BM1: 破竹穿透 | BN1: 破竹加成 | BO1: 生效精准 | BP1: 生效会心 | BQ1: 生效会心伤害 | BR1: 生效会意 | BS1: 生效会意伤害 | BT1: 会心占比 | BU1: 普攻占比 | BV1: 擦伤占比 | BW1: 特殊增伤 | BX1: 结算增伤
A2: 外功 | B2: 4006.7 | C2: 3083.9 | D2: =58.4+IF($E$24="征人归",5.1,0) -> 58.4 | E2: =IF($E$22="三穷致知",2.5%,0) -> 0 | F2: 套装 | G2: 撼天 | H2: 防御 | I2: =620*(1-IF(F17="√",0.06,0)-IF(D20="√",0.04,0)) -> 558 | K2: =$L2*VLOOKUP($R2,武学奇术!$A:$ZZ,31,FALSE) -> 24679.691 | L2: =($M2*$BT2+$N2*$BR2+$O2*$BU2+$P2*$BV2) -> 24679.691 | M2: =((($AT2+($AU2-$AT2)*IF(VLOOKUP($R2,武学奇术!$A:$ZZ,31,FALSE)=1,$F$18,0.5))*$AN2+$AO2)*(1+$AV2)*(1+$AW2)+(($AY2+($AZ2-$AY2)*IF(VLOOKUP($R2,武学奇术!$A:$ZZ,31,FALSE)=1,$F$18,0.5))*IF($G$1="鸣金",$AP2,$AN2)+IF($G$1="鸣金",$AQ2*1.5,0))*(1+$BA2)*(1+$BB2)+(($BC2+($BD2-$BC2)*IF(VLOOKUP($R2,武学奇术!$A:$ZZ,31,FALSE)=1,$F$18,0.5))*IF($G$1="裂石",$AP2,$AN2)+IF($G$1="裂石",$AQ2*1.5,0))*(1+$BE2)*(1+$BF2)+(($BG2+($BH2-$BG2)*IF(VLOOKUP($R2,武学奇术!$A:$ZZ,31,FALSE)=1,$F$18,0.5))*IF($G$1="牵丝",$AP2,$AN2)+IF($G$1="牵丝",$AQ2*1.5,0))*(1+$BI2)*(1+$BJ2)+(($BK2+($BL2-$BK2)*IF(VLOOKUP($R2,武学奇术!$A:$ZZ,31,FALSE)=1,$F$18,0.5))*IF($G$1="破竹",$AP2,$AN2)+IF($G$1="破竹",$AQ2*1.5,0))*(1+$BM2)*(1+$BN2))*(1+$AR2)*$BQ2*$Q2*(1+IF(VLOOKUP($R2,武学奇术!$A:$ZZ,30,FALSE)="蓄力技",$B$21,0))*(1+$BW2) -> 24744.747 | N2: =(($AU2*$AN2+$AO2)*(1+$AV2)*(1+$AW2)+($AZ2*IF($G$1="鸣金",$AP2,$AN2)+IF($G$1="鸣金",$AQ2*1.5,0))*(1+$BA2)*(1+$BB2)+($BD2*IF($G$1="裂石",$AP2,$AN2)+IF($G$1="裂石",$AQ2*1.5,0))*(1+$BE2)*(1+$BF2)+($BH2*IF($G$1="牵丝",$AP2,$AN2)+IF($G$1="牵丝",$AQ2*1.5,0))*(1+$BI2)*(1+$BJ2)+($BL2*IF($G$1="破竹",$AP2,$AN2)+IF($G$1="破竹",$AQ2*1.5,0))*(1+$BM2)*(1+$BN2))*(1+$AR2)*$BS2*$Q2*(1+IF(VLOOKUP($R2,武学奇术!$A:$ZZ,30,FALSE)="蓄力技",$B$21,0))*(1+$BW2) -> 24375.263 | O2: =((($AT2+($AU2-$AT2)*IF(VLOOKUP($R2,武学奇术!$A:$ZZ,31,FALSE)=1,$F$18,0.5))*$AN2+$AO2)*(1+$AV2)*(1+$AW2)+(($AY2+($AZ2-$AY2)*IF(VLOOKUP($R2,武学奇术!$A:$ZZ,31,FALSE)=1,$F$18,0.5))*IF($G$1="鸣金",$AP2,$AN2)+IF($G$1="鸣金",$AQ2*1.5,0))*(1+$BA2)*(1+$BB2)+(($BC2+($BD2-$BC2)*IF(VLOOKUP($R2,武学奇术!$A:$ZZ,31,FALSE)=1,$F$18,0.5))*IF($G$1="裂石",$AP2,$AN2)+IF($G$1="裂石",$AQ2*1.5,0))*(1+$BE2)*(1+$BF2)+(($BG2+($BH2-$BG2)*IF(VLOOKUP($R2,武学奇术!$A:$ZZ,31,FALSE)=1,$F$18,0.5))*IF($G$1="牵丝",$AP2,$AN2)+IF($G$1="牵丝",$AQ2*1.5,0))*(1+$BI2)*(1+$BJ2)+(($BK2+($BL2-$BK2)*IF(VLOOKUP($R2,武学奇术!$A:$ZZ,31,FALSE)=1,$F$18,0.5))*IF($G$1="破竹",$AP2,$AN2)+IF($G$1="破竹",$AQ2*1.5,0))*(1+$BM2)*(1+$BN2))*(1+$AR2)*$Q2*(1+IF(VLOOKUP($R2,武学奇术!$A:$ZZ,30,FALSE)="蓄力技",$B$21,0))*(1+$BW2) -> 15964.353 | P2: =((($AT2*$AN2+$AO2)*(1+$AV2)*(1+$AW2)+($AY2*IF($G$1="鸣金",$AP2,$AN2)+IF($G$1="鸣金",$AQ2*1.5,0))*(1+$BA2)*(1+$BB2)+($BC2*IF($G$1="裂石",$AP2,$AN2)+IF($G$1="裂石",$AQ2*1.5,0))*(1+$BE2)*(1+$BF2)+($BG2*IF($G$1="牵丝",$AP2,$AN2)+IF($G$1="牵丝",$AQ2*1.5,0))*(1+$BI2)*(1+$BJ2)+($BK2*IF($G$1="破竹",$AP2,$AN2)+IF($G$1="破竹",$AQ2*1.5,0))*(1+$BM2)*(1+$BN2))*(1+$AR2))*$Q2*(1+IF(VLOOKUP($R2,武学奇术!$A:$ZZ,30,FALSE)="蓄力技",$B$21,0))*(1+$BW2) -> 13872.956 | Q2: 1 | R2: 萧呤千浪流星 | S2: 易水歌1层 | T2: N/a | U2: N/a | V2: 近战笛 | W2: N/a | X2: N/a | Y2: 沧海帖1层 | Z2: N/a | AA2: N/a | AB2: N/a | AC2: N/a | AD2: 离猎(拐) | AE2: 裁云(拐) | AF2: 无惧 | AG2: 天志增伤 | AH2: N/a | AI2: N/a | AJ2: N/a | AK2: N/a | AL2: N/a | AM2: =VLOOKUP($R2,武学奇术!$A:$ZZ,25,FALSE) -> 群体奇术 | AN2: =VLOOKUP($R2,武学奇术!$A:$ZZ,26,FALSE) -> 1.4904 | AO2: =VLOOKUP($R2,武学奇术!$A:$ZZ,27,FALSE)*(1+IF(OR($AM2=$F$4,$AM2=$F$5),$B$22,0)) -> 378 | AP2: =VLOOKUP($R2,武学奇术!$A:$ZZ,28,FALSE) -> 2.2356 | AQ2: =VLOOKUP($R2,武学奇术!$A:$ZZ,29,FALSE)*(1+IF(OR($AM2=$F$4,$AM2=$F$5),$B$22,0)) -> 0 | AR2: {=$G$3+IFERROR(VLOOKUP($AM2,$F$4:$G$7,2,FALSE),0)+VLOOKUP($R2,武学奇术!$A:$ZZ,2,FALSE)+SUM(_xlfn.XLOOKUP($S2:$AL2,增益!$A:$A,增益!$B:$B,0))} -> 0.2137 | AS2: {=VLOOKUP($R2,武学奇术!$A:$ZZ,5,FALSE)+SUM(_xlfn.XLOOKUP($S2:$AL2,增益!$A:$A,增益!$E:$E,0))} -> 0 | AT2: {=$D$10*(1+$AS2)+VLOOKUP($R2,武学奇术!$A:$ZZ,3,FALSE)+SUM(_xlfn.XLOOKUP($S2:$AL2,增益!$A:$A,增益!$C:$C,0))-$I$2} -> 3901.102 | AU2: {=$E$10*(1+$AS2)+VLOOKUP($R2,武学奇术!$A:$ZZ,4,FALSE)+SUM(_xlfn.XLOOKUP($S2:$AL2,增益!$A:$A,增益!$D:$D,0))-$I$2} -> 3901.102 | AV2: {=IF($F$10-$I$3+VLOOKUP($R2,武学奇术!$A:$ZZ,6,FALSE)+SUM(_xlfn.XLOOKUP($S2:$AL2,增益!$A:$A,增益!$F:$F,0))>0,($F$10-$I$3+VLOOKUP($R2,武学奇术!$A:$ZZ,6,FALSE)+SUM(_xlfn.XLOOKUP($S2:$AL2,增益!$A:$A,增益!$F:$F,0)))/200,($F$10-$I$3+VLOOKUP($R2,武学奇术!$A:$ZZ,6,FALSE)+SUM(_xlfn.XLOOKUP($S2:$AL2,增益!$A:$A,增益!$F:$F,0)))/100)} -> 0.277 | AW2: {=$G$10+VLOOKUP($R2,武学奇术!$A:$ZZ,7,FALSE)+SUM(_xlfn.XLOOKUP($S2:$AL2,增益!$A:$A,增益!$G:$G,0))} -> 0.09 | AX2: {=VLOOKUP($R2,武学奇术!$A:$ZZ,8,FALSE)+SUM(_xlfn.XLOOKUP($S2:$AL2,增益!$A:$A,增益!$H:$H,0))} -> 0 | AY2: =$D$11*(1+$AX2) -> 0 | AZ2: =$E$11*(1+$AX2) -> 0 | BA2: {=IF($F$11-$I$4+VLOOKUP($R2,武学奇术!$A:$ZZ,9,FALSE)+SUM(_xlfn.XLOOKUP($S2:$AL2,增益!$A:$A,增益!$I:$I,0))>0,($F$11-$I$4+VLOOKUP($R2,武学奇术!$A:$ZZ,9,FALSE)+SUM(_xlfn.XLOOKUP($S2:$AL2,增益!$A:$A,增益!$I:$I,0)))/200,($F$11-$I$4+VLOOKUP($R2,武学奇术!$A:$ZZ,9,FALSE)+SUM(_xlfn.XLOOKUP($S2:$AL2,增益!$A:$A,增益!$I:$I,0)))/100)} -> -0.3 | BB2: {=$G$11+VLOOKUP($R2,武学奇术!$A:$ZZ,10,FALSE)+SUM(_xlfn.XLOOKUP($S2:$AL2,增益!$A:$A,增益!$J:$J,0))} -> 0 | BC2: =$D$12*(1+$AX2) -> 0 | BD2: =$E$12*(1+$AX2) -> 0 | BE2: {=IF($F$12-$I$4+VLOOKUP($R2,武学奇术!$A:$ZZ,11,FALSE)+SUM(_xlfn.XLOOKUP($S2:$AL2,增益!$A:$A,增益!$K:$K,0))>0,($F$12-$I$4+VLOOKUP($R2,武学奇术!$A:$ZZ,11,FALSE)+SUM(_xlfn.XLOOKUP($S2:$AL2,增益!$A:$A,增益!$K:$K,0)))/200,($F$12-$I$4+VLOOKUP($R2,武学奇术!$A:$ZZ,11,FALSE)+SUM(_xlfn.XLOOKUP($S2:$AL2,增益!$A:$A,增益!$K:$K,0)))/100)} -> -0.3 | BF2: {=$G$12+VLOOKUP($R2,武学奇术!$A:$ZZ,12,FALSE)+SUM(_xlfn.XLOOKUP($S2:$AL2,增益!$A:$A,增益!$L:$L,0))} -> 0 | BG2: =$D$13*(1+$AX2) -> 0 | BH2: =$E$13*(1+$AX2) -> 0 | BI2: {=IF($F$13-$I$4+VLOOKUP($R2,武学奇术!$A:$ZZ,13,FALSE)+SUM(_xlfn.XLOOKUP($S2:$AL2,增益!$A:$A,增益!$M:$M,0))>0,($F$13-$I$4+VLOOKUP($R2,武学奇术!$A:$ZZ,13,FALSE)+SUM(_xlfn.XLOOKUP($S2:$AL2,增益!$A:$A,增益!$K:$K,0)))/200,($F$13-$I$4+VLOOKUP($R2,武学奇术!$A:$ZZ,13,FALSE)+SUM(_xlfn.XLOOKUP($S2:$AL2,增益!$A:$A,增益!$M:$M,0)))/100)} -> -0.3 | BJ2: {=$G$13+VLOOKUP($R2,武学奇术!$A:$ZZ,14,FALSE)+SUM(_xlfn.XLOOKUP($S2:$AL2,增益!$A:$A,增益!$N:$N,0))} -> 0 | BK2: =$D$14*(1+$AX2) -> 605.472 | BL2: =$E$14*(1+$AX2) -> 1725.468 | BM2: {=IF($F$14-$I$4+VLOOKUP($R2,武学奇术!$A:$ZZ,15,FALSE)+SUM(_xlfn.XLOOKUP($S2:$AL2,增益!$A:$A,增益!$O:$O,0))>0,($F$14-$I$4+VLOOKUP($R2,武学奇术!$A:$ZZ,15,FALSE)+SUM(_xlfn.XLOOKUP($S2:$AL2,增益!$A:$A,增益!$O:$O,0)))/200,($F$14-$I$4+VLOOKUP($R2,武学奇术!$A:$ZZ,15,FALSE)+SUM(_xlfn.XLOOKUP($S2:$AL2,增益!$A:$A,增益!$O:$O,0)))/100)} -> 0 | BN2: {=$G$14+VLOOKUP($R2,武学奇术!$A:$ZZ,16,FALSE)+SUM(_xlfn.XLOOKUP($S2:$AL2,增益!$A:$A,增益!$P:$P,0))} -> 0.24 | BO2: =MIN(IF(VLOOKUP($R2,武学奇术!$A:$ZZ,23,FALSE)=1,100%,$B$8),100%) -> 1 | BP2: {=IF(VLOOKUP($R2,武学奇术!$A:$ZZ,23,FALSE)=1,100%,MIN(80%,$B$9+VLOOKUP($R2,武学奇术!$A:$ZZ,17,FALSE)+SUM(_xlfn.XLOOKUP($S2:$AL2,增益!$A:$A,增益!$Q:$Q,0)))+$B$11+SUM(_xlfn.XLOOKUP($S2:$AL2,增益!$A:$A,增益!$U:$U,0)))*IF(VLOOKUP($R2,武学奇术!$A:$ZZ,24,FALSE)=1,0,1)+MIN(IF(VLOOKUP($R2,武学奇术!$A:$ZZ,32,FALSE)=1,IF(VLOOKUP($R2,武学奇术!$A:$ZZ,24,FALSE)=1,100%,MIN(40%,$B$10+VLOOKUP($R2,武学奇术!$A:$ZZ,19,FALSE)+SUM(_xlfn.XLOOKUP($S2:$AL2,增益!$A:$A,增益!$S:$S,0)))+$B$12+SUM(_xlfn.XLOOKUP($S2:$AL2,增益!$A:$A,增益!$V:$V,0))),0),12%)} -> 0.9036 | BQ2: {=1+$B$13+VLOOKUP($R2,武学奇术!$A:$ZZ,18,FALSE)+SUM(_xlfn.XLOOKUP($S2:$AL2,增益!$A:$A,增益!$R:$R,0))} -> 1.55 | BR2: {=MAX(IF(VLOOKUP($R2,武学奇术!$A:$ZZ,24,FALSE)=1,100%,MIN(40%,$B$10+VLOOKUP($R2,武学奇术!$A:$ZZ,19,FALSE)+SUM(_xlfn.XLOOKUP($S2:$AL2,增益!$A:$A,增益!$S:$S,0)))+$B$12+SUM(_xlfn.XLOOKUP($S2:$AL2,增益!$A:$A,增益!$V:$V,0)))*IF(VLOOKUP($R2,武学奇术!$A:$ZZ,23,FALSE)=1,0,1)-IF(VLOOKUP($R2,武学奇术!$A:$ZZ,32,FALSE)=1,12%,0),0)} -> 0.0929 | BS2: {=1+$B$14+VLOOKUP($R2,武学奇术!$A:$ZZ,20,FALSE)+SUM(_xlfn.XLOOKUP($S2:$AL2,增益!$A:$A,增益!$T:$T,0))} -> 1.35 | BT2: =MIN((1-BR2)*BO2,BO2*BP2) -> 0.9036 | BU2: =1-BR2-BT2-BV2 -> 0.0035 | BV2: =IF(VLOOKUP($R2,武学奇术!$A:$ZZ,22,FALSE)=1,0,(1-$BO2))*(1-$BR2) -> 0 | BW2: {=SUM(_xlfn.XLOOKUP($S2:$AL2,增益!$A:$A,增益!$W:$W,0))+$I$5} -> 0.11 | BX2: {=SUM(_xlfn.XLOOKUP($S2:$AL2,增益!$A:$A,增益!$X:$X,0))} -> 0
A3: 鸣金 | F3: 通用增伤 | G3: =B16+1.5%+IF($D$16="√",8%,0)+IF($E$24="征人归",8%,0) -> 0.1837 | H3: 外抗 | I3: =25-IF(D17="√",10,0)-IF(F17="√",10,0) -> 5 | K3: =$L3*VLOOKUP($R3,武学奇术!$A:$ZZ,31,FALSE) -> 25730.829 | L3: =($M3*$BT3+$N3*$BR3+$O3*$BU3+$P3*$BV3) -> 25730.829 | M3: =((($AT3+($AU3-$AT3)*IF(VLOOKUP($R3,武学奇术!$A:$ZZ,31,FALSE)=1,$F$18,0.5))*$AN3+$AO3)*(1+$AV3)*(1+$AW3)+(($AY3+($AZ3-$AY3)*IF(VLOOKUP($R3,武学奇术!$A:$ZZ,31,FALSE)=1,$F$18,0.5))*IF($G$1="鸣金",$AP3,$AN3)+IF($G$1="鸣金",$AQ3*1.5,0))*(1+$BA3)*(1+$BB3)+(($BC3+($BD3-$BC3)*IF(VLOOKUP($R3,武学奇术!$A:$ZZ,31,FALSE)=1,$F$18,0.5))*IF($G$1="裂石",$AP3,$AN3)+IF($G$1="裂石",$AQ3*1.5,0))*(1+$BE3)*(1+$BF3)+(($BG3+($BH3-$BG3)*IF(VLOOKUP($R3,武学奇术!$A:$ZZ,31,FALSE)=1,$F$18,0.5))*IF($G$1="牵丝",$AP3,$AN3)+IF($G$1="牵丝",$AQ3*1.5,0))*(1+$BI3)*(1+$BJ3)+(($BK3+($BL3-$BK3)*IF(VLOOKUP($R3,武学奇术!$A:$ZZ,31,FALSE)=1,$F$18,0.5))*IF($G$1="破竹",$AP3,$AN3)+IF($G$1="破竹",$AQ3*1.5,0))*(1+$BM3)*(1+$BN3))*(1+$AR3)*$BQ3*$Q3*(1+IF(VLOOKUP($R3,武学奇术!$A:$ZZ,30,FALSE)="蓄力技",$B$21,0))*(1+$BW3) -> 25800.287 | N3: =(($AU3*$AN3+$AO3)*(1+$AV3)*(1+$AW3)+($AZ3*IF($G$1="鸣金",$AP3,$AN3)+IF($G$1="鸣金",$AQ3*1.5,0))*(1+$BA3)*(1+$BB3)+($BD3*IF($G$1="裂石",$AP3,$AN3)+IF($G$1="裂石",$AQ3*1.5,0))*(1+$BE3)*(1+$BF3)+($BH3*IF($G$1="牵丝",$AP3,$AN3)+IF($G$1="牵丝",$AQ3*1.5,0))*(1+$BI3)*(1+$BJ3)+($BL3*IF($G$1="破竹",$AP3,$AN3)+IF($G$1="破竹",$AQ3*1.5,0))*(1+$BM3)*(1+$BN3))*(1+$AR3)*$BS3*$Q3*(1+IF(VLOOKUP($R3,武学奇术!$A:$ZZ,30,FALSE)="蓄力技",$B$21,0))*(1+$BW3) -> 25401.553 | O3: =((($AT3+($AU3-$AT3)*IF(VLOOKUP($R3,武学奇术!$A:$ZZ,31,FALSE)=1,$F$18,0.5))*$AN3+$AO3)*(1+$AV3)*(1+$AW3)+(($AY3+($AZ3-$AY3)*IF(VLOOKUP($R3,武学奇术!$A:$ZZ,31,FALSE)=1,$F$18,0.5))*IF($G$1="鸣金",$AP3,$AN3)+IF($G$1="鸣金",$AQ3*1.5,0))*(1+$BA3)*(1+$BB3)+(($BC3+($BD3-$BC3)*IF(VLOOKUP($R3,武学奇术!$A:$ZZ,31,FALSE)=1,$F$18,0.5))*IF($G$1="裂石",$AP3,$AN3)+IF($G$1="裂石",$AQ3*1.5,0))*(1+$BE3)*(1+$BF3)+(($BG3+($BH3-$BG3)*IF(VLOOKUP($R3,武学奇术!$A:$ZZ,31,FALSE)=1,$F$18,0.5))*IF($G$1="牵丝",$AP3,$AN3)+IF($G$1="牵丝",$AQ3*1.5,0))*(1+$BI3)*(1+$BJ3)+(($BK3+($BL3-$BK3)*IF(VLOOKUP($R3,武学奇术!$A:$ZZ,31,FALSE)=1,$F$18,0.5))*IF($G$1="破竹",$AP3,$AN3)+IF($G$1="破竹",$AQ3*1.5,0))*(1+$BM3)*(1+$BN3))*(1+$AR3)*$Q3*(1+IF(VLOOKUP($R3,武学奇术!$A:$ZZ,30,FALSE)="蓄力技",$B$21,0))*(1+$BW3) -> 16538.646 | P3: =((($AT3*$AN3+$AO3)*(1+$AV3)*(1+$AW3)+($AY3*IF($G$1="鸣金",$AP3,$AN3)+IF($G$1="鸣金",$AQ3*1.5,0))*(1+$BA3)*(1+$BB3)+($BC3*IF($G$1="裂石",$AP3,$AN3)+IF($G$1="裂石",$AQ3*1.5,0))*(1+$BE3)*(1+$BF3)+($BG3*IF($G$1="牵丝",$AP3,$AN3)+IF($G$1="牵丝",$AQ3*1.5,0))*(1+$BI3)*(1+$BJ3)+($BK3*IF($G$1="破竹",$AP3,$AN3)+IF($G$1="破竹",$AQ3*1.5,0))*(1+$BM3)*(1+$BN3))*(1+$AR3))*$Q3*(1+IF(VLOOKUP($R3,武学奇术!$A:$ZZ,30,FALSE)="蓄力技",$B$21,0))*(1+$BW3) -> 14261.326 | Q3: 1 | R3: 萧呤千浪流星 | S3: 易水歌2层 | T3: N/a | U3: N/a | V3: 近战笛 | W3: N/a | X3: N/a | Y3: 沧海帖2层 | Z3: 惧刃(拐) | AA3: N/a | AB3: 扶风(拐) | AC3: N/a | AD3: 离猎(拐) | AE3: 裁云(拐) | AF3: 无惧 | AG3: 天志增伤 | AH3: N/a | AI3: N/a | AJ3: N/a | AK3: N/a | AL3: N/a | AM3: =VLOOKUP($R3,武学奇术!$A:$ZZ,25,FALSE) -> 群体奇术 | AN3: =VLOOKUP($R3,武学奇术!$A:$ZZ,26,FALSE) -> 1.4904 | AO3: =VLOOKUP($R3,武学奇术!$A:$ZZ,27,FALSE)*(1+IF(OR($AM3=$F$4,$AM3=$F$5),$B$22,0)) -> 378 | AP3: =VLOOKUP($R3,武学奇术!$A:$ZZ,28,FALSE) -> 2.2356 | AQ3: =VLOOKUP($R3,武学奇术!$A:$ZZ,29,FALSE)*(1+IF(OR($AM3=$F$4,$AM3=$F$5),$B$22,0)) -> 0 | AR3: {=$G$3+IFERROR(VLOOKUP($AM3,$F$4:$G$7,2,FALSE),0)+VLOOKUP($R3,武学奇术!$A:$ZZ,2,FALSE)+SUM(_xlfn.XLOOKUP($S3:$AL3,增益!$A:$A,增益!$B:$B,0))} -> 0.2237 | AS3: {=VLOOKUP($R3,武学奇术!$A:$ZZ,5,FALSE)+SUM(_xlfn.XLOOKUP($S3:$AL3,增益!$A:$A,增益!$E:$E,0))} -> 0 | AT3: {=$D$10*(1+$AS3)+VLOOKUP($R3,武学奇术!$A:$ZZ,3,FALSE)+SUM(_xlfn.XLOOKUP($S3:$AL3,增益!$A:$A,增益!$C:$C,0))-$I$2} -> 3901.102 | AU3: {=$E$10*(1+$AS3)+VLOOKUP($R3,武学奇术!$A:$ZZ,4,FALSE)+SUM(_xlfn.XLOOKUP($S3:$AL3,增益!$A:$A,增益!$D:$D,0))-$I$2} -> 3901.102 | AV3: {=IF($F$10-$I$3+VLOOKUP($R3,武学奇术!$A:$ZZ,6,FALSE)+SUM(_xlfn.XLOOKUP($S3:$AL3,增益!$A:$A,增益!$F:$F,0))>0,($F$10-$I$3+VLOOKUP($R3,武学奇术!$A:$ZZ,6,FALSE)+SUM(_xlfn.XLOOKUP($S3:$AL3,增益!$A:$A,增益!$F:$F,0)))/200,($F$10-$I$3+VLOOKUP($R3,武学奇术!$A:$ZZ,6,FALSE)+SUM(_xlfn.XLOOKUP($S3:$AL3,增益!$A:$A,增益!$F:$F,0)))/100)} -> 0.287 | AW3: {=$G$10+VLOOKUP($R3,武学奇术!$A:$ZZ,7,FALSE)+SUM(_xlfn.XLOOKUP($S3:$AL3,增益!$A:$A,增益!$G:$G,0))} -> 0.09 | AX3: {=VLOOKUP($R3,武学奇术!$A:$ZZ,8,FALSE)+SUM(_xlfn.XLOOKUP($S3:$AL3,增益!$A:$A,增益!$H:$H,0))} -> 0 | AY3: =$D$11*(1+$AX3) -> 0 | AZ3: =$E$11*(1+$AX3) -> 0 | BA3: {=IF($F$11-$I$4+VLOOKUP($R3,武学奇术!$A:$ZZ,9,FALSE)+SUM(_xlfn.XLOOKUP($S3:$AL3,增益!$A:$A,增益!$I:$I,0))>0,($F$11-$I$4+VLOOKUP($R3,武学奇术!$A:$ZZ,9,FALSE)+SUM(_xlfn.XLOOKUP($S3:$AL3,增益!$A:$A,增益!$I:$I,0)))/200,($F$11-$I$4+VLOOKUP($R3,武学奇术!$A:$ZZ,9,FALSE)+SUM(_xlfn.XLOOKUP($S3:$AL3,增益!$A:$A,增益!$I:$I,0)))/100)} -> -0.14 | BB3: {=$G$11+VLOOKUP($R3,武学奇术!$A:$ZZ,10,FALSE)+SUM(_xlfn.XLOOKUP($S3:$AL3,增益!$A:$A,增益!$J:$J,0))} -> 0 | BC3: =$D$12*(1+$AX3) -> 0 | BD3: =$E$12*(1+$AX3) -> 0 | BE3: {=IF($F$12-$I$4+VLOOKUP($R3,武学奇术!$A:$ZZ,11,FALSE)+SUM(_xlfn.XLOOKUP($S3:$AL3,增益!$A:$A,增益!$K:$K,0))>0,($F$12-$I$4+VLOOKUP($R3,武学奇术!$A:$ZZ,11,FALSE)+SUM(_xlfn.XLOOKUP($S3:$AL3,增益!$A:$A,增益!$K:$K,0)))/200,($F$12-$I$4+VLOOKUP($R3,武学奇术!$A:$ZZ,11,FALSE)+SUM(_xlfn.XLOOKUP($S3:$AL3,增益!$A:$A,增益!$K:$K,0)))/100)} -> -0.14 | BF3: {=$G$12+VLOOKUP($R3,武学奇术!$A:$ZZ,12,FALSE)+SUM(_xlfn.XLOOKUP($S3:$AL3,增益!$A:$A,增益!$L:$L,0))} -> 0 | BG3: =$D$13*(1+$AX3) -> 0 | BH3: =$E$13*(1+$AX3) -> 0 | BI3: {=IF($F$13-$I$4+VLOOKUP($R3,武学奇术!$A:$ZZ,13,FALSE)+SUM(_xlfn.XLOOKUP($S3:$AL3,增益!$A:$A,增益!$M:$M,0))>0,($F$13-$I$4+VLOOKUP($R3,武学奇术!$A:$ZZ,13,FALSE)+SUM(_xlfn.XLOOKUP($S3:$AL3,增益!$A:$A,增益!$K:$K,0)))/200,($F$13-$I$4+VLOOKUP($R3,武学奇术!$A:$ZZ,13,FALSE)+SUM(_xlfn.XLOOKUP($S3:$AL3,增益!$A:$A,增益!$M:$M,0)))/100)} -> -0.14 | BJ3: {=$G$13+VLOOKUP($R3,武学奇术!$A:$ZZ,14,FALSE)+SUM(_xlfn.XLOOKUP($S3:$AL3,增益!$A:$A,增益!$N:$N,0))} -> 0 | BK3: =$D$14*(1+$AX3) -> 605.472 | BL3: =$E$14*(1+$AX3) -> 1725.468 | BM3: {=IF($F$14-$I$4+VLOOKUP($R3,武学奇术!$A:$ZZ,15,FALSE)+SUM(_xlfn.XLOOKUP($S3:$AL3,增益!$A:$A,增益!$O:$O,0))>0,($F$14-$I$4+VLOOKUP($R3,武学奇术!$A:$ZZ,15,FALSE)+SUM(_xlfn.XLOOKUP($S3:$AL3,增益!$A:$A,增益!$O:$O,0)))/200,($F$14-$I$4+VLOOKUP($R3,武学奇术!$A:$ZZ,15,FALSE)+SUM(_xlfn.XLOOKUP($S3:$AL3,增益!$A:$A,增益!$O:$O,0)))/100)} -> 0.08 | BN3: {=$G$14+VLOOKUP($R3,武学奇术!$A:$ZZ,16,FALSE)+SUM(_xlfn.XLOOKUP($S3:$AL3,增益!$A:$A,增益!$P:$P,0))} -> 0.24 | BO3: =MIN(IF(VLOOKUP($R3,武学奇术!$A:$ZZ,23,FALSE)=1,100%,$B$8),100%) -> 1 | BP3: {=IF(VLOOKUP($R3,武学奇术!$A:$ZZ,23,FALSE)=1,100%,MIN(80%,$B$9+VLOOKUP($R3,武学奇术!$A:$ZZ,17,FALSE)+SUM(_xlfn.XLOOKUP($S3:$AL3,增益!$A:$A,增益!$Q:$Q,0)))+$B$11+SUM(_xlfn.XLOOKUP($S3:$AL3,增益!$A:$A,增益!$U:$U,0)))*IF(VLOOKUP($R3,武学奇术!$A:$ZZ,24,FALSE)=1,0,1)+MIN(IF(VLOOKUP($R3,武学奇术!$A:$ZZ,32,FALSE)=1,IF(VLOOKUP($R3,武学奇术!$A:$ZZ,24,FALSE)=1,100%,MIN(40%,$B$10+VLOOKUP($R3,武学奇术!$A:$ZZ,19,FALSE)+SUM(_xlfn.XLOOKUP($S3:$AL3,增益!$A:$A,增益!$S:$S,0)))+$B$12+SUM(_xlfn.XLOOKUP($S3:$AL3,增益!$A:$A,增益!$V:$V,0))),0),12%)} -> 0.9036 | BQ3: {=1+$B$13+VLOOKUP($R3,武学奇术!$A:$ZZ,18,FALSE)+SUM(_xlfn.XLOOKUP($S3:$AL3,增益!$A:$A,增益!$R:$R,0))} -> 1.56 | BR3: {=MAX(IF(VLOOKUP($R3,武学奇术!$A:$ZZ,24,FALSE)=1,100%,MIN(40%,$B$10+VLOOKUP($R3,武学奇术!$A:$ZZ,19,FALSE)+SUM(_xlfn.XLOOKUP($S3:$AL3,增益!$A:$A,增益!$S:$S,0)))+$B$12+SUM(_xlfn.XLOOKUP($S3:$AL3,增益!$A:$A,增益!$V:$V,0)))*IF(VLOOKUP($R3,武学奇术!$A:$ZZ,23,FALSE)=1,0,1)-IF(VLOOKUP($R3,武学奇术!$A:$ZZ,32,FALSE)=1,12%,0),0)} -> 0.0929 | BS3: {=1+$B$14+VLOOKUP($R3,武学奇术!$A:$ZZ,20,FALSE)+SUM(_xlfn.XLOOKUP($S3:$AL3,增益!$A:$A,增益!$T:$T,0))} -> 1.35 | BT3: =MIN((1-BR3)*BO3,BO3*BP3) -> 0.9036 | BU3: =1-BR3-BT3-BV3 -> 0.0035 | BV3: =IF(VLOOKUP($R3,武学奇术!$A:$ZZ,22,FALSE)=1,0,(1-$BO3))*(1-$BR3) -> 0 | BW3: {=SUM(_xlfn.XLOOKUP($S3:$AL3,增益!$A:$A,增益!$W:$W,0))+$I$5} -> 0.11 | BX3: {=SUM(_xlfn.XLOOKUP($S3:$AL3,增益!$A:$A,增益!$X:$X,0))} -> 0
A4: 裂石 | F4: 拳甲 | G4: =B15+B17 -> 0.1704 | H4: 属抗 | I4: =30 -> 30 | K4: =$L4*VLOOKUP($R4,武学奇术!$A:$ZZ,31,FALSE) -> 26234.803 | L4: =($M4*$BT4+$N4*$BR4+$O4*$BU4+$P4*$BV4) -> 26234.803 | M4: =((($AT4+($AU4-$AT4)*IF(VLOOKUP($R4,武学奇术!$A:$ZZ,31,FALSE)=1,$F$18,0.5))*$AN4+$AO4)*(1+$AV4)*(1+$AW4)+(($AY4+($AZ4-$AY4)*IF(VLOOKUP($R4,武学奇术!$A:$ZZ,31,FALSE)=1,$F$18,0.5))*IF($G$1="鸣金",$AP4,$AN4)+IF($G$1="鸣金",$AQ4*1.5,0))*(1+$BA4)*(1+$BB4)+(($BC4+($BD4-$BC4)*IF(VLOOKUP($R4,武学奇术!$A:$ZZ,31,FALSE)=1,$F$18,0.5))*IF($G$1="裂石",$AP4,$AN4)+IF($G$1="裂石",$AQ4*1.5,0))*(1+$BE4)*(1+$BF4)+(($BG4+($BH4-$BG4)*IF(VLOOKUP($R4,武学奇术!$A:$ZZ,31,FALSE)=1,$F$18,0.5))*IF($G$1="牵丝",$AP4,$AN4)+IF($G$1="牵丝",$AQ4*1.5,0))*(1+$BI4)*(1+$BJ4)+(($BK4+($BL4-$BK4)*IF(VLOOKUP($R4,武学奇术!$A:$ZZ,31,FALSE)=1,$F$18,0.5))*IF($G$1="破竹",$AP4,$AN4)+IF($G$1="破竹",$AQ4*1.5,0))*(1+$BM4)*(1+$BN4))*(1+$AR4)*$BQ4*$Q4*(1+IF(VLOOKUP($R4,武学奇术!$A:$ZZ,30,FALSE)="蓄力技",$B$21,0))*(1+$BW4) -> 26322.976 | N4: =(($AU4*$AN4+$AO4)*(1+$AV4)*(1+$AW4)+($AZ4*IF($G$1="鸣金",$AP4,$AN4)+IF($G$1="鸣金",$AQ4*1.5,0))*(1+$BA4)*(1+$BB4)+($BD4*IF($G$1="裂石",$AP4,$AN4)+IF($G$1="裂石",$AQ4*1.5,0))*(1+$BE4)*(1+$BF4)+($BH4*IF($G$1="牵丝",$AP4,$AN4)+IF($G$1="牵丝",$AQ4*1.5,0))*(1+$BI4)*(1+$BJ4)+($BL4*IF($G$1="破竹",$AP4,$AN4)+IF($G$1="破竹",$AQ4*1.5,0))*(1+$BM4)*(1+$BN4))*(1+$AR4)*$BS4*$Q4*(1+IF(VLOOKUP($R4,武学奇术!$A:$ZZ,30,FALSE)="蓄力技",$B$21,0))*(1+$BW4) -> 25733.911 | O4: =((($AT4+($AU4-$AT4)*IF(VLOOKUP($R4,武学奇术!$A:$ZZ,31,FALSE)=1,$F$18,0.5))*$AN4+$AO4)*(1+$AV4)*(1+$AW4)+(($AY4+($AZ4-$AY4)*IF(VLOOKUP($R4,武学奇术!$A:$ZZ,31,FALSE)=1,$F$18,0.5))*IF($G$1="鸣金",$AP4,$AN4)+IF($G$1="鸣金",$AQ4*1.5,0))*(1+$BA4)*(1+$BB4)+(($BC4+($BD4-$BC4)*IF(VLOOKUP($R4,武学奇术!$A:$ZZ,31,FALSE)=1,$F$18,0.5))*IF($G$1="裂石",$AP4,$AN4)+IF($G$1="裂石",$AQ4*1.5,0))*(1+$BE4)*(1+$BF4)+(($BG4+($BH4-$BG4)*IF(VLOOKUP($R4,武学奇术!$A:$ZZ,31,FALSE)=1,$F$18,0.5))*IF($G$1="牵丝",$AP4,$AN4)+IF($G$1="牵丝",$AQ4*1.5,0))*(1+$BI4)*(1+$BJ4)+(($BK4+($BL4-$BK4)*IF(VLOOKUP($R4,武学奇术!$A:$ZZ,31,FALSE)=1,$F$18,0.5))*IF($G$1="破竹",$AP4,$AN4)+IF($G$1="破竹",$AQ4*1.5,0))*(1+$BM4)*(1+$BN4))*(1+$AR4)*$Q4*(1+IF(VLOOKUP($R4,武学奇术!$A:$ZZ,30,FALSE)="蓄力技",$B$21,0))*(1+$BW4) -> 16766.226 | P4: =((($AT4*$AN4+$AO4)*(1+$AV4)*(1+$AW4)+($AY4*IF($G$1="鸣金",$AP4,$AN4)+IF($G$1="鸣金",$AQ4*1.5,0))*(1+$BA4)*(1+$BB4)+($BC4*IF($G$1="裂石",$AP4,$AN4)+IF($G$1="裂石",$AQ4*1.5,0))*(1+$BE4)*(1+$BF4)+($BG4*IF($G$1="牵丝",$AP4,$AN4)+IF($G$1="牵丝",$AQ4*1.5,0))*(1+$BI4)*(1+$BJ4)+($BK4*IF($G$1="破竹",$AP4,$AN4)+IF($G$1="破竹",$AQ4*1.5,0))*(1+$BM4)*(1+$BN4))*(1+$AR4))*$Q4*(1+IF(VLOOKUP($R4,武学奇术!$A:$ZZ,30,FALSE)="蓄力技",$B$21,0))*(1+$BW4) -> 14470.297 | Q4: 1 | R4: 萧呤千浪流星 | S4: 易水歌3层 | T4: N/a | U4: N/a | V4: 近战笛 | W4: N/a | X4: N/a | Y4: 沧海帖3层 | Z4: 惧刃(拐) | AA4: N/a | AB4: 烁鼓(拐) | AC4: N/a | AD4: 离猎(拐) | AE4: 裁云(拐) | AF4: 无惧 | AG4: 天志增伤 | AH4: N/a | AI4: N/a | AJ4: N/a | AK4: N/a | AL4: N/a | AM4: =VLOOKUP($R4,武学奇术!$A:$ZZ,25,FALSE) -> 群体奇术 | AN4: =VLOOKUP($R4,武学奇术!$A:$ZZ,26,FALSE) -> 1.4904 | AO4: =VLOOKUP($R4,武学奇术!$A:$ZZ,27,FALSE)*(1+IF(OR($AM4=$F$4,$AM4=$F$5),$B$22,0)) -> 378 | AP4: =VLOOKUP($R4,武学奇术!$A:$ZZ,28,FALSE) -> 2.2356 | AQ4: =VLOOKUP($R4,武学奇术!$A:$ZZ,29,FALSE)*(1+IF(OR($AM4=$F$4,$AM4=$F$5),$B$22,0)) -> 0 | AR4: {=$G$3+IFERROR(VLOOKUP($AM4,$F$4:$G$7,2,FALSE),0)+VLOOKUP($R4,武学奇术!$A:$ZZ,2,FALSE)+SUM(_xlfn.XLOOKUP($S4:$AL4,增益!$A:$A,增益!$B:$B,0))} -> 0.2337 | AS4: {=VLOOKUP($R4,武学奇术!$A:$ZZ,5,FALSE)+SUM(_xlfn.XLOOKUP($S4:$AL4,增益!$A:$A,增益!$E:$E,0))} -> 0 | AT4: {=$D$10*(1+$AS4)+VLOOKUP($R4,武学奇术!$A:$ZZ,3,FALSE)+SUM(_xlfn.XLOOKUP($S4:$AL4,增益!$A:$A,增益!$C:$C,0))-$I$2} -> 3901.102 | AU4: {=$E$10*(1+$AS4)+VLOOKUP($R4,武学奇术!$A:$ZZ,4,FALSE)+SUM(_xlfn.XLOOKUP($S4:$AL4,增益!$A:$A,增益!$D:$D,0))-$I$2} -> 3901.102 | AV4: {=IF($F$10-$I$3+VLOOKUP($R4,武学奇术!$A:$ZZ,6,FALSE)+SUM(_xlfn.XLOOKUP($S4:$AL4,增益!$A:$A,增益!$F:$F,0))>0,($F$10-$I$3+VLOOKUP($R4,武学奇术!$A:$ZZ,6,FALSE)+SUM(_xlfn.XLOOKUP($S4:$AL4,增益!$A:$A,增益!$F:$F,0)))/200,($F$10-$I$3+VLOOKUP($R4,武学奇术!$A:$ZZ,6,FALSE)+SUM(_xlfn.XLOOKUP($S4:$AL4,增益!$A:$A,增益!$F:$F,0)))/100)} -> 0.297 | AW4: {=$G$10+VLOOKUP($R4,武学奇术!$A:$ZZ,7,FALSE)+SUM(_xlfn.XLOOKUP($S4:$AL4,增益!$A:$A,增益!$G:$G,0))} -> 0.09 | AX4: {=VLOOKUP($R4,武学奇术!$A:$ZZ,8,FALSE)+SUM(_xlfn.XLOOKUP($S4:$AL4,增益!$A:$A,增益!$H:$H,0))} -> 0 | AY4: =$D$11*(1+$AX4) -> 0 | AZ4: =$E$11*(1+$AX4) -> 0 | BA4: {=IF($F$11-$I$4+VLOOKUP($R4,武学奇术!$A:$ZZ,9,FALSE)+SUM(_xlfn.XLOOKUP($S4:$AL4,增益!$A:$A,增益!$I:$I,0))>0,($F$11-$I$4+VLOOKUP($R4,武学奇术!$A:$ZZ,9,FALSE)+SUM(_xlfn.XLOOKUP($S4:$AL4,增益!$A:$A,增益!$I:$I,0)))/200,($F$11-$I$4+VLOOKUP($R4,武学奇术!$A:$ZZ,9,FALSE)+SUM(_xlfn.XLOOKUP($S4:$AL4,增益!$A:$A,增益!$I:$I,0)))/100)} -> -0.14 | BB4: {=$G$11+VLOOKUP($R4,武学奇术!$A:$ZZ,10,FALSE)+SUM(_xlfn.XLOOKUP($S4:$AL4,增益!$A:$A,增益!$J:$J,0))} -> 0 | BC4: =$D$12*(1+$AX4) -> 0 | BD4: =$E$12*(1+$AX4) -> 0 | BE4: {=IF($F$12-$I$4+VLOOKUP($R4,武学奇术!$A:$ZZ,11,FALSE)+SUM(_xlfn.XLOOKUP($S4:$AL4,增益!$A:$A,增益!$K:$K,0))>0,($F$12-$I$4+VLOOKUP($R4,武学奇术!$A:$ZZ,11,FALSE)+SUM(_xlfn.XLOOKUP($S4:$AL4,增益!$A:$A,增益!$K:$K,0)))/200,($F$12-$I$4+VLOOKUP($R4,武学奇术!$A:$ZZ,11,FALSE)+SUM(_xlfn.XLOOKUP($S4:$AL4,增益!$A:$A,增益!$K:$K,0)))/100)} -> -0.14 | BF4: {=$G$12+VLOOKUP($R4,武学奇术!$A:$ZZ,12,FALSE)+SUM(_xlfn.XLOOKUP($S4:$AL4,增益!$A:$A,增益!$L:$L,0))} -> 0 | BG4: =$D$13*(1+$AX4) -> 0 | BH4: =$E$13*(1+$AX4) -> 0 | BI4: {=IF($F$13-$I$4+VLOOKUP($R4,武学奇术!$A:$ZZ,13,FALSE)+SUM(_xlfn.XLOOKUP($S4:$AL4,增益!$A:$A,增益!$M:$M,0))>0,($F$13-$I$4+VLOOKUP($R4,武学奇术!$A:$ZZ,13,FALSE)+SUM(_xlfn.XLOOKUP($S4:$AL4,增益!$A:$A,增益!$K:$K,0)))/200,($F$13-$I$4+VLOOKUP($R4,武学奇术!$A:$ZZ,13,FALSE)+SUM(_xlfn.XLOOKUP($S4:$AL4,增益!$A:$A,增益!$M:$M,0)))/100)} -> -0.14 | BJ4: {=$G$13+VLOOKUP($R4,武学奇术!$A:$ZZ,14,FALSE)+SUM(_xlfn.XLOOKUP($S4:$AL4,增益!$A:$A,增益!$N:$N,0))} -> 0 | BK4: =$D$14*(1+$AX4) -> 605.472 | BL4: =$E$14*(1+$AX4) -> 1725.468 | BM4: {=IF($F$14-$I$4+VLOOKUP($R4,武学奇术!$A:$ZZ,15,FALSE)+SUM(_xlfn.XLOOKUP($S4:$AL4,增益!$A:$A,增益!$O:$O,0))>0,($F$14-$I$4+VLOOKUP($R4,武学奇术!$A:$ZZ,15,FALSE)+SUM(_xlfn.XLOOKUP($S4:$AL4,增益!$A:$A,增益!$O:$O,0)))/200,($F$14-$I$4+VLOOKUP($R4,武学奇术!$A:$ZZ,15,FALSE)+SUM(_xlfn.XLOOKUP($S4:$AL4,增益!$A:$A,增益!$O:$O,0)))/100)} -> 0.08 | BN4: {=$G$14+VLOOKUP($R4,武学奇术!$A:$ZZ,16,FALSE)+SUM(_xlfn.XLOOKUP($S4:$AL4,增益!$A:$A,增益!$P:$P,0))} -> 0.24 | BO4: =MIN(IF(VLOOKUP($R4,武学奇术!$A:$ZZ,23,FALSE)=1,100%,$B$8),100%) -> 1 | BP4: {=IF(VLOOKUP($R4,武学奇术!$A:$ZZ,23,FALSE)=1,100%,MIN(80%,$B$9+VLOOKUP($R4,武学奇术!$A:$ZZ,17,FALSE)+SUM(_xlfn.XLOOKUP($S4:$AL4,增益!$A:$A,增益!$Q:$Q,0)))+$B$11+SUM(_xlfn.XLOOKUP($S4:$AL4,增益!$A:$A,增益!$U:$U,0)))*IF(VLOOKUP($R4,武学奇术!$A:$ZZ,24,FALSE)=1,0,1)+MIN(IF(VLOOKUP($R4,武学奇术!$A:$ZZ,32,FALSE)=1,IF(VLOOKUP($R4,武学奇术!$A:$ZZ,24,FALSE)=1,100%,MIN(40%,$B$10+VLOOKUP($R4,武学奇术!$A:$ZZ,19,FALSE)+SUM(_xlfn.XLOOKUP($S4:$AL4,增益!$A:$A,增益!$S:$S,0)))+$B$12+SUM(_xlfn.XLOOKUP($S4:$AL4,增益!$A:$A,增益!$V:$V,0))),0),12%)} -> 0.9036 | BQ4: {=1+$B$13+VLOOKUP($R4,武学奇术!$A:$ZZ,18,FALSE)+SUM(_xlfn.XLOOKUP($S4:$AL4,增益!$A:$A,增益!$R:$R,0))} -> 1.57 | BR4: {=MAX(IF(VLOOKUP($R4,武学奇术!$A:$ZZ,24,FALSE)=1,100%,MIN(40%,$B$10+VLOOKUP($R4,武学奇术!$A:$ZZ,19,FALSE)+SUM(_xlfn.XLOOKUP($S4:$AL4,增益!$A:$A,增益!$S:$S,0)))+$B$12+SUM(_xlfn.XLOOKUP($S4:$AL4,增益!$A:$A,增益!$V:$V,0)))*IF(VLOOKUP($R4,武学奇术!$A:$ZZ,23,FALSE)=1,0,1)-IF(VLOOKUP($R4,武学奇术!$A:$ZZ,32,FALSE)=1,12%,0),0)} -> 0.0929 | BS4: {=1+$B$14+VLOOKUP($R4,武学奇术!$A:$ZZ,20,FALSE)+SUM(_xlfn.XLOOKUP($S4:$AL4,增益!$A:$A,增益!$T:$T,0))} -> 1.35 | BT4: =MIN((1-BR4)*BO4,BO4*BP4) -> 0.9036 | BU4: =1-BR4-BT4-BV4 -> 0.0035 | BV4: =IF(VLOOKUP($R4,武学奇术!$A:$ZZ,22,FALSE)=1,0,(1-$BO4))*(1-$BR4) -> 0 | BW4: {=SUM(_xlfn.XLOOKUP($S4:$AL4,增益!$A:$A,增益!$W:$W,0))+$I$5} -> 0.11 | BX4: {=SUM(_xlfn.XLOOKUP($S4:$AL4,增益!$A:$A,增益!$X:$X,0))} -> 0
A5: 牵丝 | F5: 绳镖 | G5: =B15+B18 -> 0.0852 | H5: 副本天赋 | I5: 0.06 | K5: =$L5*VLOOKUP($R5,武学奇术!$A:$ZZ,31,FALSE) -> 26745.222 | L5: =($M5*$BT5+$N5*$BR5+$O5*$BU5+$P5*$BV5) -> 26745.222 | M5: =((($AT5+($AU5-$AT5)*IF(VLOOKUP($R5,武学奇术!$A:$ZZ,31,FALSE)=1,$F$18,0.5))*$AN5+$AO5)*(1+$AV5)*(1+$AW5)+(($AY5+($AZ5-$AY5)*IF(VLOOKUP($R5,武学奇术!$A:$ZZ,31,FALSE)=1,$F$18,0.5))*IF($G$1="鸣金",$AP5,$AN5)+IF($G$1="鸣金",$AQ5*1.5,0))*(1+$BA5)*(1+$BB5)+(($BC5+($BD5-$BC5)*IF(VLOOKUP($R5,武学奇术!$A:$ZZ,31,FALSE)=1,$F$18,0.5))*IF($G$1="裂石",$AP5,$AN5)+IF($G$1="裂石",$AQ5*1.5,0))*(1+$BE5)*(1+$BF5)+(($BG5+($BH5-$BG5)*IF(VLOOKUP($R5,武学奇术!$A:$ZZ,31,FALSE)=1,$F$18,0.5))*IF($G$1="牵丝",$AP5,$AN5)+IF($G$1="牵丝",$AQ5*1.5,0))*(1+$BI5)*(1+$BJ5)+(($BK5+($BL5-$BK5)*IF(VLOOKUP($R5,武学奇术!$A:$ZZ,31,FALSE)=1,$F$18,0.5))*IF($G$1="破竹",$AP5,$AN5)+IF($G$1="破竹",$AQ5*1.5,0))*(1+$BM5)*(1+$BN5))*(1+$AR5)*$BQ5*$Q5*(1+IF(VLOOKUP($R5,武学奇术!$A:$ZZ,30,FALSE)="蓄力技",$B$21,0))*(1+$BW5) -> 26852.583 | N5: =(($AU5*$AN5+$AO5)*(1+$AV5)*(1+$AW5)+($AZ5*IF($G$1="鸣金",$AP5,$AN5)+IF($G$1="鸣金",$AQ5*1.5,0))*(1+$BA5)*(1+$BB5)+($BD5*IF($G$1="裂石",$AP5,$AN5)+IF($G$1="裂石",$AQ5*1.5,0))*(1+$BE5)*(1+$BF5)+($BH5*IF($G$1="牵丝",$AP5,$AN5)+IF($G$1="牵丝",$AQ5*1.5,0))*(1+$BI5)*(1+$BJ5)+($BL5*IF($G$1="破竹",$AP5,$AN5)+IF($G$1="破竹",$AQ5*1.5,0))*(1+$BM5)*(1+$BN5))*(1+$AR5)*$BS5*$Q5*(1+IF(VLOOKUP($R5,武学奇术!$A:$ZZ,30,FALSE)="蓄力技",$B$21,0))*(1+$BW5) -> 26068.291 | O5: =((($AT5+($AU5-$AT5)*IF(VLOOKUP($R5,武学奇术!$A:$ZZ,31,FALSE)=1,$F$18,0.5))*$AN5+$AO5)*(1+$AV5)*(1+$AW5)+(($AY5+($AZ5-$AY5)*IF(VLOOKUP($R5,武学奇术!$A:$ZZ,31,FALSE)=1,$F$18,0.5))*IF($G$1="鸣金",$AP5,$AN5)+IF($G$1="鸣金",$AQ5*1.5,0))*(1+$BA5)*(1+$BB5)+(($BC5+($BD5-$BC5)*IF(VLOOKUP($R5,武学奇术!$A:$ZZ,31,FALSE)=1,$F$18,0.5))*IF($G$1="裂石",$AP5,$AN5)+IF($G$1="裂石",$AQ5*1.5,0))*(1+$BE5)*(1+$BF5)+(($BG5+($BH5-$BG5)*IF(VLOOKUP($R5,武学奇术!$A:$ZZ,31,FALSE)=1,$F$18,0.5))*IF($G$1="牵丝",$AP5,$AN5)+IF($G$1="牵丝",$AQ5*1.5,0))*(1+$BI5)*(1+$BJ5)+(($BK5+($BL5-$BK5)*IF(VLOOKUP($R5,武学奇术!$A:$ZZ,31,FALSE)=1,$F$18,0.5))*IF($G$1="破竹",$AP5,$AN5)+IF($G$1="破竹",$AQ5*1.5,0))*(1+$BM5)*(1+$BN5))*(1+$AR5)*$Q5*(1+IF(VLOOKUP($R5,武学奇术!$A:$ZZ,30,FALSE)="蓄力技",$B$21,0))*(1+$BW5) -> 16995.306 | P5: =((($AT5*$AN5+$AO5)*(1+$AV5)*(1+$AW5)+($AY5*IF($G$1="鸣金",$AP5,$AN5)+IF($G$1="鸣金",$AQ5*1.5,0))*(1+$BA5)*(1+$BB5)+($BC5*IF($G$1="裂石",$AP5,$AN5)+IF($G$1="裂石",$AQ5*1.5,0))*(1+$BE5)*(1+$BF5)+($BG5*IF($G$1="牵丝",$AP5,$AN5)+IF($G$1="牵丝",$AQ5*1.5,0))*(1+$BI5)*(1+$BJ5)+($BK5*IF($G$1="破竹",$AP5,$AN5)+IF($G$1="破竹",$AQ5*1.5,0))*(1+$BM5)*(1+$BN5))*(1+$AR5))*$Q5*(1+IF(VLOOKUP($R5,武学奇术!$A:$ZZ,30,FALSE)="蓄力技",$B$21,0))*(1+$BW5) -> 14680.766 | Q5: 1 | R5: 萧呤千浪流星 | S5: 易水歌4层 | T5: N/a | U5: N/a | V5: 近战笛 | W5: N/a | X5: N/a | Y5: 沧海帖4层 | Z5: 惧刃(拐) | AA5: N/a | AB5: 烁鼓(拐) | AC5: N/a | AD5: 离猎(拐) | AE5: 裁云(拐) | AF5: 无惧 | AG5: 天志增伤 | AH5: N/a | AI5: N/a | AJ5: N/a | AK5: N/a | AL5: N/a | AM5: =VLOOKUP($R5,武学奇术!$A:$ZZ,25,FALSE) -> 群体奇术 | AN5: =VLOOKUP($R5,武学奇术!$A:$ZZ,26,FALSE) -> 1.4904 | AO5: =VLOOKUP($R5,武学奇术!$A:$ZZ,27,FALSE)*(1+IF(OR($AM5=$F$4,$AM5=$F$5),$B$22,0)) -> 378 | AP5: =VLOOKUP($R5,武学奇术!$A:$ZZ,28,FALSE) -> 2.2356 | AQ5: =VLOOKUP($R5,武学奇术!$A:$ZZ,29,FALSE)*(1+IF(OR($AM5=$F$4,$AM5=$F$5),$B$22,0)) -> 0 | AR5: {=$G$3+IFERROR(VLOOKUP($AM5,$F$4:$G$7,2,FALSE),0)+VLOOKUP($R5,武学奇术!$A:$ZZ,2,FALSE)+SUM(_xlfn.XLOOKUP($S5:$AL5,增益!$A:$A,增益!$B:$B,0))} -> 0.2437 | AS5: {=VLOOKUP($R5,武学奇术!$A:$ZZ,5,FALSE)+SUM(_xlfn.XLOOKUP($S5:$AL5,增益!$A:$A,增益!$E:$E,0))} -> 0 | AT5: {=$D$10*(1+$AS5)+VLOOKUP($R5,武学奇术!$A:$ZZ,3,FALSE)+SUM(_xlfn.XLOOKUP($S5:$AL5,增益!$A:$A,增益!$C:$C,0))-$I$2} -> 3901.102 | AU5: {=$E$10*(1+$AS5)+VLOOKUP($R5,武学奇术!$A:$ZZ,4,FALSE)+SUM(_xlfn.XLOOKUP($S5:$AL5,增益!$A:$A,增益!$D:$D,0))-$I$2} -> 3901.102 | AV5: {=IF($F$10-$I$3+VLOOKUP($R5,武学奇术!$A:$ZZ,6,FALSE)+SUM(_xlfn.XLOOKUP($S5:$AL5,增益!$A:$A,增益!$F:$F,0))>0,($F$10-$I$3+VLOOKUP($R5,武学奇术!$A:$ZZ,6,FALSE)+SUM(_xlfn.XLOOKUP($S5:$AL5,增益!$A:$A,增益!$F:$F,0)))/200,($F$10-$I$3+VLOOKUP($R5,武学奇术!$A:$ZZ,6,FALSE)+SUM(_xlfn.XLOOKUP($S5:$AL5,增益!$A:$A,增益!$F:$F,0)))/100)} -> 0.307 | AW5: {=$G$10+VLOOKUP($R5,武学奇术!$A:$ZZ,7,FALSE)+SUM(_xlfn.XLOOKUP($S5:$AL5,增益!$A:$A,增益!$G:$G,0))} -> 0.09 | AX5: {=VLOOKUP($R5,武学奇术!$A:$ZZ,8,FALSE)+SUM(_xlfn.XLOOKUP($S5:$AL5,增益!$A:$A,增益!$H:$H,0))} -> 0 | AY5: =$D$11*(1+$AX5) -> 0 | AZ5: =$E$11*(1+$AX5) -> 0 | BA5: {=IF($F$11-$I$4+VLOOKUP($R5,武学奇术!$A:$ZZ,9,FALSE)+SUM(_xlfn.XLOOKUP($S5:$AL5,增益!$A:$A,增益!$I:$I,0))>0,($F$11-$I$4+VLOOKUP($R5,武学奇术!$A:$ZZ,9,FALSE)+SUM(_xlfn.XLOOKUP($S5:$AL5,增益!$A:$A,增益!$I:$I,0)))/200,($F$11-$I$4+VLOOKUP($R5,武学奇术!$A:$ZZ,9,FALSE)+SUM(_xlfn.XLOOKUP($S5:$AL5,增益!$A:$A,增益!$I:$I,0)))/100)} -> -0.14 | BB5: {=$G$11+VLOOKUP($R5,武学奇术!$A:$ZZ,10,FALSE)+SUM(_xlfn.XLOOKUP($S5:$AL5,增益!$A:$A,增益!$J:$J,0))} -> 0 | BC5: =$D$12*(1+$AX5) -> 0 | BD5: =$E$12*(1+$AX5) -> 0 | BE5: {=IF($F$12-$I$4+VLOOKUP($R5,武学奇术!$A:$ZZ,11,FALSE)+SUM(_xlfn.XLOOKUP($S5:$AL5,增益!$A:$A,增益!$K:$K,0))>0,($F$12-$I$4+VLOOKUP($R5,武学奇术!$A:$ZZ,11,FALSE)+SUM(_xlfn.XLOOKUP($S5:$AL5,增益!$A:$A,增益!$K:$K,0)))/200,($F$12-$I$4+VLOOKUP($R5,武学奇术!$A:$ZZ,11,FALSE)+SUM(_xlfn.XLOOKUP($S5:$AL5,增益!$A:$A,增益!$K:$K,0)))/100)} -> -0.14 | BF5: {=$G$12+VLOOKUP($R5,武学奇术!$A:$ZZ,12,FALSE)+SUM(_xlfn.XLOOKUP($S5:$AL5,增益!$A:$A,增益!$L:$L,0))} -> 0 | BG5: =$D$13*(1+$AX5) -> 0 | BH5: =$E$13*(1+$AX5) -> 0 | BI5: {=IF($F$13-$I$4+VLOOKUP($R5,武学奇术!$A:$ZZ,13,FALSE)+SUM(_xlfn.XLOOKUP($S5:$AL5,增益!$A:$A,增益!$M:$M,0))>0,($F$13-$I$4+VLOOKUP($R5,武学奇术!$A:$ZZ,13,FALSE)+SUM(_xlfn.XLOOKUP($S5:$AL5,增益!$A:$A,增益!$K:$K,0)))/200,($F$13-$I$4+VLOOKUP($R5,武学奇术!$A:$ZZ,13,FALSE)+SUM(_xlfn.XLOOKUP($S5:$AL5,增益!$A:$A,增益!$M:$M,0)))/100)} -> -0.14 | BJ5: {=$G$13+VLOOKUP($R5,武学奇术!$A:$ZZ,14,FALSE)+SUM(_xlfn.XLOOKUP($S5:$AL5,增益!$A:$A,增益!$N:$N,0))} -> 0 | BK5: =$D$14*(1+$AX5) -> 605.472 | BL5: =$E$14*(1+$AX5) -> 1725.468 | BM5: {=IF($F$14-$I$4+VLOOKUP($R5,武学奇术!$A:$ZZ,15,FALSE)+SUM(_xlfn.XLOOKUP($S5:$AL5,增益!$A:$A,增益!$O:$O,0))>0,($F$14-$I$4+VLOOKUP($R5,武学奇术!$A:$ZZ,15,FALSE)+SUM(_xlfn.XLOOKUP($S5:$AL5,增益!$A:$A,增益!$O:$O,0)))/200,($F$14-$I$4+VLOOKUP($R5,武学奇术!$A:$ZZ,15,FALSE)+SUM(_xlfn.XLOOKUP($S5:$AL5,增益!$A:$A,增益!$O:$O,0)))/100)} -> 0.08 | BN5: {=$G$14+VLOOKUP($R5,武学奇术!$A:$ZZ,16,FALSE)+SUM(_xlfn.XLOOKUP($S5:$AL5,增益!$A:$A,增益!$P:$P,0))} -> 0.24 | BO5: =MIN(IF(VLOOKUP($R5,武学奇术!$A:$ZZ,23,FALSE)=1,100%,$B$8),100%) -> 1 | BP5: {=IF(VLOOKUP($R5,武学奇术!$A:$ZZ,23,FALSE)=1,100%,MIN(80%,$B$9+VLOOKUP($R5,武学奇术!$A:$ZZ,17,FALSE)+SUM(_xlfn.XLOOKUP($S5:$AL5,增益!$A:$A,增益!$Q:$Q,0)))+$B$11+SUM(_xlfn.XLOOKUP($S5:$AL5,增益!$A:$A,增益!$U:$U,0)))*IF(VLOOKUP($R5,武学奇术!$A:$ZZ,24,FALSE)=1,0,1)+MIN(IF(VLOOKUP($R5,武学奇术!$A:$ZZ,32,FALSE)=1,IF(VLOOKUP($R5,武学奇术!$A:$ZZ,24,FALSE)=1,100%,MIN(40%,$B$10+VLOOKUP($R5,武学奇术!$A:$ZZ,19,FALSE)+SUM(_xlfn.XLOOKUP($S5:$AL5,增益!$A:$A,增益!$S:$S,0)))+$B$12+SUM(_xlfn.XLOOKUP($S5:$AL5,增益!$A:$A,增益!$V:$V,0))),0),12%)} -> 0.9036 | BQ5: {=1+$B$13+VLOOKUP($R5,武学奇术!$A:$ZZ,18,FALSE)+SUM(_xlfn.XLOOKUP($S5:$AL5,增益!$A:$A,增益!$R:$R,0))} -> 1.58 | BR5: {=MAX(IF(VLOOKUP($R5,武学奇术!$A:$ZZ,24,FALSE)=1,100%,MIN(40%,$B$10+VLOOKUP($R5,武学奇术!$A:$ZZ,19,FALSE)+SUM(_xlfn.XLOOKUP($S5:$AL5,增益!$A:$A,增益!$S:$S,0)))+$B$12+SUM(_xlfn.XLOOKUP($S5:$AL5,增益!$A:$A,增益!$V:$V,0)))*IF(VLOOKUP($R5,武学奇术!$A:$ZZ,23,FALSE)=1,0,1)-IF(VLOOKUP($R5,武学奇术!$A:$ZZ,32,FALSE)=1,12%,0),0)} -> 0.0929 | BS5: {=1+$B$14+VLOOKUP($R5,武学奇术!$A:$ZZ,20,FALSE)+SUM(_xlfn.XLOOKUP($S5:$AL5,增益!$A:$A,增益!$T:$T,0))} -> 1.35 | BT5: =MIN((1-BR5)*BO5,BO5*BP5) -> 0.9036 | BU5: =1-BR5-BT5-BV5 -> 0.0035 | BV5: =IF(VLOOKUP($R5,武学奇术!$A:$ZZ,22,FALSE)=1,0,(1-$BO5))*(1-$BR5) -> 0 | BW5: {=SUM(_xlfn.XLOOKUP($S5:$AL5,增益!$A:$A,增益!$W:$W,0))+$I$5} -> 0.11 | BX5: {=SUM(_xlfn.XLOOKUP($S5:$AL5,增益!$A:$A,增益!$X:$X,0))} -> 0
A6: 破竹 | B6: 492 | C6: 1397.8 | D6: 30 | E6: 0.15 | F6: 单体奇术 | G6: =B19 -> 0 | K6: =$L6*VLOOKUP($R6,武学奇术!$A:$ZZ,31,FALSE) -> 27106.474 | L6: =($M6*$BT6+$N6*$BR6+$O6*$BU6+$P6*$BV6) -> 27106.474 | M6: =((($AT6+($AU6-$AT6)*IF(VLOOKUP($R6,武学奇术!$A:$ZZ,31,FALSE)=1,$F$18,0.5))*$AN6+$AO6)*(1+$AV6)*(1+$AW6)+(($AY6+($AZ6-$AY6)*IF(VLOOKUP($R6,武学奇术!$A:$ZZ,31,FALSE)=1,$F$18,0.5))*IF($G$1="鸣金",$AP6,$AN6)+IF($G$1="鸣金",$AQ6*1.5,0))*(1+$BA6)*(1+$BB6)+(($BC6+($BD6-$BC6)*IF(VLOOKUP($R6,武学奇术!$A:$ZZ,31,FALSE)=1,$F$18,0.5))*IF($G$1="裂石",$AP6,$AN6)+IF($G$1="裂石",$AQ6*1.5,0))*(1+$BE6)*(1+$BF6)+(($BG6+($BH6-$BG6)*IF(VLOOKUP($R6,武学奇术!$A:$ZZ,31,FALSE)=1,$F$18,0.5))*IF($G$1="牵丝",$AP6,$AN6)+IF($G$1="牵丝",$AQ6*1.5,0))*(1+$BI6)*(1+$BJ6)+(($BK6+($BL6-$BK6)*IF(VLOOKUP($R6,武学奇术!$A:$ZZ,31,FALSE)=1,$F$18,0.5))*IF($G$1="破竹",$AP6,$AN6)+IF($G$1="破竹",$AQ6*1.5,0))*(1+$BM6)*(1+$BN6))*(1+$AR6)*$BQ6*$Q6*(1+IF(VLOOKUP($R6,武学奇术!$A:$ZZ,30,FALSE)="蓄力技",$B$21,0))*(1+$BW6) -> 27216.896 | N6: =(($AU6*$AN6+$AO6)*(1+$AV6)*(1+$AW6)+($AZ6*IF($G$1="鸣金",$AP6,$AN6)+IF($G$1="鸣金",$AQ6*1.5,0))*(1+$BA6)*(1+$BB6)+($BD6*IF($G$1="裂石",$AP6,$AN6)+IF($G$1="裂石",$AQ6*1.5,0))*(1+$BE6)*(1+$BF6)+($BH6*IF($G$1="牵丝",$AP6,$AN6)+IF($G$1="牵丝",$AQ6*1.5,0))*(1+$BI6)*(1+$BJ6)+($BL6*IF($G$1="破竹",$AP6,$AN6)+IF($G$1="破竹",$AQ6*1.5,0))*(1+$BM6)*(1+$BN6))*(1+$AR6)*$BS6*$Q6*(1+IF(VLOOKUP($R6,武学奇术!$A:$ZZ,30,FALSE)="蓄力技",$B$21,0))*(1+$BW6) -> 26404.695 | O6: =((($AT6+($AU6-$AT6)*IF(VLOOKUP($R6,武学奇术!$A:$ZZ,31,FALSE)=1,$F$18,0.5))*$AN6+$AO6)*(1+$AV6)*(1+$AW6)+(($AY6+($AZ6-$AY6)*IF(VLOOKUP($R6,武学奇术!$A:$ZZ,31,FALSE)=1,$F$18,0.5))*IF($G$1="鸣金",$AP6,$AN6)+IF($G$1="鸣金",$AQ6*1.5,0))*(1+$BA6)*(1+$BB6)+(($BC6+($BD6-$BC6)*IF(VLOOKUP($R6,武学奇术!$A:$ZZ,31,FALSE)=1,$F$18,0.5))*IF($G$1="裂石",$AP6,$AN6)+IF($G$1="裂石",$AQ6*1.5,0))*(1+$BE6)*(1+$BF6)+(($BG6+($BH6-$BG6)*IF(VLOOKUP($R6,武学奇术!$A:$ZZ,31,FALSE)=1,$F$18,0.5))*IF($G$1="牵丝",$AP6,$AN6)+IF($G$1="牵丝",$AQ6*1.5,0))*(1+$BI6)*(1+$BJ6)+(($BK6+($BL6-$BK6)*IF(VLOOKUP($R6,武学奇术!$A:$ZZ,31,FALSE)=1,$F$18,0.5))*IF($G$1="破竹",$AP6,$AN6)+IF($G$1="破竹",$AQ6*1.5,0))*(1+$BM6)*(1+$BN6))*(1+$AR6)*$Q6*(1+IF(VLOOKUP($R6,武学奇术!$A:$ZZ,30,FALSE)="蓄力技",$B$21,0))*(1+$BW6) -> 17225.883 | P6: =((($AT6*$AN6+$AO6)*(1+$AV6)*(1+$AW6)+($AY6*IF($G$1="鸣金",$AP6,$AN6)+IF($G$1="鸣金",$AQ6*1.5,0))*(1+$BA6)*(1+$BB6)+($BC6*IF($G$1="裂石",$AP6,$AN6)+IF($G$1="裂石",$AQ6*1.5,0))*(1+$BE6)*(1+$BF6)+($BG6*IF($G$1="牵丝",$AP6,$AN6)+IF($G$1="牵丝",$AQ6*1.5,0))*(1+$BI6)*(1+$BJ6)+($BK6*IF($G$1="破竹",$AP6,$AN6)+IF($G$1="破竹",$AQ6*1.5,0))*(1+$BM6)*(1+$BN6))*(1+$AR6))*$Q6*(1+IF(VLOOKUP($R6,武学奇术!$A:$ZZ,30,FALSE)="蓄力技",$B$21,0))*(1+$BW6) -> 14892.734 | Q6: 1 | R6: 萧呤千浪流星 | S6: 易水歌5层 | T6: N/a | U6: N/a | V6: 近战笛 | W6: N/a | X6: N/a | Y6: 沧海帖4层 | Z6: 惧刃(拐) | AA6: N/a | AB6: 扶风(拐) | AC6: N/a | AD6: 离猎(拐) | AE6: 裁云(拐) | AF6: 无惧 | AG6: 天志增伤 | AH6: N/a | AI6: N/a | AJ6: N/a | AK6: N/a | AL6: N/a | AM6: =VLOOKUP($R6,武学奇术!$A:$ZZ,25,FALSE) -> 群体奇术 | AN6: =VLOOKUP($R6,武学奇术!$A:$ZZ,26,FALSE) -> 1.4904 | AO6: =VLOOKUP($R6,武学奇术!$A:$ZZ,27,FALSE)*(1+IF(OR($AM6=$F$4,$AM6=$F$5),$B$22,0)) -> 378 | AP6: =VLOOKUP($R6,武学奇术!$A:$ZZ,28,FALSE) -> 2.2356 | AQ6: =VLOOKUP($R6,武学奇术!$A:$ZZ,29,FALSE)*(1+IF(OR($AM6=$F$4,$AM6=$F$5),$B$22,0)) -> 0 | AR6: {=$G$3+IFERROR(VLOOKUP($AM6,$F$4:$G$7,2,FALSE),0)+VLOOKUP($R6,武学奇术!$A:$ZZ,2,FALSE)+SUM(_xlfn.XLOOKUP($S6:$AL6,增益!$A:$A,增益!$B:$B,0))} -> 0.2537 | AS6: {=VLOOKUP($R6,武学奇术!$A:$ZZ,5,FALSE)+SUM(_xlfn.XLOOKUP($S6:$AL6,增益!$A:$A,增益!$E:$E,0))} -> 0 | AT6: {=$D$10*(1+$AS6)+VLOOKUP($R6,武学奇术!$A:$ZZ,3,FALSE)+SUM(_xlfn.XLOOKUP($S6:$AL6,增益!$A:$A,增益!$C:$C,0))-$I$2} -> 3901.102 | AU6: {=$E$10*(1+$AS6)+VLOOKUP($R6,武学奇术!$A:$ZZ,4,FALSE)+SUM(_xlfn.XLOOKUP($S6:$AL6,增益!$A:$A,增益!$D:$D,0))-$I$2} -> 3901.102 | AV6: {=IF($F$10-$I$3+VLOOKUP($R6,武学奇术!$A:$ZZ,6,FALSE)+SUM(_xlfn.XLOOKUP($S6:$AL6,增益!$A:$A,增益!$F:$F,0))>0,($F$10-$I$3+VLOOKUP($R6,武学奇术!$A:$ZZ,6,FALSE)+SUM(_xlfn.XLOOKUP($S6:$AL6,增益!$A:$A,增益!$F:$F,0)))/200,($F$10-$I$3+VLOOKUP($R6,武学奇术!$A:$ZZ,6,FALSE)+SUM(_xlfn.XLOOKUP($S6:$AL6,增益!$A:$A,增益!$F:$F,0)))/100)} -> 0.317 | AW6: {=$G$10+VLOOKUP($R6,武学奇术!$A:$ZZ,7,FALSE)+SUM(_xlfn.XLOOKUP($S6:$AL6,增益!$A:$A,增益!$G:$G,0))} -> 0.09 | AX6: {=VLOOKUP($R6,武学奇术!$A:$ZZ,8,FALSE)+SUM(_xlfn.XLOOKUP($S6:$AL6,增益!$A:$A,增益!$H:$H,0))} -> 0 | AY6: =$D$11*(1+$AX6) -> 0 | AZ6: =$E$11*(1+$AX6) -> 0 | BA6: {=IF($F$11-$I$4+VLOOKUP($R6,武学奇术!$A:$ZZ,9,FALSE)+SUM(_xlfn.XLOOKUP($S6:$AL6,增益!$A:$A,增益!$I:$I,0))>0,($F$11-$I$4+VLOOKUP($R6,武学奇术!$A:$ZZ,9,FALSE)+SUM(_xlfn.XLOOKUP($S6:$AL6,增益!$A:$A,增益!$I:$I,0)))/200,($F$11-$I$4+VLOOKUP($R6,武学奇术!$A:$ZZ,9,FALSE)+SUM(_xlfn.XLOOKUP($S6:$AL6,增益!$A:$A,增益!$I:$I,0)))/100)} -> -0.14 | BB6: {=$G$11+VLOOKUP($R6,武学奇术!$A:$ZZ,10,FALSE)+SUM(_xlfn.XLOOKUP($S6:$AL6,增益!$A:$A,增益!$J:$J,0))} -> 0 | BC6: =$D$12*(1+$AX6) -> 0 | BD6: =$E$12*(1+$AX6) -> 0 | BE6: {=IF($F$12-$I$4+VLOOKUP($R6,武学奇术!$A:$ZZ,11,FALSE)+SUM(_xlfn.XLOOKUP($S6:$AL6,增益!$A:$A,增益!$K:$K,0))>0,($F$12-$I$4+VLOOKUP($R6,武学奇术!$A:$ZZ,11,FALSE)+SUM(_xlfn.XLOOKUP($S6:$AL6,增益!$A:$A,增益!$K:$K,0)))/200,($F$12-$I$4+VLOOKUP($R6,武学奇术!$A:$ZZ,11,FALSE)+SUM(_xlfn.XLOOKUP($S6:$AL6,增益!$A:$A,增益!$K:$K,0)))/100)} -> -0.14 | BF6: {=$G$12+VLOOKUP($R6,武学奇术!$A:$ZZ,12,FALSE)+SUM(_xlfn.XLOOKUP($S6:$AL6,增益!$A:$A,增益!$L:$L,0))} -> 0 | BG6: =$D$13*(1+$AX6) -> 0 | BH6: =$E$13*(1+$AX6) -> 0 | BI6: {=IF($F$13-$I$4+VLOOKUP($R6,武学奇术!$A:$ZZ,13,FALSE)+SUM(_xlfn.XLOOKUP($S6:$AL6,增益!$A:$A,增益!$M:$M,0))>0,($F$13-$I$4+VLOOKUP($R6,武学奇术!$A:$ZZ,13,FALSE)+SUM(_xlfn.XLOOKUP($S6:$AL6,增益!$A:$A,增益!$K:$K,0)))/200,($F$13-$I$4+VLOOKUP($R6,武学奇术!$A:$ZZ,13,FALSE)+SUM(_xlfn.XLOOKUP($S6:$AL6,增益!$A:$A,增益!$M:$M,0)))/100)} -> -0.14 | BJ6: {=$G$13+VLOOKUP($R6,武学奇术!$A:$ZZ,14,FALSE)+SUM(_xlfn.XLOOKUP($S6:$AL6,增益!$A:$A,增益!$N:$N,0))} -> 0 | BK6: =$D$14*(1+$AX6) -> 605.472 | BL6: =$E$14*(1+$AX6) -> 1725.468 | BM6: {=IF($F$14-$I$4+VLOOKUP($R6,武学奇术!$A:$ZZ,15,FALSE)+SUM(_xlfn.XLOOKUP($S6:$AL6,增益!$A:$A,增益!$O:$O,0))>0,($F$14-$I$4+VLOOKUP($R6,武学奇术!$A:$ZZ,15,FALSE)+SUM(_xlfn.XLOOKUP($S6:$AL6,增益!$A:$A,增益!$O:$O,0)))/200,($F$14-$I$4+VLOOKUP($R6,武学奇术!$A:$ZZ,15,FALSE)+SUM(_xlfn.XLOOKUP($S6:$AL6,增益!$A:$A,增益!$O:$O,0)))/100)} -> 0.08 | BN6: {=$G$14+VLOOKUP($R6,武学奇术!$A:$ZZ,16,FALSE)+SUM(_xlfn.XLOOKUP($S6:$AL6,增益!$A:$A,增益!$P:$P,0))} -> 0.24 | BO6: =MIN(IF(VLOOKUP($R6,武学奇术!$A:$ZZ,23,FALSE)=1,100%,$B$8),100%) -> 1 | BP6: {=IF(VLOOKUP($R6,武学奇术!$A:$ZZ,23,FALSE)=1,100%,MIN(80%,$B$9+VLOOKUP($R6,武学奇术!$A:$ZZ,17,FALSE)+SUM(_xlfn.XLOOKUP($S6:$AL6,增益!$A:$A,增益!$Q:$Q,0)))+$B$11+SUM(_xlfn.XLOOKUP($S6:$AL6,增益!$A:$A,增益!$U:$U,0)))*IF(VLOOKUP($R6,武学奇术!$A:$ZZ,24,FALSE)=1,0,1)+MIN(IF(VLOOKUP($R6,武学奇术!$A:$ZZ,32,FALSE)=1,IF(VLOOKUP($R6,武学奇术!$A:$ZZ,24,FALSE)=1,100%,MIN(40%,$B$10+VLOOKUP($R6,武学奇术!$A:$ZZ,19,FALSE)+SUM(_xlfn.XLOOKUP($S6:$AL6,增益!$A:$A,增益!$S:$S,0)))+$B$12+SUM(_xlfn.XLOOKUP($S6:$AL6,增益!$A:$A,增益!$V:$V,0))),0),12%)} -> 0.9036 | BQ6: {=1+$B$13+VLOOKUP($R6,武学奇术!$A:$ZZ,18,FALSE)+SUM(_xlfn.XLOOKUP($S6:$AL6,增益!$A:$A,增益!$R:$R,0))} -> 1.58 | BR6: {=MAX(IF(VLOOKUP($R6,武学奇术!$A:$ZZ,24,FALSE)=1,100%,MIN(40%,$B$10+VLOOKUP($R6,武学奇术!$A:$ZZ,19,FALSE)+SUM(_xlfn.XLOOKUP($S6:$AL6,增益!$A:$A,增益!$S:$S,0)))+$B$12+SUM(_xlfn.XLOOKUP($S6:$AL6,增益!$A:$A,增益!$V:$V,0)))*IF(VLOOKUP($R6,武学奇术!$A:$ZZ,23,FALSE)=1,0,1)-IF(VLOOKUP($R6,武学奇术!$A:$ZZ,32,FALSE)=1,12%,0),0)} -> 0.0929 | BS6: {=1+$B$14+VLOOKUP($R6,武学奇术!$A:$ZZ,20,FALSE)+SUM(_xlfn.XLOOKUP($S6:$AL6,增益!$A:$A,增益!$T:$T,0))} -> 1.35 | BT6: =MIN((1-BR6)*BO6,BO6*BP6) -> 0.9036 | BU6: =1-BR6-BT6-BV6 -> 0.0035 | BV6: =IF(VLOOKUP($R6,武学奇术!$A:$ZZ,22,FALSE)=1,0,(1-$BO6))*(1-$BR6) -> 0 | BW6: {=SUM(_xlfn.XLOOKUP($S6:$AL6,增益!$A:$A,增益!$W:$W,0))+$I$5} -> 0.11 | BX6: {=SUM(_xlfn.XLOOKUP($S6:$AL6,增益!$A:$A,增益!$X:$X,0))} -> 0
A7: 无相 | B7: 79.2 | C7: =92.4+68.8*2 -> 230 | F7: 群体奇术 | G7: =B20 -> 0 | K7: =$L7*VLOOKUP($R7,武学奇术!$A:$ZZ,31,FALSE) -> 23128.659 | L7: =($M7*$BT7+$N7*$BR7+$O7*$BU7+$P7*$BV7) -> 23128.659 | M7: =((($AT7+($AU7-$AT7)*IF(VLOOKUP($R7,武学奇术!$A:$ZZ,31,FALSE)=1,$F$18,0.5))*$AN7+$AO7)*(1+$AV7)*(1+$AW7)+(($AY7+($AZ7-$AY7)*IF(VLOOKUP($R7,武学奇术!$A:$ZZ,31,FALSE)=1,$F$18,0.5))*IF($G$1="鸣金",$AP7,$AN7)+IF($G$1="鸣金",$AQ7*1.5,0))*(1+$BA7)*(1+$BB7)+(($BC7+($BD7-$BC7)*IF(VLOOKUP($R7,武学奇术!$A:$ZZ,31,FALSE)=1,$F$18,0.5))*IF($G$1="裂石",$AP7,$AN7)+IF($G$1="裂石",$AQ7*1.5,0))*(1+$BE7)*(1+$BF7)+(($BG7+($BH7-$BG7)*IF(VLOOKUP($R7,武学奇术!$A:$ZZ,31,FALSE)=1,$F$18,0.5))*IF($G$1="牵丝",$AP7,$AN7)+IF($G$1="牵丝",$AQ7*1.5,0))*(1+$BI7)*(1+$BJ7)+(($BK7+($BL7-$BK7)*IF(VLOOKUP($R7,武学奇术!$A:$ZZ,31,FALSE)=1,$F$18,0.5))*IF($G$1="破竹",$AP7,$AN7)+IF($G$1="破竹",$AQ7*1.5,0))*(1+$BM7)*(1+$BN7))*(1+$AR7)*$BQ7*$Q7*(1+IF(VLOOKUP($R7,武学奇术!$A:$ZZ,30,FALSE)="蓄力技",$B$21,0))*(1+$BW7) -> 23192.901 | N7: =(($AU7*$AN7+$AO7)*(1+$AV7)*(1+$AW7)+($AZ7*IF($G$1="鸣金",$AP7,$AN7)+IF($G$1="鸣金",$AQ7*1.5,0))*(1+$BA7)*(1+$BB7)+($BD7*IF($G$1="裂石",$AP7,$AN7)+IF($G$1="裂石",$AQ7*1.5,0))*(1+$BE7)*(1+$BF7)+($BH7*IF($G$1="牵丝",$AP7,$AN7)+IF($G$1="牵丝",$AQ7*1.5,0))*(1+$BI7)*(1+$BJ7)+($BL7*IF($G$1="破竹",$AP7,$AN7)+IF($G$1="破竹",$AQ7*1.5,0))*(1+$BM7)*(1+$BN7))*(1+$AR7)*$BS7*$Q7*(1+IF(VLOOKUP($R7,武学奇术!$A:$ZZ,30,FALSE)="蓄力技",$B$21,0))*(1+$BW7) -> 22807.774 | O7: =((($AT7+($AU7-$AT7)*IF(VLOOKUP($R7,武学奇术!$A:$ZZ,31,FALSE)=1,$F$18,0.5))*$AN7+$AO7)*(1+$AV7)*(1+$AW7)+(($AY7+($AZ7-$AY7)*IF(VLOOKUP($R7,武学奇术!$A:$ZZ,31,FALSE)=1,$F$18,0.5))*IF($G$1="鸣金",$AP7,$AN7)+IF($G$1="鸣金",$AQ7*1.5,0))*(1+$BA7)*(1+$BB7)+(($BC7+($BD7-$BC7)*IF(VLOOKUP($R7,武学奇术!$A:$ZZ,31,FALSE)=1,$F$18,0.5))*IF($G$1="裂石",$AP7,$AN7)+IF($G$1="裂石",$AQ7*1.5,0))*(1+$BE7)*(1+$BF7)+(($BG7+($BH7-$BG7)*IF(VLOOKUP($R7,武学奇术!$A:$ZZ,31,FALSE)=1,$F$18,0.5))*IF($G$1="牵丝",$AP7,$AN7)+IF($G$1="牵丝",$AQ7*1.5,0))*(1+$BI7)*(1+$BJ7)+(($BK7+($BL7-$BK7)*IF(VLOOKUP($R7,武学奇术!$A:$ZZ,31,FALSE)=1,$F$18,0.5))*IF($G$1="破竹",$AP7,$AN7)+IF($G$1="破竹",$AQ7*1.5,0))*(1+$BM7)*(1+$BN7))*(1+$AR7)*$Q7*(1+IF(VLOOKUP($R7,武学奇术!$A:$ZZ,30,FALSE)="蓄力技",$B$21,0))*(1+$BW7) -> 15060.326 | P7: =((($AT7*$AN7+$AO7)*(1+$AV7)*(1+$AW7)+($AY7*IF($G$1="鸣金",$AP7,$AN7)+IF($G$1="鸣金",$AQ7*1.5,0))*(1+$BA7)*(1+$BB7)+($BC7*IF($G$1="裂石",$AP7,$AN7)+IF($G$1="裂石",$AQ7*1.5,0))*(1+$BE7)*(1+$BF7)+($BG7*IF($G$1="牵丝",$AP7,$AN7)+IF($G$1="牵丝",$AQ7*1.5,0))*(1+$BI7)*(1+$BJ7)+($BK7*IF($G$1="破竹",$AP7,$AN7)+IF($G$1="破竹",$AQ7*1.5,0))*(1+$BM7)*(1+$BN7))*(1+$AR7))*$Q7*(1+IF(VLOOKUP($R7,武学奇术!$A:$ZZ,30,FALSE)="蓄力技",$B$21,0))*(1+$BW7) -> 13226.003 | Q7: 1 | R7: 绳标～ | S7: N/a | T7: N/a | U7: N/a | V7: N/a | W7: N/a | X7: N/a | Y7: N/a | Z7: N/a | AA7: N/a | AB7: N/a | AC7: N/a | AD7: 离猎(拐) | AE7: 裁云(拐) | AF7: 无惧 | AG7: 天志增伤 | AH7: N/a | AI7: N/a | AJ7: N/a | AK7: N/a | AL7: N/a | AM7: =VLOOKUP($R7,武学奇术!$A:$ZZ,25,FALSE) -> 绳镖 | AN7: =VLOOKUP($R7,武学奇术!$A:$ZZ,26,FALSE) -> 1.2503 | AO7: =VLOOKUP($R7,武学奇术!$A:$ZZ,27,FALSE)*(1+IF(OR($AM7=$F$4,$AM7=$F$5),$B$22,0)) -> 520.5 | AP7: =VLOOKUP($R7,武学奇术!$A:$ZZ,28,FALSE) -> 1.8755 | AQ7: =VLOOKUP($R7,武学奇术!$A:$ZZ,29,FALSE)*(1+IF(OR($AM7=$F$4,$AM7=$F$5),$B$22,0)) -> 283.5 | AR7: {=$G$3+IFERROR(VLOOKUP($AM7,$F$4:$G$7,2,FALSE),0)+VLOOKUP($R7,武学奇术!$A:$ZZ,2,FALSE)+SUM(_xlfn.XLOOKUP($S7:$AL7,增益!$A:$A,增益!$B:$B,0))} -> 0.2689 | AS7: {=VLOOKUP($R7,武学奇术!$A:$ZZ,5,FALSE)+SUM(_xlfn.XLOOKUP($S7:$AL7,增益!$A:$A,增益!$E:$E,0))} -> 0 | AT7: {=$D$10*(1+$AS7)+VLOOKUP($R7,武学奇术!$A:$ZZ,3,FALSE)+SUM(_xlfn.XLOOKUP($S7:$AL7,增益!$A:$A,增益!$C:$C,0))-$I$2} -> 3901.102 | AU7: {=$E$10*(1+$AS7)+VLOOKUP($R7,武学奇术!$A:$ZZ,4,FALSE)+SUM(_xlfn.XLOOKUP($S7:$AL7,增益!$A:$A,增益!$D:$D,0))-$I$2} -> 3901.102 | AV7: {=IF($F$10-$I$3+VLOOKUP($R7,武学奇术!$A:$ZZ,6,FALSE)+SUM(_xlfn.XLOOKUP($S7:$AL7,增益!$A:$A,增益!$F:$F,0))>0,($F$10-$I$3+VLOOKUP($R7,武学奇术!$A:$ZZ,6,FALSE)+SUM(_xlfn.XLOOKUP($S7:$AL7,增益!$A:$A,增益!$F:$F,0)))/200,($F$10-$I$3+VLOOKUP($R7,武学奇术!$A:$ZZ,6,FALSE)+SUM(_xlfn.XLOOKUP($S7:$AL7,增益!$A:$A,增益!$F:$F,0)))/100)} -> 0.267 | AW7: {=$G$10+VLOOKUP($R7,武学奇术!$A:$ZZ,7,FALSE)+SUM(_xlfn.XLOOKUP($S7:$AL7,增益!$A:$A,增益!$G:$G,0))} -> 0.09 | AX7: {=VLOOKUP($R7,武学奇术!$A:$ZZ,8,FALSE)+SUM(_xlfn.XLOOKUP($S7:$AL7,增益!$A:$A,增益!$H:$H,0))} -> 0 | AY7: =$D$11*(1+$AX7) -> 0 | AZ7: =$E$11*(1+$AX7) -> 0 | BA7: {=IF($F$11-$I$4+VLOOKUP($R7,武学奇术!$A:$ZZ,9,FALSE)+SUM(_xlfn.XLOOKUP($S7:$AL7,增益!$A:$A,增益!$I:$I,0))>0,($F$11-$I$4+VLOOKUP($R7,武学奇术!$A:$ZZ,9,FALSE)+SUM(_xlfn.XLOOKUP($S7:$AL7,增益!$A:$A,增益!$I:$I,0)))/200,($F$11-$I$4+VLOOKUP($R7,武学奇术!$A:$ZZ,9,FALSE)+SUM(_xlfn.XLOOKUP($S7:$AL7,增益!$A:$A,增益!$I:$I,0)))/100)} -> -0.3 | BB7: {=$G$11+VLOOKUP($R7,武学奇术!$A:$ZZ,10,FALSE)+SUM(_xlfn.XLOOKUP($S7:$AL7,增益!$A:$A,增益!$J:$J,0))} -> 0 | BC7: =$D$12*(1+$AX7) -> 0 | BD7: =$E$12*(1+$AX7) -> 0 | BE7: {=IF($F$12-$I$4+VLOOKUP($R7,武学奇术!$A:$ZZ,11,FALSE)+SUM(_xlfn.XLOOKUP($S7:$AL7,增益!$A:$A,增益!$K:$K,0))>0,($F$12-$I$4+VLOOKUP($R7,武学奇术!$A:$ZZ,11,FALSE)+SUM(_xlfn.XLOOKUP($S7:$AL7,增益!$A:$A,增益!$K:$K,0)))/200,($F$12-$I$4+VLOOKUP($R7,武学奇术!$A:$ZZ,11,FALSE)+SUM(_xlfn.XLOOKUP($S7:$AL7,增益!$A:$A,增益!$K:$K,0)))/100)} -> -0.3 | BF7: {=$G$12+VLOOKUP($R7,武学奇术!$A:$ZZ,12,FALSE)+SUM(_xlfn.XLOOKUP($S7:$AL7,增益!$A:$A,增益!$L:$L,0))} -> 0 | BG7: =$D$13*(1+$AX7) -> 0 | BH7: =$E$13*(1+$AX7) -> 0 | BI7: {=IF($F$13-$I$4+VLOOKUP($R7,武学奇术!$A:$ZZ,13,FALSE)+SUM(_xlfn.XLOOKUP($S7:$AL7,增益!$A:$A,增益!$M:$M,0))>0,($F$13-$I$4+VLOOKUP($R7,武学奇术!$A:$ZZ,13,FALSE)+SUM(_xlfn.XLOOKUP($S7:$AL7,增益!$A:$A,增益!$K:$K,0)))/200,($F$13-$I$4+VLOOKUP($R7,武学奇术!$A:$ZZ,13,FALSE)+SUM(_xlfn.XLOOKUP($S7:$AL7,增益!$A:$A,增益!$M:$M,0)))/100)} -> -0.3 | BJ7: {=$G$13+VLOOKUP($R7,武学奇术!$A:$ZZ,14,FALSE)+SUM(_xlfn.XLOOKUP($S7:$AL7,增益!$A:$A,增益!$N:$N,0))} -> 0 | BK7: =$D$14*(1+$AX7) -> 605.472 | BL7: =$E$14*(1+$AX7) -> 1725.468 | BM7: {=IF($F$14-$I$4+VLOOKUP($R7,武学奇术!$A:$ZZ,15,FALSE)+SUM(_xlfn.XLOOKUP($S7:$AL7,增益!$A:$A,增益!$O:$O,0))>0,($F$14-$I$4+VLOOKUP($R7,武学奇术!$A:$ZZ,15,FALSE)+SUM(_xlfn.XLOOKUP($S7:$AL7,增益!$A:$A,增益!$O:$O,0)))/200,($F$14-$I$4+VLOOKUP($R7,武学奇术!$A:$ZZ,15,FALSE)+SUM(_xlfn.XLOOKUP($S7:$AL7,增益!$A:$A,增益!$O:$O,0)))/100)} -> 0 | BN7: {=$G$14+VLOOKUP($R7,武学奇术!$A:$ZZ,16,FALSE)+SUM(_xlfn.XLOOKUP($S7:$AL7,增益!$A:$A,增益!$P:$P,0))} -> 0.24 | BO7: =MIN(IF(VLOOKUP($R7,武学奇术!$A:$ZZ,23,FALSE)=1,100%,$B$8),100%) -> 1 | BP7: {=IF(VLOOKUP($R7,武学奇术!$A:$ZZ,23,FALSE)=1,100%,MIN(80%,$B$9+VLOOKUP($R7,武学奇术!$A:$ZZ,17,FALSE)+SUM(_xlfn.XLOOKUP($S7:$AL7,增益!$A:$A,增益!$Q:$Q,0)))+$B$11+SUM(_xlfn.XLOOKUP($S7:$AL7,增益!$A:$A,增益!$U:$U,0)))*IF(VLOOKUP($R7,武学奇术!$A:$ZZ,24,FALSE)=1,0,1)+MIN(IF(VLOOKUP($R7,武学奇术!$A:$ZZ,32,FALSE)=1,IF(VLOOKUP($R7,武学奇术!$A:$ZZ,24,FALSE)=1,100%,MIN(40%,$B$10+VLOOKUP($R7,武学奇术!$A:$ZZ,19,FALSE)+SUM(_xlfn.XLOOKUP($S7:$AL7,增益!$A:$A,增益!$S:$S,0)))+$B$12+SUM(_xlfn.XLOOKUP($S7:$AL7,增益!$A:$A,增益!$V:$V,0))),0),12%)} -> 0.9036 | BQ7: {=1+$B$13+VLOOKUP($R7,武学奇术!$A:$ZZ,18,FALSE)+SUM(_xlfn.XLOOKUP($S7:$AL7,增益!$A:$A,增益!$R:$R,0))} -> 1.54 | BR7: {=MAX(IF(VLOOKUP($R7,武学奇术!$A:$ZZ,24,FALSE)=1,100%,MIN(40%,$B$10+VLOOKUP($R7,武学奇术!$A:$ZZ,19,FALSE)+SUM(_xlfn.XLOOKUP($S7:$AL7,增益!$A:$A,增益!$S:$S,0)))+$B$12+SUM(_xlfn.XLOOKUP($S7:$AL7,增益!$A:$A,增益!$V:$V,0)))*IF(VLOOKUP($R7,武学奇术!$A:$ZZ,23,FALSE)=1,0,1)-IF(VLOOKUP($R7,武学奇术!$A:$ZZ,32,FALSE)=1,12%,0),0)} -> 0.0929 | BS7: {=1+$B$14+VLOOKUP($R7,武学奇术!$A:$ZZ,20,FALSE)+SUM(_xlfn.XLOOKUP($S7:$AL7,增益!$A:$A,增益!$T:$T,0))} -> 1.35 | BT7: =MIN((1-BR7)*BO7,BO7*BP7) -> 0.9036 | BU7: =1-BR7-BT7-BV7 -> 0.0035 | BV7: =IF(VLOOKUP($R7,武学奇术!$A:$ZZ,22,FALSE)=1,0,(1-$BO7))*(1-$BR7) -> 0 | BW7: {=SUM(_xlfn.XLOOKUP($S7:$AL7,增益!$A:$A,增益!$W:$W,0))+$I$5} -> 0.11 | BX7: {=SUM(_xlfn.XLOOKUP($S7:$AL7,增益!$A:$A,增益!$X:$X,0))} -> 0
A8: 精准率 | B8: 1.0063 | C8: 实际属性 | H8: 战斗时间 | I8: 100.8 | K8: =$L8*VLOOKUP($R8,武学奇术!$A:$ZZ,31,FALSE) -> 70955.933 | L8: =($M8*$BT8+$N8*$BR8+$O8*$BU8+$P8*$BV8) -> 54581.487 | M8: =((($AT8+($AU8-$AT8)*IF(VLOOKUP($R8,武学奇术!$A:$ZZ,31,FALSE)=1,$F$18,0.5))*$AN8+$AO8)*(1+$AV8)*(1+$AW8)+(($AY8+($AZ8-$AY8)*IF(VLOOKUP($R8,武学奇术!$A:$ZZ,31,FALSE)=1,$F$18,0.5))*IF($G$1="鸣金",$AP8,$AN8)+IF($G$1="鸣金",$AQ8*1.5,0))*(1+$BA8)*(1+$BB8)+(($BC8+($BD8-$BC8)*IF(VLOOKUP($R8,武学奇术!$A:$ZZ,31,FALSE)=1,$F$18,0.5))*IF($G$1="裂石",$AP8,$AN8)+IF($G$1="裂石",$AQ8*1.5,0))*(1+$BE8)*(1+$BF8)+(($BG8+($BH8-$BG8)*IF(VLOOKUP($R8,武学奇术!$A:$ZZ,31,FALSE)=1,$F$18,0.5))*IF($G$1="牵丝",$AP8,$AN8)+IF($G$1="牵丝",$AQ8*1.5,0))*(1+$BI8)*(1+$BJ8)+(($BK8+($BL8-$BK8)*IF(VLOOKUP($R8,武学奇术!$A:$ZZ,31,FALSE)=1,$F$18,0.5))*IF($G$1="破竹",$AP8,$AN8)+IF($G$1="破竹",$AQ8*1.5,0))*(1+$BM8)*(1+$BN8))*(1+$AR8)*$BQ8*$Q8*(1+IF(VLOOKUP($R8,武学奇术!$A:$ZZ,30,FALSE)="蓄力技",$B$21,0))*(1+$BW8) -> 55546.914 | N8: =(($AU8*$AN8+$AO8)*(1+$AV8)*(1+$AW8)+($AZ8*IF($G$1="鸣金",$AP8,$AN8)+IF($G$1="鸣金",$AQ8*1.5,0))*(1+$BA8)*(1+$BB8)+($BD8*IF($G$1="裂石",$AP8,$AN8)+IF($G$1="裂石",$AQ8*1.5,0))*(1+$BE8)*(1+$BF8)+($BH8*IF($G$1="牵丝",$AP8,$AN8)+IF($G$1="牵丝",$AQ8*1.5,0))*(1+$BI8)*(1+$BJ8)+($BL8*IF($G$1="破竹",$AP8,$AN8)+IF($G$1="破竹",$AQ8*1.5,0))*(1+$BM8)*(1+$BN8))*(1+$AR8)*$BS8*$Q8*(1+IF(VLOOKUP($R8,武学奇术!$A:$ZZ,30,FALSE)="蓄力技",$B$21,0))*(1+$BW8) -> 46116.326 | O8: =((($AT8+($AU8-$AT8)*IF(VLOOKUP($R8,武学奇术!$A:$ZZ,31,FALSE)=1,$F$18,0.5))*$AN8+$AO8)*(1+$AV8)*(1+$AW8)+(($AY8+($AZ8-$AY8)*IF(VLOOKUP($R8,武学奇术!$A:$ZZ,31,FALSE)=1,$F$18,0.5))*IF($G$1="鸣金",$AP8,$AN8)+IF($G$1="鸣金",$AQ8*1.5,0))*(1+$BA8)*(1+$BB8)+(($BC8+($BD8-$BC8)*IF(VLOOKUP($R8,武学奇术!$A:$ZZ,31,FALSE)=1,$F$18,0.5))*IF($G$1="裂石",$AP8,$AN8)+IF($G$1="裂石",$AQ8*1.5,0))*(1+$BE8)*(1+$BF8)+(($BG8+($BH8-$BG8)*IF(VLOOKUP($R8,武学奇术!$A:$ZZ,31,FALSE)=1,$F$18,0.5))*IF($G$1="牵丝",$AP8,$AN8)+IF($G$1="牵丝",$AQ8*1.5,0))*(1+$BI8)*(1+$BJ8)+(($BK8+($BL8-$BK8)*IF(VLOOKUP($R8,武学奇术!$A:$ZZ,31,FALSE)=1,$F$18,0.5))*IF($G$1="破竹",$AP8,$AN8)+IF($G$1="破竹",$AQ8*1.5,0))*(1+$BM8)*(1+$BN8))*(1+$AR8)*$Q8*(1+IF(VLOOKUP($R8,武学奇术!$A:$ZZ,30,FALSE)="蓄力技",$B$21,0))*(1+$BW8) -> 30025.359 | P8: =((($AT8*$AN8+$AO8)*(1+$AV8)*(1+$AW8)+($AY8*IF($G$1="鸣金",$AP8,$AN8)+IF($G$1="鸣金",$AQ8*1.5,0))*(1+$BA8)*(1+$BB8)+($BC8*IF($G$1="裂石",$AP8,$AN8)+IF($G$1="裂石",$AQ8*1.5,0))*(1+$BE8)*(1+$BF8)+($BG8*IF($G$1="牵丝",$AP8,$AN8)+IF($G$1="牵丝",$AQ8*1.5,0))*(1+$BI8)*(1+$BJ8)+($BK8*IF($G$1="破竹",$AP8,$AN8)+IF($G$1="破竹",$AQ8*1.5,0))*(1+$BM8)*(1+$BN8))*(1+$AR8))*$Q8*(1+IF(VLOOKUP($R8,武学奇术!$A:$ZZ,30,FALSE)="蓄力技",$B$21,0))*(1+$BW8) -> 25890.476 | Q8: 1 | R8: 鹰隼追击(绳特殊技) | S8: 易水歌1层 | T8: N/a | U8: N/a | V8: N/a | W8: N/a | X8: N/a | Y8: 沧海帖1层 | Z8: N/a | AA8: 三穷 | AB8: 扶风(拐) | AC8: N/a | AD8: 离猎(拐) | AE8: 裁云(拐) | AF8: 无惧 | AG8: 天志增伤 | AH8: N/a | AI8: N/a | AJ8: N/a | AK8: N/a | AL8: N/a | AM8: =VLOOKUP($R8,武学奇术!$A:$ZZ,25,FALSE) -> 绳镖 | AN8: =VLOOKUP($R8,武学奇术!$A:$ZZ,26,FALSE) -> 2.19912 | AO8: =VLOOKUP($R8,武学奇术!$A:$ZZ,27,FALSE)*(1+IF(OR($AM8=$F$4,$AM8=$F$5),$B$22,0)) -> 0 | AP8: =VLOOKUP($R8,武学奇术!$A:$ZZ,28,FALSE) -> 3.29868 | AQ8: =VLOOKUP($R8,武学奇术!$A:$ZZ,29,FALSE)*(1+IF(OR($AM8=$F$4,$AM8=$F$5),$B$22,0)) -> 0 | AR8: {=$G$3+IFERROR(VLOOKUP($AM8,$F$4:$G$7,2,FALSE),0)+VLOOKUP($R8,武学奇术!$A:$ZZ,2,FALSE)+SUM(_xlfn.XLOOKUP($S8:$AL8,增益!$A:$A,增益!$B:$B,0))} -> 0.5789 | AS8: {=VLOOKUP($R8,武学奇术!$A:$ZZ,5,FALSE)+SUM(_xlfn.XLOOKUP($S8:$AL8,增益!$A:$A,增益!$E:$E,0))} -> 0 | AT8: {=$D$10*(1+$AS8)+VLOOKUP($R8,武学奇术!$A:$ZZ,3,FALSE)+SUM(_xlfn.XLOOKUP($S8:$AL8,增益!$A:$A,增益!$C:$C,0))-$I$2} -> 3901.102 | AU8: {=$E$10*(1+$AS8)+VLOOKUP($R8,武学奇术!$A:$ZZ,4,FALSE)+SUM(_xlfn.XLOOKUP($S8:$AL8,增益!$A:$A,增益!$D:$D,0))-$I$2} -> 3901.102 | AV8: {=IF($F$10-$I$3+VLOOKUP($R8,武学奇术!$A:$ZZ,6,FALSE)+SUM(_xlfn.XLOOKUP($S8:$AL8,增益!$A:$A,增益!$F:$F,0))>0,($F$10-$I$3+VLOOKUP($R8,武学奇术!$A:$ZZ,6,FALSE)+SUM(_xlfn.XLOOKUP($S8:$AL8,增益!$A:$A,增益!$F:$F,0)))/200,($F$10-$I$3+VLOOKUP($R8,武学奇术!$A:$ZZ,6,FALSE)+SUM(_xlfn.XLOOKUP($S8:$AL8,增益!$A:$A,增益!$F:$F,0)))/100)} -> 0.307 | AW8: {=$G$10+VLOOKUP($R8,武学奇术!$A:$ZZ,7,FALSE)+SUM(_xlfn.XLOOKUP($S8:$AL8,增益!$A:$A,增益!$G:$G,0))} -> 0.09 | AX8: {=VLOOKUP($R8,武学奇术!$A:$ZZ,8,FALSE)+SUM(_xlfn.XLOOKUP($S8:$AL8,增益!$A:$A,增益!$H:$H,0))} -> 0 | AY8: =$D$11*(1+$AX8) -> 0 | AZ8: =$E$11*(1+$AX8) -> 0 | BA8: {=IF($F$11-$I$4+VLOOKUP($R8,武学奇术!$A:$ZZ,9,FALSE)+SUM(_xlfn.XLOOKUP($S8:$AL8,增益!$A:$A,增益!$I:$I,0))>0,($F$11-$I$4+VLOOKUP($R8,武学奇术!$A:$ZZ,9,FALSE)+SUM(_xlfn.XLOOKUP($S8:$AL8,增益!$A:$A,增益!$I:$I,0)))/200,($F$11-$I$4+VLOOKUP($R8,武学奇术!$A:$ZZ,9,FALSE)+SUM(_xlfn.XLOOKUP($S8:$AL8,增益!$A:$A,增益!$I:$I,0)))/100)} -> -0.24 | BB8: {=$G$11+VLOOKUP($R8,武学奇术!$A:$ZZ,10,FALSE)+SUM(_xlfn.XLOOKUP($S8:$AL8,增益!$A:$A,增益!$J:$J,0))} -> 0 | BC8: =$D$12*(1+$AX8) -> 0 | BD8: =$E$12*(1+$AX8) -> 0 | BE8: {=IF($F$12-$I$4+VLOOKUP($R8,武学奇术!$A:$ZZ,11,FALSE)+SUM(_xlfn.XLOOKUP($S8:$AL8,增益!$A:$A,增益!$K:$K,0))>0,($F$12-$I$4+VLOOKUP($R8,武学奇术!$A:$ZZ,11,FALSE)+SUM(_xlfn.XLOOKUP($S8:$AL8,增益!$A:$A,增益!$K:$K,0)))/200,($F$12-$I$4+VLOOKUP($R8,武学奇术!$A:$ZZ,11,FALSE)+SUM(_xlfn.XLOOKUP($S8:$AL8,增益!$A:$A,增益!$K:$K,0)))/100)} -> -0.24 | BF8: {=$G$12+VLOOKUP($R8,武学奇术!$A:$ZZ,12,FALSE)+SUM(_xlfn.XLOOKUP($S8:$AL8,增益!$A:$A,增益!$L:$L,0))} -> 0 | BG8: =$D$13*(1+$AX8) -> 0 | BH8: =$E$13*(1+$AX8) -> 0 | BI8: {=IF($F$13-$I$4+VLOOKUP($R8,武学奇术!$A:$ZZ,13,FALSE)+SUM(_xlfn.XLOOKUP($S8:$AL8,增益!$A:$A,增益!$M:$M,0))>0,($F$13-$I$4+VLOOKUP($R8,武学奇术!$A:$ZZ,13,FALSE)+SUM(_xlfn.XLOOKUP($S8:$AL8,增益!$A:$A,增益!$K:$K,0)))/200,($F$13-$I$4+VLOOKUP($R8,武学奇术!$A:$ZZ,13,FALSE)+SUM(_xlfn.XLOOKUP($S8:$AL8,增益!$A:$A,增益!$M:$M,0)))/100)} -> -0.24 | BJ8: {=$G$13+VLOOKUP($R8,武学奇术!$A:$ZZ,14,FALSE)+SUM(_xlfn.XLOOKUP($S8:$AL8,增益!$A:$A,增益!$N:$N,0))} -> 0 | BK8: =$D$14*(1+$AX8) -> 605.472 | BL8: =$E$14*(1+$AX8) -> 1725.468 | BM8: {=IF($F$14-$I$4+VLOOKUP($R8,武学奇术!$A:$ZZ,15,FALSE)+SUM(_xlfn.XLOOKUP($S8:$AL8,增益!$A:$A,增益!$O:$O,0))>0,($F$14-$I$4+VLOOKUP($R8,武学奇术!$A:$ZZ,15,FALSE)+SUM(_xlfn.XLOOKUP($S8:$AL8,增益!$A:$A,增益!$O:$O,0)))/200,($F$14-$I$4+VLOOKUP($R8,武学奇术!$A:$ZZ,15,FALSE)+SUM(_xlfn.XLOOKUP($S8:$AL8,增益!$A:$A,增益!$O:$O,0)))/100)} -> 0.03 | BN8: {=$G$14+VLOOKUP($R8,武学奇术!$A:$ZZ,16,FALSE)+SUM(_xlfn.XLOOKUP($S8:$AL8,增益!$A:$A,增益!$P:$P,0))} -> 0.24 | BO8: =MIN(IF(VLOOKUP($R8,武学奇术!$A:$ZZ,23,FALSE)=1,100%,$B$8),100%) -> 1 | BP8: {=IF(VLOOKUP($R8,武学奇术!$A:$ZZ,23,FALSE)=1,100%,MIN(80%,$B$9+VLOOKUP($R8,武学奇术!$A:$ZZ,17,FALSE)+SUM(_xlfn.XLOOKUP($S8:$AL8,增益!$A:$A,增益!$Q:$Q,0)))+$B$11+SUM(_xlfn.XLOOKUP($S8:$AL8,增益!$A:$A,增益!$U:$U,0)))*IF(VLOOKUP($R8,武学奇术!$A:$ZZ,24,FALSE)=1,0,1)+MIN(IF(VLOOKUP($R8,武学奇术!$A:$ZZ,32,FALSE)=1,IF(VLOOKUP($R8,武学奇术!$A:$ZZ,24,FALSE)=1,100%,MIN(40%,$B$10+VLOOKUP($R8,武学奇术!$A:$ZZ,19,FALSE)+SUM(_xlfn.XLOOKUP($S8:$AL8,增益!$A:$A,增益!$S:$S,0)))+$B$12+SUM(_xlfn.XLOOKUP($S8:$AL8,增益!$A:$A,增益!$V:$V,0))),0),12%)} -> 0.9036 | BQ8: {=1+$B$13+VLOOKUP($R8,武学奇术!$A:$ZZ,18,FALSE)+SUM(_xlfn.XLOOKUP($S8:$AL8,增益!$A:$A,增益!$R:$R,0))} -> 1.85 | BR8: {=MAX(IF(VLOOKUP($R8,武学奇术!$A:$ZZ,24,FALSE)=1,100%,MIN(40%,$B$10+VLOOKUP($R8,武学奇术!$A:$ZZ,19,FALSE)+SUM(_xlfn.XLOOKUP($S8:$AL8,增益!$A:$A,增益!$S:$S,0)))+$B$12+SUM(_xlfn.XLOOKUP($S8:$AL8,增益!$A:$A,增益!$V:$V,0)))*IF(VLOOKUP($R8,武学奇术!$A:$ZZ,23,FALSE)=1,0,1)-IF(VLOOKUP($R8,武学奇术!$A:$ZZ,32,FALSE)=1,12%,0),0)} -> 0.0929 | BS8: {=1+$B$14+VLOOKUP($R8,武学奇术!$A:$ZZ,20,FALSE)+SUM(_xlfn.XLOOKUP($S8:$AL8,增益!$A:$A,增益!$T:$T,0))} -> 1.35 | BT8: =MIN((1-BR8)*BO8,BO8*BP8) -> 0.9036 | BU8: =1-BR8-BT8-BV8 -> 0.0035 | BV8: =IF(VLOOKUP($R8,武学奇术!$A:$ZZ,22,FALSE)=1,0,(1-$BO8))*(1-$BR8) -> 0 | BW8: {=SUM(_xlfn.XLOOKUP($S8:$AL8,增益!$A:$A,增益!$W:$W,0))+$I$5} -> 0.11 | BX8: {=SUM(_xlfn.XLOOKUP($S8:$AL8,增益!$A:$A,增益!$X:$X,0))} -> 0
