Workbook

Sheet 期望
B1: 最小攻击 | C1: 最大攻击 | D1: 穿透 | E1: 伤害加成 | F1: 武学属性 | G1: 裂石 | H1: 怪物属性 | K1: 期望 | L1: 会心期望 | M1: 会意期望 | N1: 普通期望 | O1: 擦伤期望 | P1: 次数 | Q1: 技能 | R1: 增益1 | S1: 增益2 | T1: 增益3 | U1: 增益4 | V1: 增益5 | W1: 增益6 | X1: 增益7 | Y1: 增益8 | Z1: 增益9 | AA1: 增益10 | AB1: 增益11 | AC1: 增益12 | AD1: 增益13 | AE1: 增益14 | AF1: 增益15 | AG1: 增益16 | AH1: 增益17 | AI1: 增益18 | AJ1: 增益19 | AK1: 增益20 | AL1: 类型 | AM1: 外功倍率 | AN1: 外攻固伤 | AO1: 属性倍率 | AP1: 属性固伤 | AQ1: 通用增伤 | AR1: 外攻加成 | AS1: 即时小外 | AT1: 即时大外 | AU1: 外穿加成 | AV1: 外伤加成 | AW1: 属攻加成 | AX1: 即时小鸣 | AY1: 即时大鸣 | AZ1: 鸣金穿透 | BA1: 鸣金加成 | BB1: 即时小裂 | BC1: 即时大裂 | BD1: 裂石穿透 | BE1: 裂石加成 | BF1: 即时小牵 | BG1: 即时大牵 | BH1: 牵丝穿透 | BI1: 牵丝加成 | BJ1: 即时小破 | BK1: 即时大破 | BL1: 破竹穿透 | BM1: 破竹加成 | BN1: 生效精准 | BO1: 生效会心 | BP1: 生效会心伤害 | BQ1: 生效会意 | BR1: 生效会意伤害 | BS1: 会心占比 | BT1: 普攻占比 | BU1: 擦伤占比 | BV1: 特殊增伤
A2: 外功 | B2: 4006.7 | C2: 3083.9 | D2: =58.4+IF($E$22="征人归",5.1,0) -> 58.4 | F2: 套装 | G2: 断岳 | H2: 防御 | I2: =620*(1-IF(F17="√",0.06,0)-IF(D20="√",0.04,0)) -> 558 | K2: =($L2*$BS2+$M2*$BQ2+$N2*$BT2+$O2*$BU2) -> 24783.517 | L2: =((($AS2+$AT2)/2*$AM2+$AN2)*(1+$AU2)*(1+$AV2)+(($AX2+$AY2)/2*IF($G$1="鸣金",$AO2,$AM2)+IF($G$1="鸣金",$AP2*1.5,0))*(1+$AZ2)*(1+$BA2)+(($BB2+$BC2)/2*IF($G$1="裂石",$AO2,$AM2)+IF($G$1="裂石",$AP2*1.5,0))*(1+$BD2)*(1+$BE2)+(($BF2+$BG2)/2*IF($G$1="牵丝",$AO2,$AM2)+IF($G$1="牵丝",$AP2*1.5,0))*(1+$BH2)*(1+$BI2)+(($BJ2+$BK2)/2*IF($G$1="破竹",$AO2,$AM2)+IF($G$1="破竹",$AP2*1.5,0))*(1+$BL2)*(1+$BM2))*(1+$AQ2)*$BP2*$P2*(1+IF(VLOOKUP($Q2,武学奇术!$A:$ZZ,30,FALSE)="蓄力技",$B$21,0))*(1+$BV2) -> 25100.013 | M2: =(($AT2*$AM2+$AN2)*(1+$AU2)*(1+$AV2)+($AY2*IF($G$1="鸣金",$AO2,$AM2)+IF($G$1="鸣金",$AP2*1.5,0))*(1+$AZ2)*(1+$BA2)+($BC2*IF($G$1="裂石",$AO2,$AM2)+IF($G$1="裂石",$AP2*1.5,0))*(1+$BD2)*(1+$BE2)+($BG2*IF($G$1="牵丝",$AO2,$AM2)+IF($G$1="牵丝",$AP2*1.5,0))*(1+$BH2)*(1+$BI2)+($BK2*IF($G$1="破竹",$AO2,$AM2)+IF($G$1="破竹",$AP2*1.5,0))*(1+$BL2)*(1+$BM2))*(1+$AQ2)*$BR2*$P2*(1+IF(VLOOKUP($Q2,武学奇术!$A:$ZZ,30,FALSE)="蓄力技",$B$21,0))*(1+$BV2) -> 24713.06 | N2: =((($AS2+$AT2)/2*$AM2+$AN2)*(1+$AU2)*(1+$AV2)+(($AX2+$AY2)/2*IF($G$1="鸣金",$AO2,$AM2)+IF($G$1="鸣金",$AP2*1.5,0))*(1+$AZ2)*(1+$BA2)+(($BB2+$BC2)/2*IF($G$1="裂石",$AO2,$AM2)+IF($G$1="裂石",$AP2*1.5,0))*(1+$BD2)*(1+$BE2)+(($BF2+$BG2)/2*IF($G$1="牵丝",$AO2,$AM2)+IF($G$1="牵丝",$AP2*1.5,0))*(1+$BH2)*(1+$BI2)+(($BJ2+$BK2)/2*IF($G$1="破竹",$AO2,$AM2)+IF($G$1="破竹",$AP2*1.5,0))*(1+$BL2)*(1+$BM2))*(1+$AQ2)*$P2*(1+IF(VLOOKUP($Q2,武学奇术!$A:$ZZ,30,FALSE)="蓄力技",$B$21,0))*(1+$BV2) -> 16193.557 | O2: =((($AS2*$AM2+$AN2)*(1+$AU2)*(1+$AV2)+($AX2*IF($G$1="鸣金",$AO2,$AM2)+IF($G$1="鸣金",$AP2*1.5,0))*(1+$AZ2)*(1+$BA2)+($BB2*IF($G$1="裂石",$AO2,$AM2)+IF($G$1="裂石",$AP2*1.5,0))*(1+$BD2)*(1+$BE2)+($BF2*IF($G$1="牵丝",$AO2,$AM2)+IF($G$1="牵丝",$AP2*1.5,0))*(1+$BH2)*(1+$BI2)+($BJ2*IF($G$1="破竹",$AO2,$AM2)+IF($G$1="破竹",$AP2*1.5,0))*(1+$BL2)*(1+$BM2))*(1+$AQ2))*$P2*(1+IF(VLOOKUP($Q2,武学奇术!$A:$ZZ,30,FALSE)="蓄力技",$B$21,0))*(1+$BV2) -> 14081.143 | P2: 1 | Q2: 萧呤千浪流星 | R2: 易水歌1层 | S2: N/a | T2: N/a | U2: N/a | V2: N/a | W2: 近战笛 | X2: 沧海帖1层 | Y2: N/a | Z2: N/a | AA2: N/a | AB2: N/a | AC2: N/a | AD2: 裁云(拐) | AE2: 无惧 | AF2: 铁衣 | AG2: N/a | AH2: N/a | AI2: N/a | AJ2: N/a | AK2: N/a | AL2: =VLOOKUP($Q2,武学奇术!$A:$ZZ,25,FALSE) -> 群体奇术 | AM2: =VLOOKUP($Q2,武学奇术!$A:$ZZ,26,FALSE) -> 1.4904 | AN2: =VLOOKUP($Q2,武学奇术!$A:$ZZ,27,FALSE)*(1+IF(OR($AL2=$F$4,$AL2=$F$5),$B$22,0)) -> 378 | AO2: =VLOOKUP($Q2,武学奇术!$A:$ZZ,28,FALSE) -> 2.2356 | AP2: =VLOOKUP($Q2,武学奇术!$A:$ZZ,29,FALSE)*(1+IF(OR($AL2=$F$4,$AL2=$F$5),$B$22,0)) -> 0 | AQ2: {=$G$3+IFERROR(VLOOKUP($AL2,$F$4:$G$7,2,FALSE),0)+VLOOKUP($Q2,武学奇术!$A:$ZZ,2,FALSE)+SUM(_xlfn.XLOOKUP($R2:$AK2,增益!$A:$A,增益!$B:$B,0))} -> 0.3437 | AR2: {=VLOOKUP($Q2,武学奇术!$A:$ZZ,5,FALSE)+SUM(_xlfn.XLOOKUP($R2:$AK2,增益!$A:$A,增益!$E:$E,0))} -> 0 | AS2: {=$D$10*(1+$AR2)+VLOOKUP($Q2,武学奇术!$A:$ZZ,3,FALSE)+SUM(_xlfn.XLOOKUP($R2:$AK2,增益!$A:$A,增益!$C:$C,0))-$I$2} -> 3648.7 | AT2: {=$E$10*(1+$AR2)+VLOOKUP($Q2,武学奇术!$A:$ZZ,4,FALSE)+SUM(_xlfn.XLOOKUP($R2:$AK2,增益!$A:$A,增益!$D:$D,0))-$I$2} -> 3648.7 | AU2: {=IF($F$10-$I$3+VLOOKUP($Q2,武学奇术!$A:$ZZ,6,FALSE)+SUM(_xlfn.XLOOKUP($R2:$AK2,增益!$A:$A,增益!$F:$F,0))>0,($F$10-$I$3+VLOOKUP($Q2,武学奇术!$A:$ZZ,6,FALSE)+SUM(_xlfn.XLOOKUP($R2:$AK2,增益!$A:$A,增益!$F:$F,0)))/200,($F$10-$I$3+VLOOKUP($Q2,武学奇术!$A:$ZZ,6,FALSE)+SUM(_xlfn.XLOOKUP($R2:$AK2,增益!$A:$A,增益!$F:$F,0)))/100)} -> 0.337 | AV2: {=$G$10+VLOOKUP($Q2,武学奇术!$A:$ZZ,7,FALSE)+SUM(_xlfn.XLOOKUP($R2:$AK2,增益!$A:$A,增益!$G:$G,0))} -> 0 | AW2: {=VLOOKUP($Q2,武学奇术!$A:$ZZ,8,FALSE)+SUM(_xlfn.XLOOKUP($R2:$AK2,增益!$A:$A,增益!$H:$H,0))} -> 0 | AX2: =$D$11*(1+$AW2) -> 0 | AY2: =$E$11*(1+$AW2) -> 0 | AZ2: {=IF($F$11-$I$4+VLOOKUP($Q2,武学奇术!$A:$ZZ,9,FALSE)+SUM(_xlfn.XLOOKUP($R2:$AK2,增益!$A:$A,增益!$I:$I,0))>0,($F$11-$I$4+VLOOKUP($Q2,武学奇术!$A:$ZZ,9,FALSE)+SUM(_xlfn.XLOOKUP($R2:$AK2,增益!$A:$A,增益!$I:$I,0)))/200,($F$11-$I$4+VLOOKUP($Q2,武学奇术!$A:$ZZ,9,FALSE)+SUM(_xlfn.XLOOKUP($R2:$AK2,增益!$A:$A,增益!$I:$I,0)))/100)} -> -0.3 | BA2: {=$G$11+VLOOKUP($Q2,武学奇术!$A:$ZZ,10,FALSE)+SUM(_xlfn.XLOOKUP($R2:$AK2,增益!$A:$A,增益!$J:$J,0))} -> 0 | BB2: =$D$12*(1+$AW2) -> 594.1 | BC2: =$E$12*(1+$AW2) -> 1604.9 | BD2: {=IF($F$12-$I$4+VLOOKUP($Q2,武学奇术!$A:$ZZ,11,FALSE)+SUM(_xlfn.XLOOKUP($R2:$AK2,增益!$A:$A,增益!$K:$K,0))>0,($F$12-$I$4+VLOOKUP($Q2,武学奇术!$A:$ZZ,11,FALSE)+SUM(_xlfn.XLOOKUP($R2:$AK2,增益!$A:$A,增益!$K:$K,0)))/200,($F$12-$I$4+VLOOKUP($Q2,武学奇术!$A:$ZZ,11,FALSE)+SUM(_xlfn.XLOOKUP($R2:$AK2,增益!$A:$A,增益!$K:$K,0)))/100)} -> 0.09 | BE2: {=$G$12+VLOOKUP($Q2,武学奇术!$A:$ZZ,12,FALSE)+SUM(_xlfn.XLOOKUP($R2:$AK2,增益!$A:$A,增益!$L:$L,0))} -> 0.15 | BF2: =$D$13*(1+$AW2) -> 0 | BG2: =$E$13*(1+$AW2) -> 0 | BH2: {=IF($F$13-$I$4+VLOOKUP($Q2,武学奇术!$A:$ZZ,13,FALSE)+SUM(_xlfn.XLOOKUP($R2:$AK2,增益!$A:$A,增益!$M:$M,0))>0,($F$13-$I$4+VLOOKUP($Q2,武学奇术!$A:$ZZ,13,FALSE)+SUM(_xlfn.XLOOKUP($R2:$AK2,增益!$A:$A,增益!$K:$K,0)))/200,($F$13-$I$4+VLOOKUP($Q2,武学奇术!$A:$ZZ,13,FALSE)+SUM(_xlfn.XLOOKUP($R2:$AK2,增益!$A:$A,增益!$M:$M,0)))/100)} -> -0.3 | BI2: {=$G$13+VLOOKUP($Q2,武学奇术!$A:$ZZ,14,FALSE)+SUM(_xlfn.XLOOKUP($R2:$AK2,增益!$A:$A,增益!$N:$N,0))} -> 0 | BJ2: =$D$14*(1+$AW2) -> 0 | BK2: =$E$14*(1+$AW2) -> 0 | BL2: {=IF($F$14-$I$4+VLOOKUP($Q2,武学奇术!$A:$ZZ,15,FALSE)+SUM(_xlfn.XLOOKUP($R2:$AK2,增益!$A:$A,增益!$O:$O,0))>0,($F$14-$I$4+VLOOKUP($Q2,武学奇术!$A:$ZZ,15,FALSE)+SUM(_xlfn.XLOOKUP($R2:$AK2,增益!$A:$A,增益!$O:$O,0)))/200,($F$14-$I$4+VLOOKUP($Q2,武学奇术!$A:$ZZ,15,FALSE)+SUM(_xlfn.XLOOKUP($R2:$AK2,增益!$A:$A,增益!$O:$O,0)))/100)} -> -0.3 | BM2: {=$G$14+VLOOKUP($Q2,武学奇术!$A:$ZZ,16,FALSE)+SUM(_xlfn.XLOOKUP($R2:$AK2,增益!$A:$A,增益!$P:$P,0))} -> 0 | BN2: =MIN(IF(VLOOKUP($Q2,武学奇术!$A:$ZZ,23,FALSE)=1,100%,$B$8),100%) -> 0.9859 | BO2: {=IF(VLOOKUP($Q2,武学奇术!$A:$ZZ,23,FALSE)=1,100%,MIN(80%,$B$9+VLOOKUP($Q2,武学奇术!$A:$ZZ,17,FALSE)+SUM(_xlfn.XLOOKUP($R2:$AK2,增益!$A:$A,增益!$Q:$Q,0)))+$B$11+SUM(_xlfn.XLOOKUP($R2:$AK2,增益!$A:$A,增益!$U:$U,0)))*IF(VLOOKUP($Q2,武学奇术!$A:$ZZ,24,FALSE)=1,0,1)} -> 0.8912 | BP2: {=1+$B$13+VLOOKUP($Q2,武学奇术!$A:$ZZ,18,FALSE)+SUM(_xlfn.XLOOKUP($R2:$AK2,增益!$A:$A,增益!$R:$R,0))} -> 1.55 | BQ2: {=IF(VLOOKUP($Q2,武学奇术!$A:$ZZ,24,FALSE)=1,100%,MIN(40%,$B$10+VLOOKUP($Q2,武学奇术!$A:$ZZ,19,FALSE)+SUM(_xlfn.XLOOKUP($R2:$AK2,增益!$A:$A,增益!$S:$S,0)))+$B$12+SUM(_xlfn.XLOOKUP($R2:$AK2,增益!$A:$A,增益!$V:$V,0)))*IF(VLOOKUP($Q2,武学奇术!$A:$ZZ,23,FALSE)=1,0,1)} -> 0.0929 | BR2: {=1+$B$14+VLOOKUP($Q2,武学奇术!$A:$ZZ,20,FALSE)+SUM(_xlfn.XLOOKUP($R2:$AK2,增益!$A:$A,增益!$T:$T,0))} -> 1.35 | BS2: =MIN((1-BQ2)*BN2,BN2*BO2) -> 0.87863408 | BT2: =1-BQ2-BS2-BU2 -> 0.01567581 | BU2: =IF(VLOOKUP($Q2,武学奇术!$A:$ZZ,22,FALSE)=1,0,(1-$BN2))*(1-$BQ2) -> 0.01279011 | BV2: {=SUM(_xlfn.XLOOKUP($R2:$AK2,增益!$A:$A,增益!$W:$W,0))+$I$5} -> 0.11
A3: 鸣金 | F3: 通用增伤 | G3: =B16+1.5%+IF(G2="断岳",5%,0)+IF($D$16="√",8%,0)+IF($E$22="征人归",8%,0) -> 0.2337 | H3: 外抗 | I3: =25-IF(D17="√",10,0)-IF(F17="√",10,0) -> 5 | K3: =($L3*$BS3+$M3*$BQ3+$N3*$BT3+$O3*$BU3) -> 29607.775 | L3: =((($AS3+$AT3)/2*$AM3+$AN3)*(1+$AU3)*(1+$AV3)+(($AX3+$AY3)/2*IF($G$1="鸣金",$AO3,$AM3)+IF($G$1="鸣金",$AP3*1.5,0))*(1+$AZ3)*(1+$BA3)+(($BB3+$BC3)/2*IF($G$1="裂石",$AO3,$AM3)+IF($G$1="裂石",$AP3*1.5,0))*(1+$BD3)*(1+$BE3)+(($BF3+$BG3)/2*IF($G$1="牵丝",$AO3,$AM3)+IF($G$1="牵丝",$AP3*1.5,0))*(1+$BH3)*(1+$BI3)+(($BJ3+$BK3)/2*IF($G$1="破竹",$AO3,$AM3)+IF($G$1="破竹",$AP3*1.5,0))*(1+$BL3)*(1+$BM3))*(1+$AQ3)*$BP3*$P3*(1+IF(VLOOKUP($Q3,武学奇术!$A:$ZZ,30,FALSE)="蓄力技",$B$21,0))*(1+$BV3) -> 30201.059 | M3: =(($AT3*$AM3+$AN3)*(1+$AU3)*(1+$AV3)+($AY3*IF($G$1="鸣金",$AO3,$AM3)+IF($G$1="鸣金",$AP3*1.5,0))*(1+$AZ3)*(1+$BA3)+($BC3*IF($G$1="裂石",$AO3,$AM3)+IF($G$1="裂石",$AP3*1.5,0))*(1+$BD3)*(1+$BE3)+($BG3*IF($G$1="牵丝",$AO3,$AM3)+IF($G$1="牵丝",$AP3*1.5,0))*(1+$BH3)*(1+$BI3)+($BK3*IF($G$1="破竹",$AO3,$AM3)+IF($G$1="破竹",$AP3*1.5,0))*(1+$BL3)*(1+$BM3))*(1+$AQ3)*$BR3*$P3*(1+IF(VLOOKUP($Q3,武学奇术!$A:$ZZ,30,FALSE)="蓄力技",$B$21,0))*(1+$BV3) -> 27827.192 | N3: =((($AS3+$AT3)/2*$AM3+$AN3)*(1+$AU3)*(1+$AV3)+(($AX3+$AY3)/2*IF($G$1="鸣金",$AO3,$AM3)+IF($G$1="鸣金",$AP3*1.5,0))*(1+$AZ3)*(1+$BA3)+(($BB3+$BC3)/2*IF($G$1="裂石",$AO3,$AM3)+IF($G$1="裂石",$AP3*1.5,0))*(1+$BD3)*(1+$BE3)+(($BF3+$BG3)/2*IF($G$1="牵丝",$AO3,$AM3)+IF($G$1="牵丝",$AP3*1.5,0))*(1+$BH3)*(1+$BI3)+(($BJ3+$BK3)/2*IF($G$1="破竹",$AO3,$AM3)+IF($G$1="破竹",$AP3*1.5,0))*(1+$BL3)*(1+$BM3))*(1+$AQ3)*$P3*(1+IF(VLOOKUP($Q3,武学奇术!$A:$ZZ,30,FALSE)="蓄力技",$B$21,0))*(1+$BV3) -> 18193.409 | O3: =((($AS3*$AM3+$AN3)*(1+$AU3)*(1+$AV3)+($AX3*IF($G$1="鸣金",$AO3,$AM3)+IF($G$1="鸣金",$AP3*1.5,0))*(1+$AZ3)*(1+$BA3)+($BB3*IF($G$1="裂石",$AO3,$AM3)+IF($G$1="裂石",$AP3*1.5,0))*(1+$BD3)*(1+$BE3)+($BF3*IF($G$1="牵丝",$AO3,$AM3)+IF($G$1="牵丝",$AP3*1.5,0))*(1+$BH3)*(1+$BI3)+($BJ3*IF($G$1="破竹",$AO3,$AM3)+IF($G$1="破竹",$AP3*1.5,0))*(1+$BL3)*(1+$BM3))*(1+$AQ3))*$P3*(1+IF(VLOOKUP($Q3,武学奇术!$A:$ZZ,30,FALSE)="蓄力技",$B$21,0))*(1+$BV3) -> 15774.084 | P3: 1 | Q3: 萧呤千浪流星 | R3: 易水歌2层 | S3: N/a | T3: 惧刃 | U3: 穿喉5(普) | V3: N/a | W3: 近战笛 | X3: 沧海帖2层 | Y3: N/a | Z3: N/a | AA3: N/a | AB3: 扶风(拐) | AC3: N/a | AD3: 裁云(拐) | AE3: 无惧 | AF3: 铁衣 | AG3: N/a | AH3: N/a | AI3: N/a | AJ3: N/a | AK3: 离猎(拐) | AL3: =VLOOKUP($Q3,武学奇术!$A:$ZZ,25,FALSE) -> 群体奇术 | AM3: =VLOOKUP($Q3,武学奇术!$A:$ZZ,26,FALSE) -> 1.4904 | AN3: =VLOOKUP($Q3,武学奇术!$A:$ZZ,27,FALSE)*(1+IF(OR($AL3=$F$4,$AL3=$F$5),$B$22,0)) -> 378 | AO3: =VLOOKUP($Q3,武学奇术!$A:$ZZ,28,FALSE) -> 2.2356 | AP3: =VLOOKUP($Q3,武学奇术!$A:$ZZ,29,FALSE)*(1+IF(OR($AL3=$F$4,$AL3=$F$5),$B$22,0)) -> 0 | AQ3: {=$G$3+IFERROR(VLOOKUP($AL3,$F$4:$G$7,2,FALSE),0)+VLOOKUP($Q3,武学奇术!$A:$ZZ,2,FALSE)+SUM(_xlfn.XLOOKUP($R3:$AK3,增益!$A:$A,增益!$B:$B,0))} -> 0.4337 | AR3: {=VLOOKUP($Q3,武学奇术!$A:$ZZ,5,FALSE)+SUM(_xlfn.XLOOKUP($R3:$AK3,增益!$A:$A,增益!$E:$E,0))} -> 0 | AS3: {=$D$10*(1+$AR3)+VLOOKUP($Q3,武学奇术!$A:$ZZ,3,FALSE)+SUM(_xlfn.XLOOKUP($R3:$AK3,增益!$A:$A,增益!$C:$C,0))-$I$2} -> 3648.7 | AT3: {=$E$10*(1+$AR3)+VLOOKUP($Q3,武学奇术!$A:$ZZ,4,FALSE)+SUM(_xlfn.XLOOKUP($R3:$AK3,增益!$A:$A,增益!$D:$D,0))-$I$2} -> 3648.7 | AU3: {=IF($F$10-$I$3+VLOOKUP($Q3,武学奇术!$A:$ZZ,6,FALSE)+SUM(_xlfn.XLOOKUP($R3:$AK3,增益!$A:$A,增益!$F:$F,0))>0,($F$10-$I$3+VLOOKUP($Q3,武学奇术!$A:$ZZ,6,FALSE)+SUM(_xlfn.XLOOKUP($R3:$AK3,增益!$A:$A,增益!$F:$F,0)))/200,($F$10-$I$3+VLOOKUP($Q3,武学奇术!$A:$ZZ,6,FALSE)+SUM(_xlfn.XLOOKUP($R3:$AK3,增益!$A:$A,增益!$F:$F,0)))/100)} -> 0.397 | AV3: {=$G$10+VLOOKUP($Q3,武学奇术!$A:$ZZ,7,FALSE)+SUM(_xlfn.XLOOKUP($R3:$AK3,增益!$A:$A,增益!$G:$G,0))} -> 0 | AW3: {=VLOOKUP($Q3,武学奇术!$A:$ZZ,8,FALSE)+SUM(_xlfn.XLOOKUP($R3:$AK3,增益!$A:$A,增益!$H:$H,0))} -> 0 | AX3: =$D$11*(1+$AW3) -> 0 | AY3: =$E$11*(1+$AW3) -> 0 | AZ3: {=IF($F$11-$I$4+VLOOKUP($Q3,武学奇术!$A:$ZZ,9,FALSE)+SUM(_xlfn.XLOOKUP($R3:$AK3,增益!$A:$A,增益!$I:$I,0))>0,($F$11-$I$4+VLOOKUP($Q3,武学奇术!$A:$ZZ,9,FALSE)+SUM(_xlfn.XLOOKUP($R3:$AK3,增益!$A:$A,增益!$I:$I,0)))/200,($F$11-$I$4+VLOOKUP($Q3,武学奇术!$A:$ZZ,9,FALSE)+SUM(_xlfn.XLOOKUP($R3:$AK3,增益!$A:$A,增益!$I:$I,0)))/100)} -> -0.14 | BA3: {=$G$11+VLOOKUP($Q3,武学奇术!$A:$ZZ,10,FALSE)+SUM(_xlfn.XLOOKUP($R3:$AK3,增益!$A:$A,增益!$J:$J,0))} -> 0 | BB3: =$D$12*(1+$AW3) -> 594.1 | BC3: =$E$12*(1+$AW3) -> 1604.9 | BD3: {=IF($F$12-$I$4+VLOOKUP($Q3,武学奇术!$A:$ZZ,11,FALSE)+SUM(_xlfn.XLOOKUP($R3:$AK3,增益!$A:$A,增益!$K:$K,0))>0,($F$12-$I$4+VLOOKUP($Q3,武学奇术!$A:$ZZ,11,FALSE)+SUM(_xlfn.XLOOKUP($R3:$AK3,增益!$A:$A,增益!$K:$K,0)))/200,($F$12-$I$4+VLOOKUP($Q3,武学奇术!$A:$ZZ,11,FALSE)+SUM(_xlfn.XLOOKUP($R3:$AK3,增益!$A:$A,增益!$K:$K,0)))/100)} -> 0.17 | BE3: {=$G$12+VLOOKUP($Q3,武学奇术!$A:$ZZ,12,FALSE)+SUM(_xlfn.XLOOKUP($R3:$AK3,增益!$A:$A,增益!$L:$L,0))} -> 0.15 | BF3: =$D$13*(1+$AW3) -> 0 | BG3: =$E$13*(1+$AW3) -> 0 | BH3: {=IF($F$13-$I$4+VLOOKUP($Q3,武学奇术!$A:$ZZ,13,FALSE)+SUM(_xlfn.XLOOKUP($R3:$AK3,增益!$A:$A,增益!$M:$M,0))>0,($F$13-$I$4+VLOOKUP($Q3,武学奇术!$A:$ZZ,13,FALSE)+SUM(_xlfn.XLOOKUP($R3:$AK3,增益!$A:$A,增益!$K:$K,0)))/200,($F$13-$I$4+VLOOKUP($Q3,武学奇术!$A:$ZZ,13,FALSE)+SUM(_xlfn.XLOOKUP($R3:$AK3,增益!$A:$A,增益!$M:$M,0)))/100)} -> -0.14 | BI3: {=$G$13+VLOOKUP($Q3,武学奇术!$A:$ZZ,14,FALSE)+SUM(_xlfn.XLOOKUP($R3:$AK3,增益!$A:$A,增益!$N:$N,0))} -> 0 | BJ3: =$D$14*(1+$AW3) -> 0 | BK3: =$E$14*(1+$AW3) -> 0 | BL3: {=IF($F$14-$I$4+VLOOKUP($Q3,武学奇术!$A:$ZZ,15,FALSE)+SUM(_xlfn.XLOOKUP($R3:$AK3,增益!$A:$A,增益!$O:$O,0))>0,($F$14-$I$4+VLOOKUP($Q3,武学奇术!$A:$ZZ,15,FALSE)+SUM(_xlfn.XLOOKUP($R3:$AK3,增益!$A:$A,增益!$O:$O,0)))/200,($F$14-$I$4+VLOOKUP($Q3,武学奇术!$A:$ZZ,15,FALSE)+SUM(_xlfn.XLOOKUP($R3:$AK3,增益!$A:$A,增益!$O:$O,0)))/100)} -> -0.14 | BM3: {=$G$14+VLOOKUP($Q3,武学奇术!$A:$ZZ,16,FALSE)+SUM(_xlfn.XLOOKUP($R3:$AK3,增益!$A:$A,增益!$P:$P,0))} -> 0 | BN3: =MIN(IF(VLOOKUP($Q3,武学奇术!$A:$ZZ,23,FALSE)=1,100%,$B$8),100%) -> 0.9859 | BO3: {=IF(VLOOKUP($Q3,武学奇术!$A:$ZZ,23,FALSE)=1,100%,MIN(80%,$B$9+VLOOKUP($Q3,武学奇术!$A:$ZZ,17,FALSE)+SUM(_xlfn.XLOOKUP($R3:$AK3,增益!$A:$A,增益!$Q:$Q,0)))+$B$11+SUM(_xlfn.XLOOKUP($R3:$AK3,增益!$A:$A,增益!$U:$U,0)))*IF(VLOOKUP($Q3,武学奇术!$A:$ZZ,24,FALSE)=1,0,1)} -> 0.8912 | BP3: {=1+$B$13+VLOOKUP($Q3,武学奇术!$A:$ZZ,18,FALSE)+SUM(_xlfn.XLOOKUP($R3:$AK3,增益!$A:$A,增益!$R:$R,0))} -> 1.66 | BQ3: {=IF(VLOOKUP($Q3,武学奇术!$A:$ZZ,24,FALSE)=1,100%,MIN(40%,$B$10+VLOOKUP($Q3,武学奇术!$A:$ZZ,19,FALSE)+SUM(_xlfn.XLOOKUP($R3:$AK3,增益!$A:$A,增益!$S:$S,0)))+$B$12+SUM(_xlfn.XLOOKUP($R3:$AK3,增益!$A:$A,增益!$V:$V,0)))*IF(VLOOKUP($Q3,武学奇术!$A:$ZZ,23,FALSE)=1,0,1)} -> 0.0929 | BR3: {=1+$B$14+VLOOKUP($Q3,武学奇术!$A:$ZZ,20,FALSE)+SUM(_xlfn.XLOOKUP($R3:$AK3,增益!$A:$A,增益!$T:$T,0))} -> 1.35 | BS3: =MIN((1-BQ3)*BN3,BN3*BO3) -> 0.87863408 | BT3: =1-BQ3-BS3-BU3 -> 0.01567581 | BU3: =IF(VLOOKUP($Q3,武学奇术!$A:$ZZ,22,FALSE)=1,0,(1-$BN3))*(1-$BQ3) -> 0.01279011 | BV3: {=SUM(_xlfn.XLOOKUP($R3:$AK3,增益!$A:$A,增益!$W:$W,0))+$I$5} -> 0.11
A4: 裂石 | B4: 514.9 | C4: 1374.9 | D4: 36 | E4: 0.15 | F4: 陌刀 | G4: =B15+B17 -> 0.1704 | H4: 属抗 | I4: =30 -> 30 | K4: =($L4*$BS4+$M4*$BQ4+$N4*$BT4+$O4*$BU4) -> 30126.355 | L4: =((($AS4+$AT4)/2*$AM4+$AN4)*(1+$AU4)*(1+$AV4)+(($AX4+$AY4)/2*IF($G$1="鸣金",$AO4,$AM4)+IF($G$1="鸣金",$AP4*1.5,0))*(1+$AZ4)*(1+$BA4)+(($BB4+$BC4)/2*IF($G$1="裂石",$AO4,$AM4)+IF($G$1="裂石",$AP4*1.5,0))*(1+$BD4)*(1+$BE4)+(($BF4+$BG4)/2*IF($G$1="牵丝",$AO4,$AM4)+IF($G$1="牵丝",$AP4*1.5,0))*(1+$BH4)*(1+$BI4)+(($BJ4+$BK4)/2*IF($G$1="破竹",$AO4,$AM4)+IF($G$1="破竹",$AP4*1.5,0))*(1+$BL4)*(1+$BM4))*(1+$AQ4)*$BP4*$P4*(1+IF(VLOOKUP($Q4,武学奇术!$A:$ZZ,30,FALSE)="蓄力技",$B$21,0))*(1+$BV4) -> 30750.561 | M4: =(($AT4*$AM4+$AN4)*(1+$AU4)*(1+$AV4)+($AY4*IF($G$1="鸣金",$AO4,$AM4)+IF($G$1="鸣金",$AP4*1.5,0))*(1+$AZ4)*(1+$BA4)+($BC4*IF($G$1="裂石",$AO4,$AM4)+IF($G$1="裂石",$AP4*1.5,0))*(1+$BD4)*(1+$BE4)+($BG4*IF($G$1="牵丝",$AO4,$AM4)+IF($G$1="牵丝",$AP4*1.5,0))*(1+$BH4)*(1+$BI4)+($BK4*IF($G$1="破竹",$AO4,$AM4)+IF($G$1="破竹",$AP4*1.5,0))*(1+$BL4)*(1+$BM4))*(1+$AQ4)*$BR4*$P4*(1+IF(VLOOKUP($Q4,武学奇术!$A:$ZZ,30,FALSE)="蓄力技",$B$21,0))*(1+$BV4) -> 28147.108 | N4: =((($AS4+$AT4)/2*$AM4+$AN4)*(1+$AU4)*(1+$AV4)+(($AX4+$AY4)/2*IF($G$1="鸣金",$AO4,$AM4)+IF($G$1="鸣金",$AP4*1.5,0))*(1+$AZ4)*(1+$BA4)+(($BB4+$BC4)/2*IF($G$1="裂石",$AO4,$AM4)+IF($G$1="裂石",$AP4*1.5,0))*(1+$BD4)*(1+$BE4)+(($BF4+$BG4)/2*IF($G$1="牵丝",$AO4,$AM4)+IF($G$1="牵丝",$AP4*1.5,0))*(1+$BH4)*(1+$BI4)+(($BJ4+$BK4)/2*IF($G$1="破竹",$AO4,$AM4)+IF($G$1="破竹",$AP4*1.5,0))*(1+$BL4)*(1+$BM4))*(1+$AQ4)*$P4*(1+IF(VLOOKUP($Q4,武学奇术!$A:$ZZ,30,FALSE)="蓄力技",$B$21,0))*(1+$BV4) -> 18413.51 | O4: =((($AS4*$AM4+$AN4)*(1+$AU4)*(1+$AV4)+($AX4*IF($G$1="鸣金",$AO4,$AM4)+IF($G$1="鸣金",$AP4*1.5,0))*(1+$AZ4)*(1+$BA4)+($BB4*IF($G$1="裂石",$AO4,$AM4)+IF($G$1="裂石",$AP4*1.5,0))*(1+$BD4)*(1+$BE4)+($BF4*IF($G$1="牵丝",$AO4,$AM4)+IF($G$1="牵丝",$AP4*1.5,0))*(1+$BH4)*(1+$BI4)+($BJ4*IF($G$1="破竹",$AO4,$AM4)+IF($G$1="破竹",$AP4*1.5,0))*(1+$BL4)*(1+$BM4))*(1+$AQ4))*$P4*(1+IF(VLOOKUP($Q4,武学奇术!$A:$ZZ,30,FALSE)="蓄力技",$B$21,0))*(1+$BV4) -> 15977.309 | P4: 1 | Q4: 萧呤千浪流星 | R4: 易水歌3层 | S4: N/a | T4: 惧刃 | U4: 穿喉5(普) | V4: N/a | W4: 近战笛 | X4: 沧海帖3层 | Y4: N/a | Z4: N/a | AA4: N/a | AB4: 烁鼓(拐) | AC4: N/a | AD4: 裁云(拐) | AE4: 无惧 | AF4: 铁衣 | AG4: N/a | AH4: N/a | AI4: N/a | AJ4: N/a | AK4: 离猎(拐) | AL4: =VLOOKUP($Q4,武学奇术!$A:$ZZ,25,FALSE) -> 群体奇术 | AM4: =VLOOKUP($Q4,武学奇术!$A:$ZZ,26,FALSE) -> 1.4904 | AN4: =VLOOKUP($Q4,武学奇术!$A:$ZZ,27,FALSE)*(1+IF(OR($AL4=$F$4,$AL4=$F$5),$B$22,0)) -> 378 | AO4: =VLOOKUP($Q4,武学奇术!$A:$ZZ,28,FALSE) -> 2.2356 | AP4: =VLOOKUP($Q4,武学奇术!$A:$ZZ,29,FALSE)*(1+IF(OR($AL4=$F$4,$AL4=$F$5),$B$22,0)) -> 0 | AQ4: {=$G$3+IFERROR(VLOOKUP($AL4,$F$4:$G$7,2,FALSE),0)+VLOOKUP($Q4,武学奇术!$A:$ZZ,2,FALSE)+SUM(_xlfn.XLOOKUP($R4:$AK4,增益!$A:$A,增益!$B:$B,0))} -> 0.4437 | AR4: {=VLOOKUP($Q4,武学奇术!$A:$ZZ,5,FALSE)+SUM(_xlfn.XLOOKUP($R4:$AK4,增益!$A:$A,增益!$E:$E,0))} -> 0 | AS4: {=$D$10*(1+$AR4)+VLOOKUP($Q4,武学奇术!$A:$ZZ,3,FALSE)+SUM(_xlfn.XLOOKUP($R4:$AK4,增益!$A:$A,增益!$C:$C,0))-$I$2} -> 3648.7 | AT4: {=$E$10*(1+$AR4)+VLOOKUP($Q4,武学奇术!$A:$ZZ,4,FALSE)+SUM(_xlfn.XLOOKUP($R4:$AK4,增益!$A:$A,增益!$D:$D,0))-$I$2} -> 3648.7 | AU4: {=IF($F$10-$I$3+VLOOKUP($Q4,武学奇术!$A:$ZZ,6,FALSE)+SUM(_xlfn.XLOOKUP($R4:$AK4,增益!$A:$A,增益!$F:$F,0))>0,($F$10-$I$3+VLOOKUP($Q4,武学奇术!$A:$ZZ,6,FALSE)+SUM(_xlfn.XLOOKUP($R4:$AK4,增益!$A:$A,增益!$F:$F,0)))/200,($F$10-$I$3+VLOOKUP($Q4,武学奇术!$A:$ZZ,6,FALSE)+SUM(_xlfn.XLOOKUP($R4:$AK4,增益!$A:$A,增益!$F:$F,0)))/100)} -> 0.407 | AV4: {=$G$10+VLOOKUP($Q4,武学奇术!$A:$ZZ,7,FALSE)+SUM(_xlfn.XLOOKUP($R4:$AK4,增益!$A:$A,增益!$G:$G,0))} -> 0 | AW4: {=VLOOKUP($Q4,武学奇术!$A:$ZZ,8,FALSE)+SUM(_xlfn.XLOOKUP($R4:$AK4,增益!$A:$A,增益!$H:$H,0))} -> 0 | AX4: =$D$11*(1+$AW4) -> 0 | AY4: =$E$11*(1+$AW4) -> 0 | AZ4: {=IF($F$11-$I$4+VLOOKUP($Q4,武学奇术!$A:$ZZ,9,FALSE)+SUM(_xlfn.XLOOKUP($R4:$AK4,增益!$A:$A,增益!$I:$I,0))>0,($F$11-$I$4+VLOOKUP($Q4,武学奇术!$A:$ZZ,9,FALSE)+SUM(_xlfn.XLOOKUP($R4:$AK4,增益!$A:$A,增益!$I:$I,0)))/200,($F$11-$I$4+VLOOKUP($Q4,武学奇术!$A:$ZZ,9,FALSE)+SUM(_xlfn.XLOOKUP($R4:$AK4,增益!$A:$A,增益!$I:$I,0)))/100)} -> -0.14 | BA4: {=$G$11+VLOOKUP($Q4,武学奇术!$A:$ZZ,10,FALSE)+SUM(_xlfn.XLOOKUP($R4:$AK4,增益!$A:$A,增益!$J:$J,0))} -> 0 | BB4: =$D$12*(1+$AW4) -> 594.1 | BC4: =$E$12*(1+$AW4) -> 1604.9 | BD4: {=IF($F$12-$I$4+VLOOKUP($Q4,武学奇术!$A:$ZZ,11,FALSE)+SUM(_xlfn.XLOOKUP($R4:$AK4,增益!$A:$A,增益!$K:$K,0))>0,($F$12-$I$4+VLOOKUP($Q4,武学奇术!$A:$ZZ,11,FALSE)+SUM(_xlfn.XLOOKUP($R4:$AK4,增益!$A:$A,增益!$K:$K,0)))/200,($F$12-$I$4+VLOOKUP($Q4,武学奇术!$A:$ZZ,11,FALSE)+SUM(_xlfn.XLOOKUP($R4:$AK4,增益!$A:$A,增益!$K:$K,0)))/100)} -> 0.17 | BE4: {=$G$12+VLOOKUP($Q4,武学奇术!$A:$ZZ,12,FALSE)+SUM(_xlfn.XLOOKUP($R4:$AK4,增益!$A:$A,增益!$L:$L,0))} -> 0.15 | BF4: =$D$13*(1+$AW4) -> 0 | BG4: =$E$13*(1+$AW4) -> 0 | BH4: {=IF($F$13-$I$4+VLOOKUP($Q4,武学奇术!$A:$ZZ,13,FALSE)+SUM(_xlfn.XLOOKUP($R4:$AK4,增益!$A:$A,增益!$M:$M,0))>0,($F$13-$I$4+VLOOKUP($Q4,武学奇术!$A:$ZZ,13,FALSE)+SUM(_xlfn.XLOOKUP($R4:$AK4,增益!$A:$A,增益!$K:$K,0)))/200,($F$13-$I$4+VLOOKUP($Q4,武学奇术!$A:$ZZ,13,FALSE)+SUM(_xlfn.XLOOKUP($R4:$AK4,增益!$A:$A,增益!$M:$M,0)))/100)} -> -0.14 | BI4: {=$G$13+VLOOKUP($Q4,武学奇术!$A:$ZZ,14,FALSE)+SUM(_xlfn.XLOOKUP($R4:$AK4,增益!$A:$A,增益!$N:$N,0))} -> 0 | BJ4: =$D$14*(1+$AW4) -> 0 | BK4: =$E$14*(1+$AW4) -> 0 | BL4: {=IF($F$14-$I$4+VLOOKUP($Q4,武学奇术!$A:$ZZ,15,FALSE)+SUM(_xlfn.XLOOKUP($R4:$AK4,增益!$A:$A,增益!$O:$O,0))>0,($F$14-$I$4+VLOOKUP($Q4,武学奇术!$A:$ZZ,15,FALSE)+SUM(_xlfn.XLOOKUP($R4:$AK4,增益!$A:$A,增益!$O:$O,0)))/200,($F$14-$I$4+VLOOKUP($Q4,武学奇术!$A:$ZZ,15,FALSE)+SUM(_xlfn.XLOOKUP($R4:$AK4,增益!$A:$A,增益!$O:$O,0)))/100)} -> -0.14 | BM4: {=$G$14+VLOOKUP($Q4,武学奇术!$A:$ZZ,16,FALSE)+SUM(_xlfn.XLOOKUP($R4:$AK4,增益!$A:$A,增益!$P:$P,0))} -> 0 | BN4: =MIN(IF(VLOOKUP($Q4,武学奇术!$A:$ZZ,23,FALSE)=1,100%,$B$8),100%) -> 0.9859 | BO4: {=IF(VLOOKUP($Q4,武学奇术!$A:$ZZ,23,FALSE)=1,100%,MIN(80%,$B$9+VLOOKUP($Q4,武学奇术!$A:$ZZ,17,FALSE)+SUM(_xlfn.XLOOKUP($R4:$AK4,增益!$A:$A,增益!$Q:$Q,0)))+$B$11+SUM(_xlfn.XLOOKUP($R4:$AK4,增益!$A:$A,增益!$U:$U,0)))*IF(VLOOKUP($Q4,武学奇术!$A:$ZZ,24,FALSE)=1,0,1)} -> 0.8912 | BP4: {=1+$B$13+VLOOKUP($Q4,武学奇术!$A:$ZZ,18,FALSE)+SUM(_xlfn.XLOOKUP($R4:$AK4,增益!$A:$A,增益!$R:$R,0))} -> 1.67 | BQ4: {=IF(VLOOKUP($Q4,武学奇术!$A:$ZZ,24,FALSE)=1,100%,MIN(40%,$B$10+VLOOKUP($Q4,武学奇术!$A:$ZZ,19,FALSE)+SUM(_xlfn.XLOOKUP($R4:$AK4,增益!$A:$A,增益!$S:$S,0)))+$B$12+SUM(_xlfn.XLOOKUP($R4:$AK4,增益!$A:$A,增益!$V:$V,0)))*IF(VLOOKUP($Q4,武学奇术!$A:$ZZ,23,FALSE)=1,0,1)} -> 0.0929 | BR4: {=1+$B$14+VLOOKUP($Q4,武学奇术!$A:$ZZ,20,FALSE)+SUM(_xlfn.XLOOKUP($R4:$AK4,增益!$A:$A,增益!$T:$T,0))} -> 1.35 | BS4: =MIN((1-BQ4)*BN4,BN4*BO4) -> 0.87863408 | BT4: =1-BQ4-BS4-BU4 -> 0.01567581 | BU4: =IF(VLOOKUP($Q4,武学奇术!$A:$ZZ,22,FALSE)=1,0,(1-$BN4))*(1-$BQ4) -> 0.01279011 | BV4: {=SUM(_xlfn.XLOOKUP($R4:$AK4,增益!$A:$A,增益!$W:$W,0))+$I$5} -> 0.11
A5: 牵丝 | F5: 横刀 | G5: =B15+B18 -> 0.0852 | H5: 副本天赋 | I5: 0.06 | K5: =($L5*$BS5+$M5*$BQ5+$N5*$BT5+$O5*$BU5) -> 30650.909 | L5: =((($AS5+$AT5)/2*$AM5+$AN5)*(1+$AU5)*(1+$AV5)+(($AX5+$AY5)/2*IF($G$1="鸣金",$AO5,$AM5)+IF($G$1="鸣金",$AP5*1.5,0))*(1+$AZ5)*(1+$BA5)+(($BB5+$BC5)/2*IF($G$1="裂石",$AO5,$AM5)+IF($G$1="裂石",$AP5*1.5,0))*(1+$BD5)*(1+$BE5)+(($BF5+$BG5)/2*IF($G$1="牵丝",$AO5,$AM5)+IF($G$1="牵丝",$AP5*1.5,0))*(1+$BH5)*(1+$BI5)+(($BJ5+$BK5)/2*IF($G$1="破竹",$AO5,$AM5)+IF($G$1="破竹",$AP5*1.5,0))*(1+$BL5)*(1+$BM5))*(1+$AQ5)*$BP5*$P5*(1+IF(VLOOKUP($Q5,武学奇术!$A:$ZZ,30,FALSE)="蓄力技",$B$21,0))*(1+$BV5) -> 31306.634 | M5: =(($AT5*$AM5+$AN5)*(1+$AU5)*(1+$AV5)+($AY5*IF($G$1="鸣金",$AO5,$AM5)+IF($G$1="鸣金",$AP5*1.5,0))*(1+$AZ5)*(1+$BA5)+($BC5*IF($G$1="裂石",$AO5,$AM5)+IF($G$1="裂石",$AP5*1.5,0))*(1+$BD5)*(1+$BE5)+($BG5*IF($G$1="牵丝",$AO5,$AM5)+IF($G$1="牵丝",$AP5*1.5,0))*(1+$BH5)*(1+$BI5)+($BK5*IF($G$1="破竹",$AO5,$AM5)+IF($G$1="破竹",$AP5*1.5,0))*(1+$BL5)*(1+$BM5))*(1+$AQ5)*$BR5*$P5*(1+IF(VLOOKUP($Q5,武学奇术!$A:$ZZ,30,FALSE)="蓄力技",$B$21,0))*(1+$BV5) -> 28468.768 | N5: =((($AS5+$AT5)/2*$AM5+$AN5)*(1+$AU5)*(1+$AV5)+(($AX5+$AY5)/2*IF($G$1="鸣金",$AO5,$AM5)+IF($G$1="鸣金",$AP5*1.5,0))*(1+$AZ5)*(1+$BA5)+(($BB5+$BC5)/2*IF($G$1="裂石",$AO5,$AM5)+IF($G$1="裂石",$AP5*1.5,0))*(1+$BD5)*(1+$BE5)+(($BF5+$BG5)/2*IF($G$1="牵丝",$AO5,$AM5)+IF($G$1="牵丝",$AP5*1.5,0))*(1+$BH5)*(1+$BI5)+(($BJ5+$BK5)/2*IF($G$1="破竹",$AO5,$AM5)+IF($G$1="破竹",$AP5*1.5,0))*(1+$BL5)*(1+$BM5))*(1+$AQ5)*$P5*(1+IF(VLOOKUP($Q5,武学奇术!$A:$ZZ,30,FALSE)="蓄力技",$B$21,0))*(1+$BV5) -> 18634.901 | O5: =((($AS5*$AM5+$AN5)*(1+$AU5)*(1+$AV5)+($AX5*IF($G$1="鸣金",$AO5,$AM5)+IF($G$1="鸣金",$AP5*1.5,0))*(1+$AZ5)*(1+$BA5)+($BB5*IF($G$1="裂石",$AO5,$AM5)+IF($G$1="裂石",$AP5*1.5,0))*(1+$BD5)*(1+$BE5)+($BF5*IF($G$1="牵丝",$AO5,$AM5)+IF($G$1="牵丝",$AP5*1.5,0))*(1+$BH5)*(1+$BI5)+($BJ5*IF($G$1="破竹",$AO5,$AM5)+IF($G$1="破竹",$AP5*1.5,0))*(1+$BL5)*(1+$BM5))*(1+$AQ5))*$P5*(1+IF(VLOOKUP($Q5,武学奇术!$A:$ZZ,30,FALSE)="蓄力技",$B$21,0))*(1+$BV5) -> 16181.826 | P5: 1 | Q5: 萧呤千浪流星 | R5: 易水歌4层 | S5: N/a | T5: 惧刃 | U5: 穿喉5(普) | V5: N/a | W5: 近战笛 | X5: 沧海帖4层 | Y5: N/a | Z5: N/a | AA5: N/a | AB5: 烁鼓(拐) | AC5: N/a | AD5: 裁云(拐) | AE5: 无惧 | AF5: 铁衣 | AG5: N/a | AH5: N/a | AI5: N/a | AJ5: N/a | AK5: 离猎(拐) | AL5: =VLOOKUP($Q5,武学奇术!$A:$ZZ,25,FALSE) -> 群体奇术 | AM5: =VLOOKUP($Q5,武学奇术!$A:$ZZ,26,FALSE) -> 1.4904 | AN5: =VLOOKUP($Q5,武学奇术!$A:$ZZ,27,FALSE)*(1+IF(OR($AL5=$F$4,$AL5=$F$5),$B$22,0)) -> 378 | AO5: =VLOOKUP($Q5,武学奇术!$A:$ZZ,28,FALSE) -> 2.2356 | AP5: =VLOOKUP($Q5,武学奇术!$A:$ZZ,29,FALSE)*(1+IF(OR($AL5=$F$4,$AL5=$F$5),$B$22,0)) -> 0 | AQ5: {=$G$3+IFERROR(VLOOKUP($AL5,$F$4:$G$7,2,FALSE),0)+VLOOKUP($Q5,武学奇术!$A:$ZZ,2,FALSE)+SUM(_xlfn.XLOOKUP($R5:$AK5,增益!$A:$A,增益!$B:$B,0))} -> 0.4537 | AR5: {=VLOOKUP($Q5,武学奇术!$A:$ZZ,5,FALSE)+SUM(_xlfn.XLOOKUP($R5:$AK5,增益!$A:$A,增益!$E:$E,0))} -> 0 | AS5: {=$D$10*(1+$AR5)+VLOOKUP($Q5,武学奇术!$A:$ZZ,3,FALSE)+SUM(_xlfn.XLOOKUP($R5:$AK5,增益!$A:$A,增益!$C:$C,0))-$I$2} -> 3648.7 | AT5: {=$E$10*(1+$AR5)+VLOOKUP($Q5,武学奇术!$A:$ZZ,4,FALSE)+SUM(_xlfn.XLOOKUP($R5:$AK5,增益!$A:$A,增益!$D:$D,0))-$I$2} -> 3648.7 | AU5: {=IF($F$10-$I$3+VLOOKUP($Q5,武学奇术!$A:$ZZ,6,FALSE)+SUM(_xlfn.XLOOKUP($R5:$AK5,增益!$A:$A,增益!$F:$F,0))>0,($F$10-$I$3+VLOOKUP($Q5,武学奇术!$A:$ZZ,6,FALSE)+SUM(_xlfn.XLOOKUP($R5:$AK5,增益!$A:$A,增益!$F:$F,0)))/200,($F$10-$I$3+VLOOKUP($Q5,武学奇术!$A:$ZZ,6,FALSE)+SUM(_xlfn.XLOOKUP($R5:$AK5,增益!$A:$A,增益!$F:$F,0)))/100)} -> 0.417 | AV5: {=$G$10+VLOOKUP($Q5,武学奇术!$A:$ZZ,7,FALSE)+SUM(_xlfn.XLOOKUP($R5:$AK5,增益!$A:$A,增益!$G:$G,0))} -> 0 | AW5: {=VLOOKUP($Q5,武学奇术!$A:$ZZ,8,FALSE)+SUM(_xlfn.XLOOKUP($R5:$AK5,增益!$A:$A,增益!$H:$H,0))} -> 0 | AX5: =$D$11*(1+$AW5) -> 0 | AY5: =$E$11*(1+$AW5) -> 0 | AZ5: {=IF($F$11-$I$4+VLOOKUP($Q5,武学奇术!$A:$ZZ,9,FALSE)+SUM(_xlfn.XLOOKUP($R5:$AK5,增益!$A:$A,增益!$I:$I,0))>0,($F$11-$I$4+VLOOKUP($Q5,武学奇术!$A:$ZZ,9,FALSE)+SUM(_xlfn.XLOOKUP($R5:$AK5,增益!$A:$A,增益!$I:$I,0)))/200,($F$11-$I$4+VLOOKUP($Q5,武学奇术!$A:$ZZ,9,FALSE)+SUM(_xlfn.XLOOKUP($R5:$AK5,增益!$A:$A,增益!$I:$I,0)))/100)} -> -0.14 | BA5: {=$G$11+VLOOKUP($Q5,武学奇术!$A:$ZZ,10,FALSE)+SUM(_xlfn.XLOOKUP($R5:$AK5,增益!$A:$A,增益!$J:$J,0))} -> 0 | BB5: =$D$12*(1+$AW5) -> 594.1 | BC5: =$E$12*(1+$AW5) -> 1604.9 | BD5: {=IF($F$12-$I$4+VLOOKUP($Q5,武学奇术!$A:$ZZ,11,FALSE)+SUM(_xlfn.XLOOKUP($R5:$AK5,增益!$A:$A,增益!$K:$K,0))>0,($F$12-$I$4+VLOOKUP($Q5,武学奇术!$A:$ZZ,11,FALSE)+SUM(_xlfn.XLOOKUP($R5:$AK5,增益!$A:$A,增益!$K:$K,0)))/200,($F$12-$I$4+VLOOKUP($Q5,武学奇术!$A:$ZZ,11,FALSE)+SUM(_xlfn.XLOOKUP($R5:$AK5,增益!$A:$A,增益!$K:$K,0)))/100)} -> 0.17 | BE5: {=$G$12+VLOOKUP($Q5,武学奇术!$A:$ZZ,12,FALSE)+SUM(_xlfn.XLOOKUP($R5:$AK5,增益!$A:$A,增益!$L:$L,0))} -> 0.15 | BF5: =$D$13*(1+$AW5) -> 0 | BG5: =$E$13*(1+$AW5) -> 0 | BH5: {=IF($F$13-$I$4+VLOOKUP($Q5,武学奇术!$A:$ZZ,13,FALSE)+SUM(_xlfn.XLOOKUP($R5:$AK5,增益!$A:$A,增益!$M:$M,0))>0,($F$13-$I$4+VLOOKUP($Q5,武学奇术!$A:$ZZ,13,FALSE)+SUM(_xlfn.XLOOKUP($R5:$AK5,增益!$A:$A,增益!$K:$K,0)))/200,($F$13-$I$4+VLOOKUP($Q5,武学奇术!$A:$ZZ,13,FALSE)+SUM(_xlfn.XLOOKUP($R5:$AK5,增益!$A:$A,增益!$M:$M,0)))/100)} -> -0.14 | BI5: {=$G$13+VLOOKUP($Q5,武学奇术!$A:$ZZ,14,FALSE)+SUM(_xlfn.XLOOKUP($R5:$AK5,增益!$A:$A,增益!$N:$N,0))} -> 0 | BJ5: =$D$14*(1+$AW5) -> 0 | BK5: =$E$14*(1+$AW5) -> 0 | BL5: {=IF($F$14-$I$4+VLOOKUP($Q5,武学奇术!$A:$ZZ,15,FALSE)+SUM(_xlfn.XLOOKUP($R5:$AK5,增益!$A:$A,增益!$O:$O,0))>0,($F$14-$I$4+VLOOKUP($Q5,武学奇术!$A:$ZZ,15,FALSE)+SUM(_xlfn.XLOOKUP($R5:$AK5,增益!$A:$A,增益!$O:$O,0)))/200,($F$14-$I$4+VLOOKUP($Q5,武学奇术!$A:$ZZ,15,FALSE)+SUM(_xlfn.XLOOKUP($R5:$AK5,增益!$A:$A,增益!$O:$O,0)))/100)} -> -0.14 | BM5: {=$G$14+VLOOKUP($Q5,武学奇术!$A:$ZZ,16,FALSE)+SUM(_xlfn.XLOOKUP($R5:$AK5,增益!$A:$A,增益!$P:$P,0))} -> 0 | BN5: =MIN(IF(VLOOKUP($Q5,武学奇术!$A:$ZZ,23,FALSE)=1,100%,$B$8),100%) -> 0.9859 | BO5: {=IF(VLOOKUP($Q5,武学奇术!$A:$ZZ,23,FALSE)=1,100%,MIN(80%,$B$9+VLOOKUP($Q5,武学奇术!$A:$ZZ,17,FALSE)+SUM(_xlfn.XLOOKUP($R5:$AK5,增益!$A:$A,增益!$Q:$Q,0)))+$B$11+SUM(_xlfn.XLOOKUP($R5:$AK5,增益!$A:$A,增益!$U:$U,0)))*IF(VLOOKUP($Q5,武学奇术!$A:$ZZ,24,FALSE)=1,0,1)} -> 0.8912 | BP5: {=1+$B$13+VLOOKUP($Q5,武学奇术!$A:$ZZ,18,FALSE)+SUM(_xlfn.XLOOKUP($R5:$AK5,增益!$A:$A,增益!$R:$R,0))} -> 1.68 | BQ5: {=IF(VLOOKUP($Q5,武学奇术!$A:$ZZ,24,FALSE)=1,100%,MIN(40%,$B$10+VLOOKUP($Q5,武学奇术!$A:$ZZ,19,FALSE)+SUM(_xlfn.XLOOKUP($R5:$AK5,增益!$A:$A,增益!$S:$S,0)))+$B$12+SUM(_xlfn.XLOOKUP($R5:$AK5,增益!$A:$A,增益!$V:$V,0)))*IF(VLOOKUP($Q5,武学奇术!$A:$ZZ,23,FALSE)=1,0,1)} -> 0.0929 | BR5: {=1+$B$14+VLOOKUP($Q5,武学奇术!$A:$ZZ,20,FALSE)+SUM(_xlfn.XLOOKUP($R5:$AK5,增益!$A:$A,增益!$T:$T,0))} -> 1.35 | BS5: =MIN((1-BQ5)*BN5,BN5*BO5) -> 0.87863408 | BT5: =1-BQ5-BS5-BU5 -> 0.01567581 | BU5: =IF(VLOOKUP($Q5,武学奇术!$A:$ZZ,22,FALSE)=1,0,(1-$BN5))*(1-$BQ5) -> 0.01279011 | BV5: {=SUM(_xlfn.XLOOKUP($R5:$AK5,增益!$A:$A,增益!$W:$W,0))+$I$5} -> 0.11
A6: 破竹 | F6: 单体奇术 | G6: =B19 -> 0 | K6: =($L6*$BS6+$M6*$BQ6+$N6*$BT6+$O6*$BU6) -> 31015.779 | L6: =((($AS6+$AT6)/2*$AM6+$AN6)*(1+$AU6)*(1+$AV6)+(($AX6+$AY6)/2*IF($G$1="鸣金",$AO6,$AM6)+IF($G$1="鸣金",$AP6*1.5,0))*(1+$AZ6)*(1+$BA6)+(($BB6+$BC6)/2*IF($G$1="裂石",$AO6,$AM6)+IF($G$1="裂石",$AP6*1.5,0))*(1+$BD6)*(1+$BE6)+(($BF6+$BG6)/2*IF($G$1="牵丝",$AO6,$AM6)+IF($G$1="牵丝",$AP6*1.5,0))*(1+$BH6)*(1+$BI6)+(($BJ6+$BK6)/2*IF($G$1="破竹",$AO6,$AM6)+IF($G$1="破竹",$AP6*1.5,0))*(1+$BL6)*(1+$BM6))*(1+$AQ6)*$BP6*$P6*(1+IF(VLOOKUP($Q6,武学奇术!$A:$ZZ,30,FALSE)="蓄力技",$B$21,0))*(1+$BV6) -> 31680.741 | M6: =(($AT6*$AM6+$AN6)*(1+$AU6)*(1+$AV6)+($AY6*IF($G$1="鸣金",$AO6,$AM6)+IF($G$1="鸣金",$AP6*1.5,0))*(1+$AZ6)*(1+$BA6)+($BC6*IF($G$1="裂石",$AO6,$AM6)+IF($G$1="裂石",$AP6*1.5,0))*(1+$BD6)*(1+$BE6)+($BG6*IF($G$1="牵丝",$AO6,$AM6)+IF($G$1="牵丝",$AP6*1.5,0))*(1+$BH6)*(1+$BI6)+($BK6*IF($G$1="破竹",$AO6,$AM6)+IF($G$1="破竹",$AP6*1.5,0))*(1+$BL6)*(1+$BM6))*(1+$AQ6)*$BR6*$P6*(1+IF(VLOOKUP($Q6,武学奇术!$A:$ZZ,30,FALSE)="蓄力技",$B$21,0))*(1+$BV6) -> 28792.17 | N6: =((($AS6+$AT6)/2*$AM6+$AN6)*(1+$AU6)*(1+$AV6)+(($AX6+$AY6)/2*IF($G$1="鸣金",$AO6,$AM6)+IF($G$1="鸣金",$AP6*1.5,0))*(1+$AZ6)*(1+$BA6)+(($BB6+$BC6)/2*IF($G$1="裂石",$AO6,$AM6)+IF($G$1="裂石",$AP6*1.5,0))*(1+$BD6)*(1+$BE6)+(($BF6+$BG6)/2*IF($G$1="牵丝",$AO6,$AM6)+IF($G$1="牵丝",$AP6*1.5,0))*(1+$BH6)*(1+$BI6)+(($BJ6+$BK6)/2*IF($G$1="破竹",$AO6,$AM6)+IF($G$1="破竹",$AP6*1.5,0))*(1+$BL6)*(1+$BM6))*(1+$AQ6)*$P6*(1+IF(VLOOKUP($Q6,武学奇术!$A:$ZZ,30,FALSE)="蓄力技",$B$21,0))*(1+$BV6) -> 18857.584 | O6: =((($AS6*$AM6+$AN6)*(1+$AU6)*(1+$AV6)+($AX6*IF($G$1="鸣金",$AO6,$AM6)+IF($G$1="鸣金",$AP6*1.5,0))*(1+$AZ6)*(1+$BA6)+($BB6*IF($G$1="裂石",$AO6,$AM6)+IF($G$1="裂石",$AP6*1.5,0))*(1+$BD6)*(1+$BE6)+($BF6*IF($G$1="牵丝",$AO6,$AM6)+IF($G$1="牵丝",$AP6*1.5,0))*(1+$BH6)*(1+$BI6)+($BJ6*IF($G$1="破竹",$AO6,$AM6)+IF($G$1="破竹",$AP6*1.5,0))*(1+$BL6)*(1+$BM6))*(1+$AQ6))*$P6*(1+IF(VLOOKUP($Q6,武学奇术!$A:$ZZ,30,FALSE)="蓄力技",$B$21,0))*(1+$BV6) -> 16387.634 | P6: 1 | Q6: 萧呤千浪流星 | R6: 易水歌5层 | S6: N/a | T6: 惧刃 | U6: 穿喉5(普) | V6: N/a | W6: 近战笛 | X6: 沧海帖4层 | Y6: N/a | Z6: N/a | AA6: N/a | AB6: 扶风(拐) | AC6: N/a | AD6: 裁云(拐) | AE6: 无惧 | AF6: 铁衣 | AG6: N/a | AH6: N/a | AI6: N/a | AJ6: N/a | AK6: 离猎(拐) | AL6: =VLOOKUP($Q6,武学奇术!$A:$ZZ,25,FALSE) -> 群体奇术 | AM6: =VLOOKUP($Q6,武学奇术!$A:$ZZ,26,FALSE) -> 1.4904 | AN6: =VLOOKUP($Q6,武学奇术!$A:$ZZ,27,FALSE)*(1+IF(OR($AL6=$F$4,$AL6=$F$5),$B$22,0)) -> 378 | AO6: =VLOOKUP($Q6,武学奇术!$A:$ZZ,28,FALSE) -> 2.2356 | AP6: =VLOOKUP($Q6,武学奇术!$A:$ZZ,29,FALSE)*(1+IF(OR($AL6=$F$4,$AL6=$F$5),$B$22,0)) -> 0 | AQ6: {=$G$3+IFERROR(VLOOKUP($AL6,$F$4:$G$7,2,FALSE),0)+VLOOKUP($Q6,武学奇术!$A:$ZZ,2,FALSE)+SUM(_xlfn.XLOOKUP($R6:$AK6,增益!$A:$A,增益!$B:$B,0))} -> 0.4637 | AR6: {=VLOOKUP($Q6,武学奇术!$A:$ZZ,5,FALSE)+SUM(_xlfn.XLOOKUP($R6:$AK6,增益!$A:$A,增益!$E:$E,0))} -> 0 | AS6: {=$D$10*(1+$AR6)+VLOOKUP($Q6,武学奇术!$A:$ZZ,3,FALSE)+SUM(_xlfn.XLOOKUP($R6:$AK6,增益!$A:$A,增益!$C:$C,0))-$I$2} -> 3648.7 | AT6: {=$E$10*(1+$AR6)+VLOOKUP($Q6,武学奇术!$A:$ZZ,4,FALSE)+SUM(_xlfn.XLOOKUP($R6:$AK6,增益!$A:$A,增益!$D:$D,0))-$I$2} -> 3648.7 | AU6: {=IF($F$10-$I$3+VLOOKUP($Q6,武学奇术!$A:$ZZ,6,FALSE)+SUM(_xlfn.XLOOKUP($R6:$AK6,增益!$A:$A,增益!$F:$F,0))>0,($F$10-$I$3+VLOOKUP($Q6,武学奇术!$A:$ZZ,6,FALSE)+SUM(_xlfn.XLOOKUP($R6:$AK6,增益!$A:$A,增益!$F:$F,0)))/200,($F$10-$I$3+VLOOKUP($Q6,武学奇术!$A:$ZZ,6,FALSE)+SUM(_xlfn.XLOOKUP($R6:$AK6,增益!$A:$A,增益!$F:$F,0)))/100)} -> 0.427 | AV6: {=$G$10+VLOOKUP($Q6,武学奇术!$A:$ZZ,7,FALSE)+SUM(_xlfn.XLOOKUP($R6:$AK6,增益!$A:$A,增益!$G:$G,0))} -> 0 | AW6: {=VLOOKUP($Q6,武学奇术!$A:$ZZ,8,FALSE)+SUM(_xlfn.XLOOKUP($R6:$AK6,增益!$A:$A,增益!$H:$H,0))} -> 0 | AX6: =$D$11*(1+$AW6) -> 0 | AY6: =$E$11*(1+$AW6) -> 0 | AZ6: {=IF($F$11-$I$4+VLOOKUP($Q6,武学奇术!$A:$ZZ,9,FALSE)+SUM(_xlfn.XLOOKUP($R6:$AK6,增益!$A:$A,增益!$I:$I,0))>0,($F$11-$I$4+VLOOKUP($Q6,武学奇术!$A:$ZZ,9,FALSE)+SUM(_xlfn.XLOOKUP($R6:$AK6,增益!$A:$A,增益!$I:$I,0)))/200,($F$11-$I$4+VLOOKUP($Q6,武学奇术!$A:$ZZ,9,FALSE)+SUM(_xlfn.XLOOKUP($R6:$AK6,增益!$A:$A,增益!$I:$I,0)))/100)} -> -0.14 | BA6: {=$G$11+VLOOKUP($Q6,武学奇术!$A:$ZZ,10,FALSE)+SUM(_xlfn.XLOOKUP($R6:$AK6,增益!$A:$A,增益!$J:$J,0))} -> 0 | BB6: =$D$12*(1+$AW6) -> 594.1 | BC6: =$E$12*(1+$AW6) -> 1604.9 | BD6: {=IF($F$12-$I$4+VLOOKUP($Q6,武学奇术!$A:$ZZ,11,FALSE)+SUM(_xlfn.XLOOKUP($R6:$AK6,增益!$A:$A,增益!$K:$K,0))>0,($F$12-$I$4+VLOOKUP($Q6,武学奇术!$A:$ZZ,11,FALSE)+SUM(_xlfn.XLOOKUP($R6:$AK6,增益!$A:$A,增益!$K:$K,0)))/200,($F$12-$I$4+VLOOKUP($Q6,武学奇术!$A:$ZZ,11,FALSE)+SUM(_xlfn.XLOOKUP($R6:$AK6,增益!$A:$A,增益!$K:$K,0)))/100)} -> 0.17 | BE6: {=$G$12+VLOOKUP($Q6,武学奇术!$A:$ZZ,12,FALSE)+SUM(_xlfn.XLOOKUP($R6:$AK6,增益!$A:$A,增益!$L:$L,0))} -> 0.15 | BF6: =$D$13*(1+$AW6) -> 0 | BG6: =$E$13*(1+$AW6) -> 0 | BH6: {=IF($F$13-$I$4+VLOOKUP($Q6,武学奇术!$A:$ZZ,13,FALSE)+SUM(_xlfn.XLOOKUP($R6:$AK6,增益!$A:$A,增益!$M:$M,0))>0,($F$13-$I$4+VLOOKUP($Q6,武学奇术!$A:$ZZ,13,FALSE)+SUM(_xlfn.XLOOKUP($R6:$AK6,增益!$A:$A,增益!$K:$K,0)))/200,($F$13-$I$4+VLOOKUP($Q6,武学奇术!$A:$ZZ,13,FALSE)+SUM(_xlfn.XLOOKUP($R6:$AK6,增益!$A:$A,增益!$M:$M,0)))/100)} -> -0.14 | BI6: {=$G$13+VLOOKUP($Q6,武学奇术!$A:$ZZ,14,FALSE)+SUM(_xlfn.XLOOKUP($R6:$AK6,增益!$A:$A,增益!$N:$N,0))} -> 0 | BJ6: =$D$14*(1+$AW6) -> 0 | BK6: =$E$14*(1+$AW6) -> 0 | BL6: {=IF($F$14-$I$4+VLOOKUP($Q6,武学奇术!$A:$ZZ,15,FALSE)+SUM(_xlfn.XLOOKUP($R6:$AK6,增益!$A:$A,增益!$O:$O,0))>0,($F$14-$I$4+VLOOKUP($Q6,武学奇术!$A:$ZZ,15,FALSE)+SUM(_xlfn.XLOOKUP($R6:$AK6,增益!$A:$A,增益!$O:$O,0)))/200,($F$14-$I$4+VLOOKUP($Q6,武学奇术!$A:$ZZ,15,FALSE)+SUM(_xlfn.XLOOKUP($R6:$AK6,增益!$A:$A,增益!$O:$O,0)))/100)} -> -0.14 | BM6: {=$G$14+VLOOKUP($Q6,武学奇术!$A:$ZZ,16,FALSE)+SUM(_xlfn.XLOOKUP($R6:$AK6,增益!$A:$A,增益!$P:$P,0))} -> 0 | BN6: =MIN(IF(VLOOKUP($Q6,武学奇术!$A:$ZZ,23,FALSE)=1,100%,$B$8),100%) -> 0.9859 | BO6: {=IF(VLOOKUP($Q6,武学奇术!$A:$ZZ,23,FALSE)=1,100%,MIN(80%,$B$9+VLOOKUP($Q6,武学奇术!$A:$ZZ,17,FALSE)+SUM(_xlfn.XLOOKUP($R6:$AK6,增益!$A:$A,增益!$Q:$Q,0)))+$B$11+SUM(_xlfn.XLOOKUP($R6:$AK6,增益!$A:$A,增益!$U:$U,0)))*IF(VLOOKUP($Q6,武学奇术!$A:$ZZ,24,FALSE)=1,0,1)} -> 0.8912 | BP6: {=1+$B$13+VLOOKUP($Q6,武学奇术!$A:$ZZ,18,FALSE)+SUM(_xlfn.XLOOKUP($R6:$AK6,增益!$A:$A,增益!$R:$R,0))} -> 1.68 | BQ6: {=IF(VLOOKUP($Q6,武学奇术!$A:$ZZ,24,FALSE)=1,100%,MIN(40%,$B$10+VLOOKUP($Q6,武学奇术!$A:$ZZ,19,FALSE)+SUM(_xlfn.XLOOKUP($R6:$AK6,增益!$A:$A,增益!$S:$S,0)))+$B$12+SUM(_xlfn.XLOOKUP($R6:$AK6,增益!$A:$A,增益!$V:$V,0)))*IF(VLOOKUP($Q6,武学奇术!$A:$ZZ,23,FALSE)=1,0,1)} -> 0.0929 | BR6: {=1+$B$14+VLOOKUP($Q6,武学奇术!$A:$ZZ,20,FALSE)+SUM(_xlfn.XLOOKUP($R6:$AK6,增益!$A:$A,增益!$T:$T,0))} -> 1.35 | BS6: =MIN((1-BQ6)*BN6,BN6*BO6) -> 0.87863408 | BT6: =1-BQ6-BS6-BU6 -> 0.01567581 | BU6: =IF(VLOOKUP($Q6,武学奇术!$A:$ZZ,22,FALSE)=1,0,(1-$BN6))*(1-$BQ6) -> 0.01279011 | BV6: {=SUM(_xlfn.XLOOKUP($R6:$AK6,增益!$A:$A,增益!$W:$W,0))+$I$5} -> 0.11
A7: 无相 | B7: 79.2 | C7: =92.4+68.8*2 -> 230 | F7: 群体奇术 | G7: =B20 -> 0 | K7: =($L7*$BS7+$M7*$BQ7+$N7*$BT7+$O7*$BU7) -> 47949.242 | L7: =((($AS7+$AT7)/2*$AM7+$AN7)*(1+$AU7)*(1+$AV7)+(($AX7+$AY7)/2*IF($G$1="鸣金",$AO7,$AM7)+IF($G$1="鸣金",$AP7*1.5,0))*(1+$AZ7)*(1+$BA7)+(($BB7+$BC7)/2*IF($G$1="裂石",$AO7,$AM7)+IF($G$1="裂石",$AP7*1.5,0))*(1+$BD7)*(1+$BE7)+(($BF7+$BG7)/2*IF($G$1="牵丝",$AO7,$AM7)+IF($G$1="牵丝",$AP7*1.5,0))*(1+$BH7)*(1+$BI7)+(($BJ7+$BK7)/2*IF($G$1="破竹",$AO7,$AM7)+IF($G$1="破竹",$AP7*1.5,0))*(1+$BL7)*(1+$BM7))*(1+$AQ7)*$BP7*$P7*(1+IF(VLOOKUP($Q7,武学奇术!$A:$ZZ,30,FALSE)="蓄力技",$B$21,0))*(1+$BV7) -> 49240.439 | M7: =(($AT7*$AM7+$AN7)*(1+$AU7)*(1+$AV7)+($AY7*IF($G$1="鸣金",$AO7,$AM7)+IF($G$1="鸣金",$AP7*1.5,0))*(1+$AZ7)*(1+$BA7)+($BC7*IF($G$1="裂石",$AO7,$AM7)+IF($G$1="裂石",$AP7*1.5,0))*(1+$BD7)*(1+$BE7)+($BG7*IF($G$1="牵丝",$AO7,$AM7)+IF($G$1="牵丝",$AP7*1.5,0))*(1+$BH7)*(1+$BI7)+($BK7*IF($G$1="破竹",$AO7,$AM7)+IF($G$1="破竹",$AP7*1.5,0))*(1+$BL7)*(1+$BM7))*(1+$AQ7)*$BR7*$P7*(1+IF(VLOOKUP($Q7,武学奇术!$A:$ZZ,30,FALSE)="蓄力技",$B$21,0))*(1+$BV7) -> 42321.096 | N7: =((($AS7+$AT7)/2*$AM7+$AN7)*(1+$AU7)*(1+$AV7)+(($AX7+$AY7)/2*IF($G$1="鸣金",$AO7,$AM7)+IF($G$1="鸣金",$AP7*1.5,0))*(1+$AZ7)*(1+$BA7)+(($BB7+$BC7)/2*IF($G$1="裂石",$AO7,$AM7)+IF($G$1="裂石",$AP7*1.5,0))*(1+$BD7)*(1+$BE7)+(($BF7+$BG7)/2*IF($G$1="牵丝",$AO7,$AM7)+IF($G$1="牵丝",$AP7*1.5,0))*(1+$BH7)*(1+$BI7)+(($BJ7+$BK7)/2*IF($G$1="破竹",$AO7,$AM7)+IF($G$1="破竹",$AP7*1.5,0))*(1+$BL7)*(1+$BM7))*(1+$AQ7)*$P7*(1+IF(VLOOKUP($Q7,武学奇术!$A:$ZZ,30,FALSE)="蓄力技",$B$21,0))*(1+$BV7) -> 27977.522 | O7: =((($AS7*$AM7+$AN7)*(1+$AU7)*(1+$AV7)+($AX7*IF($G$1="鸣金",$AO7,$AM7)+IF($G$1="鸣金",$AP7*1.5,0))*(1+$AZ7)*(1+$BA7)+($BB7*IF($G$1="裂石",$AO7,$AM7)+IF($G$1="裂石",$AP7*1.5,0))*(1+$BD7)*(1+$BE7)+($BF7*IF($G$1="牵丝",$AO7,$AM7)+IF($G$1="牵丝",$AP7*1.5,0))*(1+$BH7)*(1+$BI7)+($BJ7*IF($G$1="破竹",$AO7,$AM7)+IF($G$1="破竹",$AP7*1.5,0))*(1+$BL7)*(1+$BM7))*(1+$AQ7))*$P7*(1+IF(VLOOKUP($Q7,武学奇术!$A:$ZZ,30,FALSE)="蓄力技",$B$21,0))*(1+$BV7) -> 24606.084 | P7: 1 | Q7: 白刃杀将刺 | R7: N/a | S7: N/a | T7: N/a | U7: N/a | V7: N/a | W7: 近战笛 | X7: 沧海帖1层 | Y7: N/a | Z7: N/a | AA7: 断岳 | AB7: N/a | AC7: N/a | AD7: 裁云(拐) | AE7: 无惧 | AF7: 铁衣 | AG7: N/a | AH7: N/a | AI7: N/a | AJ7: N/a | AK7: N/a | AL7: =VLOOKUP($Q7,武学奇术!$A:$ZZ,25,FALSE) -> 横刀 | AM7: =VLOOKUP($Q7,武学奇术!$A:$ZZ,26,FALSE) -> 2.1324 | AN7: =VLOOKUP($Q7,武学奇术!$A:$ZZ,27,FALSE)*(1+IF(OR($AL7=$F$4,$AL7=$F$5),$B$22,0)) -> 885 | AO7: =VLOOKUP($Q7,武学奇术!$A:$ZZ,28,FALSE) -> 3.1986 | AP7: =VLOOKUP($Q7,武学奇术!$A:$ZZ,29,FALSE)*(1+IF(OR($AL7=$F$4,$AL7=$F$5),$B$22,0)) -> 483 | AQ7: {=$G$3+IFERROR(VLOOKUP($AL7,$F$4:$G$7,2,FALSE),0)+VLOOKUP($Q7,武学奇术!$A:$ZZ,2,FALSE)+SUM(_xlfn.XLOOKUP($R7:$AK7,增益!$A:$A,增益!$B:$B,0))} -> 0.4989 | AR7: {=VLOOKUP($Q7,武学奇术!$A:$ZZ,5,FALSE)+SUM(_xlfn.XLOOKUP($R7:$AK7,增益!$A:$A,增益!$E:$E,0))} -> 0 | AS7: {=$D$10*(1+$AR7)+VLOOKUP($Q7,武学奇术!$A:$ZZ,3,FALSE)+SUM(_xlfn.XLOOKUP($R7:$AK7,增益!$A:$A,增益!$C:$C,0))-$I$2} -> 3648.7 | AT7: {=$E$10*(1+$AR7)+VLOOKUP($Q7,武学奇术!$A:$ZZ,4,FALSE)+SUM(_xlfn.XLOOKUP($R7:$AK7,增益!$A:$A,增益!$D:$D,0))-$I$2} -> 3648.7 | AU7: {=IF($F$10-$I$3+VLOOKUP($Q7,武学奇术!$A:$ZZ,6,FALSE)+SUM(_xlfn.XLOOKUP($R7:$AK7,增益!$A:$A,增益!$F:$F,0))>0,($F$10-$I$3+VLOOKUP($Q7,武学奇术!$A:$ZZ,6,FALSE)+SUM(_xlfn.XLOOKUP($R7:$AK7,增益!$A:$A,增益!$F:$F,0)))/200,($F$10-$I$3+VLOOKUP($Q7,武学奇术!$A:$ZZ,6,FALSE)+SUM(_xlfn.XLOOKUP($R7:$AK7,增益!$A:$A,增益!$F:$F,0)))/100)} -> 0.327 | AV7: {=$G$10+VLOOKUP($Q7,武学奇术!$A:$ZZ,7,FALSE)+SUM(_xlfn.XLOOKUP($R7:$AK7,增益!$A:$A,增益!$G:$G,0))} -> 0 | AW7: {=VLOOKUP($Q7,武学奇术!$A:$ZZ,8,FALSE)+SUM(_xlfn.XLOOKUP($R7:$AK7,增益!$A:$A,增益!$H:$H,0))} -> 0 | AX7: =$D$11*(1+$AW7) -> 0 | AY7: =$E$11*(1+$AW7) -> 0 | AZ7: {=IF($F$11-$I$4+VLOOKUP($Q7,武学奇术!$A:$ZZ,9,FALSE)+SUM(_xlfn.XLOOKUP($R7:$AK7,增益!$A:$A,增益!$I:$I,0))>0,($F$11-$I$4+VLOOKUP($Q7,武学奇术!$A:$ZZ,9,FALSE)+SUM(_xlfn.XLOOKUP($R7:$AK7,增益!$A:$A,增益!$I:$I,0)))/200,($F$11-$I$4+VLOOKUP($Q7,武学奇术!$A:$ZZ,9,FALSE)+SUM(_xlfn.XLOOKUP($R7:$AK7,增益!$A:$A,增益!$I:$I,0)))/100)} -> -0.3 | BA7: {=$G$11+VLOOKUP($Q7,武学奇术!$A:$ZZ,10,FALSE)+SUM(_xlfn.XLOOKUP($R7:$AK7,增益!$A:$A,增益!$J:$J,0))} -> 0 | BB7: =$D$12*(1+$AW7) -> 594.1 | BC7: =$E$12*(1+$AW7) -> 1604.9 | BD7: {=IF($F$12-$I$4+VLOOKUP($Q7,武学奇术!$A:$ZZ,11,FALSE)+SUM(_xlfn.XLOOKUP($R7:$AK7,增益!$A:$A,增益!$K:$K,0))>0,($F$12-$I$4+VLOOKUP($Q7,武学奇术!$A:$ZZ,11,FALSE)+SUM(_xlfn.XLOOKUP($R7:$AK7,增益!$A:$A,增益!$K:$K,0)))/200,($F$12-$I$4+VLOOKUP($Q7,武学奇术!$A:$ZZ,11,FALSE)+SUM(_xlfn.XLOOKUP($R7:$AK7,增益!$A:$A,增益!$K:$K,0)))/100)} -> 0.09 | BE7: {=$G$12+VLOOKUP($Q7,武学奇术!$A:$ZZ,12,FALSE)+SUM(_xlfn.XLOOKUP($R7:$AK7,增益!$A:$A,增益!$L:$L,0))} -> 0.15 | BF7: =$D$13*(1+$AW7) -> 0 | BG7: =$E$13*(1+$AW7) -> 0 | BH7: {=IF($F$13-$I$4+VLOOKUP($Q7,武学奇术!$A:$ZZ,13,FALSE)+SUM(_xlfn.XLOOKUP($R7:$AK7,增益!$A:$A,增益!$M:$M,0))>0,($F$13-$I$4+VLOOKUP($Q7,武学奇术!$A:$ZZ,13,FALSE)+SUM(_xlfn.XLOOKUP($R7:$AK7,增益!$A:$A,增益!$K:$K,0)))/200,($F$13-$I$4+VLOOKUP($Q7,武学奇术!$A:$ZZ,13,FALSE)+SUM(_xlfn.XLOOKUP($R7:$AK7,增益!$A:$A,增益!$M:$M,0)))/100)} -> -0.3 | BI7: {=$G$13+VLOOKUP($Q7,武学奇术!$A:$ZZ,14,FALSE)+SUM(_xlfn.XLOOKUP($R7:$AK7,增益!$A:$A,增益!$N:$N,0))} -> 0 | BJ7: =$D$14*(1+$AW7) -> 0 | BK7: =$E$14*(1+$AW7) -> 0 | BL7: {=IF($F$14-$I$4+VLOOKUP($Q7,武学奇术!$A:$ZZ,15,FALSE)+SUM(_xlfn.XLOOKUP($R7:$AK7,增益!$A:$A,增益!$O:$O,0))>0,($F$14-$I$4+VLOOKUP($Q7,武学奇术!$A:$ZZ,15,FALSE)+SUM(_xlfn.XLOOKUP($R7:$AK7,增益!$A:$A,增益!$O:$O,0)))/200,($F$14-$I$4+VLOOKUP($Q7,武学奇术!$A:$ZZ,15,FALSE)+SUM(_xlfn.XLOOKUP($R7:$AK7,增益!$A:$A,增益!$O:$O,0)))/100)} -> -0.3 | BM7: {=$G$14+VLOOKUP($Q7,武学奇术!$A:$ZZ,16,FALSE)+SUM(_xlfn.XLOOKUP($R7:$AK7,增益!$A:$A,增益!$P:$P,0))} -> 0 | BN7: =MIN(IF(VLOOKUP($Q7,武学奇术!$A:$ZZ,23,FALSE)=1,100%,$B$8),100%) -> 0.9859 | BO7: {=IF(VLOOKUP($Q7,武学奇术!$A:$ZZ,23,FALSE)=1,100%,MIN(80%,$B$9+VLOOKUP($Q7,武学奇术!$A:$ZZ,17,FALSE)+SUM(_xlfn.XLOOKUP($R7:$AK7,增益!$A:$A,增益!$Q:$Q,0)))+$B$11+SUM(_xlfn.XLOOKUP($R7:$AK7,增益!$A:$A,增益!$U:$U,0)))*IF(VLOOKUP($Q7,武学奇术!$A:$ZZ,24,FALSE)=1,0,1)} -> 0.8912 | BP7: {=1+$B$13+VLOOKUP($Q7,武学奇术!$A:$ZZ,18,FALSE)+SUM(_xlfn.XLOOKUP($R7:$AK7,增益!$A:$A,增益!$R:$R,0))} -> 1.76 | BQ7: {=IF(VLOOKUP($Q7,武学奇术!$A:$ZZ,24,FALSE)=1,100%,MIN(40%,$B$10+VLOOKUP($Q7,武学奇术!$A:$ZZ,19,FALSE)+SUM(_xlfn.XLOOKUP($R7:$AK7,增益!$A:$A,增益!$S:$S,0)))+$B$12+SUM(_xlfn.XLOOKUP($R7:$AK7,增益!$A:$A,增益!$V:$V,0)))*IF(VLOOKUP($Q7,武学奇术!$A:$ZZ,23,FALSE)=1,0,1)} -> 0.0929 | BR7: {=1+$B$14+VLOOKUP($Q7,武学奇术!$A:$ZZ,20,FALSE)+SUM(_xlfn.XLOOKUP($R7:$AK7,增益!$A:$A,增益!$T:$T,0))} -> 1.35 | BS7: =MIN((1-BQ7)*BN7,BN7*BO7) -> 0.87863408 | BT7: =1-BQ7-BS7-BU7 -> 0.01567581 | BU7: =IF(VLOOKUP($Q7,武学奇术!$A:$ZZ,22,FALSE)=1,0,(1-$BN7))*(1-$BQ7) -> 0.01279011 | BV7: {=SUM(_xlfn.XLOOKUP($R7:$AK7,增益!$A:$A,增益!$W:$W,0))+$I$5} -> 0.11
A8: 精准率 | B8: 0.9859 | C8: 实际属性 | H8: 战斗时间 | I8: 101.7 | K8: =($L8*$BS8+$M8*$BQ8+$N8*$BT8+$O8*$BU8) -> 30080.149 | L8: =((($AS8+$AT8)/2*$AM8+$AN8)*(1+$AU8)*(1+$AV8)+(($AX8+$AY8)/2*IF($G$1="鸣金",$AO8,$AM8)+IF($G$1="鸣金",$AP8*1.5,0))*(1+$AZ8)*(1+$BA8)+(($BB8+$BC8)/2*IF($G$1="裂石",$AO8,$AM8)+IF($G$1="裂石",$AP8*1.5,0))*(1+$BD8)*(1+$BE8)+(($BF8+$BG8)/2*IF($G$1="牵丝",$AO8,$AM8)+IF($G$1="牵丝",$AP8*1.5,0))*(1+$BH8)*(1+$BI8)+(($BJ8+$BK8)/2*IF($G$1="破竹",$AO8,$AM8)+IF($G$1="破竹",$AP8*1.5,0))*(1+$BL8)*(1+$BM8))*(1+$AQ8)*$BP8*$P8*(1+IF(VLOOKUP($Q8,武学奇术!$A:$ZZ,30,FALSE)="蓄力技",$B$21,0))*(1+$BV8) -> 30843.11 | M8: =(($AT8*$AM8+$AN8)*(1+$AU8)*(1+$AV8)+($AY8*IF($G$1="鸣金",$AO8,$AM8)+IF($G$1="鸣金",$AP8*1.5,0))*(1+$AZ8)*(1+$BA8)+($BC8*IF($G$1="裂石",$AO8,$AM8)+IF($G$1="裂石",$AP8*1.5,0))*(1+$BD8)*(1+$BE8)+($BG8*IF($G$1="牵丝",$AO8,$AM8)+IF($G$1="牵丝",$AP8*1.5,0))*(1+$BH8)*(1+$BI8)+($BK8*IF($G$1="破竹",$AO8,$AM8)+IF($G$1="破竹",$AP8*1.5,0))*(1+$BL8)*(1+$BM8))*(1+$AQ8)*$BR8*$P8*(1+IF(VLOOKUP($Q8,武学奇术!$A:$ZZ,30,FALSE)="蓄力技",$B$21,0))*(1+$BV8) -> 27058.167 | N8: =((($AS8+$AT8)/2*$AM8+$AN8)*(1+$AU8)*(1+$AV8)+(($AX8+$AY8)/2*IF($G$1="鸣金",$AO8,$AM8)+IF($G$1="鸣金",$AP8*1.5,0))*(1+$AZ8)*(1+$BA8)+(($BB8+$BC8)/2*IF($G$1="裂石",$AO8,$AM8)+IF($G$1="裂石",$AP8*1.5,0))*(1+$BD8)*(1+$BE8)+(($BF8+$BG8)/2*IF($G$1="牵丝",$AO8,$AM8)+IF($G$1="牵丝",$AP8*1.5,0))*(1+$BH8)*(1+$BI8)+(($BJ8+$BK8)/2*IF($G$1="破竹",$AO8,$AM8)+IF($G$1="破竹",$AP8*1.5,0))*(1+$BL8)*(1+$BM8))*(1+$AQ8)*$P8*(1+IF(VLOOKUP($Q8,武学奇术!$A:$ZZ,30,FALSE)="蓄力技",$B$21,0))*(1+$BV8) -> 17524.495 | O8: =((($AS8*$AM8+$AN8)*(1+$AU8)*(1+$AV8)+($AX8*IF($G$1="鸣金",$AO8,$AM8)+IF($G$1="鸣金",$AP8*1.5,0))*(1+$AZ8)*(1+$BA8)+($BB8*IF($G$1="裂石",$AO8,$AM8)+IF($G$1="裂石",$AP8*1.5,0))*(1+$BD8)*(1+$BE8)+($BF8*IF($G$1="牵丝",$AO8,$AM8)+IF($G$1="牵丝",$AP8*1.5,0))*(1+$BH8)*(1+$BI8)+($BJ8*IF($G$1="破竹",$AO8,$AM8)+IF($G$1="破竹",$AP8*1.5,0))*(1+$BL8)*(1+$BM8))*(1+$AQ8))*$P8*(1+IF(VLOOKUP($Q8,武学奇术!$A:$ZZ,30,FALSE)="蓄力技",$B$21,0))*(1+$BV8) -> 15005.903 | P8: 1 | Q8: 横刀安西军 | R8: 易水歌1层 | S8: N/a | T8: 惧刃 | U8: N/a | V8: N/a | W8: 近战笛 | X8: 沧海帖1层 | Y8: N/a | Z8: N/a | AA8: 断岳 | AB8: 扶风(拐) | AC8: N/a | AD8: 裁云(拐) | AE8: 无惧 | AF8: 铁衣 | AG8: N/a | AH8: N/a | AI8: N/a | AJ8: N/a | AK8: 离猎(拐) | AL8: =VLOOKUP($Q8,武学奇术!$A:$ZZ,25,FALSE) -> 横刀 | AM8: =VLOOKUP($Q8,武学奇术!$A:$ZZ,26,FALSE) -> 1.4 | AN8: =VLOOKUP($Q8,武学奇术!$A:$ZZ,27,FALSE)*(1+IF(OR($AL8=$F$4,$AL8=$F$5),$B$22,0)) -> 0 | AO8: =VLOOKUP($Q8,武学奇术!$A:$ZZ,28,FALSE) -> 2.1 | AP8: =VLOOKUP($Q8,武学奇术!$A:$ZZ,29,FALSE)*(1+IF(OR($AL8=$F$4,$AL8=$F$5),$B$22,0)) -> 0 | AQ8: {=$G$3+IFERROR(VLOOKUP($AL8,$F$4:$G$7,2,FALSE),0)+VLOOKUP($Q8,武学奇术!$A:$ZZ,2,FALSE)+SUM(_xlfn.XLOOKUP($R8:$AK8,增益!$A:$A,增益!$B:$B,0))} -> 0.5889 | AR8: {=VLOOKUP($Q8,武学奇术!$A:$ZZ,5,FALSE)+SUM(_xlfn.XLOOKUP($R8:$AK8,增益!$A:$A,增益!$E:$E,0))} -> 0 | AS8: {=$D$10*(1+$AR8)+VLOOKUP($Q8,武学奇术!$A:$ZZ,3,FALSE)+SUM(_xlfn.XLOOKUP($R8:$AK8,增益!$A:$A,增益!$C:$C,0))-$I$2} -> 3648.7 | AT8: {=$E$10*(1+$AR8)+VLOOKUP($Q8,武学奇术!$A:$ZZ,4,FALSE)+SUM(_xlfn.XLOOKUP($R8:$AK8,增益!$A:$A,增益!$D:$D,0))-$I$2} -> 3648.7 | AU8: {=IF($F$10-$I$3+VLOOKUP($Q8,武学奇术!$A:$ZZ,6,FALSE)+SUM(_xlfn.XLOOKUP($R8:$AK8,增益!$A:$A,增益!$F:$F,0))>0,($F$10-$I$3+VLOOKUP($Q8,武学奇术!$A:$ZZ,6,FALSE)+SUM(_xlfn.XLOOKUP($R8:$AK8,增益!$A:$A,增益!$F:$F,0)))/200,($F$10-$I$3+VLOOKUP($Q8,武学奇术!$A:$ZZ,6,FALSE)+SUM(_xlfn.XLOOKUP($R8:$AK8,增益!$A:$A,增益!$F:$F,0)))/100)} -> 0.337 | AV8: {=$G$10+VLOOKUP($Q8,武学奇术!$A:$ZZ,7,FALSE)+SUM(_xlfn.XLOOKUP($R8:$AK8,增益!$A:$A,增益!$G:$G,0))} -> 0 | AW8: {=VLOOKUP($Q8,武学奇术!$A:$ZZ,8,FALSE)+SUM(_xlfn.XLOOKUP($R8:$AK8,增益!$A:$A,增益!$H:$H,0))} -> 0 | AX8: =$D$11*(1+$AW8) -> 0 | AY8: =$E$11*(1+$AW8) -> 0 | AZ8: {=IF($F$11-$I$4+VLOOKUP($Q8,武学奇术!$A:$ZZ,9,FALSE)+SUM(_xlfn.XLOOKUP($R8:$AK8,增益!$A:$A,增益!$I:$I,0))>0,($F$11-$I$4+VLOOKUP($Q8,武学奇术!$A:$ZZ,9,FALSE)+SUM(_xlfn.XLOOKUP($R8:$AK8,增益!$A:$A,增益!$I:$I,0)))/200,($F$11-$I$4+VLOOKUP($Q8,武学奇术!$A:$ZZ,9,FALSE)+SUM(_xlfn.XLOOKUP($R8:$AK8,增益!$A:$A,增益!$I:$I,0)))/100)} -> -0.14 | BA8: {=$G$11+VLOOKUP($Q8,武学奇术!$A:$ZZ,10,FALSE)+SUM(_xlfn.XLOOKUP($R8:$AK8,增益!$A:$A,增益!$J:$J,0))} -> 0 | BB8: =$D$12*(1+$AW8) -> 594.1 | BC8: =$E$12*(1+$AW8) -> 1604.9 | BD8: {=IF($F$12-$I$4+VLOOKUP($Q8,武学奇术!$A:$ZZ,11,FALSE)+SUM(_xlfn.XLOOKUP($R8:$AK8,增益!$A:$A,增益!$K:$K,0))>0,($F$12-$I$4+VLOOKUP($Q8,武学奇术!$A:$ZZ,11,FALSE)+SUM(_xlfn.XLOOKUP($R8:$AK8,增益!$A:$A,增益!$K:$K,0)))/200,($F$12-$I$4+VLOOKUP($Q8,武学奇术!$A:$ZZ,11,FALSE)+SUM(_xlfn.XLOOKUP($R8:$AK8,增益!$A:$A,增益!$K:$K,0)))/100)} -> 0.17 | BE8: {=$G$12+VLOOKUP($Q8,武学奇术!$A:$ZZ,12,FALSE)+SUM(_xlfn.XLOOKUP($R8:$AK8,增益!$A:$A,增益!$L:$L,0))} -> 0.15 | BF8: =$D$13*(1+$AW8) -> 0 | BG8: =$E$13*(1+$AW8) -> 0 | BH8: {=IF($F$13-$I$4+VLOOKUP($Q8,武学奇术!$A:$ZZ,13,FALSE)+SUM(_xlfn.XLOOKUP($R8:$AK8,增益!$A:$A,增益!$M:$M,0))>0,($F$13-$I$4+VLOOKUP($Q8,武学奇术!$A:$ZZ,13,FALSE)+SUM(_xlfn.XLOOKUP($R8:$AK8,增益!$A:$A,增益!$K:$K,0)))/200,($F$13-$I$4+VLOOKUP($Q8,武学奇术!$A:$ZZ,13,FALSE)+SUM(_xlfn.XLOOKUP($R8:$AK8,增益!$A:$A,增益!$M:$M,0)))/100)} -> -0.14 | BI8: {=$G$13+VLOOKUP($Q8,武学奇术!$A:$ZZ,14,FALSE)+SUM(_xlfn.XLOOKUP($R8:$AK8,增益!$A:$A,增益!$N:$N,0))} -> 0 | BJ8: =$D$14*(1+$AW8) -> 0 | BK8: =$E$14*(1+$AW8) -> 0 | BL8: {=IF($F$14-$I$4+VLOOKUP($Q8,武学奇术!$A:$ZZ,15,FALSE)+SUM(_xlfn.XLOOKUP($R8:$AK8,增益!$A:$A,增益!$O:$O,0))>0,($F$14-$I$4+VLOOKUP($Q8,武学奇术!$A:$ZZ,15,FALSE)+SUM(_xlfn.XLOOKUP($R8:$AK8,增益!$A:$A,增益!$O:$O,0)))/200,($F$14-$I$4+VLOOKUP($Q8,武学奇术!$A:$ZZ,15,FALSE)+SUM(_xlfn.XLOOKUP($R8:$AK8,增益!$A:$A,增益!$O:$O,0)))/100)} -> -0.14 | BM8: {=$G$14+VLOOKUP($Q8,武学奇术!$A:$ZZ,16,FALSE)+SUM(_xlfn.XLOOKUP($R8:$AK8,增益!$A:$A,增益!$P:$P,0))} -> 0 | BN8: =MIN(IF(VLOOKUP($Q8,武学奇术!$A:$ZZ,23,FALSE)=1,100%,$B$8),100%) -> 0.9859 | BO8: {=IF(VLOOKUP($Q8,武学奇术!$A:$ZZ,23,FALSE)=1,100%,MIN(80%,$B$9+VLOOKUP($Q8,武学奇术!$A:$ZZ,17,FALSE)+SUM(_xlfn.XLOOKUP($R8:$AK8,增益!$A:$A,增益!$Q:$Q,0)))+$B$11+SUM(_xlfn.XLOOKUP($R8:$AK8,增益!$A:$A,增益!$U:$U,0)))*IF(VLOOKUP($Q8,武学奇术!$A:$ZZ,24,FALSE)=1,0,1)} -> 0.8912 | BP8: {=1+$B$13+VLOOKUP($Q8,武学奇术!$A:$ZZ,18,FALSE)+SUM(_xlfn.XLOOKUP($R8:$AK8,增益!$A:$A,增益!$R:$R,0))} -> 1.76 | BQ8: {=IF(VLOOKUP($Q8,武学奇术!$A:$ZZ,24,FALSE)=1,100%,MIN(40%,$B$10+VLOOKUP($Q8,武学奇术!$A:$ZZ,19,FALSE)+SUM(_xlfn.XLOOKUP($R8:$AK8,增益!$A:$A,增益!$S:$S,0)))+$B$12+SUM(_xlfn.XLOOKUP($R8:$AK8,增益!$A:$A,增益!$V:$V,0)))*IF(VLOOKUP($Q8,武学奇术!$A:$ZZ,23,FALSE)=1,0,1)} -> 0.0929 | BR8: {=1+$B$14+VLOOKUP($Q8,武学奇术!$A:$ZZ,20,FALSE)+SUM(_xlfn.XLOOKUP($R8:$AK8,增益!$A:$A,增益!$T:$T,0))} -> 1.35 | BS8: =MIN((1-BQ8)*BN8,BN8*BO8) -> 0.87863408 | BT8: =1-BQ8-BS8-BU8 -> 0.01567581 | BU8: =IF(VLOOKUP($Q8,武学奇术!$A:$ZZ,22,FALSE)=1,0,(1-$BN8))*(1-$BQ8) -> 0.01279011 | BV8: {=SUM(_xlfn.XLOOKUP($R8:$AK8,增益!$A:$A,增益!$W:$W,0))+$I$5} -> 0.11
A9: 会心率 | B9: 0.7992 | D9: 最小攻击 | E9: 最大攻击 | F9: 穿透 | G9: 伤害加成 | K9: =($L9*$BS9+$M9*$BQ9+$N9*$BT9+$O9*$BU9) -> 16636.516 | L9: =((($AS9+$AT9)/2*$AM9+$AN9)*(1+$AU9)*(1+$AV9)+(($AX9+$AY9)/2*IF($G$1="鸣金",$AO9,$AM9)+IF($G$1="鸣金",$AP9*1.5,0))*(1+$AZ9)*(1+$BA9)+(($BB9+$BC9)/2*IF($G$1="裂石",$AO9,$AM9)+IF($G$1="裂石",$AP9*1.5,0))*(1+$BD9)*(1+$BE9)+(($BF9+$BG9)/2*IF($G$1="牵丝",$AO9,$AM9)+IF($G$1="牵丝",$AP9*1.5,0))*(1+$BH9)*(1+$BI9)+(($BJ9+$BK9)/2*IF($G$1="破竹",$AO9,$AM9)+IF($G$1="破竹",$AP9*1.5,0))*(1+$BL9)*(1+$BM9))*(1+$AQ9)*$BP9*$P9*(1+IF(VLOOKUP($Q9,武学奇术!$A:$ZZ,30,FALSE)="蓄力技",$B$21,0))*(1+$BV9) -> 17171.622 | M9: =(($AT9*$AM9+$AN9)*(1+$AU9)*(1+$AV9)+($AY9*IF($G$1="鸣金",$AO9,$AM9)+IF($G$1="鸣金",$AP9*1.5,0))*(1+$AZ9)*(1+$BA9)+($BC9*IF($G$1="裂石",$AO9,$AM9)+IF($G$1="裂石",$AP9*1.5,0))*(1+$BD9)*(1+$BE9)+($BG9*IF($G$1="牵丝",$AO9,$AM9)+IF($G$1="牵丝",$AP9*1.5,0))*(1+$BH9)*(1+$BI9)+($BK9*IF($G$1="破竹",$AO9,$AM9)+IF($G$1="破竹",$AP9*1.5,0))*(1+$BL9)*(1+$BM9))*(1+$AQ9)*$BR9*$P9*(1+IF(VLOOKUP($Q9,武学奇术!$A:$ZZ,30,FALSE)="蓄力技",$B$21,0))*(1+$BV9) -> 14049.805 | N9: =((($AS9+$AT9)/2*$AM9+$AN9)*(1+$AU9)*(1+$AV9)+(($AX9+$AY9)/2*IF($G$1="鸣金",$AO9,$AM9)+IF($G$1="鸣金",$AP9*1.5,0))*(1+$AZ9)*(1+$BA9)+(($BB9+$BC9)/2*IF($G$1="裂石",$AO9,$AM9)+IF($G$1="裂石",$AP9*1.5,0))*(1+$BD9)*(1+$BE9)+(($BF9+$BG9)/2*IF($G$1="牵丝",$AO9,$AM9)+IF($G$1="牵丝",$AP9*1.5,0))*(1+$BH9)*(1+$BI9)+(($BJ9+$BK9)/2*IF($G$1="破竹",$AO9,$AM9)+IF($G$1="破竹",$AP9*1.5,0))*(1+$BL9)*(1+$BM9))*(1+$AQ9)*$P9*(1+IF(VLOOKUP($Q9,武学奇术!$A:$ZZ,30,FALSE)="蓄力技",$B$21,0))*(1+$BV9) -> 9133.8417 | O9: =((($AS9*$AM9+$AN9)*(1+$AU9)*(1+$AV9)+($AX9*IF($G$1="鸣金",$AO9,$AM9)+IF($G$1="鸣金",$AP9*1.5,0))*(1+$AZ9)*(1+$BA9)+($BB9*IF($G$1="裂石",$AO9,$AM9)+IF($G$1="裂石",$AP9*1.5,0))*(1+$BD9)*(1+$BE9)+($BF9*IF($G$1="牵丝",$AO9,$AM9)+IF($G$1="牵丝",$AP9*1.5,0))*(1+$BH9)*(1+$BI9)+($BJ9*IF($G$1="破竹",$AO9,$AM9)+IF($G$1="破竹",$AP9*1.5,0))*(1+$BL9)*(1+$BM9))*(1+$AQ9))*$P9*(1+IF(VLOOKUP($Q9,武学奇术!$A:$ZZ,30,FALSE)="蓄力技",$B$21,0))*(1+$BV9) -> 7860.4202 | P9: 1 | Q9: 陌刀安西军下劈无开山 | R9: 易水歌1层 | S9: N/a | T9: 惧刃 | U9: 穿喉4 | V9: N/a | W9: 中程笛(小人) | X9: 沧海帖1层 | Y9: N/a | Z9: N/a | AA9: 断岳 | AB9: 扶风(拐) | AC9: N/a | AD9: 裁云(拐) | AE9: 无惧 | AF9: 铁衣 | AG9: N/a | AH9: N/a | AI9: N/a | AJ9: N/a | AK9: 离猎(拐) | AL9: =VLOOKUP($Q9,武学奇术!$A:$ZZ,25,FALSE) -> 陌刀 | AM9: =VLOOKUP($Q9,武学奇术!$A:$ZZ,26,FALSE) -> 0.5 | AN9: =VLOOKUP($Q9,武学奇术!$A:$ZZ,27,FALSE)*(1+IF(OR($AL9=$F$4,$AL9=$F$5),$B$22,0)) -> 0 | AO9: =VLOOKUP($Q9,武学奇术!$A:$ZZ,28,FALSE) -> 0.75 | AP9: =VLOOKUP($Q9,武学奇术!$A:$ZZ,29,FALSE)*(1+IF(OR($AL9=$F$4,$AL9=$F$5),$B$22,0)) -> 0 | AQ9: {=$G$3+IFERROR(VLOOKUP($AL9,$F$4:$G$7,2,FALSE),0)+VLOOKUP($Q9,武学奇术!$A:$ZZ,2,FALSE)+SUM(_xlfn.XLOOKUP($R9:$AK9,增益!$A:$A,增益!$B:$B,0))} -> 0.7041 | AR9: {=VLOOKUP($Q9,武学奇术!$A:$ZZ,5,FALSE)+SUM(_xlfn.XLOOKUP($R9:$AK9,增益!$A:$A,增益!$E:$E,0))} -> 0 | AS9: {=$D$10*(1+$AR9)+VLOOKUP($Q9,武学奇术!$A:$ZZ,3,FALSE)+SUM(_xlfn.XLOOKUP($R9:$AK9,增益!$A:$A,增益!$C:$C,0))-$I$2} -> 3648.7 | AT9: {=$E$10*(1+$AR9)+VLOOKUP($Q9,武学奇术!$A:$ZZ,4,FALSE)+SUM(_xlfn.XLOOKUP($R9:$AK9,增益!$A:$A,增益!$D:$D,0))-$I$2} -> 3648.7 | AU9: {=IF($F$10-$I$3+VLOOKUP($Q9,武学奇术!$A:$ZZ,6,FALSE)+SUM(_xlfn.XLOOKUP($R9:$AK9,增益!$A:$A,增益!$F:$F,0))>0,($F$10-$I$3+VLOOKUP($Q9,武学奇术!$A:$ZZ,6,FALSE)+SUM(_xlfn.XLOOKUP($R9:$AK9,增益!$A:$A,增益!$F:$F,0)))/200,($F$10-$I$3+VLOOKUP($Q9,武学奇术!$A:$ZZ,6,FALSE)+SUM(_xlfn.XLOOKUP($R9:$AK9,增益!$A:$A,增益!$F:$F,0)))/100)} -> 0.397 | AV9: {=$G$10+VLOOKUP($Q9,武学奇术!$A:$ZZ,7,FALSE)+SUM(_xlfn.XLOOKUP($R9:$AK9,增益!$A:$A,增益!$G:$G,0))} -> 0 | AW9: {=VLOOKUP($Q9,武学奇术!$A:$ZZ,8,FALSE)+SUM(_xlfn.XLOOKUP($R9:$AK9,增益!$A:$A,增益!$H:$H,0))} -> 0 | AX9: =$D$11*(1+$AW9) -> 0 | AY9: =$E$11*(1+$AW9) -> 0 | AZ9: {=IF($F$11-$I$4+VLOOKUP($Q9,武学奇术!$A:$ZZ,9,FALSE)+SUM(_xlfn.XLOOKUP($R9:$AK9,增益!$A:$A,增益!$I:$I,0))>0,($F$11-$I$4+VLOOKUP($Q9,武学奇术!$A:$ZZ,9,FALSE)+SUM(_xlfn.XLOOKUP($R9:$AK9,增益!$A:$A,增益!$I:$I,0)))/200,($F$11-$I$4+VLOOKUP($Q9,武学奇术!$A:$ZZ,9,FALSE)+SUM(_xlfn.XLOOKUP($R9:$AK9,增益!$A:$A,增益!$I:$I,0)))/100)} -> -0.14 | BA9: {=$G$11+VLOOKUP($Q9,武学奇术!$A:$ZZ,10,FALSE)+SUM(_xlfn.XLOOKUP($R9:$AK9,增益!$A:$A,增益!$J:$J,0))} -> 0 | BB9: =$D$12*(1+$AW9) -> 594.1 | BC9: =$E$12*(1+$AW9) -> 1604.9 | BD9: {=IF($F$12-$I$4+VLOOKUP($Q9,武学奇术!$A:$ZZ,11,FALSE)+SUM(_xlfn.XLOOKUP($R9:$AK9,增益!$A:$A,增益!$K:$K,0))>0,($F$12-$I$4+VLOOKUP($Q9,武学奇术!$A:$ZZ,11,FALSE)+SUM(_xlfn.XLOOKUP($R9:$AK9,增益!$A:$A,增益!$K:$K,0)))/200,($F$12-$I$4+VLOOKUP($Q9,武学奇术!$A:$ZZ,11,FALSE)+SUM(_xlfn.XLOOKUP($R9:$AK9,增益!$A:$A,增益!$K:$K,0)))/100)} -> 0.17 | BE9: {=$G$12+VLOOKUP($Q9,武学奇术!$A:$ZZ,12,FALSE)+SUM(_xlfn.XLOOKUP($R9:$AK9,增益!$A:$A,增益!$L:$L,0))} -> 0.15 | BF9: =$D$13*(1+$AW9) -> 0 | BG9: =$E$13*(1+$AW9) -> 0 | BH9: {=IF($F$13-$I$4+VLOOKUP($Q9,武学奇术!$A:$ZZ,13,FALSE)+SUM(_xlfn.XLOOKUP($R9:$AK9,增益!$A:$A,增益!$M:$M,0))>0,($F$13-$I$4+VLOOKUP($Q9,武学奇术!$A:$ZZ,13,FALSE)+SUM(_xlfn.XLOOKUP($R9:$AK9,增益!$A:$A,增益!$K:$K,0)))/200,($F$13-$I$4+VLOOKUP($Q9,武学奇术!$A:$ZZ,13,FALSE)+SUM(_xlfn.XLOOKUP($R9:$AK9,增益!$A:$A,增益!$M:$M,0)))/100)} -> -0.14 | BI9: {=$G$13+VLOOKUP($Q9,武学奇术!$A:$ZZ,14,FALSE)+SUM(_xlfn.XLOOKUP($R9:$AK9,增益!$A:$A,增益!$N:$N,0))} -> 0 | BJ9: =$D$14*(1+$AW9) -> 0 | BK9: =$E$14*(1+$AW9) -> 0 | BL9: {=IF($F$14-$I$4+VLOOKUP($Q9,武学奇术!$A:$ZZ,15,FALSE)+SUM(_xlfn.XLOOKUP($R9:$AK9,增益!$A:$A,增益!$O:$O,0))>0,($F$14-$I$4+VLOOKUP($Q9,武学奇术!$A:$ZZ,15,FALSE)+SUM(_xlfn.XLOOKUP($R9:$AK9,增益!$A:$A,增益!$O:$O,0)))/200,($F$14-$I$4+VLOOKUP($Q9,武学奇术!$A:$ZZ,15,FALSE)+SUM(_xlfn.XLOOKUP($R9:$AK9,增益!$A:$A,增益!$O:$O,0)))/100)} -> -0.14 | BM9: {=$G$14+VLOOKUP($Q9,武学奇术!$A:$ZZ,16,FALSE)+SUM(_xlfn.XLOOKUP($R9:$AK9,增益!$A:$A,增益!$P:$P,0))} -> 0 | BN9: =MIN(IF(VLOOKUP($Q9,武学奇术!$A:$ZZ,23,FALSE)=1,100%,$B$8),100%) -> 0.9859 | BO9: {=IF(VLOOKUP($Q9,武学奇术!$A:$ZZ,23,FALSE)=1,100%,MIN(80%,$B$9+VLOOKUP($Q9,武学奇术!$A:$ZZ,17,FALSE)+SUM(_xlfn.XLOOKUP($R9:$AK9,增益!$A:$A,增益!$Q:$Q,0)))+$B$11+SUM(_xlfn.XLOOKUP($R9:$AK9,增益!$A:$A,增益!$U:$U,0)))*IF(VLOOKUP($Q9,武学奇术!$A:$ZZ,24,FALSE)=1,0,1)} -> 0.8912 | BP9: {=1+$B$13+VLOOKUP($Q9,武学奇术!$A:$ZZ,18,FALSE)+SUM(_xlfn.XLOOKUP($R9:$AK9,增益!$A:$A,增益!$R:$R,0))} -> 1.88 | BQ9: {=IF(VLOOKUP($Q9,武学奇术!$A:$ZZ,24,FALSE)=1,100%,MIN(40%,$B$10+VLOOKUP($Q9,武学奇术!$A:$ZZ,19,FALSE)+SUM(_xlfn.XLOOKUP($R9:$AK9,增益!$A:$A,增益!$S:$S,0)))+$B$12+SUM(_xlfn.XLOOKUP($R9:$AK9,增益!$A:$A,增益!$V:$V,0)))*IF(VLOOKUP($Q9,武学奇术!$A:$ZZ,23,FALSE)=1,0,1)} -> 0.0929 | BR9: {=1+$B$14+VLOOKUP($Q9,武学奇术!$A:$ZZ,20,FALSE)+SUM(_xlfn.XLOOKUP($R9:$AK9,增益!$A:$A,增益!$T:$T,0))} -> 1.35 | BS9: =MIN((1-BQ9)*BN9,BN9*BO9) -> 0.87863408 | BT9: =1-BQ9-BS9-BU9 -> 0.01567581 | BU9: =IF(VLOOKUP($Q9,武学奇术!$A:$ZZ,22,FALSE)=1,0,(1-$BN9))*(1-$BQ9) -> 0.01279011 | BV9: {=SUM(_xlfn.XLOOKUP($R9:$AK9,增益!$A:$A,增益!$W:$W,0))+$I$5} -> 0.11
A10: 会意率 | B10: 0.0929 | C10: 外功 | D10: =B2+B23 -> 4206.7 | E10: =MAX(B2+B23,C2+B24) -> 4206.7 | F10: =D2 -> 58.4 | G10: =E2 -> 0 | H10: 总伤 | I10: =SUM(K:K) -> 13685292 | K10: =($L10*$BS10+$M10*$BQ10+$N10*$BT10+$O10*$BU10) -> 32553.012 | L10: =((($AS10+$AT10)/2*$AM10+$AN10)*(1+$AU10)*(1+$AV10)+(($AX10+$AY10)/2*IF($G$1="鸣金",$AO10,$AM10)+IF($G$1="鸣金",$AP10*1.5,0))*(1+$AZ10)*(1+$BA10)+(($BB10+$BC10)/2*IF($G$1="裂石",$AO10,$AM10)+IF($G$1="裂石",$AP10*1.5,0))*(1+$BD10)*(1+$BE10)+(($BF10+$BG10)/2*IF($G$1="牵丝",$AO10,$AM10)+IF($G$1="牵丝",$AP10*1.5,0))*(1+$BH10)*(1+$BI10)+(($BJ10+$BK10)/2*IF($G$1="破竹",$AO10,$AM10)+IF($G$1="破竹",$AP10*1.5,0))*(1+$BL10)*(1+$BM10))*(1+$AQ10)*$BP10*$P10*(1+IF(VLOOKUP($Q10,武学奇术!$A:$ZZ,30,FALSE)="蓄力技",$B$21,0))*(1+$BV10) -> 32553.012 | M10: =(($AT10*$AM10+$AN10)*(1+$AU10)*(1+$AV10)+($AY10*IF($G$1="鸣金",$AO10,$AM10)+IF($G$1="鸣金",$AP10*1.5,0))*(1+$AZ10)*(1+$BA10)+($BC10*IF($G$1="裂石",$AO10,$AM10)+IF($G$1="裂石",$AP10*1.5,0))*(1+$BD10)*(1+$BE10)+($BG10*IF($G$1="牵丝",$AO10,$AM10)+IF($G$1="牵丝",$AP10*1.5,0))*(1+$BH10)*(1+$BI10)+($BK10*IF($G$1="破竹",$AO10,$AM10)+IF($G$1="破竹",$AP10*1.5,0))*(1+$BL10)*(1+$BM10))*(1+$AQ10)*$BR10*$P10*(1+IF(VLOOKUP($Q10,武学奇术!$A:$ZZ,30,FALSE)="蓄力技",$B$21,0))*(1+$BV10) -> 25289.65 | N10: =((($AS10+$AT10)/2*$AM10+$AN10)*(1+$AU10)*(1+$AV10)+(($AX10+$AY10)/2*IF($G$1="鸣金",$AO10,$AM10)+IF($G$1="鸣金",$AP10*1.5,0))*(1+$AZ10)*(1+$BA10)+(($BB10+$BC10)/2*IF($G$1="裂石",$AO10,$AM10)+IF($G$1="裂石",$AP10*1.5,0))*(1+$BD10)*(1+$BE10)+(($BF10+$BG10)/2*IF($G$1="牵丝",$AO10,$AM10)+IF($G$1="牵丝",$AP10*1.5,0))*(1+$BH10)*(1+$BI10)+(($BJ10+$BK10)/2*IF($G$1="破竹",$AO10,$AM10)+IF($G$1="破竹",$AP10*1.5,0))*(1+$BL10)*(1+$BM10))*(1+$AQ10)*$P10*(1+IF(VLOOKUP($Q10,武学奇术!$A:$ZZ,30,FALSE)="蓄力技",$B$21,0))*(1+$BV10) -> 16440.915 | O10: =((($AS10*$AM10+$AN10)*(1+$AU10)*(1+$AV10)+($AX10*IF($G$1="鸣金",$AO10,$AM10)+IF($G$1="鸣金",$AP10*1.5,0))*(1+$AZ10)*(1+$BA10)+($BB10*IF($G$1="裂石",$AO10,$AM10)+IF($G$1="裂石",$AP10*1.5,0))*(1+$BD10)*(1+$BE10)+($BF10*IF($G$1="牵丝",$AO10,$AM10)+IF($G$1="牵丝",$AP10*1.5,0))*(1+$BH10)*(1+$BI10)+($BJ10*IF($G$1="破竹",$AO10,$AM10)+IF($G$1="破竹",$AP10*1.5,0))*(1+$BL10)*(1+$BM10))*(1+$AQ10))*$P10*(1+IF(VLOOKUP($Q10,武学奇术!$A:$ZZ,30,FALSE)="蓄力技",$B$21,0))*(1+$BV10) -> 14148.756 | P10: 1 | Q10: 陌刀安西军跳劈 | R10: 易水歌1层 | S10: N/a | T10: 惧刃 | U10: 穿喉4 | V10: 开山 | W10: 中程笛(小人) | X10: 沧海帖1层 | Y10: N/a | Z10: N/a | AA10: 断岳 | AB10: 扶风(拐) | AC10: N/a | AD10: 裁云(拐) | AE10: 无惧 | AF10: 铁衣 | AG10: N/a | AH10: N/a | AI10: N/a | AJ10: N/a | AK10: 离猎(拐) | AL10: =VLOOKUP($Q10,武学奇术!$A:$ZZ,25,FALSE) -> 陌刀 | AM10: =VLOOKUP($Q10,武学奇术!$A:$ZZ,26,FALSE) -> 0.9 | AN10: =VLOOKUP($Q10,武学奇术!$A:$ZZ,27,FALSE)*(1+IF(OR($AL10=$F$4,$AL10=$F$5),$B$22,0)) -> 0 | AO10: =VLOOKUP($Q10,武学奇术!$A:$ZZ,28,FALSE) -> 1.35 | AP10: =VLOOKUP($Q10,武学奇术!$A:$ZZ,29,FALSE)*(1+IF(OR($AL10=$F$4,$AL10=$F$5),$B$22,0)) -> 0 | AQ10: {=$G$3+IFERROR(VLOOKUP($AL10,$F$4:$G$7,2,FALSE),0)+VLOOKUP($Q10,武学奇术!$A:$ZZ,2,FALSE)+SUM(_xlfn.XLOOKUP($R10:$AK10,增益!$A:$A,增益!$B:$B,0))} -> 0.7041 | AR10: {=VLOOKUP($Q10,武学奇术!$A:$ZZ,5,FALSE)+SUM(_xlfn.XLOOKUP($R10:$AK10,增益!$A:$A,增益!$E:$E,0))} -> 0 | AS10: {=$D$10*(1+$AR10)+VLOOKUP($Q10,武学奇术!$A:$ZZ,3,FALSE)+SUM(_xlfn.XLOOKUP($R10:$AK10,增益!$A:$A,增益!$C:$C,0))-$I$2} -> 3648.7 | AT10: {=$E$10*(1+$AR10)+VLOOKUP($Q10,武学奇术!$A:$ZZ,4,FALSE)+SUM(_xlfn.XLOOKUP($R10:$AK10,增益!$A:$A,增益!$D:$D,0))-$I$2} -> 3648.7 | AU10: {=IF($F$10-$I$3+VLOOKUP($Q10,武学奇术!$A:$ZZ,6,FALSE)+SUM(_xlfn.XLOOKUP($R10:$AK10,增益!$A:$A,增益!$F:$F,0))>0,($F$10-$I$3+VLOOKUP($Q10,武学奇术!$A:$ZZ,6,FALSE)+SUM(_xlfn.XLOOKUP($R10:$AK10,增益!$A:$A,增益!$F:$F,0)))/200,($F$10-$I$3+VLOOKUP($Q10,武学奇术!$A:$ZZ,6,FALSE)+SUM(_xlfn.XLOOKUP($R10:$AK10,增益!$A:$A,增益!$F:$F,0)))/100)} -> 0.397 | AV10: {=$G$10+VLOOKUP($Q10,武学奇术!$A:$ZZ,7,FALSE)+SUM(_xlfn.XLOOKUP($R10:$AK10,增益!$A:$A,增益!$G:$G,0))} -> 0 | AW10: {=VLOOKUP($Q10,武学奇术!$A:$ZZ,8,FALSE)+SUM(_xlfn.XLOOKUP($R10:$AK10,增益!$A:$A,增益!$H:$H,0))} -> 0 | AX10: =$D$11*(1+$AW10) -> 0 | AY10: =$E$11*(1+$AW10) -> 0 | AZ10: {=IF($F$11-$I$4+VLOOKUP($Q10,武学奇术!$A:$ZZ,9,FALSE)+SUM(_xlfn.XLOOKUP($R10:$AK10,增益!$A:$A,增益!$I:$I,0))>0,($F$11-$I$4+VLOOKUP($Q10,武学奇术!$A:$ZZ,9,FALSE)+SUM(_xlfn.XLOOKUP($R10:$AK10,增益!$A:$A,增益!$I:$I,0)))/200,($F$11-$I$4+VLOOKUP($Q10,武学奇术!$A:$ZZ,9,FALSE)+SUM(_xlfn.XLOOKUP($R10:$AK10,增益!$A:$A,增益!$I:$I,0)))/100)} -> -0.14 | BA10: {=$G$11+VLOOKUP($Q10,武学奇术!$A:$ZZ,10,FALSE)+SUM(_xlfn.XLOOKUP($R10:$AK10,增益!$A:$A,增益!$J:$J,0))} -> 0 | BB10: =$D$12*(1+$AW10) -> 594.1 | BC10: =$E$12*(1+$AW10) -> 1604.9 | BD10: {=IF($F$12-$I$4+VLOOKUP($Q10,武学奇术!$A:$ZZ,11,FALSE)+SUM(_xlfn.XLOOKUP($R10:$AK10,增益!$A:$A,增益!$K:$K,0))>0,($F$12-$I$4+VLOOKUP($Q10,武学奇术!$A:$ZZ,11,FALSE)+SUM(_xlfn.XLOOKUP($R10:$AK10,增益!$A:$A,增益!$K:$K,0)))/200,($F$12-$I$4+VLOOKUP($Q10,武学奇术!$A:$ZZ,11,FALSE)+SUM(_xlfn.XLOOKUP($R10:$AK10,增益!$A:$A,增益!$K:$K,0)))/100)} -> 0.17 | BE10: {=$G$12+VLOOKUP($Q10,武学奇术!$A:$ZZ,12,FALSE)+SUM(_xlfn.XLOOKUP($R10:$AK10,增益!$A:$A,增益!$L:$L,0))} -> 0.15 | BF10: =$D$13*(1+$AW10) -> 0 | BG10: =$E$13*(1+$AW10) -> 0 | BH10: {=IF($F$13-$I$4+VLOOKUP($Q10,武学奇术!$A:$ZZ,13,FALSE)+SUM(_xlfn.XLOOKUP($R10:$AK10,增益!$A:$A,增益!$M:$M,0))>0,($F$13-$I$4+VLOOKUP($Q10,武学奇术!$A:$ZZ,13,FALSE)+SUM(_xlfn.XLOOKUP($R10:$AK10,增益!$A:$A,增益!$K:$K,0)))/200,($F$13-$I$4+VLOOKUP($Q10,武学奇术!$A:$ZZ,13,FALSE)+SUM(_xlfn.XLOOKUP($R10:$AK10,增益!$A:$A,增益!$M:$M,0)))/100)} -> -0.14 | BI10: {=$G$13+VLOOKUP($Q10,武学奇术!$A:$ZZ,14,FALSE)+SUM(_xlfn.XLOOKUP($R10:$AK10,增益!$A:$A,增益!$N:$N,0))} -> 0 | BJ10: =$D$14*(1+$AW10) -> 0 | BK10: =$E$14*(1+$AW10) -> 0 | BL10: {=IF($F$14-$I$4+VLOOKUP($Q10,武学奇术!$A:$ZZ,15,FALSE)+SUM(_xlfn.XLOOKUP($R10:$AK10,增益!$A:$A,增益!$O:$O,0))>0,($F$14-$I$4+VLOOKUP($Q10,武学奇术!$A:$ZZ,15,FALSE)+SUM(_xlfn.XLOOKUP($R10:$AK10,增益!$A:$A,增益!$O:$O,0)))/200,($F$14-$I$4+VLOOKUP($Q10,武学奇术!$A:$ZZ,15,FALSE)+SUM(_xlfn.XLOOKUP($R10:$AK10,增益!$A:$A,增益!$O:$O,0)))/100)} -> -0.14 | BM10: {=$G$14+VLOOKUP($Q10,武学奇术!$A:$ZZ,16,FALSE)+SUM(_xlfn.XLOOKUP($R10:$AK10,增益!$A:$A,增益!$P:$P,0))} -> 0 | BN10: =MIN(IF(VLOOKUP($Q10,武学奇术!$A:$ZZ,23,FALSE)=1,100%,$B$8),100%) -> 1 | BO10: {=IF(VLOOKUP($Q10,武学奇术!$A:$ZZ,23,FALSE)=1,100%,MIN(80%,$B$9+VLOOKUP($Q10,武学奇术!$A:$ZZ,17,FALSE)+SUM(_xlfn.XLOOKUP($R10:$AK10,增益!$A:$A,增益!$Q:$Q,0)))+$B$11+SUM(_xlfn.XLOOKUP($R10:$AK10,增益!$A:$A,增益!$U:$U,0)))*IF(VLOOKUP($Q10,武学奇术!$A:$ZZ,24,FALSE)=1,0,1)} -> 1 | BP10: {=1+$B$13+VLOOKUP($Q10,武学奇术!$A:$ZZ,18,FALSE)+SUM(_xlfn.XLOOKUP($R10:$AK10,增益!$A:$A,增益!$R:$R,0))} -> 1.98 | BQ10: {=IF(VLOOKUP($Q10,武学奇术!$A:$ZZ,24,FALSE)=1,100%,MIN(40%,$B$10+VLOOKUP($Q10,武学奇术!$A:$ZZ,19,FALSE)+SUM(_xlfn.XLOOKUP($R10:$AK10,增益!$A:$A,增益!$S:$S,0)))+$B$12+SUM(_xlfn.XLOOKUP($R10:$AK10,增益!$A:$A,增益!$V:$V,0)))*IF(VLOOKUP($Q10,武学奇术!$A:$ZZ,23,FALSE)=1,0,1)} -> 0 | BR10: {=1+$B$14+VLOOKUP($Q10,武学奇术!$A:$ZZ,20,FALSE)+SUM(_xlfn.XLOOKUP($R10:$AK10,增益!$A:$A,增益!$T:$T,0))} -> 1.35 | BS10: =MIN((1-BQ10)*BN10,BN10*BO10) -> 1 | BT10: =1-BQ10-BS10-BU10 -> 0 | BU10: =IF(VLOOKUP($Q10,武学奇术!$A:$ZZ,22,FALSE)=1,0,(1-$BN10))*(1-$BQ10) -> 0 | BV10: {=SUM(_xlfn.XLOOKUP($R10:$AK10,增益!$A:$A,增益!$W:$W,0))+$I$5} -> 0.11
