Workbook

Sheet 期望
B1: 最小攻击 | C1: 最大攻击 | D1: 穿透 | E1: 伤害加成 | F1: 武学属性 | G1: 破竹 | H1: 怪物属性 | K1: 真气比列 | L1: 期望 | M1: 会心期望 | N1: 会意期望 | O1: 普通期望 | P1: 擦伤期望 | Q1: 次数 | R1: 技能 | S1: 增益1 | T1: 增益2 | U1: 增益3 | V1: 增益4 | W1: 增益5 | X1: 增益6 | Y1: 增益7 | Z1: 增益8 | AA1: 增益9 | AB1: 增益10 | AC1: 增益11 | AD1: 增益12 | AE1: 增益13 | AF1: 增益14 | AG1: 增益15 | AH1: 类型 | AI1: 外功倍率 | AJ1: 外攻固伤 | AK1: 属性倍率 | AL1: 属性固伤 | AM1: 通用增伤 | AN1: 外攻加成 | AO1: 即时小外 | AP1: 即时大外 | AQ1: 外穿加成 | AR1: 外伤加成 | AS1: 属攻加成 | AT1: 即时小鸣 | AU1: 即时大鸣 | AV1: 鸣金穿透 | AW1: 鸣金加成 | AX1: 即时小裂 | AY1: 即时大裂 | AZ1: 裂石穿透 | BA1: 裂石加成 | BB1: 即时小牵 | BC1: 即时大牵 | BD1: 牵丝穿透 | BE1: 牵丝加成 | BF1: 即时小破 | BG1: 即时大破 | BH1: 破竹穿透 | BI1: 破竹加成 | BJ1: 生效精准 | BK1: 生效会心 | BL1: 生效会心伤害 | BM1: 生效会意 | BN1: 生效会意伤害 | BO1: 会心占比 | BP1: 普攻占比 | BQ1: 擦伤占比 | BR1: 特殊增伤
A2: 外功 | B2: 3982.6 | C2: 3071.9 | D2: 63.5 | E2: =2.8%+IF(E24="所恨年年",2.5%,0) -> 0.028 | F2: 套装 | G2: 连星 | H2: 防御 | I2: =620*(1-IF(F17="√",0.06,0)-IF(D20="√",0.04,0)) -> 558 | K2: =$L2*VLOOKUP($R2,武学奇术!$A:$ZZ,31,FALSE) -> 26125.795 | L2: =($M2*$BO2+$N2*$BM2+$O2*$BP2+$P2*$BQ2) -> 24881.709 | M2: =((($AO2+$AP2)/2*$AI2+$AJ2)*(1+$AQ2)*(1+$AR2)+(($AT2+$AU2)/2*IF($G$1="鸣金",$AK2,$AI2)+IF($G$1="鸣金",$AL2*1.5,0))*(1+$AV2)*(1+$AW2)+(($AX2+$AY2)/2*IF($G$1="裂石",$AK2,$AI2)+IF($G$1="裂石",$AL2*1.5,0))*(1+$AZ2)*(1+$BA2)+(($BB2+$BC2)/2*IF($G$1="牵丝",$AK2,$AI2)+IF($G$1="牵丝",$AL2*1.5,0))*(1+$BD2)*(1+$BE2)+(($BF2+$BG2)/2*IF($G$1="破竹",$AK2,$AI2)+IF($G$1="破竹",$AL2*1.5,0))*(1+$BH2)*(1+$BI2))*(1+$AM2)*$BL2*$Q2*(1+IF(VLOOKUP($R2,武学奇术!$A:$ZZ,30,FALSE)="回旋伞",$B$21,0))*(1+$BR2) -> 26216.099 | N2: =(($AP2*$AI2+$AJ2)*(1+$AQ2)*(1+$AR2)+($AU2*IF($G$1="鸣金",$AK2,$AI2)+IF($G$1="鸣金",$AL2*1.5,0))*(1+$AV2)*(1+$AW2)+($AY2*IF($G$1="裂石",$AK2,$AI2)+IF($G$1="裂石",$AL2*1.5,0))*(1+$AZ2)*(1+$BA2)+($BC2*IF($G$1="牵丝",$AK2,$AI2)+IF($G$1="牵丝",$AL2*1.5,0))*(1+$BD2)*(1+$BE2)+($BG2*IF($G$1="破竹",$AK2,$AI2)+IF($G$1="破竹",$AL2*1.5,0))*(1+$BH2)*(1+$BI2))*(1+$AM2)*$BN2*$Q2*(1+IF(VLOOKUP($R2,武学奇术!$A:$ZZ,30,FALSE)="回旋伞",$B$21,0))*(1+$BR2) -> 22018.021 | O2: =((($AO2+$AP2)/2*$AI2+$AJ2)*(1+$AQ2)*(1+$AR2)+(($AT2+$AU2)/2*IF($G$1="鸣金",$AK2,$AI2)+IF($G$1="鸣金",$AL2*1.5,0))*(1+$AV2)*(1+$AW2)+(($AX2+$AY2)/2*IF($G$1="裂石",$AK2,$AI2)+IF($G$1="裂石",$AL2*1.5,0))*(1+$AZ2)*(1+$BA2)+(($BB2+$BC2)/2*IF($G$1="牵丝",$AK2,$AI2)+IF($G$1="牵丝",$AL2*1.5,0))*(1+$BD2)*(1+$BE2)+(($BF2+$BG2)/2*IF($G$1="破竹",$AK2,$AI2)+IF($G$1="破竹",$AL2*1.5,0))*(1+$BH2)*(1+$BI2))*(1+$AM2)*$Q2*(1+IF(VLOOKUP($R2,武学奇术!$A:$ZZ,30,FALSE)="回旋伞",$B$21,0))*(1+$BR2) -> 14404.45 | P2: =((($AO2*$AI2+$AJ2)*(1+$AQ2)*(1+$AR2)+($AT2*IF($G$1="鸣金",$AK2,$AI2)+IF($G$1="鸣金",$AL2*1.5,0))*(1+$AV2)*(1+$AW2)+($AX2*IF($G$1="裂石",$AK2,$AI2)+IF($G$1="裂石",$AL2*1.5,0))*(1+$AZ2)*(1+$BA2)+($BB2*IF($G$1="牵丝",$AK2,$AI2)+IF($G$1="牵丝",$AL2*1.5,0))*(1+$BD2)*(1+$BE2)+($BF2*IF($G$1="破竹",$AK2,$AI2)+IF($G$1="破竹",$AL2*1.5,0))*(1+$BH2)*(1+$BI2))*(1+$AM2))*$Q2*(1+IF(VLOOKUP($R2,武学奇术!$A:$ZZ,30,FALSE)="回旋伞",$B$21,0))*(1+$BR2) -> 12499.254 | Q2: 1 | R2: 萧呤千浪流星 | S2: N/a | T2: N/a | U2: 失魂落魄 | V2: 近战笛 | W2: 沧海帖1层 | X2: 易水歌1层 | Y2: N/a | Z2: N/a | AA2: N/a | AB2: N/a | AC2: N/a | AD2: N/a | AE2: N/a | AF2: 裁云(拐) | AG2: 无惧 | AH2: =VLOOKUP($R2,武学奇术!$A:$ZZ,25,FALSE) -> 群体奇术 | AI2: =VLOOKUP($R2,武学奇术!$A:$ZZ,26,FALSE) -> 1.4904 | AJ2: =VLOOKUP($R2,武学奇术!$A:$ZZ,27,FALSE)*(1+IF(OR($AH2=$F$4,$AH2=$F$5),$B$22,0)) -> 378 | AK2: =VLOOKUP($R2,武学奇术!$A:$ZZ,28,FALSE) -> 2.2356 | AL2: =VLOOKUP($R2,武学奇术!$A:$ZZ,29,FALSE)*(1+IF(OR($AH2=$F$4,$AH2=$F$5),$B$22,0)) -> 0 | AM2: {=$G$3+IFERROR(VLOOKUP($AH2,$F$4:$G$7,2,FALSE),0)+VLOOKUP($R2,武学奇术!$A:$ZZ,2,FALSE)+SUM(_xlfn.XLOOKUP($S2:$AG2,增益!$A:$A,增益!$B:$B,0))} -> 0.2637 | AN2: {=VLOOKUP($R2,武学奇术!$A:$ZZ,5,FALSE)+SUM(_xlfn.XLOOKUP($S2:$AG2,增益!$A:$A,增益!$E:$E,0))} -> 0 | AO2: {=$D$10*(1+$AN2)+VLOOKUP($R2,武学奇术!$A:$ZZ,3,FALSE)+SUM(_xlfn.XLOOKUP($S2:$AG2,增益!$A:$A,增益!$C:$C,0))-$I$2} -> 3624.6 | AP2: {=$E$10*(1+$AN2)+VLOOKUP($R2,武学奇术!$A:$ZZ,4,FALSE)+SUM(_xlfn.XLOOKUP($S2:$AG2,增益!$A:$A,增益!$D:$D,0))-$I$2} -> 3624.6 | AQ2: {=IF($F$10-$I$3+VLOOKUP($R2,武学奇术!$A:$ZZ,6,FALSE)+SUM(_xlfn.XLOOKUP(S2:AG2,增益!$A:$A,增益!$F:$F,0))>0,($F$10-$I$3+VLOOKUP($R2,武学奇术!$A:$ZZ,6,FALSE)+SUM(_xlfn.XLOOKUP(S2:AG2,增益!$A:$A,增益!$F:$F,0)))/200,($F$10-$I$3+VLOOKUP($R2,武学奇术!$A:$ZZ,6,FALSE)+SUM(_xlfn.XLOOKUP(S2:AG2,增益!$A:$A,增益!$F:$F,0)))/100)} -> 0.2525 | AR2: {=$G$10+VLOOKUP($R2,武学奇术!$A:$ZZ,7,FALSE)+SUM(_xlfn.XLOOKUP(S2:AG2,增益!$A:$A,增益!$G:$G,0))} -> 0.028 | AS2: {=VLOOKUP($R2,武学奇术!$A:$ZZ,8,FALSE)+SUM(_xlfn.XLOOKUP(S2:AG2,增益!$A:$A,增益!$H:$H,0))} -> 0 | AT2: =$D$11*(1+$AS2) -> 0 | AU2: =$E$11*(1+$AS2) -> 0 | AV2: {=IF($F$11-$I$4+VLOOKUP($R2,武学奇术!$A:$ZZ,9,FALSE)+SUM(_xlfn.XLOOKUP(S2:AG2,增益!$A:$A,增益!$I:$I,0))>0,($F$11-$I$4+VLOOKUP($R2,武学奇术!$A:$ZZ,9,FALSE)+SUM(_xlfn.XLOOKUP(S2:AG2,增益!$A:$A,增益!$I:$I,0)))/200,($F$11-$I$4+VLOOKUP($R2,武学奇术!$A:$ZZ,9,FALSE)+SUM(_xlfn.XLOOKUP(S2:AG2,增益!$A:$A,增益!$I:$I,0)))/100)} -> -0.3 | AW2: {=$G$11+VLOOKUP($R2,武学奇术!$A:$ZZ,10,FALSE)+SUM(_xlfn.XLOOKUP(S2:AG2,增益!$A:$A,增益!$J:$J,0))} -> 0 | AX2: =$D$12*(1+$AS2) -> 0 | AY2: =$E$12*(1+$AS2) -> 0 | AZ2: {=IF($F$12-$I$4+VLOOKUP($R2,武学奇术!$A:$ZZ,11,FALSE)+SUM(_xlfn.XLOOKUP(S2:AG2,增益!$A:$A,增益!$K:$K,0))>0,($F$12-$I$4+VLOOKUP($R2,武学奇术!$A:$ZZ,11,FALSE)+SUM(_xlfn.XLOOKUP(S2:AG2,增益!$A:$A,增益!$K:$K,0)))/200,($F$12-$I$4+VLOOKUP($R2,武学奇术!$A:$ZZ,11,FALSE)+SUM(_xlfn.XLOOKUP(S2:AG2,增益!$A:$A,增益!$K:$K,0)))/100)} -> -0.3 | BA2: {=$G$12+VLOOKUP($R2,武学奇术!$A:$ZZ,12,FALSE)+SUM(_xlfn.XLOOKUP(S2:AG2,增益!$A:$A,增益!$L:$L,0))} -> 0 | BB2: =$D$13*(1+$AS2) -> 0 | BC2: =$E$13*(1+$AS2) -> 0 | BD2: {=IF($F$13-$I$4+VLOOKUP($R2,武学奇术!$A:$ZZ,13,FALSE)+SUM(_xlfn.XLOOKUP(S2:AG2,增益!$A:$A,增益!$M:$M,0))>0,($F$13-$I$4+VLOOKUP($R2,武学奇术!$A:$ZZ,13,FALSE)+SUM(_xlfn.XLOOKUP(S2:AG2,增益!$A:$A,增益!$K:$K,0)))/200,($F$13-$I$4+VLOOKUP($R2,武学奇术!$A:$ZZ,13,FALSE)+SUM(_xlfn.XLOOKUP(S2:AG2,增益!$A:$A,增益!$M:$M,0)))/100)} -> -0.3 | BE2: {=$G$13+VLOOKUP($R2,武学奇术!$A:$ZZ,14,FALSE)+SUM(_xlfn.XLOOKUP(S2:AG2,增益!$A:$A,增益!$N:$N,0))} -> 0 | BF2: =$D$14*(1+$AS2) -> 571.2 | BG2: =$E$14*(1+$AS2) -> 1627.8 | BH2: {=IF($F$14-$I$4+VLOOKUP($R2,武学奇术!$A:$ZZ,15,FALSE)+SUM(_xlfn.XLOOKUP(S2:AG2,增益!$A:$A,增益!$O:$O,0))>0,($F$14-$I$4+VLOOKUP($R2,武学奇术!$A:$ZZ,15,FALSE)+SUM(_xlfn.XLOOKUP(S2:AG2,增益!$A:$A,增益!$O:$O,0)))/200,($F$14-$I$4+VLOOKUP($R2,武学奇术!$A:$ZZ,15,FALSE)+SUM(_xlfn.XLOOKUP(S2:AG2,增益!$A:$A,增益!$O:$O,0)))/100)} -> 0 | BI2: {=$G$14+VLOOKUP($R2,武学奇术!$A:$ZZ,16,FALSE)+SUM(_xlfn.XLOOKUP(S2:AG2,增益!$A:$A,增益!$P:$P,0))} -> 0.15 | BJ2: =MIN(IF(VLOOKUP($R2,武学奇术!$A:$ZZ,23,FALSE)=1,100%,$B$8),100%) -> 0.981 | BK2: {=IF(VLOOKUP($R2,武学奇术!$A:$ZZ,23,FALSE)=1,100%,MIN(80%,$B$9+VLOOKUP($R2,武学奇术!$A:$ZZ,17,FALSE)+SUM(_xlfn.XLOOKUP(S2:AG2,增益!$A:$A,增益!$Q:$Q,0)))+$B$11+SUM(_xlfn.XLOOKUP(S2:AG2,增益!$A:$A,增益!$U:$U,0)))*IF(VLOOKUP($R2,武学奇术!$A:$ZZ,24,FALSE)=1,0,1)} -> 0.846 | BL2: {=1+$B$13+VLOOKUP($R2,武学奇术!$A:$ZZ,18,FALSE)+SUM(_xlfn.XLOOKUP(S2:AG2,增益!$A:$A,增益!$R:$R,0))} -> 1.82 | BM2: {=IF(VLOOKUP($R2,武学奇术!$A:$ZZ,24,FALSE)=1,100%,MIN(40%,$B$10+VLOOKUP($R2,武学奇术!$A:$ZZ,19,FALSE)+SUM(_xlfn.XLOOKUP(S2:AG2,增益!$A:$A,增益!$S:$S,0)))+$B$12+SUM(_xlfn.XLOOKUP(S2:AG2,增益!$A:$A,增益!$V:$V,0)))*IF(VLOOKUP($R2,武学奇术!$A:$ZZ,23,FALSE)=1,0,1)} -> 0.0929 | BN2: {=1+$B$14+VLOOKUP($R2,武学奇术!$A:$ZZ,20,FALSE)+SUM(_xlfn.XLOOKUP(S2:AG2,增益!$A:$A,增益!$T:$T,0))} -> 1.35 | BO2: =MIN((1-BM2)*BJ2,BJ2*BK2) -> 0.829926 | BP2: =1-BM2-BO2-BQ2 -> 0.0599391 | BQ2: =IF(VLOOKUP($R2,武学奇术!$A:$ZZ,22,FALSE)=1,0,(1-$BJ2))*(1-$BM2) -> 0.0172349 | BR2: {=SUM(_xlfn.XLOOKUP(S2:AG2,增益!$A:$A,增益!$W:$W,0))+$I$5} -> 0.11
A3: 鸣金 | F3: 通用增伤 | G3: =B16+1.5%+IF($D$16="√",8%,0)+IF($E$24="征人归",8%,0) -> 0.1837 | H3: 外抗 | I3: =25-IF(F17="√",10,0) -> 15 | K3: =$L3*VLOOKUP($R3,武学奇术!$A:$ZZ,31,FALSE) -> 31051.001 | L3: =($M3*$BO3+$N3*$BM3+$O3*$BP3+$P3*$BQ3) -> 29572.381 | M3: =((($AO3+$AP3)/2*$AI3+$AJ3)*(1+$AQ3)*(1+$AR3)+(($AT3+$AU3)/2*IF($G$1="鸣金",$AK3,$AI3)+IF($G$1="鸣金",$AL3*1.5,0))*(1+$AV3)*(1+$AW3)+(($AX3+$AY3)/2*IF($G$1="裂石",$AK3,$AI3)+IF($G$1="裂石",$AL3*1.5,0))*(1+$AZ3)*(1+$BA3)+(($BB3+$BC3)/2*IF($G$1="牵丝",$AK3,$AI3)+IF($G$1="牵丝",$AL3*1.5,0))*(1+$BD3)*(1+$BE3)+(($BF3+$BG3)/2*IF($G$1="破竹",$AK3,$AI3)+IF($G$1="破竹",$AL3*1.5,0))*(1+$BH3)*(1+$BI3))*(1+$AM3)*$BL3*$Q3*(1+IF(VLOOKUP($R3,武学奇术!$A:$ZZ,30,FALSE)="回旋伞",$B$21,0))*(1+$BR3) -> 31166.676 | N3: =(($AP3*$AI3+$AJ3)*(1+$AQ3)*(1+$AR3)+($AU3*IF($G$1="鸣金",$AK3,$AI3)+IF($G$1="鸣金",$AL3*1.5,0))*(1+$AV3)*(1+$AW3)+($AY3*IF($G$1="裂石",$AK3,$AI3)+IF($G$1="裂石",$AL3*1.5,0))*(1+$AZ3)*(1+$BA3)+($BC3*IF($G$1="牵丝",$AK3,$AI3)+IF($G$1="牵丝",$AL3*1.5,0))*(1+$BD3)*(1+$BE3)+($BG3*IF($G$1="破竹",$AK3,$AI3)+IF($G$1="破竹",$AL3*1.5,0))*(1+$BH3)*(1+$BI3))*(1+$AM3)*$BN3*$Q3*(1+IF(VLOOKUP($R3,武学奇术!$A:$ZZ,30,FALSE)="回旋伞",$B$21,0))*(1+$BR3) -> 26187.229 | O3: =((($AO3+$AP3)/2*$AI3+$AJ3)*(1+$AQ3)*(1+$AR3)+(($AT3+$AU3)/2*IF($G$1="鸣金",$AK3,$AI3)+IF($G$1="鸣金",$AL3*1.5,0))*(1+$AV3)*(1+$AW3)+(($AX3+$AY3)/2*IF($G$1="裂石",$AK3,$AI3)+IF($G$1="裂石",$AL3*1.5,0))*(1+$AZ3)*(1+$BA3)+(($BB3+$BC3)/2*IF($G$1="牵丝",$AK3,$AI3)+IF($G$1="牵丝",$AL3*1.5,0))*(1+$BD3)*(1+$BE3)+(($BF3+$BG3)/2*IF($G$1="破竹",$AK3,$AI3)+IF($G$1="破竹",$AL3*1.5,0))*(1+$BH3)*(1+$BI3))*(1+$AM3)*$Q3*(1+IF(VLOOKUP($R3,武学奇术!$A:$ZZ,30,FALSE)="回旋伞",$B$21,0))*(1+$BR3) -> 17030.97 | P3: =((($AO3*$AI3+$AJ3)*(1+$AQ3)*(1+$AR3)+($AT3*IF($G$1="鸣金",$AK3,$AI3)+IF($G$1="鸣金",$AL3*1.5,0))*(1+$AV3)*(1+$AW3)+($AX3*IF($G$1="裂石",$AK3,$AI3)+IF($G$1="裂石",$AL3*1.5,0))*(1+$AZ3)*(1+$BA3)+($BB3*IF($G$1="牵丝",$AK3,$AI3)+IF($G$1="牵丝",$AL3*1.5,0))*(1+$BD3)*(1+$BE3)+($BF3*IF($G$1="破竹",$AK3,$AI3)+IF($G$1="破竹",$AL3*1.5,0))*(1+$BH3)*(1+$BI3))*(1+$AM3))*$Q3*(1+IF(VLOOKUP($R3,武学奇术!$A:$ZZ,30,FALSE)="回旋伞",$B$21,0))*(1+$BR3) -> 14663.993 | Q3: 1 | R3: 萧呤千浪流星 | S3: N/a | T3: N/a | U3: 失魂落魄 | V3: 远程笛 | W3: 沧海帖2层 | X3: 易水歌2层 | Y3: 惧刃(拐) | Z3: N/a | AA3: N/a | AB3: N/a | AC3: 扶风(拐) | AD3: N/a | AE3: N/a | AF3: 裁云(拐) | AG3: 无惧 | AH3: =VLOOKUP($R3,武学奇术!$A:$ZZ,25,FALSE) -> 群体奇术 | AI3: =VLOOKUP($R3,武学奇术!$A:$ZZ,26,FALSE) -> 1.4904 | AJ3: =VLOOKUP($R3,武学奇术!$A:$ZZ,27,FALSE)*(1+IF(OR($AH3=$F$4,$AH3=$F$5),$B$22,0)) -> 378 | AK3: =VLOOKUP($R3,武学奇术!$A:$ZZ,28,FALSE) -> 2.2356 | AL3: =VLOOKUP($R3,武学奇术!$A:$ZZ,29,FALSE)*(1+IF(OR($AH3=$F$4,$AH3=$F$5),$B$22,0)) -> 0 | AM3: {=$G$3+IFERROR(VLOOKUP($AH3,$F$4:$G$7,2,FALSE),0)+VLOOKUP($R3,武学奇术!$A:$ZZ,2,FALSE)+SUM(_xlfn.XLOOKUP($S3:$AG3,增益!$A:$A,增益!$B:$B,0))} -> 0.4537 | AN3: {=VLOOKUP($R3,武学奇术!$A:$ZZ,5,FALSE)+SUM(_xlfn.XLOOKUP($S3:$AG3,增益!$A:$A,增益!$E:$E,0))} -> 0 | AO3: {=$D$10*(1+$AN3)+VLOOKUP($R3,武学奇术!$A:$ZZ,3,FALSE)+SUM(_xlfn.XLOOKUP($S3:$AG3,增益!$A:$A,增益!$C:$C,0))-$I$2} -> 3624.6 | AP3: {=$E$10*(1+$AN3)+VLOOKUP($R3,武学奇术!$A:$ZZ,4,FALSE)+SUM(_xlfn.XLOOKUP($S3:$AG3,增益!$A:$A,增益!$D:$D,0))-$I$2} -> 3624.6 | AQ3: {=IF($F$10-$I$3+VLOOKUP($R3,武学奇术!$A:$ZZ,6,FALSE)+SUM(_xlfn.XLOOKUP(S3:AG3,增益!$A:$A,增益!$F:$F,0))>0,($F$10-$I$3+VLOOKUP($R3,武学奇术!$A:$ZZ,6,FALSE)+SUM(_xlfn.XLOOKUP(S3:AG3,增益!$A:$A,增益!$F:$F,0)))/200,($F$10-$I$3+VLOOKUP($R3,武学奇术!$A:$ZZ,6,FALSE)+SUM(_xlfn.XLOOKUP(S3:AG3,增益!$A:$A,增益!$F:$F,0)))/100)} -> 0.2625 | AR3: {=$G$10+VLOOKUP($R3,武学奇术!$A:$ZZ,7,FALSE)+SUM(_xlfn.XLOOKUP(S3:AG3,增益!$A:$A,增益!$G:$G,0))} -> 0.028 | AS3: {=VLOOKUP($R3,武学奇术!$A:$ZZ,8,FALSE)+SUM(_xlfn.XLOOKUP(S3:AG3,增益!$A:$A,增益!$H:$H,0))} -> 0 | AT3: =$D$11*(1+$AS3) -> 0 | AU3: =$E$11*(1+$AS3) -> 0 | AV3: {=IF($F$11-$I$4+VLOOKUP($R3,武学奇术!$A:$ZZ,9,FALSE)+SUM(_xlfn.XLOOKUP(S3:AG3,增益!$A:$A,增益!$I:$I,0))>0,($F$11-$I$4+VLOOKUP($R3,武学奇术!$A:$ZZ,9,FALSE)+SUM(_xlfn.XLOOKUP(S3:AG3,增益!$A:$A,增益!$I:$I,0)))/200,($F$11-$I$4+VLOOKUP($R3,武学奇术!$A:$ZZ,9,FALSE)+SUM(_xlfn.XLOOKUP(S3:AG3,增益!$A:$A,增益!$I:$I,0)))/100)} -> -0.14 | AW3: {=$G$11+VLOOKUP($R3,武学奇术!$A:$ZZ,10,FALSE)+SUM(_xlfn.XLOOKUP(S3:AG3,增益!$A:$A,增益!$J:$J,0))} -> 0 | AX3: =$D$12*(1+$AS3) -> 0 | AY3: =$E$12*(1+$AS3) -> 0 | AZ3: {=IF($F$12-$I$4+VLOOKUP($R3,武学奇术!$A:$ZZ,11,FALSE)+SUM(_xlfn.XLOOKUP(S3:AG3,增益!$A:$A,增益!$K:$K,0))>0,($F$12-$I$4+VLOOKUP($R3,武学奇术!$A:$ZZ,11,FALSE)+SUM(_xlfn.XLOOKUP(S3:AG3,增益!$A:$A,增益!$K:$K,0)))/200,($F$12-$I$4+VLOOKUP($R3,武学奇术!$A:$ZZ,11,FALSE)+SUM(_xlfn.XLOOKUP(S3:AG3,增益!$A:$A,增益!$K:$K,0)))/100)} -> -0.14 | BA3: {=$G$12+VLOOKUP($R3,武学奇术!$A:$ZZ,12,FALSE)+SUM(_xlfn.XLOOKUP(S3:AG3,增益!$A:$A,增益!$L:$L,0))} -> 0 | BB3: =$D$13*(1+$AS3) -> 0 | BC3: =$E$13*(1+$AS3) -> 0 | BD3: {=IF($F$13-$I$4+VLOOKUP($R3,武学奇术!$A:$ZZ,13,FALSE)+SUM(_xlfn.XLOOKUP(S3:AG3,增益!$A:$A,增益!$M:$M,0))>0,($F$13-$I$4+VLOOKUP($R3,武学奇术!$A:$ZZ,13,FALSE)+SUM(_xlfn.XLOOKUP(S3:AG3,增益!$A:$A,增益!$K:$K,0)))/200,($F$13-$I$4+VLOOKUP($R3,武学奇术!$A:$ZZ,13,FALSE)+SUM(_xlfn.XLOOKUP(S3:AG3,增益!$A:$A,增益!$M:$M,0)))/100)} -> -0.14 | BE3: {=$G$13+VLOOKUP($R3,武学奇术!$A:$ZZ,14,FALSE)+SUM(_xlfn.XLOOKUP(S3:AG3,增益!$A:$A,增益!$N:$N,0))} -> 0 | BF3: =$D$14*(1+$AS3) -> 571.2 | BG3: =$E$14*(1+$AS3) -> 1627.8 | BH3: {=IF($F$14-$I$4+VLOOKUP($R3,武学奇术!$A:$ZZ,15,FALSE)+SUM(_xlfn.XLOOKUP(S3:AG3,增益!$A:$A,增益!$O:$O,0))>0,($F$14-$I$4+VLOOKUP($R3,武学奇术!$A:$ZZ,15,FALSE)+SUM(_xlfn.XLOOKUP(S3:AG3,增益!$A:$A,增益!$O:$O,0)))/200,($F$14-$I$4+VLOOKUP($R3,武学奇术!$A:$ZZ,15,FALSE)+SUM(_xlfn.XLOOKUP(S3:AG3,增益!$A:$A,增益!$O:$O,0)))/100)} -> 0.08 | BI3: {=$G$14+VLOOKUP($R3,武学奇术!$A:$ZZ,16,FALSE)+SUM(_xlfn.XLOOKUP(S3:AG3,增益!$A:$A,增益!$P:$P,0))} -> 0.15 | BJ3: =MIN(IF(VLOOKUP($R3,武学奇术!$A:$ZZ,23,FALSE)=1,100%,$B$8),100%) -> 0.981 | BK3: {=IF(VLOOKUP($R3,武学奇术!$A:$ZZ,23,FALSE)=1,100%,MIN(80%,$B$9+VLOOKUP($R3,武学奇术!$A:$ZZ,17,FALSE)+SUM(_xlfn.XLOOKUP(S3:AG3,增益!$A:$A,增益!$Q:$Q,0)))+$B$11+SUM(_xlfn.XLOOKUP(S3:AG3,增益!$A:$A,增益!$U:$U,0)))*IF(VLOOKUP($R3,武学奇术!$A:$ZZ,24,FALSE)=1,0,1)} -> 0.846 | BL3: {=1+$B$13+VLOOKUP($R3,武学奇术!$A:$ZZ,18,FALSE)+SUM(_xlfn.XLOOKUP(S3:AG3,增益!$A:$A,增益!$R:$R,0))} -> 1.83 | BM3: {=IF(VLOOKUP($R3,武学奇术!$A:$ZZ,24,FALSE)=1,100%,MIN(40%,$B$10+VLOOKUP($R3,武学奇术!$A:$ZZ,19,FALSE)+SUM(_xlfn.XLOOKUP(S3:AG3,增益!$A:$A,增益!$S:$S,0)))+$B$12+SUM(_xlfn.XLOOKUP(S3:AG3,增益!$A:$A,增益!$V:$V,0)))*IF(VLOOKUP($R3,武学奇术!$A:$ZZ,23,FALSE)=1,0,1)} -> 0.0929 | BN3: {=1+$B$14+VLOOKUP($R3,武学奇术!$A:$ZZ,20,FALSE)+SUM(_xlfn.XLOOKUP(S3:AG3,增益!$A:$A,增益!$T:$T,0))} -> 1.35 | BO3: =MIN((1-BM3)*BJ3,BJ3*BK3) -> 0.829926 | BP3: =1-BM3-BO3-BQ3 -> 0.0599391 | BQ3: =IF(VLOOKUP($R3,武学奇术!$A:$ZZ,22,FALSE)=1,0,(1-$BJ3))*(1-$BM3) -> 0.0172349 | BR3: {=SUM(_xlfn.XLOOKUP(S3:AG3,增益!$A:$A,增益!$W:$W,0))+$I$5} -> 0.11
A4: 裂石 | F4: 伞 | G4: =B15+B17 -> 0.1704 | H4: 属抗 | I4: =30 -> 30 | K4: =$L4*VLOOKUP($R4,武学奇术!$A:$ZZ,31,FALSE) -> 31589.361 | L4: =($M4*$BO4+$N4*$BM4+$O4*$BP4+$P4*$BQ4) -> 30085.106 | M4: =((($AO4+$AP4)/2*$AI4+$AJ4)*(1+$AQ4)*(1+$AR4)+(($AT4+$AU4)/2*IF($G$1="鸣金",$AK4,$AI4)+IF($G$1="鸣金",$AL4*1.5,0))*(1+$AV4)*(1+$AW4)+(($AX4+$AY4)/2*IF($G$1="裂石",$AK4,$AI4)+IF($G$1="裂石",$AL4*1.5,0))*(1+$AZ4)*(1+$BA4)+(($BB4+$BC4)/2*IF($G$1="牵丝",$AK4,$AI4)+IF($G$1="牵丝",$AL4*1.5,0))*(1+$BD4)*(1+$BE4)+(($BF4+$BG4)/2*IF($G$1="破竹",$AK4,$AI4)+IF($G$1="破竹",$AL4*1.5,0))*(1+$BH4)*(1+$BI4))*(1+$AM4)*$BL4*$Q4*(1+IF(VLOOKUP($R4,武学奇术!$A:$ZZ,30,FALSE)="回旋伞",$B$21,0))*(1+$BR4) -> 31730.185 | N4: =(($AP4*$AI4+$AJ4)*(1+$AQ4)*(1+$AR4)+($AU4*IF($G$1="鸣金",$AK4,$AI4)+IF($G$1="鸣金",$AL4*1.5,0))*(1+$AV4)*(1+$AW4)+($AY4*IF($G$1="裂石",$AK4,$AI4)+IF($G$1="裂石",$AL4*1.5,0))*(1+$AZ4)*(1+$BA4)+($BC4*IF($G$1="牵丝",$AK4,$AI4)+IF($G$1="牵丝",$AL4*1.5,0))*(1+$BD4)*(1+$BE4)+($BG4*IF($G$1="破竹",$AK4,$AI4)+IF($G$1="破竹",$AL4*1.5,0))*(1+$BH4)*(1+$BI4))*(1+$AM4)*$BN4*$Q4*(1+IF(VLOOKUP($R4,武学奇术!$A:$ZZ,30,FALSE)="回旋伞",$B$21,0))*(1+$BR4) -> 26497.699 | O4: =((($AO4+$AP4)/2*$AI4+$AJ4)*(1+$AQ4)*(1+$AR4)+(($AT4+$AU4)/2*IF($G$1="鸣金",$AK4,$AI4)+IF($G$1="鸣金",$AL4*1.5,0))*(1+$AV4)*(1+$AW4)+(($AX4+$AY4)/2*IF($G$1="裂石",$AK4,$AI4)+IF($G$1="裂石",$AL4*1.5,0))*(1+$AZ4)*(1+$BA4)+(($BB4+$BC4)/2*IF($G$1="牵丝",$AK4,$AI4)+IF($G$1="牵丝",$AL4*1.5,0))*(1+$BD4)*(1+$BE4)+(($BF4+$BG4)/2*IF($G$1="破竹",$AK4,$AI4)+IF($G$1="破竹",$AL4*1.5,0))*(1+$BH4)*(1+$BI4))*(1+$AM4)*$Q4*(1+IF(VLOOKUP($R4,武学奇术!$A:$ZZ,30,FALSE)="回旋伞",$B$21,0))*(1+$BR4) -> 17244.666 | P4: =((($AO4*$AI4+$AJ4)*(1+$AQ4)*(1+$AR4)+($AT4*IF($G$1="鸣金",$AK4,$AI4)+IF($G$1="鸣金",$AL4*1.5,0))*(1+$AV4)*(1+$AW4)+($AX4*IF($G$1="裂石",$AK4,$AI4)+IF($G$1="裂石",$AL4*1.5,0))*(1+$AZ4)*(1+$BA4)+($BB4*IF($G$1="牵丝",$AK4,$AI4)+IF($G$1="牵丝",$AL4*1.5,0))*(1+$BD4)*(1+$BE4)+($BF4*IF($G$1="破竹",$AK4,$AI4)+IF($G$1="破竹",$AL4*1.5,0))*(1+$BH4)*(1+$BI4))*(1+$AM4))*$Q4*(1+IF(VLOOKUP($R4,武学奇术!$A:$ZZ,30,FALSE)="回旋伞",$B$21,0))*(1+$BR4) -> 14861.406 | Q4: 1 | R4: 萧呤千浪流星 | S4: N/a | T4: N/a | U4: 失魂落魄 | V4: 远程笛 | W4: 沧海帖3层 | X4: 易水歌3层 | Y4: 惧刃(拐) | Z4: N/a | AA4: N/a | AB4: N/a | AC4: 烁鼓(拐) | AD4: N/a | AE4: N/a | AF4: 裁云(拐) | AG4: 无惧 | AH4: =VLOOKUP($R4,武学奇术!$A:$ZZ,25,FALSE) -> 群体奇术 | AI4: =VLOOKUP($R4,武学奇术!$A:$ZZ,26,FALSE) -> 1.4904 | AJ4: =VLOOKUP($R4,武学奇术!$A:$ZZ,27,FALSE)*(1+IF(OR($AH4=$F$4,$AH4=$F$5),$B$22,0)) -> 378 | AK4: =VLOOKUP($R4,武学奇术!$A:$ZZ,28,FALSE) -> 2.2356 | AL4: =VLOOKUP($R4,武学奇术!$A:$ZZ,29,FALSE)*(1+IF(OR($AH4=$F$4,$AH4=$F$5),$B$22,0)) -> 0 | AM4: {=$G$3+IFERROR(VLOOKUP($AH4,$F$4:$G$7,2,FALSE),0)+VLOOKUP($R4,武学奇术!$A:$ZZ,2,FALSE)+SUM(_xlfn.XLOOKUP($S4:$AG4,增益!$A:$A,增益!$B:$B,0))} -> 0.4637 | AN4: {=VLOOKUP($R4,武学奇术!$A:$ZZ,5,FALSE)+SUM(_xlfn.XLOOKUP($S4:$AG4,增益!$A:$A,增益!$E:$E,0))} -> 0 | AO4: {=$D$10*(1+$AN4)+VLOOKUP($R4,武学奇术!$A:$ZZ,3,FALSE)+SUM(_xlfn.XLOOKUP($S4:$AG4,增益!$A:$A,增益!$C:$C,0))-$I$2} -> 3624.6 | AP4: {=$E$10*(1+$AN4)+VLOOKUP($R4,武学奇术!$A:$ZZ,4,FALSE)+SUM(_xlfn.XLOOKUP($S4:$AG4,增益!$A:$A,增益!$D:$D,0))-$I$2} -> 3624.6 | AQ4: {=IF($F$10-$I$3+VLOOKUP($R4,武学奇术!$A:$ZZ,6,FALSE)+SUM(_xlfn.XLOOKUP(S4:AG4,增益!$A:$A,增益!$F:$F,0))>0,($F$10-$I$3+VLOOKUP($R4,武学奇术!$A:$ZZ,6,FALSE)+SUM(_xlfn.XLOOKUP(S4:AG4,增益!$A:$A,增益!$F:$F,0)))/200,($F$10-$I$3+VLOOKUP($R4,武学奇术!$A:$ZZ,6,FALSE)+SUM(_xlfn.XLOOKUP(S4:AG4,增益!$A:$A,增益!$F:$F,0)))/100)} -> 0.2725 | AR4: {=$G$10+VLOOKUP($R4,武学奇术!$A:$ZZ,7,FALSE)+SUM(_xlfn.XLOOKUP(S4:AG4,增益!$A:$A,增益!$G:$G,0))} -> 0.028 | AS4: {=VLOOKUP($R4,武学奇术!$A:$ZZ,8,FALSE)+SUM(_xlfn.XLOOKUP(S4:AG4,增益!$A:$A,增益!$H:$H,0))} -> 0 | AT4: =$D$11*(1+$AS4) -> 0 | AU4: =$E$11*(1+$AS4) -> 0 | AV4: {=IF($F$11-$I$4+VLOOKUP($R4,武学奇术!$A:$ZZ,9,FALSE)+SUM(_xlfn.XLOOKUP(S4:AG4,增益!$A:$A,增益!$I:$I,0))>0,($F$11-$I$4+VLOOKUP($R4,武学奇术!$A:$ZZ,9,FALSE)+SUM(_xlfn.XLOOKUP(S4:AG4,增益!$A:$A,增益!$I:$I,0)))/200,($F$11-$I$4+VLOOKUP($R4,武学奇术!$A:$ZZ,9,FALSE)+SUM(_xlfn.XLOOKUP(S4:AG4,增益!$A:$A,增益!$I:$I,0)))/100)} -> -0.14 | AW4: {=$G$11+VLOOKUP($R4,武学奇术!$A:$ZZ,10,FALSE)+SUM(_xlfn.XLOOKUP(S4:AG4,增益!$A:$A,增益!$J:$J,0))} -> 0 | AX4: =$D$12*(1+$AS4) -> 0 | AY4: =$E$12*(1+$AS4) -> 0 | AZ4: {=IF($F$12-$I$4+VLOOKUP($R4,武学奇术!$A:$ZZ,11,FALSE)+SUM(_xlfn.XLOOKUP(S4:AG4,增益!$A:$A,增益!$K:$K,0))>0,($F$12-$I$4+VLOOKUP($R4,武学奇术!$A:$ZZ,11,FALSE)+SUM(_xlfn.XLOOKUP(S4:AG4,增益!$A:$A,增益!$K:$K,0)))/200,($F$12-$I$4+VLOOKUP($R4,武学奇术!$A:$ZZ,11,FALSE)+SUM(_xlfn.XLOOKUP(S4:AG4,增益!$A:$A,增益!$K:$K,0)))/100)} -> -0.14 | BA4: {=$G$12+VLOOKUP($R4,武学奇术!$A:$ZZ,12,FALSE)+SUM(_xlfn.XLOOKUP(S4:AG4,增益!$A:$A,增益!$L:$L,0))} -> 0 | BB4: =$D$13*(1+$AS4) -> 0 | BC4: =$E$13*(1+$AS4) -> 0 | BD4: {=IF($F$13-$I$4+VLOOKUP($R4,武学奇术!$A:$ZZ,13,FALSE)+SUM(_xlfn.XLOOKUP(S4:AG4,增益!$A:$A,增益!$M:$M,0))>0,($F$13-$I$4+VLOOKUP($R4,武学奇术!$A:$ZZ,13,FALSE)+SUM(_xlfn.XLOOKUP(S4:AG4,增益!$A:$A,增益!$K:$K,0)))/200,($F$13-$I$4+VLOOKUP($R4,武学奇术!$A:$ZZ,13,FALSE)+SUM(_xlfn.XLOOKUP(S4:AG4,增益!$A:$A,增益!$M:$M,0)))/100)} -> -0.14 | BE4: {=$G$13+VLOOKUP($R4,武学奇术!$A:$ZZ,14,FALSE)+SUM(_xlfn.XLOOKUP(S4:AG4,增益!$A:$A,增益!$N:$N,0))} -> 0 | BF4: =$D$14*(1+$AS4) -> 571.2 | BG4: =$E$14*(1+$AS4) -> 1627.8 | BH4: {=IF($F$14-$I$4+VLOOKUP($R4,武学奇术!$A:$ZZ,15,FALSE)+SUM(_xlfn.XLOOKUP(S4:AG4,增益!$A:$A,增益!$O:$O,0))>0,($F$14-$I$4+VLOOKUP($R4,武学奇术!$A:$ZZ,15,FALSE)+SUM(_xlfn.XLOOKUP(S4:AG4,增益!$A:$A,增益!$O:$O,0)))/200,($F$14-$I$4+VLOOKUP($R4,武学奇术!$A:$ZZ,15,FALSE)+SUM(_xlfn.XLOOKUP(S4:AG4,增益!$A:$A,增益!$O:$O,0)))/100)} -> 0.08 | BI4: {=$G$14+VLOOKUP($R4,武学奇术!$A:$ZZ,16,FALSE)+SUM(_xlfn.XLOOKUP(S4:AG4,增益!$A:$A,增益!$P:$P,0))} -> 0.15 | BJ4: =MIN(IF(VLOOKUP($R4,武学奇术!$A:$ZZ,23,FALSE)=1,100%,$B$8),100%) -> 0.981 | BK4: {=IF(VLOOKUP($R4,武学奇术!$A:$ZZ,23,FALSE)=1,100%,MIN(80%,$B$9+VLOOKUP($R4,武学奇术!$A:$ZZ,17,FALSE)+SUM(_xlfn.XLOOKUP(S4:AG4,增益!$A:$A,增益!$Q:$Q,0)))+$B$11+SUM(_xlfn.XLOOKUP(S4:AG4,增益!$A:$A,增益!$U:$U,0)))*IF(VLOOKUP($R4,武学奇术!$A:$ZZ,24,FALSE)=1,0,1)} -> 0.846 | BL4: {=1+$B$13+VLOOKUP($R4,武学奇术!$A:$ZZ,18,FALSE)+SUM(_xlfn.XLOOKUP(S4:AG4,增益!$A:$A,增益!$R:$R,0))} -> 1.84 | BM4: {=IF(VLOOKUP($R4,武学奇术!$A:$ZZ,24,FALSE)=1,100%,MIN(40%,$B$10+VLOOKUP($R4,武学奇术!$A:$ZZ,19,FALSE)+SUM(_xlfn.XLOOKUP(S4:AG4,增益!$A:$A,增益!$S:$S,0)))+$B$12+SUM(_xlfn.XLOOKUP(S4:AG4,增益!$A:$A,增益!$V:$V,0)))*IF(VLOOKUP($R4,武学奇术!$A:$ZZ,23,FALSE)=1,0,1)} -> 0.0929 | BN4: {=1+$B$14+VLOOKUP($R4,武学奇术!$A:$ZZ,20,FALSE)+SUM(_xlfn.XLOOKUP(S4:AG4,增益!$A:$A,增益!$T:$T,0))} -> 1.35 | BO4: =MIN((1-BM4)*BJ4,BJ4*BK4) -> 0.829926 | BP4: =1-BM4-BO4-BQ4 -> 0.0599391 | BQ4: =IF(VLOOKUP($R4,武学奇术!$A:$ZZ,22,FALSE)=1,0,(1-$BJ4))*(1-$BM4) -> 0.0172349 | BR4: {=SUM(_xlfn.XLOOKUP(S4:AG4,增益!$A:$A,增益!$W:$W,0))+$I$5} -> 0.11
A5: 牵丝 | F5: 绳镖 | G5: =B15+B18 -> 0.0852 | H5: 副本天赋 | I5: 0.06 | K5: =$L5*VLOOKUP($R5,武学奇术!$A:$ZZ,31,FALSE) -> 33020.719 | L5: =($M5*$BO5+$N5*$BM5+$O5*$BP5+$P5*$BQ5) -> 31448.304 | M5: =((($AO5+$AP5)/2*$AI5+$AJ5)*(1+$AQ5)*(1+$AR5)+(($AT5+$AU5)/2*IF($G$1="鸣金",$AK5,$AI5)+IF($G$1="鸣金",$AL5*1.5,0))*(1+$AV5)*(1+$AW5)+(($AX5+$AY5)/2*IF($G$1="裂石",$AK5,$AI5)+IF($G$1="裂石",$AL5*1.5,0))*(1+$AZ5)*(1+$BA5)+(($BB5+$BC5)/2*IF($G$1="牵丝",$AK5,$AI5)+IF($G$1="牵丝",$AL5*1.5,0))*(1+$BD5)*(1+$BE5)+(($BF5+$BG5)/2*IF($G$1="破竹",$AK5,$AI5)+IF($G$1="破竹",$AL5*1.5,0))*(1+$BH5)*(1+$BI5))*(1+$AM5)*$BL5*$Q5*(1+IF(VLOOKUP($R5,武学奇术!$A:$ZZ,30,FALSE)="回旋伞",$B$21,0))*(1+$BR5) -> 33199.496 | N5: =(($AP5*$AI5+$AJ5)*(1+$AQ5)*(1+$AR5)+($AU5*IF($G$1="鸣金",$AK5,$AI5)+IF($G$1="鸣金",$AL5*1.5,0))*(1+$AV5)*(1+$AW5)+($AY5*IF($G$1="裂石",$AK5,$AI5)+IF($G$1="裂石",$AL5*1.5,0))*(1+$AZ5)*(1+$BA5)+($BC5*IF($G$1="牵丝",$AK5,$AI5)+IF($G$1="牵丝",$AL5*1.5,0))*(1+$BD5)*(1+$BE5)+($BG5*IF($G$1="破竹",$AK5,$AI5)+IF($G$1="破竹",$AL5*1.5,0))*(1+$BH5)*(1+$BI5))*(1+$AM5)*$BN5*$Q5*(1+IF(VLOOKUP($R5,武学奇术!$A:$ZZ,30,FALSE)="回旋伞",$B$21,0))*(1+$BR5) -> 27466.041 | O5: =((($AO5+$AP5)/2*$AI5+$AJ5)*(1+$AQ5)*(1+$AR5)+(($AT5+$AU5)/2*IF($G$1="鸣金",$AK5,$AI5)+IF($G$1="鸣金",$AL5*1.5,0))*(1+$AV5)*(1+$AW5)+(($AX5+$AY5)/2*IF($G$1="裂石",$AK5,$AI5)+IF($G$1="裂石",$AL5*1.5,0))*(1+$AZ5)*(1+$BA5)+(($BB5+$BC5)/2*IF($G$1="牵丝",$AK5,$AI5)+IF($G$1="牵丝",$AL5*1.5,0))*(1+$BD5)*(1+$BE5)+(($BF5+$BG5)/2*IF($G$1="破竹",$AK5,$AI5)+IF($G$1="破竹",$AL5*1.5,0))*(1+$BH5)*(1+$BI5))*(1+$AM5)*$Q5*(1+IF(VLOOKUP($R5,武学奇术!$A:$ZZ,30,FALSE)="回旋伞",$B$21,0))*(1+$BR5) -> 17945.674 | P5: =((($AO5*$AI5+$AJ5)*(1+$AQ5)*(1+$AR5)+($AT5*IF($G$1="鸣金",$AK5,$AI5)+IF($G$1="鸣金",$AL5*1.5,0))*(1+$AV5)*(1+$AW5)+($AX5*IF($G$1="裂石",$AK5,$AI5)+IF($G$1="裂石",$AL5*1.5,0))*(1+$AZ5)*(1+$BA5)+($BB5*IF($G$1="牵丝",$AK5,$AI5)+IF($G$1="牵丝",$AL5*1.5,0))*(1+$BD5)*(1+$BE5)+($BF5*IF($G$1="破竹",$AK5,$AI5)+IF($G$1="破竹",$AL5*1.5,0))*(1+$BH5)*(1+$BI5))*(1+$AM5))*$Q5*(1+IF(VLOOKUP($R5,武学奇术!$A:$ZZ,30,FALSE)="回旋伞",$B$21,0))*(1+$BR5) -> 15546.132 | Q5: 1 | R5: 萧呤千浪流星 | S5: N/a | T5: 幻鸣5层 | U5: 失魂落魄 | V5: 远程笛 | W5: 沧海帖4层 | X5: 易水歌4层 | Y5: 惧刃(拐) | Z5: N/a | AA5: N/a | AB5: N/a | AC5: 烁鼓(拐) | AD5: N/a | AE5: N/a | AF5: 裁云(拐) | AG5: 无惧 | AH5: =VLOOKUP($R5,武学奇术!$A:$ZZ,25,FALSE) -> 群体奇术 | AI5: =VLOOKUP($R5,武学奇术!$A:$ZZ,26,FALSE) -> 1.4904 | AJ5: =VLOOKUP($R5,武学奇术!$A:$ZZ,27,FALSE)*(1+IF(OR($AH5=$F$4,$AH5=$F$5),$B$22,0)) -> 378 | AK5: =VLOOKUP($R5,武学奇术!$A:$ZZ,28,FALSE) -> 2.2356 | AL5: =VLOOKUP($R5,武学奇术!$A:$ZZ,29,FALSE)*(1+IF(OR($AH5=$F$4,$AH5=$F$5),$B$22,0)) -> 0 | AM5: {=$G$3+IFERROR(VLOOKUP($AH5,$F$4:$G$7,2,FALSE),0)+VLOOKUP($R5,武学奇术!$A:$ZZ,2,FALSE)+SUM(_xlfn.XLOOKUP($S5:$AG5,增益!$A:$A,增益!$B:$B,0))} -> 0.4737 | AN5: {=VLOOKUP($R5,武学奇术!$A:$ZZ,5,FALSE)+SUM(_xlfn.XLOOKUP($S5:$AG5,增益!$A:$A,增益!$E:$E,0))} -> 0 | AO5: {=$D$10*(1+$AN5)+VLOOKUP($R5,武学奇术!$A:$ZZ,3,FALSE)+SUM(_xlfn.XLOOKUP($S5:$AG5,增益!$A:$A,增益!$C:$C,0))-$I$2} -> 3624.6 | AP5: {=$E$10*(1+$AN5)+VLOOKUP($R5,武学奇术!$A:$ZZ,4,FALSE)+SUM(_xlfn.XLOOKUP($S5:$AG5,增益!$A:$A,增益!$D:$D,0))-$I$2} -> 3624.6 | AQ5: {=IF($F$10-$I$3+VLOOKUP($R5,武学奇术!$A:$ZZ,6,FALSE)+SUM(_xlfn.XLOOKUP(S5:AG5,增益!$A:$A,增益!$F:$F,0))>0,($F$10-$I$3+VLOOKUP($R5,武学奇术!$A:$ZZ,6,FALSE)+SUM(_xlfn.XLOOKUP(S5:AG5,增益!$A:$A,增益!$F:$F,0)))/200,($F$10-$I$3+VLOOKUP($R5,武学奇术!$A:$ZZ,6,FALSE)+SUM(_xlfn.XLOOKUP(S5:AG5,增益!$A:$A,增益!$F:$F,0)))/100)} -> 0.3325 | AR5: {=$G$10+VLOOKUP($R5,武学奇术!$A:$ZZ,7,FALSE)+SUM(_xlfn.XLOOKUP(S5:AG5,增益!$A:$A,增益!$G:$G,0))} -> 0.028 | AS5: {=VLOOKUP($R5,武学奇术!$A:$ZZ,8,FALSE)+SUM(_xlfn.XLOOKUP(S5:AG5,增益!$A:$A,增益!$H:$H,0))} -> 0 | AT5: =$D$11*(1+$AS5) -> 0 | AU5: =$E$11*(1+$AS5) -> 0 | AV5: {=IF($F$11-$I$4+VLOOKUP($R5,武学奇术!$A:$ZZ,9,FALSE)+SUM(_xlfn.XLOOKUP(S5:AG5,增益!$A:$A,增益!$I:$I,0))>0,($F$11-$I$4+VLOOKUP($R5,武学奇术!$A:$ZZ,9,FALSE)+SUM(_xlfn.XLOOKUP(S5:AG5,增益!$A:$A,增益!$I:$I,0)))/200,($F$11-$I$4+VLOOKUP($R5,武学奇术!$A:$ZZ,9,FALSE)+SUM(_xlfn.XLOOKUP(S5:AG5,增益!$A:$A,增益!$I:$I,0)))/100)} -> -0.14 | AW5: {=$G$11+VLOOKUP($R5,武学奇术!$A:$ZZ,10,FALSE)+SUM(_xlfn.XLOOKUP(S5:AG5,增益!$A:$A,增益!$J:$J,0))} -> 0 | AX5: =$D$12*(1+$AS5) -> 0 | AY5: =$E$12*(1+$AS5) -> 0 | AZ5: {=IF($F$12-$I$4+VLOOKUP($R5,武学奇术!$A:$ZZ,11,FALSE)+SUM(_xlfn.XLOOKUP(S5:AG5,增益!$A:$A,增益!$K:$K,0))>0,($F$12-$I$4+VLOOKUP($R5,武学奇术!$A:$ZZ,11,FALSE)+SUM(_xlfn.XLOOKUP(S5:AG5,增益!$A:$A,增益!$K:$K,0)))/200,($F$12-$I$4+VLOOKUP($R5,武学奇术!$A:$ZZ,11,FALSE)+SUM(_xlfn.XLOOKUP(S5:AG5,增益!$A:$A,增益!$K:$K,0)))/100)} -> -0.14 | BA5: {=$G$12+VLOOKUP($R5,武学奇术!$A:$ZZ,12,FALSE)+SUM(_xlfn.XLOOKUP(S5:AG5,增益!$A:$A,增益!$L:$L,0))} -> 0 | BB5: =$D$13*(1+$AS5) -> 0 | BC5: =$E$13*(1+$AS5) -> 0 | BD5: {=IF($F$13-$I$4+VLOOKUP($R5,武学奇术!$A:$ZZ,13,FALSE)+SUM(_xlfn.XLOOKUP(S5:AG5,增益!$A:$A,增益!$M:$M,0))>0,($F$13-$I$4+VLOOKUP($R5,武学奇术!$A:$ZZ,13,FALSE)+SUM(_xlfn.XLOOKUP(S5:AG5,增益!$A:$A,增益!$K:$K,0)))/200,($F$13-$I$4+VLOOKUP($R5,武学奇术!$A:$ZZ,13,FALSE)+SUM(_xlfn.XLOOKUP(S5:AG5,增益!$A:$A,增益!$M:$M,0)))/100)} -> -0.14 | BE5: {=$G$13+VLOOKUP($R5,武学奇术!$A:$ZZ,14,FALSE)+SUM(_xlfn.XLOOKUP(S5:AG5,增益!$A:$A,增益!$N:$N,0))} -> 0 | BF5: =$D$14*(1+$AS5) -> 571.2 | BG5: =$E$14*(1+$AS5) -> 1627.8 | BH5: {=IF($F$14-$I$4+VLOOKUP($R5,武学奇术!$A:$ZZ,15,FALSE)+SUM(_xlfn.XLOOKUP(S5:AG5,增益!$A:$A,增益!$O:$O,0))>0,($F$14-$I$4+VLOOKUP($R5,武学奇术!$A:$ZZ,15,FALSE)+SUM(_xlfn.XLOOKUP(S5:AG5,增益!$A:$A,增益!$O:$O,0)))/200,($F$14-$I$4+VLOOKUP($R5,武学奇术!$A:$ZZ,15,FALSE)+SUM(_xlfn.XLOOKUP(S5:AG5,增益!$A:$A,增益!$O:$O,0)))/100)} -> 0.08 | BI5: {=$G$14+VLOOKUP($R5,武学奇术!$A:$ZZ,16,FALSE)+SUM(_xlfn.XLOOKUP(S5:AG5,增益!$A:$A,增益!$P:$P,0))} -> 0.15 | BJ5: =MIN(IF(VLOOKUP($R5,武学奇术!$A:$ZZ,23,FALSE)=1,100%,$B$8),100%) -> 0.981 | BK5: {=IF(VLOOKUP($R5,武学奇术!$A:$ZZ,23,FALSE)=1,100%,MIN(80%,$B$9+VLOOKUP($R5,武学奇术!$A:$ZZ,17,FALSE)+SUM(_xlfn.XLOOKUP(S5:AG5,增益!$A:$A,增益!$Q:$Q,0)))+$B$11+SUM(_xlfn.XLOOKUP(S5:AG5,增益!$A:$A,增益!$U:$U,0)))*IF(VLOOKUP($R5,武学奇术!$A:$ZZ,24,FALSE)=1,0,1)} -> 0.846 | BL5: {=1+$B$13+VLOOKUP($R5,武学奇术!$A:$ZZ,18,FALSE)+SUM(_xlfn.XLOOKUP(S5:AG5,增益!$A:$A,增益!$R:$R,0))} -> 1.85 | BM5: {=IF(VLOOKUP($R5,武学奇术!$A:$ZZ,24,FALSE)=1,100%,MIN(40%,$B$10+VLOOKUP($R5,武学奇术!$A:$ZZ,19,FALSE)+SUM(_xlfn.XLOOKUP(S5:AG5,增益!$A:$A,增益!$S:$S,0)))+$B$12+SUM(_xlfn.XLOOKUP(S5:AG5,增益!$A:$A,增益!$V:$V,0)))*IF(VLOOKUP($R5,武学奇术!$A:$ZZ,23,FALSE)=1,0,1)} -> 0.0929 | BN5: {=1+$B$14+VLOOKUP($R5,武学奇术!$A:$ZZ,20,FALSE)+SUM(_xlfn.XLOOKUP(S5:AG5,增益!$A:$A,增益!$T:$T,0))} -> 1.35 | BO5: =MIN((1-BM5)*BJ5,BJ5*BK5) -> 0.829926 | BP5: =1-BM5-BO5-BQ5 -> 0.0599391 | BQ5: =IF(VLOOKUP($R5,武学奇术!$A:$ZZ,22,FALSE)=1,0,(1-$BJ5))*(1-$BM5) -> 0.0172349 | BR5: {=SUM(_xlfn.XLOOKUP(S5:AG5,增益!$A:$A,增益!$W:$W,0))+$I$5} -> 0.11
A6: 破竹 | B6: 492 | C6: 1397.8 | D6: 30 | E6: 0.15 | F6: 单体奇术 | G6: =B19 -> 0 | K6: =$L6*VLOOKUP($R6,武学奇术!$A:$ZZ,31,FALSE) -> 33423.363 | L6: =($M6*$BO6+$N6*$BM6+$O6*$BP6+$P6*$BQ6) -> 31831.774 | M6: =((($AO6+$AP6)/2*$AI6+$AJ6)*(1+$AQ6)*(1+$AR6)+(($AT6+$AU6)/2*IF($G$1="鸣金",$AK6,$AI6)+IF($G$1="鸣金",$AL6*1.5,0))*(1+$AV6)*(1+$AW6)+(($AX6+$AY6)/2*IF($G$1="裂石",$AK6,$AI6)+IF($G$1="裂石",$AL6*1.5,0))*(1+$AZ6)*(1+$BA6)+(($BB6+$BC6)/2*IF($G$1="牵丝",$AK6,$AI6)+IF($G$1="牵丝",$AL6*1.5,0))*(1+$BD6)*(1+$BE6)+(($BF6+$BG6)/2*IF($G$1="破竹",$AK6,$AI6)+IF($G$1="破竹",$AL6*1.5,0))*(1+$BH6)*(1+$BI6))*(1+$AM6)*$BL6*$Q6*(1+IF(VLOOKUP($R6,武学奇术!$A:$ZZ,30,FALSE)="回旋伞",$B$21,0))*(1+$BR6) -> 33605.814 | N6: =(($AP6*$AI6+$AJ6)*(1+$AQ6)*(1+$AR6)+($AU6*IF($G$1="鸣金",$AK6,$AI6)+IF($G$1="鸣金",$AL6*1.5,0))*(1+$AV6)*(1+$AW6)+($AY6*IF($G$1="裂石",$AK6,$AI6)+IF($G$1="裂石",$AL6*1.5,0))*(1+$AZ6)*(1+$BA6)+($BC6*IF($G$1="牵丝",$AK6,$AI6)+IF($G$1="牵丝",$AL6*1.5,0))*(1+$BD6)*(1+$BE6)+($BG6*IF($G$1="破竹",$AK6,$AI6)+IF($G$1="破竹",$AL6*1.5,0))*(1+$BH6)*(1+$BI6))*(1+$AM6)*$BN6*$Q6*(1+IF(VLOOKUP($R6,武学奇术!$A:$ZZ,30,FALSE)="回旋伞",$B$21,0))*(1+$BR6) -> 27784.525 | O6: =((($AO6+$AP6)/2*$AI6+$AJ6)*(1+$AQ6)*(1+$AR6)+(($AT6+$AU6)/2*IF($G$1="鸣金",$AK6,$AI6)+IF($G$1="鸣金",$AL6*1.5,0))*(1+$AV6)*(1+$AW6)+(($AX6+$AY6)/2*IF($G$1="裂石",$AK6,$AI6)+IF($G$1="裂石",$AL6*1.5,0))*(1+$AZ6)*(1+$BA6)+(($BB6+$BC6)/2*IF($G$1="牵丝",$AK6,$AI6)+IF($G$1="牵丝",$AL6*1.5,0))*(1+$BD6)*(1+$BE6)+(($BF6+$BG6)/2*IF($G$1="破竹",$AK6,$AI6)+IF($G$1="破竹",$AL6*1.5,0))*(1+$BH6)*(1+$BI6))*(1+$AM6)*$Q6*(1+IF(VLOOKUP($R6,武学奇术!$A:$ZZ,30,FALSE)="回旋伞",$B$21,0))*(1+$BR6) -> 18165.305 | P6: =((($AO6*$AI6+$AJ6)*(1+$AQ6)*(1+$AR6)+($AT6*IF($G$1="鸣金",$AK6,$AI6)+IF($G$1="鸣金",$AL6*1.5,0))*(1+$AV6)*(1+$AW6)+($AX6*IF($G$1="裂石",$AK6,$AI6)+IF($G$1="裂石",$AL6*1.5,0))*(1+$AZ6)*(1+$BA6)+($BB6*IF($G$1="牵丝",$AK6,$AI6)+IF($G$1="牵丝",$AL6*1.5,0))*(1+$BD6)*(1+$BE6)+($BF6*IF($G$1="破竹",$AK6,$AI6)+IF($G$1="破竹",$AL6*1.5,0))*(1+$BH6)*(1+$BI6))*(1+$AM6))*$Q6*(1+IF(VLOOKUP($R6,武学奇术!$A:$ZZ,30,FALSE)="回旋伞",$B$21,0))*(1+$BR6) -> 15749.481 | Q6: 1 | R6: 萧呤千浪流星 | S6: N/a | T6: 幻鸣5层 | U6: 失魂落魄 | V6: 远程笛 | W6: 沧海帖4层 | X6: 易水歌5层 | Y6: 惧刃(拐) | Z6: N/a | AA6: N/a | AB6: N/a | AC6: 扶风(拐) | AD6: N/a | AE6: N/a | AF6: 裁云(拐) | AG6: 无惧 | AH6: =VLOOKUP($R6,武学奇术!$A:$ZZ,25,FALSE) -> 群体奇术 | AI6: =VLOOKUP($R6,武学奇术!$A:$ZZ,26,FALSE) -> 1.4904 | AJ6: =VLOOKUP($R6,武学奇术!$A:$ZZ,27,FALSE)*(1+IF(OR($AH6=$F$4,$AH6=$F$5),$B$22,0)) -> 378 | AK6: =VLOOKUP($R6,武学奇术!$A:$ZZ,28,FALSE) -> 2.2356 | AL6: =VLOOKUP($R6,武学奇术!$A:$ZZ,29,FALSE)*(1+IF(OR($AH6=$F$4,$AH6=$F$5),$B$22,0)) -> 0 | AM6: {=$G$3+IFERROR(VLOOKUP($AH6,$F$4:$G$7,2,FALSE),0)+VLOOKUP($R6,武学奇术!$A:$ZZ,2,FALSE)+SUM(_xlfn.XLOOKUP($S6:$AG6,增益!$A:$A,增益!$B:$B,0))} -> 0.4837 | AN6: {=VLOOKUP($R6,武学奇术!$A:$ZZ,5,FALSE)+SUM(_xlfn.XLOOKUP($S6:$AG6,增益!$A:$A,增益!$E:$E,0))} -> 0 | AO6: {=$D$10*(1+$AN6)+VLOOKUP($R6,武学奇术!$A:$ZZ,3,FALSE)+SUM(_xlfn.XLOOKUP($S6:$AG6,增益!$A:$A,增益!$C:$C,0))-$I$2} -> 3624.6 | AP6: {=$E$10*(1+$AN6)+VLOOKUP($R6,武学奇术!$A:$ZZ,4,FALSE)+SUM(_xlfn.XLOOKUP($S6:$AG6,增益!$A:$A,增益!$D:$D,0))-$I$2} -> 3624.6 | AQ6: {=IF($F$10-$I$3+VLOOKUP($R6,武学奇术!$A:$ZZ,6,FALSE)+SUM(_xlfn.XLOOKUP(S6:AG6,增益!$A:$A,增益!$F:$F,0))>0,($F$10-$I$3+VLOOKUP($R6,武学奇术!$A:$ZZ,6,FALSE)+SUM(_xlfn.XLOOKUP(S6:AG6,增益!$A:$A,增益!$F:$F,0)))/200,($F$10-$I$3+VLOOKUP($R6,武学奇术!$A:$ZZ,6,FALSE)+SUM(_xlfn.XLOOKUP(S6:AG6,增益!$A:$A,增益!$F:$F,0)))/100)} -> 0.3425 | AR6: {=$G$10+VLOOKUP($R6,武学奇术!$A:$ZZ,7,FALSE)+SUM(_xlfn.XLOOKUP(S6:AG6,增益!$A:$A,增益!$G:$G,0))} -> 0.028 | AS6: {=VLOOKUP($R6,武学奇术!$A:$ZZ,8,FALSE)+SUM(_xlfn.XLOOKUP(S6:AG6,增益!$A:$A,增益!$H:$H,0))} -> 0 | AT6: =$D$11*(1+$AS6) -> 0 | AU6: =$E$11*(1+$AS6) -> 0 | AV6: {=IF($F$11-$I$4+VLOOKUP($R6,武学奇术!$A:$ZZ,9,FALSE)+SUM(_xlfn.XLOOKUP(S6:AG6,增益!$A:$A,增益!$I:$I,0))>0,($F$11-$I$4+VLOOKUP($R6,武学奇术!$A:$ZZ,9,FALSE)+SUM(_xlfn.XLOOKUP(S6:AG6,增益!$A:$A,增益!$I:$I,0)))/200,($F$11-$I$4+VLOOKUP($R6,武学奇术!$A:$ZZ,9,FALSE)+SUM(_xlfn.XLOOKUP(S6:AG6,增益!$A:$A,增益!$I:$I,0)))/100)} -> -0.14 | AW6: {=$G$11+VLOOKUP($R6,武学奇术!$A:$ZZ,10,FALSE)+SUM(_xlfn.XLOOKUP(S6:AG6,增益!$A:$A,增益!$J:$J,0))} -> 0 | AX6: =$D$12*(1+$AS6) -> 0 | AY6: =$E$12*(1+$AS6) -> 0 | AZ6: {=IF($F$12-$I$4+VLOOKUP($R6,武学奇术!$A:$ZZ,11,FALSE)+SUM(_xlfn.XLOOKUP(S6:AG6,增益!$A:$A,增益!$K:$K,0))>0,($F$12-$I$4+VLOOKUP($R6,武学奇术!$A:$ZZ,11,FALSE)+SUM(_xlfn.XLOOKUP(S6:AG6,增益!$A:$A,增益!$K:$K,0)))/200,($F$12-$I$4+VLOOKUP($R6,武学奇术!$A:$ZZ,11,FALSE)+SUM(_xlfn.XLOOKUP(S6:AG6,增益!$A:$A,增益!$K:$K,0)))/100)} -> -0.14 | BA6: {=$G$12+VLOOKUP($R6,武学奇术!$A:$ZZ,12,FALSE)+SUM(_xlfn.XLOOKUP(S6:AG6,增益!$A:$A,增益!$L:$L,0))} -> 0 | BB6: =$D$13*(1+$AS6) -> 0 | BC6: =$E$13*(1+$AS6) -> 0 | BD6: {=IF($F$13-$I$4+VLOOKUP($R6,武学奇术!$A:$ZZ,13,FALSE)+SUM(_xlfn.XLOOKUP(S6:AG6,增益!$A:$A,增益!$M:$M,0))>0,($F$13-$I$4+VLOOKUP($R6,武学奇术!$A:$ZZ,13,FALSE)+SUM(_xlfn.XLOOKUP(S6:AG6,增益!$A:$A,增益!$K:$K,0)))/200,($F$13-$I$4+VLOOKUP($R6,武学奇术!$A:$ZZ,13,FALSE)+SUM(_xlfn.XLOOKUP(S6:AG6,增益!$A:$A,增益!$M:$M,0)))/100)} -> -0.14 | BE6: {=$G$13+VLOOKUP($R6,武学奇术!$A:$ZZ,14,FALSE)+SUM(_xlfn.XLOOKUP(S6:AG6,增益!$A:$A,增益!$N:$N,0))} -> 0 | BF6: =$D$14*(1+$AS6) -> 571.2 | BG6: =$E$14*(1+$AS6) -> 1627.8 | BH6: {=IF($F$14-$I$4+VLOOKUP($R6,武学奇术!$A:$ZZ,15,FALSE)+SUM(_xlfn.XLOOKUP(S6:AG6,增益!$A:$A,增益!$O:$O,0))>0,($F$14-$I$4+VLOOKUP($R6,武学奇术!$A:$ZZ,15,FALSE)+SUM(_xlfn.XLOOKUP(S6:AG6,增益!$A:$A,增益!$O:$O,0)))/200,($F$14-$I$4+VLOOKUP($R6,武学奇术!$A:$ZZ,15,FALSE)+SUM(_xlfn.XLOOKUP(S6:AG6,增益!$A:$A,增益!$O:$O,0)))/100)} -> 0.08 | BI6: {=$G$14+VLOOKUP($R6,武学奇术!$A:$ZZ,16,FALSE)+SUM(_xlfn.XLOOKUP(S6:AG6,增益!$A:$A,增益!$P:$P,0))} -> 0.15 | BJ6: =MIN(IF(VLOOKUP($R6,武学奇术!$A:$ZZ,23,FALSE)=1,100%,$B$8),100%) -> 0.981 | BK6: {=IF(VLOOKUP($R6,武学奇术!$A:$ZZ,23,FALSE)=1,100%,MIN(80%,$B$9+VLOOKUP($R6,武学奇术!$A:$ZZ,17,FALSE)+SUM(_xlfn.XLOOKUP(S6:AG6,增益!$A:$A,增益!$Q:$Q,0)))+$B$11+SUM(_xlfn.XLOOKUP(S6:AG6,增益!$A:$A,增益!$U:$U,0)))*IF(VLOOKUP($R6,武学奇术!$A:$ZZ,24,FALSE)=1,0,1)} -> 0.846 | BL6: {=1+$B$13+VLOOKUP($R6,武学奇术!$A:$ZZ,18,FALSE)+SUM(_xlfn.XLOOKUP(S6:AG6,增益!$A:$A,增益!$R:$R,0))} -> 1.85 | BM6: {=IF(VLOOKUP($R6,武学奇术!$A:$ZZ,24,FALSE)=1,100%,MIN(40%,$B$10+VLOOKUP($R6,武学奇术!$A:$ZZ,19,FALSE)+SUM(_xlfn.XLOOKUP(S6:AG6,增益!$A:$A,增益!$S:$S,0)))+$B$12+SUM(_xlfn.XLOOKUP(S6:AG6,增益!$A:$A,增益!$V:$V,0)))*IF(VLOOKUP($R6,武学奇术!$A:$ZZ,23,FALSE)=1,0,1)} -> 0.0929 | BN6: {=1+$B$14+VLOOKUP($R6,武学奇术!$A:$ZZ,20,FALSE)+SUM(_xlfn.XLOOKUP(S6:AG6,增益!$A:$A,增益!$T:$T,0))} -> 1.35 | BO6: =MIN((1-BM6)*BJ6,BJ6*BK6) -> 0.829926 | BP6: =1-BM6-BO6-BQ6 -> 0.0599391 | BQ6: =IF(VLOOKUP($R6,武学奇术!$A:$ZZ,22,FALSE)=1,0,(1-$BJ6))*(1-$BM6) -> 0.0172349 | BR6: {=SUM(_xlfn.XLOOKUP(S6:AG6,增益!$A:$A,增益!$W:$W,0))+$I$5} -> 0.11
A7: 无相 | B7: 79.2 | C7: =92.4+68.8*2 -> 230 | F7: 群体奇术 | G7: =B20 -> 0 | K7: =$L7*VLOOKUP($R7,武学奇术!$A:$ZZ,31,FALSE) -> 19406.751 | L7: =($M7*$BO7+$N7*$BM7+$O7*$BP7+$P7*$BQ7) -> 18482.62 | M7: =((($AO7+$AP7)/2*$AI7+$AJ7)*(1+$AQ7)*(1+$AR7)+(($AT7+$AU7)/2*IF($G$1="鸣金",$AK7,$AI7)+IF($G$1="鸣金",$AL7*1.5,0))*(1+$AV7)*(1+$AW7)+(($AX7+$AY7)/2*IF($G$1="裂石",$AK7,$AI7)+IF($G$1="裂石",$AL7*1.5,0))*(1+$AZ7)*(1+$BA7)+(($BB7+$BC7)/2*IF($G$1="牵丝",$AK7,$AI7)+IF($G$1="牵丝",$AL7*1.5,0))*(1+$BD7)*(1+$BE7)+(($BF7+$BG7)/2*IF($G$1="破竹",$AK7,$AI7)+IF($G$1="破竹",$AL7*1.5,0))*(1+$BH7)*(1+$BI7))*(1+$AM7)*$BL7*$Q7*(1+IF(VLOOKUP($R7,武学奇术!$A:$ZZ,30,FALSE)="回旋伞",$B$21,0))*(1+$BR7) -> 19071.531 | N7: =(($AP7*$AI7+$AJ7)*(1+$AQ7)*(1+$AR7)+($AU7*IF($G$1="鸣金",$AK7,$AI7)+IF($G$1="鸣金",$AL7*1.5,0))*(1+$AV7)*(1+$AW7)+($AY7*IF($G$1="裂石",$AK7,$AI7)+IF($G$1="裂石",$AL7*1.5,0))*(1+$AZ7)*(1+$BA7)+($BC7*IF($G$1="牵丝",$AK7,$AI7)+IF($G$1="牵丝",$AL7*1.5,0))*(1+$BD7)*(1+$BE7)+($BG7*IF($G$1="破竹",$AK7,$AI7)+IF($G$1="破竹",$AL7*1.5,0))*(1+$BH7)*(1+$BI7))*(1+$AM7)*$BN7*$Q7*(1+IF(VLOOKUP($R7,武学奇术!$A:$ZZ,30,FALSE)="回旋伞",$B$21,0))*(1+$BR7) -> 18631.845 | O7: =((($AO7+$AP7)/2*$AI7+$AJ7)*(1+$AQ7)*(1+$AR7)+(($AT7+$AU7)/2*IF($G$1="鸣金",$AK7,$AI7)+IF($G$1="鸣金",$AL7*1.5,0))*(1+$AV7)*(1+$AW7)+(($AX7+$AY7)/2*IF($G$1="裂石",$AK7,$AI7)+IF($G$1="裂石",$AL7*1.5,0))*(1+$AZ7)*(1+$BA7)+(($BB7+$BC7)/2*IF($G$1="牵丝",$AK7,$AI7)+IF($G$1="牵丝",$AL7*1.5,0))*(1+$BD7)*(1+$BE7)+(($BF7+$BG7)/2*IF($G$1="破竹",$AK7,$AI7)+IF($G$1="破竹",$AL7*1.5,0))*(1+$BH7)*(1+$BI7))*(1+$AM7)*$Q7*(1+IF(VLOOKUP($R7,武学奇术!$A:$ZZ,30,FALSE)="回旋伞",$B$21,0))*(1+$BR7) -> 12304.213 | P7: =((($AO7*$AI7+$AJ7)*(1+$AQ7)*(1+$AR7)+($AT7*IF($G$1="鸣金",$AK7,$AI7)+IF($G$1="鸣金",$AL7*1.5,0))*(1+$AV7)*(1+$AW7)+($AX7*IF($G$1="裂石",$AK7,$AI7)+IF($G$1="裂石",$AL7*1.5,0))*(1+$AZ7)*(1+$BA7)+($BB7*IF($G$1="牵丝",$AK7,$AI7)+IF($G$1="牵丝",$AL7*1.5,0))*(1+$BD7)*(1+$BE7)+($BF7*IF($G$1="破竹",$AK7,$AI7)+IF($G$1="破竹",$AL7*1.5,0))*(1+$BH7)*(1+$BI7))*(1+$AM7))*$Q7*(1+IF(VLOOKUP($R7,武学奇术!$A:$ZZ,30,FALSE)="回旋伞",$B$21,0))*(1+$BR7) -> 10807.06 | Q7: 1 | R7: R蓄123 | S7: N/a | T7: N/a | U7: N/a | V7: N/a | W7: 沧海帖1层 | X7: 易水歌1层 | Y7: N/a | Z7: N/a | AA7: N/a | AB7: N/a | AC7: N/a | AD7: N/a | AE7: N/a | AF7: 裁云(拐) | AG7: 无惧 | AH7: =VLOOKUP($R7,武学奇术!$A:$ZZ,25,FALSE) -> 绳镖 | AI7: =VLOOKUP($R7,武学奇术!$A:$ZZ,26,FALSE) -> 1.1137 | AJ7: =VLOOKUP($R7,武学奇术!$A:$ZZ,27,FALSE)*(1+IF(OR($AH7=$F$4,$AH7=$F$5),$B$22,0)) -> 463.5 | AK7: =VLOOKUP($R7,武学奇术!$A:$ZZ,28,FALSE) -> 1.6706 | AL7: =VLOOKUP($R7,武学奇术!$A:$ZZ,29,FALSE)*(1+IF(OR($AH7=$F$4,$AH7=$F$5),$B$22,0)) -> 252 | AM7: {=$G$3+IFERROR(VLOOKUP($AH7,$F$4:$G$7,2,FALSE),0)+VLOOKUP($R7,武学奇术!$A:$ZZ,2,FALSE)+SUM(_xlfn.XLOOKUP($S7:$AG7,增益!$A:$A,增益!$B:$B,0))} -> 0.3289 | AN7: {=VLOOKUP($R7,武学奇术!$A:$ZZ,5,FALSE)+SUM(_xlfn.XLOOKUP($S7:$AG7,增益!$A:$A,增益!$E:$E,0))} -> 0 | AO7: {=$D$10*(1+$AN7)+VLOOKUP($R7,武学奇术!$A:$ZZ,3,FALSE)+SUM(_xlfn.XLOOKUP($S7:$AG7,增益!$A:$A,增益!$C:$C,0))-$I$2} -> 3624.6 | AP7: {=$E$10*(1+$AN7)+VLOOKUP($R7,武学奇术!$A:$ZZ,4,FALSE)+SUM(_xlfn.XLOOKUP($S7:$AG7,增益!$A:$A,增益!$D:$D,0))-$I$2} -> 3624.6 | AQ7: {=IF($F$10-$I$3+VLOOKUP($R7,武学奇术!$A:$ZZ,6,FALSE)+SUM(_xlfn.XLOOKUP(S7:AG7,增益!$A:$A,增益!$F:$F,0))>0,($F$10-$I$3+VLOOKUP($R7,武学奇术!$A:$ZZ,6,FALSE)+SUM(_xlfn.XLOOKUP(S7:AG7,增益!$A:$A,增益!$F:$F,0)))/200,($F$10-$I$3+VLOOKUP($R7,武学奇术!$A:$ZZ,6,FALSE)+SUM(_xlfn.XLOOKUP(S7:AG7,增益!$A:$A,增益!$F:$F,0)))/100)} -> 0.2525 | AR7: {=$G$10+VLOOKUP($R7,武学奇术!$A:$ZZ,7,FALSE)+SUM(_xlfn.XLOOKUP(S7:AG7,增益!$A:$A,增益!$G:$G,0))} -> 0.028 | AS7: {=VLOOKUP($R7,武学奇术!$A:$ZZ,8,FALSE)+SUM(_xlfn.XLOOKUP(S7:AG7,增益!$A:$A,增益!$H:$H,0))} -> 0 | AT7: =$D$11*(1+$AS7) -> 0 | AU7: =$E$11*(1+$AS7) -> 0 | AV7: {=IF($F$11-$I$4+VLOOKUP($R7,武学奇术!$A:$ZZ,9,FALSE)+SUM(_xlfn.XLOOKUP(S7:AG7,增益!$A:$A,增益!$I:$I,0))>0,($F$11-$I$4+VLOOKUP($R7,武学奇术!$A:$ZZ,9,FALSE)+SUM(_xlfn.XLOOKUP(S7:AG7,增益!$A:$A,增益!$I:$I,0)))/200,($F$11-$I$4+VLOOKUP($R7,武学奇术!$A:$ZZ,9,FALSE)+SUM(_xlfn.XLOOKUP(S7:AG7,增益!$A:$A,增益!$I:$I,0)))/100)} -> -0.3 | AW7: {=$G$11+VLOOKUP($R7,武学奇术!$A:$ZZ,10,FALSE)+SUM(_xlfn.XLOOKUP(S7:AG7,增益!$A:$A,增益!$J:$J,0))} -> 0 | AX7: =$D$12*(1+$AS7) -> 0 | AY7: =$E$12*(1+$AS7) -> 0 | AZ7: {=IF($F$12-$I$4+VLOOKUP($R7,武学奇术!$A:$ZZ,11,FALSE)+SUM(_xlfn.XLOOKUP(S7:AG7,增益!$A:$A,增益!$K:$K,0))>0,($F$12-$I$4+VLOOKUP($R7,武学奇术!$A:$ZZ,11,FALSE)+SUM(_xlfn.XLOOKUP(S7:AG7,增益!$A:$A,增益!$K:$K,0)))/200,($F$12-$I$4+VLOOKUP($R7,武学奇术!$A:$ZZ,11,FALSE)+SUM(_xlfn.XLOOKUP(S7:AG7,增益!$A:$A,增益!$K:$K,0)))/100)} -> -0.3 | BA7: {=$G$12+VLOOKUP($R7,武学奇术!$A:$ZZ,12,FALSE)+SUM(_xlfn.XLOOKUP(S7:AG7,增益!$A:$A,增益!$L:$L,0))} -> 0 | BB7: =$D$13*(1+$AS7) -> 0 | BC7: =$E$13*(1+$AS7) -> 0 | BD7: {=IF($F$13-$I$4+VLOOKUP($R7,武学奇术!$A:$ZZ,13,FALSE)+SUM(_xlfn.XLOOKUP(S7:AG7,增益!$A:$A,增益!$M:$M,0))>0,($F$13-$I$4+VLOOKUP($R7,武学奇术!$A:$ZZ,13,FALSE)+SUM(_xlfn.XLOOKUP(S7:AG7,增益!$A:$A,增益!$K:$K,0)))/200,($F$13-$I$4+VLOOKUP($R7,武学奇术!$A:$ZZ,13,FALSE)+SUM(_xlfn.XLOOKUP(S7:AG7,增益!$A:$A,增益!$M:$M,0)))/100)} -> -0.3 | BE7: {=$G$13+VLOOKUP($R7,武学奇术!$A:$ZZ,14,FALSE)+SUM(_xlfn.XLOOKUP(S7:AG7,增益!$A:$A,增益!$N:$N,0))} -> 0 | BF7: =$D$14*(1+$AS7) -> 571.2 | BG7: =$E$14*(1+$AS7) -> 1627.8 | BH7: {=IF($F$14-$I$4+VLOOKUP($R7,武学奇术!$A:$ZZ,15,FALSE)+SUM(_xlfn.XLOOKUP(S7:AG7,增益!$A:$A,增益!$O:$O,0))>0,($F$14-$I$4+VLOOKUP($R7,武学奇术!$A:$ZZ,15,FALSE)+SUM(_xlfn.XLOOKUP(S7:AG7,增益!$A:$A,增益!$O:$O,0)))/200,($F$14-$I$4+VLOOKUP($R7,武学奇术!$A:$ZZ,15,FALSE)+SUM(_xlfn.XLOOKUP(S7:AG7,增益!$A:$A,增益!$O:$O,0)))/100)} -> 0 | BI7: {=$G$14+VLOOKUP($R7,武学奇术!$A:$ZZ,16,FALSE)+SUM(_xlfn.XLOOKUP(S7:AG7,增益!$A:$A,增益!$P:$P,0))} -> 0.15 | BJ7: =MIN(IF(VLOOKUP($R7,武学奇术!$A:$ZZ,23,FALSE)=1,100%,$B$8),100%) -> 0.981 | BK7: {=IF(VLOOKUP($R7,武学奇术!$A:$ZZ,23,FALSE)=1,100%,MIN(80%,$B$9+VLOOKUP($R7,武学奇术!$A:$ZZ,17,FALSE)+SUM(_xlfn.XLOOKUP(S7:AG7,增益!$A:$A,增益!$Q:$Q,0)))+$B$11+SUM(_xlfn.XLOOKUP(S7:AG7,增益!$A:$A,增益!$U:$U,0)))*IF(VLOOKUP($R7,武学奇术!$A:$ZZ,24,FALSE)=1,0,1)} -> 0.846 | BL7: {=1+$B$13+VLOOKUP($R7,武学奇术!$A:$ZZ,18,FALSE)+SUM(_xlfn.XLOOKUP(S7:AG7,增益!$A:$A,增益!$R:$R,0))} -> 1.55 | BM7: {=IF(VLOOKUP($R7,武学奇术!$A:$ZZ,24,FALSE)=1,100%,MIN(40%,$B$10+VLOOKUP($R7,武学奇术!$A:$ZZ,19,FALSE)+SUM(_xlfn.XLOOKUP(S7:AG7,增益!$A:$A,增益!$S:$S,0)))+$B$12+SUM(_xlfn.XLOOKUP(S7:AG7,增益!$A:$A,增益!$V:$V,0)))*IF(VLOOKUP($R7,武学奇术!$A:$ZZ,23,FALSE)=1,0,1)} -> 0.0929 | BN7: {=1+$B$14+VLOOKUP($R7,武学奇术!$A:$ZZ,20,FALSE)+SUM(_xlfn.XLOOKUP(S7:AG7,增益!$A:$A,增益!$T:$T,0))} -> 1.35 | BO7: =MIN((1-BM7)*BJ7,BJ7*BK7) -> 0.829926 | BP7: =1-BM7-BO7-BQ7 -> 0.0599391 | BQ7: =IF(VLOOKUP($R7,武学奇术!$A:$ZZ,22,FALSE)=1,0,(1-$BJ7))*(1-$BM7) -> 0.0172349 | BR7: {=SUM(_xlfn.XLOOKUP(S7:AG7,增益!$A:$A,增益!$W:$W,0))+$I$5} -> 0.11
A8: 精准率 | B8: 0.981 | C8: 实际属性 | H8: 战斗时间 | I8: 101 | K8: =$L8*VLOOKUP($R8,武学奇术!$A:$ZZ,31,FALSE) -> 14534.316 | L8: =($M8*$BO8+$N8*$BM8+$O8*$BP8+$P8*$BQ8) -> 13842.206 | M8: =((($AO8+$AP8)/2*$AI8+$AJ8)*(1+$AQ8)*(1+$AR8)+(($AT8+$AU8)/2*IF($G$1="鸣金",$AK8,$AI8)+IF($G$1="鸣金",$AL8*1.5,0))*(1+$AV8)*(1+$AW8)+(($AX8+$AY8)/2*IF($G$1="裂石",$AK8,$AI8)+IF($G$1="裂石",$AL8*1.5,0))*(1+$AZ8)*(1+$BA8)+(($BB8+$BC8)/2*IF($G$1="牵丝",$AK8,$AI8)+IF($G$1="牵丝",$AL8*1.5,0))*(1+$BD8)*(1+$BE8)+(($BF8+$BG8)/2*IF($G$1="破竹",$AK8,$AI8)+IF($G$1="破竹",$AL8*1.5,0))*(1+$BH8)*(1+$BI8))*(1+$AM8)*$BL8*$Q8*(1+IF(VLOOKUP($R8,武学奇术!$A:$ZZ,30,FALSE)="回旋伞",$B$21,0))*(1+$BR8) -> 14276.539 | N8: =(($AP8*$AI8+$AJ8)*(1+$AQ8)*(1+$AR8)+($AU8*IF($G$1="鸣金",$AK8,$AI8)+IF($G$1="鸣金",$AL8*1.5,0))*(1+$AV8)*(1+$AW8)+($AY8*IF($G$1="裂石",$AK8,$AI8)+IF($G$1="裂石",$AL8*1.5,0))*(1+$AZ8)*(1+$BA8)+($BC8*IF($G$1="牵丝",$AK8,$AI8)+IF($G$1="牵丝",$AL8*1.5,0))*(1+$BD8)*(1+$BE8)+($BG8*IF($G$1="破竹",$AK8,$AI8)+IF($G$1="破竹",$AL8*1.5,0))*(1+$BH8)*(1+$BI8))*(1+$AM8)*$BN8*$Q8*(1+IF(VLOOKUP($R8,武学奇术!$A:$ZZ,30,FALSE)="回旋伞",$B$21,0))*(1+$BR8) -> 14028.676 | O8: =((($AO8+$AP8)/2*$AI8+$AJ8)*(1+$AQ8)*(1+$AR8)+(($AT8+$AU8)/2*IF($G$1="鸣金",$AK8,$AI8)+IF($G$1="鸣金",$AL8*1.5,0))*(1+$AV8)*(1+$AW8)+(($AX8+$AY8)/2*IF($G$1="裂石",$AK8,$AI8)+IF($G$1="裂石",$AL8*1.5,0))*(1+$AZ8)*(1+$BA8)+(($BB8+$BC8)/2*IF($G$1="牵丝",$AK8,$AI8)+IF($G$1="牵丝",$AL8*1.5,0))*(1+$BD8)*(1+$BE8)+(($BF8+$BG8)/2*IF($G$1="破竹",$AK8,$AI8)+IF($G$1="破竹",$AL8*1.5,0))*(1+$BH8)*(1+$BI8))*(1+$AM8)*$Q8*(1+IF(VLOOKUP($R8,武学奇术!$A:$ZZ,30,FALSE)="回旋伞",$B$21,0))*(1+$BR8) -> 9210.6704 | P8: =((($AO8*$AI8+$AJ8)*(1+$AQ8)*(1+$AR8)+($AT8*IF($G$1="鸣金",$AK8,$AI8)+IF($G$1="鸣金",$AL8*1.5,0))*(1+$AV8)*(1+$AW8)+($AX8*IF($G$1="裂石",$AK8,$AI8)+IF($G$1="裂石",$AL8*1.5,0))*(1+$AZ8)*(1+$BA8)+($BB8*IF($G$1="牵丝",$AK8,$AI8)+IF($G$1="牵丝",$AL8*1.5,0))*(1+$BD8)*(1+$BE8)+($BF8*IF($G$1="破竹",$AK8,$AI8)+IF($G$1="破竹",$AL8*1.5,0))*(1+$BH8)*(1+$BI8))*(1+$AM8))*$Q8*(1+IF(VLOOKUP($R8,武学奇术!$A:$ZZ,30,FALSE)="回旋伞",$B$21,0))*(1+$BR8) -> 8029.729 | Q8: 1 | R8: R蓄45 | S8: N/a | T8: N/a | U8: N/a | V8: N/a | W8: 沧海帖1层 | X8: 易水歌1层 | Y8: 惧刃(拐) | Z8: N/a | AA8: N/a | AB8: N/a | AC8: 扶风(拐) | AD8: N/a | AE8: N/a | AF8: 裁云(拐) | AG8: 无惧 | AH8: =VLOOKUP($R8,武学奇术!$A:$ZZ,25,FALSE) -> 绳镖 | AI8: =VLOOKUP($R8,武学奇术!$A:$ZZ,26,FALSE) -> 0.7839 | AJ8: =VLOOKUP($R8,武学奇术!$A:$ZZ,27,FALSE)*(1+IF(OR($AH8=$F$4,$AH8=$F$5),$B$22,0)) -> 327 | AK8: =VLOOKUP($R8,武学奇术!$A:$ZZ,28,FALSE) -> 1.1759 | AL8: =VLOOKUP($R8,武学奇术!$A:$ZZ,29,FALSE)*(1+IF(OR($AH8=$F$4,$AH8=$F$5),$B$22,0)) -> 178.5 | AM8: {=$G$3+IFERROR(VLOOKUP($AH8,$F$4:$G$7,2,FALSE),0)+VLOOKUP($R8,武学奇术!$A:$ZZ,2,FALSE)+SUM(_xlfn.XLOOKUP($S8:$AG8,增益!$A:$A,增益!$B:$B,0))} -> 0.3789 | AN8: {=VLOOKUP($R8,武学奇术!$A:$ZZ,5,FALSE)+SUM(_xlfn.XLOOKUP($S8:$AG8,增益!$A:$A,增益!$E:$E,0))} -> 0 | AO8: {=$D$10*(1+$AN8)+VLOOKUP($R8,武学奇术!$A:$ZZ,3,FALSE)+SUM(_xlfn.XLOOKUP($S8:$AG8,增益!$A:$A,增益!$C:$C,0))-$I$2} -> 3624.6 | AP8: {=$E$10*(1+$AN8)+VLOOKUP($R8,武学奇术!$A:$ZZ,4,FALSE)+SUM(_xlfn.XLOOKUP($S8:$AG8,增益!$A:$A,增益!$D:$D,0))-$I$2} -> 3624.6 | AQ8: {=IF($F$10-$I$3+VLOOKUP($R8,武学奇术!$A:$ZZ,6,FALSE)+SUM(_xlfn.XLOOKUP(S8:AG8,增益!$A:$A,增益!$F:$F,0))>0,($F$10-$I$3+VLOOKUP($R8,武学奇术!$A:$ZZ,6,FALSE)+SUM(_xlfn.XLOOKUP(S8:AG8,增益!$A:$A,增益!$F:$F,0)))/200,($F$10-$I$3+VLOOKUP($R8,武学奇术!$A:$ZZ,6,FALSE)+SUM(_xlfn.XLOOKUP(S8:AG8,增益!$A:$A,增益!$F:$F,0)))/100)} -> 0.2525 | AR8: {=$G$10+VLOOKUP($R8,武学奇术!$A:$ZZ,7,FALSE)+SUM(_xlfn.XLOOKUP(S8:AG8,增益!$A:$A,增益!$G:$G,0))} -> 0.028 | AS8: {=VLOOKUP($R8,武学奇术!$A:$ZZ,8,FALSE)+SUM(_xlfn.XLOOKUP(S8:AG8,增益!$A:$A,增益!$H:$H,0))} -> 0 | AT8: =$D$11*(1+$AS8) -> 0 | AU8: =$E$11*(1+$AS8) -> 0 | AV8: {=IF($F$11-$I$4+VLOOKUP($R8,武学奇术!$A:$ZZ,9,FALSE)+SUM(_xlfn.XLOOKUP(S8:AG8,增益!$A:$A,增益!$I:$I,0))>0,($F$11-$I$4+VLOOKUP($R8,武学奇术!$A:$ZZ,9,FALSE)+SUM(_xlfn.XLOOKUP(S8:AG8,增益!$A:$A,增益!$I:$I,0)))/200,($F$11-$I$4+VLOOKUP($R8,武学奇术!$A:$ZZ,9,FALSE)+SUM(_xlfn.XLOOKUP(S8:AG8,增益!$A:$A,增益!$I:$I,0)))/100)} -> -0.14 | AW8: {=$G$11+VLOOKUP($R8,武学奇术!$A:$ZZ,10,FALSE)+SUM(_xlfn.XLOOKUP(S8:AG8,增益!$A:$A,增益!$J:$J,0))} -> 0 | AX8: =$D$12*(1+$AS8) -> 0 | AY8: =$E$12*(1+$AS8) -> 0 | AZ8: {=IF($F$12-$I$4+VLOOKUP($R8,武学奇术!$A:$ZZ,11,FALSE)+SUM(_xlfn.XLOOKUP(S8:AG8,增益!$A:$A,增益!$K:$K,0))>0,($F$12-$I$4+VLOOKUP($R8,武学奇术!$A:$ZZ,11,FALSE)+SUM(_xlfn.XLOOKUP(S8:AG8,增益!$A:$A,增益!$K:$K,0)))/200,($F$12-$I$4+VLOOKUP($R8,武学奇术!$A:$ZZ,11,FALSE)+SUM(_xlfn.XLOOKUP(S8:AG8,增益!$A:$A,增益!$K:$K,0)))/100)} -> -0.14 | BA8: {=$G$12+VLOOKUP($R8,武学奇术!$A:$ZZ,12,FALSE)+SUM(_xlfn.XLOOKUP(S8:AG8,增益!$A:$A,增益!$L:$L,0))} -> 0 | BB8: =$D$13*(1+$AS8) -> 0 | BC8: =$E$13*(1+$AS8) -> 0 | BD8: {=IF($F$13-$I$4+VLOOKUP($R8,武学奇术!$A:$ZZ,13,FALSE)+SUM(_xlfn.XLOOKUP(S8:AG8,增益!$A:$A,增益!$M:$M,0))>0,($F$13-$I$4+VLOOKUP($R8,武学奇术!$A:$ZZ,13,FALSE)+SUM(_xlfn.XLOOKUP(S8:AG8,增益!$A:$A,增益!$K:$K,0)))/200,($F$13-$I$4+VLOOKUP($R8,武学奇术!$A:$ZZ,13,FALSE)+SUM(_xlfn.XLOOKUP(S8:AG8,增益!$A:$A,增益!$M:$M,0)))/100)} -> -0.14 | BE8: {=$G$13+VLOOKUP($R8,武学奇术!$A:$ZZ,14,FALSE)+SUM(_xlfn.XLOOKUP(S8:AG8,增益!$A:$A,增益!$N:$N,0))} -> 0 | BF8: =$D$14*(1+$AS8) -> 571.2 | BG8: =$E$14*(1+$AS8) -> 1627.8 | BH8: {=IF($F$14-$I$4+VLOOKUP($R8,武学奇术!$A:$ZZ,15,FALSE)+SUM(_xlfn.XLOOKUP(S8:AG8,增益!$A:$A,增益!$O:$O,0))>0,($F$14-$I$4+VLOOKUP($R8,武学奇术!$A:$ZZ,15,FALSE)+SUM(_xlfn.XLOOKUP(S8:AG8,增益!$A:$A,增益!$O:$O,0)))/200,($F$14-$I$4+VLOOKUP($R8,武学奇术!$A:$ZZ,15,FALSE)+SUM(_xlfn.XLOOKUP(S8:AG8,增益!$A:$A,增益!$O:$O,0)))/100)} -> 0.08 | BI8: {=$G$14+VLOOKUP($R8,武学奇术!$A:$ZZ,16,FALSE)+SUM(_xlfn.XLOOKUP(S8:AG8,增益!$A:$A,增益!$P:$P,0))} -> 0.15 | BJ8: =MIN(IF(VLOOKUP($R8,武学奇术!$A:$ZZ,23,FALSE)=1,100%,$B$8),100%) -> 0.981 | BK8: {=IF(VLOOKUP($R8,武学奇术!$A:$ZZ,23,FALSE)=1,100%,MIN(80%,$B$9+VLOOKUP($R8,武学奇术!$A:$ZZ,17,FALSE)+SUM(_xlfn.XLOOKUP(S8:AG8,增益!$A:$A,增益!$Q:$Q,0)))+$B$11+SUM(_xlfn.XLOOKUP(S8:AG8,增益!$A:$A,增益!$U:$U,0)))*IF(VLOOKUP($R8,武学奇术!$A:$ZZ,24,FALSE)=1,0,1)} -> 0.846 | BL8: {=1+$B$13+VLOOKUP($R8,武学奇术!$A:$ZZ,18,FALSE)+SUM(_xlfn.XLOOKUP(S8:AG8,增益!$A:$A,增益!$R:$R,0))} -> 1.55 | BM8: {=IF(VLOOKUP($R8,武学奇术!$A:$ZZ,24,FALSE)=1,100%,MIN(40%,$B$10+VLOOKUP($R8,武学奇术!$A:$ZZ,19,FALSE)+SUM(_xlfn.XLOOKUP(S8:AG8,增益!$A:$A,增益!$S:$S,0)))+$B$12+SUM(_xlfn.XLOOKUP(S8:AG8,增益!$A:$A,增益!$V:$V,0)))*IF(VLOOKUP($R8,武学奇术!$A:$ZZ,23,FALSE)=1,0,1)} -> 0.0929 | BN8: {=1+$B$14+VLOOKUP($R8,武学奇术!$A:$ZZ,20,FALSE)+SUM(_xlfn.XLOOKUP(S8:AG8,增益!$A:$A,增益!$T:$T,0))} -> 1.35 | BO8: =MIN((1-BM8)*BJ8,BJ8*BK8) -> 0.829926 | BP8: =1-BM8-BO8-BQ8 -> 0.0599391 | BQ8: =IF(VLOOKUP($R8,武学奇术!$A:$ZZ,22,FALSE)=1,0,(1-$BJ8))*(1-$BM8) -> 0.0172349 | BR8: {=SUM(_xlfn.XLOOKUP(S8:AG8,增益!$A:$A,增益!$W:$W,0))+$I$5} -> 0.11
A9: 会心率 | B9: 0.8049 | D9: 最小攻击 | E9: 最大攻击 | F9: 穿透 | G9: 伤害加成 | K9: =$L9*VLOOKUP($R9,武学奇术!$A:$ZZ,31,FALSE) -> 75193.991 | L9: =($M9*$BO9+$N9*$BM9+$O9*$BP9+$P9*$BQ9) -> 71613.324 | M9: =((($AO9+$AP9)/2*$AI9+$AJ9)*(1+$AQ9)*(1+$AR9)+(($AT9+$AU9)/2*IF($G$1="鸣金",$AK9,$AI9)+IF($G$1="鸣金",$AL9*1.5,0))*(1+$AV9)*(1+$AW9)+(($AX9+$AY9)/2*IF($G$1="裂石",$AK9,$AI9)+IF($G$1="裂石",$AL9*1.5,0))*(1+$AZ9)*(1+$BA9)+(($BB9+$BC9)/2*IF($G$1="牵丝",$AK9,$AI9)+IF($G$1="牵丝",$AL9*1.5,0))*(1+$BD9)*(1+$BE9)+(($BF9+$BG9)/2*IF($G$1="破竹",$AK9,$AI9)+IF($G$1="破竹",$AL9*1.5,0))*(1+$BH9)*(1+$BI9))*(1+$AM9)*$BL9*$Q9*(1+IF(VLOOKUP($R9,武学奇术!$A:$ZZ,30,FALSE)="回旋伞",$B$21,0))*(1+$BR9) -> 75480.34 | N9: =(($AP9*$AI9+$AJ9)*(1+$AQ9)*(1+$AR9)+($AU9*IF($G$1="鸣金",$AK9,$AI9)+IF($G$1="鸣金",$AL9*1.5,0))*(1+$AV9)*(1+$AW9)+($AY9*IF($G$1="裂石",$AK9,$AI9)+IF($G$1="裂石",$AL9*1.5,0))*(1+$AZ9)*(1+$BA9)+($BC9*IF($G$1="牵丝",$AK9,$AI9)+IF($G$1="牵丝",$AL9*1.5,0))*(1+$BD9)*(1+$BE9)+($BG9*IF($G$1="破竹",$AK9,$AI9)+IF($G$1="破竹",$AL9*1.5,0))*(1+$BH9)*(1+$BI9))*(1+$AM9)*$BN9*$Q9*(1+IF(VLOOKUP($R9,武学奇术!$A:$ZZ,30,FALSE)="回旋伞",$B$21,0))*(1+$BR9) -> 63080.237 | O9: =((($AO9+$AP9)/2*$AI9+$AJ9)*(1+$AQ9)*(1+$AR9)+(($AT9+$AU9)/2*IF($G$1="鸣金",$AK9,$AI9)+IF($G$1="鸣金",$AL9*1.5,0))*(1+$AV9)*(1+$AW9)+(($AX9+$AY9)/2*IF($G$1="裂石",$AK9,$AI9)+IF($G$1="裂石",$AL9*1.5,0))*(1+$AZ9)*(1+$BA9)+(($BB9+$BC9)/2*IF($G$1="牵丝",$AK9,$AI9)+IF($G$1="牵丝",$AL9*1.5,0))*(1+$BD9)*(1+$BE9)+(($BF9+$BG9)/2*IF($G$1="破竹",$AK9,$AI9)+IF($G$1="破竹",$AL9*1.5,0))*(1+$BH9)*(1+$BI9))*(1+$AM9)*$Q9*(1+IF(VLOOKUP($R9,武学奇术!$A:$ZZ,30,FALSE)="回旋伞",$B$21,0))*(1+$BR9) -> 41472.714 | P9: =((($AO9*$AI9+$AJ9)*(1+$AQ9)*(1+$AR9)+($AT9*IF($G$1="鸣金",$AK9,$AI9)+IF($G$1="鸣金",$AL9*1.5,0))*(1+$AV9)*(1+$AW9)+($AX9*IF($G$1="裂石",$AK9,$AI9)+IF($G$1="裂石",$AL9*1.5,0))*(1+$AZ9)*(1+$BA9)+($BB9*IF($G$1="牵丝",$AK9,$AI9)+IF($G$1="牵丝",$AL9*1.5,0))*(1+$BD9)*(1+$BE9)+($BF9*IF($G$1="破竹",$AK9,$AI9)+IF($G$1="破竹",$AL9*1.5,0))*(1+$BH9)*(1+$BI9))*(1+$AM9))*$Q9*(1+IF(VLOOKUP($R9,武学奇术!$A:$ZZ,30,FALSE)="回旋伞",$B$21,0))*(1+$BR9) -> 36219.327 | Q9: 1 | R9: 完美伞 | S9: 连星(8+) | T9: N/a | U9: 失魂落魄 | V9: 远程笛 | W9: 沧海帖1层 | X9: 易水歌2层 | Y9: 惧刃(拐) | Z9: N/a | AA9: N/a | AB9: N/a | AC9: 扶风(拐) | AD9: N/a | AE9: N/a | AF9: 裁云(拐) | AG9: 无惧 | AH9: =VLOOKUP($R9,武学奇术!$A:$ZZ,25,FALSE) -> 伞 | AI9: =VLOOKUP($R9,武学奇术!$A:$ZZ,26,FALSE) -> 1.8084 | AJ9: =VLOOKUP($R9,武学奇术!$A:$ZZ,27,FALSE)*(1+IF(OR($AH9=$F$4,$AH9=$F$5),$B$22,0)) -> 750 | AK9: =VLOOKUP($R9,武学奇术!$A:$ZZ,28,FALSE) -> 2.7126 | AL9: =VLOOKUP($R9,武学奇术!$A:$ZZ,29,FALSE)*(1+IF(OR($AH9=$F$4,$AH9=$F$5),$B$22,0)) -> 408 | AM9: {=$G$3+IFERROR(VLOOKUP($AH9,$F$4:$G$7,2,FALSE),0)+VLOOKUP($R9,武学奇术!$A:$ZZ,2,FALSE)+SUM(_xlfn.XLOOKUP($S9:$AG9,增益!$A:$A,增益!$B:$B,0))} -> 0.8241 | AN9: {=VLOOKUP($R9,武学奇术!$A:$ZZ,5,FALSE)+SUM(_xlfn.XLOOKUP($S9:$AG9,增益!$A:$A,增益!$E:$E,0))} -> 0 | AO9: {=$D$10*(1+$AN9)+VLOOKUP($R9,武学奇术!$A:$ZZ,3,FALSE)+SUM(_xlfn.XLOOKUP($S9:$AG9,增益!$A:$A,增益!$C:$C,0))-$I$2} -> 3624.6 | AP9: {=$E$10*(1+$AN9)+VLOOKUP($R9,武学奇术!$A:$ZZ,4,FALSE)+SUM(_xlfn.XLOOKUP($S9:$AG9,增益!$A:$A,增益!$D:$D,0))-$I$2} -> 3624.6 | AQ9: {=IF($F$10-$I$3+VLOOKUP($R9,武学奇术!$A:$ZZ,6,FALSE)+SUM(_xlfn.XLOOKUP(S9:AG9,增益!$A:$A,增益!$F:$F,0))>0,($F$10-$I$3+VLOOKUP($R9,武学奇术!$A:$ZZ,6,FALSE)+SUM(_xlfn.XLOOKUP(S9:AG9,增益!$A:$A,增益!$F:$F,0)))/200,($F$10-$I$3+VLOOKUP($R9,武学奇术!$A:$ZZ,6,FALSE)+SUM(_xlfn.XLOOKUP(S9:AG9,增益!$A:$A,增益!$F:$F,0)))/100)} -> 0.2625 | AR9: {=$G$10+VLOOKUP($R9,武学奇术!$A:$ZZ,7,FALSE)+SUM(_xlfn.XLOOKUP(S9:AG9,增益!$A:$A,增益!$G:$G,0))} -> 0.148 | AS9: {=VLOOKUP($R9,武学奇术!$A:$ZZ,8,FALSE)+SUM(_xlfn.XLOOKUP(S9:AG9,增益!$A:$A,增益!$H:$H,0))} -> 0 | AT9: =$D$11*(1+$AS9) -> 0 | AU9: =$E$11*(1+$AS9) -> 0 | AV9: {=IF($F$11-$I$4+VLOOKUP($R9,武学奇术!$A:$ZZ,9,FALSE)+SUM(_xlfn.XLOOKUP(S9:AG9,增益!$A:$A,增益!$I:$I,0))>0,($F$11-$I$4+VLOOKUP($R9,武学奇术!$A:$ZZ,9,FALSE)+SUM(_xlfn.XLOOKUP(S9:AG9,增益!$A:$A,增益!$I:$I,0)))/200,($F$11-$I$4+VLOOKUP($R9,武学奇术!$A:$ZZ,9,FALSE)+SUM(_xlfn.XLOOKUP(S9:AG9,增益!$A:$A,增益!$I:$I,0)))/100)} -> -0.14 | AW9: {=$G$11+VLOOKUP($R9,武学奇术!$A:$ZZ,10,FALSE)+SUM(_xlfn.XLOOKUP(S9:AG9,增益!$A:$A,增益!$J:$J,0))} -> 0 | AX9: =$D$12*(1+$AS9) -> 0 | AY9: =$E$12*(1+$AS9) -> 0 | AZ9: {=IF($F$12-$I$4+VLOOKUP($R9,武学奇术!$A:$ZZ,11,FALSE)+SUM(_xlfn.XLOOKUP(S9:AG9,增益!$A:$A,增益!$K:$K,0))>0,($F$12-$I$4+VLOOKUP($R9,武学奇术!$A:$ZZ,11,FALSE)+SUM(_xlfn.XLOOKUP(S9:AG9,增益!$A:$A,增益!$K:$K,0)))/200,($F$12-$I$4+VLOOKUP($R9,武学奇术!$A:$ZZ,11,FALSE)+SUM(_xlfn.XLOOKUP(S9:AG9,增益!$A:$A,增益!$K:$K,0)))/100)} -> -0.14 | BA9: {=$G$12+VLOOKUP($R9,武学奇术!$A:$ZZ,12,FALSE)+SUM(_xlfn.XLOOKUP(S9:AG9,增益!$A:$A,增益!$L:$L,0))} -> 0 | BB9: =$D$13*(1+$AS9) -> 0 | BC9: =$E$13*(1+$AS9) -> 0 | BD9: {=IF($F$13-$I$4+VLOOKUP($R9,武学奇术!$A:$ZZ,13,FALSE)+SUM(_xlfn.XLOOKUP(S9:AG9,增益!$A:$A,增益!$M:$M,0))>0,($F$13-$I$4+VLOOKUP($R9,武学奇术!$A:$ZZ,13,FALSE)+SUM(_xlfn.XLOOKUP(S9:AG9,增益!$A:$A,增益!$K:$K,0)))/200,($F$13-$I$4+VLOOKUP($R9,武学奇术!$A:$ZZ,13,FALSE)+SUM(_xlfn.XLOOKUP(S9:AG9,增益!$A:$A,增益!$M:$M,0)))/100)} -> -0.14 | BE9: {=$G$13+VLOOKUP($R9,武学奇术!$A:$ZZ,14,FALSE)+SUM(_xlfn.XLOOKUP(S9:AG9,增益!$A:$A,增益!$N:$N,0))} -> 0 | BF9: =$D$14*(1+$AS9) -> 571.2 | BG9: =$E$14*(1+$AS9) -> 1627.8 | BH9: {=IF($F$14-$I$4+VLOOKUP($R9,武学奇术!$A:$ZZ,15,FALSE)+SUM(_xlfn.XLOOKUP(S9:AG9,增益!$A:$A,增益!$O:$O,0))>0,($F$14-$I$4+VLOOKUP($R9,武学奇术!$A:$ZZ,15,FALSE)+SUM(_xlfn.XLOOKUP(S9:AG9,增益!$A:$A,增益!$O:$O,0)))/200,($F$14-$I$4+VLOOKUP($R9,武学奇术!$A:$ZZ,15,FALSE)+SUM(_xlfn.XLOOKUP(S9:AG9,增益!$A:$A,增益!$O:$O,0)))/100)} -> 0.08 | BI9: {=$G$14+VLOOKUP($R9,武学奇术!$A:$ZZ,16,FALSE)+SUM(_xlfn.XLOOKUP(S9:AG9,增益!$A:$A,增益!$P:$P,0))} -> 0.27 | BJ9: =MIN(IF(VLOOKUP($R9,武学奇术!$A:$ZZ,23,FALSE)=1,100%,$B$8),100%) -> 0.981 | BK9: {=IF(VLOOKUP($R9,武学奇术!$A:$ZZ,23,FALSE)=1,100%,MIN(80%,$B$9+VLOOKUP($R9,武学奇术!$A:$ZZ,17,FALSE)+SUM(_xlfn.XLOOKUP(S9:AG9,增益!$A:$A,增益!$Q:$Q,0)))+$B$11+SUM(_xlfn.XLOOKUP(S9:AG9,增益!$A:$A,增益!$U:$U,0)))*IF(VLOOKUP($R9,武学奇术!$A:$ZZ,24,FALSE)=1,0,1)} -> 0.846 | BL9: {=1+$B$13+VLOOKUP($R9,武学奇术!$A:$ZZ,18,FALSE)+SUM(_xlfn.XLOOKUP(S9:AG9,增益!$A:$A,增益!$R:$R,0))} -> 1.82 | BM9: {=IF(VLOOKUP($R9,武学奇术!$A:$ZZ,24,FALSE)=1,100%,MIN(40%,$B$10+VLOOKUP($R9,武学奇术!$A:$ZZ,19,FALSE)+SUM(_xlfn.XLOOKUP(S9:AG9,增益!$A:$A,增益!$S:$S,0)))+$B$12+SUM(_xlfn.XLOOKUP(S9:AG9,增益!$A:$A,增益!$V:$V,0)))*IF(VLOOKUP($R9,武学奇术!$A:$ZZ,23,FALSE)=1,0,1)} -> 0.0929 | BN9: {=1+$B$14+VLOOKUP($R9,武学奇术!$A:$ZZ,20,FALSE)+SUM(_xlfn.XLOOKUP(S9:AG9,增益!$A:$A,增益!$T:$T,0))} -> 1.35 | BO9: =MIN((1-BM9)*BJ9,BJ9*BK9) -> 0.829926 | BP9: =1-BM9-BO9-BQ9 -> 0.0599391 | BQ9: =IF(VLOOKUP($R9,武学奇术!$A:$ZZ,22,FALSE)=1,0,(1-$BJ9))*(1-$BM9) -> 0.0172349 | BR9: {=SUM(_xlfn.XLOOKUP(S9:AG9,增益!$A:$A,增益!$W:$W,0))+$I$5} -> 0.11
A10: 会意率 | B10: 0.0929 | C10: 外功 | D10: =(B2+B23)*IF($G$2="撼天",1.06,1) -> 4182.6 | E10: =MAX(B2+B23,C2+B24)*IF($G$2="撼天",1.06,1) -> 4182.6 | F10: =D2 -> 63.5 | G10: =E2 -> 0.028 | H10: 总伤 | I10: =SUM(L:L) -> 13394742 | K10: =$L10*VLOOKUP($R10,武学奇术!$A:$ZZ,31,FALSE) -> 43693.327 | L10: =($M10*$BO10+$N10*$BM10+$O10*$BP10+$P10*$BQ10) -> 41612.692 | M10: =((($AO10+$AP10)/2*$AI10+$AJ10)*(1+$AQ10)*(1+$AR10)+(($AT10+$AU10)/2*IF($G$1="鸣金",$AK10,$AI10)+IF($G$1="鸣金",$AL10*1.5,0))*(1+$AV10)*(1+$AW10)+(($AX10+$AY10)/2*IF($G$1="裂石",$AK10,$AI10)+IF($G$1="裂石",$AL10*1.5,0))*(1+$AZ10)*(1+$BA10)+(($BB10+$BC10)/2*IF($G$1="牵丝",$AK10,$AI10)+IF($G$1="牵丝",$AL10*1.5,0))*(1+$BD10)*(1+$BE10)+(($BF10+$BG10)/2*IF($G$1="破竹",$AK10,$AI10)+IF($G$1="破竹",$AL10*1.5,0))*(1+$BH10)*(1+$BI10))*(1+$AM10)*$BL10*$Q10*(1+IF(VLOOKUP($R10,武学奇术!$A:$ZZ,30,FALSE)="回旋伞",$B$21,0))*(1+$BR10) -> 43810.437 | N10: =(($AP10*$AI10+$AJ10)*(1+$AQ10)*(1+$AR10)+($AU10*IF($G$1="鸣金",$AK10,$AI10)+IF($G$1="鸣金",$AL10*1.5,0))*(1+$AV10)*(1+$AW10)+($AY10*IF($G$1="裂石",$AK10,$AI10)+IF($G$1="裂石",$AL10*1.5,0))*(1+$AZ10)*(1+$BA10)+($BC10*IF($G$1="牵丝",$AK10,$AI10)+IF($G$1="牵丝",$AL10*1.5,0))*(1+$BD10)*(1+$BE10)+($BG10*IF($G$1="破竹",$AK10,$AI10)+IF($G$1="破竹",$AL10*1.5,0))*(1+$BH10)*(1+$BI10))*(1+$AM10)*$BN10*$Q10*(1+IF(VLOOKUP($R10,武学奇术!$A:$ZZ,30,FALSE)="回旋伞",$B$21,0))*(1+$BR10) -> 37196.621 | O10: =((($AO10+$AP10)/2*$AI10+$AJ10)*(1+$AQ10)*(1+$AR10)+(($AT10+$AU10)/2*IF($G$1="鸣金",$AK10,$AI10)+IF($G$1="鸣金",$AL10*1.5,0))*(1+$AV10)*(1+$AW10)+(($AX10+$AY10)/2*IF($G$1="裂石",$AK10,$AI10)+IF($G$1="裂石",$AL10*1.5,0))*(1+$AZ10)*(1+$BA10)+(($BB10+$BC10)/2*IF($G$1="牵丝",$AK10,$AI10)+IF($G$1="牵丝",$AL10*1.5,0))*(1+$BD10)*(1+$BE10)+(($BF10+$BG10)/2*IF($G$1="破竹",$AK10,$AI10)+IF($G$1="破竹",$AL10*1.5,0))*(1+$BH10)*(1+$BI10))*(1+$AM10)*$Q10*(1+IF(VLOOKUP($R10,武学奇术!$A:$ZZ,30,FALSE)="回旋伞",$B$21,0))*(1+$BR10) -> 24071.668 | P10: =((($AO10*$AI10+$AJ10)*(1+$AQ10)*(1+$AR10)+($AT10*IF($G$1="鸣金",$AK10,$AI10)+IF($G$1="鸣金",$AL10*1.5,0))*(1+$AV10)*(1+$AW10)+($AX10*IF($G$1="裂石",$AK10,$AI10)+IF($G$1="裂石",$AL10*1.5,0))*(1+$AZ10)*(1+$BA10)+($BB10*IF($G$1="牵丝",$AK10,$AI10)+IF($G$1="牵丝",$AL10*1.5,0))*(1+$BD10)*(1+$BE10)+($BF10*IF($G$1="破竹",$AK10,$AI10)+IF($G$1="破竹",$AL10*1.5,0))*(1+$BH10)*(1+$BI10))*(1+$AM10))*$Q10*(1+IF(VLOOKUP($R10,武学奇术!$A:$ZZ,30,FALSE)="回旋伞",$B$21,0))*(1+$BR10) -> 20590.284 | Q10: 2 | R10: 共鸣 | S10: 连星(8+) | T10: N/a | U10: 失魂落魄 | V10: 远程笛 | W10: 沧海帖1层 | X10: 易水歌2层 | Y10: 惧刃(拐) | Z10: N/a | AA10: N/a | AB10: N/a | AC10: 扶风(拐) | AD10: N/a | AE10: N/a | AF10: 裁云(拐) | AG10: 无惧 | AH10: =VLOOKUP($R10,武学奇术!$A:$ZZ,25,FALSE) -> 伞 | AI10: =VLOOKUP($R10,武学奇术!$A:$ZZ,26,FALSE) -> 0.54 | AJ10: =VLOOKUP($R10,武学奇术!$A:$ZZ,27,FALSE)*(1+IF(OR($AH10=$F$4,$AH10=$F$5),$B$22,0)) -> 0 | AK10: =VLOOKUP($R10,武学奇术!$A:$ZZ,28,FALSE) -> 0.81 | AL10: =VLOOKUP($R10,武学奇术!$A:$ZZ,29,FALSE)*(1+IF(OR($AH10=$F$4,$AH10=$F$5),$B$22,0)) -> 0 | AM10: {=$G$3+IFERROR(VLOOKUP($AH10,$F$4:$G$7,2,FALSE),0)+VLOOKUP($R10,武学奇术!$A:$ZZ,2,FALSE)+SUM(_xlfn.XLOOKUP($S10:$AG10,增益!$A:$A,增益!$B:$B,0))} -> 1.0241 | AN10: {=VLOOKUP($R10,武学奇术!$A:$ZZ,5,FALSE)+SUM(_xlfn.XLOOKUP($S10:$AG10,增益!$A:$A,增益!$E:$E,0))} -> 0 | AO10: {=$D$10*(1+$AN10)+VLOOKUP($R10,武学奇术!$A:$ZZ,3,FALSE)+SUM(_xlfn.XLOOKUP($S10:$AG10,增益!$A:$A,增益!$C:$C,0))-$I$2} -> 3624.6 | AP10: {=$E$10*(1+$AN10)+VLOOKUP($R10,武学奇术!$A:$ZZ,4,FALSE)+SUM(_xlfn.XLOOKUP($S10:$AG10,增益!$A:$A,增益!$D:$D,0))-$I$2} -> 3624.6 | AQ10: {=IF($F$10-$I$3+VLOOKUP($R10,武学奇术!$A:$ZZ,6,FALSE)+SUM(_xlfn.XLOOKUP(S10:AG10,增益!$A:$A,增益!$F:$F,0))>0,($F$10-$I$3+VLOOKUP($R10,武学奇术!$A:$ZZ,6,FALSE)+SUM(_xlfn.XLOOKUP(S10:AG10,增益!$A:$A,增益!$F:$F,0)))/200,($F$10-$I$3+VLOOKUP($R10,武学奇术!$A:$ZZ,6,FALSE)+SUM(_xlfn.XLOOKUP(S10:AG10,增益!$A:$A,增益!$F:$F,0)))/100)} -> 0.2625 | AR10: {=$G$10+VLOOKUP($R10,武学奇术!$A:$ZZ,7,FALSE)+SUM(_xlfn.XLOOKUP(S10:AG10,增益!$A:$A,增益!$G:$G,0))} -> 0.148 | AS10: {=VLOOKUP($R10,武学奇术!$A:$ZZ,8,FALSE)+SUM(_xlfn.XLOOKUP(S10:AG10,增益!$A:$A,增益!$H:$H,0))} -> 0 | AT10: =$D$11*(1+$AS10) -> 0 | AU10: =$E$11*(1+$AS10) -> 0 | AV10: {=IF($F$11-$I$4+VLOOKUP($R10,武学奇术!$A:$ZZ,9,FALSE)+SUM(_xlfn.XLOOKUP(S10:AG10,增益!$A:$A,增益!$I:$I,0))>0,($F$11-$I$4+VLOOKUP($R10,武学奇术!$A:$ZZ,9,FALSE)+SUM(_xlfn.XLOOKUP(S10:AG10,增益!$A:$A,增益!$I:$I,0)))/200,($F$11-$I$4+VLOOKUP($R10,武学奇术!$A:$ZZ,9,FALSE)+SUM(_xlfn.XLOOKUP(S10:AG10,增益!$A:$A,增益!$I:$I,0)))/100)} -> -0.14 | AW10: {=$G$11+VLOOKUP($R10,武学奇术!$A:$ZZ,10,FALSE)+SUM(_xlfn.XLOOKUP(S10:AG10,增益!$A:$A,增益!$J:$J,0))} -> 0 | AX10: =$D$12*(1+$AS10) -> 0 | AY10: =$E$12*(1+$AS10) -> 0 | AZ10: {=IF($F$12-$I$4+VLOOKUP($R10,武学奇术!$A:$ZZ,11,FALSE)+SUM(_xlfn.XLOOKUP(S10:AG10,增益!$A:$A,增益!$K:$K,0))>0,($F$12-$I$4+VLOOKUP($R10,武学奇术!$A:$ZZ,11,FALSE)+SUM(_xlfn.XLOOKUP(S10:AG10,增益!$A:$A,增益!$K:$K,0)))/200,($F$12-$I$4+VLOOKUP($R10,武学奇术!$A:$ZZ,11,FALSE)+SUM(_xlfn.XLOOKUP(S10:AG10,增益!$A:$A,增益!$K:$K,0)))/100)} -> -0.14 | BA10: {=$G$12+VLOOKUP($R10,武学奇术!$A:$ZZ,12,FALSE)+SUM(_xlfn.XLOOKUP(S10:AG10,增益!$A:$A,增益!$L:$L,0))} -> 0 | BB10: =$D$13*(1+$AS10) -> 0 | BC10: =$E$13*(1+$AS10) -> 0 | BD10: {=IF($F$13-$I$4+VLOOKUP($R10,武学奇术!$A:$ZZ,13,FALSE)+SUM(_xlfn.XLOOKUP(S10:AG10,增益!$A:$A,增益!$M:$M,0))>0,($F$13-$I$4+VLOOKUP($R10,武学奇术!$A:$ZZ,13,FALSE)+SUM(_xlfn.XLOOKUP(S10:AG10,增益!$A:$A,增益!$K:$K,0)))/200,($F$13-$I$4+VLOOKUP($R10,武学奇术!$A:$ZZ,13,FALSE)+SUM(_xlfn.XLOOKUP(S10:AG10,增益!$A:$A,增益!$M:$M,0)))/100)} -> -0.14 | BE10: {=$G$13+VLOOKUP($R10,武学奇术!$A:$ZZ,14,FALSE)+SUM(_xlfn.XLOOKUP(S10:AG10,增益!$A:$A,增益!$N:$N,0))} -> 0 | BF10: =$D$14*(1+$AS10) -> 571.2 | BG10: =$E$14*(1+$AS10) -> 1627.8 | BH10: {=IF($F$14-$I$4+VLOOKUP($R10,武学奇术!$A:$ZZ,15,FALSE)+SUM(_xlfn.XLOOKUP(S10:AG10,增益!$A:$A,增益!$O:$O,0))>0,($F$14-$I$4+VLOOKUP($R10,武学奇术!$A:$ZZ,15,FALSE)+SUM(_xlfn.XLOOKUP(S10:AG10,增益!$A:$A,增益!$O:$O,0)))/200,($F$14-$I$4+VLOOKUP($R10,武学奇术!$A:$ZZ,15,FALSE)+SUM(_xlfn.XLOOKUP(S10:AG10,增益!$A:$A,增益!$O:$O,0)))/100)} -> 0.08 | BI10: {=$G$14+VLOOKUP($R10,武学奇术!$A:$ZZ,16,FALSE)+SUM(_xlfn.XLOOKUP(S10:AG10,增益!$A:$A,增益!$P:$P,0))} -> 0.27 | BJ10: =MIN(IF(VLOOKUP($R10,武学奇术!$A:$ZZ,23,FALSE)=1,100%,$B$8),100%) -> 0.981 | BK10: {=IF(VLOOKUP($R10,武学奇术!$A:$ZZ,23,FALSE)=1,100%,MIN(80%,$B$9+VLOOKUP($R10,武学奇术!$A:$ZZ,17,FALSE)+SUM(_xlfn.XLOOKUP(S10:AG10,增益!$A:$A,增益!$Q:$Q,0)))+$B$11+SUM(_xlfn.XLOOKUP(S10:AG10,增益!$A:$A,增益!$U:$U,0)))*IF(VLOOKUP($R10,武学奇术!$A:$ZZ,24,FALSE)=1,0,1)} -> 0.846 | BL10: {=1+$B$13+VLOOKUP($R10,武学奇术!$A:$ZZ,18,FALSE)+SUM(_xlfn.XLOOKUP(S10:AG10,增益!$A:$A,增益!$R:$R,0))} -> 1.82 | BM10: {=IF(VLOOKUP($R10,武学奇术!$A:$ZZ,24,FALSE)=1,100%,MIN(40%,$B$10+VLOOKUP($R10,武学奇术!$A:$ZZ,19,FALSE)+SUM(_xlfn.XLOOKUP(S10:AG10,增益!$A:$A,增益!$S:$S,0)))+$B$12+SUM(_xlfn.XLOOKUP(S10:AG10,增益!$A:$A,增益!$V:$V,0)))*IF(VLOOKUP($R10,武学奇术!$A:$ZZ,23,FALSE)=1,0,1)} -> 0.0929 | BN10: {=1+$B$14+VLOOKUP($R10,武学奇术!$A:$ZZ,20,FALSE)+SUM(_xlfn.XLOOKUP(S10:AG10,增益!$A:$A,增益!$T:$T,0))} -> 1.35 | BO10: =MIN((1-BM10)*BJ10,BJ10*BK10) -> 0.829926 | BP10: =1-BM10-BO10-BQ10 -> 0.0599391 | BQ10: =IF(VLOOKUP($R10,武学奇术!$A:$ZZ,22,FALSE)=1,0,(1-$BJ10))*(1-$BM10) -> 0.0172349 | BR10: {=SUM(_xlfn.XLOOKUP(S10:AG10,增益!$A:$A,增益!$W:$W,0))+$I$5} -> 0.11
