Workbook

Sheet 期望
B1: 最小攻击 | C1: 最大攻击 | D1: 穿透 | E1: 伤害加成 | F1: 武学属性 | G1: 破竹 | H1: 怪物属性 | K1: 期望 | L1: 会心期望 | M1: 会意期望 | N1: 普通期望 | O1: 擦伤期望 | P1: 次数 | Q1: 技能 | R1: 增益1 | S1: 增益2 | T1: 增益3 | U1: 增益4 | V1: 增益5 | W1: 增益6 | X1: 增益7 | Y1: 增益8 | Z1: 增益9 | AA1: 增益10 | AB1: 增益11 | AC1: 增益12 | AD1: 增益13 | AE1: 增益14 | AF1: 增益15 | AG1: 类型 | AH1: 外功倍率 | AI1: 外攻固伤 | AJ1: 属性倍率 | AK1: 属性固伤 | AL1: 通用增伤 | AM1: 外攻加成 | AN1: 即时小外 | AO1: 即时大外 | AP1: 外穿加成 | AQ1: 外伤加成 | AR1: 属攻加成 | AS1: 即时小鸣 | AT1: 即时大鸣 | AU1: 鸣金穿透 | AV1: 鸣金加成 | AW1: 即时小裂 | AX1: 即时大裂 | AY1: 裂石穿透 | AZ1: 裂石加成 | BA1: 即时小牵 | BB1: 即时大牵 | BC1: 牵丝穿透 | BD1: 牵丝加成 | BE1: 即时小破 | BF1: 即时大破 | BG1: 破竹穿透 | BH1: 破竹加成 | BI1: 生效精准 | BJ1: 生效会心 | BK1: 生效会心伤害 | BL1: 生效会意 | BM1: 生效会意伤害 | BN1: 会心占比 | BO1: 普攻占比 | BP1: 擦伤占比 | BQ1: 特殊增伤
A2: 外功 | B2: 3915.1 | C2: 2944.8 | D2: =58.4+IF($C$24="征人归",5.1,0) -> 58.4 | E2: =IF($C$22="三穷致知",2.5%,0) -> 0 | F2: 套装 | G2: 撼天 | H2: 防御 | I2: =620*(1-IF(F17="√",0.06,0)-IF(D20="√",0.04,0)) -> 558 | K2: =($L2*$BN2+$M2*$BL2+$N2*$BO2+$O2*$BP2) -> 23731.25 | L2: =((($AN2+($AO2-$AN2)*IF(VLOOKUP($Q2,武学奇术!$A:$ZZ,31,FALSE)=1,$F$18,0.5))*$AH2+$AI2)*(1+$AP2)*(1+$AQ2)+(($AS2+($AT2-$AS2)*IF(VLOOKUP($Q2,武学奇术!$A:$ZZ,31,FALSE)=1,$F$18,0.5))*IF($G$1="鸣金",$AJ2,$AH2)+IF($G$1="鸣金",$AK2*1.5,0))*(1+$AU2)*(1+$AV2)+(($AW2+($AX2-$AW2)*IF(VLOOKUP($Q2,武学奇术!$A:$ZZ,31,FALSE)=1,$F$18,0.5))*IF($G$1="裂石",$AJ2,$AH2)+IF($G$1="裂石",$AK2*1.5,0))*(1+$AY2)*(1+$AZ2)+(($BA2+($BB2-$BA2)*IF(VLOOKUP($Q2,武学奇术!$A:$ZZ,31,FALSE)=1,$F$18,0.5))*IF($G$1="牵丝",$AJ2,$AH2)+IF($G$1="牵丝",$AK2*1.5,0))*(1+$BC2)*(1+$BD2)+(($BE2+($BF2-$BE2)*IF(VLOOKUP($Q2,武学奇术!$A:$ZZ,31,FALSE)=1,$F$18,0.5))*IF($G$1="破竹",$AJ2,$AH2)+IF($G$1="破竹",$AK2*1.5,0))*(1+$BG2)*(1+$BH2))*(1+$AL2)*$BK2*$P2*(1+IF(VLOOKUP($Q2,武学奇术!$A:$ZZ,30,FALSE)="蓄力技",$B$21,0))*(1+$BQ2) -> 23777.574 | M2: =(($AO2*$AH2+$AI2)*(1+$AP2)*(1+$AQ2)+($AT2*IF($G$1="鸣金",$AJ2,$AH2)+IF($G$1="鸣金",$AK2*1.5,0))*(1+$AU2)*(1+$AV2)+($AX2*IF($G$1="裂石",$AJ2,$AH2)+IF($G$1="裂石",$AK2*1.5,0))*(1+$AY2)*(1+$AZ2)+($BB2*IF($G$1="牵丝",$AJ2,$AH2)+IF($G$1="牵丝",$AK2*1.5,0))*(1+$BC2)*(1+$BD2)+($BF2*IF($G$1="破竹",$AJ2,$AH2)+IF($G$1="破竹",$AK2*1.5,0))*(1+$BG2)*(1+$BH2))*(1+$AL2)*$BM2*$P2*(1+IF(VLOOKUP($Q2,武学奇术!$A:$ZZ,30,FALSE)="蓄力技",$B$21,0))*(1+$BQ2) -> 23259.985 | N2: =((($AN2+($AO2-$AN2)*IF(VLOOKUP($Q2,武学奇术!$A:$ZZ,31,FALSE)=1,$F$18,0.5))*$AH2+$AI2)*(1+$AP2)*(1+$AQ2)+(($AS2+($AT2-$AS2)*IF(VLOOKUP($Q2,武学奇术!$A:$ZZ,31,FALSE)=1,$F$18,0.5))*IF($G$1="鸣金",$AJ2,$AH2)+IF($G$1="鸣金",$AK2*1.5,0))*(1+$AU2)*(1+$AV2)+(($AW2+($AX2-$AW2)*IF(VLOOKUP($Q2,武学奇术!$A:$ZZ,31,FALSE)=1,$F$18,0.5))*IF($G$1="裂石",$AJ2,$AH2)+IF($G$1="裂石",$AK2*1.5,0))*(1+$AY2)*(1+$AZ2)+(($BA2+($BB2-$BA2)*IF(VLOOKUP($Q2,武学奇术!$A:$ZZ,31,FALSE)=1,$F$18,0.5))*IF($G$1="牵丝",$AJ2,$AH2)+IF($G$1="牵丝",$AK2*1.5,0))*(1+$BC2)*(1+$BD2)+(($BE2+($BF2-$BE2)*IF(VLOOKUP($Q2,武学奇术!$A:$ZZ,31,FALSE)=1,$F$18,0.5))*IF($G$1="破竹",$AJ2,$AH2)+IF($G$1="破竹",$AK2*1.5,0))*(1+$BG2)*(1+$BH2))*(1+$AL2)*$P2*(1+IF(VLOOKUP($Q2,武学奇术!$A:$ZZ,30,FALSE)="蓄力技",$B$21,0))*(1+$BQ2) -> 15340.37 | O2: =((($AN2*$AH2+$AI2)*(1+$AP2)*(1+$AQ2)+($AS2*IF($G$1="鸣金",$AJ2,$AH2)+IF($G$1="鸣金",$AK2*1.5,0))*(1+$AU2)*(1+$AV2)+($AW2*IF($G$1="裂石",$AJ2,$AH2)+IF($G$1="裂石",$AK2*1.5,0))*(1+$AY2)*(1+$AZ2)+($BA2*IF($G$1="牵丝",$AJ2,$AH2)+IF($G$1="牵丝",$AK2*1.5,0))*(1+$BC2)*(1+$BD2)+($BE2*IF($G$1="破竹",$AJ2,$AH2)+IF($G$1="破竹",$AK2*1.5,0))*(1+$BG2)*(1+$BH2))*(1+$AL2))*$P2*(1+IF(VLOOKUP($Q2,武学奇术!$A:$ZZ,30,FALSE)="蓄力技",$B$21,0))*(1+$BQ2) -> 13451.121 | P2: 1 | Q2: 萧呤千浪流星 | R2: 易水歌1层 | S2: N/a | T2: N/a | U2: 近战笛 | V2: N/a | W2: N/a | X2: 沧海帖1层 | Y2: N/a | Z2: N/a | AA2: N/a | AB2: N/a | AC2: N/a | AD2: N/a | AE2: 无惧 | AF2: 天志增伤 | AG2: =VLOOKUP($Q2,武学奇术!$A:$ZZ,25,FALSE) -> 群体奇术 | AH2: =VLOOKUP($Q2,武学奇术!$A:$ZZ,26,FALSE) -> 1.4904 | AI2: =VLOOKUP($Q2,武学奇术!$A:$ZZ,27,FALSE)*(1+IF(OR($AG2=$F$4,$AG2=$F$5),$B$22,0)) -> 368 | AJ2: =VLOOKUP($Q2,武学奇术!$A:$ZZ,28,FALSE) -> 2.2353 | AK2: =VLOOKUP($Q2,武学奇术!$A:$ZZ,29,FALSE)*(1+IF(OR($AG2=$F$4,$AG2=$F$5),$B$22,0)) -> 0 | AL2: {=$G$3+IFERROR(VLOOKUP($AG2,$F$4:$G$7,2,FALSE),0)+VLOOKUP($Q2,武学奇术!$A:$ZZ,2,FALSE)+SUM(_xlfn.XLOOKUP($R2:$AF2,增益!$A:$A,增益!$B:$B,0))} -> 0.2137 | AM2: {=VLOOKUP($Q2,武学奇术!$A:$ZZ,5,FALSE)+SUM(_xlfn.XLOOKUP($R2:$AF2,增益!$A:$A,增益!$E:$E,0))} -> 0 | AN2: {=$D$10*(1+$AM2)+VLOOKUP($Q2,武学奇术!$A:$ZZ,3,FALSE)+SUM(_xlfn.XLOOKUP($R2:$AF2,增益!$A:$A,增益!$C:$C,0))-$I$2} -> 3804.006 | AO2: {=$E$10*(1+$AM2)+VLOOKUP($Q2,武学奇术!$A:$ZZ,4,FALSE)+SUM(_xlfn.XLOOKUP($R2:$AF2,增益!$A:$A,增益!$D:$D,0))-$I$2} -> 3804.006 | AP2: {=IF($F$10-$I$3+VLOOKUP($Q2,武学奇术!$A:$ZZ,6,FALSE)+SUM(_xlfn.XLOOKUP(R2:AF2,增益!$A:$A,增益!$F:$F,0))>0,($F$10-$I$3+VLOOKUP($Q2,武学奇术!$A:$ZZ,6,FALSE)+SUM(_xlfn.XLOOKUP(R2:AF2,增益!$A:$A,增益!$F:$F,0)))/200,($F$10-$I$3+VLOOKUP($Q2,武学奇术!$A:$ZZ,6,FALSE)+SUM(_xlfn.XLOOKUP(R2:AF2,增益!$A:$A,增益!$F:$F,0)))/100)} -> 0.277 | AQ2: {=$G$10+VLOOKUP($Q2,武学奇术!$A:$ZZ,7,FALSE)+SUM(_xlfn.XLOOKUP(R2:AF2,增益!$A:$A,增益!$G:$G,0))} -> 0.09 | AR2: {=VLOOKUP($Q2,武学奇术!$A:$ZZ,8,FALSE)+SUM(_xlfn.XLOOKUP(R2:AF2,增益!$A:$A,增益!$H:$H,0))} -> 0 | AS2: =$D$11*(1+$AR2) -> 0 | AT2: =$E$11*(1+$AR2) -> 0 | AU2: {=IF($F$11-$I$4+VLOOKUP($Q2,武学奇术!$A:$ZZ,9,FALSE)+SUM(_xlfn.XLOOKUP(R2:AF2,增益!$A:$A,增益!$I:$I,0))>0,($F$11-$I$4+VLOOKUP($Q2,武学奇术!$A:$ZZ,9,FALSE)+SUM(_xlfn.XLOOKUP(R2:AF2,增益!$A:$A,增益!$I:$I,0)))/200,($F$11-$I$4+VLOOKUP($Q2,武学奇术!$A:$ZZ,9,FALSE)+SUM(_xlfn.XLOOKUP(R2:AF2,增益!$A:$A,增益!$I:$I,0)))/100)} -> -0.3 | AV2: {=$G$11+VLOOKUP($Q2,武学奇术!$A:$ZZ,10,FALSE)+SUM(_xlfn.XLOOKUP(R2:AF2,增益!$A:$A,增益!$J:$J,0))} -> 0 | AW2: =$D$12*(1+$AR2) -> 0 | AX2: =$E$12*(1+$AR2) -> 0 | AY2: {=IF($F$12-$I$4+VLOOKUP($Q2,武学奇术!$A:$ZZ,11,FALSE)+SUM(_xlfn.XLOOKUP(R2:AF2,增益!$A:$A,增益!$K:$K,0))>0,($F$12-$I$4+VLOOKUP($Q2,武学奇术!$A:$ZZ,11,FALSE)+SUM(_xlfn.XLOOKUP(R2:AF2,增益!$A:$A,增益!$K:$K,0)))/200,($F$12-$I$4+VLOOKUP($Q2,武学奇术!$A:$ZZ,11,FALSE)+SUM(_xlfn.XLOOKUP(R2:AF2,增益!$A:$A,增益!$K:$K,0)))/100)} -> -0.3 | AZ2: {=$G$12+VLOOKUP($Q2,武学奇术!$A:$ZZ,12,FALSE)+SUM(_xlfn.XLOOKUP(R2:AF2,增益!$A:$A,增益!$L:$L,0))} -> 0 | BA2: =$D$13*(1+$AR2) -> 0 | BB2: =$E$13*(1+$AR2) -> 0 | BC2: {=IF($F$13-$I$4+VLOOKUP($Q2,武学奇术!$A:$ZZ,13,FALSE)+SUM(_xlfn.XLOOKUP(R2:AF2,增益!$A:$A,增益!$M:$M,0))>0,($F$13-$I$4+VLOOKUP($Q2,武学奇术!$A:$ZZ,13,FALSE)+SUM(_xlfn.XLOOKUP(R2:AF2,增益!$A:$A,增益!$K:$K,0)))/200,($F$13-$I$4+VLOOKUP($Q2,武学奇术!$A:$ZZ,13,FALSE)+SUM(_xlfn.XLOOKUP(R2:AF2,增益!$A:$A,增益!$M:$M,0)))/100)} -> -0.3 | BD2: {=$G$13+VLOOKUP($Q2,武学奇术!$A:$ZZ,14,FALSE)+SUM(_xlfn.XLOOKUP(R2:AF2,增益!$A:$A,增益!$N:$N,0))} -> 0 | BE2: =$D$14*(1+$AR2) -> 570.28 | BF2: =$E$14*(1+$AR2) -> 1582.156 | BG2: {=IF($F$14-$I$4+VLOOKUP($Q2,武学奇术!$A:$ZZ,15,FALSE)+SUM(_xlfn.XLOOKUP(R2:AF2,增益!$A:$A,增益!$O:$O,0))>0,($F$14-$I$4+VLOOKUP($Q2,武学奇术!$A:$ZZ,15,FALSE)+SUM(_xlfn.XLOOKUP(R2:AF2,增益!$A:$A,增益!$O:$O,0)))/200,($F$14-$I$4+VLOOKUP($Q2,武学奇术!$A:$ZZ,15,FALSE)+SUM(_xlfn.XLOOKUP(R2:AF2,增益!$A:$A,增益!$O:$O,0)))/100)} -> 0 | BH2: {=$G$14+VLOOKUP($Q2,武学奇术!$A:$ZZ,16,FALSE)+SUM(_xlfn.XLOOKUP(R2:AF2,增益!$A:$A,增益!$P:$P,0))} -> 0.24 | BI2: =MIN(IF(VLOOKUP($Q2,武学奇术!$A:$ZZ,23,FALSE)=1,100%,$B$8),100%) -> 1 | BJ2: {=IF(VLOOKUP($Q2,武学奇术!$A:$ZZ,23,FALSE)=1,100%,MIN(80%,$B$9+VLOOKUP($Q2,武学奇术!$A:$ZZ,17,FALSE)+SUM(_xlfn.XLOOKUP(R2:AF2,增益!$A:$A,增益!$Q:$Q,0)))+$B$11+SUM(_xlfn.XLOOKUP(R2:AF2,增益!$A:$A,增益!$U:$U,0)))*IF(VLOOKUP($Q2,武学奇术!$A:$ZZ,24,FALSE)=1,0,1)+MIN(IF(VLOOKUP($Q2,武学奇术!$A:$ZZ,32,FALSE)=1,IF(VLOOKUP($Q2,武学奇术!$A:$ZZ,24,FALSE)=1,100%,MIN(40%,$B$10+VLOOKUP($Q2,武学奇术!$A:$ZZ,19,FALSE)+SUM(_xlfn.XLOOKUP(R2:AF2,增益!$A:$A,增益!$S:$S,0)))+$B$12+SUM(_xlfn.XLOOKUP(R2:AF2,增益!$A:$A,增益!$V:$V,0))),0),12%)} -> 0.918 | BK2: {=1+$B$13+VLOOKUP($Q2,武学奇术!$A:$ZZ,18,FALSE)+SUM(_xlfn.XLOOKUP(R2:AF2,增益!$A:$A,增益!$R:$R,0))} -> 1.55 | BL2: {=MAX(IF(VLOOKUP($Q2,武学奇术!$A:$ZZ,24,FALSE)=1,100%,MIN(40%,$B$10+VLOOKUP($Q2,武学奇术!$A:$ZZ,19,FALSE)+SUM(_xlfn.XLOOKUP(R2:AF2,增益!$A:$A,增益!$S:$S,0)))+$B$12+SUM(_xlfn.XLOOKUP(R2:AF2,增益!$A:$A,增益!$V:$V,0)))*IF(VLOOKUP($Q2,武学奇术!$A:$ZZ,23,FALSE)=1,0,1)-IF(VLOOKUP($Q2,武学奇术!$A:$ZZ,32,FALSE)=1,12%,0),0)} -> 0.0895 | BM2: {=1+$B$14+VLOOKUP($Q2,武学奇术!$A:$ZZ,20,FALSE)+SUM(_xlfn.XLOOKUP(R2:AF2,增益!$A:$A,增益!$T:$T,0))} -> 1.35 | BN2: =MIN((1-BL2)*BI2,BI2*BJ2) -> 0.9105 | BO2: =1-BL2-BN2-BP2 -> 0 | BP2: =IF(VLOOKUP($Q2,武学奇术!$A:$ZZ,22,FALSE)=1,0,(1-$BI2))*(1-$BL2) -> 0 | BQ2: {=SUM(_xlfn.XLOOKUP(R2:AF2,增益!$A:$A,增益!$W:$W,0))+$I$5} -> 0.11
A3: 鸣金 | F3: 通用增伤 | G3: =B16+1.5%+IF($D$16="√",8%,0)+IF($C$24="征人归",8%,0) -> 0.1837 | H3: 外抗 | I3: =25-IF(D17="√",10,0)-IF(F17="√",10,0) -> 5 | K3: =($L3*$BN3+$M3*$BL3+$N3*$BO3+$O3*$BP3) -> 24723.361 | L3: =((($AN3+($AO3-$AN3)*IF(VLOOKUP($Q3,武学奇术!$A:$ZZ,31,FALSE)=1,$F$18,0.5))*$AH3+$AI3)*(1+$AP3)*(1+$AQ3)+(($AS3+($AT3-$AS3)*IF(VLOOKUP($Q3,武学奇术!$A:$ZZ,31,FALSE)=1,$F$18,0.5))*IF($G$1="鸣金",$AJ3,$AH3)+IF($G$1="鸣金",$AK3*1.5,0))*(1+$AU3)*(1+$AV3)+(($AW3+($AX3-$AW3)*IF(VLOOKUP($Q3,武学奇术!$A:$ZZ,31,FALSE)=1,$F$18,0.5))*IF($G$1="裂石",$AJ3,$AH3)+IF($G$1="裂石",$AK3*1.5,0))*(1+$AY3)*(1+$AZ3)+(($BA3+($BB3-$BA3)*IF(VLOOKUP($Q3,武学奇术!$A:$ZZ,31,FALSE)=1,$F$18,0.5))*IF($G$1="牵丝",$AJ3,$AH3)+IF($G$1="牵丝",$AK3*1.5,0))*(1+$BC3)*(1+$BD3)+(($BE3+($BF3-$BE3)*IF(VLOOKUP($Q3,武学奇术!$A:$ZZ,31,FALSE)=1,$F$18,0.5))*IF($G$1="破竹",$AJ3,$AH3)+IF($G$1="破竹",$AK3*1.5,0))*(1+$BG3)*(1+$BH3))*(1+$AL3)*$BK3*$P3*(1+IF(VLOOKUP($Q3,武学奇术!$A:$ZZ,30,FALSE)="蓄力技",$B$21,0))*(1+$BQ3) -> 24773.271 | M3: =(($AO3*$AH3+$AI3)*(1+$AP3)*(1+$AQ3)+($AT3*IF($G$1="鸣金",$AJ3,$AH3)+IF($G$1="鸣金",$AK3*1.5,0))*(1+$AU3)*(1+$AV3)+($AX3*IF($G$1="裂石",$AJ3,$AH3)+IF($G$1="裂石",$AK3*1.5,0))*(1+$AY3)*(1+$AZ3)+($BB3*IF($G$1="牵丝",$AJ3,$AH3)+IF($G$1="牵丝",$AK3*1.5,0))*(1+$BC3)*(1+$BD3)+($BF3*IF($G$1="破竹",$AJ3,$AH3)+IF($G$1="破竹",$AK3*1.5,0))*(1+$BG3)*(1+$BH3))*(1+$AL3)*$BM3*$P3*(1+IF(VLOOKUP($Q3,武学奇术!$A:$ZZ,30,FALSE)="蓄力技",$B$21,0))*(1+$BQ3) -> 24215.627 | N3: =((($AN3+($AO3-$AN3)*IF(VLOOKUP($Q3,武学奇术!$A:$ZZ,31,FALSE)=1,$F$18,0.5))*$AH3+$AI3)*(1+$AP3)*(1+$AQ3)+(($AS3+($AT3-$AS3)*IF(VLOOKUP($Q3,武学奇术!$A:$ZZ,31,FALSE)=1,$F$18,0.5))*IF($G$1="鸣金",$AJ3,$AH3)+IF($G$1="鸣金",$AK3*1.5,0))*(1+$AU3)*(1+$AV3)+(($AW3+($AX3-$AW3)*IF(VLOOKUP($Q3,武学奇术!$A:$ZZ,31,FALSE)=1,$F$18,0.5))*IF($G$1="裂石",$AJ3,$AH3)+IF($G$1="裂石",$AK3*1.5,0))*(1+$AY3)*(1+$AZ3)+(($BA3+($BB3-$BA3)*IF(VLOOKUP($Q3,武学奇术!$A:$ZZ,31,FALSE)=1,$F$18,0.5))*IF($G$1="牵丝",$AJ3,$AH3)+IF($G$1="牵丝",$AK3*1.5,0))*(1+$BC3)*(1+$BD3)+(($BE3+($BF3-$BE3)*IF(VLOOKUP($Q3,武学奇术!$A:$ZZ,31,FALSE)=1,$F$18,0.5))*IF($G$1="破竹",$AJ3,$AH3)+IF($G$1="破竹",$AK3*1.5,0))*(1+$BG3)*(1+$BH3))*(1+$AL3)*$P3*(1+IF(VLOOKUP($Q3,武学奇术!$A:$ZZ,30,FALSE)="蓄力技",$B$21,0))*(1+$BQ3) -> 15880.302 | O3: =((($AN3*$AH3+$AI3)*(1+$AP3)*(1+$AQ3)+($AS3*IF($G$1="鸣金",$AJ3,$AH3)+IF($G$1="鸣金",$AK3*1.5,0))*(1+$AU3)*(1+$AV3)+($AW3*IF($G$1="裂石",$AJ3,$AH3)+IF($G$1="裂石",$AK3*1.5,0))*(1+$AY3)*(1+$AZ3)+($BA3*IF($G$1="牵丝",$AJ3,$AH3)+IF($G$1="牵丝",$AK3*1.5,0))*(1+$BC3)*(1+$BD3)+($BE3*IF($G$1="破竹",$AJ3,$AH3)+IF($G$1="破竹",$AK3*1.5,0))*(1+$BG3)*(1+$BH3))*(1+$AL3))*$P3*(1+IF(VLOOKUP($Q3,武学奇术!$A:$ZZ,30,FALSE)="蓄力技",$B$21,0))*(1+$BQ3) -> 13823.102 | P3: 1 | Q3: 萧呤千浪流星 | R3: 易水歌2层 | S3: N/a | T3: N/a | U3: 近战笛 | V3: N/a | W3: N/a | X3: 沧海帖2层 | Y3: 惧刃(拐) | Z3: N/a | AA3: N/a | AB3: N/a | AC3: N/a | AD3: N/a | AE3: 无惧 | AF3: 天志增伤 | AG3: =VLOOKUP($Q3,武学奇术!$A:$ZZ,25,FALSE) -> 群体奇术 | AH3: =VLOOKUP($Q3,武学奇术!$A:$ZZ,26,FALSE) -> 1.4904 | AI3: =VLOOKUP($Q3,武学奇术!$A:$ZZ,27,FALSE)*(1+IF(OR($AG3=$F$4,$AG3=$F$5),$B$22,0)) -> 368 | AJ3: =VLOOKUP($Q3,武学奇术!$A:$ZZ,28,FALSE) -> 2.2353 | AK3: =VLOOKUP($Q3,武学奇术!$A:$ZZ,29,FALSE)*(1+IF(OR($AG3=$F$4,$AG3=$F$5),$B$22,0)) -> 0 | AL3: {=$G$3+IFERROR(VLOOKUP($AG3,$F$4:$G$7,2,FALSE),0)+VLOOKUP($Q3,武学奇术!$A:$ZZ,2,FALSE)+SUM(_xlfn.XLOOKUP($R3:$AF3,增益!$A:$A,增益!$B:$B,0))} -> 0.2237 | AM3: {=VLOOKUP($Q3,武学奇术!$A:$ZZ,5,FALSE)+SUM(_xlfn.XLOOKUP($R3:$AF3,增益!$A:$A,增益!$E:$E,0))} -> 0 | AN3: {=$D$10*(1+$AM3)+VLOOKUP($Q3,武学奇术!$A:$ZZ,3,FALSE)+SUM(_xlfn.XLOOKUP($R3:$AF3,增益!$A:$A,增益!$C:$C,0))-$I$2} -> 3804.006 | AO3: {=$E$10*(1+$AM3)+VLOOKUP($Q3,武学奇术!$A:$ZZ,4,FALSE)+SUM(_xlfn.XLOOKUP($R3:$AF3,增益!$A:$A,增益!$D:$D,0))-$I$2} -> 3804.006 | AP3: {=IF($F$10-$I$3+VLOOKUP($Q3,武学奇术!$A:$ZZ,6,FALSE)+SUM(_xlfn.XLOOKUP(R3:AF3,增益!$A:$A,增益!$F:$F,0))>0,($F$10-$I$3+VLOOKUP($Q3,武学奇术!$A:$ZZ,6,FALSE)+SUM(_xlfn.XLOOKUP(R3:AF3,增益!$A:$A,增益!$F:$F,0)))/200,($F$10-$I$3+VLOOKUP($Q3,武学奇术!$A:$ZZ,6,FALSE)+SUM(_xlfn.XLOOKUP(R3:AF3,增益!$A:$A,增益!$F:$F,0)))/100)} -> 0.287 | AQ3: {=$G$10+VLOOKUP($Q3,武学奇术!$A:$ZZ,7,FALSE)+SUM(_xlfn.XLOOKUP(R3:AF3,增益!$A:$A,增益!$G:$G,0))} -> 0.09 | AR3: {=VLOOKUP($Q3,武学奇术!$A:$ZZ,8,FALSE)+SUM(_xlfn.XLOOKUP(R3:AF3,增益!$A:$A,增益!$H:$H,0))} -> 0 | AS3: =$D$11*(1+$AR3) -> 0 | AT3: =$E$11*(1+$AR3) -> 0 | AU3: {=IF($F$11-$I$4+VLOOKUP($Q3,武学奇术!$A:$ZZ,9,FALSE)+SUM(_xlfn.XLOOKUP(R3:AF3,增益!$A:$A,增益!$I:$I,0))>0,($F$11-$I$4+VLOOKUP($Q3,武学奇术!$A:$ZZ,9,FALSE)+SUM(_xlfn.XLOOKUP(R3:AF3,增益!$A:$A,增益!$I:$I,0)))/200,($F$11-$I$4+VLOOKUP($Q3,武学奇术!$A:$ZZ,9,FALSE)+SUM(_xlfn.XLOOKUP(R3:AF3,增益!$A:$A,增益!$I:$I,0)))/100)} -> -0.14 | AV3: {=$G$11+VLOOKUP($Q3,武学奇术!$A:$ZZ,10,FALSE)+SUM(_xlfn.XLOOKUP(R3:AF3,增益!$A:$A,增益!$J:$J,0))} -> 0 | AW3: =$D$12*(1+$AR3) -> 0 | AX3: =$E$12*(1+$AR3) -> 0 | AY3: {=IF($F$12-$I$4+VLOOKUP($Q3,武学奇术!$A:$ZZ,11,FALSE)+SUM(_xlfn.XLOOKUP(R3:AF3,增益!$A:$A,增益!$K:$K,0))>0,($F$12-$I$4+VLOOKUP($Q3,武学奇术!$A:$ZZ,11,FALSE)+SUM(_xlfn.XLOOKUP(R3:AF3,增益!$A:$A,增益!$K:$K,0)))/200,($F$12-$I$4+VLOOKUP($Q3,武学奇术!$A:$ZZ,11,FALSE)+SUM(_xlfn.XLOOKUP(R3:AF3,增益!$A:$A,增益!$K:$K,0)))/100)} -> -0.14 | AZ3: {=$G$12+VLOOKUP($Q3,武学奇术!$A:$ZZ,12,FALSE)+SUM(_xlfn.XLOOKUP(R3:AF3,增益!$A:$A,增益!$L:$L,0))} -> 0 | BA3: =$D$13*(1+$AR3) -> 0 | BB3: =$E$13*(1+$AR3) -> 0 | BC3: {=IF($F$13-$I$4+VLOOKUP($Q3,武学奇术!$A:$ZZ,13,FALSE)+SUM(_xlfn.XLOOKUP(R3:AF3,增益!$A:$A,增益!$M:$M,0))>0,($F$13-$I$4+VLOOKUP($Q3,武学奇术!$A:$ZZ,13,FALSE)+SUM(_xlfn.XLOOKUP(R3:AF3,增益!$A:$A,增益!$K:$K,0)))/200,($F$13-$I$4+VLOOKUP($Q3,武学奇术!$A:$ZZ,13,FALSE)+SUM(_xlfn.XLOOKUP(R3:AF3,增益!$A:$A,增益!$M:$M,0)))/100)} -> -0.14 | BD3: {=$G$13+VLOOKUP($Q3,武学奇术!$A:$ZZ,14,FALSE)+SUM(_xlfn.XLOOKUP(R3:AF3,增益!$A:$A,增益!$N:$N,0))} -> 0 | BE3: =$D$14*(1+$AR3) -> 570.28 | BF3: =$E$14*(1+$AR3) -> 1582.156 | BG3: {=IF($F$14-$I$4+VLOOKUP($Q3,武学奇术!$A:$ZZ,15,FALSE)+SUM(_xlfn.XLOOKUP(R3:AF3,增益!$A:$A,增益!$O:$O,0))>0,($F$14-$I$4+VLOOKUP($Q3,武学奇术!$A:$ZZ,15,FALSE)+SUM(_xlfn.XLOOKUP(R3:AF3,增益!$A:$A,增益!$O:$O,0)))/200,($F$14-$I$4+VLOOKUP($Q3,武学奇术!$A:$ZZ,15,FALSE)+SUM(_xlfn.XLOOKUP(R3:AF3,增益!$A:$A,增益!$O:$O,0)))/100)} -> 0.08 | BH3: {=$G$14+VLOOKUP($Q3,武学奇术!$A:$ZZ,16,FALSE)+SUM(_xlfn.XLOOKUP(R3:AF3,增益!$A:$A,增益!$P:$P,0))} -> 0.24 | BI3: =MIN(IF(VLOOKUP($Q3,武学奇术!$A:$ZZ,23,FALSE)=1,100%,$B$8),100%) -> 1 | BJ3: {=IF(VLOOKUP($Q3,武学奇术!$A:$ZZ,23,FALSE)=1,100%,MIN(80%,$B$9+VLOOKUP($Q3,武学奇术!$A:$ZZ,17,FALSE)+SUM(_xlfn.XLOOKUP(R3:AF3,增益!$A:$A,增益!$Q:$Q,0)))+$B$11+SUM(_xlfn.XLOOKUP(R3:AF3,增益!$A:$A,增益!$U:$U,0)))*IF(VLOOKUP($Q3,武学奇术!$A:$ZZ,24,FALSE)=1,0,1)+MIN(IF(VLOOKUP($Q3,武学奇术!$A:$ZZ,32,FALSE)=1,IF(VLOOKUP($Q3,武学奇术!$A:$ZZ,24,FALSE)=1,100%,MIN(40%,$B$10+VLOOKUP($Q3,武学奇术!$A:$ZZ,19,FALSE)+SUM(_xlfn.XLOOKUP(R3:AF3,增益!$A:$A,增益!$S:$S,0)))+$B$12+SUM(_xlfn.XLOOKUP(R3:AF3,增益!$A:$A,增益!$V:$V,0))),0),12%)} -> 0.918 | BK3: {=1+$B$13+VLOOKUP($Q3,武学奇术!$A:$ZZ,18,FALSE)+SUM(_xlfn.XLOOKUP(R3:AF3,增益!$A:$A,增益!$R:$R,0))} -> 1.56 | BL3: {=MAX(IF(VLOOKUP($Q3,武学奇术!$A:$ZZ,24,FALSE)=1,100%,MIN(40%,$B$10+VLOOKUP($Q3,武学奇术!$A:$ZZ,19,FALSE)+SUM(_xlfn.XLOOKUP(R3:AF3,增益!$A:$A,增益!$S:$S,0)))+$B$12+SUM(_xlfn.XLOOKUP(R3:AF3,增益!$A:$A,增益!$V:$V,0)))*IF(VLOOKUP($Q3,武学奇术!$A:$ZZ,23,FALSE)=1,0,1)-IF(VLOOKUP($Q3,武学奇术!$A:$ZZ,32,FALSE)=1,12%,0),0)} -> 0.0895 | BM3: {=1+$B$14+VLOOKUP($Q3,武学奇术!$A:$ZZ,20,FALSE)+SUM(_xlfn.XLOOKUP(R3:AF3,增益!$A:$A,增益!$T:$T,0))} -> 1.35 | BN3: =MIN((1-BL3)*BI3,BI3*BJ3) -> 0.9105 | BO3: =1-BL3-BN3-BP3 -> 0 | BP3: =IF(VLOOKUP($Q3,武学奇术!$A:$ZZ,22,FALSE)=1,0,(1-$BI3))*(1-$BL3) -> 0 | BQ3: {=SUM(_xlfn.XLOOKUP(R3:AF3,增益!$A:$A,增益!$W:$W,0))+$I$5} -> 0.11
A4: 裂石 | F4: 拳甲 | G4: =B15+B17 -> 0.1704 | H4: 属抗 | I4: =30 -> 30 | K4: =($L4*$BN4+$M4*$BL4+$N4*$BO4+$O4*$BP4) -> 25210.883 | L4: =((($AN4+($AO4-$AN4)*IF(VLOOKUP($Q4,武学奇术!$A:$ZZ,31,FALSE)=1,$F$18,0.5))*$AH4+$AI4)*(1+$AP4)*(1+$AQ4)+(($AS4+($AT4-$AS4)*IF(VLOOKUP($Q4,武学奇术!$A:$ZZ,31,FALSE)=1,$F$18,0.5))*IF($G$1="鸣金",$AJ4,$AH4)+IF($G$1="鸣金",$AK4*1.5,0))*(1+$AU4)*(1+$AV4)+(($AW4+($AX4-$AW4)*IF(VLOOKUP($Q4,武学奇术!$A:$ZZ,31,FALSE)=1,$F$18,0.5))*IF($G$1="裂石",$AJ4,$AH4)+IF($G$1="裂石",$AK4*1.5,0))*(1+$AY4)*(1+$AZ4)+(($BA4+($BB4-$BA4)*IF(VLOOKUP($Q4,武学奇术!$A:$ZZ,31,FALSE)=1,$F$18,0.5))*IF($G$1="牵丝",$AJ4,$AH4)+IF($G$1="牵丝",$AK4*1.5,0))*(1+$BC4)*(1+$BD4)+(($BE4+($BF4-$BE4)*IF(VLOOKUP($Q4,武学奇术!$A:$ZZ,31,FALSE)=1,$F$18,0.5))*IF($G$1="破竹",$AJ4,$AH4)+IF($G$1="破竹",$AK4*1.5,0))*(1+$BG4)*(1+$BH4))*(1+$AL4)*$BK4*$P4*(1+IF(VLOOKUP($Q4,武学奇术!$A:$ZZ,30,FALSE)="蓄力技",$B$21,0))*(1+$BQ4) -> 25277.303 | M4: =(($AO4*$AH4+$AI4)*(1+$AP4)*(1+$AQ4)+($AT4*IF($G$1="鸣金",$AJ4,$AH4)+IF($G$1="鸣金",$AK4*1.5,0))*(1+$AU4)*(1+$AV4)+($AX4*IF($G$1="裂石",$AJ4,$AH4)+IF($G$1="裂石",$AK4*1.5,0))*(1+$AY4)*(1+$AZ4)+($BB4*IF($G$1="牵丝",$AJ4,$AH4)+IF($G$1="牵丝",$AK4*1.5,0))*(1+$BC4)*(1+$BD4)+($BF4*IF($G$1="破竹",$AJ4,$AH4)+IF($G$1="破竹",$AK4*1.5,0))*(1+$BG4)*(1+$BH4))*(1+$AL4)*$BM4*$P4*(1+IF(VLOOKUP($Q4,武学奇术!$A:$ZZ,30,FALSE)="蓄力技",$B$21,0))*(1+$BQ4) -> 24535.176 | N4: =((($AN4+($AO4-$AN4)*IF(VLOOKUP($Q4,武学奇术!$A:$ZZ,31,FALSE)=1,$F$18,0.5))*$AH4+$AI4)*(1+$AP4)*(1+$AQ4)+(($AS4+($AT4-$AS4)*IF(VLOOKUP($Q4,武学奇术!$A:$ZZ,31,FALSE)=1,$F$18,0.5))*IF($G$1="鸣金",$AJ4,$AH4)+IF($G$1="鸣金",$AK4*1.5,0))*(1+$AU4)*(1+$AV4)+(($AW4+($AX4-$AW4)*IF(VLOOKUP($Q4,武学奇术!$A:$ZZ,31,FALSE)=1,$F$18,0.5))*IF($G$1="裂石",$AJ4,$AH4)+IF($G$1="裂石",$AK4*1.5,0))*(1+$AY4)*(1+$AZ4)+(($BA4+($BB4-$BA4)*IF(VLOOKUP($Q4,武学奇术!$A:$ZZ,31,FALSE)=1,$F$18,0.5))*IF($G$1="牵丝",$AJ4,$AH4)+IF($G$1="牵丝",$AK4*1.5,0))*(1+$BC4)*(1+$BD4)+(($BE4+($BF4-$BE4)*IF(VLOOKUP($Q4,武学奇术!$A:$ZZ,31,FALSE)=1,$F$18,0.5))*IF($G$1="破竹",$AJ4,$AH4)+IF($G$1="破竹",$AK4*1.5,0))*(1+$BG4)*(1+$BH4))*(1+$AL4)*$P4*(1+IF(VLOOKUP($Q4,武学奇术!$A:$ZZ,30,FALSE)="蓄力技",$B$21,0))*(1+$BQ4) -> 16100.193 | O4: =((($AN4*$AH4+$AI4)*(1+$AP4)*(1+$AQ4)+($AS4*IF($G$1="鸣金",$AJ4,$AH4)+IF($G$1="鸣金",$AK4*1.5,0))*(1+$AU4)*(1+$AV4)+($AW4*IF($G$1="裂石",$AJ4,$AH4)+IF($G$1="裂石",$AK4*1.5,0))*(1+$AY4)*(1+$AZ4)+($BA4*IF($G$1="牵丝",$AJ4,$AH4)+IF($G$1="牵丝",$AK4*1.5,0))*(1+$BC4)*(1+$BD4)+($BE4*IF($G$1="破竹",$AJ4,$AH4)+IF($G$1="破竹",$AK4*1.5,0))*(1+$BG4)*(1+$BH4))*(1+$AL4))*$P4*(1+IF(VLOOKUP($Q4,武学奇术!$A:$ZZ,30,FALSE)="蓄力技",$B$21,0))*(1+$BQ4) -> 14026.182 | P4: 1 | Q4: 萧呤千浪流星 | R4: 易水歌3层 | S4: N/a | T4: N/a | U4: 近战笛 | V4: N/a | W4: N/a | X4: 沧海帖3层 | Y4: 惧刃(拐) | Z4: N/a | AA4: N/a | AB4: N/a | AC4: N/a | AD4: N/a | AE4: 无惧 | AF4: 天志增伤 | AG4: =VLOOKUP($Q4,武学奇术!$A:$ZZ,25,FALSE) -> 群体奇术 | AH4: =VLOOKUP($Q4,武学奇术!$A:$ZZ,26,FALSE) -> 1.4904 | AI4: =VLOOKUP($Q4,武学奇术!$A:$ZZ,27,FALSE)*(1+IF(OR($AG4=$F$4,$AG4=$F$5),$B$22,0)) -> 368 | AJ4: =VLOOKUP($Q4,武学奇术!$A:$ZZ,28,FALSE) -> 2.2353 | AK4: =VLOOKUP($Q4,武学奇术!$A:$ZZ,29,FALSE)*(1+IF(OR($AG4=$F$4,$AG4=$F$5),$B$22,0)) -> 0 | AL4: {=$G$3+IFERROR(VLOOKUP($AG4,$F$4:$G$7,2,FALSE),0)+VLOOKUP($Q4,武学奇术!$A:$ZZ,2,FALSE)+SUM(_xlfn.XLOOKUP($R4:$AF4,增益!$A:$A,增益!$B:$B,0))} -> 0.2337 | AM4: {=VLOOKUP($Q4,武学奇术!$A:$ZZ,5,FALSE)+SUM(_xlfn.XLOOKUP($R4:$AF4,增益!$A:$A,增益!$E:$E,0))} -> 0 | AN4: {=$D$10*(1+$AM4)+VLOOKUP($Q4,武学奇术!$A:$ZZ,3,FALSE)+SUM(_xlfn.XLOOKUP($R4:$AF4,增益!$A:$A,增益!$C:$C,0))-$I$2} -> 3804.006 | AO4: {=$E$10*(1+$AM4)+VLOOKUP($Q4,武学奇术!$A:$ZZ,4,FALSE)+SUM(_xlfn.XLOOKUP($R4:$AF4,增益!$A:$A,增益!$D:$D,0))-$I$2} -> 3804.006 | AP4: {=IF($F$10-$I$3+VLOOKUP($Q4,武学奇术!$A:$ZZ,6,FALSE)+SUM(_xlfn.XLOOKUP(R4:AF4,增益!$A:$A,增益!$F:$F,0))>0,($F$10-$I$3+VLOOKUP($Q4,武学奇术!$A:$ZZ,6,FALSE)+SUM(_xlfn.XLOOKUP(R4:AF4,增益!$A:$A,增益!$F:$F,0)))/200,($F$10-$I$3+VLOOKUP($Q4,武学奇术!$A:$ZZ,6,FALSE)+SUM(_xlfn.XLOOKUP(R4:AF4,增益!$A:$A,增益!$F:$F,0)))/100)} -> 0.297 | AQ4: {=$G$10+VLOOKUP($Q4,武学奇术!$A:$ZZ,7,FALSE)+SUM(_xlfn.XLOOKUP(R4:AF4,增益!$A:$A,增益!$G:$G,0))} -> 0.09 | AR4: {=VLOOKUP($Q4,武学奇术!$A:$ZZ,8,FALSE)+SUM(_xlfn.XLOOKUP(R4:AF4,增益!$A:$A,增益!$H:$H,0))} -> 0 | AS4: =$D$11*(1+$AR4) -> 0 | AT4: =$E$11*(1+$AR4) -> 0 | AU4: {=IF($F$11-$I$4+VLOOKUP($Q4,武学奇术!$A:$ZZ,9,FALSE)+SUM(_xlfn.XLOOKUP(R4:AF4,增益!$A:$A,增益!$I:$I,0))>0,($F$11-$I$4+VLOOKUP($Q4,武学奇术!$A:$ZZ,9,FALSE)+SUM(_xlfn.XLOOKUP(R4:AF4,增益!$A:$A,增益!$I:$I,0)))/200,($F$11-$I$4+VLOOKUP($Q4,武学奇术!$A:$ZZ,9,FALSE)+SUM(_xlfn.XLOOKUP(R4:AF4,增益!$A:$A,增益!$I:$I,0)))/100)} -> -0.14 | AV4: {=$G$11+VLOOKUP($Q4,武学奇术!$A:$ZZ,10,FALSE)+SUM(_xlfn.XLOOKUP(R4:AF4,增益!$A:$A,增益!$J:$J,0))} -> 0 | AW4: =$D$12*(1+$AR4) -> 0 | AX4: =$E$12*(1+$AR4) -> 0 | AY4: {=IF($F$12-$I$4+VLOOKUP($Q4,武学奇术!$A:$ZZ,11,FALSE)+SUM(_xlfn.XLOOKUP(R4:AF4,增益!$A:$A,增益!$K:$K,0))>0,($F$12-$I$4+VLOOKUP($Q4,武学奇术!$A:$ZZ,11,FALSE)+SUM(_xlfn.XLOOKUP(R4:AF4,增益!$A:$A,增益!$K:$K,0)))/200,($F$12-$I$4+VLOOKUP($Q4,武学奇术!$A:$ZZ,11,FALSE)+SUM(_xlfn.XLOOKUP(R4:AF4,增益!$A:$A,增益!$K:$K,0)))/100)} -> -0.14 | AZ4: {=$G$12+VLOOKUP($Q4,武学奇术!$A:$ZZ,12,FALSE)+SUM(_xlfn.XLOOKUP(R4:AF4,增益!$A:$A,增益!$L:$L,0))} -> 0 | BA4: =$D$13*(1+$AR4) -> 0 | BB4: =$E$13*(1+$AR4) -> 0 | BC4: {=IF($F$13-$I$4+VLOOKUP($Q4,武学奇术!$A:$ZZ,13,FALSE)+SUM(_xlfn.XLOOKUP(R4:AF4,增益!$A:$A,增益!$M:$M,0))>0,($F$13-$I$4+VLOOKUP($Q4,武学奇术!$A:$ZZ,13,FALSE)+SUM(_xlfn.XLOOKUP(R4:AF4,增益!$A:$A,增益!$K:$K,0)))/200,($F$13-$I$4+VLOOKUP($Q4,武学奇术!$A:$ZZ,13,FALSE)+SUM(_xlfn.XLOOKUP(R4:AF4,增益!$A:$A,增益!$M:$M,0)))/100)} -> -0.14 | BD4: {=$G$13+VLOOKUP($Q4,武学奇术!$A:$ZZ,14,FALSE)+SUM(_xlfn.XLOOKUP(R4:AF4,增益!$A:$A,增益!$N:$N,0))} -> 0 | BE4: =$D$14*(1+$AR4) -> 570.28 | BF4: =$E$14*(1+$AR4) -> 1582.156 | BG4: {=IF($F$14-$I$4+VLOOKUP($Q4,武学奇术!$A:$ZZ,15,FALSE)+SUM(_xlfn.XLOOKUP(R4:AF4,增益!$A:$A,增益!$O:$O,0))>0,($F$14-$I$4+VLOOKUP($Q4,武学奇术!$A:$ZZ,15,FALSE)+SUM(_xlfn.XLOOKUP(R4:AF4,增益!$A:$A,增益!$O:$O,0)))/200,($F$14-$I$4+VLOOKUP($Q4,武学奇术!$A:$ZZ,15,FALSE)+SUM(_xlfn.XLOOKUP(R4:AF4,增益!$A:$A,增益!$O:$O,0)))/100)} -> 0.08 | BH4: {=$G$14+VLOOKUP($Q4,武学奇术!$A:$ZZ,16,FALSE)+SUM(_xlfn.XLOOKUP(R4:AF4,增益!$A:$A,增益!$P:$P,0))} -> 0.24 | BI4: =MIN(IF(VLOOKUP($Q4,武学奇术!$A:$ZZ,23,FALSE)=1,100%,$B$8),100%) -> 1 | BJ4: {=IF(VLOOKUP($Q4,武学奇术!$A:$ZZ,23,FALSE)=1,100%,MIN(80%,$B$9+VLOOKUP($Q4,武学奇术!$A:$ZZ,17,FALSE)+SUM(_xlfn.XLOOKUP(R4:AF4,增益!$A:$A,增益!$Q:$Q,0)))+$B$11+SUM(_xlfn.XLOOKUP(R4:AF4,增益!$A:$A,增益!$U:$U,0)))*IF(VLOOKUP($Q4,武学奇术!$A:$ZZ,24,FALSE)=1,0,1)+MIN(IF(VLOOKUP($Q4,武学奇术!$A:$ZZ,32,FALSE)=1,IF(VLOOKUP($Q4,武学奇术!$A:$ZZ,24,FALSE)=1,100%,MIN(40%,$B$10+VLOOKUP($Q4,武学奇术!$A:$ZZ,19,FALSE)+SUM(_xlfn.XLOOKUP(R4:AF4,增益!$A:$A,增益!$S:$S,0)))+$B$12+SUM(_xlfn.XLOOKUP(R4:AF4,增益!$A:$A,增益!$V:$V,0))),0),12%)} -> 0.918 | BK4: {=1+$B$13+VLOOKUP($Q4,武学奇术!$A:$ZZ,18,FALSE)+SUM(_xlfn.XLOOKUP(R4:AF4,增益!$A:$A,增益!$R:$R,0))} -> 1.57 | BL4: {=MAX(IF(VLOOKUP($Q4,武学奇术!$A:$ZZ,24,FALSE)=1,100%,MIN(40%,$B$10+VLOOKUP($Q4,武学奇术!$A:$ZZ,19,FALSE)+SUM(_xlfn.XLOOKUP(R4:AF4,增益!$A:$A,增益!$S:$S,0)))+$B$12+SUM(_xlfn.XLOOKUP(R4:AF4,增益!$A:$A,增益!$V:$V,0)))*IF(VLOOKUP($Q4,武学奇术!$A:$ZZ,23,FALSE)=1,0,1)-IF(VLOOKUP($Q4,武学奇术!$A:$ZZ,32,FALSE)=1,12%,0),0)} -> 0.0895 | BM4: {=1+$B$14+VLOOKUP($Q4,武学奇术!$A:$ZZ,20,FALSE)+SUM(_xlfn.XLOOKUP(R4:AF4,增益!$A:$A,增益!$T:$T,0))} -> 1.35 | BN4: =MIN((1-BL4)*BI4,BI4*BJ4) -> 0.9105 | BO4: =1-BL4-BN4-BP4 -> 0 | BP4: =IF(VLOOKUP($Q4,武学奇术!$A:$ZZ,22,FALSE)=1,0,(1-$BI4))*(1-$BL4) -> 0 | BQ4: {=SUM(_xlfn.XLOOKUP(R4:AF4,增益!$A:$A,增益!$W:$W,0))+$I$5} -> 0.11
A5: 牵丝 | F5: 绳镖 | G5: =B15+B18 -> 0.0852 | H5: 副本天赋 | I5: 0.06 | K5: =($L5*$BN5+$M5*$BL5+$N5*$BO5+$O5*$BP5) -> 25704.687 | L5: =((($AN5+($AO5-$AN5)*IF(VLOOKUP($Q5,武学奇术!$A:$ZZ,31,FALSE)=1,$F$18,0.5))*$AH5+$AI5)*(1+$AP5)*(1+$AQ5)+(($AS5+($AT5-$AS5)*IF(VLOOKUP($Q5,武学奇术!$A:$ZZ,31,FALSE)=1,$F$18,0.5))*IF($G$1="鸣金",$AJ5,$AH5)+IF($G$1="鸣金",$AK5*1.5,0))*(1+$AU5)*(1+$AV5)+(($AW5+($AX5-$AW5)*IF(VLOOKUP($Q5,武学奇术!$A:$ZZ,31,FALSE)=1,$F$18,0.5))*IF($G$1="裂石",$AJ5,$AH5)+IF($G$1="裂石",$AK5*1.5,0))*(1+$AY5)*(1+$AZ5)+(($BA5+($BB5-$BA5)*IF(VLOOKUP($Q5,武学奇术!$A:$ZZ,31,FALSE)=1,$F$18,0.5))*IF($G$1="牵丝",$AJ5,$AH5)+IF($G$1="牵丝",$AK5*1.5,0))*(1+$BC5)*(1+$BD5)+(($BE5+($BF5-$BE5)*IF(VLOOKUP($Q5,武学奇术!$A:$ZZ,31,FALSE)=1,$F$18,0.5))*IF($G$1="破竹",$AJ5,$AH5)+IF($G$1="破竹",$AK5*1.5,0))*(1+$BG5)*(1+$BH5))*(1+$AL5)*$BK5*$P5*(1+IF(VLOOKUP($Q5,武学奇术!$A:$ZZ,30,FALSE)="蓄力技",$B$21,0))*(1+$BQ5) -> 25788.042 | M5: =(($AO5*$AH5+$AI5)*(1+$AP5)*(1+$AQ5)+($AT5*IF($G$1="鸣金",$AJ5,$AH5)+IF($G$1="鸣金",$AK5*1.5,0))*(1+$AU5)*(1+$AV5)+($AX5*IF($G$1="裂石",$AJ5,$AH5)+IF($G$1="裂石",$AK5*1.5,0))*(1+$AY5)*(1+$AZ5)+($BB5*IF($G$1="牵丝",$AJ5,$AH5)+IF($G$1="牵丝",$AK5*1.5,0))*(1+$BC5)*(1+$BD5)+($BF5*IF($G$1="破竹",$AJ5,$AH5)+IF($G$1="破竹",$AK5*1.5,0))*(1+$BG5)*(1+$BH5))*(1+$AL5)*$BM5*$P5*(1+IF(VLOOKUP($Q5,武学奇术!$A:$ZZ,30,FALSE)="蓄力技",$B$21,0))*(1+$BQ5) -> 24856.697 | N5: =((($AN5+($AO5-$AN5)*IF(VLOOKUP($Q5,武学奇术!$A:$ZZ,31,FALSE)=1,$F$18,0.5))*$AH5+$AI5)*(1+$AP5)*(1+$AQ5)+(($AS5+($AT5-$AS5)*IF(VLOOKUP($Q5,武学奇术!$A:$ZZ,31,FALSE)=1,$F$18,0.5))*IF($G$1="鸣金",$AJ5,$AH5)+IF($G$1="鸣金",$AK5*1.5,0))*(1+$AU5)*(1+$AV5)+(($AW5+($AX5-$AW5)*IF(VLOOKUP($Q5,武学奇术!$A:$ZZ,31,FALSE)=1,$F$18,0.5))*IF($G$1="裂石",$AJ5,$AH5)+IF($G$1="裂石",$AK5*1.5,0))*(1+$AY5)*(1+$AZ5)+(($BA5+($BB5-$BA5)*IF(VLOOKUP($Q5,武学奇术!$A:$ZZ,31,FALSE)=1,$F$18,0.5))*IF($G$1="牵丝",$AJ5,$AH5)+IF($G$1="牵丝",$AK5*1.5,0))*(1+$BC5)*(1+$BD5)+(($BE5+($BF5-$BE5)*IF(VLOOKUP($Q5,武学奇术!$A:$ZZ,31,FALSE)=1,$F$18,0.5))*IF($G$1="破竹",$AJ5,$AH5)+IF($G$1="破竹",$AK5*1.5,0))*(1+$BG5)*(1+$BH5))*(1+$AL5)*$P5*(1+IF(VLOOKUP($Q5,武学奇术!$A:$ZZ,30,FALSE)="蓄力技",$B$21,0))*(1+$BQ5) -> 16321.546 | O5: =((($AN5*$AH5+$AI5)*(1+$AP5)*(1+$AQ5)+($AS5*IF($G$1="鸣金",$AJ5,$AH5)+IF($G$1="鸣金",$AK5*1.5,0))*(1+$AU5)*(1+$AV5)+($AW5*IF($G$1="裂石",$AJ5,$AH5)+IF($G$1="裂石",$AK5*1.5,0))*(1+$AY5)*(1+$AZ5)+($BA5*IF($G$1="牵丝",$AJ5,$AH5)+IF($G$1="牵丝",$AK5*1.5,0))*(1+$BC5)*(1+$BD5)+($BE5*IF($G$1="破竹",$AJ5,$AH5)+IF($G$1="破竹",$AK5*1.5,0))*(1+$BG5)*(1+$BH5))*(1+$AL5))*$P5*(1+IF(VLOOKUP($Q5,武学奇术!$A:$ZZ,30,FALSE)="蓄力技",$B$21,0))*(1+$BQ5) -> 14230.723 | P5: 1 | Q5: 萧呤千浪流星 | R5: 易水歌4层 | S5: N/a | T5: N/a | U5: 近战笛 | V5: N/a | W5: N/a | X5: 沧海帖4层 | Y5: 惧刃(拐) | Z5: N/a | AA5: N/a | AB5: N/a | AC5: N/a | AD5: N/a | AE5: 无惧 | AF5: 天志增伤 | AG5: =VLOOKUP($Q5,武学奇术!$A:$ZZ,25,FALSE) -> 群体奇术 | AH5: =VLOOKUP($Q5,武学奇术!$A:$ZZ,26,FALSE) -> 1.4904 | AI5: =VLOOKUP($Q5,武学奇术!$A:$ZZ,27,FALSE)*(1+IF(OR($AG5=$F$4,$AG5=$F$5),$B$22,0)) -> 368 | AJ5: =VLOOKUP($Q5,武学奇术!$A:$ZZ,28,FALSE) -> 2.2353 | AK5: =VLOOKUP($Q5,武学奇术!$A:$ZZ,29,FALSE)*(1+IF(OR($AG5=$F$4,$AG5=$F$5),$B$22,0)) -> 0 | AL5: {=$G$3+IFERROR(VLOOKUP($AG5,$F$4:$G$7,2,FALSE),0)+VLOOKUP($Q5,武学奇术!$A:$ZZ,2,FALSE)+SUM(_xlfn.XLOOKUP($R5:$AF5,增益!$A:$A,增益!$B:$B,0))} -> 0.2437 | AM5: {=VLOOKUP($Q5,武学奇术!$A:$ZZ,5,FALSE)+SUM(_xlfn.XLOOKUP($R5:$AF5,增益!$A:$A,增益!$E:$E,0))} -> 0 | AN5: {=$D$10*(1+$AM5)+VLOOKUP($Q5,武学奇术!$A:$ZZ,3,FALSE)+SUM(_xlfn.XLOOKUP($R5:$AF5,增益!$A:$A,增益!$C:$C,0))-$I$2} -> 3804.006 | AO5: {=$E$10*(1+$AM5)+VLOOKUP($Q5,武学奇术!$A:$ZZ,4,FALSE)+SUM(_xlfn.XLOOKUP($R5:$AF5,增益!$A:$A,增益!$D:$D,0))-$I$2} -> 3804.006 | AP5: {=IF($F$10-$I$3+VLOOKUP($Q5,武学奇术!$A:$ZZ,6,FALSE)+SUM(_xlfn.XLOOKUP(R5:AF5,增益!$A:$A,增益!$F:$F,0))>0,($F$10-$I$3+VLOOKUP($Q5,武学奇术!$A:$ZZ,6,FALSE)+SUM(_xlfn.XLOOKUP(R5:AF5,增益!$A:$A,增益!$F:$F,0)))/200,($F$10-$I$3+VLOOKUP($Q5,武学奇术!$A:$ZZ,6,FALSE)+SUM(_xlfn.XLOOKUP(R5:AF5,增益!$A:$A,增益!$F:$F,0)))/100)} -> 0.307 | AQ5: {=$G$10+VLOOKUP($Q5,武学奇术!$A:$ZZ,7,FALSE)+SUM(_xlfn.XLOOKUP(R5:AF5,增益!$A:$A,增益!$G:$G,0))} -> 0.09 | AR5: {=VLOOKUP($Q5,武学奇术!$A:$ZZ,8,FALSE)+SUM(_xlfn.XLOOKUP(R5:AF5,增益!$A:$A,增益!$H:$H,0))} -> 0 | AS5: =$D$11*(1+$AR5) -> 0 | AT5: =$E$11*(1+$AR5) -> 0 | AU5: {=IF($F$11-$I$4+VLOOKUP($Q5,武学奇术!$A:$ZZ,9,FALSE)+SUM(_xlfn.XLOOKUP(R5:AF5,增益!$A:$A,增益!$I:$I,0))>0,($F$11-$I$4+VLOOKUP($Q5,武学奇术!$A:$ZZ,9,FALSE)+SUM(_xlfn.XLOOKUP(R5:AF5,增益!$A:$A,增益!$I:$I,0)))/200,($F$11-$I$4+VLOOKUP($Q5,武学奇术!$A:$ZZ,9,FALSE)+SUM(_xlfn.XLOOKUP(R5:AF5,增益!$A:$A,增益!$I:$I,0)))/100)} -> -0.14 | AV5: {=$G$11+VLOOKUP($Q5,武学奇术!$A:$ZZ,10,FALSE)+SUM(_xlfn.XLOOKUP(R5:AF5,增益!$A:$A,增益!$J:$J,0))} -> 0 | AW5: =$D$12*(1+$AR5) -> 0 | AX5: =$E$12*(1+$AR5) -> 0 | AY5: {=IF($F$12-$I$4+VLOOKUP($Q5,武学奇术!$A:$ZZ,11,FALSE)+SUM(_xlfn.XLOOKUP(R5:AF5,增益!$A:$A,增益!$K:$K,0))>0,($F$12-$I$4+VLOOKUP($Q5,武学奇术!$A:$ZZ,11,FALSE)+SUM(_xlfn.XLOOKUP(R5:AF5,增益!$A:$A,增益!$K:$K,0)))/200,($F$12-$I$4+VLOOKUP($Q5,武学奇术!$A:$ZZ,11,FALSE)+SUM(_xlfn.XLOOKUP(R5:AF5,增益!$A:$A,增益!$K:$K,0)))/100)} -> -0.14 | AZ5: {=$G$12+VLOOKUP($Q5,武学奇术!$A:$ZZ,12,FALSE)+SUM(_xlfn.XLOOKUP(R5:AF5,增益!$A:$A,增益!$L:$L,0))} -> 0 | BA5: =$D$13*(1+$AR5) -> 0 | BB5: =$E$13*(1+$AR5) -> 0 | BC5: {=IF($F$13-$I$4+VLOOKUP($Q5,武学奇术!$A:$ZZ,13,FALSE)+SUM(_xlfn.XLOOKUP(R5:AF5,增益!$A:$A,增益!$M:$M,0))>0,($F$13-$I$4+VLOOKUP($Q5,武学奇术!$A:$ZZ,13,FALSE)+SUM(_xlfn.XLOOKUP(R5:AF5,增益!$A:$A,增益!$K:$K,0)))/200,($F$13-$I$4+VLOOKUP($Q5,武学奇术!$A:$ZZ,13,FALSE)+SUM(_xlfn.XLOOKUP(R5:AF5,增益!$A:$A,增益!$M:$M,0)))/100)} -> -0.14 | BD5: {=$G$13+VLOOKUP($Q5,武学奇术!$A:$ZZ,14,FALSE)+SUM(_xlfn.XLOOKUP(R5:AF5,增益!$A:$A,增益!$N:$N,0))} -> 0 | BE5: =$D$14*(1+$AR5) -> 570.28 | BF5: =$E$14*(1+$AR5) -> 1582.156 | BG5: {=IF($F$14-$I$4+VLOOKUP($Q5,武学奇术!$A:$ZZ,15,FALSE)+SUM(_xlfn.XLOOKUP(R5:AF5,增益!$A:$A,增益!$O:$O,0))>0,($F$14-$I$4+VLOOKUP($Q5,武学奇术!$A:$ZZ,15,FALSE)+SUM(_xlfn.XLOOKUP(R5:AF5,增益!$A:$A,增益!$O:$O,0)))/200,($F$14-$I$4+VLOOKUP($Q5,武学奇术!$A:$ZZ,15,FALSE)+SUM(_xlfn.XLOOKUP(R5:AF5,增益!$A:$A,增益!$O:$O,0)))/100)} -> 0.08 | BH5: {=$G$14+VLOOKUP($Q5,武学奇术!$A:$ZZ,16,FALSE)+SUM(_xlfn.XLOOKUP(R5:AF5,增益!$A:$A,增益!$P:$P,0))} -> 0.24 | BI5: =MIN(IF(VLOOKUP($Q5,武学奇术!$A:$ZZ,23,FALSE)=1,100%,$B$8),100%) -> 1 | BJ5: {=IF(VLOOKUP($Q5,武学奇术!$A:$ZZ,23,FALSE)=1,100%,MIN(80%,$B$9+VLOOKUP($Q5,武学奇术!$A:$ZZ,17,FALSE)+SUM(_xlfn.XLOOKUP(R5:AF5,增益!$A:$A,增益!$Q:$Q,0)))+$B$11+SUM(_xlfn.XLOOKUP(R5:AF5,增益!$A:$A,增益!$U:$U,0)))*IF(VLOOKUP($Q5,武学奇术!$A:$ZZ,24,FALSE)=1,0,1)+MIN(IF(VLOOKUP($Q5,武学奇术!$A:$ZZ,32,FALSE)=1,IF(VLOOKUP($Q5,武学奇术!$A:$ZZ,24,FALSE)=1,100%,MIN(40%,$B$10+VLOOKUP($Q5,武学奇术!$A:$ZZ,19,FALSE)+SUM(_xlfn.XLOOKUP(R5:AF5,增益!$A:$A,增益!$S:$S,0)))+$B$12+SUM(_xlfn.XLOOKUP(R5:AF5,增益!$A:$A,增益!$V:$V,0))),0),12%)} -> 0.918 | BK5: {=1+$B$13+VLOOKUP($Q5,武学奇术!$A:$ZZ,18,FALSE)+SUM(_xlfn.XLOOKUP(R5:AF5,增益!$A:$A,增益!$R:$R,0))} -> 1.58 | BL5: {=MAX(IF(VLOOKUP($Q5,武学奇术!$A:$ZZ,24,FALSE)=1,100%,MIN(40%,$B$10+VLOOKUP($Q5,武学奇术!$A:$ZZ,19,FALSE)+SUM(_xlfn.XLOOKUP(R5:AF5,增益!$A:$A,增益!$S:$S,0)))+$B$12+SUM(_xlfn.XLOOKUP(R5:AF5,增益!$A:$A,增益!$V:$V,0)))*IF(VLOOKUP($Q5,武学奇术!$A:$ZZ,23,FALSE)=1,0,1)-IF(VLOOKUP($Q5,武学奇术!$A:$ZZ,32,FALSE)=1,12%,0),0)} -> 0.0895 | BM5: {=1+$B$14+VLOOKUP($Q5,武学奇术!$A:$ZZ,20,FALSE)+SUM(_xlfn.XLOOKUP(R5:AF5,增益!$A:$A,增益!$T:$T,0))} -> 1.35 | BN5: =MIN((1-BL5)*BI5,BI5*BJ5) -> 0.9105 | BO5: =1-BL5-BN5-BP5 -> 0 | BP5: =IF(VLOOKUP($Q5,武学奇术!$A:$ZZ,22,FALSE)=1,0,(1-$BI5))*(1-$BL5) -> 0 | BQ5: {=SUM(_xlfn.XLOOKUP(R5:AF5,增益!$A:$A,增益!$W:$W,0))+$I$5} -> 0.11
A6: 破竹 | B6: 472 | C6: 1289 | D6: 30 | E6: 0.15 | F6: 单体奇术 | G6: =B19 -> 0 | K6: =($L6*$BN6+$M6*$BL6+$N6*$BO6+$O6*$BP6) -> 26054.177 | L6: =((($AN6+($AO6-$AN6)*IF(VLOOKUP($Q6,武学奇术!$A:$ZZ,31,FALSE)=1,$F$18,0.5))*$AH6+$AI6)*(1+$AP6)*(1+$AQ6)+(($AS6+($AT6-$AS6)*IF(VLOOKUP($Q6,武学奇术!$A:$ZZ,31,FALSE)=1,$F$18,0.5))*IF($G$1="鸣金",$AJ6,$AH6)+IF($G$1="鸣金",$AK6*1.5,0))*(1+$AU6)*(1+$AV6)+(($AW6+($AX6-$AW6)*IF(VLOOKUP($Q6,武学奇术!$A:$ZZ,31,FALSE)=1,$F$18,0.5))*IF($G$1="裂石",$AJ6,$AH6)+IF($G$1="裂石",$AK6*1.5,0))*(1+$AY6)*(1+$AZ6)+(($BA6+($BB6-$BA6)*IF(VLOOKUP($Q6,武学奇术!$A:$ZZ,31,FALSE)=1,$F$18,0.5))*IF($G$1="牵丝",$AJ6,$AH6)+IF($G$1="牵丝",$AK6*1.5,0))*(1+$BC6)*(1+$BD6)+(($BE6+($BF6-$BE6)*IF(VLOOKUP($Q6,武学奇术!$A:$ZZ,31,FALSE)=1,$F$18,0.5))*IF($G$1="破竹",$AJ6,$AH6)+IF($G$1="破竹",$AK6*1.5,0))*(1+$BG6)*(1+$BH6))*(1+$AL6)*$BK6*$P6*(1+IF(VLOOKUP($Q6,武学奇术!$A:$ZZ,30,FALSE)="蓄力技",$B$21,0))*(1+$BQ6) -> 26140.088 | M6: =(($AO6*$AH6+$AI6)*(1+$AP6)*(1+$AQ6)+($AT6*IF($G$1="鸣金",$AJ6,$AH6)+IF($G$1="鸣金",$AK6*1.5,0))*(1+$AU6)*(1+$AV6)+($AX6*IF($G$1="裂石",$AJ6,$AH6)+IF($G$1="裂石",$AK6*1.5,0))*(1+$AY6)*(1+$AZ6)+($BB6*IF($G$1="牵丝",$AJ6,$AH6)+IF($G$1="牵丝",$AK6*1.5,0))*(1+$BC6)*(1+$BD6)+($BF6*IF($G$1="破竹",$AJ6,$AH6)+IF($G$1="破竹",$AK6*1.5,0))*(1+$BG6)*(1+$BH6))*(1+$AL6)*$BM6*$P6*(1+IF(VLOOKUP($Q6,武学奇术!$A:$ZZ,30,FALSE)="蓄力技",$B$21,0))*(1+$BQ6) -> 25180.191 | N6: =((($AN6+($AO6-$AN6)*IF(VLOOKUP($Q6,武学奇术!$A:$ZZ,31,FALSE)=1,$F$18,0.5))*$AH6+$AI6)*(1+$AP6)*(1+$AQ6)+(($AS6+($AT6-$AS6)*IF(VLOOKUP($Q6,武学奇术!$A:$ZZ,31,FALSE)=1,$F$18,0.5))*IF($G$1="鸣金",$AJ6,$AH6)+IF($G$1="鸣金",$AK6*1.5,0))*(1+$AU6)*(1+$AV6)+(($AW6+($AX6-$AW6)*IF(VLOOKUP($Q6,武学奇术!$A:$ZZ,31,FALSE)=1,$F$18,0.5))*IF($G$1="裂石",$AJ6,$AH6)+IF($G$1="裂石",$AK6*1.5,0))*(1+$AY6)*(1+$AZ6)+(($BA6+($BB6-$BA6)*IF(VLOOKUP($Q6,武学奇术!$A:$ZZ,31,FALSE)=1,$F$18,0.5))*IF($G$1="牵丝",$AJ6,$AH6)+IF($G$1="牵丝",$AK6*1.5,0))*(1+$BC6)*(1+$BD6)+(($BE6+($BF6-$BE6)*IF(VLOOKUP($Q6,武学奇术!$A:$ZZ,31,FALSE)=1,$F$18,0.5))*IF($G$1="破竹",$AJ6,$AH6)+IF($G$1="破竹",$AK6*1.5,0))*(1+$BG6)*(1+$BH6))*(1+$AL6)*$P6*(1+IF(VLOOKUP($Q6,武学奇术!$A:$ZZ,30,FALSE)="蓄力技",$B$21,0))*(1+$BQ6) -> 16544.359 | O6: =((($AN6*$AH6+$AI6)*(1+$AP6)*(1+$AQ6)+($AS6*IF($G$1="鸣金",$AJ6,$AH6)+IF($G$1="鸣金",$AK6*1.5,0))*(1+$AU6)*(1+$AV6)+($AW6*IF($G$1="裂石",$AJ6,$AH6)+IF($G$1="裂石",$AK6*1.5,0))*(1+$AY6)*(1+$AZ6)+($BA6*IF($G$1="牵丝",$AJ6,$AH6)+IF($G$1="牵丝",$AK6*1.5,0))*(1+$BC6)*(1+$BD6)+($BE6*IF($G$1="破竹",$AJ6,$AH6)+IF($G$1="破竹",$AK6*1.5,0))*(1+$BG6)*(1+$BH6))*(1+$AL6))*$P6*(1+IF(VLOOKUP($Q6,武学奇术!$A:$ZZ,30,FALSE)="蓄力技",$B$21,0))*(1+$BQ6) -> 14436.726 | P6: 1 | Q6: 萧呤千浪流星 | R6: 易水歌5层 | S6: N/a | T6: N/a | U6: 近战笛 | V6: N/a | W6: N/a | X6: 沧海帖4层 | Y6: 惧刃(拐) | Z6: N/a | AA6: N/a | AB6: N/a | AC6: N/a | AD6: N/a | AE6: 无惧 | AF6: 天志增伤 | AG6: =VLOOKUP($Q6,武学奇术!$A:$ZZ,25,FALSE) -> 群体奇术 | AH6: =VLOOKUP($Q6,武学奇术!$A:$ZZ,26,FALSE) -> 1.4904 | AI6: =VLOOKUP($Q6,武学奇术!$A:$ZZ,27,FALSE)*(1+IF(OR($AG6=$F$4,$AG6=$F$5),$B$22,0)) -> 368 | AJ6: =VLOOKUP($Q6,武学奇术!$A:$ZZ,28,FALSE) -> 2.2353 | AK6: =VLOOKUP($Q6,武学奇术!$A:$ZZ,29,FALSE)*(1+IF(OR($AG6=$F$4,$AG6=$F$5),$B$22,0)) -> 0 | AL6: {=$G$3+IFERROR(VLOOKUP($AG6,$F$4:$G$7,2,FALSE),0)+VLOOKUP($Q6,武学奇术!$A:$ZZ,2,FALSE)+SUM(_xlfn.XLOOKUP($R6:$AF6,增益!$A:$A,增益!$B:$B,0))} -> 0.2537 | AM6: {=VLOOKUP($Q6,武学奇术!$A:$ZZ,5,FALSE)+SUM(_xlfn.XLOOKUP($R6:$AF6,增益!$A:$A,增益!$E:$E,0))} -> 0 | AN6: {=$D$10*(1+$AM6)+VLOOKUP($Q6,武学奇术!$A:$ZZ,3,FALSE)+SUM(_xlfn.XLOOKUP($R6:$AF6,增益!$A:$A,增益!$C:$C,0))-$I$2} -> 3804.006 | AO6: {=$E$10*(1+$AM6)+VLOOKUP($Q6,武学奇术!$A:$ZZ,4,FALSE)+SUM(_xlfn.XLOOKUP($R6:$AF6,增益!$A:$A,增益!$D:$D,0))-$I$2} -> 3804.006 | AP6: {=IF($F$10-$I$3+VLOOKUP($Q6,武学奇术!$A:$ZZ,6,FALSE)+SUM(_xlfn.XLOOKUP(R6:AF6,增益!$A:$A,增益!$F:$F,0))>0,($F$10-$I$3+VLOOKUP($Q6,武学奇术!$A:$ZZ,6,FALSE)+SUM(_xlfn.XLOOKUP(R6:AF6,增益!$A:$A,增益!$F:$F,0)))/200,($F$10-$I$3+VLOOKUP($Q6,武学奇术!$A:$ZZ,6,FALSE)+SUM(_xlfn.XLOOKUP(R6:AF6,增益!$A:$A,增益!$F:$F,0)))/100)} -> 0.317 | AQ6: {=$G$10+VLOOKUP($Q6,武学奇术!$A:$ZZ,7,FALSE)+SUM(_xlfn.XLOOKUP(R6:AF6,增益!$A:$A,增益!$G:$G,0))} -> 0.09 | AR6: {=VLOOKUP($Q6,武学奇术!$A:$ZZ,8,FALSE)+SUM(_xlfn.XLOOKUP(R6:AF6,增益!$A:$A,增益!$H:$H,0))} -> 0 | AS6: =$D$11*(1+$AR6) -> 0 | AT6: =$E$11*(1+$AR6) -> 0 | AU6: {=IF($F$11-$I$4+VLOOKUP($Q6,武学奇术!$A:$ZZ,9,FALSE)+SUM(_xlfn.XLOOKUP(R6:AF6,增益!$A:$A,增益!$I:$I,0))>0,($F$11-$I$4+VLOOKUP($Q6,武学奇术!$A:$ZZ,9,FALSE)+SUM(_xlfn.XLOOKUP(R6:AF6,增益!$A:$A,增益!$I:$I,0)))/200,($F$11-$I$4+VLOOKUP($Q6,武学奇术!$A:$ZZ,9,FALSE)+SUM(_xlfn.XLOOKUP(R6:AF6,增益!$A:$A,增益!$I:$I,0)))/100)} -> -0.14 | AV6: {=$G$11+VLOOKUP($Q6,武学奇术!$A:$ZZ,10,FALSE)+SUM(_xlfn.XLOOKUP(R6:AF6,增益!$A:$A,增益!$J:$J,0))} -> 0 | AW6: =$D$12*(1+$AR6) -> 0 | AX6: =$E$12*(1+$AR6) -> 0 | AY6: {=IF($F$12-$I$4+VLOOKUP($Q6,武学奇术!$A:$ZZ,11,FALSE)+SUM(_xlfn.XLOOKUP(R6:AF6,增益!$A:$A,增益!$K:$K,0))>0,($F$12-$I$4+VLOOKUP($Q6,武学奇术!$A:$ZZ,11,FALSE)+SUM(_xlfn.XLOOKUP(R6:AF6,增益!$A:$A,增益!$K:$K,0)))/200,($F$12-$I$4+VLOOKUP($Q6,武学奇术!$A:$ZZ,11,FALSE)+SUM(_xlfn.XLOOKUP(R6:AF6,增益!$A:$A,增益!$K:$K,0)))/100)} -> -0.14 | AZ6: {=$G$12+VLOOKUP($Q6,武学奇术!$A:$ZZ,12,FALSE)+SUM(_xlfn.XLOOKUP(R6:AF6,增益!$A:$A,增益!$L:$L,0))} -> 0 | BA6: =$D$13*(1+$AR6) -> 0 | BB6: =$E$13*(1+$AR6) -> 0 | BC6: {=IF($F$13-$I$4+VLOOKUP($Q6,武学奇术!$A:$ZZ,13,FALSE)+SUM(_xlfn.XLOOKUP(R6:AF6,增益!$A:$A,增益!$M:$M,0))>0,($F$13-$I$4+VLOOKUP($Q6,武学奇术!$A:$ZZ,13,FALSE)+SUM(_xlfn.XLOOKUP(R6:AF6,增益!$A:$A,增益!$K:$K,0)))/200,($F$13-$I$4+VLOOKUP($Q6,武学奇术!$A:$ZZ,13,FALSE)+SUM(_xlfn.XLOOKUP(R6:AF6,增益!$A:$A,增益!$M:$M,0)))/100)} -> -0.14 | BD6: {=$G$13+VLOOKUP($Q6,武学奇术!$A:$ZZ,14,FALSE)+SUM(_xlfn.XLOOKUP(R6:AF6,增益!$A:$A,增益!$N:$N,0))} -> 0 | BE6: =$D$14*(1+$AR6) -> 570.28 | BF6: =$E$14*(1+$AR6) -> 1582.156 | BG6: {=IF($F$14-$I$4+VLOOKUP($Q6,武学奇术!$A:$ZZ,15,FALSE)+SUM(_xlfn.XLOOKUP(R6:AF6,增益!$A:$A,增益!$O:$O,0))>0,($F$14-$I$4+VLOOKUP($Q6,武学奇术!$A:$ZZ,15,FALSE)+SUM(_xlfn.XLOOKUP(R6:AF6,增益!$A:$A,增益!$O:$O,0)))/200,($F$14-$I$4+VLOOKUP($Q6,武学奇术!$A:$ZZ,15,FALSE)+SUM(_xlfn.XLOOKUP(R6:AF6,增益!$A:$A,增益!$O:$O,0)))/100)} -> 0.08 | BH6: {=$G$14+VLOOKUP($Q6,武学奇术!$A:$ZZ,16,FALSE)+SUM(_xlfn.XLOOKUP(R6:AF6,增益!$A:$A,增益!$P:$P,0))} -> 0.24 | BI6: =MIN(IF(VLOOKUP($Q6,武学奇术!$A:$ZZ,23,FALSE)=1,100%,$B$8),100%) -> 1 | BJ6: {=IF(VLOOKUP($Q6,武学奇术!$A:$ZZ,23,FALSE)=1,100%,MIN(80%,$B$9+VLOOKUP($Q6,武学奇术!$A:$ZZ,17,FALSE)+SUM(_xlfn.XLOOKUP(R6:AF6,增益!$A:$A,增益!$Q:$Q,0)))+$B$11+SUM(_xlfn.XLOOKUP(R6:AF6,增益!$A:$A,增益!$U:$U,0)))*IF(VLOOKUP($Q6,武学奇术!$A:$ZZ,24,FALSE)=1,0,1)+MIN(IF(VLOOKUP($Q6,武学奇术!$A:$ZZ,32,FALSE)=1,IF(VLOOKUP($Q6,武学奇术!$A:$ZZ,24,FALSE)=1,100%,MIN(40%,$B$10+VLOOKUP($Q6,武学奇术!$A:$ZZ,19,FALSE)+SUM(_xlfn.XLOOKUP(R6:AF6,增益!$A:$A,增益!$S:$S,0)))+$B$12+SUM(_xlfn.XLOOKUP(R6:AF6,增益!$A:$A,增益!$V:$V,0))),0),12%)} -> 0.918 | BK6: {=1+$B$13+VLOOKUP($Q6,武学奇术!$A:$ZZ,18,FALSE)+SUM(_xlfn.XLOOKUP(R6:AF6,增益!$A:$A,增益!$R:$R,0))} -> 1.58 | BL6: {=MAX(IF(VLOOKUP($Q6,武学奇术!$A:$ZZ,24,FALSE)=1,100%,MIN(40%,$B$10+VLOOKUP($Q6,武学奇术!$A:$ZZ,19,FALSE)+SUM(_xlfn.XLOOKUP(R6:AF6,增益!$A:$A,增益!$S:$S,0)))+$B$12+SUM(_xlfn.XLOOKUP(R6:AF6,增益!$A:$A,增益!$V:$V,0)))*IF(VLOOKUP($Q6,武学奇术!$A:$ZZ,23,FALSE)=1,0,1)-IF(VLOOKUP($Q6,武学奇术!$A:$ZZ,32,FALSE)=1,12%,0),0)} -> 0.0895 | BM6: {=1+$B$14+VLOOKUP($Q6,武学奇术!$A:$ZZ,20,FALSE)+SUM(_xlfn.XLOOKUP(R6:AF6,增益!$A:$A,增益!$T:$T,0))} -> 1.35 | BN6: =MIN((1-BL6)*BI6,BI6*BJ6) -> 0.9105 | BO6: =1-BL6-BN6-BP6 -> 0 | BP6: =IF(VLOOKUP($Q6,武学奇术!$A:$ZZ,22,FALSE)=1,0,(1-$BI6))*(1-$BL6) -> 0 | BQ6: {=SUM(_xlfn.XLOOKUP(R6:AF6,增益!$A:$A,增益!$W:$W,0))+$I$5} -> 0.11
A7: 无相 | B7: 66 | C7: =66+68.8*2 -> 203.6 | F7: 群体奇术 | G7: =B20 -> 0 | K7: =($L7*$BN7+$M7*$BL7+$N7*$BO7+$O7*$BP7) -> 8809.6528 | L7: =((($AN7+($AO7-$AN7)*IF(VLOOKUP($Q7,武学奇术!$A:$ZZ,31,FALSE)=1,$F$18,0.5))*$AH7+$AI7)*(1+$AP7)*(1+$AQ7)+(($AS7+($AT7-$AS7)*IF(VLOOKUP($Q7,武学奇术!$A:$ZZ,31,FALSE)=1,$F$18,0.5))*IF($G$1="鸣金",$AJ7,$AH7)+IF($G$1="鸣金",$AK7*1.5,0))*(1+$AU7)*(1+$AV7)+(($AW7+($AX7-$AW7)*IF(VLOOKUP($Q7,武学奇术!$A:$ZZ,31,FALSE)=1,$F$18,0.5))*IF($G$1="裂石",$AJ7,$AH7)+IF($G$1="裂石",$AK7*1.5,0))*(1+$AY7)*(1+$AZ7)+(($BA7+($BB7-$BA7)*IF(VLOOKUP($Q7,武学奇术!$A:$ZZ,31,FALSE)=1,$F$18,0.5))*IF($G$1="牵丝",$AJ7,$AH7)+IF($G$1="牵丝",$AK7*1.5,0))*(1+$BC7)*(1+$BD7)+(($BE7+($BF7-$BE7)*IF(VLOOKUP($Q7,武学奇术!$A:$ZZ,31,FALSE)=1,$F$18,0.5))*IF($G$1="破竹",$AJ7,$AH7)+IF($G$1="破竹",$AK7*1.5,0))*(1+$BG7)*(1+$BH7))*(1+$AL7)*$BK7*$P7*(1+IF(VLOOKUP($Q7,武学奇术!$A:$ZZ,30,FALSE)="蓄力技",$B$21,0))*(1+$BQ7) -> 8827.4491 | M7: =(($AO7*$AH7+$AI7)*(1+$AP7)*(1+$AQ7)+($AT7*IF($G$1="鸣金",$AJ7,$AH7)+IF($G$1="鸣金",$AK7*1.5,0))*(1+$AU7)*(1+$AV7)+($AX7*IF($G$1="裂石",$AJ7,$AH7)+IF($G$1="裂石",$AK7*1.5,0))*(1+$AY7)*(1+$AZ7)+($BB7*IF($G$1="牵丝",$AJ7,$AH7)+IF($G$1="牵丝",$AK7*1.5,0))*(1+$BC7)*(1+$BD7)+($BF7*IF($G$1="破竹",$AJ7,$AH7)+IF($G$1="破竹",$AK7*1.5,0))*(1+$BG7)*(1+$BH7))*(1+$AL7)*$BM7*$P7*(1+IF(VLOOKUP($Q7,武学奇术!$A:$ZZ,30,FALSE)="蓄力技",$B$21,0))*(1+$BQ7) -> 8628.6076 | N7: =((($AN7+($AO7-$AN7)*IF(VLOOKUP($Q7,武学奇术!$A:$ZZ,31,FALSE)=1,$F$18,0.5))*$AH7+$AI7)*(1+$AP7)*(1+$AQ7)+(($AS7+($AT7-$AS7)*IF(VLOOKUP($Q7,武学奇术!$A:$ZZ,31,FALSE)=1,$F$18,0.5))*IF($G$1="鸣金",$AJ7,$AH7)+IF($G$1="鸣金",$AK7*1.5,0))*(1+$AU7)*(1+$AV7)+(($AW7+($AX7-$AW7)*IF(VLOOKUP($Q7,武学奇术!$A:$ZZ,31,FALSE)=1,$F$18,0.5))*IF($G$1="裂石",$AJ7,$AH7)+IF($G$1="裂石",$AK7*1.5,0))*(1+$AY7)*(1+$AZ7)+(($BA7+($BB7-$BA7)*IF(VLOOKUP($Q7,武学奇术!$A:$ZZ,31,FALSE)=1,$F$18,0.5))*IF($G$1="牵丝",$AJ7,$AH7)+IF($G$1="牵丝",$AK7*1.5,0))*(1+$BC7)*(1+$BD7)+(($BE7+($BF7-$BE7)*IF(VLOOKUP($Q7,武学奇术!$A:$ZZ,31,FALSE)=1,$F$18,0.5))*IF($G$1="破竹",$AJ7,$AH7)+IF($G$1="破竹",$AK7*1.5,0))*(1+$BG7)*(1+$BH7))*(1+$AL7)*$P7*(1+IF(VLOOKUP($Q7,武学奇术!$A:$ZZ,30,FALSE)="蓄力技",$B$21,0))*(1+$BQ7) -> 5732.1098 | O7: =((($AN7*$AH7+$AI7)*(1+$AP7)*(1+$AQ7)+($AS7*IF($G$1="鸣金",$AJ7,$AH7)+IF($G$1="鸣金",$AK7*1.5,0))*(1+$AU7)*(1+$AV7)+($AW7*IF($G$1="裂石",$AJ7,$AH7)+IF($G$1="裂石",$AK7*1.5,0))*(1+$AY7)*(1+$AZ7)+($BA7*IF($G$1="牵丝",$AJ7,$AH7)+IF($G$1="牵丝",$AK7*1.5,0))*(1+$BC7)*(1+$BD7)+($BE7*IF($G$1="破竹",$AJ7,$AH7)+IF($G$1="破竹",$AK7*1.5,0))*(1+$BG7)*(1+$BH7))*(1+$AL7))*$P7*(1+IF(VLOOKUP($Q7,武学奇术!$A:$ZZ,30,FALSE)="蓄力技",$B$21,0))*(1+$BQ7) -> 5072.6584 | P7: 1 | Q7: 绳标Q卸 | R7: N/a | S7: N/a | T7: N/a | U7: N/a | V7: N/a | W7: N/a | X7: N/a | Y7: N/a | Z7: N/a | AA7: N/a | AB7: N/a | AC7: N/a | AD7: N/a | AE7: 无惧 | AF7: 天志增伤 | AG7: =VLOOKUP($Q7,武学奇术!$A:$ZZ,25,FALSE) -> 绳镖 | AH7: =VLOOKUP($Q7,武学奇术!$A:$ZZ,26,FALSE) -> 0.4975 | AI7: =VLOOKUP($Q7,武学奇术!$A:$ZZ,27,FALSE)*(1+IF(OR($AG7=$F$4,$AG7=$F$5),$B$22,0)) -> 191.8 | AJ7: =VLOOKUP($Q7,武学奇术!$A:$ZZ,28,FALSE) -> 0.7463 | AK7: =VLOOKUP($Q7,武学奇术!$A:$ZZ,29,FALSE)*(1+IF(OR($AG7=$F$4,$AG7=$F$5),$B$22,0)) -> 105 | AL7: {=$G$3+IFERROR(VLOOKUP($AG7,$F$4:$G$7,2,FALSE),0)+VLOOKUP($Q7,武学奇术!$A:$ZZ,2,FALSE)+SUM(_xlfn.XLOOKUP($R7:$AF7,增益!$A:$A,增益!$B:$B,0))} -> 0.2689 | AM7: {=VLOOKUP($Q7,武学奇术!$A:$ZZ,5,FALSE)+SUM(_xlfn.XLOOKUP($R7:$AF7,增益!$A:$A,增益!$E:$E,0))} -> 0 | AN7: {=$D$10*(1+$AM7)+VLOOKUP($Q7,武学奇术!$A:$ZZ,3,FALSE)+SUM(_xlfn.XLOOKUP($R7:$AF7,增益!$A:$A,增益!$C:$C,0))-$I$2} -> 3804.006 | AO7: {=$E$10*(1+$AM7)+VLOOKUP($Q7,武学奇术!$A:$ZZ,4,FALSE)+SUM(_xlfn.XLOOKUP($R7:$AF7,增益!$A:$A,增益!$D:$D,0))-$I$2} -> 3804.006 | AP7: {=IF($F$10-$I$3+VLOOKUP($Q7,武学奇术!$A:$ZZ,6,FALSE)+SUM(_xlfn.XLOOKUP(R7:AF7,增益!$A:$A,增益!$F:$F,0))>0,($F$10-$I$3+VLOOKUP($Q7,武学奇术!$A:$ZZ,6,FALSE)+SUM(_xlfn.XLOOKUP(R7:AF7,增益!$A:$A,增益!$F:$F,0)))/200,($F$10-$I$3+VLOOKUP($Q7,武学奇术!$A:$ZZ,6,FALSE)+SUM(_xlfn.XLOOKUP(R7:AF7,增益!$A:$A,增益!$F:$F,0)))/100)} -> 0.267 | AQ7: {=$G$10+VLOOKUP($Q7,武学奇术!$A:$ZZ,7,FALSE)+SUM(_xlfn.XLOOKUP(R7:AF7,增益!$A:$A,增益!$G:$G,0))} -> 0.09 | AR7: {=VLOOKUP($Q7,武学奇术!$A:$ZZ,8,FALSE)+SUM(_xlfn.XLOOKUP(R7:AF7,增益!$A:$A,增益!$H:$H,0))} -> 0 | AS7: =$D$11*(1+$AR7) -> 0 | AT7: =$E$11*(1+$AR7) -> 0 | AU7: {=IF($F$11-$I$4+VLOOKUP($Q7,武学奇术!$A:$ZZ,9,FALSE)+SUM(_xlfn.XLOOKUP(R7:AF7,增益!$A:$A,增益!$I:$I,0))>0,($F$11-$I$4+VLOOKUP($Q7,武学奇术!$A:$ZZ,9,FALSE)+SUM(_xlfn.XLOOKUP(R7:AF7,增益!$A:$A,增益!$I:$I,0)))/200,($F$11-$I$4+VLOOKUP($Q7,武学奇术!$A:$ZZ,9,FALSE)+SUM(_xlfn.XLOOKUP(R7:AF7,增益!$A:$A,增益!$I:$I,0)))/100)} -> -0.3 | AV7: {=$G$11+VLOOKUP($Q7,武学奇术!$A:$ZZ,10,FALSE)+SUM(_xlfn.XLOOKUP(R7:AF7,增益!$A:$A,增益!$J:$J,0))} -> 0 | AW7: =$D$12*(1+$AR7) -> 0 | AX7: =$E$12*(1+$AR7) -> 0 | AY7: {=IF($F$12-$I$4+VLOOKUP($Q7,武学奇术!$A:$ZZ,11,FALSE)+SUM(_xlfn.XLOOKUP(R7:AF7,增益!$A:$A,增益!$K:$K,0))>0,($F$12-$I$4+VLOOKUP($Q7,武学奇术!$A:$ZZ,11,FALSE)+SUM(_xlfn.XLOOKUP(R7:AF7,增益!$A:$A,增益!$K:$K,0)))/200,($F$12-$I$4+VLOOKUP($Q7,武学奇术!$A:$ZZ,11,FALSE)+SUM(_xlfn.XLOOKUP(R7:AF7,增益!$A:$A,增益!$K:$K,0)))/100)} -> -0.3 | AZ7: {=$G$12+VLOOKUP($Q7,武学奇术!$A:$ZZ,12,FALSE)+SUM(_xlfn.XLOOKUP(R7:AF7,增益!$A:$A,增益!$L:$L,0))} -> 0 | BA7: =$D$13*(1+$AR7) -> 0 | BB7: =$E$13*(1+$AR7) -> 0 | BC7: {=IF($F$13-$I$4+VLOOKUP($Q7,武学奇术!$A:$ZZ,13,FALSE)+SUM(_xlfn.XLOOKUP(R7:AF7,增益!$A:$A,增益!$M:$M,0))>0,($F$13-$I$4+VLOOKUP($Q7,武学奇术!$A:$ZZ,13,FALSE)+SUM(_xlfn.XLOOKUP(R7:AF7,增益!$A:$A,增益!$K:$K,0)))/200,($F$13-$I$4+VLOOKUP($Q7,武学奇术!$A:$ZZ,13,FALSE)+SUM(_xlfn.XLOOKUP(R7:AF7,增益!$A:$A,增益!$M:$M,0)))/100)} -> -0.3 | BD7: {=$G$13+VLOOKUP($Q7,武学奇术!$A:$ZZ,14,FALSE)+SUM(_xlfn.XLOOKUP(R7:AF7,增益!$A:$A,增益!$N:$N,0))} -> 0 | BE7: =$D$14*(1+$AR7) -> 570.28 | BF7: =$E$14*(1+$AR7) -> 1582.156 | BG7: {=IF($F$14-$I$4+VLOOKUP($Q7,武学奇术!$A:$ZZ,15,FALSE)+SUM(_xlfn.XLOOKUP(R7:AF7,增益!$A:$A,增益!$O:$O,0))>0,($F$14-$I$4+VLOOKUP($Q7,武学奇术!$A:$ZZ,15,FALSE)+SUM(_xlfn.XLOOKUP(R7:AF7,增益!$A:$A,增益!$O:$O,0)))/200,($F$14-$I$4+VLOOKUP($Q7,武学奇术!$A:$ZZ,15,FALSE)+SUM(_xlfn.XLOOKUP(R7:AF7,增益!$A:$A,增益!$O:$O,0)))/100)} -> 0 | BH7: {=$G$14+VLOOKUP($Q7,武学奇术!$A:$ZZ,16,FALSE)+SUM(_xlfn.XLOOKUP(R7:AF7,增益!$A:$A,增益!$P:$P,0))} -> 0.24 | BI7: =MIN(IF(VLOOKUP($Q7,武学奇术!$A:$ZZ,23,FALSE)=1,100%,$B$8),100%) -> 1 | BJ7: {=IF(VLOOKUP($Q7,武学奇术!$A:$ZZ,23,FALSE)=1,100%,MIN(80%,$B$9+VLOOKUP($Q7,武学奇术!$A:$ZZ,17,FALSE)+SUM(_xlfn.XLOOKUP(R7:AF7,增益!$A:$A,增益!$Q:$Q,0)))+$B$11+SUM(_xlfn.XLOOKUP(R7:AF7,增益!$A:$A,增益!$U:$U,0)))*IF(VLOOKUP($Q7,武学奇术!$A:$ZZ,24,FALSE)=1,0,1)+MIN(IF(VLOOKUP($Q7,武学奇术!$A:$ZZ,32,FALSE)=1,IF(VLOOKUP($Q7,武学奇术!$A:$ZZ,24,FALSE)=1,100%,MIN(40%,$B$10+VLOOKUP($Q7,武学奇术!$A:$ZZ,19,FALSE)+SUM(_xlfn.XLOOKUP(R7:AF7,增益!$A:$A,增益!$S:$S,0)))+$B$12+SUM(_xlfn.XLOOKUP(R7:AF7,增益!$A:$A,增益!$V:$V,0))),0),12%)} -> 0.918 | BK7: {=1+$B$13+VLOOKUP($Q7,武学奇术!$A:$ZZ,18,FALSE)+SUM(_xlfn.XLOOKUP(R7:AF7,增益!$A:$A,增益!$R:$R,0))} -> 1.54 | BL7: {=MAX(IF(VLOOKUP($Q7,武学奇术!$A:$ZZ,24,FALSE)=1,100%,MIN(40%,$B$10+VLOOKUP($Q7,武学奇术!$A:$ZZ,19,FALSE)+SUM(_xlfn.XLOOKUP(R7:AF7,增益!$A:$A,增益!$S:$S,0)))+$B$12+SUM(_xlfn.XLOOKUP(R7:AF7,增益!$A:$A,增益!$V:$V,0)))*IF(VLOOKUP($Q7,武学奇术!$A:$ZZ,23,FALSE)=1,0,1)-IF(VLOOKUP($Q7,武学奇术!$A:$ZZ,32,FALSE)=1,12%,0),0)} -> 0.0895 | BM7: {=1+$B$14+VLOOKUP($Q7,武学奇术!$A:$ZZ,20,FALSE)+SUM(_xlfn.XLOOKUP(R7:AF7,增益!$A:$A,增益!$T:$T,0))} -> 1.35 | BN7: =MIN((1-BL7)*BI7,BI7*BJ7) -> 0.9105 | BO7: =1-BL7-BN7-BP7 -> 0 | BP7: =IF(VLOOKUP($Q7,武学奇术!$A:$ZZ,22,FALSE)=1,0,(1-$BI7))*(1-$BL7) -> 0 | BQ7: {=SUM(_xlfn.XLOOKUP(R7:AF7,增益!$A:$A,增益!$W:$W,0))+$I$5} -> 0.11
A8: 精准率 | B8: 1.0218 | C8: 实际属性 | H8: 战斗时间 | I8: 111 | K8: =($L8*$BN8+$M8*$BL8+$N8*$BO8+$O8*$BP8) -> 55716.977 | L8: =((($AN8+($AO8-$AN8)*IF(VLOOKUP($Q8,武学奇术!$A:$ZZ,31,FALSE)=1,$F$18,0.5))*$AH8+$AI8)*(1+$AP8)*(1+$AQ8)+(($AS8+($AT8-$AS8)*IF(VLOOKUP($Q8,武学奇术!$A:$ZZ,31,FALSE)=1,$F$18,0.5))*IF($G$1="鸣金",$AJ8,$AH8)+IF($G$1="鸣金",$AK8*1.5,0))*(1+$AU8)*(1+$AV8)+(($AW8+($AX8-$AW8)*IF(VLOOKUP($Q8,武学奇术!$A:$ZZ,31,FALSE)=1,$F$18,0.5))*IF($G$1="裂石",$AJ8,$AH8)+IF($G$1="裂石",$AK8*1.5,0))*(1+$AY8)*(1+$AZ8)+(($BA8+($BB8-$BA8)*IF(VLOOKUP($Q8,武学奇术!$A:$ZZ,31,FALSE)=1,$F$18,0.5))*IF($G$1="牵丝",$AJ8,$AH8)+IF($G$1="牵丝",$AK8*1.5,0))*(1+$BC8)*(1+$BD8)+(($BE8+($BF8-$BE8)*IF(VLOOKUP($Q8,武学奇术!$A:$ZZ,31,FALSE)=1,$F$18,0.5))*IF($G$1="破竹",$AJ8,$AH8)+IF($G$1="破竹",$AK8*1.5,0))*(1+$BG8)*(1+$BH8))*(1+$AL8)*$BK8*$P8*(1+IF(VLOOKUP($Q8,武学奇术!$A:$ZZ,30,FALSE)="蓄力技",$B$21,0))*(1+$BQ8) -> 56607.258 | M8: =(($AO8*$AH8+$AI8)*(1+$AP8)*(1+$AQ8)+($AT8*IF($G$1="鸣金",$AJ8,$AH8)+IF($G$1="鸣金",$AK8*1.5,0))*(1+$AU8)*(1+$AV8)+($AX8*IF($G$1="裂石",$AJ8,$AH8)+IF($G$1="裂石",$AK8*1.5,0))*(1+$AY8)*(1+$AZ8)+($BB8*IF($G$1="牵丝",$AJ8,$AH8)+IF($G$1="牵丝",$AK8*1.5,0))*(1+$BC8)*(1+$BD8)+($BF8*IF($G$1="破竹",$AJ8,$AH8)+IF($G$1="破竹",$AK8*1.5,0))*(1+$BG8)*(1+$BH8))*(1+$AL8)*$BM8*$P8*(1+IF(VLOOKUP($Q8,武学奇术!$A:$ZZ,30,FALSE)="蓄力技",$B$21,0))*(1+$BQ8) -> 46659.986 | N8: =((($AN8+($AO8-$AN8)*IF(VLOOKUP($Q8,武学奇术!$A:$ZZ,31,FALSE)=1,$F$18,0.5))*$AH8+$AI8)*(1+$AP8)*(1+$AQ8)+(($AS8+($AT8-$AS8)*IF(VLOOKUP($Q8,武学奇术!$A:$ZZ,31,FALSE)=1,$F$18,0.5))*IF($G$1="鸣金",$AJ8,$AH8)+IF($G$1="鸣金",$AK8*1.5,0))*(1+$AU8)*(1+$AV8)+(($AW8+($AX8-$AW8)*IF(VLOOKUP($Q8,武学奇术!$A:$ZZ,31,FALSE)=1,$F$18,0.5))*IF($G$1="裂石",$AJ8,$AH8)+IF($G$1="裂石",$AK8*1.5,0))*(1+$AY8)*(1+$AZ8)+(($BA8+($BB8-$BA8)*IF(VLOOKUP($Q8,武学奇术!$A:$ZZ,31,FALSE)=1,$F$18,0.5))*IF($G$1="牵丝",$AJ8,$AH8)+IF($G$1="牵丝",$AK8*1.5,0))*(1+$BC8)*(1+$BD8)+(($BE8+($BF8-$BE8)*IF(VLOOKUP($Q8,武学奇术!$A:$ZZ,31,FALSE)=1,$F$18,0.5))*IF($G$1="破竹",$AJ8,$AH8)+IF($G$1="破竹",$AK8*1.5,0))*(1+$BG8)*(1+$BH8))*(1+$AL8)*$P8*(1+IF(VLOOKUP($Q8,武学奇术!$A:$ZZ,30,FALSE)="蓄力技",$B$21,0))*(1+$BQ8) -> 30598.518 | O8: =((($AN8*$AH8+$AI8)*(1+$AP8)*(1+$AQ8)+($AS8*IF($G$1="鸣金",$AJ8,$AH8)+IF($G$1="鸣金",$AK8*1.5,0))*(1+$AU8)*(1+$AV8)+($AW8*IF($G$1="裂石",$AJ8,$AH8)+IF($G$1="裂石",$AK8*1.5,0))*(1+$AY8)*(1+$AZ8)+($BA8*IF($G$1="牵丝",$AJ8,$AH8)+IF($G$1="牵丝",$AK8*1.5,0))*(1+$BC8)*(1+$BD8)+($BE8*IF($G$1="破竹",$AJ8,$AH8)+IF($G$1="破竹",$AK8*1.5,0))*(1+$BG8)*(1+$BH8))*(1+$AL8))*$P8*(1+IF(VLOOKUP($Q8,武学奇术!$A:$ZZ,30,FALSE)="蓄力技",$B$21,0))*(1+$BQ8) -> 26634.083 | P8: 1 | Q8: 鹰隼追击(绳标) | R8: 易水歌1层 | S8: N/a | T8: N/a | U8: N/a | V8: N/a | W8: N/a | X8: 沧海帖1层 | Y8: N/a | Z8: 三穷 | AA8: N/a | AB8: N/a | AC8: N/a | AD8: N/a | AE8: 无惧 | AF8: 天志增伤 | AG8: =VLOOKUP($Q8,武学奇术!$A:$ZZ,25,FALSE) -> 绳镖 | AH8: =VLOOKUP($Q8,武学奇术!$A:$ZZ,26,FALSE) -> 2.33376 | AI8: =VLOOKUP($Q8,武学奇术!$A:$ZZ,27,FALSE)*(1+IF(OR($AG8=$F$4,$AG8=$F$5),$B$22,0)) -> 0 | AJ8: =VLOOKUP($Q8,武学奇术!$A:$ZZ,28,FALSE) -> 3.50064 | AK8: =VLOOKUP($Q8,武学奇术!$A:$ZZ,29,FALSE)*(1+IF(OR($AG8=$F$4,$AG8=$F$5),$B$22,0)) -> 0 | AL8: {=$G$3+IFERROR(VLOOKUP($AG8,$F$4:$G$7,2,FALSE),0)+VLOOKUP($Q8,武学奇术!$A:$ZZ,2,FALSE)+SUM(_xlfn.XLOOKUP($R8:$AF8,增益!$A:$A,增益!$B:$B,0))} -> 0.5789 | AM8: {=VLOOKUP($Q8,武学奇术!$A:$ZZ,5,FALSE)+SUM(_xlfn.XLOOKUP($R8:$AF8,增益!$A:$A,增益!$E:$E,0))} -> 0 | AN8: {=$D$10*(1+$AM8)+VLOOKUP($Q8,武学奇术!$A:$ZZ,3,FALSE)+SUM(_xlfn.XLOOKUP($R8:$AF8,增益!$A:$A,增益!$C:$C,0))-$I$2} -> 3804.006 | AO8: {=$E$10*(1+$AM8)+VLOOKUP($Q8,武学奇术!$A:$ZZ,4,FALSE)+SUM(_xlfn.XLOOKUP($R8:$AF8,增益!$A:$A,增益!$D:$D,0))-$I$2} -> 3804.006 | AP8: {=IF($F$10-$I$3+VLOOKUP($Q8,武学奇术!$A:$ZZ,6,FALSE)+SUM(_xlfn.XLOOKUP(R8:AF8,增益!$A:$A,增益!$F:$F,0))>0,($F$10-$I$3+VLOOKUP($Q8,武学奇术!$A:$ZZ,6,FALSE)+SUM(_xlfn.XLOOKUP(R8:AF8,增益!$A:$A,增益!$F:$F,0)))/200,($F$10-$I$3+VLOOKUP($Q8,武学奇术!$A:$ZZ,6,FALSE)+SUM(_xlfn.XLOOKUP(R8:AF8,增益!$A:$A,增益!$F:$F,0)))/100)} -> 0.307 | AQ8: {=$G$10+VLOOKUP($Q8,武学奇术!$A:$ZZ,7,FALSE)+SUM(_xlfn.XLOOKUP(R8:AF8,增益!$A:$A,增益!$G:$G,0))} -> 0.09 | AR8: {=VLOOKUP($Q8,武学奇术!$A:$ZZ,8,FALSE)+SUM(_xlfn.XLOOKUP(R8:AF8,增益!$A:$A,增益!$H:$H,0))} -> 0 | AS8: =$D$11*(1+$AR8) -> 0 | AT8: =$E$11*(1+$AR8) -> 0 | AU8: {=IF($F$11-$I$4+VLOOKUP($Q8,武学奇术!$A:$ZZ,9,FALSE)+SUM(_xlfn.XLOOKUP(R8:AF8,增益!$A:$A,增益!$I:$I,0))>0,($F$11-$I$4+VLOOKUP($Q8,武学奇术!$A:$ZZ,9,FALSE)+SUM(_xlfn.XLOOKUP(R8:AF8,增益!$A:$A,增益!$I:$I,0)))/200,($F$11-$I$4+VLOOKUP($Q8,武学奇术!$A:$ZZ,9,FALSE)+SUM(_xlfn.XLOOKUP(R8:AF8,增益!$A:$A,增益!$I:$I,0)))/100)} -> -0.24 | AV8: {=$G$11+VLOOKUP($Q8,武学奇术!$A:$ZZ,10,FALSE)+SUM(_xlfn.XLOOKUP(R8:AF8,增益!$A:$A,增益!$J:$J,0))} -> 0 | AW8: =$D$12*(1+$AR8) -> 0 | AX8: =$E$12*(1+$AR8) -> 0 | AY8: {=IF($F$12-$I$4+VLOOKUP($Q8,武学奇术!$A:$ZZ,11,FALSE)+SUM(_xlfn.XLOOKUP(R8:AF8,增益!$A:$A,增益!$K:$K,0))>0,($F$12-$I$4+VLOOKUP($Q8,武学奇术!$A:$ZZ,11,FALSE)+SUM(_xlfn.XLOOKUP(R8:AF8,增益!$A:$A,增益!$K:$K,0)))/200,($F$12-$I$4+VLOOKUP($Q8,武学奇术!$A:$ZZ,11,FALSE)+SUM(_xlfn.XLOOKUP(R8:AF8,增益!$A:$A,增益!$K:$K,0)))/100)} -> -0.24 | AZ8: {=$G$12+VLOOKUP($Q8,武学奇术!$A:$ZZ,12,FALSE)+SUM(_xlfn.XLOOKUP(R8:AF8,增益!$A:$A,增益!$L:$L,0))} -> 0 | BA8: =$D$13*(1+$AR8) -> 0 | BB8: =$E$13*(1+$AR8) -> 0 | BC8: {=IF($F$13-$I$4+VLOOKUP($Q8,武学奇术!$A:$ZZ,13,FALSE)+SUM(_xlfn.XLOOKUP(R8:AF8,增益!$A:$A,增益!$M:$M,0))>0,($F$13-$I$4+VLOOKUP($Q8,武学奇术!$A:$ZZ,13,FALSE)+SUM(_xlfn.XLOOKUP(R8:AF8,增益!$A:$A,增益!$K:$K,0)))/200,($F$13-$I$4+VLOOKUP($Q8,武学奇术!$A:$ZZ,13,FALSE)+SUM(_xlfn.XLOOKUP(R8:AF8,增益!$A:$A,增益!$M:$M,0)))/100)} -> -0.24 | BD8: {=$G$13+VLOOKUP($Q8,武学奇术!$A:$ZZ,14,FALSE)+SUM(_xlfn.XLOOKUP(R8:AF8,增益!$A:$A,增益!$N:$N,0))} -> 0 | BE8: =$D$14*(1+$AR8) -> 570.28 | BF8: =$E$14*(1+$AR8) -> 1582.156 | BG8: {=IF($F$14-$I$4+VLOOKUP($Q8,武学奇术!$A:$ZZ,15,FALSE)+SUM(_xlfn.XLOOKUP(R8:AF8,增益!$A:$A,增益!$O:$O,0))>0,($F$14-$I$4+VLOOKUP($Q8,武学奇术!$A:$ZZ,15,FALSE)+SUM(_xlfn.XLOOKUP(R8:AF8,增益!$A:$A,增益!$O:$O,0)))/200,($F$14-$I$4+VLOOKUP($Q8,武学奇术!$A:$ZZ,15,FALSE)+SUM(_xlfn.XLOOKUP(R8:AF8,增益!$A:$A,增益!$O:$O,0)))/100)} -> 0.03 | BH8: {=$G$14+VLOOKUP($Q8,武学奇术!$A:$ZZ,16,FALSE)+SUM(_xlfn.XLOOKUP(R8:AF8,增益!$A:$A,增益!$P:$P,0))} -> 0.24 | BI8: =MIN(IF(VLOOKUP($Q8,武学奇术!$A:$ZZ,23,FALSE)=1,100%,$B$8),100%) -> 1 | BJ8: {=IF(VLOOKUP($Q8,武学奇术!$A:$ZZ,23,FALSE)=1,100%,MIN(80%,$B$9+VLOOKUP($Q8,武学奇术!$A:$ZZ,17,FALSE)+SUM(_xlfn.XLOOKUP(R8:AF8,增益!$A:$A,增益!$Q:$Q,0)))+$B$11+SUM(_xlfn.XLOOKUP(R8:AF8,增益!$A:$A,增益!$U:$U,0)))*IF(VLOOKUP($Q8,武学奇术!$A:$ZZ,24,FALSE)=1,0,1)+MIN(IF(VLOOKUP($Q8,武学奇术!$A:$ZZ,32,FALSE)=1,IF(VLOOKUP($Q8,武学奇术!$A:$ZZ,24,FALSE)=1,100%,MIN(40%,$B$10+VLOOKUP($Q8,武学奇术!$A:$ZZ,19,FALSE)+SUM(_xlfn.XLOOKUP(R8:AF8,增益!$A:$A,增益!$S:$S,0)))+$B$12+SUM(_xlfn.XLOOKUP(R8:AF8,增益!$A:$A,增益!$V:$V,0))),0),12%)} -> 0.918 | BK8: {=1+$B$13+VLOOKUP($Q8,武学奇术!$A:$ZZ,18,FALSE)+SUM(_xlfn.XLOOKUP(R8:AF8,增益!$A:$A,增益!$R:$R,0))} -> 1.85 | BL8: {=MAX(IF(VLOOKUP($Q8,武学奇术!$A:$ZZ,24,FALSE)=1,100%,MIN(40%,$B$10+VLOOKUP($Q8,武学奇术!$A:$ZZ,19,FALSE)+SUM(_xlfn.XLOOKUP(R8:AF8,增益!$A:$A,增益!$S:$S,0)))+$B$12+SUM(_xlfn.XLOOKUP(R8:AF8,增益!$A:$A,增益!$V:$V,0)))*IF(VLOOKUP($Q8,武学奇术!$A:$ZZ,23,FALSE)=1,0,1)-IF(VLOOKUP($Q8,武学奇术!$A:$ZZ,32,FALSE)=1,12%,0),0)} -> 0.0895 | BM8: {=1+$B$14+VLOOKUP($Q8,武学奇术!$A:$ZZ,20,FALSE)+SUM(_xlfn.XLOOKUP(R8:AF8,增益!$A:$A,增益!$T:$T,0))} -> 1.35 | BN8: =MIN((1-BL8)*BI8,BI8*BJ8) -> 0.9105 | BO8: =1-BL8-BN8-BP8 -> 0 | BP8: =IF(VLOOKUP($Q8,武学奇术!$A:$ZZ,22,FALSE)=1,0,(1-$BI8))*(1-$BL8) -> 0 | BQ8: {=SUM(_xlfn.XLOOKUP(R8:AF8,增益!$A:$A,增益!$W:$W,0))+$I$5} -> 0.11
A9: 会心率 | B9: 0.785 | D9: 最小攻击 | E9: 最大攻击 | F9: 穿透 | G9: 伤害加成 | K9: =($L9*$BN9+$M9*$BL9+$N9*$BO9+$O9*$BP9) -> 77950.728 | L9: =((($AN9+($AO9-$AN9)*IF(VLOOKUP($Q9,武学奇术!$A:$ZZ,31,FALSE)=1,$F$18,0.5))*$AH9+$AI9)*(1+$AP9)*(1+$AQ9)+(($AS9+($AT9-$AS9)*IF(VLOOKUP($Q9,武学奇术!$A:$ZZ,31,FALSE)=1,$F$18,0.5))*IF($G$1="鸣金",$AJ9,$AH9)+IF($G$1="鸣金",$AK9*1.5,0))*(1+$AU9)*(1+$AV9)+(($AW9+($AX9-$AW9)*IF(VLOOKUP($Q9,武学奇术!$A:$ZZ,31,FALSE)=1,$F$18,0.5))*IF($G$1="裂石",$AJ9,$AH9)+IF($G$1="裂石",$AK9*1.5,0))*(1+$AY9)*(1+$AZ9)+(($BA9+($BB9-$BA9)*IF(VLOOKUP($Q9,武学奇术!$A:$ZZ,31,FALSE)=1,$F$18,0.5))*IF($G$1="牵丝",$AJ9,$AH9)+IF($G$1="牵丝",$AK9*1.5,0))*(1+$BC9)*(1+$BD9)+(($BE9+($BF9-$BE9)*IF(VLOOKUP($Q9,武学奇术!$A:$ZZ,31,FALSE)=1,$F$18,0.5))*IF($G$1="破竹",$AJ9,$AH9)+IF($G$1="破竹",$AK9*1.5,0))*(1+$BG9)*(1+$BH9))*(1+$AL9)*$BK9*$P9*(1+IF(VLOOKUP($Q9,武学奇术!$A:$ZZ,30,FALSE)="蓄力技",$B$21,0))*(1+$BQ9) -> 79272.985 | M9: =(($AO9*$AH9+$AI9)*(1+$AP9)*(1+$AQ9)+($AT9*IF($G$1="鸣金",$AJ9,$AH9)+IF($G$1="鸣金",$AK9*1.5,0))*(1+$AU9)*(1+$AV9)+($AX9*IF($G$1="裂石",$AJ9,$AH9)+IF($G$1="裂石",$AK9*1.5,0))*(1+$AY9)*(1+$AZ9)+($BB9*IF($G$1="牵丝",$AJ9,$AH9)+IF($G$1="牵丝",$AK9*1.5,0))*(1+$BC9)*(1+$BD9)+($BF9*IF($G$1="破竹",$AJ9,$AH9)+IF($G$1="破竹",$AK9*1.5,0))*(1+$BG9)*(1+$BH9))*(1+$AL9)*$BM9*$P9*(1+IF(VLOOKUP($Q9,武学奇术!$A:$ZZ,30,FALSE)="蓄力技",$B$21,0))*(1+$BQ9) -> 64499.158 | N9: =((($AN9+($AO9-$AN9)*IF(VLOOKUP($Q9,武学奇术!$A:$ZZ,31,FALSE)=1,$F$18,0.5))*$AH9+$AI9)*(1+$AP9)*(1+$AQ9)+(($AS9+($AT9-$AS9)*IF(VLOOKUP($Q9,武学奇术!$A:$ZZ,31,FALSE)=1,$F$18,0.5))*IF($G$1="鸣金",$AJ9,$AH9)+IF($G$1="鸣金",$AK9*1.5,0))*(1+$AU9)*(1+$AV9)+(($AW9+($AX9-$AW9)*IF(VLOOKUP($Q9,武学奇术!$A:$ZZ,31,FALSE)=1,$F$18,0.5))*IF($G$1="裂石",$AJ9,$AH9)+IF($G$1="裂石",$AK9*1.5,0))*(1+$AY9)*(1+$AZ9)+(($BA9+($BB9-$BA9)*IF(VLOOKUP($Q9,武学奇术!$A:$ZZ,31,FALSE)=1,$F$18,0.5))*IF($G$1="牵丝",$AJ9,$AH9)+IF($G$1="牵丝",$AK9*1.5,0))*(1+$BC9)*(1+$BD9)+(($BE9+($BF9-$BE9)*IF(VLOOKUP($Q9,武学奇术!$A:$ZZ,31,FALSE)=1,$F$18,0.5))*IF($G$1="破竹",$AJ9,$AH9)+IF($G$1="破竹",$AK9*1.5,0))*(1+$BG9)*(1+$BH9))*(1+$AL9)*$P9*(1+IF(VLOOKUP($Q9,武学奇术!$A:$ZZ,30,FALSE)="蓄力技",$B$21,0))*(1+$BQ9) -> 42850.262 | O9: =((($AN9*$AH9+$AI9)*(1+$AP9)*(1+$AQ9)+($AS9*IF($G$1="鸣金",$AJ9,$AH9)+IF($G$1="鸣金",$AK9*1.5,0))*(1+$AU9)*(1+$AV9)+($AW9*IF($G$1="裂石",$AJ9,$AH9)+IF($G$1="裂石",$AK9*1.5,0))*(1+$AY9)*(1+$AZ9)+($BA9*IF($G$1="牵丝",$AJ9,$AH9)+IF($G$1="牵丝",$AK9*1.5,0))*(1+$BC9)*(1+$BD9)+($BE9*IF($G$1="破竹",$AJ9,$AH9)+IF($G$1="破竹",$AK9*1.5,0))*(1+$BG9)*(1+$BH9))*(1+$AL9))*$P9*(1+IF(VLOOKUP($Q9,武学奇术!$A:$ZZ,30,FALSE)="蓄力技",$B$21,0))*(1+$BQ9) -> 37923.37 | P9: 1 | Q9: 拳甲Q2 | R9: 易水歌1层 | S9: N/a | T9: N/a | U9: N/a | V9: N/a | W9: N/a | X9: 沧海帖1层 | Y9: N/a | Z9: 三穷 | AA9: N/a | AB9: N/a | AC9: N/a | AD9: N/a | AE9: 无惧 | AF9: 天志增伤 | AG9: =VLOOKUP($Q9,武学奇术!$A:$ZZ,25,FALSE) -> 拳甲 | AH9: =VLOOKUP($Q9,武学奇术!$A:$ZZ,26,FALSE) -> 2.75166 | AI9: =VLOOKUP($Q9,武学奇术!$A:$ZZ,27,FALSE)*(1+IF(OR($AG9=$F$4,$AG9=$F$5),$B$22,0)) -> 1060.92 | AJ9: =VLOOKUP($Q9,武学奇术!$A:$ZZ,28,FALSE) -> 4.12776 | AK9: =VLOOKUP($Q9,武学奇术!$A:$ZZ,29,FALSE)*(1+IF(OR($AG9=$F$4,$AG9=$F$5),$B$22,0)) -> 574.56 | AL9: {=$G$3+IFERROR(VLOOKUP($AG9,$F$4:$G$7,2,FALSE),0)+VLOOKUP($Q9,武学奇术!$A:$ZZ,2,FALSE)+SUM(_xlfn.XLOOKUP($R9:$AF9,增益!$A:$A,增益!$B:$B,0))} -> 0.6641 | AM9: {=VLOOKUP($Q9,武学奇术!$A:$ZZ,5,FALSE)+SUM(_xlfn.XLOOKUP($R9:$AF9,增益!$A:$A,增益!$E:$E,0))} -> 0 | AN9: {=$D$10*(1+$AM9)+VLOOKUP($Q9,武学奇术!$A:$ZZ,3,FALSE)+SUM(_xlfn.XLOOKUP($R9:$AF9,增益!$A:$A,增益!$C:$C,0))-$I$2} -> 3804.006 | AO9: {=$E$10*(1+$AM9)+VLOOKUP($Q9,武学奇术!$A:$ZZ,4,FALSE)+SUM(_xlfn.XLOOKUP($R9:$AF9,增益!$A:$A,增益!$D:$D,0))-$I$2} -> 3804.006 | AP9: {=IF($F$10-$I$3+VLOOKUP($Q9,武学奇术!$A:$ZZ,6,FALSE)+SUM(_xlfn.XLOOKUP(R9:AF9,增益!$A:$A,增益!$F:$F,0))>0,($F$10-$I$3+VLOOKUP($Q9,武学奇术!$A:$ZZ,6,FALSE)+SUM(_xlfn.XLOOKUP(R9:AF9,增益!$A:$A,增益!$F:$F,0)))/200,($F$10-$I$3+VLOOKUP($Q9,武学奇术!$A:$ZZ,6,FALSE)+SUM(_xlfn.XLOOKUP(R9:AF9,增益!$A:$A,增益!$F:$F,0)))/100)} -> 0.307 | AQ9: {=$G$10+VLOOKUP($Q9,武学奇术!$A:$ZZ,7,FALSE)+SUM(_xlfn.XLOOKUP(R9:AF9,增益!$A:$A,增益!$G:$G,0))} -> 0.09 | AR9: {=VLOOKUP($Q9,武学奇术!$A:$ZZ,8,FALSE)+SUM(_xlfn.XLOOKUP(R9:AF9,增益!$A:$A,增益!$H:$H,0))} -> 0 | AS9: =$D$11*(1+$AR9) -> 0 | AT9: =$E$11*(1+$AR9) -> 0 | AU9: {=IF($F$11-$I$4+VLOOKUP($Q9,武学奇术!$A:$ZZ,9,FALSE)+SUM(_xlfn.XLOOKUP(R9:AF9,增益!$A:$A,增益!$I:$I,0))>0,($F$11-$I$4+VLOOKUP($Q9,武学奇术!$A:$ZZ,9,FALSE)+SUM(_xlfn.XLOOKUP(R9:AF9,增益!$A:$A,增益!$I:$I,0)))/200,($F$11-$I$4+VLOOKUP($Q9,武学奇术!$A:$ZZ,9,FALSE)+SUM(_xlfn.XLOOKUP(R9:AF9,增益!$A:$A,增益!$I:$I,0)))/100)} -> -0.24 | AV9: {=$G$11+VLOOKUP($Q9,武学奇术!$A:$ZZ,10,FALSE)+SUM(_xlfn.XLOOKUP(R9:AF9,增益!$A:$A,增益!$J:$J,0))} -> 0 | AW9: =$D$12*(1+$AR9) -> 0 | AX9: =$E$12*(1+$AR9) -> 0 | AY9: {=IF($F$12-$I$4+VLOOKUP($Q9,武学奇术!$A:$ZZ,11,FALSE)+SUM(_xlfn.XLOOKUP(R9:AF9,增益!$A:$A,增益!$K:$K,0))>0,($F$12-$I$4+VLOOKUP($Q9,武学奇术!$A:$ZZ,11,FALSE)+SUM(_xlfn.XLOOKUP(R9:AF9,增益!$A:$A,增益!$K:$K,0)))/200,($F$12-$I$4+VLOOKUP($Q9,武学奇术!$A:$ZZ,11,FALSE)+SUM(_xlfn.XLOOKUP(R9:AF9,增益!$A:$A,增益!$K:$K,0)))/100)} -> -0.24 | AZ9: {=$G$12+VLOOKUP($Q9,武学奇术!$A:$ZZ,12,FALSE)+SUM(_xlfn.XLOOKUP(R9:AF9,增益!$A:$A,增益!$L:$L,0))} -> 0 | BA9: =$D$13*(1+$AR9) -> 0 | BB9: =$E$13*(1+$AR9) -> 0 | BC9: {=IF($F$13-$I$4+VLOOKUP($Q9,武学奇术!$A:$ZZ,13,FALSE)+SUM(_xlfn.XLOOKUP(R9:AF9,增益!$A:$A,增益!$M:$M,0))>0,($F$13-$I$4+VLOOKUP($Q9,武学奇术!$A:$ZZ,13,FALSE)+SUM(_xlfn.XLOOKUP(R9:AF9,增益!$A:$A,增益!$K:$K,0)))/200,($F$13-$I$4+VLOOKUP($Q9,武学奇术!$A:$ZZ,13,FALSE)+SUM(_xlfn.XLOOKUP(R9:AF9,增益!$A:$A,增益!$M:$M,0)))/100)} -> -0.24 | BD9: {=$G$13+VLOOKUP($Q9,武学奇术!$A:$ZZ,14,FALSE)+SUM(_xlfn.XLOOKUP(R9:AF9,增益!$A:$A,增益!$N:$N,0))} -> 0 | BE9: =$D$14*(1+$AR9) -> 570.28 | BF9: =$E$14*(1+$AR9) -> 1582.156 | BG9: {=IF($F$14-$I$4+VLOOKUP($Q9,武学奇术!$A:$ZZ,15,FALSE)+SUM(_xlfn.XLOOKUP(R9:AF9,增益!$A:$A,增益!$O:$O,0))>0,($F$14-$I$4+VLOOKUP($Q9,武学奇术!$A:$ZZ,15,FALSE)+SUM(_xlfn.XLOOKUP(R9:AF9,增益!$A:$A,增益!$O:$O,0)))/200,($F$14-$I$4+VLOOKUP($Q9,武学奇术!$A:$ZZ,15,FALSE)+SUM(_xlfn.XLOOKUP(R9:AF9,增益!$A:$A,增益!$O:$O,0)))/100)} -> 0.03 | BH9: {=$G$14+VLOOKUP($Q9,武学奇术!$A:$ZZ,16,FALSE)+SUM(_xlfn.XLOOKUP(R9:AF9,增益!$A:$A,增益!$P:$P,0))} -> 0.24 | BI9: =MIN(IF(VLOOKUP($Q9,武学奇术!$A:$ZZ,23,FALSE)=1,100%,$B$8),100%) -> 1 | BJ9: {=IF(VLOOKUP($Q9,武学奇术!$A:$ZZ,23,FALSE)=1,100%,MIN(80%,$B$9+VLOOKUP($Q9,武学奇术!$A:$ZZ,17,FALSE)+SUM(_xlfn.XLOOKUP(R9:AF9,增益!$A:$A,增益!$Q:$Q,0)))+$B$11+SUM(_xlfn.XLOOKUP(R9:AF9,增益!$A:$A,增益!$U:$U,0)))*IF(VLOOKUP($Q9,武学奇术!$A:$ZZ,24,FALSE)=1,0,1)+MIN(IF(VLOOKUP($Q9,武学奇术!$A:$ZZ,32,FALSE)=1,IF(VLOOKUP($Q9,武学奇术!$A:$ZZ,24,FALSE)=1,100%,MIN(40%,$B$10+VLOOKUP($Q9,武学奇术!$A:$ZZ,19,FALSE)+SUM(_xlfn.XLOOKUP(R9:AF9,增益!$A:$A,增益!$S:$S,0)))+$B$12+SUM(_xlfn.XLOOKUP(R9:AF9,增益!$A:$A,增益!$V:$V,0))),0),12%)} -> 0.918 | BK9: {=1+$B$13+VLOOKUP($Q9,武学奇术!$A:$ZZ,18,FALSE)+SUM(_xlfn.XLOOKUP(R9:AF9,增益!$A:$A,增益!$R:$R,0))} -> 1.85 | BL9: {=MAX(IF(VLOOKUP($Q9,武学奇术!$A:$ZZ,24,FALSE)=1,100%,MIN(40%,$B$10+VLOOKUP($Q9,武学奇术!$A:$ZZ,19,FALSE)+SUM(_xlfn.XLOOKUP(R9:AF9,增益!$A:$A,增益!$S:$S,0)))+$B$12+SUM(_xlfn.XLOOKUP(R9:AF9,增益!$A:$A,增益!$V:$V,0)))*IF(VLOOKUP($Q9,武学奇术!$A:$ZZ,23,FALSE)=1,0,1)-IF(VLOOKUP($Q9,武学奇术!$A:$ZZ,32,FALSE)=1,12%,0),0)} -> 0.0895 | BM9: {=1+$B$14+VLOOKUP($Q9,武学奇术!$A:$ZZ,20,FALSE)+SUM(_xlfn.XLOOKUP(R9:AF9,增益!$A:$A,增益!$T:$T,0))} -> 1.35 | BN9: =MIN((1-BL9)*BI9,BI9*BJ9) -> 0.9105 | BO9: =1-BL9-BN9-BP9 -> 0 | BP9: =IF(VLOOKUP($Q9,武学奇术!$A:$ZZ,22,FALSE)=1,0,(1-$BI9))*(1-$BL9) -> 0 | BQ9: {=SUM(_xlfn.XLOOKUP(R9:AF9,增益!$A:$A,增益!$W:$W,0))+$I$5} -> 0.11
